/*
*** MADE BY MRPONYCAPTAIN'S .SCHEMATIC TO .JAVA CONVERTING TOOL v2.0 ***
*/

package com.DavidM1A2.AfraidOfTheDark.common.worldGeneration.darkForestDungeon;

import java.util.Random;

import net.minecraft.block.Block;
import net.minecraft.client.Minecraft;
import net.minecraft.init.Blocks;
import net.minecraft.util.BlockPos;
import net.minecraft.world.World;

import com.DavidM1A2.AfraidOfTheDark.common.initializeMod.ModBlocks;

public class BedHouse
{
	public BedHouse(World world, Random rand, int x, int y, int z)
	{
		this.generate(world, rand, x, y, z);
	}

	public void setBlock(World world, int x, int y, int z, Block block, int metadata)
	{
		world.setBlockState(new BlockPos(x, y, z), block.getStateFromMeta(metadata));
	}

	public boolean generate(World world, Random rand, int i, int j, int k)
	{
		this.setBlock(world, i + 0, j + 0, k + 0, Blocks.stonebrick, 0);
		this.setBlock(world, i + 0, j + 0, k + 1, Blocks.stonebrick, 1);
		this.setBlock(world, i + 0, j + 0, k + 2, Blocks.stonebrick, 0);
		this.setBlock(world, i + 0, j + 0, k + 3, Blocks.stonebrick, 1);
		this.setBlock(world, i + 0, j + 0, k + 4, Blocks.stonebrick, 1);
		this.setBlock(world, i + 0, j + 0, k + 5, Blocks.stonebrick, 1);
		this.setBlock(world, i + 0, j + 0, k + 6, Blocks.stonebrick, 0);
		this.setBlock(world, i + 0, j + 0, k + 7, Blocks.stonebrick, 0);
		this.setBlock(world, i + 0, j + 0, k + 8, Blocks.stonebrick, 0);
		this.setBlock(world, i + 0, j + 0, k + 9, Blocks.stonebrick, 0);
		this.setBlock(world, i + 0, j + 0, k + 10, Blocks.stonebrick, 0);
		this.setBlock(world, i + 0, j + 0, k + 11, Blocks.stonebrick, 1);
		this.setBlock(world, i + 0, j + 0, k + 12, Blocks.stonebrick, 0);
		this.setBlock(world, i + 0, j + 0, k + 13, Blocks.stonebrick, 0);
		this.setBlock(world, i + 0, j + 0, k + 14, Blocks.stonebrick, 0);
		this.setBlock(world, i + 0, j + 0, k + 15, Blocks.stonebrick, 1);
		this.setBlock(world, i + 0, j + 0, k + 16, Blocks.stonebrick, 0);
		this.setBlock(world, i + 0, j + 0, k + 17, Blocks.dirt, 0);
		this.setBlock(world, i + 0, j + 0, k + 18, Blocks.stonebrick, 0);
		this.setBlock(world, i + 0, j + 0, k + 19, Blocks.stonebrick, 0);
		this.setBlock(world, i + 0, j + 0, k + 20, Blocks.stonebrick, 1);
		this.setBlock(world, i + 0, j + 0, k + 21, Blocks.stonebrick, 1);
		this.setBlock(world, i + 0, j + 0, k + 22, Blocks.stonebrick, 1);
		this.setBlock(world, i + 0, j + 1, k + 0, Blocks.air, 0);
		this.setBlock(world, i + 0, j + 1, k + 1, Blocks.air, 0);
		this.setBlock(world, i + 0, j + 1, k + 2, Blocks.air, 0);
		this.setBlock(world, i + 0, j + 1, k + 3, Blocks.air, 0);
		this.setBlock(world, i + 0, j + 1, k + 4, Blocks.air, 0);
		this.setBlock(world, i + 0, j + 1, k + 5, Blocks.air, 0);
		this.setBlock(world, i + 0, j + 1, k + 6, Blocks.air, 0);
		this.setBlock(world, i + 0, j + 1, k + 7, Blocks.air, 0);
		this.setBlock(world, i + 0, j + 1, k + 8, Blocks.air, 0);
		this.setBlock(world, i + 0, j + 1, k + 9, Blocks.air, 0);
		this.setBlock(world, i + 0, j + 1, k + 10, Blocks.air, 0);
		this.setBlock(world, i + 0, j + 1, k + 11, Blocks.air, 0);
		this.setBlock(world, i + 0, j + 1, k + 12, Blocks.air, 0);
		this.setBlock(world, i + 0, j + 1, k + 13, Blocks.air, 0);
		this.setBlock(world, i + 0, j + 1, k + 14, Blocks.air, 0);
		this.setBlock(world, i + 0, j + 1, k + 15, Blocks.air, 0);
		this.setBlock(world, i + 0, j + 1, k + 16, Blocks.air, 0);
		this.setBlock(world, i + 0, j + 1, k + 17, Blocks.air, 0);
		this.setBlock(world, i + 0, j + 1, k + 18, Blocks.air, 0);
		this.setBlock(world, i + 0, j + 1, k + 19, Blocks.air, 0);
		this.setBlock(world, i + 0, j + 1, k + 20, Blocks.air, 0);
		this.setBlock(world, i + 0, j + 1, k + 21, Blocks.vine, 8);
		this.setBlock(world, i + 0, j + 1, k + 22, Blocks.air, 0);
		this.setBlock(world, i + 0, j + 2, k + 0, Blocks.air, 0);
		this.setBlock(world, i + 0, j + 2, k + 1, Blocks.air, 0);
		this.setBlock(world, i + 0, j + 2, k + 2, Blocks.air, 0);
		this.setBlock(world, i + 0, j + 2, k + 3, Blocks.air, 0);
		this.setBlock(world, i + 0, j + 2, k + 4, Blocks.air, 0);
		this.setBlock(world, i + 0, j + 2, k + 5, Blocks.air, 0);
		this.setBlock(world, i + 0, j + 2, k + 6, Blocks.air, 0);
		this.setBlock(world, i + 0, j + 2, k + 7, Blocks.air, 0);
		this.setBlock(world, i + 0, j + 2, k + 8, Blocks.air, 0);
		this.setBlock(world, i + 0, j + 2, k + 9, Blocks.air, 0);
		this.setBlock(world, i + 0, j + 2, k + 10, Blocks.air, 0);
		this.setBlock(world, i + 0, j + 2, k + 11, Blocks.air, 0);
		this.setBlock(world, i + 0, j + 2, k + 12, Blocks.air, 0);
		this.setBlock(world, i + 0, j + 2, k + 13, Blocks.air, 0);
		this.setBlock(world, i + 0, j + 2, k + 14, Blocks.air, 0);
		this.setBlock(world, i + 0, j + 2, k + 15, Blocks.air, 0);
		this.setBlock(world, i + 0, j + 2, k + 16, Blocks.air, 0);
		this.setBlock(world, i + 0, j + 2, k + 17, Blocks.air, 0);
		this.setBlock(world, i + 0, j + 2, k + 18, Blocks.air, 0);
		this.setBlock(world, i + 0, j + 2, k + 19, Blocks.air, 0);
		this.setBlock(world, i + 0, j + 2, k + 20, Blocks.air, 0);
		this.setBlock(world, i + 0, j + 2, k + 21, Blocks.vine, 8);
		this.setBlock(world, i + 0, j + 2, k + 22, Blocks.air, 0);
		this.setBlock(world, i + 0, j + 3, k + 0, Blocks.air, 0);
		this.setBlock(world, i + 0, j + 3, k + 1, Blocks.air, 0);
		this.setBlock(world, i + 0, j + 3, k + 2, Blocks.air, 0);
		this.setBlock(world, i + 0, j + 3, k + 3, Blocks.air, 0);
		this.setBlock(world, i + 0, j + 3, k + 4, Blocks.air, 0);
		this.setBlock(world, i + 0, j + 3, k + 5, Blocks.air, 0);
		this.setBlock(world, i + 0, j + 3, k + 6, Blocks.air, 0);
		this.setBlock(world, i + 0, j + 3, k + 7, Blocks.air, 0);
		this.setBlock(world, i + 0, j + 3, k + 8, Blocks.air, 0);
		this.setBlock(world, i + 0, j + 3, k + 9, Blocks.air, 0);
		this.setBlock(world, i + 0, j + 3, k + 10, Blocks.air, 0);
		this.setBlock(world, i + 0, j + 3, k + 11, Blocks.air, 0);
		this.setBlock(world, i + 0, j + 3, k + 12, Blocks.air, 0);
		this.setBlock(world, i + 0, j + 3, k + 13, Blocks.air, 0);
		this.setBlock(world, i + 0, j + 3, k + 14, Blocks.air, 0);
		this.setBlock(world, i + 0, j + 3, k + 15, Blocks.air, 0);
		this.setBlock(world, i + 0, j + 3, k + 16, Blocks.air, 0);
		this.setBlock(world, i + 0, j + 3, k + 17, Blocks.air, 0);
		this.setBlock(world, i + 0, j + 3, k + 18, Blocks.air, 0);
		this.setBlock(world, i + 0, j + 3, k + 19, Blocks.air, 0);
		this.setBlock(world, i + 0, j + 3, k + 20, Blocks.air, 0);
		this.setBlock(world, i + 0, j + 3, k + 21, Blocks.vine, 8);
		this.setBlock(world, i + 0, j + 3, k + 22, Blocks.air, 0);
		this.setBlock(world, i + 0, j + 4, k + 0, Blocks.air, 0);
		this.setBlock(world, i + 0, j + 4, k + 1, Blocks.air, 0);
		this.setBlock(world, i + 0, j + 4, k + 2, Blocks.air, 0);
		this.setBlock(world, i + 0, j + 4, k + 3, Blocks.air, 0);
		this.setBlock(world, i + 0, j + 4, k + 4, Blocks.air, 0);
		this.setBlock(world, i + 0, j + 4, k + 5, Blocks.air, 0);
		this.setBlock(world, i + 0, j + 4, k + 6, Blocks.air, 0);
		this.setBlock(world, i + 0, j + 4, k + 7, Blocks.air, 0);
		this.setBlock(world, i + 0, j + 4, k + 8, Blocks.air, 0);
		this.setBlock(world, i + 0, j + 4, k + 9, Blocks.air, 0);
		this.setBlock(world, i + 0, j + 4, k + 10, Blocks.air, 0);
		this.setBlock(world, i + 0, j + 4, k + 11, Blocks.air, 0);
		this.setBlock(world, i + 0, j + 4, k + 12, Blocks.air, 0);
		this.setBlock(world, i + 0, j + 4, k + 13, Blocks.air, 0);
		this.setBlock(world, i + 0, j + 4, k + 14, Blocks.air, 0);
		this.setBlock(world, i + 0, j + 4, k + 15, Blocks.air, 0);
		this.setBlock(world, i + 0, j + 4, k + 16, Blocks.air, 0);
		this.setBlock(world, i + 0, j + 4, k + 17, Blocks.air, 0);
		this.setBlock(world, i + 0, j + 4, k + 18, Blocks.air, 0);
		this.setBlock(world, i + 0, j + 4, k + 19, Blocks.air, 0);
		this.setBlock(world, i + 0, j + 4, k + 20, Blocks.air, 0);
		this.setBlock(world, i + 0, j + 4, k + 21, Blocks.air, 0);
		this.setBlock(world, i + 0, j + 4, k + 22, Blocks.air, 0);
		this.setBlock(world, i + 0, j + 5, k + 0, Blocks.air, 0);
		this.setBlock(world, i + 0, j + 5, k + 1, Blocks.stone_brick_stairs, 4);
		this.setBlock(world, i + 0, j + 5, k + 2, Blocks.air, 0);
		this.setBlock(world, i + 0, j + 5, k + 3, Blocks.air, 0);
		this.setBlock(world, i + 0, j + 5, k + 4, Blocks.air, 0);
		this.setBlock(world, i + 0, j + 5, k + 5, Blocks.stone_brick_stairs, 4);
		this.setBlock(world, i + 0, j + 5, k + 6, Blocks.air, 0);
		this.setBlock(world, i + 0, j + 5, k + 7, Blocks.air, 0);
		this.setBlock(world, i + 0, j + 5, k + 8, Blocks.air, 0);
		this.setBlock(world, i + 0, j + 5, k + 9, Blocks.stone_brick_stairs, 4);
		this.setBlock(world, i + 0, j + 5, k + 10, Blocks.air, 0);
		this.setBlock(world, i + 0, j + 5, k + 11, Blocks.air, 0);
		this.setBlock(world, i + 0, j + 5, k + 12, Blocks.air, 0);
		this.setBlock(world, i + 0, j + 5, k + 13, Blocks.stone_brick_stairs, 4);
		this.setBlock(world, i + 0, j + 5, k + 14, Blocks.air, 0);
		this.setBlock(world, i + 0, j + 5, k + 15, Blocks.air, 0);
		this.setBlock(world, i + 0, j + 5, k + 16, Blocks.air, 0);
		this.setBlock(world, i + 0, j + 5, k + 17, Blocks.stone_brick_stairs, 4);
		this.setBlock(world, i + 0, j + 5, k + 18, Blocks.air, 0);
		this.setBlock(world, i + 0, j + 5, k + 19, Blocks.air, 0);
		this.setBlock(world, i + 0, j + 5, k + 20, Blocks.air, 0);
		this.setBlock(world, i + 0, j + 5, k + 21, Blocks.stone_brick_stairs, 4);
		this.setBlock(world, i + 0, j + 5, k + 22, Blocks.air, 0);
		this.setBlock(world, i + 0, j + 6, k + 0, Blocks.air, 0);
		this.setBlock(world, i + 0, j + 6, k + 1, Blocks.stonebrick, 1);
		this.setBlock(world, i + 0, j + 6, k + 2, Blocks.stone_brick_stairs, 4);
		this.setBlock(world, i + 0, j + 6, k + 3, Blocks.stone_brick_stairs, 4);
		this.setBlock(world, i + 0, j + 6, k + 4, Blocks.stone_brick_stairs, 4);
		this.setBlock(world, i + 0, j + 6, k + 5, Blocks.stonebrick, 0);
		this.setBlock(world, i + 0, j + 6, k + 6, Blocks.stone_brick_stairs, 4);
		this.setBlock(world, i + 0, j + 6, k + 7, Blocks.stone_brick_stairs, 4);
		this.setBlock(world, i + 0, j + 6, k + 8, Blocks.stone_brick_stairs, 4);
		this.setBlock(world, i + 0, j + 6, k + 9, Blocks.stonebrick, 1);
		this.setBlock(world, i + 0, j + 6, k + 10, Blocks.stone_brick_stairs, 4);
		this.setBlock(world, i + 0, j + 6, k + 11, Blocks.stone_brick_stairs, 4);
		this.setBlock(world, i + 0, j + 6, k + 12, Blocks.stone_brick_stairs, 4);
		this.setBlock(world, i + 0, j + 6, k + 13, Blocks.stonebrick, 1);
		this.setBlock(world, i + 0, j + 6, k + 14, Blocks.stone_brick_stairs, 4);
		this.setBlock(world, i + 0, j + 6, k + 15, Blocks.stone_brick_stairs, 4);
		this.setBlock(world, i + 0, j + 6, k + 16, Blocks.stone_brick_stairs, 4);
		this.setBlock(world, i + 0, j + 6, k + 17, Blocks.stonebrick, 1);
		this.setBlock(world, i + 0, j + 6, k + 18, Blocks.stone_brick_stairs, 4);
		this.setBlock(world, i + 0, j + 6, k + 19, Blocks.stone_brick_stairs, 4);
		this.setBlock(world, i + 0, j + 6, k + 20, Blocks.stone_brick_stairs, 4);
		this.setBlock(world, i + 0, j + 6, k + 21, Blocks.stonebrick, 1);
		this.setBlock(world, i + 0, j + 6, k + 22, Blocks.air, 0);
		this.setBlock(world, i + 0, j + 7, k + 0, Blocks.air, 0);
		this.setBlock(world, i + 0, j + 7, k + 1, Blocks.stonebrick, 0);
		this.setBlock(world, i + 0, j + 7, k + 2, Blocks.cobblestone_wall, 0);
		this.setBlock(world, i + 0, j + 7, k + 3, Blocks.cobblestone_wall, 0);
		this.setBlock(world, i + 0, j + 7, k + 4, Blocks.cobblestone_wall, 0);
		this.setBlock(world, i + 0, j + 7, k + 5, Blocks.stonebrick, 1);
		this.setBlock(world, i + 0, j + 7, k + 6, Blocks.cobblestone_wall, 0);
		this.setBlock(world, i + 0, j + 7, k + 7, Blocks.cobblestone_wall, 0);
		this.setBlock(world, i + 0, j + 7, k + 8, Blocks.cobblestone_wall, 0);
		this.setBlock(world, i + 0, j + 7, k + 9, Blocks.stonebrick, 1);
		this.setBlock(world, i + 0, j + 7, k + 10, Blocks.cobblestone_wall, 0);
		this.setBlock(world, i + 0, j + 7, k + 11, Blocks.cobblestone_wall, 0);
		this.setBlock(world, i + 0, j + 7, k + 12, Blocks.cobblestone_wall, 0);
		this.setBlock(world, i + 0, j + 7, k + 13, Blocks.stonebrick, 1);
		this.setBlock(world, i + 0, j + 7, k + 14, Blocks.cobblestone_wall, 0);
		this.setBlock(world, i + 0, j + 7, k + 15, Blocks.cobblestone_wall, 0);
		this.setBlock(world, i + 0, j + 7, k + 16, Blocks.cobblestone_wall, 0);
		this.setBlock(world, i + 0, j + 7, k + 17, Blocks.stonebrick, 0);
		this.setBlock(world, i + 0, j + 7, k + 18, Blocks.cobblestone_wall, 0);
		this.setBlock(world, i + 0, j + 7, k + 19, Blocks.cobblestone_wall, 0);
		this.setBlock(world, i + 0, j + 7, k + 20, Blocks.cobblestone_wall, 0);
		this.setBlock(world, i + 0, j + 7, k + 21, Blocks.stonebrick, 1);
		this.setBlock(world, i + 0, j + 7, k + 22, Blocks.air, 0);
		this.setBlock(world, i + 0, j + 8, k + 0, Blocks.air, 0);
		this.setBlock(world, i + 0, j + 8, k + 1, Blocks.stonebrick, 0);
		this.setBlock(world, i + 0, j + 8, k + 2, Blocks.air, 0);
		this.setBlock(world, i + 0, j + 8, k + 3, Blocks.air, 0);
		this.setBlock(world, i + 0, j + 8, k + 4, Blocks.air, 0);
		this.setBlock(world, i + 0, j + 8, k + 5, Blocks.stonebrick, 1);
		this.setBlock(world, i + 0, j + 8, k + 6, Blocks.air, 0);
		this.setBlock(world, i + 0, j + 8, k + 7, Blocks.air, 0);
		this.setBlock(world, i + 0, j + 8, k + 8, Blocks.air, 0);
		this.setBlock(world, i + 0, j + 8, k + 9, Blocks.stonebrick, 0);
		this.setBlock(world, i + 0, j + 8, k + 10, Blocks.air, 0);
		this.setBlock(world, i + 0, j + 8, k + 11, Blocks.air, 0);
		this.setBlock(world, i + 0, j + 8, k + 12, Blocks.air, 0);
		this.setBlock(world, i + 0, j + 8, k + 13, Blocks.stonebrick, 1);
		this.setBlock(world, i + 0, j + 8, k + 14, Blocks.air, 0);
		this.setBlock(world, i + 0, j + 8, k + 15, Blocks.air, 0);
		this.setBlock(world, i + 0, j + 8, k + 16, Blocks.air, 0);
		this.setBlock(world, i + 0, j + 8, k + 17, Blocks.stonebrick, 1);
		this.setBlock(world, i + 0, j + 8, k + 18, Blocks.air, 0);
		this.setBlock(world, i + 0, j + 8, k + 19, Blocks.air, 0);
		this.setBlock(world, i + 0, j + 8, k + 20, Blocks.air, 0);
		this.setBlock(world, i + 0, j + 8, k + 21, Blocks.stonebrick, 0);
		this.setBlock(world, i + 0, j + 8, k + 22, Blocks.air, 0);
		this.setBlock(world, i + 0, j + 9, k + 0, Blocks.air, 0);
		this.setBlock(world, i + 0, j + 9, k + 1, Blocks.stonebrick, 1);
		this.setBlock(world, i + 0, j + 9, k + 2, Blocks.air, 0);
		this.setBlock(world, i + 0, j + 9, k + 3, Blocks.air, 0);
		this.setBlock(world, i + 0, j + 9, k + 4, Blocks.air, 0);
		this.setBlock(world, i + 0, j + 9, k + 5, Blocks.stonebrick, 1);
		this.setBlock(world, i + 0, j + 9, k + 6, Blocks.air, 0);
		this.setBlock(world, i + 0, j + 9, k + 7, Blocks.air, 0);
		this.setBlock(world, i + 0, j + 9, k + 8, Blocks.air, 0);
		this.setBlock(world, i + 0, j + 9, k + 9, Blocks.stonebrick, 0);
		this.setBlock(world, i + 0, j + 9, k + 10, Blocks.air, 0);
		this.setBlock(world, i + 0, j + 9, k + 11, Blocks.air, 0);
		this.setBlock(world, i + 0, j + 9, k + 12, Blocks.air, 0);
		this.setBlock(world, i + 0, j + 9, k + 13, Blocks.stonebrick, 1);
		this.setBlock(world, i + 0, j + 9, k + 14, Blocks.air, 0);
		this.setBlock(world, i + 0, j + 9, k + 15, Blocks.air, 0);
		this.setBlock(world, i + 0, j + 9, k + 16, Blocks.air, 0);
		this.setBlock(world, i + 0, j + 9, k + 17, Blocks.stonebrick, 1);
		this.setBlock(world, i + 0, j + 9, k + 18, Blocks.air, 0);
		this.setBlock(world, i + 0, j + 9, k + 19, Blocks.air, 0);
		this.setBlock(world, i + 0, j + 9, k + 20, Blocks.air, 0);
		this.setBlock(world, i + 0, j + 9, k + 21, Blocks.stonebrick, 1);
		this.setBlock(world, i + 0, j + 9, k + 22, Blocks.air, 0);
		this.setBlock(world, i + 0, j + 10, k + 0, Blocks.air, 0);
		this.setBlock(world, i + 0, j + 10, k + 1, Blocks.stone_brick_stairs, 0);
		this.setBlock(world, i + 0, j + 10, k + 2, Blocks.stone_brick_stairs, 0);
		this.setBlock(world, i + 0, j + 10, k + 3, Blocks.stone_brick_stairs, 0);
		this.setBlock(world, i + 0, j + 10, k + 4, Blocks.stone_brick_stairs, 0);
		this.setBlock(world, i + 0, j + 10, k + 5, Blocks.stonebrick, 1);
		this.setBlock(world, i + 0, j + 10, k + 6, Blocks.stone_brick_stairs, 7);
		this.setBlock(world, i + 0, j + 10, k + 7, Blocks.air, 0);
		this.setBlock(world, i + 0, j + 10, k + 8, Blocks.stone_brick_stairs, 6);
		this.setBlock(world, i + 0, j + 10, k + 9, Blocks.stonebrick, 1);
		this.setBlock(world, i + 0, j + 10, k + 10, Blocks.stone_brick_stairs, 7);
		this.setBlock(world, i + 0, j + 10, k + 11, Blocks.air, 0);
		this.setBlock(world, i + 0, j + 10, k + 12, Blocks.stone_brick_stairs, 6);
		this.setBlock(world, i + 0, j + 10, k + 13, Blocks.stonebrick, 1);
		this.setBlock(world, i + 0, j + 10, k + 14, Blocks.stone_brick_stairs, 7);
		this.setBlock(world, i + 0, j + 10, k + 15, Blocks.air, 0);
		this.setBlock(world, i + 0, j + 10, k + 16, Blocks.stone_brick_stairs, 6);
		this.setBlock(world, i + 0, j + 10, k + 17, Blocks.stonebrick, 1);
		this.setBlock(world, i + 0, j + 10, k + 18, Blocks.stone_brick_stairs, 0);
		this.setBlock(world, i + 0, j + 10, k + 19, Blocks.stone_brick_stairs, 0);
		this.setBlock(world, i + 0, j + 10, k + 20, Blocks.stone_brick_stairs, 0);
		this.setBlock(world, i + 0, j + 10, k + 21, Blocks.stone_brick_stairs, 0);
		this.setBlock(world, i + 0, j + 10, k + 22, Blocks.air, 0);
		this.setBlock(world, i + 0, j + 11, k + 0, Blocks.air, 0);
		this.setBlock(world, i + 0, j + 11, k + 1, Blocks.air, 0);
		this.setBlock(world, i + 0, j + 11, k + 2, Blocks.air, 0);
		this.setBlock(world, i + 0, j + 11, k + 3, Blocks.air, 0);
		this.setBlock(world, i + 0, j + 11, k + 4, Blocks.air, 0);
		this.setBlock(world, i + 0, j + 11, k + 5, Blocks.air, 0);
		this.setBlock(world, i + 0, j + 11, k + 6, Blocks.stone_brick_stairs, 0);
		this.setBlock(world, i + 0, j + 11, k + 7, Blocks.stone_brick_stairs, 0);
		this.setBlock(world, i + 0, j + 11, k + 8, Blocks.stone_brick_stairs, 0);
		this.setBlock(world, i + 0, j + 11, k + 9, Blocks.air, 0);
		this.setBlock(world, i + 0, j + 11, k + 10, Blocks.stone_brick_stairs, 0);
		this.setBlock(world, i + 0, j + 11, k + 11, Blocks.stone_brick_stairs, 0);
		this.setBlock(world, i + 0, j + 11, k + 12, Blocks.stone_brick_stairs, 0);
		this.setBlock(world, i + 0, j + 11, k + 13, Blocks.air, 0);
		this.setBlock(world, i + 0, j + 11, k + 14, Blocks.stone_brick_stairs, 0);
		this.setBlock(world, i + 0, j + 11, k + 15, Blocks.stone_brick_stairs, 0);
		this.setBlock(world, i + 0, j + 11, k + 16, Blocks.stone_brick_stairs, 0);
		this.setBlock(world, i + 0, j + 11, k + 17, Blocks.air, 0);
		this.setBlock(world, i + 0, j + 11, k + 18, Blocks.air, 0);
		this.setBlock(world, i + 0, j + 11, k + 19, Blocks.air, 0);
		this.setBlock(world, i + 0, j + 11, k + 20, Blocks.air, 0);
		this.setBlock(world, i + 0, j + 11, k + 21, Blocks.air, 0);
		this.setBlock(world, i + 0, j + 11, k + 22, Blocks.air, 0);
		this.setBlock(world, i + 0, j + 12, k + 0, Blocks.air, 0);
		this.setBlock(world, i + 0, j + 12, k + 1, Blocks.air, 0);
		this.setBlock(world, i + 0, j + 12, k + 2, Blocks.air, 0);
		this.setBlock(world, i + 0, j + 12, k + 3, Blocks.air, 0);
		this.setBlock(world, i + 0, j + 12, k + 4, Blocks.air, 0);
		this.setBlock(world, i + 0, j + 12, k + 5, Blocks.air, 0);
		this.setBlock(world, i + 0, j + 12, k + 6, Blocks.air, 0);
		this.setBlock(world, i + 0, j + 12, k + 7, Blocks.air, 0);
		this.setBlock(world, i + 0, j + 12, k + 8, Blocks.air, 0);
		this.setBlock(world, i + 0, j + 12, k + 9, Blocks.air, 0);
		this.setBlock(world, i + 0, j + 12, k + 10, Blocks.air, 0);
		this.setBlock(world, i + 0, j + 12, k + 11, Blocks.air, 0);
		this.setBlock(world, i + 0, j + 12, k + 12, Blocks.air, 0);
		this.setBlock(world, i + 0, j + 12, k + 13, Blocks.air, 0);
		this.setBlock(world, i + 0, j + 12, k + 14, Blocks.air, 0);
		this.setBlock(world, i + 0, j + 12, k + 15, Blocks.air, 0);
		this.setBlock(world, i + 0, j + 12, k + 16, Blocks.air, 0);
		this.setBlock(world, i + 0, j + 12, k + 17, Blocks.air, 0);
		this.setBlock(world, i + 0, j + 12, k + 18, Blocks.air, 0);
		this.setBlock(world, i + 0, j + 12, k + 19, Blocks.air, 0);
		this.setBlock(world, i + 0, j + 12, k + 20, Blocks.air, 0);
		this.setBlock(world, i + 0, j + 12, k + 21, Blocks.air, 0);
		this.setBlock(world, i + 0, j + 12, k + 22, Blocks.air, 0);
		this.setBlock(world, i + 1, j + 0, k + 0, Blocks.stonebrick, 0);
		this.setBlock(world, i + 1, j + 0, k + 1, Blocks.stonebrick, 0);
		this.setBlock(world, i + 1, j + 0, k + 2, Blocks.stonebrick, 0);
		this.setBlock(world, i + 1, j + 0, k + 3, Blocks.stonebrick, 1);
		this.setBlock(world, i + 1, j + 0, k + 4, Blocks.stonebrick, 0);
		this.setBlock(world, i + 1, j + 0, k + 5, Blocks.stonebrick, 0);
		this.setBlock(world, i + 1, j + 0, k + 6, Blocks.stonebrick, 1);
		this.setBlock(world, i + 1, j + 0, k + 7, Blocks.stonebrick, 0);
		this.setBlock(world, i + 1, j + 0, k + 8, Blocks.stonebrick, 0);
		this.setBlock(world, i + 1, j + 0, k + 9, Blocks.dirt, 0);
		this.setBlock(world, i + 1, j + 0, k + 10, Blocks.dirt, 0);
		this.setBlock(world, i + 1, j + 0, k + 11, Blocks.stonebrick, 0);
		this.setBlock(world, i + 1, j + 0, k + 12, Blocks.dirt, 0);
		this.setBlock(world, i + 1, j + 0, k + 13, Blocks.stonebrick, 0);
		this.setBlock(world, i + 1, j + 0, k + 14, Blocks.stonebrick, 0);
		this.setBlock(world, i + 1, j + 0, k + 15, Blocks.stonebrick, 0);
		this.setBlock(world, i + 1, j + 0, k + 16, Blocks.stonebrick, 0);
		this.setBlock(world, i + 1, j + 0, k + 17, Blocks.stonebrick, 0);
		this.setBlock(world, i + 1, j + 0, k + 18, Blocks.stonebrick, 0);
		this.setBlock(world, i + 1, j + 0, k + 19, Blocks.stonebrick, 0);
		this.setBlock(world, i + 1, j + 0, k + 20, Blocks.stonebrick, 1);
		this.setBlock(world, i + 1, j + 0, k + 21, Blocks.stonebrick, 0);
		this.setBlock(world, i + 1, j + 0, k + 22, Blocks.stonebrick, 0);
		this.setBlock(world, i + 1, j + 1, k + 0, Blocks.air, 0);
		this.setBlock(world, i + 1, j + 1, k + 1, Blocks.stonebrick, 1);
		this.setBlock(world, i + 1, j + 1, k + 2, Blocks.leaves, 13);
		this.setBlock(world, i + 1, j + 1, k + 3, Blocks.leaves, 13);
		this.setBlock(world, i + 1, j + 1, k + 4, Blocks.leaves, 13);
		this.setBlock(world, i + 1, j + 1, k + 5, Blocks.stonebrick, 1);
		this.setBlock(world, i + 1, j + 1, k + 6, Blocks.vine, 8);
		this.setBlock(world, i + 1, j + 1, k + 7, Blocks.leaves, 13);
		this.setBlock(world, i + 1, j + 1, k + 8, Blocks.leaves, 13);
		this.setBlock(world, i + 1, j + 1, k + 9, Blocks.stonebrick, 1);
		this.setBlock(world, i + 1, j + 1, k + 10, Blocks.air, 0);
		this.setBlock(world, i + 1, j + 1, k + 11, Blocks.air, 0);
		this.setBlock(world, i + 1, j + 1, k + 12, Blocks.air, 0);
		this.setBlock(world, i + 1, j + 1, k + 13, Blocks.stonebrick, 0);
		this.setBlock(world, i + 1, j + 1, k + 14, Blocks.leaves, 5);
		this.setBlock(world, i + 1, j + 1, k + 15, Blocks.leaves, 5);
		this.setBlock(world, i + 1, j + 1, k + 16, Blocks.leaves, 5);
		this.setBlock(world, i + 1, j + 1, k + 17, Blocks.stonebrick, 1);
		this.setBlock(world, i + 1, j + 1, k + 18, Blocks.leaves, 5);
		this.setBlock(world, i + 1, j + 1, k + 19, Blocks.leaves, 5);
		this.setBlock(world, i + 1, j + 1, k + 20, Blocks.vine, 1);
		this.setBlock(world, i + 1, j + 1, k + 21, Blocks.stonebrick, 1);
		this.setBlock(world, i + 1, j + 1, k + 22, Blocks.vine, 4);
		this.setBlock(world, i + 1, j + 2, k + 0, Blocks.air, 0);
		this.setBlock(world, i + 1, j + 2, k + 1, Blocks.stonebrick, 1);
		this.setBlock(world, i + 1, j + 2, k + 2, Blocks.leaves, 13);
		this.setBlock(world, i + 1, j + 2, k + 3, Blocks.air, 0);
		this.setBlock(world, i + 1, j + 2, k + 4, Blocks.vine, 8);
		this.setBlock(world, i + 1, j + 2, k + 5, Blocks.stonebrick, 0);
		this.setBlock(world, i + 1, j + 2, k + 6, Blocks.air, 0);
		this.setBlock(world, i + 1, j + 2, k + 7, Blocks.air, 0);
		this.setBlock(world, i + 1, j + 2, k + 8, Blocks.leaves, 13);
		this.setBlock(world, i + 1, j + 2, k + 9, Blocks.stonebrick, 1);
		this.setBlock(world, i + 1, j + 2, k + 10, Blocks.air, 0);
		this.setBlock(world, i + 1, j + 2, k + 11, Blocks.air, 0);
		this.setBlock(world, i + 1, j + 2, k + 12, Blocks.air, 0);
		this.setBlock(world, i + 1, j + 2, k + 13, Blocks.stonebrick, 1);
		this.setBlock(world, i + 1, j + 2, k + 14, Blocks.air, 0);
		this.setBlock(world, i + 1, j + 2, k + 15, Blocks.vine, 8);
		this.setBlock(world, i + 1, j + 2, k + 16, Blocks.leaves, 5);
		this.setBlock(world, i + 1, j + 2, k + 17, Blocks.stonebrick, 0);
		this.setBlock(world, i + 1, j + 2, k + 18, Blocks.air, 0);
		this.setBlock(world, i + 1, j + 2, k + 19, Blocks.air, 0);
		this.setBlock(world, i + 1, j + 2, k + 20, Blocks.air, 0);
		this.setBlock(world, i + 1, j + 2, k + 21, Blocks.stonebrick, 1);
		this.setBlock(world, i + 1, j + 2, k + 22, Blocks.vine, 4);
		this.setBlock(world, i + 1, j + 3, k + 0, Blocks.air, 0);
		this.setBlock(world, i + 1, j + 3, k + 1, Blocks.stonebrick, 1);
		this.setBlock(world, i + 1, j + 3, k + 2, Blocks.air, 0);
		this.setBlock(world, i + 1, j + 3, k + 3, Blocks.air, 0);
		this.setBlock(world, i + 1, j + 3, k + 4, Blocks.air, 0);
		this.setBlock(world, i + 1, j + 3, k + 5, Blocks.stonebrick, 1);
		this.setBlock(world, i + 1, j + 3, k + 6, Blocks.air, 0);
		this.setBlock(world, i + 1, j + 3, k + 7, Blocks.air, 0);
		this.setBlock(world, i + 1, j + 3, k + 8, Blocks.air, 0);
		this.setBlock(world, i + 1, j + 3, k + 9, Blocks.stonebrick, 0);
		this.setBlock(world, i + 1, j + 3, k + 10, Blocks.air, 0);
		this.setBlock(world, i + 1, j + 3, k + 11, Blocks.air, 0);
		this.setBlock(world, i + 1, j + 3, k + 12, Blocks.air, 0);
		this.setBlock(world, i + 1, j + 3, k + 13, Blocks.stonebrick, 1);
		this.setBlock(world, i + 1, j + 3, k + 14, Blocks.air, 0);
		this.setBlock(world, i + 1, j + 3, k + 15, Blocks.air, 0);
		this.setBlock(world, i + 1, j + 3, k + 16, Blocks.air, 0);
		this.setBlock(world, i + 1, j + 3, k + 17, Blocks.stonebrick, 1);
		this.setBlock(world, i + 1, j + 3, k + 18, Blocks.air, 0);
		this.setBlock(world, i + 1, j + 3, k + 19, Blocks.air, 0);
		this.setBlock(world, i + 1, j + 3, k + 20, Blocks.vine, 1);
		this.setBlock(world, i + 1, j + 3, k + 21, Blocks.stonebrick, 1);
		this.setBlock(world, i + 1, j + 3, k + 22, Blocks.air, 0);
		this.setBlock(world, i + 1, j + 4, k + 0, Blocks.air, 0);
		this.setBlock(world, i + 1, j + 4, k + 1, Blocks.stonebrick, 1);
		this.setBlock(world, i + 1, j + 4, k + 2, Blocks.stone_brick_stairs, 7);
		this.setBlock(world, i + 1, j + 4, k + 3, Blocks.air, 0);
		this.setBlock(world, i + 1, j + 4, k + 4, Blocks.stone_brick_stairs, 6);
		this.setBlock(world, i + 1, j + 4, k + 5, Blocks.stonebrick, 1);
		this.setBlock(world, i + 1, j + 4, k + 6, Blocks.stone_brick_stairs, 7);
		this.setBlock(world, i + 1, j + 4, k + 7, Blocks.air, 0);
		this.setBlock(world, i + 1, j + 4, k + 8, Blocks.stone_brick_stairs, 6);
		this.setBlock(world, i + 1, j + 4, k + 9, Blocks.stonebrick, 1);
		this.setBlock(world, i + 1, j + 4, k + 10, Blocks.stone_brick_stairs, 7);
		this.setBlock(world, i + 1, j + 4, k + 11, Blocks.air, 0);
		this.setBlock(world, i + 1, j + 4, k + 12, Blocks.stone_brick_stairs, 6);
		this.setBlock(world, i + 1, j + 4, k + 13, Blocks.stonebrick, 1);
		this.setBlock(world, i + 1, j + 4, k + 14, Blocks.stone_brick_stairs, 7);
		this.setBlock(world, i + 1, j + 4, k + 15, Blocks.air, 0);
		this.setBlock(world, i + 1, j + 4, k + 16, Blocks.stone_brick_stairs, 6);
		this.setBlock(world, i + 1, j + 4, k + 17, Blocks.stonebrick, 1);
		this.setBlock(world, i + 1, j + 4, k + 18, Blocks.stone_brick_stairs, 7);
		this.setBlock(world, i + 1, j + 4, k + 19, Blocks.air, 0);
		this.setBlock(world, i + 1, j + 4, k + 20, Blocks.stone_brick_stairs, 6);
		this.setBlock(world, i + 1, j + 4, k + 21, Blocks.stonebrick, 0);
		this.setBlock(world, i + 1, j + 4, k + 22, Blocks.air, 0);
		this.setBlock(world, i + 1, j + 5, k + 0, Blocks.stone_brick_stairs, 6);
		this.setBlock(world, i + 1, j + 5, k + 1, Blocks.stonebrick, 0);
		this.setBlock(world, i + 1, j + 5, k + 2, Blocks.stonebrick, 1);
		this.setBlock(world, i + 1, j + 5, k + 3, Blocks.stonebrick, 1);
		this.setBlock(world, i + 1, j + 5, k + 4, Blocks.stonebrick, 0);
		this.setBlock(world, i + 1, j + 5, k + 5, Blocks.stonebrick, 0);
		this.setBlock(world, i + 1, j + 5, k + 6, Blocks.stonebrick, 1);
		this.setBlock(world, i + 1, j + 5, k + 7, Blocks.stonebrick, 1);
		this.setBlock(world, i + 1, j + 5, k + 8, Blocks.stonebrick, 0);
		this.setBlock(world, i + 1, j + 5, k + 9, Blocks.stonebrick, 1);
		this.setBlock(world, i + 1, j + 5, k + 10, Blocks.stonebrick, 1);
		this.setBlock(world, i + 1, j + 5, k + 11, Blocks.stonebrick, 1);
		this.setBlock(world, i + 1, j + 5, k + 12, Blocks.stonebrick, 0);
		this.setBlock(world, i + 1, j + 5, k + 13, Blocks.stonebrick, 0);
		this.setBlock(world, i + 1, j + 5, k + 14, Blocks.stonebrick, 1);
		this.setBlock(world, i + 1, j + 5, k + 15, Blocks.stonebrick, 1);
		this.setBlock(world, i + 1, j + 5, k + 16, Blocks.stonebrick, 0);
		this.setBlock(world, i + 1, j + 5, k + 17, Blocks.stonebrick, 1);
		this.setBlock(world, i + 1, j + 5, k + 18, Blocks.stonebrick, 0);
		this.setBlock(world, i + 1, j + 5, k + 19, Blocks.stonebrick, 1);
		this.setBlock(world, i + 1, j + 5, k + 20, Blocks.stonebrick, 1);
		this.setBlock(world, i + 1, j + 5, k + 21, Blocks.stonebrick, 1);
		this.setBlock(world, i + 1, j + 5, k + 22, Blocks.stone_brick_stairs, 7);
		this.setBlock(world, i + 1, j + 6, k + 0, Blocks.stonebrick, 1);
		this.setBlock(world, i + 1, j + 6, k + 1, Blocks.planks, 5);
		this.setBlock(world, i + 1, j + 6, k + 2, Blocks.planks, 5);
		this.setBlock(world, i + 1, j + 6, k + 3, Blocks.planks, 5);
		this.setBlock(world, i + 1, j + 6, k + 4, Blocks.planks, 5);
		this.setBlock(world, i + 1, j + 6, k + 5, Blocks.planks, 5);
		this.setBlock(world, i + 1, j + 6, k + 6, Blocks.planks, 5);
		this.setBlock(world, i + 1, j + 6, k + 7, Blocks.planks, 5);
		this.setBlock(world, i + 1, j + 6, k + 8, Blocks.planks, 5);
		this.setBlock(world, i + 1, j + 6, k + 9, Blocks.planks, 5);
		this.setBlock(world, i + 1, j + 6, k + 10, Blocks.planks, 5);
		this.setBlock(world, i + 1, j + 6, k + 11, Blocks.planks, 5);
		this.setBlock(world, i + 1, j + 6, k + 12, Blocks.planks, 5);
		this.setBlock(world, i + 1, j + 6, k + 13, Blocks.planks, 5);
		this.setBlock(world, i + 1, j + 6, k + 14, Blocks.planks, 5);
		this.setBlock(world, i + 1, j + 6, k + 15, Blocks.planks, 5);
		this.setBlock(world, i + 1, j + 6, k + 16, Blocks.planks, 5);
		this.setBlock(world, i + 1, j + 6, k + 17, Blocks.planks, 5);
		this.setBlock(world, i + 1, j + 6, k + 18, Blocks.planks, 5);
		this.setBlock(world, i + 1, j + 6, k + 19, Blocks.planks, 5);
		this.setBlock(world, i + 1, j + 6, k + 20, Blocks.planks, 5);
		this.setBlock(world, i + 1, j + 6, k + 21, Blocks.planks, 5);
		this.setBlock(world, i + 1, j + 6, k + 22, Blocks.stonebrick, 1);
		this.setBlock(world, i + 1, j + 7, k + 0, Blocks.stonebrick, 1);
		this.setBlock(world, i + 1, j + 7, k + 1, Blocks.planks, 5);
		this.setBlock(world, i + 1, j + 7, k + 2, Blocks.chest, 5);
		this.setBlock(world, i + 1, j + 7, k + 4, Blocks.wooden_slab, 9);
		this.setBlock(world, i + 1, j + 7, k + 5, Blocks.planks, 1);
		this.setBlock(world, i + 1, j + 7, k + 6, Blocks.wooden_slab, 9);
		this.setBlock(world, i + 1, j + 7, k + 8, Blocks.wooden_slab, 9);
		this.setBlock(world, i + 1, j + 7, k + 9, Blocks.planks, 1);
		this.setBlock(world, i + 1, j + 7, k + 10, Blocks.wooden_slab, 9);
		this.setBlock(world, i + 1, j + 7, k + 12, Blocks.wooden_slab, 9);
		this.setBlock(world, i + 1, j + 7, k + 13, Blocks.planks, 1);
		this.setBlock(world, i + 1, j + 7, k + 14, Blocks.wooden_slab, 9);
		this.setBlock(world, i + 1, j + 7, k + 16, Blocks.wooden_slab, 9);
		this.setBlock(world, i + 1, j + 7, k + 17, Blocks.planks, 1);
		this.setBlock(world, i + 1, j + 7, k + 18, Blocks.wooden_slab, 9);
		this.setBlock(world, i + 1, j + 7, k + 20, Blocks.chest, 5);
		this.setBlock(world, i + 1, j + 7, k + 21, Blocks.planks, 5);
		this.setBlock(world, i + 1, j + 7, k + 22, Blocks.stonebrick, 0);
		this.setBlock(world, i + 1, j + 8, k + 0, Blocks.stonebrick, 1);
		this.setBlock(world, i + 1, j + 8, k + 1, Blocks.air, 0);
		this.setBlock(world, i + 1, j + 8, k + 2, Blocks.air, 0);
		this.setBlock(world, i + 1, j + 8, k + 3, Blocks.air, 0);
		this.setBlock(world, i + 1, j + 8, k + 4, Blocks.air, 0);
		this.setBlock(world, i + 1, j + 8, k + 5, Blocks.flower_pot, 0);
		this.setBlock(world, i + 1, j + 8, k + 6, Blocks.air, 0);
		this.setBlock(world, i + 1, j + 8, k + 7, Blocks.air, 0);
		this.setBlock(world, i + 1, j + 8, k + 8, Blocks.air, 0);
		this.setBlock(world, i + 1, j + 8, k + 9, Blocks.flower_pot, 0);
		this.setBlock(world, i + 1, j + 8, k + 10, Blocks.air, 0);
		this.setBlock(world, i + 1, j + 8, k + 11, Blocks.air, 0);
		this.setBlock(world, i + 1, j + 8, k + 12, Blocks.air, 0);
		this.setBlock(world, i + 1, j + 8, k + 13, Blocks.flower_pot, 0);
		this.setBlock(world, i + 1, j + 8, k + 14, Blocks.air, 0);
		this.setBlock(world, i + 1, j + 8, k + 15, Blocks.air, 0);
		this.setBlock(world, i + 1, j + 8, k + 16, Blocks.air, 0);
		this.setBlock(world, i + 1, j + 8, k + 17, Blocks.flower_pot, 0);
		this.setBlock(world, i + 1, j + 8, k + 18, Blocks.air, 0);
		this.setBlock(world, i + 1, j + 8, k + 19, Blocks.air, 0);
		this.setBlock(world, i + 1, j + 8, k + 20, Blocks.air, 0);
		this.setBlock(world, i + 1, j + 8, k + 21, Blocks.air, 0);
		this.setBlock(world, i + 1, j + 8, k + 22, Blocks.stonebrick, 0);
		this.setBlock(world, i + 1, j + 9, k + 0, Blocks.stonebrick, 0);
		this.setBlock(world, i + 1, j + 9, k + 1, Blocks.stone_slab, 13);
		this.setBlock(world, i + 1, j + 9, k + 2, Blocks.air, 0);
		this.setBlock(world, i + 1, j + 9, k + 3, Blocks.air, 0);
		this.setBlock(world, i + 1, j + 9, k + 4, Blocks.air, 0);
		this.setBlock(world, i + 1, j + 9, k + 5, Blocks.air, 0);
		this.setBlock(world, i + 1, j + 9, k + 6, Blocks.air, 0);
		this.setBlock(world, i + 1, j + 9, k + 7, Blocks.air, 0);
		this.setBlock(world, i + 1, j + 9, k + 8, Blocks.air, 0);
		this.setBlock(world, i + 1, j + 9, k + 9, Blocks.air, 0);
		this.setBlock(world, i + 1, j + 9, k + 10, Blocks.air, 0);
		this.setBlock(world, i + 1, j + 9, k + 11, Blocks.air, 0);
		this.setBlock(world, i + 1, j + 9, k + 12, Blocks.air, 0);
		this.setBlock(world, i + 1, j + 9, k + 13, Blocks.air, 0);
		this.setBlock(world, i + 1, j + 9, k + 14, Blocks.air, 0);
		this.setBlock(world, i + 1, j + 9, k + 15, Blocks.air, 0);
		this.setBlock(world, i + 1, j + 9, k + 16, Blocks.air, 0);
		this.setBlock(world, i + 1, j + 9, k + 17, Blocks.air, 0);
		this.setBlock(world, i + 1, j + 9, k + 18, Blocks.air, 0);
		this.setBlock(world, i + 1, j + 9, k + 19, Blocks.air, 0);
		this.setBlock(world, i + 1, j + 9, k + 20, Blocks.air, 0);
		this.setBlock(world, i + 1, j + 9, k + 21, Blocks.stone_slab, 13);
		this.setBlock(world, i + 1, j + 9, k + 22, Blocks.stonebrick, 1);
		this.setBlock(world, i + 1, j + 10, k + 0, Blocks.stone_brick_stairs, 2);
		this.setBlock(world, i + 1, j + 10, k + 1, Blocks.stonebrick, 1);
		this.setBlock(world, i + 1, j + 10, k + 2, Blocks.stone_brick_stairs, 7);
		this.setBlock(world, i + 1, j + 10, k + 3, Blocks.air, 0);
		this.setBlock(world, i + 1, j + 10, k + 4, Blocks.air, 0);
		this.setBlock(world, i + 1, j + 10, k + 5, Blocks.stone_brick_stairs, 5);
		this.setBlock(world, i + 1, j + 10, k + 6, Blocks.air, 0);
		this.setBlock(world, i + 1, j + 10, k + 7, Blocks.air, 0);
		this.setBlock(world, i + 1, j + 10, k + 8, Blocks.air, 0);
		this.setBlock(world, i + 1, j + 10, k + 9, Blocks.stone_brick_stairs, 5);
		this.setBlock(world, i + 1, j + 10, k + 10, Blocks.air, 0);
		this.setBlock(world, i + 1, j + 10, k + 11, Blocks.air, 0);
		this.setBlock(world, i + 1, j + 10, k + 12, Blocks.air, 0);
		this.setBlock(world, i + 1, j + 10, k + 13, Blocks.stone_brick_stairs, 5);
		this.setBlock(world, i + 1, j + 10, k + 14, Blocks.air, 0);
		this.setBlock(world, i + 1, j + 10, k + 15, Blocks.air, 0);
		this.setBlock(world, i + 1, j + 10, k + 16, Blocks.air, 0);
		this.setBlock(world, i + 1, j + 10, k + 17, Blocks.stone_brick_stairs, 5);
		this.setBlock(world, i + 1, j + 10, k + 18, Blocks.air, 0);
		this.setBlock(world, i + 1, j + 10, k + 19, Blocks.air, 0);
		this.setBlock(world, i + 1, j + 10, k + 20, Blocks.stone_brick_stairs, 6);
		this.setBlock(world, i + 1, j + 10, k + 21, Blocks.stonebrick, 1);
		this.setBlock(world, i + 1, j + 10, k + 22, Blocks.stone_brick_stairs, 3);
		this.setBlock(world, i + 1, j + 11, k + 0, Blocks.air, 0);
		this.setBlock(world, i + 1, j + 11, k + 1, Blocks.stone_slab, 5);
		this.setBlock(world, i + 1, j + 11, k + 2, Blocks.stone_brick_stairs, 0);
		this.setBlock(world, i + 1, j + 11, k + 3, Blocks.stone_brick_stairs, 0);
		this.setBlock(world, i + 1, j + 11, k + 4, Blocks.stone_brick_stairs, 0);
		this.setBlock(world, i + 1, j + 11, k + 5, Blocks.stone_brick_stairs, 0);
		this.setBlock(world, i + 1, j + 11, k + 6, Blocks.stone_brick_stairs, 5);
		this.setBlock(world, i + 1, j + 11, k + 7, Blocks.stone_brick_stairs, 5);
		this.setBlock(world, i + 1, j + 11, k + 8, Blocks.stone_brick_stairs, 5);
		this.setBlock(world, i + 1, j + 11, k + 9, Blocks.stone_brick_stairs, 0);
		this.setBlock(world, i + 1, j + 11, k + 10, Blocks.stone_brick_stairs, 5);
		this.setBlock(world, i + 1, j + 11, k + 11, Blocks.stone_brick_stairs, 5);
		this.setBlock(world, i + 1, j + 11, k + 12, Blocks.stone_brick_stairs, 5);
		this.setBlock(world, i + 1, j + 11, k + 13, Blocks.stone_brick_stairs, 0);
		this.setBlock(world, i + 1, j + 11, k + 14, Blocks.stone_brick_stairs, 5);
		this.setBlock(world, i + 1, j + 11, k + 15, Blocks.stone_brick_stairs, 5);
		this.setBlock(world, i + 1, j + 11, k + 16, Blocks.stone_brick_stairs, 5);
		this.setBlock(world, i + 1, j + 11, k + 17, Blocks.stone_brick_stairs, 0);
		this.setBlock(world, i + 1, j + 11, k + 18, Blocks.stone_brick_stairs, 0);
		this.setBlock(world, i + 1, j + 11, k + 19, Blocks.stone_brick_stairs, 0);
		this.setBlock(world, i + 1, j + 11, k + 20, Blocks.stone_brick_stairs, 0);
		this.setBlock(world, i + 1, j + 11, k + 21, Blocks.stone_slab, 5);
		this.setBlock(world, i + 1, j + 11, k + 22, Blocks.air, 0);
		this.setBlock(world, i + 1, j + 12, k + 0, Blocks.air, 0);
		this.setBlock(world, i + 1, j + 12, k + 1, Blocks.air, 0);
		this.setBlock(world, i + 1, j + 12, k + 2, Blocks.air, 0);
		this.setBlock(world, i + 1, j + 12, k + 3, Blocks.air, 0);
		this.setBlock(world, i + 1, j + 12, k + 4, Blocks.air, 0);
		this.setBlock(world, i + 1, j + 12, k + 5, Blocks.air, 0);
		this.setBlock(world, i + 1, j + 12, k + 6, Blocks.stone_brick_stairs, 0);
		this.setBlock(world, i + 1, j + 12, k + 7, Blocks.stone_brick_stairs, 0);
		this.setBlock(world, i + 1, j + 12, k + 8, Blocks.stone_brick_stairs, 0);
		this.setBlock(world, i + 1, j + 12, k + 9, Blocks.air, 0);
		this.setBlock(world, i + 1, j + 12, k + 10, Blocks.stone_brick_stairs, 0);
		this.setBlock(world, i + 1, j + 12, k + 11, Blocks.stone_brick_stairs, 0);
		this.setBlock(world, i + 1, j + 12, k + 12, Blocks.stone_brick_stairs, 0);
		this.setBlock(world, i + 1, j + 12, k + 13, Blocks.air, 0);
		this.setBlock(world, i + 1, j + 12, k + 14, Blocks.stone_brick_stairs, 0);
		this.setBlock(world, i + 1, j + 12, k + 15, Blocks.stone_brick_stairs, 0);
		this.setBlock(world, i + 1, j + 12, k + 16, Blocks.stone_brick_stairs, 0);
		this.setBlock(world, i + 1, j + 12, k + 17, Blocks.air, 0);
		this.setBlock(world, i + 1, j + 12, k + 18, Blocks.air, 0);
		this.setBlock(world, i + 1, j + 12, k + 19, Blocks.air, 0);
		this.setBlock(world, i + 1, j + 12, k + 20, Blocks.air, 0);
		this.setBlock(world, i + 1, j + 12, k + 21, Blocks.air, 0);
		this.setBlock(world, i + 1, j + 12, k + 22, Blocks.air, 0);
		this.setBlock(world, i + 2, j + 0, k + 0, Blocks.stonebrick, 1);
		this.setBlock(world, i + 2, j + 0, k + 1, Blocks.stonebrick, 0);
		this.setBlock(world, i + 2, j + 0, k + 2, Blocks.stonebrick, 0);
		this.setBlock(world, i + 2, j + 0, k + 3, Blocks.planks, 5);
		this.setBlock(world, i + 2, j + 0, k + 4, Blocks.planks, 5);
		this.setBlock(world, i + 2, j + 0, k + 5, Blocks.planks, 5);
		this.setBlock(world, i + 2, j + 0, k + 6, Blocks.planks, 5);
		this.setBlock(world, i + 2, j + 0, k + 7, Blocks.planks, 5);
		this.setBlock(world, i + 2, j + 0, k + 8, Blocks.planks, 5);
		this.setBlock(world, i + 2, j + 0, k + 9, Blocks.planks, 5);
		this.setBlock(world, i + 2, j + 0, k + 10, Blocks.planks, 5);
		this.setBlock(world, i + 2, j + 0, k + 11, Blocks.planks, 5);
		this.setBlock(world, i + 2, j + 0, k + 12, Blocks.planks, 5);
		this.setBlock(world, i + 2, j + 0, k + 13, Blocks.planks, 5);
		this.setBlock(world, i + 2, j + 0, k + 14, Blocks.planks, 5);
		this.setBlock(world, i + 2, j + 0, k + 15, Blocks.planks, 5);
		this.setBlock(world, i + 2, j + 0, k + 16, Blocks.planks, 5);
		this.setBlock(world, i + 2, j + 0, k + 17, Blocks.planks, 5);
		this.setBlock(world, i + 2, j + 0, k + 18, Blocks.planks, 5);
		this.setBlock(world, i + 2, j + 0, k + 19, Blocks.planks, 5);
		this.setBlock(world, i + 2, j + 0, k + 20, Blocks.stonebrick, 0);
		this.setBlock(world, i + 2, j + 0, k + 21, Blocks.stonebrick, 1);
		this.setBlock(world, i + 2, j + 0, k + 22, Blocks.dirt, 0);
		this.setBlock(world, i + 2, j + 1, k + 0, Blocks.air, 0);
		this.setBlock(world, i + 2, j + 1, k + 1, Blocks.vine, 3);
		this.setBlock(world, i + 2, j + 1, k + 2, Blocks.mossy_cobblestone, 0);
		this.setBlock(world, i + 2, j + 1, k + 3, Blocks.cobblestone, 0);
		this.setBlock(world, i + 2, j + 1, k + 4, Blocks.cobblestone, 0);
		this.setBlock(world, i + 2, j + 1, k + 5, Blocks.mossy_cobblestone, 0);
		this.setBlock(world, i + 2, j + 1, k + 6, Blocks.mossy_cobblestone, 0);
		this.setBlock(world, i + 2, j + 1, k + 7, Blocks.mossy_cobblestone, 0);
		this.setBlock(world, i + 2, j + 1, k + 8, Blocks.cobblestone, 0);
		this.setBlock(world, i + 2, j + 1, k + 9, Blocks.mossy_cobblestone, 0);
		this.setBlock(world, i + 2, j + 1, k + 10, Blocks.air, 0);
		this.setBlock(world, i + 2, j + 1, k + 11, Blocks.air, 0);
		this.setBlock(world, i + 2, j + 1, k + 12, Blocks.air, 0);
		this.setBlock(world, i + 2, j + 1, k + 13, Blocks.cobblestone, 0);
		this.setBlock(world, i + 2, j + 1, k + 14, Blocks.cobblestone, 0);
		this.setBlock(world, i + 2, j + 1, k + 15, Blocks.cobblestone, 0);
		this.setBlock(world, i + 2, j + 1, k + 16, Blocks.cobblestone, 0);
		this.setBlock(world, i + 2, j + 1, k + 17, Blocks.cobblestone, 0);
		this.setBlock(world, i + 2, j + 1, k + 18, Blocks.cobblestone, 0);
		this.setBlock(world, i + 2, j + 1, k + 19, Blocks.cobblestone, 0);
		this.setBlock(world, i + 2, j + 1, k + 20, Blocks.mossy_cobblestone, 0);
		this.setBlock(world, i + 2, j + 1, k + 21, Blocks.air, 0);
		this.setBlock(world, i + 2, j + 1, k + 22, Blocks.air, 0);
		this.setBlock(world, i + 2, j + 2, k + 0, Blocks.air, 0);
		this.setBlock(world, i + 2, j + 2, k + 1, Blocks.vine, 5);
		this.setBlock(world, i + 2, j + 2, k + 2, Blocks.mossy_cobblestone, 0);
		this.setBlock(world, i + 2, j + 2, k + 3, Blocks.mossy_cobblestone, 0);
		this.setBlock(world, i + 2, j + 2, k + 4, Blocks.mossy_cobblestone, 0);
		this.setBlock(world, i + 2, j + 2, k + 5, Blocks.cobblestone, 0);
		this.setBlock(world, i + 2, j + 2, k + 6, Blocks.mossy_cobblestone, 0);
		this.setBlock(world, i + 2, j + 2, k + 7, Blocks.mossy_cobblestone, 0);
		this.setBlock(world, i + 2, j + 2, k + 8, Blocks.mossy_cobblestone, 0);
		this.setBlock(world, i + 2, j + 2, k + 9, Blocks.cobblestone_wall, 0);
		this.setBlock(world, i + 2, j + 2, k + 10, Blocks.air, 0);
		this.setBlock(world, i + 2, j + 2, k + 11, Blocks.air, 0);
		this.setBlock(world, i + 2, j + 2, k + 12, Blocks.air, 0);
		this.setBlock(world, i + 2, j + 2, k + 13, Blocks.cobblestone_wall, 0);
		this.setBlock(world, i + 2, j + 2, k + 14, Blocks.cobblestone, 0);
		this.setBlock(world, i + 2, j + 2, k + 15, Blocks.cobblestone, 0);
		this.setBlock(world, i + 2, j + 2, k + 16, Blocks.cobblestone, 0);
		this.setBlock(world, i + 2, j + 2, k + 17, Blocks.cobblestone, 0);
		this.setBlock(world, i + 2, j + 2, k + 18, Blocks.mossy_cobblestone, 0);
		this.setBlock(world, i + 2, j + 2, k + 19, Blocks.mossy_cobblestone, 0);
		this.setBlock(world, i + 2, j + 2, k + 20, Blocks.cobblestone, 0);
		this.setBlock(world, i + 2, j + 2, k + 21, Blocks.air, 0);
		this.setBlock(world, i + 2, j + 2, k + 22, Blocks.air, 0);
		this.setBlock(world, i + 2, j + 3, k + 0, Blocks.air, 0);
		this.setBlock(world, i + 2, j + 3, k + 1, Blocks.air, 0);
		this.setBlock(world, i + 2, j + 3, k + 2, Blocks.mossy_cobblestone, 0);
		this.setBlock(world, i + 2, j + 3, k + 3, Blocks.mossy_cobblestone, 0);
		this.setBlock(world, i + 2, j + 3, k + 4, Blocks.cobblestone, 0);
		this.setBlock(world, i + 2, j + 3, k + 5, Blocks.mossy_cobblestone, 0);
		this.setBlock(world, i + 2, j + 3, k + 6, Blocks.cobblestone, 0);
		this.setBlock(world, i + 2, j + 3, k + 7, Blocks.mossy_cobblestone, 0);
		this.setBlock(world, i + 2, j + 3, k + 8, Blocks.mossy_cobblestone, 0);
		this.setBlock(world, i + 2, j + 3, k + 9, Blocks.cobblestone_wall, 0);
		this.setBlock(world, i + 2, j + 3, k + 10, Blocks.air, 0);
		this.setBlock(world, i + 2, j + 3, k + 11, Blocks.air, 0);
		this.setBlock(world, i + 2, j + 3, k + 12, Blocks.air, 0);
		this.setBlock(world, i + 2, j + 3, k + 13, Blocks.cobblestone_wall, 0);
		this.setBlock(world, i + 2, j + 3, k + 14, Blocks.mossy_cobblestone, 0);
		this.setBlock(world, i + 2, j + 3, k + 15, Blocks.mossy_cobblestone, 0);
		this.setBlock(world, i + 2, j + 3, k + 16, Blocks.mossy_cobblestone, 0);
		this.setBlock(world, i + 2, j + 3, k + 17, Blocks.mossy_cobblestone, 0);
		this.setBlock(world, i + 2, j + 3, k + 18, Blocks.cobblestone, 0);
		this.setBlock(world, i + 2, j + 3, k + 19, Blocks.cobblestone, 0);
		this.setBlock(world, i + 2, j + 3, k + 20, Blocks.mossy_cobblestone, 0);
		this.setBlock(world, i + 2, j + 3, k + 21, Blocks.air, 0);
		this.setBlock(world, i + 2, j + 3, k + 22, Blocks.air, 0);
		this.setBlock(world, i + 2, j + 4, k + 0, Blocks.air, 0);
		this.setBlock(world, i + 2, j + 4, k + 1, Blocks.stone_brick_stairs, 5);
		this.setBlock(world, i + 2, j + 4, k + 2, Blocks.cobblestone, 0);
		this.setBlock(world, i + 2, j + 4, k + 3, Blocks.mossy_cobblestone, 0);
		this.setBlock(world, i + 2, j + 4, k + 4, Blocks.mossy_cobblestone, 0);
		this.setBlock(world, i + 2, j + 4, k + 5, Blocks.cobblestone, 0);
		this.setBlock(world, i + 2, j + 4, k + 6, Blocks.cobblestone, 0);
		this.setBlock(world, i + 2, j + 4, k + 7, Blocks.cobblestone, 0);
		this.setBlock(world, i + 2, j + 4, k + 8, Blocks.cobblestone, 0);
		this.setBlock(world, i + 2, j + 4, k + 9, Blocks.cobblestone, 0);
		this.setBlock(world, i + 2, j + 4, k + 10, Blocks.air, 0);
		this.setBlock(world, i + 2, j + 4, k + 11, Blocks.air, 0);
		this.setBlock(world, i + 2, j + 4, k + 12, Blocks.air, 0);
		this.setBlock(world, i + 2, j + 4, k + 13, Blocks.cobblestone, 0);
		this.setBlock(world, i + 2, j + 4, k + 14, Blocks.mossy_cobblestone, 0);
		this.setBlock(world, i + 2, j + 4, k + 15, Blocks.cobblestone, 0);
		this.setBlock(world, i + 2, j + 4, k + 16, Blocks.cobblestone, 0);
		this.setBlock(world, i + 2, j + 4, k + 17, Blocks.cobblestone, 0);
		this.setBlock(world, i + 2, j + 4, k + 18, Blocks.mossy_cobblestone, 0);
		this.setBlock(world, i + 2, j + 4, k + 19, Blocks.cobblestone, 0);
		this.setBlock(world, i + 2, j + 4, k + 20, Blocks.mossy_cobblestone, 0);
		this.setBlock(world, i + 2, j + 4, k + 21, Blocks.stone_brick_stairs, 5);
		this.setBlock(world, i + 2, j + 4, k + 22, Blocks.air, 0);
		this.setBlock(world, i + 2, j + 5, k + 0, Blocks.air, 0);
		this.setBlock(world, i + 2, j + 5, k + 1, Blocks.stonebrick, 0);
		this.setBlock(world, i + 2, j + 5, k + 2, Blocks.planks, 5);
		this.setBlock(world, i + 2, j + 5, k + 3, Blocks.planks, 5);
		this.setBlock(world, i + 2, j + 5, k + 4, Blocks.planks, 5);
		this.setBlock(world, i + 2, j + 5, k + 5, Blocks.planks, 5);
		this.setBlock(world, i + 2, j + 5, k + 6, Blocks.planks, 5);
		this.setBlock(world, i + 2, j + 5, k + 7, Blocks.planks, 5);
		this.setBlock(world, i + 2, j + 5, k + 8, Blocks.planks, 5);
		this.setBlock(world, i + 2, j + 5, k + 9, Blocks.planks, 5);
		this.setBlock(world, i + 2, j + 5, k + 10, Blocks.oak_stairs, 7);
		this.setBlock(world, i + 2, j + 5, k + 11, Blocks.oak_stairs, 5);
		this.setBlock(world, i + 2, j + 5, k + 12, Blocks.oak_stairs, 6);
		this.setBlock(world, i + 2, j + 5, k + 13, Blocks.planks, 5);
		this.setBlock(world, i + 2, j + 5, k + 14, Blocks.planks, 5);
		this.setBlock(world, i + 2, j + 5, k + 15, Blocks.planks, 5);
		this.setBlock(world, i + 2, j + 5, k + 16, Blocks.planks, 5);
		this.setBlock(world, i + 2, j + 5, k + 17, Blocks.planks, 5);
		this.setBlock(world, i + 2, j + 5, k + 18, Blocks.planks, 5);
		this.setBlock(world, i + 2, j + 5, k + 19, Blocks.planks, 5);
		this.setBlock(world, i + 2, j + 5, k + 20, Blocks.planks, 5);
		this.setBlock(world, i + 2, j + 5, k + 21, Blocks.stonebrick, 1);
		this.setBlock(world, i + 2, j + 5, k + 22, Blocks.air, 0);
		this.setBlock(world, i + 2, j + 6, k + 0, Blocks.stone_brick_stairs, 6);
		this.setBlock(world, i + 2, j + 6, k + 1, Blocks.planks, 5);
		this.setBlock(world, i + 2, j + 6, k + 2, Blocks.planks, 5);
		this.setBlock(world, i + 2, j + 6, k + 3, Blocks.planks, 5);
		this.setBlock(world, i + 2, j + 6, k + 4, Blocks.planks, 5);
		this.setBlock(world, i + 2, j + 6, k + 5, Blocks.planks, 5);
		this.setBlock(world, i + 2, j + 6, k + 6, Blocks.planks, 5);
		this.setBlock(world, i + 2, j + 6, k + 7, Blocks.planks, 5);
		this.setBlock(world, i + 2, j + 6, k + 8, Blocks.planks, 5);
		this.setBlock(world, i + 2, j + 6, k + 9, Blocks.planks, 5);
		this.setBlock(world, i + 2, j + 6, k + 10, Blocks.planks, 5);
		this.setBlock(world, i + 2, j + 6, k + 11, Blocks.planks, 5);
		this.setBlock(world, i + 2, j + 6, k + 12, Blocks.planks, 5);
		this.setBlock(world, i + 2, j + 6, k + 13, Blocks.planks, 5);
		this.setBlock(world, i + 2, j + 6, k + 14, Blocks.planks, 5);
		this.setBlock(world, i + 2, j + 6, k + 15, Blocks.planks, 5);
		this.setBlock(world, i + 2, j + 6, k + 16, Blocks.planks, 5);
		this.setBlock(world, i + 2, j + 6, k + 17, Blocks.planks, 5);
		this.setBlock(world, i + 2, j + 6, k + 18, Blocks.planks, 5);
		this.setBlock(world, i + 2, j + 6, k + 19, Blocks.planks, 5);
		this.setBlock(world, i + 2, j + 6, k + 20, Blocks.planks, 5);
		this.setBlock(world, i + 2, j + 6, k + 21, Blocks.planks, 5);
		this.setBlock(world, i + 2, j + 6, k + 22, Blocks.stone_brick_stairs, 7);
		this.setBlock(world, i + 2, j + 7, k + 0, Blocks.cobblestone_wall, 0);
		this.setBlock(world, i + 2, j + 7, k + 1, Blocks.chest, 3);
		this.setBlock(world, i + 2, j + 7, k + 2, Blocks.wooden_slab, 5);
		this.setBlock(world, i + 2, j + 7, k + 4, Blocks.air, 0);
		this.setBlock(world, i + 2, j + 7, k + 6, Blocks.air, 0);
		this.setBlock(world, i + 2, j + 7, k + 8, Blocks.air, 0);
		this.setBlock(world, i + 2, j + 7, k + 10, Blocks.air, 0);
		this.setBlock(world, i + 2, j + 7, k + 12, Blocks.air, 0);
		this.setBlock(world, i + 2, j + 7, k + 14, Blocks.air, 0);
		this.setBlock(world, i + 2, j + 7, k + 16, Blocks.air, 0);
		this.setBlock(world, i + 2, j + 7, k + 18, Blocks.air, 0);
		this.setBlock(world, i + 2, j + 7, k + 20, Blocks.wooden_slab, 5);
		this.setBlock(world, i + 2, j + 7, k + 21, Blocks.chest, 2);
		this.setBlock(world, i + 2, j + 7, k + 22, Blocks.cobblestone_wall, 0);
		this.setBlock(world, i + 2, j + 8, k + 0, Blocks.air, 0);
		this.setBlock(world, i + 2, j + 8, k + 1, Blocks.air, 0);
		this.setBlock(world, i + 2, j + 8, k + 2, Blocks.air, 0);
		this.setBlock(world, i + 2, j + 8, k + 3, Blocks.air, 0);
		this.setBlock(world, i + 2, j + 8, k + 4, Blocks.air, 0);
		this.setBlock(world, i + 2, j + 8, k + 5, Blocks.air, 0);
		this.setBlock(world, i + 2, j + 8, k + 6, Blocks.air, 0);
		this.setBlock(world, i + 2, j + 8, k + 7, Blocks.air, 0);
		this.setBlock(world, i + 2, j + 8, k + 8, Blocks.air, 0);
		this.setBlock(world, i + 2, j + 8, k + 9, Blocks.air, 0);
		this.setBlock(world, i + 2, j + 8, k + 10, Blocks.air, 0);
		this.setBlock(world, i + 2, j + 8, k + 11, Blocks.air, 0);
		this.setBlock(world, i + 2, j + 8, k + 12, Blocks.air, 0);
		this.setBlock(world, i + 2, j + 8, k + 13, Blocks.air, 0);
		this.setBlock(world, i + 2, j + 8, k + 14, Blocks.air, 0);
		this.setBlock(world, i + 2, j + 8, k + 15, Blocks.air, 0);
		this.setBlock(world, i + 2, j + 8, k + 16, Blocks.air, 0);
		this.setBlock(world, i + 2, j + 8, k + 17, Blocks.air, 0);
		this.setBlock(world, i + 2, j + 8, k + 18, Blocks.air, 0);
		this.setBlock(world, i + 2, j + 8, k + 19, Blocks.air, 0);
		this.setBlock(world, i + 2, j + 8, k + 20, Blocks.air, 0);
		this.setBlock(world, i + 2, j + 8, k + 21, Blocks.air, 0);
		this.setBlock(world, i + 2, j + 8, k + 22, Blocks.air, 0);
		this.setBlock(world, i + 2, j + 9, k + 0, Blocks.air, 0);
		this.setBlock(world, i + 2, j + 9, k + 1, Blocks.air, 0);
		this.setBlock(world, i + 2, j + 9, k + 2, Blocks.air, 0);
		this.setBlock(world, i + 2, j + 9, k + 3, Blocks.air, 0);
		this.setBlock(world, i + 2, j + 9, k + 4, Blocks.air, 0);
		this.setBlock(world, i + 2, j + 9, k + 5, Blocks.air, 0);
		this.setBlock(world, i + 2, j + 9, k + 6, Blocks.air, 0);
		this.setBlock(world, i + 2, j + 9, k + 7, Blocks.air, 0);
		this.setBlock(world, i + 2, j + 9, k + 8, Blocks.air, 0);
		this.setBlock(world, i + 2, j + 9, k + 9, Blocks.air, 0);
		this.setBlock(world, i + 2, j + 9, k + 10, Blocks.air, 0);
		this.setBlock(world, i + 2, j + 9, k + 11, Blocks.air, 0);
		this.setBlock(world, i + 2, j + 9, k + 12, Blocks.air, 0);
		this.setBlock(world, i + 2, j + 9, k + 13, Blocks.air, 0);
		this.setBlock(world, i + 2, j + 9, k + 14, Blocks.air, 0);
		this.setBlock(world, i + 2, j + 9, k + 15, Blocks.air, 0);
		this.setBlock(world, i + 2, j + 9, k + 16, Blocks.air, 0);
		this.setBlock(world, i + 2, j + 9, k + 17, Blocks.air, 0);
		this.setBlock(world, i + 2, j + 9, k + 18, Blocks.air, 0);
		this.setBlock(world, i + 2, j + 9, k + 19, Blocks.air, 0);
		this.setBlock(world, i + 2, j + 9, k + 20, Blocks.air, 0);
		this.setBlock(world, i + 2, j + 9, k + 21, Blocks.air, 0);
		this.setBlock(world, i + 2, j + 9, k + 22, Blocks.air, 0);
		this.setBlock(world, i + 2, j + 10, k + 0, Blocks.stone_brick_stairs, 2);
		this.setBlock(world, i + 2, j + 10, k + 1, Blocks.stone_brick_stairs, 5);
		this.setBlock(world, i + 2, j + 10, k + 2, Blocks.stone_brick_stairs, 5);
		this.setBlock(world, i + 2, j + 10, k + 3, Blocks.air, 0);
		this.setBlock(world, i + 2, j + 10, k + 4, Blocks.air, 0);
		this.setBlock(world, i + 2, j + 10, k + 5, Blocks.air, 0);
		this.setBlock(world, i + 2, j + 10, k + 6, Blocks.air, 0);
		this.setBlock(world, i + 2, j + 10, k + 7, Blocks.air, 0);
		this.setBlock(world, i + 2, j + 10, k + 8, Blocks.air, 0);
		this.setBlock(world, i + 2, j + 10, k + 9, Blocks.air, 0);
		this.setBlock(world, i + 2, j + 10, k + 10, Blocks.air, 0);
		this.setBlock(world, i + 2, j + 10, k + 11, Blocks.air, 0);
		this.setBlock(world, i + 2, j + 10, k + 12, Blocks.air, 0);
		this.setBlock(world, i + 2, j + 10, k + 13, Blocks.air, 0);
		this.setBlock(world, i + 2, j + 10, k + 14, Blocks.air, 0);
		this.setBlock(world, i + 2, j + 10, k + 15, Blocks.air, 0);
		this.setBlock(world, i + 2, j + 10, k + 16, Blocks.air, 0);
		this.setBlock(world, i + 2, j + 10, k + 17, Blocks.air, 0);
		this.setBlock(world, i + 2, j + 10, k + 18, Blocks.air, 0);
		this.setBlock(world, i + 2, j + 10, k + 19, Blocks.air, 0);
		this.setBlock(world, i + 2, j + 10, k + 20, Blocks.stone_brick_stairs, 6);
		this.setBlock(world, i + 2, j + 10, k + 21, Blocks.stone_brick_stairs, 5);
		this.setBlock(world, i + 2, j + 10, k + 22, Blocks.stone_brick_stairs, 3);
		this.setBlock(world, i + 2, j + 11, k + 0, Blocks.air, 0);
		this.setBlock(world, i + 2, j + 11, k + 1, Blocks.stone_brick_stairs, 2);
		this.setBlock(world, i + 2, j + 11, k + 2, Blocks.stonebrick, 1);
		this.setBlock(world, i + 2, j + 11, k + 3, Blocks.stone_brick_stairs, 7);
		this.setBlock(world, i + 2, j + 11, k + 4, Blocks.air, 0);
		this.setBlock(world, i + 2, j + 11, k + 5, Blocks.stone_brick_stairs, 5);
		this.setBlock(world, i + 2, j + 11, k + 6, Blocks.air, 0);
		this.setBlock(world, i + 2, j + 11, k + 7, Blocks.air, 0);
		this.setBlock(world, i + 2, j + 11, k + 8, Blocks.air, 0);
		this.setBlock(world, i + 2, j + 11, k + 9, Blocks.stone_brick_stairs, 5);
		this.setBlock(world, i + 2, j + 11, k + 10, Blocks.air, 0);
		this.setBlock(world, i + 2, j + 11, k + 11, Blocks.air, 0);
		this.setBlock(world, i + 2, j + 11, k + 12, Blocks.air, 0);
		this.setBlock(world, i + 2, j + 11, k + 13, Blocks.stone_brick_stairs, 5);
		this.setBlock(world, i + 2, j + 11, k + 14, Blocks.air, 0);
		this.setBlock(world, i + 2, j + 11, k + 15, Blocks.air, 0);
		this.setBlock(world, i + 2, j + 11, k + 16, Blocks.air, 0);
		this.setBlock(world, i + 2, j + 11, k + 17, Blocks.stone_brick_stairs, 5);
		this.setBlock(world, i + 2, j + 11, k + 18, Blocks.air, 0);
		this.setBlock(world, i + 2, j + 11, k + 19, Blocks.stone_brick_stairs, 6);
		this.setBlock(world, i + 2, j + 11, k + 20, Blocks.stonebrick, 1);
		this.setBlock(world, i + 2, j + 11, k + 21, Blocks.stone_brick_stairs, 3);
		this.setBlock(world, i + 2, j + 11, k + 22, Blocks.air, 0);
		this.setBlock(world, i + 2, j + 12, k + 0, Blocks.air, 0);
		this.setBlock(world, i + 2, j + 12, k + 1, Blocks.air, 0);
		this.setBlock(world, i + 2, j + 12, k + 2, Blocks.stone_slab, 5);
		this.setBlock(world, i + 2, j + 12, k + 3, Blocks.stone_brick_stairs, 0);
		this.setBlock(world, i + 2, j + 12, k + 4, Blocks.stone_brick_stairs, 0);
		this.setBlock(world, i + 2, j + 12, k + 5, Blocks.stone_brick_stairs, 0);
		this.setBlock(world, i + 2, j + 12, k + 6, Blocks.stonebrick, 0);
		this.setBlock(world, i + 2, j + 12, k + 7, Blocks.stonebrick, 0);
		this.setBlock(world, i + 2, j + 12, k + 8, Blocks.stonebrick, 0);
		this.setBlock(world, i + 2, j + 12, k + 9, Blocks.stone_brick_stairs, 0);
		this.setBlock(world, i + 2, j + 12, k + 10, Blocks.stonebrick, 0);
		this.setBlock(world, i + 2, j + 12, k + 11, Blocks.stonebrick, 0);
		this.setBlock(world, i + 2, j + 12, k + 12, Blocks.stonebrick, 0);
		this.setBlock(world, i + 2, j + 12, k + 13, Blocks.stone_brick_stairs, 0);
		this.setBlock(world, i + 2, j + 12, k + 14, Blocks.stonebrick, 0);
		this.setBlock(world, i + 2, j + 12, k + 15, Blocks.stonebrick, 0);
		this.setBlock(world, i + 2, j + 12, k + 16, Blocks.stonebrick, 0);
		this.setBlock(world, i + 2, j + 12, k + 17, Blocks.stone_brick_stairs, 0);
		this.setBlock(world, i + 2, j + 12, k + 18, Blocks.stone_brick_stairs, 0);
		this.setBlock(world, i + 2, j + 12, k + 19, Blocks.stone_brick_stairs, 0);
		this.setBlock(world, i + 2, j + 12, k + 20, Blocks.stone_slab, 5);
		this.setBlock(world, i + 2, j + 12, k + 21, Blocks.air, 0);
		this.setBlock(world, i + 2, j + 12, k + 22, Blocks.air, 0);
		this.setBlock(world, i + 3, j + 0, k + 0, Blocks.stonebrick, 1);
		this.setBlock(world, i + 3, j + 0, k + 1, Blocks.stonebrick, 0);
		this.setBlock(world, i + 3, j + 0, k + 2, Blocks.planks, 5);
		this.setBlock(world, i + 3, j + 0, k + 3, Blocks.wooden_slab, 5);
		this.setBlock(world, i + 3, j + 0, k + 4, Blocks.wooden_slab, 5);
		this.setBlock(world, i + 3, j + 0, k + 5, Blocks.wooden_slab, 5);
		this.setBlock(world, i + 3, j + 0, k + 6, Blocks.wooden_slab, 5);
		this.setBlock(world, i + 3, j + 0, k + 7, Blocks.wooden_slab, 5);
		this.setBlock(world, i + 3, j + 0, k + 8, Blocks.wooden_slab, 5);
		this.setBlock(world, i + 3, j + 0, k + 9, Blocks.wooden_slab, 5);
		this.setBlock(world, i + 3, j + 0, k + 10, Blocks.planks, 5);
		this.setBlock(world, i + 3, j + 0, k + 11, Blocks.planks, 5);
		this.setBlock(world, i + 3, j + 0, k + 12, Blocks.planks, 5);
		this.setBlock(world, i + 3, j + 0, k + 13, Blocks.wooden_slab, 5);
		this.setBlock(world, i + 3, j + 0, k + 14, Blocks.wooden_slab, 5);
		this.setBlock(world, i + 3, j + 0, k + 15, Blocks.wooden_slab, 5);
		this.setBlock(world, i + 3, j + 0, k + 16, Blocks.wooden_slab, 5);
		this.setBlock(world, i + 3, j + 0, k + 17, Blocks.wooden_slab, 5);
		this.setBlock(world, i + 3, j + 0, k + 18, Blocks.wooden_slab, 5);
		this.setBlock(world, i + 3, j + 0, k + 19, Blocks.wooden_slab, 5);
		this.setBlock(world, i + 3, j + 0, k + 20, Blocks.planks, 5);
		this.setBlock(world, i + 3, j + 0, k + 21, Blocks.stonebrick, 1);
		this.setBlock(world, i + 3, j + 0, k + 22, Blocks.stonebrick, 1);
		this.setBlock(world, i + 3, j + 1, k + 0, Blocks.air, 0);
		this.setBlock(world, i + 3, j + 1, k + 1, Blocks.vine, 1);
		this.setBlock(world, i + 3, j + 1, k + 2, Blocks.mossy_cobblestone, 0);
		this.setBlock(world, i + 3, j + 1, k + 3, Blocks.air, 0);
		this.setBlock(world, i + 3, j + 1, k + 4, Blocks.air, 0);
		this.setBlock(world, i + 3, j + 1, k + 5, Blocks.air, 0);
		this.setBlock(world, i + 3, j + 1, k + 6, Blocks.air, 0);
		this.setBlock(world, i + 3, j + 1, k + 7, Blocks.air, 0);
		this.setBlock(world, i + 3, j + 1, k + 8, Blocks.air, 0);
		this.setBlock(world, i + 3, j + 1, k + 9, Blocks.air, 0);
		this.setBlock(world, i + 3, j + 1, k + 10, Blocks.air, 0);
		this.setBlock(world, i + 3, j + 1, k + 11, Blocks.air, 0);
		this.setBlock(world, i + 3, j + 1, k + 12, Blocks.air, 0);
		this.setBlock(world, i + 3, j + 1, k + 13, Blocks.air, 0);
		this.setBlock(world, i + 3, j + 1, k + 14, Blocks.air, 0);
		this.setBlock(world, i + 3, j + 1, k + 15, Blocks.air, 0);
		this.setBlock(world, i + 3, j + 1, k + 16, Blocks.air, 0);
		this.setBlock(world, i + 3, j + 1, k + 17, Blocks.air, 0);
		this.setBlock(world, i + 3, j + 1, k + 18, Blocks.air, 0);
		this.setBlock(world, i + 3, j + 1, k + 19, Blocks.air, 0);
		this.setBlock(world, i + 3, j + 1, k + 20, Blocks.cobblestone, 0);
		this.setBlock(world, i + 3, j + 1, k + 21, Blocks.leaves, 5);
		this.setBlock(world, i + 3, j + 1, k + 22, Blocks.air, 0);
		this.setBlock(world, i + 3, j + 2, k + 0, Blocks.air, 0);
		this.setBlock(world, i + 3, j + 2, k + 1, Blocks.air, 0);
		this.setBlock(world, i + 3, j + 2, k + 2, Blocks.cobblestone, 0);
		this.setBlock(world, i + 3, j + 2, k + 3, Blocks.air, 0);
		this.setBlock(world, i + 3, j + 2, k + 4, Blocks.air, 0);
		this.setBlock(world, i + 3, j + 2, k + 5, Blocks.air, 0);
		this.setBlock(world, i + 3, j + 2, k + 6, Blocks.air, 0);
		this.setBlock(world, i + 3, j + 2, k + 7, Blocks.air, 0);
		this.setBlock(world, i + 3, j + 2, k + 8, Blocks.air, 0);
		this.setBlock(world, i + 3, j + 2, k + 9, Blocks.air, 0);
		this.setBlock(world, i + 3, j + 2, k + 10, Blocks.air, 0);
		this.setBlock(world, i + 3, j + 2, k + 11, Blocks.air, 0);
		this.setBlock(world, i + 3, j + 2, k + 12, Blocks.air, 0);
		this.setBlock(world, i + 3, j + 2, k + 13, Blocks.air, 0);
		this.setBlock(world, i + 3, j + 2, k + 14, Blocks.air, 0);
		this.setBlock(world, i + 3, j + 2, k + 15, Blocks.air, 0);
		this.setBlock(world, i + 3, j + 2, k + 16, Blocks.air, 0);
		this.setBlock(world, i + 3, j + 2, k + 17, Blocks.air, 0);
		this.setBlock(world, i + 3, j + 2, k + 18, Blocks.air, 0);
		this.setBlock(world, i + 3, j + 2, k + 19, Blocks.air, 0);
		this.setBlock(world, i + 3, j + 2, k + 20, Blocks.mossy_cobblestone, 0);
		this.setBlock(world, i + 3, j + 2, k + 21, Blocks.air, 0);
		this.setBlock(world, i + 3, j + 2, k + 22, Blocks.air, 0);
		this.setBlock(world, i + 3, j + 3, k + 0, Blocks.air, 0);
		this.setBlock(world, i + 3, j + 3, k + 1, Blocks.air, 0);
		this.setBlock(world, i + 3, j + 3, k + 2, Blocks.cobblestone, 0);
		this.setBlock(world, i + 3, j + 3, k + 3, Blocks.air, 0);
		this.setBlock(world, i + 3, j + 3, k + 4, Blocks.air, 0);
		this.setBlock(world, i + 3, j + 3, k + 5, Blocks.air, 0);
		this.setBlock(world, i + 3, j + 3, k + 6, Blocks.air, 0);
		this.setBlock(world, i + 3, j + 3, k + 7, Blocks.air, 0);
		this.setBlock(world, i + 3, j + 3, k + 8, Blocks.air, 0);
		this.setBlock(world, i + 3, j + 3, k + 9, Blocks.air, 0);
		this.setBlock(world, i + 3, j + 3, k + 10, Blocks.air, 0);
		this.setBlock(world, i + 3, j + 3, k + 11, Blocks.air, 0);
		this.setBlock(world, i + 3, j + 3, k + 12, Blocks.air, 0);
		this.setBlock(world, i + 3, j + 3, k + 13, Blocks.air, 0);
		this.setBlock(world, i + 3, j + 3, k + 14, Blocks.air, 0);
		this.setBlock(world, i + 3, j + 3, k + 15, Blocks.air, 0);
		this.setBlock(world, i + 3, j + 3, k + 16, Blocks.air, 0);
		this.setBlock(world, i + 3, j + 3, k + 17, Blocks.air, 0);
		this.setBlock(world, i + 3, j + 3, k + 18, Blocks.air, 0);
		this.setBlock(world, i + 3, j + 3, k + 19, Blocks.air, 0);
		this.setBlock(world, i + 3, j + 3, k + 20, Blocks.cobblestone, 0);
		this.setBlock(world, i + 3, j + 3, k + 21, Blocks.air, 0);
		this.setBlock(world, i + 3, j + 3, k + 22, Blocks.air, 0);
		this.setBlock(world, i + 3, j + 4, k + 0, Blocks.air, 0);
		this.setBlock(world, i + 3, j + 4, k + 1, Blocks.air, 0);
		this.setBlock(world, i + 3, j + 4, k + 2, Blocks.cobblestone, 0);
		this.setBlock(world, i + 3, j + 4, k + 3, Blocks.planks, 0);
		this.setBlock(world, i + 3, j + 4, k + 4, Blocks.planks, 0);
		this.setBlock(world, i + 3, j + 4, k + 5, Blocks.planks, 0);
		this.setBlock(world, i + 3, j + 4, k + 6, Blocks.planks, 0);
		this.setBlock(world, i + 3, j + 4, k + 7, Blocks.planks, 0);
		this.setBlock(world, i + 3, j + 4, k + 8, Blocks.planks, 0);
		this.setBlock(world, i + 3, j + 4, k + 9, Blocks.planks, 0);
		this.setBlock(world, i + 3, j + 4, k + 10, Blocks.oak_stairs, 7);
		this.setBlock(world, i + 3, j + 4, k + 11, Blocks.air, 0);
		this.setBlock(world, i + 3, j + 4, k + 12, Blocks.oak_stairs, 6);
		this.setBlock(world, i + 3, j + 4, k + 13, Blocks.planks, 0);
		this.setBlock(world, i + 3, j + 4, k + 14, Blocks.planks, 0);
		this.setBlock(world, i + 3, j + 4, k + 15, Blocks.planks, 0);
		this.setBlock(world, i + 3, j + 4, k + 16, Blocks.planks, 0);
		this.setBlock(world, i + 3, j + 4, k + 17, Blocks.planks, 0);
		this.setBlock(world, i + 3, j + 4, k + 18, Blocks.planks, 0);
		this.setBlock(world, i + 3, j + 4, k + 19, Blocks.planks, 0);
		this.setBlock(world, i + 3, j + 4, k + 20, Blocks.cobblestone, 0);
		this.setBlock(world, i + 3, j + 4, k + 21, Blocks.air, 0);
		this.setBlock(world, i + 3, j + 4, k + 22, Blocks.air, 0);
		this.setBlock(world, i + 3, j + 5, k + 0, Blocks.air, 0);
		this.setBlock(world, i + 3, j + 5, k + 1, Blocks.stonebrick, 1);
		this.setBlock(world, i + 3, j + 5, k + 2, Blocks.planks, 5);
		this.setBlock(world, i + 3, j + 5, k + 3, Blocks.planks, 0);
		this.setBlock(world, i + 3, j + 5, k + 4, Blocks.planks, 0);
		this.setBlock(world, i + 3, j + 5, k + 5, Blocks.planks, 0);
		this.setBlock(world, i + 3, j + 5, k + 6, Blocks.planks, 0);
		this.setBlock(world, i + 3, j + 5, k + 7, Blocks.planks, 0);
		this.setBlock(world, i + 3, j + 5, k + 8, Blocks.planks, 0);
		this.setBlock(world, i + 3, j + 5, k + 9, Blocks.planks, 0);
		this.setBlock(world, i + 3, j + 5, k + 10, Blocks.planks, 0);
		this.setBlock(world, i + 3, j + 5, k + 11, Blocks.glowstone, 0);
		this.setBlock(world, i + 3, j + 5, k + 12, Blocks.planks, 0);
		this.setBlock(world, i + 3, j + 5, k + 13, Blocks.planks, 0);
		this.setBlock(world, i + 3, j + 5, k + 14, Blocks.planks, 0);
		this.setBlock(world, i + 3, j + 5, k + 15, Blocks.planks, 0);
		this.setBlock(world, i + 3, j + 5, k + 16, Blocks.planks, 0);
		this.setBlock(world, i + 3, j + 5, k + 17, Blocks.planks, 0);
		this.setBlock(world, i + 3, j + 5, k + 18, Blocks.planks, 0);
		this.setBlock(world, i + 3, j + 5, k + 19, Blocks.planks, 0);
		this.setBlock(world, i + 3, j + 5, k + 20, Blocks.planks, 5);
		this.setBlock(world, i + 3, j + 5, k + 21, Blocks.stonebrick, 1);
		this.setBlock(world, i + 3, j + 5, k + 22, Blocks.air, 0);
		this.setBlock(world, i + 3, j + 6, k + 0, Blocks.stone_brick_stairs, 6);
		this.setBlock(world, i + 3, j + 6, k + 1, Blocks.planks, 5);
		this.setBlock(world, i + 3, j + 6, k + 2, Blocks.planks, 5);
		this.setBlock(world, i + 3, j + 6, k + 3, Blocks.planks, 5);
		this.setBlock(world, i + 3, j + 6, k + 4, Blocks.planks, 5);
		this.setBlock(world, i + 3, j + 6, k + 5, Blocks.planks, 5);
		this.setBlock(world, i + 3, j + 6, k + 6, Blocks.planks, 5);
		this.setBlock(world, i + 3, j + 6, k + 7, Blocks.planks, 5);
		this.setBlock(world, i + 3, j + 6, k + 8, Blocks.planks, 5);
		this.setBlock(world, i + 3, j + 6, k + 9, Blocks.planks, 5);
		this.setBlock(world, i + 3, j + 6, k + 10, Blocks.planks, 5);
		this.setBlock(world, i + 3, j + 6, k + 11, Blocks.planks, 5);
		this.setBlock(world, i + 3, j + 6, k + 12, Blocks.planks, 5);
		this.setBlock(world, i + 3, j + 6, k + 13, Blocks.planks, 5);
		this.setBlock(world, i + 3, j + 6, k + 14, Blocks.planks, 5);
		this.setBlock(world, i + 3, j + 6, k + 15, Blocks.planks, 5);
		this.setBlock(world, i + 3, j + 6, k + 16, Blocks.planks, 5);
		this.setBlock(world, i + 3, j + 6, k + 17, Blocks.planks, 5);
		this.setBlock(world, i + 3, j + 6, k + 18, Blocks.planks, 5);
		this.setBlock(world, i + 3, j + 6, k + 19, Blocks.planks, 5);
		this.setBlock(world, i + 3, j + 6, k + 20, Blocks.planks, 5);
		this.setBlock(world, i + 3, j + 6, k + 21, Blocks.planks, 5);
		this.setBlock(world, i + 3, j + 6, k + 22, Blocks.stone_brick_stairs, 7);
		this.setBlock(world, i + 3, j + 7, k + 0, Blocks.cobblestone_wall, 0);
		this.setBlock(world, i + 3, j + 7, k + 3, Blocks.air, 0);
		this.setBlock(world, i + 3, j + 7, k + 4, Blocks.air, 0);
		this.setBlock(world, i + 3, j + 7, k + 5, Blocks.air, 0);
		this.setBlock(world, i + 3, j + 7, k + 6, Blocks.air, 0);
		this.setBlock(world, i + 3, j + 7, k + 7, Blocks.chest, 5);
		this.setBlock(world, i + 3, j + 7, k + 8, Blocks.air, 0);
		this.setBlock(world, i + 3, j + 7, k + 9, Blocks.air, 0);
		this.setBlock(world, i + 3, j + 7, k + 10, Blocks.air, 0);
		this.setBlock(world, i + 3, j + 7, k + 11, Blocks.chest, 5);
		this.setBlock(world, i + 3, j + 7, k + 12, Blocks.air, 0);
		this.setBlock(world, i + 3, j + 7, k + 13, Blocks.air, 0);
		this.setBlock(world, i + 3, j + 7, k + 14, Blocks.air, 0);
		this.setBlock(world, i + 3, j + 7, k + 15, Blocks.chest, 5);
		this.setBlock(world, i + 3, j + 7, k + 16, Blocks.air, 0);
		this.setBlock(world, i + 3, j + 7, k + 17, Blocks.air, 0);
		this.setBlock(world, i + 3, j + 7, k + 18, Blocks.air, 0);
		this.setBlock(world, i + 3, j + 7, k + 19, Blocks.air, 0);
		this.setBlock(world, i + 3, j + 7, k + 22, Blocks.cobblestone_wall, 0);
		this.setBlock(world, i + 3, j + 8, k + 0, Blocks.air, 0);
		this.setBlock(world, i + 3, j + 8, k + 1, Blocks.air, 0);
		this.setBlock(world, i + 3, j + 8, k + 2, Blocks.air, 0);
		this.setBlock(world, i + 3, j + 8, k + 3, Blocks.air, 0);
		this.setBlock(world, i + 3, j + 8, k + 4, Blocks.air, 0);
		this.setBlock(world, i + 3, j + 8, k + 5, Blocks.air, 0);
		this.setBlock(world, i + 3, j + 8, k + 6, Blocks.air, 0);
		this.setBlock(world, i + 3, j + 8, k + 7, Blocks.air, 0);
		this.setBlock(world, i + 3, j + 8, k + 8, Blocks.air, 0);
		this.setBlock(world, i + 3, j + 8, k + 9, Blocks.air, 0);
		this.setBlock(world, i + 3, j + 8, k + 10, Blocks.air, 0);
		this.setBlock(world, i + 3, j + 8, k + 11, Blocks.air, 0);
		this.setBlock(world, i + 3, j + 8, k + 12, Blocks.air, 0);
		this.setBlock(world, i + 3, j + 8, k + 13, Blocks.air, 0);
		this.setBlock(world, i + 3, j + 8, k + 14, Blocks.air, 0);
		this.setBlock(world, i + 3, j + 8, k + 15, Blocks.air, 0);
		this.setBlock(world, i + 3, j + 8, k + 16, Blocks.air, 0);
		this.setBlock(world, i + 3, j + 8, k + 17, Blocks.air, 0);
		this.setBlock(world, i + 3, j + 8, k + 18, Blocks.air, 0);
		this.setBlock(world, i + 3, j + 8, k + 19, Blocks.air, 0);
		this.setBlock(world, i + 3, j + 8, k + 20, Blocks.air, 0);
		this.setBlock(world, i + 3, j + 8, k + 21, Blocks.air, 0);
		this.setBlock(world, i + 3, j + 8, k + 22, Blocks.air, 0);
		this.setBlock(world, i + 3, j + 9, k + 0, Blocks.air, 0);
		this.setBlock(world, i + 3, j + 9, k + 1, Blocks.air, 0);
		this.setBlock(world, i + 3, j + 9, k + 2, Blocks.air, 0);
		this.setBlock(world, i + 3, j + 9, k + 3, Blocks.air, 0);
		this.setBlock(world, i + 3, j + 9, k + 4, Blocks.air, 0);
		this.setBlock(world, i + 3, j + 9, k + 5, Blocks.air, 0);
		this.setBlock(world, i + 3, j + 9, k + 6, Blocks.air, 0);
		this.setBlock(world, i + 3, j + 9, k + 7, Blocks.air, 0);
		this.setBlock(world, i + 3, j + 9, k + 8, Blocks.air, 0);
		this.setBlock(world, i + 3, j + 9, k + 9, Blocks.air, 0);
		this.setBlock(world, i + 3, j + 9, k + 10, Blocks.air, 0);
		this.setBlock(world, i + 3, j + 9, k + 11, Blocks.air, 0);
		this.setBlock(world, i + 3, j + 9, k + 12, Blocks.air, 0);
		this.setBlock(world, i + 3, j + 9, k + 13, Blocks.air, 0);
		this.setBlock(world, i + 3, j + 9, k + 14, Blocks.air, 0);
		this.setBlock(world, i + 3, j + 9, k + 15, Blocks.air, 0);
		this.setBlock(world, i + 3, j + 9, k + 16, Blocks.air, 0);
		this.setBlock(world, i + 3, j + 9, k + 17, Blocks.air, 0);
		this.setBlock(world, i + 3, j + 9, k + 18, Blocks.air, 0);
		this.setBlock(world, i + 3, j + 9, k + 19, Blocks.air, 0);
		this.setBlock(world, i + 3, j + 9, k + 20, Blocks.air, 0);
		this.setBlock(world, i + 3, j + 9, k + 21, Blocks.air, 0);
		this.setBlock(world, i + 3, j + 9, k + 22, Blocks.air, 0);
		this.setBlock(world, i + 3, j + 10, k + 0, Blocks.stone_brick_stairs, 2);
		this.setBlock(world, i + 3, j + 10, k + 1, Blocks.air, 0);
		this.setBlock(world, i + 3, j + 10, k + 2, Blocks.air, 0);
		this.setBlock(world, i + 3, j + 10, k + 3, Blocks.air, 0);
		this.setBlock(world, i + 3, j + 10, k + 4, Blocks.air, 0);
		this.setBlock(world, i + 3, j + 10, k + 5, Blocks.air, 0);
		this.setBlock(world, i + 3, j + 10, k + 6, Blocks.air, 0);
		this.setBlock(world, i + 3, j + 10, k + 7, Blocks.air, 0);
		this.setBlock(world, i + 3, j + 10, k + 8, Blocks.air, 0);
		this.setBlock(world, i + 3, j + 10, k + 9, Blocks.air, 0);
		this.setBlock(world, i + 3, j + 10, k + 10, Blocks.air, 0);
		this.setBlock(world, i + 3, j + 10, k + 11, Blocks.air, 0);
		this.setBlock(world, i + 3, j + 10, k + 12, Blocks.air, 0);
		this.setBlock(world, i + 3, j + 10, k + 13, Blocks.air, 0);
		this.setBlock(world, i + 3, j + 10, k + 14, Blocks.air, 0);
		this.setBlock(world, i + 3, j + 10, k + 15, Blocks.air, 0);
		this.setBlock(world, i + 3, j + 10, k + 16, Blocks.air, 0);
		this.setBlock(world, i + 3, j + 10, k + 17, Blocks.air, 0);
		this.setBlock(world, i + 3, j + 10, k + 18, Blocks.air, 0);
		this.setBlock(world, i + 3, j + 10, k + 19, Blocks.air, 0);
		this.setBlock(world, i + 3, j + 10, k + 20, Blocks.air, 0);
		this.setBlock(world, i + 3, j + 10, k + 21, Blocks.air, 0);
		this.setBlock(world, i + 3, j + 10, k + 22, Blocks.stone_brick_stairs, 3);
		this.setBlock(world, i + 3, j + 11, k + 0, Blocks.air, 0);
		this.setBlock(world, i + 3, j + 11, k + 1, Blocks.stone_brick_stairs, 2);
		this.setBlock(world, i + 3, j + 11, k + 2, Blocks.stone_brick_stairs, 5);
		this.setBlock(world, i + 3, j + 11, k + 3, Blocks.stone_brick_stairs, 5);
		this.setBlock(world, i + 3, j + 11, k + 4, Blocks.air, 0);
		this.setBlock(world, i + 3, j + 11, k + 5, Blocks.air, 0);
		this.setBlock(world, i + 3, j + 11, k + 6, Blocks.air, 0);
		this.setBlock(world, i + 3, j + 11, k + 7, Blocks.air, 0);
		this.setBlock(world, i + 3, j + 11, k + 8, Blocks.air, 0);
		this.setBlock(world, i + 3, j + 11, k + 9, Blocks.air, 0);
		this.setBlock(world, i + 3, j + 11, k + 10, Blocks.air, 0);
		this.setBlock(world, i + 3, j + 11, k + 11, Blocks.air, 0);
		this.setBlock(world, i + 3, j + 11, k + 12, Blocks.air, 0);
		this.setBlock(world, i + 3, j + 11, k + 13, Blocks.air, 0);
		this.setBlock(world, i + 3, j + 11, k + 14, Blocks.air, 0);
		this.setBlock(world, i + 3, j + 11, k + 15, Blocks.air, 0);
		this.setBlock(world, i + 3, j + 11, k + 16, Blocks.air, 0);
		this.setBlock(world, i + 3, j + 11, k + 17, Blocks.air, 0);
		this.setBlock(world, i + 3, j + 11, k + 18, Blocks.air, 0);
		this.setBlock(world, i + 3, j + 11, k + 19, Blocks.stone_brick_stairs, 6);
		this.setBlock(world, i + 3, j + 11, k + 20, Blocks.stone_brick_stairs, 5);
		this.setBlock(world, i + 3, j + 11, k + 21, Blocks.stone_brick_stairs, 3);
		this.setBlock(world, i + 3, j + 11, k + 22, Blocks.air, 0);
		this.setBlock(world, i + 3, j + 12, k + 0, Blocks.air, 0);
		this.setBlock(world, i + 3, j + 12, k + 1, Blocks.air, 0);
		this.setBlock(world, i + 3, j + 12, k + 2, Blocks.stone_brick_stairs, 2);
		this.setBlock(world, i + 3, j + 12, k + 3, Blocks.stonebrick, 0);
		this.setBlock(world, i + 3, j + 12, k + 4, Blocks.stonebrick, 0);
		this.setBlock(world, i + 3, j + 12, k + 5, Blocks.stonebrick, 0);
		this.setBlock(world, i + 3, j + 12, k + 6, Blocks.stonebrick, 0);
		this.setBlock(world, i + 3, j + 12, k + 7, Blocks.stonebrick, 0);
		this.setBlock(world, i + 3, j + 12, k + 8, Blocks.stonebrick, 0);
		this.setBlock(world, i + 3, j + 12, k + 9, Blocks.stonebrick, 0);
		this.setBlock(world, i + 3, j + 12, k + 10, Blocks.stonebrick, 0);
		this.setBlock(world, i + 3, j + 12, k + 11, Blocks.stonebrick, 0);
		this.setBlock(world, i + 3, j + 12, k + 12, Blocks.stonebrick, 0);
		this.setBlock(world, i + 3, j + 12, k + 13, Blocks.stonebrick, 0);
		this.setBlock(world, i + 3, j + 12, k + 14, Blocks.stonebrick, 0);
		this.setBlock(world, i + 3, j + 12, k + 15, Blocks.stonebrick, 0);
		this.setBlock(world, i + 3, j + 12, k + 16, Blocks.stonebrick, 0);
		this.setBlock(world, i + 3, j + 12, k + 17, Blocks.stonebrick, 0);
		this.setBlock(world, i + 3, j + 12, k + 18, Blocks.stonebrick, 0);
		this.setBlock(world, i + 3, j + 12, k + 19, Blocks.stonebrick, 0);
		this.setBlock(world, i + 3, j + 12, k + 20, Blocks.stone_brick_stairs, 3);
		this.setBlock(world, i + 3, j + 12, k + 21, Blocks.air, 0);
		this.setBlock(world, i + 3, j + 12, k + 22, Blocks.air, 0);
		this.setBlock(world, i + 4, j + 0, k + 0, Blocks.stonebrick, 0);
		this.setBlock(world, i + 4, j + 0, k + 1, Blocks.stonebrick, 0);
		this.setBlock(world, i + 4, j + 0, k + 2, Blocks.planks, 5);
		this.setBlock(world, i + 4, j + 0, k + 3, Blocks.wooden_slab, 5);
		this.setBlock(world, i + 4, j + 0, k + 4, Blocks.wooden_slab, 5);
		this.setBlock(world, i + 4, j + 0, k + 5, Blocks.wooden_slab, 5);
		this.setBlock(world, i + 4, j + 0, k + 6, Blocks.wooden_slab, 5);
		this.setBlock(world, i + 4, j + 0, k + 7, Blocks.wooden_slab, 5);
		this.setBlock(world, i + 4, j + 0, k + 8, Blocks.wooden_slab, 5);
		this.setBlock(world, i + 4, j + 0, k + 9, Blocks.wooden_slab, 5);
		this.setBlock(world, i + 4, j + 0, k + 10, Blocks.planks, 5);
		this.setBlock(world, i + 4, j + 0, k + 11, Blocks.planks, 5);
		this.setBlock(world, i + 4, j + 0, k + 12, Blocks.planks, 5);
		this.setBlock(world, i + 4, j + 0, k + 13, Blocks.wooden_slab, 5);
		this.setBlock(world, i + 4, j + 0, k + 14, Blocks.wooden_slab, 5);
		this.setBlock(world, i + 4, j + 0, k + 15, Blocks.wooden_slab, 5);
		this.setBlock(world, i + 4, j + 0, k + 16, Blocks.wooden_slab, 5);
		this.setBlock(world, i + 4, j + 0, k + 17, Blocks.wooden_slab, 5);
		this.setBlock(world, i + 4, j + 0, k + 18, Blocks.wooden_slab, 5);
		this.setBlock(world, i + 4, j + 0, k + 19, Blocks.wooden_slab, 5);
		this.setBlock(world, i + 4, j + 0, k + 20, Blocks.planks, 5);
		this.setBlock(world, i + 4, j + 0, k + 21, Blocks.stonebrick, 0);
		this.setBlock(world, i + 4, j + 0, k + 22, Blocks.stonebrick, 0);
		this.setBlock(world, i + 4, j + 1, k + 0, Blocks.air, 0);
		this.setBlock(world, i + 4, j + 1, k + 1, Blocks.air, 0);
		this.setBlock(world, i + 4, j + 1, k + 2, Blocks.mossy_cobblestone, 0);
		this.setBlock(world, i + 4, j + 1, k + 3, Blocks.air, 0);
		this.setBlock(world, i + 4, j + 1, k + 4, Blocks.air, 0);
		this.setBlock(world, i + 4, j + 1, k + 5, Blocks.air, 0);
		this.setBlock(world, i + 4, j + 1, k + 6, Blocks.air, 0);
		this.setBlock(world, i + 4, j + 1, k + 7, Blocks.air, 0);
		this.setBlock(world, i + 4, j + 1, k + 8, Blocks.air, 0);
		this.setBlock(world, i + 4, j + 1, k + 9, Blocks.air, 0);
		this.setBlock(world, i + 4, j + 1, k + 10, Blocks.air, 0);
		this.setBlock(world, i + 4, j + 1, k + 11, Blocks.air, 0);
		this.setBlock(world, i + 4, j + 1, k + 12, Blocks.air, 0);
		this.setBlock(world, i + 4, j + 1, k + 13, Blocks.air, 0);
		this.setBlock(world, i + 4, j + 1, k + 14, Blocks.air, 0);
		this.setBlock(world, i + 4, j + 1, k + 15, Blocks.air, 0);
		this.setBlock(world, i + 4, j + 1, k + 16, Blocks.air, 0);
		this.setBlock(world, i + 4, j + 1, k + 17, Blocks.air, 0);
		this.setBlock(world, i + 4, j + 1, k + 18, Blocks.air, 0);
		this.setBlock(world, i + 4, j + 1, k + 19, Blocks.air, 0);
		this.setBlock(world, i + 4, j + 1, k + 20, Blocks.cobblestone, 0);
		this.setBlock(world, i + 4, j + 1, k + 21, Blocks.leaves, 5);
		this.setBlock(world, i + 4, j + 1, k + 22, Blocks.air, 0);
		this.setBlock(world, i + 4, j + 2, k + 0, Blocks.air, 0);
		this.setBlock(world, i + 4, j + 2, k + 1, Blocks.air, 0);
		this.setBlock(world, i + 4, j + 2, k + 2, Blocks.cobblestone, 0);
		this.setBlock(world, i + 4, j + 2, k + 3, Blocks.air, 0);
		this.setBlock(world, i + 4, j + 2, k + 4, Blocks.air, 0);
		this.setBlock(world, i + 4, j + 2, k + 5, Blocks.air, 0);
		this.setBlock(world, i + 4, j + 2, k + 6, Blocks.air, 0);
		this.setBlock(world, i + 4, j + 2, k + 7, Blocks.air, 0);
		this.setBlock(world, i + 4, j + 2, k + 8, Blocks.air, 0);
		this.setBlock(world, i + 4, j + 2, k + 9, Blocks.air, 0);
		this.setBlock(world, i + 4, j + 2, k + 10, Blocks.air, 0);
		this.setBlock(world, i + 4, j + 2, k + 11, Blocks.air, 0);
		this.setBlock(world, i + 4, j + 2, k + 12, Blocks.air, 0);
		this.setBlock(world, i + 4, j + 2, k + 13, Blocks.air, 0);
		this.setBlock(world, i + 4, j + 2, k + 14, Blocks.air, 0);
		this.setBlock(world, i + 4, j + 2, k + 15, Blocks.air, 0);
		this.setBlock(world, i + 4, j + 2, k + 16, Blocks.air, 0);
		this.setBlock(world, i + 4, j + 2, k + 17, Blocks.air, 0);
		this.setBlock(world, i + 4, j + 2, k + 18, Blocks.air, 0);
		this.setBlock(world, i + 4, j + 2, k + 19, Blocks.air, 0);
		this.setBlock(world, i + 4, j + 2, k + 20, Blocks.cobblestone, 0);
		this.setBlock(world, i + 4, j + 2, k + 21, Blocks.leaves, 5);
		this.setBlock(world, i + 4, j + 2, k + 22, Blocks.air, 0);
		this.setBlock(world, i + 4, j + 3, k + 0, Blocks.air, 0);
		this.setBlock(world, i + 4, j + 3, k + 1, Blocks.air, 0);
		this.setBlock(world, i + 4, j + 3, k + 2, Blocks.mossy_cobblestone, 0);
		this.setBlock(world, i + 4, j + 3, k + 3, Blocks.air, 0);
		this.setBlock(world, i + 4, j + 3, k + 4, Blocks.air, 0);
		this.setBlock(world, i + 4, j + 3, k + 5, Blocks.air, 0);
		this.setBlock(world, i + 4, j + 3, k + 6, Blocks.air, 0);
		this.setBlock(world, i + 4, j + 3, k + 7, Blocks.air, 0);
		this.setBlock(world, i + 4, j + 3, k + 8, Blocks.air, 0);
		this.setBlock(world, i + 4, j + 3, k + 9, Blocks.air, 0);
		this.setBlock(world, i + 4, j + 3, k + 10, Blocks.air, 0);
		this.setBlock(world, i + 4, j + 3, k + 11, Blocks.air, 0);
		this.setBlock(world, i + 4, j + 3, k + 12, Blocks.air, 0);
		this.setBlock(world, i + 4, j + 3, k + 13, Blocks.air, 0);
		this.setBlock(world, i + 4, j + 3, k + 14, Blocks.air, 0);
		this.setBlock(world, i + 4, j + 3, k + 15, Blocks.air, 0);
		this.setBlock(world, i + 4, j + 3, k + 16, Blocks.air, 0);
		this.setBlock(world, i + 4, j + 3, k + 17, Blocks.air, 0);
		this.setBlock(world, i + 4, j + 3, k + 18, Blocks.air, 0);
		this.setBlock(world, i + 4, j + 3, k + 19, Blocks.air, 0);
		this.setBlock(world, i + 4, j + 3, k + 20, Blocks.mossy_cobblestone, 0);
		this.setBlock(world, i + 4, j + 3, k + 21, Blocks.air, 0);
		this.setBlock(world, i + 4, j + 3, k + 22, Blocks.air, 0);
		this.setBlock(world, i + 4, j + 4, k + 0, Blocks.air, 0);
		this.setBlock(world, i + 4, j + 4, k + 1, Blocks.stone_brick_stairs, 4);
		this.setBlock(world, i + 4, j + 4, k + 2, Blocks.cobblestone, 0);
		this.setBlock(world, i + 4, j + 4, k + 3, Blocks.planks, 0);
		this.setBlock(world, i + 4, j + 4, k + 4, Blocks.air, 0);
		this.setBlock(world, i + 4, j + 4, k + 5, Blocks.air, 0);
		this.setBlock(world, i + 4, j + 4, k + 6, Blocks.air, 0);
		this.setBlock(world, i + 4, j + 4, k + 7, Blocks.air, 0);
		this.setBlock(world, i + 4, j + 4, k + 8, Blocks.air, 0);
		this.setBlock(world, i + 4, j + 4, k + 9, Blocks.air, 0);
		this.setBlock(world, i + 4, j + 4, k + 10, Blocks.air, 0);
		this.setBlock(world, i + 4, j + 4, k + 11, Blocks.air, 0);
		this.setBlock(world, i + 4, j + 4, k + 12, Blocks.air, 0);
		this.setBlock(world, i + 4, j + 4, k + 13, Blocks.air, 0);
		this.setBlock(world, i + 4, j + 4, k + 14, Blocks.air, 0);
		this.setBlock(world, i + 4, j + 4, k + 15, Blocks.air, 0);
		this.setBlock(world, i + 4, j + 4, k + 16, Blocks.air, 0);
		this.setBlock(world, i + 4, j + 4, k + 17, Blocks.air, 0);
		this.setBlock(world, i + 4, j + 4, k + 18, Blocks.air, 0);
		this.setBlock(world, i + 4, j + 4, k + 19, Blocks.planks, 0);
		this.setBlock(world, i + 4, j + 4, k + 20, Blocks.mossy_cobblestone, 0);
		this.setBlock(world, i + 4, j + 4, k + 21, Blocks.stone_brick_stairs, 4);
		this.setBlock(world, i + 4, j + 4, k + 22, Blocks.air, 0);
		this.setBlock(world, i + 4, j + 5, k + 0, Blocks.air, 0);
		this.setBlock(world, i + 4, j + 5, k + 1, Blocks.stonebrick, 1);
		this.setBlock(world, i + 4, j + 5, k + 2, Blocks.planks, 5);
		this.setBlock(world, i + 4, j + 5, k + 3, Blocks.planks, 0);
		this.setBlock(world, i + 4, j + 5, k + 4, Blocks.planks, 0);
		this.setBlock(world, i + 4, j + 5, k + 5, Blocks.planks, 0);
		this.setBlock(world, i + 4, j + 5, k + 6, Blocks.planks, 0);
		this.setBlock(world, i + 4, j + 5, k + 7, Blocks.planks, 0);
		this.setBlock(world, i + 4, j + 5, k + 8, Blocks.planks, 0);
		this.setBlock(world, i + 4, j + 5, k + 9, Blocks.planks, 0);
		this.setBlock(world, i + 4, j + 5, k + 10, Blocks.planks, 0);
		this.setBlock(world, i + 4, j + 5, k + 11, Blocks.planks, 0);
		this.setBlock(world, i + 4, j + 5, k + 12, Blocks.planks, 0);
		this.setBlock(world, i + 4, j + 5, k + 13, Blocks.planks, 0);
		this.setBlock(world, i + 4, j + 5, k + 14, Blocks.planks, 0);
		this.setBlock(world, i + 4, j + 5, k + 15, Blocks.planks, 0);
		this.setBlock(world, i + 4, j + 5, k + 16, Blocks.planks, 0);
		this.setBlock(world, i + 4, j + 5, k + 17, Blocks.planks, 0);
		this.setBlock(world, i + 4, j + 5, k + 18, Blocks.planks, 0);
		this.setBlock(world, i + 4, j + 5, k + 19, Blocks.planks, 0);
		this.setBlock(world, i + 4, j + 5, k + 20, Blocks.planks, 5);
		this.setBlock(world, i + 4, j + 5, k + 21, Blocks.stonebrick, 0);
		this.setBlock(world, i + 4, j + 5, k + 22, Blocks.air, 0);
		this.setBlock(world, i + 4, j + 6, k + 0, Blocks.stone_brick_stairs, 6);
		this.setBlock(world, i + 4, j + 6, k + 1, Blocks.planks, 5);
		this.setBlock(world, i + 4, j + 6, k + 2, Blocks.planks, 5);
		this.setBlock(world, i + 4, j + 6, k + 3, Blocks.planks, 5);
		this.setBlock(world, i + 4, j + 6, k + 4, Blocks.planks, 5);
		this.setBlock(world, i + 4, j + 6, k + 5, Blocks.planks, 5);
		this.setBlock(world, i + 4, j + 6, k + 6, Blocks.planks, 5);
		this.setBlock(world, i + 4, j + 6, k + 7, Blocks.planks, 5);
		this.setBlock(world, i + 4, j + 6, k + 8, Blocks.planks, 5);
		this.setBlock(world, i + 4, j + 6, k + 9, Blocks.planks, 5);
		this.setBlock(world, i + 4, j + 6, k + 10, Blocks.planks, 5);
		this.setBlock(world, i + 4, j + 6, k + 11, Blocks.planks, 5);
		this.setBlock(world, i + 4, j + 6, k + 12, Blocks.planks, 5);
		this.setBlock(world, i + 4, j + 6, k + 13, Blocks.planks, 5);
		this.setBlock(world, i + 4, j + 6, k + 14, Blocks.planks, 5);
		this.setBlock(world, i + 4, j + 6, k + 15, Blocks.planks, 5);
		this.setBlock(world, i + 4, j + 6, k + 16, Blocks.planks, 5);
		this.setBlock(world, i + 4, j + 6, k + 17, Blocks.planks, 5);
		this.setBlock(world, i + 4, j + 6, k + 18, Blocks.planks, 5);
		this.setBlock(world, i + 4, j + 6, k + 19, Blocks.planks, 5);
		this.setBlock(world, i + 4, j + 6, k + 20, Blocks.planks, 5);
		this.setBlock(world, i + 4, j + 6, k + 21, Blocks.planks, 5);
		this.setBlock(world, i + 4, j + 6, k + 22, Blocks.stone_brick_stairs, 7);
		this.setBlock(world, i + 4, j + 7, k + 0, Blocks.cobblestone_wall, 0);
		this.setBlock(world, i + 4, j + 7, k + 1, Blocks.wooden_slab, 9);
		this.setBlock(world, i + 4, j + 7, k + 2, Blocks.air, 0);
		this.setBlock(world, i + 4, j + 7, k + 3, Blocks.air, 0);
		this.setBlock(world, i + 4, j + 7, k + 4, Blocks.air, 0);
		this.setBlock(world, i + 4, j + 7, k + 5, Blocks.air, 0);
		this.setBlock(world, i + 4, j + 7, k + 6, Blocks.air, 0);
		this.setBlock(world, i + 4, j + 7, k + 7, Blocks.air, 0);
		this.setBlock(world, i + 4, j + 7, k + 8, Blocks.air, 0);
		this.setBlock(world, i + 4, j + 7, k + 9, Blocks.air, 0);
		this.setBlock(world, i + 4, j + 7, k + 10, Blocks.air, 0);
		this.setBlock(world, i + 4, j + 7, k + 11, Blocks.air, 0);
		this.setBlock(world, i + 4, j + 7, k + 12, Blocks.air, 0);
		this.setBlock(world, i + 4, j + 7, k + 13, Blocks.air, 0);
		this.setBlock(world, i + 4, j + 7, k + 14, Blocks.air, 0);
		this.setBlock(world, i + 4, j + 7, k + 15, Blocks.air, 0);
		this.setBlock(world, i + 4, j + 7, k + 16, Blocks.air, 0);
		this.setBlock(world, i + 4, j + 7, k + 17, Blocks.air, 0);
		this.setBlock(world, i + 4, j + 7, k + 18, Blocks.air, 0);
		this.setBlock(world, i + 4, j + 7, k + 19, Blocks.air, 0);
		this.setBlock(world, i + 4, j + 7, k + 20, Blocks.air, 0);
		this.setBlock(world, i + 4, j + 7, k + 21, Blocks.wooden_slab, 9);
		this.setBlock(world, i + 4, j + 7, k + 22, Blocks.cobblestone_wall, 0);
		this.setBlock(world, i + 4, j + 8, k + 0, Blocks.air, 0);
		this.setBlock(world, i + 4, j + 8, k + 1, Blocks.air, 0);
		this.setBlock(world, i + 4, j + 8, k + 2, Blocks.air, 0);
		this.setBlock(world, i + 4, j + 8, k + 3, Blocks.air, 0);
		this.setBlock(world, i + 4, j + 8, k + 4, Blocks.air, 0);
		this.setBlock(world, i + 4, j + 8, k + 5, Blocks.air, 0);
		this.setBlock(world, i + 4, j + 8, k + 6, Blocks.air, 0);
		this.setBlock(world, i + 4, j + 8, k + 7, Blocks.air, 0);
		this.setBlock(world, i + 4, j + 8, k + 8, Blocks.air, 0);
		this.setBlock(world, i + 4, j + 8, k + 9, Blocks.air, 0);
		this.setBlock(world, i + 4, j + 8, k + 10, Blocks.air, 0);
		this.setBlock(world, i + 4, j + 8, k + 11, Blocks.air, 0);
		this.setBlock(world, i + 4, j + 8, k + 12, Blocks.air, 0);
		this.setBlock(world, i + 4, j + 8, k + 13, Blocks.air, 0);
		this.setBlock(world, i + 4, j + 8, k + 14, Blocks.air, 0);
		this.setBlock(world, i + 4, j + 8, k + 15, Blocks.air, 0);
		this.setBlock(world, i + 4, j + 8, k + 16, Blocks.air, 0);
		this.setBlock(world, i + 4, j + 8, k + 17, Blocks.air, 0);
		this.setBlock(world, i + 4, j + 8, k + 18, Blocks.air, 0);
		this.setBlock(world, i + 4, j + 8, k + 19, Blocks.air, 0);
		this.setBlock(world, i + 4, j + 8, k + 20, Blocks.air, 0);
		this.setBlock(world, i + 4, j + 8, k + 21, Blocks.air, 0);
		this.setBlock(world, i + 4, j + 8, k + 22, Blocks.air, 0);
		this.setBlock(world, i + 4, j + 9, k + 0, Blocks.air, 0);
		this.setBlock(world, i + 4, j + 9, k + 1, Blocks.air, 0);
		this.setBlock(world, i + 4, j + 9, k + 2, Blocks.air, 0);
		this.setBlock(world, i + 4, j + 9, k + 3, Blocks.air, 0);
		this.setBlock(world, i + 4, j + 9, k + 4, Blocks.air, 0);
		this.setBlock(world, i + 4, j + 9, k + 5, Blocks.air, 0);
		this.setBlock(world, i + 4, j + 9, k + 6, Blocks.air, 0);
		this.setBlock(world, i + 4, j + 9, k + 7, Blocks.air, 0);
		this.setBlock(world, i + 4, j + 9, k + 8, Blocks.air, 0);
		this.setBlock(world, i + 4, j + 9, k + 9, Blocks.air, 0);
		this.setBlock(world, i + 4, j + 9, k + 10, Blocks.air, 0);
		this.setBlock(world, i + 4, j + 9, k + 11, Blocks.air, 0);
		this.setBlock(world, i + 4, j + 9, k + 12, Blocks.air, 0);
		this.setBlock(world, i + 4, j + 9, k + 13, Blocks.air, 0);
		this.setBlock(world, i + 4, j + 9, k + 14, Blocks.air, 0);
		this.setBlock(world, i + 4, j + 9, k + 15, Blocks.air, 0);
		this.setBlock(world, i + 4, j + 9, k + 16, Blocks.air, 0);
		this.setBlock(world, i + 4, j + 9, k + 17, Blocks.air, 0);
		this.setBlock(world, i + 4, j + 9, k + 18, Blocks.air, 0);
		this.setBlock(world, i + 4, j + 9, k + 19, Blocks.air, 0);
		this.setBlock(world, i + 4, j + 9, k + 20, Blocks.air, 0);
		this.setBlock(world, i + 4, j + 9, k + 21, Blocks.air, 0);
		this.setBlock(world, i + 4, j + 9, k + 22, Blocks.air, 0);
		this.setBlock(world, i + 4, j + 10, k + 0, Blocks.stone_brick_stairs, 2);
		this.setBlock(world, i + 4, j + 10, k + 1, Blocks.air, 0);
		this.setBlock(world, i + 4, j + 10, k + 2, Blocks.air, 0);
		this.setBlock(world, i + 4, j + 10, k + 3, Blocks.air, 0);
		this.setBlock(world, i + 4, j + 10, k + 4, Blocks.air, 0);
		this.setBlock(world, i + 4, j + 10, k + 5, Blocks.air, 0);
		this.setBlock(world, i + 4, j + 10, k + 6, Blocks.air, 0);
		this.setBlock(world, i + 4, j + 10, k + 7, Blocks.air, 0);
		this.setBlock(world, i + 4, j + 10, k + 8, Blocks.air, 0);
		this.setBlock(world, i + 4, j + 10, k + 9, Blocks.air, 0);
		this.setBlock(world, i + 4, j + 10, k + 10, Blocks.air, 0);
		this.setBlock(world, i + 4, j + 10, k + 11, Blocks.air, 0);
		this.setBlock(world, i + 4, j + 10, k + 12, Blocks.air, 0);
		this.setBlock(world, i + 4, j + 10, k + 13, Blocks.air, 0);
		this.setBlock(world, i + 4, j + 10, k + 14, Blocks.air, 0);
		this.setBlock(world, i + 4, j + 10, k + 15, Blocks.air, 0);
		this.setBlock(world, i + 4, j + 10, k + 16, Blocks.air, 0);
		this.setBlock(world, i + 4, j + 10, k + 17, Blocks.air, 0);
		this.setBlock(world, i + 4, j + 10, k + 18, Blocks.air, 0);
		this.setBlock(world, i + 4, j + 10, k + 19, Blocks.air, 0);
		this.setBlock(world, i + 4, j + 10, k + 20, Blocks.air, 0);
		this.setBlock(world, i + 4, j + 10, k + 21, Blocks.air, 0);
		this.setBlock(world, i + 4, j + 10, k + 22, Blocks.stone_brick_stairs, 3);
		this.setBlock(world, i + 4, j + 11, k + 0, Blocks.air, 0);
		this.setBlock(world, i + 4, j + 11, k + 1, Blocks.stone_brick_stairs, 2);
		this.setBlock(world, i + 4, j + 11, k + 2, Blocks.air, 0);
		this.setBlock(world, i + 4, j + 11, k + 3, Blocks.air, 0);
		this.setBlock(world, i + 4, j + 11, k + 4, Blocks.air, 0);
		this.setBlock(world, i + 4, j + 11, k + 5, Blocks.air, 0);
		this.setBlock(world, i + 4, j + 11, k + 6, Blocks.air, 0);
		this.setBlock(world, i + 4, j + 11, k + 7, Blocks.air, 0);
		this.setBlock(world, i + 4, j + 11, k + 8, Blocks.air, 0);
		this.setBlock(world, i + 4, j + 11, k + 9, Blocks.air, 0);
		this.setBlock(world, i + 4, j + 11, k + 10, Blocks.air, 0);
		this.setBlock(world, i + 4, j + 11, k + 11, Blocks.air, 0);
		this.setBlock(world, i + 4, j + 11, k + 12, Blocks.air, 0);
		this.setBlock(world, i + 4, j + 11, k + 13, Blocks.air, 0);
		this.setBlock(world, i + 4, j + 11, k + 14, Blocks.air, 0);
		this.setBlock(world, i + 4, j + 11, k + 15, Blocks.air, 0);
		this.setBlock(world, i + 4, j + 11, k + 16, Blocks.air, 0);
		this.setBlock(world, i + 4, j + 11, k + 17, Blocks.air, 0);
		this.setBlock(world, i + 4, j + 11, k + 18, Blocks.air, 0);
		this.setBlock(world, i + 4, j + 11, k + 19, Blocks.air, 0);
		this.setBlock(world, i + 4, j + 11, k + 20, Blocks.air, 0);
		this.setBlock(world, i + 4, j + 11, k + 21, Blocks.stone_brick_stairs, 3);
		this.setBlock(world, i + 4, j + 11, k + 22, Blocks.air, 0);
		this.setBlock(world, i + 4, j + 12, k + 0, Blocks.air, 0);
		this.setBlock(world, i + 4, j + 12, k + 1, Blocks.air, 0);
		this.setBlock(world, i + 4, j + 12, k + 2, Blocks.stone_brick_stairs, 2);
		this.setBlock(world, i + 4, j + 12, k + 3, Blocks.stonebrick, 0);
		this.setBlock(world, i + 4, j + 12, k + 4, Blocks.stonebrick, 0);
		this.setBlock(world, i + 4, j + 12, k + 5, Blocks.stonebrick, 0);
		this.setBlock(world, i + 4, j + 12, k + 6, Blocks.stonebrick, 0);
		this.setBlock(world, i + 4, j + 12, k + 7, Blocks.stonebrick, 0);
		this.setBlock(world, i + 4, j + 12, k + 8, Blocks.stonebrick, 0);
		this.setBlock(world, i + 4, j + 12, k + 9, Blocks.stonebrick, 0);
		this.setBlock(world, i + 4, j + 12, k + 10, Blocks.stonebrick, 0);
		this.setBlock(world, i + 4, j + 12, k + 11, Blocks.stonebrick, 0);
		this.setBlock(world, i + 4, j + 12, k + 12, Blocks.stonebrick, 0);
		this.setBlock(world, i + 4, j + 12, k + 13, Blocks.stonebrick, 0);
		this.setBlock(world, i + 4, j + 12, k + 14, Blocks.stonebrick, 0);
		this.setBlock(world, i + 4, j + 12, k + 15, Blocks.stonebrick, 0);
		this.setBlock(world, i + 4, j + 12, k + 16, Blocks.stonebrick, 0);
		this.setBlock(world, i + 4, j + 12, k + 17, Blocks.stonebrick, 0);
		this.setBlock(world, i + 4, j + 12, k + 18, Blocks.stonebrick, 0);
		this.setBlock(world, i + 4, j + 12, k + 19, Blocks.stonebrick, 0);
		this.setBlock(world, i + 4, j + 12, k + 20, Blocks.stone_brick_stairs, 3);
		this.setBlock(world, i + 4, j + 12, k + 21, Blocks.air, 0);
		this.setBlock(world, i + 4, j + 12, k + 22, Blocks.air, 0);
		this.setBlock(world, i + 5, j + 0, k + 0, Blocks.stonebrick, 0);
		this.setBlock(world, i + 5, j + 0, k + 1, Blocks.stonebrick, 0);
		this.setBlock(world, i + 5, j + 0, k + 2, Blocks.planks, 5);
		this.setBlock(world, i + 5, j + 0, k + 3, Blocks.wooden_slab, 5);
		this.setBlock(world, i + 5, j + 0, k + 4, Blocks.wooden_slab, 5);

		generate2(world, rand, i, j, k);
		return true;
	}

	public boolean generate2(World world, Random rand, int i, int j, int k)
	{
		this.setBlock(world, i + 5, j + 0, k + 5, Blocks.wooden_slab, 5);
		this.setBlock(world, i + 5, j + 0, k + 6, Blocks.planks, 5);
		this.setBlock(world, i + 5, j + 0, k + 7, Blocks.wooden_slab, 5);
		this.setBlock(world, i + 5, j + 0, k + 8, Blocks.wooden_slab, 5);
		this.setBlock(world, i + 5, j + 0, k + 9, Blocks.wooden_slab, 5);
		this.setBlock(world, i + 5, j + 0, k + 10, Blocks.planks, 5);
		this.setBlock(world, i + 5, j + 0, k + 11, Blocks.planks, 5);
		this.setBlock(world, i + 5, j + 0, k + 12, Blocks.planks, 5);
		this.setBlock(world, i + 5, j + 0, k + 13, Blocks.wooden_slab, 5);
		this.setBlock(world, i + 5, j + 0, k + 14, Blocks.wooden_slab, 5);
		this.setBlock(world, i + 5, j + 0, k + 15, Blocks.wooden_slab, 5);
		this.setBlock(world, i + 5, j + 0, k + 16, Blocks.planks, 5);
		this.setBlock(world, i + 5, j + 0, k + 17, Blocks.wooden_slab, 5);
		this.setBlock(world, i + 5, j + 0, k + 18, Blocks.wooden_slab, 5);
		this.setBlock(world, i + 5, j + 0, k + 19, Blocks.wooden_slab, 5);
		this.setBlock(world, i + 5, j + 0, k + 20, Blocks.planks, 5);
		this.setBlock(world, i + 5, j + 0, k + 21, Blocks.stonebrick, 0);
		this.setBlock(world, i + 5, j + 0, k + 22, Blocks.stonebrick, 0);
		this.setBlock(world, i + 5, j + 1, k + 0, Blocks.air, 0);
		this.setBlock(world, i + 5, j + 1, k + 1, Blocks.stonebrick, 1);
		this.setBlock(world, i + 5, j + 1, k + 2, Blocks.mossy_cobblestone, 0);
		this.setBlock(world, i + 5, j + 1, k + 3, Blocks.air, 0);
		this.setBlock(world, i + 5, j + 1, k + 4, Blocks.air, 0);
		this.setBlock(world, i + 5, j + 1, k + 5, Blocks.air, 0);
		this.setBlock(world, i + 5, j + 1, k + 6, Blocks.bookshelf, 0);
		this.setBlock(world, i + 5, j + 1, k + 7, Blocks.air, 0);
		this.setBlock(world, i + 5, j + 1, k + 8, Blocks.air, 0);
		this.setBlock(world, i + 5, j + 1, k + 9, Blocks.air, 0);
		this.setBlock(world, i + 5, j + 1, k + 10, Blocks.air, 0);
		this.setBlock(world, i + 5, j + 1, k + 11, Blocks.air, 0);
		this.setBlock(world, i + 5, j + 1, k + 12, Blocks.air, 0);
		this.setBlock(world, i + 5, j + 1, k + 13, Blocks.air, 0);
		this.setBlock(world, i + 5, j + 1, k + 14, Blocks.air, 0);
		this.setBlock(world, i + 5, j + 1, k + 15, Blocks.air, 0);
		this.setBlock(world, i + 5, j + 1, k + 16, Blocks.bookshelf, 0);
		this.setBlock(world, i + 5, j + 1, k + 17, Blocks.air, 0);
		this.setBlock(world, i + 5, j + 1, k + 18, Blocks.air, 0);
		this.setBlock(world, i + 5, j + 1, k + 19, Blocks.air, 0);
		this.setBlock(world, i + 5, j + 1, k + 20, Blocks.mossy_cobblestone, 0);
		this.setBlock(world, i + 5, j + 1, k + 21, Blocks.stonebrick, 1);
		this.setBlock(world, i + 5, j + 1, k + 22, Blocks.vine, 4);
		this.setBlock(world, i + 5, j + 2, k + 0, Blocks.air, 0);
		this.setBlock(world, i + 5, j + 2, k + 1, Blocks.stonebrick, 0);
		this.setBlock(world, i + 5, j + 2, k + 2, Blocks.mossy_cobblestone, 0);
		this.setBlock(world, i + 5, j + 2, k + 3, Blocks.air, 0);
		this.setBlock(world, i + 5, j + 2, k + 4, Blocks.air, 0);
		this.setBlock(world, i + 5, j + 2, k + 5, Blocks.air, 0);
		this.setBlock(world, i + 5, j + 2, k + 6, Blocks.bookshelf, 0);
		this.setBlock(world, i + 5, j + 2, k + 7, Blocks.air, 0);
		this.setBlock(world, i + 5, j + 2, k + 8, Blocks.air, 0);
