/*
*** MADE BY MRPONYCAPTAIN'S .SCHEMATIC TO .JAVA CONVERTING TOOL v2.0 ***
*/

package com.DavidM1A2.AfraidOfTheDark.common.worldGeneration.darkForestDungeon;

import java.util.Random;
import net.minecraft.block.Block;
import net.minecraft.init.Blocks;
import net.minecraft.tileentity.TileEntity;
import net.minecraft.tileentity.TileEntityChest;
import net.minecraft.tileentity.TileEntityMobSpawner;
import net.minecraft.util.BlockPos;
import net.minecraft.util.WeightedRandomChestContent;
import net.minecraft.world.World;
import java.util.Random;

public class PropFallenOverLog
{
	public PropFallenOverLog(World world, Random rand, int x, int y, int z) 
	{
		this.generate(world, rand, x, y, z);
	}

	public void setBlock(World world, int x, int y, int z, Block block, int metadata)
	{
		world.setBlockState(new BlockPos(x, y, z), block.getStateFromMeta(metadata));
	}

	public boolean generate(World world, Random rand, int i, int j, int k) {
		this.setBlock(world, i + 0, j + 0, k + 3, Blocks.log, 5);
		this.setBlock(world, i + 0, j + 0, k + 4, Blocks.log, 5);
		this.setBlock(world, i + 1, j + 0, k + 3, Blocks.log, 5);
		this.setBlock(world, i + 1, j + 0, k + 4, Blocks.log, 5);
		this.setBlock(world, i + 2, j + 0, k + 3, Blocks.log, 5);
		this.setBlock(world, i + 2, j + 0, k + 4, Blocks.log, 5);
		this.setBlock(world, i + 3, j + 1, k + 3, Blocks.log, 5);
		this.setBlock(world, i + 3, j + 1, k + 4, Blocks.log, 5);
		this.setBlock(world, i + 4, j + 1, k + 3, Blocks.log, 5);
		this.setBlock(world, i + 4, j + 1, k + 4, Blocks.log, 5);
		this.setBlock(world, i + 5, j + 1, k + 3, Blocks.log, 5);
		this.setBlock(world, i + 5, j + 1, k + 4, Blocks.log, 5);
		this.setBlock(world, i + 6, j + 1, k + 3, Blocks.log, 5);
		this.setBlock(world, i + 6, j + 1, k + 4, Blocks.log, 5);
		this.setBlock(world, i + 6, j + 2, k + 4, Blocks.log, 5);
		this.setBlock(world, i + 7, j + 1, k + 1, Blocks.air, 0);
		this.setBlock(world, i + 7, j + 1, k + 2, Blocks.log, 9);
		this.setBlock(world, i + 7, j + 1, k + 3, Blocks.log, 9);
		this.setBlock(world, i + 7, j + 1, k + 4, Blocks.log, 9);
		this.setBlock(world, i + 7, j + 1, k + 5, Blocks.log, 9);
		this.setBlock(world, i + 7, j + 1, k + 6, Blocks.log, 9);
		this.setBlock(world, i + 7, j + 1, k + 7, Blocks.log, 9);
		this.setBlock(world, i + 7, j + 1, k + 8, Blocks.air, 0);
		this.setBlock(world, i + 7, j + 1, k + 9, Blocks.log, 9);
		this.setBlock(world, i + 7, j + 1, k + 10, Blocks.log, 9);
		this.setBlock(world, i + 7, j + 1, k + 11, Blocks.log, 9);
		this.setBlock(world, i + 7, j + 1, k + 12, Blocks.log, 9);
		this.setBlock(world, i + 7, j + 1, k + 13, Blocks.log, 9);
		this.setBlock(world, i + 7, j + 1, k + 14, Blocks.log, 9);
		this.setBlock(world, i + 7, j + 1, k + 15, Blocks.log, 9);
		this.setBlock(world, i + 7, j + 2, k + 1, Blocks.log, 9);
		this.setBlock(world, i + 7, j + 2, k + 2, Blocks.log, 9);
		this.setBlock(world, i + 7, j + 2, k + 3, Blocks.log, 9);
		this.setBlock(world, i + 7, j + 2, k + 4, Blocks.log, 9);
		this.setBlock(world, i + 7, j + 2, k + 5, Blocks.log, 9);
		this.setBlock(world, i + 7, j + 2, k + 6, Blocks.log, 9);
		this.setBlock(world, i + 7, j + 2, k + 7, Blocks.air, 0);
		this.setBlock(world, i + 7, j + 2, k + 8, Blocks.air, 0);
		this.setBlock(world, i + 7, j + 2, k + 9, Blocks.log, 9);
		this.setBlock(world, i + 7, j + 2, k + 10, Blocks.log, 9);
		this.setBlock(world, i + 7, j + 2, k + 11, Blocks.log, 9);
		this.setBlock(world, i + 7, j + 2, k + 12, Blocks.log, 9);
		this.setBlock(world, i + 7, j + 2, k + 13, Blocks.log, 9);
		this.setBlock(world, i + 7, j + 2, k + 14, Blocks.log, 9);
		this.setBlock(world, i + 7, j + 2, k + 15, Blocks.air, 0);
		this.setBlock(world, i + 8, j + 0, k + 1, Blocks.log, 9);
		this.setBlock(world, i + 8, j + 0, k + 2, Blocks.log, 9);
		this.setBlock(world, i + 8, j + 0, k + 3, Blocks.log, 9);
		this.setBlock(world, i + 8, j + 0, k + 4, Blocks.log, 9);
		this.setBlock(world, i + 8, j + 0, k + 5, Blocks.log, 9);
		this.setBlock(world, i + 8, j + 0, k + 6, Blocks.log, 9);
		this.setBlock(world, i + 8, j + 0, k + 7, Blocks.log, 9);
		this.setBlock(world, i + 8, j + 0, k + 8, Blocks.log, 9);
		this.setBlock(world, i + 8, j + 0, k + 9, Blocks.log, 9);
		this.setBlock(world, i + 8, j + 0, k + 10, Blocks.log, 9);
		this.setBlock(world, i + 8, j + 0, k + 11, Blocks.log, 9);
		this.setBlock(world, i + 8, j + 0, k + 12, Blocks.log, 9);
		this.setBlock(world, i + 8, j + 0, k + 13, Blocks.log, 9);
		this.setBlock(world, i + 8, j + 0, k + 14, Blocks.log, 9);
		this.setBlock(world, i + 8, j + 0, k + 15, Blocks.log, 9);
		this.setBlock(world, i + 8, j + 0, k + 16, Blocks.log, 9);
		this.setBlock(world, i + 8, j + 1, k + 1, Blocks.air, 0);
		this.setBlock(world, i + 8, j + 1, k + 2, Blocks.air, 0);
		this.setBlock(world, i + 8, j + 1, k + 3, Blocks.air, 0);
		this.setBlock(world, i + 8, j + 1, k + 4, Blocks.air, 0);
		this.setBlock(world, i + 8, j + 1, k + 5, Blocks.air, 0);
		this.setBlock(world, i + 8, j + 1, k + 6, Blocks.air, 0);
		this.setBlock(world, i + 8, j + 1, k + 7, Blocks.air, 0);
		this.setBlock(world, i + 8, j + 1, k + 8, Blocks.air, 0);
		this.setBlock(world, i + 8, j + 1, k + 9, Blocks.air, 0);
		this.setBlock(world, i + 8, j + 1, k + 10, Blocks.air, 0);
		this.setBlock(world, i + 8, j + 1, k + 11, Blocks.air, 0);
		this.setBlock(world, i + 8, j + 1, k + 12, Blocks.air, 0);
		this.setBlock(world, i + 8, j + 1, k + 13, Blocks.air, 0);
		this.setBlock(world, i + 8, j + 1, k + 14, Blocks.air, 0);
		this.setBlock(world, i + 8, j + 1, k + 15, Blocks.air, 0);
		this.setBlock(world, i + 8, j + 1, k + 16, Blocks.air, 0);
		this.setBlock(world, i + 8, j + 2, k + 0, Blocks.air, 0);
		this.setBlock(world, i + 8, j + 2, k + 1, Blocks.air, 0);
		this.setBlock(world, i + 8, j + 2, k + 2, Blocks.air, 0);
		this.setBlock(world, i + 8, j + 2, k + 3, Blocks.air, 0);
		this.setBlock(world, i + 8, j + 2, k + 4, Blocks.air, 0);
		this.setBlock(world, i + 8, j + 2, k + 5, Blocks.air, 0);
		this.setBlock(world, i + 8, j + 2, k + 6, Blocks.air, 0);
		this.setBlock(world, i + 8, j + 2, k + 7, Blocks.air, 0);
		this.setBlock(world, i + 8, j + 2, k + 8, Blocks.air, 0);
		this.setBlock(world, i + 8, j + 2, k + 9, Blocks.air, 0);
		this.setBlock(world, i + 8, j + 2, k + 10, Blocks.air, 0);
		this.setBlock(world, i + 8, j + 2, k + 11, Blocks.air, 0);
		this.setBlock(world, i + 8, j + 2, k + 12, Blocks.air, 0);
		this.setBlock(world, i + 8, j + 2, k + 13, Blocks.air, 0);
		this.setBlock(world, i + 8, j + 2, k + 14, Blocks.air, 0);
		this.setBlock(world, i + 8, j + 2, k + 15, Blocks.air, 0);
		this.setBlock(world, i + 8, j + 2, k + 16, Blocks.air, 0);
		this.setBlock(world, i + 8, j + 3, k + 0, Blocks.log, 9);
		this.setBlock(world, i + 8, j + 3, k + 1, Blocks.log, 9);
		this.setBlock(world, i + 8, j + 3, k + 2, Blocks.log, 9);
		this.setBlock(world, i + 8, j + 3, k + 3, Blocks.log, 9);
		this.setBlock(world, i + 8, j + 3, k + 4, Blocks.log, 9);
		this.setBlock(world, i + 8, j + 3, k + 5, Blocks.log, 9);
		this.setBlock(world, i + 8, j + 3, k + 6, Blocks.log, 9);
		this.setBlock(world, i + 8, j + 3, k + 7, Blocks.log, 9);
		this.setBlock(world, i + 8, j + 3, k + 8, Blocks.log, 9);
		this.setBlock(world, i + 8, j + 3, k + 9, Blocks.log, 9);
		this.setBlock(world, i + 8, j + 3, k + 10, Blocks.log, 9);
		this.setBlock(world, i + 8, j + 3, k + 11, Blocks.log, 9);
		this.setBlock(world, i + 8, j + 3, k + 12, Blocks.log, 9);
		this.setBlock(world, i + 8, j + 3, k + 13, Blocks.log, 9);
		this.setBlock(world, i + 8, j + 3, k + 14, Blocks.log, 9);
		this.setBlock(world, i + 8, j + 3, k + 15, Blocks.log, 9);
		this.setBlock(world, i + 8, j + 4, k + 8, Blocks.log, 1);
		this.setBlock(world, i + 8, j + 4, k + 9, Blocks.log, 1);
		this.setBlock(world, i + 8, j + 5, k + 8, Blocks.log, 1);
		this.setBlock(world, i + 8, j + 5, k + 9, Blocks.log, 1);
		this.setBlock(world, i + 8, j + 6, k + 8, Blocks.log, 1);
		this.setBlock(world, i + 8, j + 6, k + 9, Blocks.log, 1);
		this.setBlock(world, i + 8, j + 7, k + 8, Blocks.log, 1);
		this.setBlock(world, i + 8, j + 7, k + 9, Blocks.log, 1);
		this.setBlock(world, i + 8, j + 8, k + 8, Blocks.log, 1);
		this.setBlock(world, i + 9, j + 0, k + 1, Blocks.air, 0);
		this.setBlock(world, i + 9, j + 0, k + 2, Blocks.log, 9);
		this.setBlock(world, i + 9, j + 0, k + 3, Blocks.log, 9);
		this.setBlock(world, i + 9, j + 0, k + 4, Blocks.log, 9);
		this.setBlock(world, i + 9, j + 0, k + 5, Blocks.log, 9);
		this.setBlock(world, i + 9, j + 0, k + 6, Blocks.log, 9);
		this.setBlock(world, i + 9, j + 0, k + 7, Blocks.log, 9);
		this.setBlock(world, i + 9, j + 0, k + 8, Blocks.log, 9);
		this.setBlock(world, i + 9, j + 0, k + 9, Blocks.log, 9);
		this.setBlock(world, i + 9, j + 0, k + 10, Blocks.log, 9);
		this.setBlock(world, i + 9, j + 0, k + 11, Blocks.log, 9);
		this.setBlock(world, i + 9, j + 0, k + 12, Blocks.log, 9);
		this.setBlock(world, i + 9, j + 0, k + 13, Blocks.log, 9);
		this.setBlock(world, i + 9, j + 0, k + 14, Blocks.log, 9);
		this.setBlock(world, i + 9, j + 0, k + 15, Blocks.log, 9);
		this.setBlock(world, i + 9, j + 1, k + 1, Blocks.air, 0);
		this.setBlock(world, i + 9, j + 1, k + 2, Blocks.air, 0);
		this.setBlock(world, i + 9, j + 1, k + 3, Blocks.air, 0);
		this.setBlock(world, i + 9, j + 1, k + 4, Blocks.air, 0);
		this.setBlock(world, i + 9, j + 1, k + 5, Blocks.air, 0);
		this.setBlock(world, i + 9, j + 1, k + 6, Blocks.air, 0);
		this.setBlock(world, i + 9, j + 1, k + 7, Blocks.air, 0);
		this.setBlock(world, i + 9, j + 1, k + 8, Blocks.air, 0);
		this.setBlock(world, i + 9, j + 1, k + 9, Blocks.air, 0);
		this.setBlock(world, i + 9, j + 1, k + 10, Blocks.air, 0);
		this.setBlock(world, i + 9, j + 1, k + 11, Blocks.air, 0);
		this.setBlock(world, i + 9, j + 1, k + 12, Blocks.air, 0);
		this.setBlock(world, i + 9, j + 1, k + 13, Blocks.air, 0);
		this.setBlock(world, i + 9, j + 1, k + 14, Blocks.air, 0);
		this.setBlock(world, i + 9, j + 1, k + 15, Blocks.air, 0);
		this.setBlock(world, i + 9, j + 1, k + 16, Blocks.air, 0);
		this.setBlock(world, i + 9, j + 2, k + 1, Blocks.air, 0);
		this.setBlock(world, i + 9, j + 2, k + 2, Blocks.air, 0);
		this.setBlock(world, i + 9, j + 2, k + 3, Blocks.air, 0);
		this.setBlock(world, i + 9, j + 2, k + 4, Blocks.air, 0);
		this.setBlock(world, i + 9, j + 2, k + 5, Blocks.air, 0);
		this.setBlock(world, i + 9, j + 2, k + 6, Blocks.air, 0);
		this.setBlock(world, i + 9, j + 2, k + 7, Blocks.air, 0);
		this.setBlock(world, i + 9, j + 2, k + 8, Blocks.air, 0);
		this.setBlock(world, i + 9, j + 2, k + 9, Blocks.air, 0);
		this.setBlock(world, i + 9, j + 2, k + 10, Blocks.air, 0);
		this.setBlock(world, i + 9, j + 2, k + 11, Blocks.air, 0);
		this.setBlock(world, i + 9, j + 2, k + 12, Blocks.air, 0);
		this.setBlock(world, i + 9, j + 2, k + 13, Blocks.air, 0);
		this.setBlock(world, i + 9, j + 2, k + 14, Blocks.air, 0);
		this.setBlock(world, i + 9, j + 2, k + 15, Blocks.air, 0);
		this.setBlock(world, i + 9, j + 2, k + 16, Blocks.air, 0);
		this.setBlock(world, i + 9, j + 3, k + 1, Blocks.log, 9);
		this.setBlock(world, i + 9, j + 3, k + 2, Blocks.log, 9);
		this.setBlock(world, i + 9, j + 3, k + 3, Blocks.log, 9);
		this.setBlock(world, i + 9, j + 3, k + 4, Blocks.log, 9);
		this.setBlock(world, i + 9, j + 3, k + 5, Blocks.log, 9);
		this.setBlock(world, i + 9, j + 3, k + 6, Blocks.log, 9);
		this.setBlock(world, i + 9, j + 3, k + 7, Blocks.log, 9);
		this.setBlock(world, i + 9, j + 3, k + 8, Blocks.log, 9);
		this.setBlock(world, i + 9, j + 3, k + 9, Blocks.log, 9);
		this.setBlock(world, i + 9, j + 3, k + 10, Blocks.log, 9);
		this.setBlock(world, i + 9, j + 3, k + 11, Blocks.log, 9);
		this.setBlock(world, i + 9, j + 3, k + 12, Blocks.log, 9);
		this.setBlock(world, i + 9, j + 3, k + 13, Blocks.log, 9);
		this.setBlock(world, i + 9, j + 3, k + 14, Blocks.log, 9);
		this.setBlock(world, i + 9, j + 4, k + 8, Blocks.log, 1);
		this.setBlock(world, i + 10, j + 1, k + 1, Blocks.log, 9);
		this.setBlock(world, i + 10, j + 1, k + 2, Blocks.log, 9);
		this.setBlock(world, i + 10, j + 1, k + 3, Blocks.log, 9);
		this.setBlock(world, i + 10, j + 1, k + 4, Blocks.log, 9);
		this.setBlock(world, i + 10, j + 1, k + 5, Blocks.log, 9);
		this.setBlock(world, i + 10, j + 1, k + 6, Blocks.log, 9);
		this.setBlock(world, i + 10, j + 1, k + 7, Blocks.log, 9);
		this.setBlock(world, i + 10, j + 1, k + 8, Blocks.log, 9);
		this.setBlock(world, i + 10, j + 1, k + 9, Blocks.log, 9);
		this.setBlock(world, i + 10, j + 1, k + 10, Blocks.log, 9);
		this.setBlock(world, i + 10, j + 1, k + 11, Blocks.log, 9);
		this.setBlock(world, i + 10, j + 1, k + 12, Blocks.log, 9);
		this.setBlock(world, i + 10, j + 1, k + 13, Blocks.log, 9);
		this.setBlock(world, i + 10, j + 1, k + 14, Blocks.log, 9);
		this.setBlock(world, i + 10, j + 1, k + 15, Blocks.log, 9);
		this.setBlock(world, i + 10, j + 1, k + 16, Blocks.log, 9);
		this.setBlock(world, i + 10, j + 2, k + 1, Blocks.air, 0);
		this.setBlock(world, i + 10, j + 2, k + 2, Blocks.log, 9);
		this.setBlock(world, i + 10, j + 2, k + 3, Blocks.log, 9);
		this.setBlock(world, i + 10, j + 2, k + 4, Blocks.log, 9);
		this.setBlock(world, i + 10, j + 2, k + 5, Blocks.log, 9);
		this.setBlock(world, i + 10, j + 2, k + 6, Blocks.log, 9);
		this.setBlock(world, i + 10, j + 2, k + 7, Blocks.log, 9);
		this.setBlock(world, i + 10, j + 2, k + 8, Blocks.log, 9);
		this.setBlock(world, i + 10, j + 2, k + 9, Blocks.log, 9);
		this.setBlock(world, i + 10, j + 2, k + 10, Blocks.log, 9);
		this.setBlock(world, i + 10, j + 2, k + 11, Blocks.log, 9);
		this.setBlock(world, i + 10, j + 2, k + 12, Blocks.log, 9);
		this.setBlock(world, i + 10, j + 2, k + 13, Blocks.log, 9);
		this.setBlock(world, i + 10, j + 2, k + 14, Blocks.log, 9);
		this.setBlock(world, i + 10, j + 2, k + 15, Blocks.log, 9);

		return true;
	}
}