/*
*** MADE BY MRPONYCAPTAIN'S .SCHEMATIC TO .JAVA CONVERTING TOOL v2.0 ***
*/

package com.DavidM1A2.AfraidOfTheDark.common.worldGeneration.darkForestDungeon;

import java.util.Random;

import net.minecraft.block.Block;
import net.minecraft.init.Blocks;
import net.minecraft.util.BlockPos;
import net.minecraft.world.World;

import com.DavidM1A2.AfraidOfTheDark.common.initializeMod.ModBlocks;

public class TreeLargeCircle
{
    public static int width = 50;
    public static int height = 50;
    
    
	public TreeLargeCircle(World world, Random rand, int x, int y, int z)
	{
		this.generate(world, rand, x, y, z);
	}

	public void setBlock(World world, int x, int y, int z, Block block, int metadata)
	{
		world.setBlockState(new BlockPos(x, y, z), block.getStateFromMeta(metadata));
	}

	public boolean generate(World world, Random rand, int i, int j, int k)
	{
		this.setBlock(world, i + 0, j + 42, k + 18, ModBlocks.gravewoodLeaves, 0);
		this.setBlock(world, i + 1, j + 41, k + 17, ModBlocks.gravewoodLeaves, 0);
		this.setBlock(world, i + 1, j + 41, k + 18, ModBlocks.gravewoodLeaves, 0);
		this.setBlock(world, i + 1, j + 41, k + 19, ModBlocks.gravewoodLeaves, 0);
		this.setBlock(world, i + 1, j + 42, k + 17, ModBlocks.gravewoodLeaves, 0);
		this.setBlock(world, i + 1, j + 42, k + 18, ModBlocks.gravewoodLeaves, 0);
		this.setBlock(world, i + 1, j + 42, k + 19, ModBlocks.gravewoodLeaves, 0);
		this.setBlock(world, i + 1, j + 43, k + 17, ModBlocks.gravewoodLeaves, 0);
		this.setBlock(world, i + 1, j + 43, k + 18, ModBlocks.gravewoodLeaves, 0);
		this.setBlock(world, i + 1, j + 43, k + 19, ModBlocks.gravewoodLeaves, 0);
		this.setBlock(world, i + 2, j + 41, k + 17, ModBlocks.gravewood, 1);
		this.setBlock(world, i + 2, j + 41, k + 18, ModBlocks.gravewood, 1);
		this.setBlock(world, i + 2, j + 41, k + 19, ModBlocks.gravewoodLeaves, 0);
		this.setBlock(world, i + 2, j + 41, k + 20, ModBlocks.gravewood, 1);
		this.setBlock(world, i + 2, j + 41, k + 21, ModBlocks.gravewood, 1);
		this.setBlock(world, i + 2, j + 42, k + 17, ModBlocks.gravewoodLeaves, 0);
		this.setBlock(world, i + 2, j + 42, k + 18, ModBlocks.gravewood, 1);
		this.setBlock(world, i + 2, j + 42, k + 19, ModBlocks.gravewoodLeaves, 0);
		this.setBlock(world, i + 2, j + 42, k + 20, ModBlocks.gravewoodLeaves, 0);
		this.setBlock(world, i + 2, j + 42, k + 21, ModBlocks.gravewoodLeaves, 0);
		this.setBlock(world, i + 2, j + 42, k + 30, ModBlocks.gravewoodLeaves, 0);
		this.setBlock(world, i + 2, j + 43, k + 13, ModBlocks.gravewoodLeaves, 0);
		this.setBlock(world, i + 2, j + 43, k + 17, ModBlocks.gravewoodLeaves, 0);
		this.setBlock(world, i + 2, j + 43, k + 18, ModBlocks.gravewoodLeaves, 0);
		this.setBlock(world, i + 2, j + 43, k + 19, ModBlocks.gravewoodLeaves, 0);
		this.setBlock(world, i + 2, j + 43, k + 20, ModBlocks.gravewoodLeaves, 0);
		this.setBlock(world, i + 2, j + 43, k + 21, ModBlocks.gravewoodLeaves, 0);
		this.setBlock(world, i + 3, j + 40, k + 18, ModBlocks.gravewood, 1);
		this.setBlock(world, i + 3, j + 40, k + 19, ModBlocks.gravewood, 1);
		this.setBlock(world, i + 3, j + 40, k + 20, ModBlocks.gravewood, 1);
		this.setBlock(world, i + 3, j + 40, k + 21, ModBlocks.gravewood, 1);
		this.setBlock(world, i + 3, j + 41, k + 13, ModBlocks.gravewoodLeaves, 0);
		this.setBlock(world, i + 3, j + 41, k + 14, ModBlocks.gravewood, 1);
		this.setBlock(world, i + 3, j + 41, k + 15, ModBlocks.gravewoodLeaves, 0);
		this.setBlock(world, i + 3, j + 41, k + 16, ModBlocks.gravewood, 1);
		this.setBlock(world, i + 3, j + 41, k + 17, ModBlocks.gravewood, 1);
		this.setBlock(world, i + 3, j + 41, k + 18, ModBlocks.gravewood, 1);
		this.setBlock(world, i + 3, j + 41, k + 19, ModBlocks.gravewood, 1);
		this.setBlock(world, i + 3, j + 41, k + 20, ModBlocks.gravewood, 1);
		this.setBlock(world, i + 3, j + 41, k + 21, ModBlocks.gravewood, 1);
		this.setBlock(world, i + 3, j + 41, k + 22, ModBlocks.gravewood, 1);
		this.setBlock(world, i + 3, j + 41, k + 29, ModBlocks.gravewoodLeaves, 0);
		this.setBlock(world, i + 3, j + 41, k + 30, ModBlocks.gravewood, 1);
		this.setBlock(world, i + 3, j + 41, k + 31, ModBlocks.gravewoodLeaves, 0);
		this.setBlock(world, i + 3, j + 42, k + 12, ModBlocks.gravewoodLeaves, 0);
		this.setBlock(world, i + 3, j + 42, k + 13, ModBlocks.gravewood, 1);
		this.setBlock(world, i + 3, j + 42, k + 14, ModBlocks.gravewoodLeaves, 0);
		this.setBlock(world, i + 3, j + 42, k + 15, ModBlocks.gravewoodLeaves, 0);
		this.setBlock(world, i + 3, j + 42, k + 16, ModBlocks.gravewoodLeaves, 0);
		this.setBlock(world, i + 3, j + 42, k + 17, ModBlocks.gravewoodLeaves, 0);
		this.setBlock(world, i + 3, j + 42, k + 18, ModBlocks.gravewood, 1);
		this.setBlock(world, i + 3, j + 42, k + 19, ModBlocks.gravewood, 1);
		this.setBlock(world, i + 3, j + 42, k + 20, ModBlocks.gravewood, 1);
		this.setBlock(world, i + 3, j + 42, k + 21, ModBlocks.gravewood, 1);
		this.setBlock(world, i + 3, j + 42, k + 22, ModBlocks.gravewoodLeaves, 0);
		this.setBlock(world, i + 3, j + 42, k + 23, ModBlocks.gravewoodLeaves, 0);
		this.setBlock(world, i + 3, j + 42, k + 24, ModBlocks.gravewoodLeaves, 0);
		this.setBlock(world, i + 3, j + 42, k + 25, ModBlocks.gravewoodLeaves, 0);
		this.setBlock(world, i + 3, j + 42, k + 26, ModBlocks.gravewood, 1);
		this.setBlock(world, i + 3, j + 42, k + 27, ModBlocks.gravewoodLeaves, 0);
		this.setBlock(world, i + 3, j + 42, k + 28, ModBlocks.gravewoodLeaves, 0);
		this.setBlock(world, i + 3, j + 42, k + 29, ModBlocks.gravewoodLeaves, 0);
		this.setBlock(world, i + 3, j + 42, k + 30, ModBlocks.gravewoodLeaves, 0);
		this.setBlock(world, i + 3, j + 42, k + 31, ModBlocks.gravewoodLeaves, 0);
		this.setBlock(world, i + 3, j + 43, k + 12, ModBlocks.gravewoodLeaves, 0);
		this.setBlock(world, i + 3, j + 43, k + 13, ModBlocks.gravewoodLeaves, 0);
		this.setBlock(world, i + 3, j + 43, k + 14, ModBlocks.gravewoodLeaves, 0);
		this.setBlock(world, i + 3, j + 43, k + 15, ModBlocks.gravewood, 1);
		this.setBlock(world, i + 3, j + 43, k + 16, ModBlocks.gravewoodLeaves, 0);
		this.setBlock(world, i + 3, j + 43, k + 17, ModBlocks.gravewoodLeaves, 0);
		this.setBlock(world, i + 3, j + 43, k + 18, ModBlocks.gravewood, 1);
		this.setBlock(world, i + 3, j + 43, k + 19, ModBlocks.gravewoodLeaves, 0);
		this.setBlock(world, i + 3, j + 43, k + 20, ModBlocks.gravewoodLeaves, 0);
		this.setBlock(world, i + 3, j + 43, k + 21, ModBlocks.gravewoodLeaves, 0);
		this.setBlock(world, i + 3, j + 43, k + 22, ModBlocks.gravewood, 1);
		this.setBlock(world, i + 3, j + 43, k + 23, ModBlocks.gravewoodLeaves, 0);
		this.setBlock(world, i + 3, j + 43, k + 24, ModBlocks.gravewood, 1);
		this.setBlock(world, i + 3, j + 43, k + 25, ModBlocks.gravewoodLeaves, 0);
		this.setBlock(world, i + 3, j + 43, k + 26, ModBlocks.gravewoodLeaves, 0);
		this.setBlock(world, i + 3, j + 43, k + 27, ModBlocks.gravewoodLeaves, 0);
		this.setBlock(world, i + 3, j + 43, k + 28, ModBlocks.gravewoodLeaves, 0);
		this.setBlock(world, i + 3, j + 43, k + 29, ModBlocks.gravewood, 1);
		this.setBlock(world, i + 3, j + 43, k + 30, ModBlocks.gravewoodLeaves, 0);
		this.setBlock(world, i + 3, j + 43, k + 31, ModBlocks.gravewoodLeaves, 0);
		this.setBlock(world, i + 3, j + 44, k + 12, ModBlocks.gravewoodLeaves, 0);
		this.setBlock(world, i + 3, j + 44, k + 13, ModBlocks.gravewoodLeaves, 0);
		this.setBlock(world, i + 3, j + 44, k + 14, ModBlocks.gravewoodLeaves, 0);
		this.setBlock(world, i + 3, j + 44, k + 15, ModBlocks.gravewoodLeaves, 0);
		this.setBlock(world, i + 3, j + 44, k + 16, ModBlocks.gravewoodLeaves, 0);
		this.setBlock(world, i + 3, j + 44, k + 17, ModBlocks.gravewoodLeaves, 0);
		this.setBlock(world, i + 3, j + 44, k + 18, ModBlocks.gravewoodLeaves, 0);
		this.setBlock(world, i + 3, j + 44, k + 19, ModBlocks.gravewoodLeaves, 0);
		this.setBlock(world, i + 3, j + 44, k + 20, ModBlocks.gravewoodLeaves, 0);
		this.setBlock(world, i + 3, j + 44, k + 21, ModBlocks.gravewoodLeaves, 0);
		this.setBlock(world, i + 3, j + 44, k + 22, ModBlocks.gravewoodLeaves, 0);
		this.setBlock(world, i + 3, j + 44, k + 23, ModBlocks.gravewoodLeaves, 0);
		this.setBlock(world, i + 3, j + 44, k + 24, ModBlocks.gravewoodLeaves, 0);
		this.setBlock(world, i + 3, j + 44, k + 25, ModBlocks.gravewoodLeaves, 0);
		this.setBlock(world, i + 3, j + 44, k + 26, ModBlocks.gravewoodLeaves, 0);
		this.setBlock(world, i + 3, j + 44, k + 27, ModBlocks.gravewoodLeaves, 0);
		this.setBlock(world, i + 3, j + 44, k + 28, ModBlocks.gravewoodLeaves, 0);
		this.setBlock(world, i + 3, j + 44, k + 29, ModBlocks.gravewoodLeaves, 0);
		this.setBlock(world, i + 4, j + 40, k + 18, ModBlocks.gravewood, 1);
		this.setBlock(world, i + 4, j + 40, k + 19, ModBlocks.gravewood, 1);
		this.setBlock(world, i + 4, j + 40, k + 20, ModBlocks.gravewood, 1);
		this.setBlock(world, i + 4, j + 40, k + 21, ModBlocks.gravewood, 1);
		this.setBlock(world, i + 4, j + 40, k + 30, ModBlocks.gravewood, 1);
		this.setBlock(world, i + 4, j + 40, k + 31, ModBlocks.gravewood, 1);
		this.setBlock(world, i + 4, j + 41, k + 12, ModBlocks.gravewoodLeaves, 0);
		this.setBlock(world, i + 4, j + 41, k + 13, ModBlocks.gravewoodLeaves, 0);
		this.setBlock(world, i + 4, j + 41, k + 14, ModBlocks.gravewoodLeaves, 0);
		this.setBlock(world, i + 4, j + 41, k + 15, ModBlocks.gravewoodLeaves, 0);
		this.setBlock(world, i + 4, j + 41, k + 16, ModBlocks.gravewoodLeaves, 0);
		this.setBlock(world, i + 4, j + 41, k + 17, ModBlocks.gravewoodLeaves, 0);
		this.setBlock(world, i + 4, j + 41, k + 18, ModBlocks.gravewood, 1);
		this.setBlock(world, i + 4, j + 41, k + 19, ModBlocks.gravewood, 1);
		this.setBlock(world, i + 4, j + 41, k + 20, ModBlocks.gravewood, 1);
		this.setBlock(world, i + 4, j + 41, k + 21, ModBlocks.gravewood, 1);
		this.setBlock(world, i + 4, j + 41, k + 22, ModBlocks.gravewood, 1);
		this.setBlock(world, i + 4, j + 41, k + 23, ModBlocks.gravewood, 1);
		this.setBlock(world, i + 4, j + 41, k + 28, ModBlocks.gravewoodLeaves, 0);
		this.setBlock(world, i + 4, j + 41, k + 29, ModBlocks.gravewood, 1);
		this.setBlock(world, i + 4, j + 41, k + 30, ModBlocks.gravewood, 1);
		this.setBlock(world, i + 4, j + 41, k + 31, ModBlocks.gravewood, 1);
		this.setBlock(world, i + 4, j + 41, k + 32, ModBlocks.gravewoodLeaves, 0);
		this.setBlock(world, i + 4, j + 42, k + 11, ModBlocks.gravewoodLeaves, 0);
		this.setBlock(world, i + 4, j + 42, k + 12, ModBlocks.gravewoodLeaves, 0);
		this.setBlock(world, i + 4, j + 42, k + 13, ModBlocks.gravewoodLeaves, 0);
		this.setBlock(world, i + 4, j + 42, k + 14, ModBlocks.gravewoodLeaves, 0);
		this.setBlock(world, i + 4, j + 42, k + 15, ModBlocks.gravewoodLeaves, 0);
		this.setBlock(world, i + 4, j + 42, k + 16, ModBlocks.gravewoodLeaves, 0);
		this.setBlock(world, i + 4, j + 42, k + 17, ModBlocks.gravewoodLeaves, 0);
		this.setBlock(world, i + 4, j + 42, k + 18, ModBlocks.gravewood, 1);
		this.setBlock(world, i + 4, j + 42, k + 19, ModBlocks.gravewood, 1);
		this.setBlock(world, i + 4, j + 42, k + 20, ModBlocks.gravewood, 1);
		this.setBlock(world, i + 4, j + 42, k + 21, ModBlocks.gravewood, 1);
		this.setBlock(world, i + 4, j + 42, k + 22, ModBlocks.gravewood, 1);
		this.setBlock(world, i + 4, j + 42, k + 23, ModBlocks.gravewoodLeaves, 0);
		this.setBlock(world, i + 4, j + 42, k + 24, ModBlocks.gravewoodLeaves, 0);
		this.setBlock(world, i + 4, j + 42, k + 25, ModBlocks.gravewood, 1);
		this.setBlock(world, i + 4, j + 42, k + 26, ModBlocks.gravewoodLeaves, 0);
		this.setBlock(world, i + 4, j + 42, k + 27, ModBlocks.gravewoodLeaves, 0);
		this.setBlock(world, i + 4, j + 42, k + 28, ModBlocks.gravewoodLeaves, 0);
		this.setBlock(world, i + 4, j + 42, k + 29, ModBlocks.gravewoodLeaves, 0);
		this.setBlock(world, i + 4, j + 42, k + 30, ModBlocks.gravewood, 1);
		this.setBlock(world, i + 4, j + 42, k + 31, ModBlocks.gravewoodLeaves, 0);
		this.setBlock(world, i + 4, j + 42, k + 32, ModBlocks.gravewoodLeaves, 0);
		this.setBlock(world, i + 4, j + 43, k + 11, ModBlocks.gravewoodLeaves, 0);
		this.setBlock(world, i + 4, j + 43, k + 12, ModBlocks.gravewoodLeaves, 0);
		this.setBlock(world, i + 4, j + 43, k + 13, ModBlocks.gravewoodLeaves, 0);
		this.setBlock(world, i + 4, j + 43, k + 14, ModBlocks.gravewoodLeaves, 0);
		this.setBlock(world, i + 4, j + 43, k + 15, ModBlocks.gravewoodLeaves, 0);
		this.setBlock(world, i + 4, j + 43, k + 16, ModBlocks.gravewoodLeaves, 0);
		this.setBlock(world, i + 4, j + 43, k + 17, ModBlocks.gravewood, 1);
		this.setBlock(world, i + 4, j + 43, k + 18, ModBlocks.gravewoodLeaves, 0);
		this.setBlock(world, i + 4, j + 43, k + 19, ModBlocks.gravewoodLeaves, 0);
		this.setBlock(world, i + 4, j + 43, k + 20, ModBlocks.gravewood, 1);
		this.setBlock(world, i + 4, j + 43, k + 21, ModBlocks.gravewoodLeaves, 0);
		this.setBlock(world, i + 4, j + 43, k + 22, ModBlocks.gravewoodLeaves, 0);
		this.setBlock(world, i + 4, j + 43, k + 23, ModBlocks.gravewoodLeaves, 0);
		this.setBlock(world, i + 4, j + 43, k + 24, ModBlocks.gravewoodLeaves, 0);
		this.setBlock(world, i + 4, j + 43, k + 25, ModBlocks.gravewood, 1);
		this.setBlock(world, i + 4, j + 43, k + 26, ModBlocks.gravewoodLeaves, 0);
		this.setBlock(world, i + 4, j + 43, k + 27, ModBlocks.gravewoodLeaves, 0);
		this.setBlock(world, i + 4, j + 43, k + 28, ModBlocks.gravewoodLeaves, 0);
		this.setBlock(world, i + 4, j + 43, k + 29, ModBlocks.gravewoodLeaves, 0);
		this.setBlock(world, i + 4, j + 43, k + 30, ModBlocks.gravewoodLeaves, 0);
		this.setBlock(world, i + 4, j + 43, k + 31, ModBlocks.gravewoodLeaves, 0);
		this.setBlock(world, i + 4, j + 43, k + 32, ModBlocks.gravewoodLeaves, 0);
		this.setBlock(world, i + 4, j + 44, k + 11, ModBlocks.gravewoodLeaves, 8);
		this.setBlock(world, i + 4, j + 44, k + 12, ModBlocks.gravewoodLeaves, 0);
		this.setBlock(world, i + 4, j + 44, k + 13, ModBlocks.gravewoodLeaves, 0);
		this.setBlock(world, i + 4, j + 44, k + 14, ModBlocks.gravewoodLeaves, 0);
		this.setBlock(world, i + 4, j + 44, k + 15, ModBlocks.gravewoodLeaves, 0);
		this.setBlock(world, i + 4, j + 44, k + 16, ModBlocks.gravewoodLeaves, 0);
		this.setBlock(world, i + 4, j + 44, k + 17, ModBlocks.gravewoodLeaves, 0);
		this.setBlock(world, i + 4, j + 44, k + 18, ModBlocks.gravewoodLeaves, 0);
		this.setBlock(world, i + 4, j + 44, k + 19, ModBlocks.gravewoodLeaves, 0);
		this.setBlock(world, i + 4, j + 44, k + 20, ModBlocks.gravewoodLeaves, 0);
		this.setBlock(world, i + 4, j + 44, k + 21, ModBlocks.gravewoodLeaves, 0);
		this.setBlock(world, i + 4, j + 44, k + 22, ModBlocks.gravewoodLeaves, 0);
		this.setBlock(world, i + 4, j + 44, k + 23, ModBlocks.gravewoodLeaves, 0);
		this.setBlock(world, i + 4, j + 44, k + 24, ModBlocks.gravewoodLeaves, 0);
		this.setBlock(world, i + 4, j + 44, k + 25, ModBlocks.gravewoodLeaves, 0);
		this.setBlock(world, i + 4, j + 44, k + 26, ModBlocks.gravewoodLeaves, 0);
		this.setBlock(world, i + 4, j + 44, k + 27, ModBlocks.gravewoodLeaves, 0);
		this.setBlock(world, i + 4, j + 44, k + 28, ModBlocks.gravewoodLeaves, 0);
		this.setBlock(world, i + 4, j + 44, k + 29, ModBlocks.gravewoodLeaves, 0);
		this.setBlock(world, i + 5, j + 40, k + 18, ModBlocks.gravewood, 1);
		this.setBlock(world, i + 5, j + 40, k + 19, ModBlocks.gravewood, 1);
		this.setBlock(world, i + 5, j + 40, k + 20, ModBlocks.gravewood, 1);
		this.setBlock(world, i + 5, j + 40, k + 21, ModBlocks.gravewood, 1);
		this.setBlock(world, i + 5, j + 40, k + 22, ModBlocks.gravewood, 1);
		this.setBlock(world, i + 5, j + 40, k + 29, ModBlocks.gravewood, 1);
		this.setBlock(world, i + 5, j + 40, k + 30, ModBlocks.gravewood, 1);
		this.setBlock(world, i + 5, j + 40, k + 31, ModBlocks.gravewood, 1);
		this.setBlock(world, i + 5, j + 40, k + 32, ModBlocks.gravewoodLeaves, 0);
		this.setBlock(world, i + 5, j + 40, k + 33, ModBlocks.gravewood, 1);
		this.setBlock(world, i + 5, j + 40, k + 34, ModBlocks.gravewood, 1);
		this.setBlock(world, i + 5, j + 40, k + 35, ModBlocks.gravewood, 1);
		this.setBlock(world, i + 5, j + 41, k + 11, ModBlocks.gravewoodLeaves, 0);
		this.setBlock(world, i + 5, j + 41, k + 12, ModBlocks.gravewoodLeaves, 0);
		this.setBlock(world, i + 5, j + 41, k + 13, ModBlocks.gravewood, 1);
		this.setBlock(world, i + 5, j + 41, k + 14, ModBlocks.gravewoodLeaves, 0);
		this.setBlock(world, i + 5, j + 41, k + 15, ModBlocks.gravewoodLeaves, 0);
		this.setBlock(world, i + 5, j + 41, k + 16, ModBlocks.gravewoodLeaves, 0);
		this.setBlock(world, i + 5, j + 41, k + 17, ModBlocks.gravewoodLeaves, 0);
		this.setBlock(world, i + 5, j + 41, k + 18, ModBlocks.gravewood, 1);
		this.setBlock(world, i + 5, j + 41, k + 19, ModBlocks.gravewood, 1);
		this.setBlock(world, i + 5, j + 41, k + 20, ModBlocks.gravewood, 1);
		this.setBlock(world, i + 5, j + 41, k + 21, ModBlocks.gravewood, 1);
		this.setBlock(world, i + 5, j + 41, k + 22, ModBlocks.gravewood, 1);
		this.setBlock(world, i + 5, j + 41, k + 23, ModBlocks.gravewood, 1);
		this.setBlock(world, i + 5, j + 41, k + 24, ModBlocks.gravewood, 1);
		this.setBlock(world, i + 5, j + 41, k + 25, ModBlocks.gravewood, 1);
		this.setBlock(world, i + 5, j + 41, k + 26, ModBlocks.gravewood, 1);
		this.setBlock(world, i + 5, j + 41, k + 27, ModBlocks.gravewoodLeaves, 0);
		this.setBlock(world, i + 5, j + 41, k + 28, ModBlocks.gravewoodLeaves, 0);
		this.setBlock(world, i + 5, j + 41, k + 29, ModBlocks.gravewood, 1);
		this.setBlock(world, i + 5, j + 41, k + 30, ModBlocks.gravewood, 1);
		this.setBlock(world, i + 5, j + 41, k + 31, ModBlocks.gravewood, 1);
		this.setBlock(world, i + 5, j + 41, k + 32, ModBlocks.gravewoodLeaves, 0);
		this.setBlock(world, i + 5, j + 41, k + 33, ModBlocks.gravewoodLeaves, 0);
		this.setBlock(world, i + 5, j + 41, k + 34, ModBlocks.gravewoodLeaves, 0);
		this.setBlock(world, i + 5, j + 41, k + 35, ModBlocks.gravewoodLeaves, 0);
		this.setBlock(world, i + 5, j + 42, k + 11, ModBlocks.gravewoodLeaves, 0);
		this.setBlock(world, i + 5, j + 42, k + 12, ModBlocks.gravewoodLeaves, 0);
		this.setBlock(world, i + 5, j + 42, k + 13, ModBlocks.gravewoodLeaves, 0);
		this.setBlock(world, i + 5, j + 42, k + 14, ModBlocks.gravewoodLeaves, 0);
		this.setBlock(world, i + 5, j + 42, k + 15, ModBlocks.gravewood, 1);
		this.setBlock(world, i + 5, j + 42, k + 16, ModBlocks.gravewoodLeaves, 0);
		this.setBlock(world, i + 5, j + 42, k + 17, ModBlocks.gravewoodLeaves, 0);
		this.setBlock(world, i + 5, j + 42, k + 18, ModBlocks.gravewoodLeaves, 0);
		this.setBlock(world, i + 5, j + 42, k + 19, ModBlocks.gravewood, 1);
		this.setBlock(world, i + 5, j + 42, k + 20, ModBlocks.gravewood, 1);
		this.setBlock(world, i + 5, j + 42, k + 21, ModBlocks.gravewood, 1);
		this.setBlock(world, i + 5, j + 42, k + 22, ModBlocks.gravewoodLeaves, 0);
		this.setBlock(world, i + 5, j + 42, k + 23, ModBlocks.gravewoodLeaves, 0);
		this.setBlock(world, i + 5, j + 42, k + 24, ModBlocks.gravewoodLeaves, 0);
		this.setBlock(world, i + 5, j + 42, k + 25, ModBlocks.gravewood, 1);
		this.setBlock(world, i + 5, j + 42, k + 26, ModBlocks.gravewoodLeaves, 0);
		this.setBlock(world, i + 5, j + 42, k + 27, ModBlocks.gravewoodLeaves, 0);
		this.setBlock(world, i + 5, j + 42, k + 28, ModBlocks.gravewoodLeaves, 0);
		this.setBlock(world, i + 5, j + 42, k + 29, ModBlocks.gravewoodLeaves, 0);
		this.setBlock(world, i + 5, j + 42, k + 30, ModBlocks.gravewood, 1);
		this.setBlock(world, i + 5, j + 42, k + 31, ModBlocks.gravewood, 1);
		this.setBlock(world, i + 5, j + 42, k + 32, ModBlocks.gravewoodLeaves, 0);
		this.setBlock(world, i + 5, j + 42, k + 33, ModBlocks.gravewoodLeaves, 0);
		this.setBlock(world, i + 5, j + 42, k + 34, ModBlocks.gravewoodLeaves, 0);
		this.setBlock(world, i + 5, j + 42, k + 35, ModBlocks.gravewoodLeaves, 0);
		this.setBlock(world, i + 5, j + 43, k + 11, ModBlocks.gravewoodLeaves, 0);
		this.setBlock(world, i + 5, j + 43, k + 12, ModBlocks.gravewoodLeaves, 0);
		this.setBlock(world, i + 5, j + 43, k + 13, ModBlocks.gravewoodLeaves, 0);
		this.setBlock(world, i + 5, j + 43, k + 14, ModBlocks.gravewood, 1);
		this.setBlock(world, i + 5, j + 43, k + 15, ModBlocks.gravewoodLeaves, 0);
		this.setBlock(world, i + 5, j + 43, k + 16, ModBlocks.gravewoodLeaves, 0);
		this.setBlock(world, i + 5, j + 43, k + 17, ModBlocks.gravewoodLeaves, 0);
		this.setBlock(world, i + 5, j + 43, k + 18, ModBlocks.gravewoodLeaves, 0);
		this.setBlock(world, i + 5, j + 43, k + 19, ModBlocks.gravewoodLeaves, 0);
		this.setBlock(world, i + 5, j + 43, k + 20, ModBlocks.gravewoodLeaves, 0);
		this.setBlock(world, i + 5, j + 43, k + 21, ModBlocks.gravewoodLeaves, 0);
		this.setBlock(world, i + 5, j + 43, k + 22, ModBlocks.gravewoodLeaves, 0);
		this.setBlock(world, i + 5, j + 43, k + 23, ModBlocks.gravewoodLeaves, 0);
		this.setBlock(world, i + 5, j + 43, k + 24, ModBlocks.gravewoodLeaves, 0);
		this.setBlock(world, i + 5, j + 43, k + 25, ModBlocks.gravewoodLeaves, 0);
		this.setBlock(world, i + 5, j + 43, k + 26, ModBlocks.gravewoodLeaves, 0);
		this.setBlock(world, i + 5, j + 43, k + 27, ModBlocks.gravewood, 1);
		this.setBlock(world, i + 5, j + 43, k + 28, ModBlocks.gravewoodLeaves, 0);
		this.setBlock(world, i + 5, j + 43, k + 29, ModBlocks.gravewoodLeaves, 0);
		this.setBlock(world, i + 5, j + 43, k + 30, ModBlocks.gravewoodLeaves, 0);
		this.setBlock(world, i + 5, j + 43, k + 31, ModBlocks.gravewoodLeaves, 0);
		this.setBlock(world, i + 5, j + 43, k + 32, ModBlocks.gravewoodLeaves, 0);
		this.setBlock(world, i + 5, j + 43, k + 33, ModBlocks.gravewoodLeaves, 0);
		this.setBlock(world, i + 5, j + 43, k + 34, ModBlocks.gravewoodLeaves, 0);
		this.setBlock(world, i + 5, j + 44, k + 11, ModBlocks.gravewoodLeaves, 0);
		this.setBlock(world, i + 5, j + 44, k + 12, ModBlocks.gravewoodLeaves, 0);
		this.setBlock(world, i + 5, j + 44, k + 13, ModBlocks.gravewoodLeaves, 0);
		this.setBlock(world, i + 5, j + 44, k + 14, ModBlocks.gravewoodLeaves, 0);
		this.setBlock(world, i + 5, j + 44, k + 15, ModBlocks.gravewoodLeaves, 0);
		this.setBlock(world, i + 5, j + 44, k + 16, ModBlocks.gravewoodLeaves, 0);
		this.setBlock(world, i + 5, j + 44, k + 17, ModBlocks.gravewoodLeaves, 0);
		this.setBlock(world, i + 5, j + 44, k + 18, ModBlocks.gravewoodLeaves, 0);
		this.setBlock(world, i + 5, j + 44, k + 19, ModBlocks.gravewoodLeaves, 0);
		this.setBlock(world, i + 5, j + 44, k + 20, ModBlocks.gravewoodLeaves, 0);
		this.setBlock(world, i + 5, j + 44, k + 21, ModBlocks.gravewoodLeaves, 0);
		this.setBlock(world, i + 5, j + 44, k + 22, ModBlocks.gravewoodLeaves, 0);
		this.setBlock(world, i + 5, j + 44, k + 23, ModBlocks.gravewoodLeaves, 0);
		this.setBlock(world, i + 5, j + 44, k + 24, ModBlocks.gravewoodLeaves, 0);
		this.setBlock(world, i + 5, j + 44, k + 25, ModBlocks.gravewoodLeaves, 0);
		this.setBlock(world, i + 5, j + 44, k + 26, ModBlocks.gravewoodLeaves, 0);
		this.setBlock(world, i + 5, j + 44, k + 27, ModBlocks.gravewoodLeaves, 0);
		this.setBlock(world, i + 5, j + 44, k + 28, ModBlocks.gravewoodLeaves, 0);
		this.setBlock(world, i + 5, j + 44, k + 29, ModBlocks.gravewoodLeaves, 0);
		this.setBlock(world, i + 5, j + 45, k + 20, ModBlocks.gravewoodLeaves, 0);
		this.setBlock(world, i + 5, j + 45, k + 21, ModBlocks.gravewoodLeaves, 0);
		this.setBlock(world, i + 5, j + 45, k + 22, ModBlocks.gravewoodLeaves, 0);
		this.setBlock(world, i + 6, j + 39, k + 29, ModBlocks.gravewood, 1);
		this.setBlock(world, i + 6, j + 39, k + 30, ModBlocks.gravewood, 1);
		this.setBlock(world, i + 6, j + 39, k + 31, ModBlocks.gravewood, 1);
		this.setBlock(world, i + 6, j + 39, k + 32, ModBlocks.gravewood, 1);
		this.setBlock(world, i + 6, j + 39, k + 33, ModBlocks.gravewood, 1);
		this.setBlock(world, i + 6, j + 39, k + 34, ModBlocks.gravewood, 1);
		this.setBlock(world, i + 6, j + 39, k + 35, ModBlocks.gravewood, 1);
		this.setBlock(world, i + 6, j + 39, k + 36, ModBlocks.gravewood, 1);
		this.setBlock(world, i + 6, j + 40, k + 18, ModBlocks.gravewood, 1);
		this.setBlock(world, i + 6, j + 40, k + 19, ModBlocks.gravewood, 1);
		this.setBlock(world, i + 6, j + 40, k + 20, ModBlocks.gravewood, 1);
		this.setBlock(world, i + 6, j + 40, k + 21, ModBlocks.gravewood, 1);
		this.setBlock(world, i + 6, j + 40, k + 22, ModBlocks.gravewood, 1);
		this.setBlock(world, i + 6, j + 40, k + 23, ModBlocks.gravewood, 1);
		this.setBlock(world, i + 6, j + 40, k + 24, ModBlocks.gravewood, 1);
		this.setBlock(world, i + 6, j + 40, k + 25, ModBlocks.gravewood, 1);
		this.setBlock(world, i + 6, j + 40, k + 26, ModBlocks.gravewoodLeaves, 0);
		this.setBlock(world, i + 6, j + 40, k + 28, ModBlocks.gravewood, 1);
		this.setBlock(world, i + 6, j + 40, k + 29, ModBlocks.gravewood, 1);
		this.setBlock(world, i + 6, j + 40, k + 30, ModBlocks.gravewood, 1);
		this.setBlock(world, i + 6, j + 40, k + 31, ModBlocks.gravewood, 1);
		this.setBlock(world, i + 6, j + 40, k + 32, ModBlocks.gravewoodLeaves, 0);
		this.setBlock(world, i + 6, j + 40, k + 33, ModBlocks.gravewood, 1);
		this.setBlock(world, i + 6, j + 40, k + 34, ModBlocks.gravewood, 1);
		this.setBlock(world, i + 6, j + 40, k + 35, ModBlocks.gravewood, 1);
		this.setBlock(world, i + 6, j + 40, k + 36, ModBlocks.gravewoodLeaves, 0);
		this.setBlock(world, i + 6, j + 41, k + 12, ModBlocks.gravewood, 1);
		this.setBlock(world, i + 6, j + 41, k + 13, ModBlocks.gravewood, 1);
		this.setBlock(world, i + 6, j + 41, k + 14, ModBlocks.gravewoodLeaves, 0);
		this.setBlock(world, i + 6, j + 41, k + 15, ModBlocks.gravewoodLeaves, 0);
		this.setBlock(world, i + 6, j + 41, k + 16, ModBlocks.gravewoodLeaves, 0);
		this.setBlock(world, i + 6, j + 41, k + 17, ModBlocks.gravewoodLeaves, 0);
		this.setBlock(world, i + 6, j + 41, k + 18, ModBlocks.gravewood, 1);
		this.setBlock(world, i + 6, j + 41, k + 19, ModBlocks.gravewood, 1);
		this.setBlock(world, i + 6, j + 41, k + 20, ModBlocks.gravewood, 1);
		this.setBlock(world, i + 6, j + 41, k + 21, ModBlocks.gravewood, 1);
		this.setBlock(world, i + 6, j + 41, k + 22, ModBlocks.gravewood, 1);
		this.setBlock(world, i + 6, j + 41, k + 23, ModBlocks.gravewood, 1);
		this.setBlock(world, i + 6, j + 41, k + 24, ModBlocks.gravewood, 1);
		this.setBlock(world, i + 6, j + 41, k + 25, ModBlocks.gravewood, 1);
		this.setBlock(world, i + 6, j + 41, k + 26, ModBlocks.gravewoodLeaves, 0);
		this.setBlock(world, i + 6, j + 41, k + 27, ModBlocks.gravewoodLeaves, 0);
		this.setBlock(world, i + 6, j + 41, k + 28, ModBlocks.gravewoodLeaves, 0);
		this.setBlock(world, i + 6, j + 41, k + 29, ModBlocks.gravewood, 1);
		this.setBlock(world, i + 6, j + 41, k + 30, ModBlocks.gravewood, 1);
		this.setBlock(world, i + 6, j + 41, k + 31, ModBlocks.gravewood, 1);
		this.setBlock(world, i + 6, j + 41, k + 32, ModBlocks.gravewoodLeaves, 0);
		this.setBlock(world, i + 6, j + 41, k + 33, ModBlocks.gravewood, 1);
		this.setBlock(world, i + 6, j + 41, k + 34, ModBlocks.gravewood, 1);
		this.setBlock(world, i + 6, j + 41, k + 35, ModBlocks.gravewood, 1);
		this.setBlock(world, i + 6, j + 41, k + 36, ModBlocks.gravewoodLeaves, 0);
		this.setBlock(world, i + 6, j + 42, k + 10, ModBlocks.gravewoodLeaves, 0);
		this.setBlock(world, i + 6, j + 42, k + 11, ModBlocks.gravewoodLeaves, 0);
		this.setBlock(world, i + 6, j + 42, k + 12, ModBlocks.gravewoodLeaves, 0);
		this.setBlock(world, i + 6, j + 42, k + 13, ModBlocks.gravewoodLeaves, 0);
		this.setBlock(world, i + 6, j + 42, k + 14, ModBlocks.gravewood, 1);
		this.setBlock(world, i + 6, j + 42, k + 15, ModBlocks.gravewoodLeaves, 0);
		this.setBlock(world, i + 6, j + 42, k + 16, ModBlocks.gravewoodLeaves, 0);
		this.setBlock(world, i + 6, j + 42, k + 17, ModBlocks.gravewoodLeaves, 0);
		this.setBlock(world, i + 6, j + 42, k + 18, ModBlocks.gravewoodLeaves, 0);
		this.setBlock(world, i + 6, j + 42, k + 19, ModBlocks.gravewood, 1);
		this.setBlock(world, i + 6, j + 42, k + 20, ModBlocks.gravewood, 1);
		this.setBlock(world, i + 6, j + 42, k + 21, ModBlocks.gravewood, 1);
		this.setBlock(world, i + 6, j + 42, k + 22, ModBlocks.gravewood, 1);
		this.setBlock(world, i + 6, j + 42, k + 23, ModBlocks.gravewood, 1);
		this.setBlock(world, i + 6, j + 42, k + 24, ModBlocks.gravewood, 1);
		this.setBlock(world, i + 6, j + 42, k + 25, ModBlocks.gravewood, 1);
		this.setBlock(world, i + 6, j + 42, k + 26, ModBlocks.gravewoodLeaves, 0);
		this.setBlock(world, i + 6, j + 42, k + 27, ModBlocks.gravewoodLeaves, 0);
		this.setBlock(world, i + 6, j + 42, k + 28, ModBlocks.gravewoodLeaves, 0);
		this.setBlock(world, i + 6, j + 42, k + 29, ModBlocks.gravewoodLeaves, 0);
		this.setBlock(world, i + 6, j + 42, k + 30, ModBlocks.gravewood, 1);
		this.setBlock(world, i + 6, j + 42, k + 31, ModBlocks.gravewoodLeaves, 0);
		this.setBlock(world, i + 6, j + 42, k + 32, ModBlocks.gravewoodLeaves, 0);
		this.setBlock(world, i + 6, j + 42, k + 33, ModBlocks.gravewood, 1);
		this.setBlock(world, i + 6, j + 42, k + 34, ModBlocks.gravewood, 1);
		this.setBlock(world, i + 6, j + 42, k + 35, ModBlocks.gravewoodLeaves, 0);
		this.setBlock(world, i + 6, j + 42, k + 36, ModBlocks.gravewoodLeaves, 0);
		this.setBlock(world, i + 6, j + 43, k + 10, ModBlocks.gravewoodLeaves, 0);
		this.setBlock(world, i + 6, j + 43, k + 11, ModBlocks.gravewoodLeaves, 0);
		this.setBlock(world, i + 6, j + 43, k + 12, ModBlocks.gravewoodLeaves, 0);
		this.setBlock(world, i + 6, j + 43, k + 13, ModBlocks.gravewoodLeaves, 0);
		this.setBlock(world, i + 6, j + 43, k + 14, ModBlocks.gravewoodLeaves, 0);
		this.setBlock(world, i + 6, j + 43, k + 15, ModBlocks.gravewoodLeaves, 0);
		this.setBlock(world, i + 6, j + 43, k + 16, ModBlocks.gravewoodLeaves, 0);
		this.setBlock(world, i + 6, j + 43, k + 17, ModBlocks.gravewoodLeaves, 0);
		this.setBlock(world, i + 6, j + 43, k + 18, ModBlocks.gravewoodLeaves, 0);
		this.setBlock(world, i + 6, j + 43, k + 19, ModBlocks.gravewoodLeaves, 0);
		this.setBlock(world, i + 6, j + 43, k + 20, ModBlocks.gravewood, 1);
		this.setBlock(world, i + 6, j + 43, k + 21, ModBlocks.gravewoodLeaves, 0);
		this.setBlock(world, i + 6, j + 43, k + 22, ModBlocks.gravewood, 1);
		this.setBlock(world, i + 6, j + 43, k + 23, ModBlocks.gravewoodLeaves, 0);
		this.setBlock(world, i + 6, j + 43, k + 24, ModBlocks.gravewood, 1);
		this.setBlock(world, i + 6, j + 43, k + 25, ModBlocks.gravewoodLeaves, 0);
		this.setBlock(world, i + 6, j + 43, k + 26, ModBlocks.gravewood, 1);
		this.setBlock(world, i + 6, j + 43, k + 27, ModBlocks.gravewoodLeaves, 0);
		this.setBlock(world, i + 6, j + 43, k + 28, ModBlocks.gravewoodLeaves, 0);
		this.setBlock(world, i + 6, j + 43, k + 29, ModBlocks.gravewood, 1);
		this.setBlock(world, i + 6, j + 43, k + 30, ModBlocks.gravewoodLeaves, 0);
		this.setBlock(world, i + 6, j + 43, k + 31, ModBlocks.gravewoodLeaves, 0);
		this.setBlock(world, i + 6, j + 43, k + 32, ModBlocks.gravewoodLeaves, 0);
		this.setBlock(world, i + 6, j + 43, k + 33, ModBlocks.gravewoodLeaves, 0);
		this.setBlock(world, i + 6, j + 43, k + 34, ModBlocks.gravewoodLeaves, 0);
		this.setBlock(world, i + 6, j + 43, k + 35, ModBlocks.gravewoodLeaves, 0);
		this.setBlock(world, i + 6, j + 44, k + 11, ModBlocks.gravewoodLeaves, 0);
		this.setBlock(world, i + 6, j + 44, k + 12, ModBlocks.gravewoodLeaves, 0);
		this.setBlock(world, i + 6, j + 44, k + 13, ModBlocks.gravewoodLeaves, 0);
		this.setBlock(world, i + 6, j + 44, k + 14, ModBlocks.gravewoodLeaves, 0);
		this.setBlock(world, i + 6, j + 44, k + 15, ModBlocks.gravewoodLeaves, 0);
		this.setBlock(world, i + 6, j + 44, k + 16, ModBlocks.gravewoodLeaves, 0);
		this.setBlock(world, i + 6, j + 44, k + 17, ModBlocks.gravewoodLeaves, 0);
		this.setBlock(world, i + 6, j + 44, k + 18, ModBlocks.gravewoodLeaves, 0);
		this.setBlock(world, i + 6, j + 44, k + 19, ModBlocks.gravewoodLeaves, 0);
		this.setBlock(world, i + 6, j + 44, k + 20, ModBlocks.gravewoodLeaves, 0);
		this.setBlock(world, i + 6, j + 44, k + 21, ModBlocks.gravewood, 1);
		this.setBlock(world, i + 6, j + 44, k + 22, ModBlocks.gravewoodLeaves, 0);
		this.setBlock(world, i + 6, j + 44, k + 23, ModBlocks.gravewood, 1);
		this.setBlock(world, i + 6, j + 44, k + 24, ModBlocks.gravewoodLeaves, 0);
		this.setBlock(world, i + 6, j + 44, k + 25, ModBlocks.gravewoodLeaves, 0);
		this.setBlock(world, i + 6, j + 44, k + 26, ModBlocks.gravewoodLeaves, 0);
		this.setBlock(world, i + 6, j + 44, k + 27, ModBlocks.gravewoodLeaves, 0);
		this.setBlock(world, i + 6, j + 44, k + 28, ModBlocks.gravewoodLeaves, 0);
		this.setBlock(world, i + 6, j + 44, k + 29, ModBlocks.gravewoodLeaves, 0);
		this.setBlock(world, i + 6, j + 45, k + 20, ModBlocks.gravewoodLeaves, 0);
		this.setBlock(world, i + 6, j + 45, k + 21, ModBlocks.gravewoodLeaves, 0);
		this.setBlock(world, i + 6, j + 45, k + 22, ModBlocks.gravewoodLeaves, 0);
		this.setBlock(world, i + 6, j + 45, k + 23, ModBlocks.gravewoodLeaves, 0);
		this.setBlock(world, i + 7, j + 39, k + 20, ModBlocks.gravewood, 1);
		this.setBlock(world, i + 7, j + 39, k + 21, ModBlocks.gravewood, 1);
		this.setBlock(world, i + 7, j + 39, k + 22, ModBlocks.gravewood, 1);
		this.setBlock(world, i + 7, j + 39, k + 23, ModBlocks.gravewood, 1);
		this.setBlock(world, i + 7, j + 39, k + 27, ModBlocks.gravewoodLeaves, 0);
		this.setBlock(world, i + 7, j + 39, k + 28, ModBlocks.gravewood, 1);
		this.setBlock(world, i + 7, j + 39, k + 29, ModBlocks.gravewood, 1);
		this.setBlock(world, i + 7, j + 39, k + 30, ModBlocks.gravewood, 1);
		this.setBlock(world, i + 7, j + 39, k + 31, ModBlocks.gravewood, 1);
		this.setBlock(world, i + 7, j + 39, k + 32, ModBlocks.gravewood, 1);
		this.setBlock(world, i + 7, j + 39, k + 33, ModBlocks.gravewood, 1);
		this.setBlock(world, i + 7, j + 39, k + 34, ModBlocks.gravewood, 1);
		this.setBlock(world, i + 7, j + 39, k + 35, ModBlocks.gravewood, 1);
		this.setBlock(world, i + 7, j + 39, k + 36, ModBlocks.gravewood, 1);
		this.setBlock(world, i + 7, j + 40, k + 17, ModBlocks.gravewood, 1);
		this.setBlock(world, i + 7, j + 40, k + 18, ModBlocks.gravewoodLeaves, 0);
		this.setBlock(world, i + 7, j + 40, k + 19, ModBlocks.gravewood, 1);
		this.setBlock(world, i + 7, j + 40, k + 20, ModBlocks.gravewood, 1);
		this.setBlock(world, i + 7, j + 40, k + 21, ModBlocks.gravewood, 1);
		this.setBlock(world, i + 7, j + 40, k + 22, ModBlocks.gravewood, 1);
		this.setBlock(world, i + 7, j + 40, k + 23, ModBlocks.gravewood, 1);
		this.setBlock(world, i + 7, j + 40, k + 24, ModBlocks.gravewood, 1);
		this.setBlock(world, i + 7, j + 40, k + 25, ModBlocks.gravewoodLeaves, 0);
		this.setBlock(world, i + 7, j + 40, k + 26, ModBlocks.gravewood, 1);
		this.setBlock(world, i + 7, j + 40, k + 27, ModBlocks.gravewoodLeaves, 0);
		this.setBlock(world, i + 7, j + 40, k + 28, ModBlocks.gravewoodLeaves, 0);
		this.setBlock(world, i + 7, j + 40, k + 29, ModBlocks.gravewoodLeaves, 0);
		this.setBlock(world, i + 7, j + 40, k + 30, ModBlocks.gravewood, 1);
		this.setBlock(world, i + 7, j + 40, k + 31, ModBlocks.gravewood, 1);
		this.setBlock(world, i + 7, j + 40, k + 32, ModBlocks.gravewood, 1);
		this.setBlock(world, i + 7, j + 40, k + 33, ModBlocks.gravewood, 1);
		this.setBlock(world, i + 7, j + 40, k + 34, ModBlocks.gravewood, 1);
		this.setBlock(world, i + 7, j + 40, k + 35, ModBlocks.gravewood, 1);
		this.setBlock(world, i + 7, j + 40, k + 36, ModBlocks.gravewood, 1);
		this.setBlock(world, i + 7, j + 41, k + 10, ModBlocks.gravewoodLeaves, 0);
		this.setBlock(world, i + 7, j + 41, k + 11, ModBlocks.gravewoodLeaves, 0);
		this.setBlock(world, i + 7, j + 41, k + 12, ModBlocks.gravewoodLeaves, 0);
		this.setBlock(world, i + 7, j + 41, k + 13, ModBlocks.gravewood, 1);
		this.setBlock(world, i + 7, j + 41, k + 14, ModBlocks.gravewood, 1);
		this.setBlock(world, i + 7, j + 41, k + 15, ModBlocks.gravewoodLeaves, 0);
		this.setBlock(world, i + 7, j + 41, k + 16, ModBlocks.gravewoodLeaves, 0);
		this.setBlock(world, i + 7, j + 41, k + 17, ModBlocks.gravewoodLeaves, 0);
		this.setBlock(world, i + 7, j + 41, k + 18, ModBlocks.gravewoodLeaves, 0);
		this.setBlock(world, i + 7, j + 41, k + 19, ModBlocks.gravewood, 1);
		this.setBlock(world, i + 7, j + 41, k + 20, ModBlocks.gravewood, 1);
		this.setBlock(world, i + 7, j + 41, k + 21, ModBlocks.gravewood, 1);
		this.setBlock(world, i + 7, j + 41, k + 22, ModBlocks.gravewood, 1);
		this.setBlock(world, i + 7, j + 41, k + 23, ModBlocks.gravewood, 1);
		this.setBlock(world, i + 7, j + 41, k + 24, ModBlocks.gravewood, 1);
		this.setBlock(world, i + 7, j + 41, k + 25, ModBlocks.gravewoodLeaves, 0);
		this.setBlock(world, i + 7, j + 41, k + 26, ModBlocks.gravewoodLeaves, 0);
		this.setBlock(world, i + 7, j + 41, k + 27, ModBlocks.gravewoodLeaves, 0);
		this.setBlock(world, i + 7, j + 41, k + 28, ModBlocks.gravewoodLeaves, 0);
		this.setBlock(world, i + 7, j + 41, k + 29, ModBlocks.gravewoodLeaves, 0);
		this.setBlock(world, i + 7, j + 41, k + 30, ModBlocks.gravewood, 1);
		this.setBlock(world, i + 7, j + 41, k + 31, ModBlocks.gravewood, 1);
		this.setBlock(world, i + 7, j + 41, k + 32, ModBlocks.gravewood, 1);
		this.setBlock(world, i + 7, j + 41, k + 33, ModBlocks.gravewood, 1);
		this.setBlock(world, i + 7, j + 41, k + 34, ModBlocks.gravewood, 1);
		this.setBlock(world, i + 7, j + 41, k + 35, ModBlocks.gravewood, 1);
		this.setBlock(world, i + 7, j + 41, k + 36, ModBlocks.gravewoodLeaves, 0);
		this.setBlock(world, i + 7, j + 42, k + 9, ModBlocks.gravewoodLeaves, 0);
		this.setBlock(world, i + 7, j + 42, k + 10, ModBlocks.gravewoodLeaves, 0);
		this.setBlock(world, i + 7, j + 42, k + 11, ModBlocks.gravewoodLeaves, 0);
		this.setBlock(world, i + 7, j + 42, k + 12, ModBlocks.gravewoodLeaves, 0);
		this.setBlock(world, i + 7, j + 42, k + 13, ModBlocks.gravewoodLeaves, 0);
		this.setBlock(world, i + 7, j + 42, k + 14, ModBlocks.gravewoodLeaves, 0);
		this.setBlock(world, i + 7, j + 42, k + 15, ModBlocks.gravewoodLeaves, 0);
		this.setBlock(world, i + 7, j + 42, k + 16, ModBlocks.gravewoodLeaves, 0);
		this.setBlock(world, i + 7, j + 42, k + 17, ModBlocks.gravewoodLeaves, 0);
		this.setBlock(world, i + 7, j + 42, k + 18, ModBlocks.gravewoodLeaves, 0);
		this.setBlock(world, i + 7, j + 42, k + 19, ModBlocks.gravewood, 1);
		this.setBlock(world, i + 7, j + 42, k + 20, ModBlocks.gravewood, 1);
		this.setBlock(world, i + 7, j + 42, k + 21, ModBlocks.gravewood, 1);
		this.setBlock(world, i + 7, j + 42, k + 22, ModBlocks.gravewood, 1);
		this.setBlock(world, i + 7, j + 42, k + 23, ModBlocks.gravewood, 1);
		this.setBlock(world, i + 7, j + 42, k + 24, ModBlocks.gravewood, 1);
		this.setBlock(world, i + 7, j + 42, k + 25, ModBlocks.gravewoodLeaves, 0);
		this.setBlock(world, i + 7, j + 42, k + 26, ModBlocks.gravewoodLeaves, 0);
		this.setBlock(world, i + 7, j + 42, k + 27, ModBlocks.gravewoodLeaves, 0);
		this.setBlock(world, i + 7, j + 42, k + 28, ModBlocks.gravewoodLeaves, 0);
		this.setBlock(world, i + 7, j + 42, k + 29, ModBlocks.gravewoodLeaves, 0);
		this.setBlock(world, i + 7, j + 42, k + 30, ModBlocks.gravewoodLeaves, 0);
		this.setBlock(world, i + 7, j + 42, k + 31, ModBlocks.gravewoodLeaves, 0);
		this.setBlock(world, i + 7, j + 42, k + 32, ModBlocks.gravewoodLeaves, 0);
		this.setBlock(world, i + 7, j + 42, k + 33, ModBlocks.gravewood, 1);
		this.setBlock(world, i + 7, j + 42, k + 34, ModBlocks.gravewood, 1);
		this.setBlock(world, i + 7, j + 42, k + 35, ModBlocks.gravewoodLeaves, 0);
		this.setBlock(world, i + 7, j + 42, k + 36, ModBlocks.gravewoodLeaves, 0);
		this.setBlock(world, i + 7, j + 43, k + 9, ModBlocks.gravewoodLeaves, 0);
		this.setBlock(world, i + 7, j + 43, k + 10, ModBlocks.gravewoodLeaves, 0);
		this.setBlock(world, i + 7, j + 43, k + 11, ModBlocks.gravewoodLeaves, 0);
		this.setBlock(world, i + 7, j + 43, k + 12, ModBlocks.gravewood, 1);
		this.setBlock(world, i + 7, j + 43, k + 13, ModBlocks.gravewoodLeaves, 0);
		this.setBlock(world, i + 7, j + 43, k + 14, ModBlocks.gravewoodLeaves, 0);
		this.setBlock(world, i + 7, j + 43, k + 15, ModBlocks.gravewoodLeaves, 0);
		this.setBlock(world, i + 7, j + 43, k + 16, ModBlocks.gravewoodLeaves, 0);
		this.setBlock(world, i + 7, j + 43, k + 17, ModBlocks.gravewoodLeaves, 0);
		this.setBlock(world, i + 7, j + 43, k + 18, ModBlocks.gravewoodLeaves, 0);
		this.setBlock(world, i + 7, j + 43, k + 19, ModBlocks.gravewoodLeaves, 0);
		this.setBlock(world, i + 7, j + 43, k + 20, ModBlocks.gravewoodLeaves, 0);
		this.setBlock(world, i + 7, j + 43, k + 21, ModBlocks.gravewood, 1);
		this.setBlock(world, i + 7, j + 43, k + 22, ModBlocks.gravewoodLeaves, 0);
		this.setBlock(world, i + 7, j + 43, k + 23, ModBlocks.gravewood, 1);
		this.setBlock(world, i + 7, j + 43, k + 24, ModBlocks.gravewoodLeaves, 0);
		this.setBlock(world, i + 7, j + 43, k + 25, ModBlocks.gravewoodLeaves, 0);
		this.setBlock(world, i + 7, j + 43, k + 26, ModBlocks.gravewood, 1);
		this.setBlock(world, i + 7, j + 43, k + 27, ModBlocks.gravewoodLeaves, 0);
		this.setBlock(world, i + 7, j + 43, k + 28, ModBlocks.gravewoodLeaves, 0);
		this.setBlock(world, i + 7, j + 43, k + 29, ModBlocks.gravewoodLeaves, 0);
		this.setBlock(world, i + 7, j + 43, k + 30, ModBlocks.gravewoodLeaves, 0);
		this.setBlock(world, i + 7, j + 43, k + 31, ModBlocks.gravewoodLeaves, 0);
		this.setBlock(world, i + 7, j + 43, k + 32, ModBlocks.gravewoodLeaves, 0);
		this.setBlock(world, i + 7, j + 43, k + 33, ModBlocks.gravewoodLeaves, 0);
		this.setBlock(world, i + 7, j + 43, k + 34, ModBlocks.gravewoodLeaves, 0);
		this.setBlock(world, i + 7, j + 43, k + 35, ModBlocks.gravewoodLeaves, 0);
		this.setBlock(world, i + 7, j + 43, k + 36, ModBlocks.gravewoodLeaves, 0);
		this.setBlock(world, i + 7, j + 44, k + 10, ModBlocks.gravewoodLeaves, 0);
		this.setBlock(world, i + 7, j + 44, k + 11, ModBlocks.gravewoodLeaves, 0);
		this.setBlock(world, i + 7, j + 44, k + 12, ModBlocks.gravewoodLeaves, 0);
		this.setBlock(world, i + 7, j + 44, k + 13, ModBlocks.gravewood, 1);
		this.setBlock(world, i + 7, j + 44, k + 14, ModBlocks.gravewoodLeaves, 0);
		this.setBlock(world, i + 7, j + 44, k + 15, ModBlocks.gravewoodLeaves, 0);
		this.setBlock(world, i + 7, j + 44, k + 16, ModBlocks.gravewoodLeaves, 0);
		this.setBlock(world, i + 7, j + 44, k + 17, ModBlocks.gravewoodLeaves, 0);
		this.setBlock(world, i + 7, j + 44, k + 18, ModBlocks.gravewoodLeaves, 0);
		this.setBlock(world, i + 7, j + 44, k + 19, ModBlocks.gravewoodLeaves, 0);
		this.setBlock(world, i + 7, j + 44, k + 20, ModBlocks.gravewoodLeaves, 0);
		this.setBlock(world, i + 7, j + 44, k + 21, ModBlocks.gravewoodLeaves, 0);
		this.setBlock(world, i + 7, j + 44, k + 22, ModBlocks.gravewoodLeaves, 0);
		this.setBlock(world, i + 7, j + 44, k + 23, ModBlocks.gravewood, 1);
		this.setBlock(world, i + 7, j + 44, k + 24, ModBlocks.gravewoodLeaves, 0);
		this.setBlock(world, i + 7, j + 44, k + 25, ModBlocks.gravewoodLeaves, 0);
		this.setBlock(world, i + 7, j + 44, k + 26, ModBlocks.gravewoodLeaves, 0);
		this.setBlock(world, i + 7, j + 44, k + 27, ModBlocks.gravewoodLeaves, 0);
		this.setBlock(world, i + 7, j + 44, k + 32, ModBlocks.gravewoodLeaves, 0);
		this.setBlock(world, i + 7, j + 44, k + 33, ModBlocks.gravewoodLeaves, 0);
		this.setBlock(world, i + 7, j + 44, k + 34, ModBlocks.gravewoodLeaves, 0);
		this.setBlock(world, i + 7, j + 45, k + 11, ModBlocks.gravewoodLeaves, 0);
		this.setBlock(world, i + 7, j + 45, k + 12, ModBlocks.gravewoodLeaves, 0);
		this.setBlock(world, i + 7, j + 45, k + 13, ModBlocks.gravewoodLeaves, 0);
		this.setBlock(world, i + 7, j + 45, k + 14, ModBlocks.gravewoodLeaves, 0);
		this.setBlock(world, i + 7, j + 45, k + 20, ModBlocks.gravewoodLeaves, 0);
		this.setBlock(world, i + 7, j + 45, k + 21, ModBlocks.gravewoodLeaves, 0);
		this.setBlock(world, i + 7, j + 45, k + 22, ModBlocks.gravewoodLeaves, 0);
		this.setBlock(world, i + 7, j + 45, k + 23, ModBlocks.gravewoodLeaves, 0);
		this.setBlock(world, i + 8, j + 38, k + 28, ModBlocks.gravewoodLeaves, 0);
		this.setBlock(world, i + 8, j + 38, k + 29, ModBlocks.gravewoodLeaves, 0);
		this.setBlock(world, i + 8, j + 38, k + 30, ModBlocks.gravewood, 1);
		this.setBlock(world, i + 8, j + 38, k + 31, ModBlocks.gravewood, 1);
		this.setBlock(world, i + 8, j + 38, k + 32, ModBlocks.gravewood, 1);
		this.setBlock(world, i + 8, j + 39, k + 8, ModBlocks.gravewood, 1);
		this.setBlock(world, i + 8, j + 39, k + 9, ModBlocks.gravewood, 1);
		this.setBlock(world, i + 8, j + 39, k + 10, ModBlocks.gravewoodLeaves, 0);
		this.setBlock(world, i + 8, j + 39, k + 11, ModBlocks.gravewoodLeaves, 0);
		this.setBlock(world, i + 8, j + 39, k + 19, ModBlocks.gravewoodLeaves, 0);
		this.setBlock(world, i + 8, j + 39, k + 20, ModBlocks.gravewood, 1);
		this.setBlock(world, i + 8, j + 39, k + 21, ModBlocks.gravewood, 1);
		this.setBlock(world, i + 8, j + 39, k + 22, ModBlocks.gravewood, 1);
		this.setBlock(world, i + 8, j + 39, k + 23, ModBlocks.gravewood, 1);
		this.setBlock(world, i + 8, j + 39, k + 24, ModBlocks.gravewoodLeaves, 0);
		this.setBlock(world, i + 8, j + 39, k + 25, ModBlocks.gravewoodLeaves, 0);
		this.setBlock(world, i + 8, j + 39, k + 26, ModBlocks.gravewoodLeaves, 0);
		this.setBlock(world, i + 8, j + 39, k + 27, ModBlocks.gravewoodLeaves, 0);
		this.setBlock(world, i + 8, j + 39, k + 28, ModBlocks.gravewoodLeaves, 0);
		this.setBlock(world, i + 8, j + 39, k + 29, ModBlocks.gravewood, 1);
		this.setBlock(world, i + 8, j + 39, k + 30, ModBlocks.gravewood, 1);
		this.setBlock(world, i + 8, j + 39, k + 31, ModBlocks.gravewood, 1);
		this.setBlock(world, i + 8, j + 39, k + 32, ModBlocks.gravewood, 1);
		this.setBlock(world, i + 8, j + 39, k + 33, ModBlocks.gravewood, 1);
		this.setBlock(world, i + 8, j + 39, k + 34, ModBlocks.gravewood, 1);
		this.setBlock(world, i + 8, j + 39, k + 35, ModBlocks.gravewood, 1);
		this.setBlock(world, i + 8, j + 39, k + 36, ModBlocks.gravewoodLeaves, 0);
		this.setBlock(world, i + 8, j + 40, k + 8, ModBlocks.gravewoodLeaves, 0);
		this.setBlock(world, i + 8, j + 40, k + 9, ModBlocks.gravewood, 1);
		this.setBlock(world, i + 8, j + 40, k + 10, ModBlocks.gravewoodLeaves, 0);
		this.setBlock(world, i + 8, j + 40, k + 11, ModBlocks.gravewood, 1);
		this.setBlock(world, i + 8, j + 40, k + 12, ModBlocks.gravewood, 1);
		this.setBlock(world, i + 8, j + 40, k + 13, ModBlocks.gravewood, 1);
		this.setBlock(world, i + 8, j + 40, k + 14, ModBlocks.gravewood, 1);
		this.setBlock(world, i + 8, j + 40, k + 15, ModBlocks.gravewoodLeaves, 0);
		this.setBlock(world, i + 8, j + 40, k + 16, ModBlocks.gravewood, 1);
		this.setBlock(world, i + 8, j + 40, k + 17, ModBlocks.gravewoodLeaves, 0);
		this.setBlock(world, i + 8, j + 40, k + 18, ModBlocks.gravewoodLeaves, 0);
		this.setBlock(world, i + 8, j + 40, k + 19, ModBlocks.gravewoodLeaves, 0);
		this.setBlock(world, i + 8, j + 40, k + 20, ModBlocks.gravewood, 1);
		this.setBlock(world, i + 8, j + 40, k + 21, ModBlocks.gravewood, 1);
		this.setBlock(world, i + 8, j + 40, k + 22, ModBlocks.gravewood, 1);
		this.setBlock(world, i + 8, j + 40, k + 23, ModBlocks.gravewood, 1);
		this.setBlock(world, i + 8, j + 40, k + 24, ModBlocks.gravewood, 1);
		this.setBlock(world, i + 8, j + 40, k + 25, ModBlocks.gravewoodLeaves, 0);
		this.setBlock(world, i + 8, j + 40, k + 26, ModBlocks.gravewood, 1);
		this.setBlock(world, i + 8, j + 40, k + 27, ModBlocks.gravewoodLeaves, 0);
		this.setBlock(world, i + 8, j + 40, k + 28, ModBlocks.gravewoodLeaves, 0);
		this.setBlock(world, i + 8, j + 40, k + 29, ModBlocks.gravewoodLeaves, 0);
		this.setBlock(world, i + 8, j + 40, k + 30, ModBlocks.gravewood, 1);
		this.setBlock(world, i + 8, j + 40, k + 31, ModBlocks.gravewood, 1);
		this.setBlock(world, i + 8, j + 40, k + 32, ModBlocks.gravewood, 1);
		this.setBlock(world, i + 8, j + 40, k + 33, ModBlocks.gravewood, 1);
		this.setBlock(world, i + 8, j + 40, k + 34, ModBlocks.gravewood, 1);
		this.setBlock(world, i + 8, j + 40, k + 35, ModBlocks.gravewood, 1);
		this.setBlock(world, i + 8, j + 40, k + 36, ModBlocks.gravewoodLeaves, 0);
		this.setBlock(world, i + 8, j + 41, k + 7, ModBlocks.gravewoodLeaves, 0);
		this.setBlock(world, i + 8, j + 41, k + 8, ModBlocks.gravewood, 1);
		this.setBlock(world, i + 8, j + 41, k + 9, ModBlocks.gravewoodLeaves, 0);
		this.setBlock(world, i + 8, j + 41, k + 10, ModBlocks.gravewoodLeaves, 0);
		this.setBlock(world, i + 8, j + 41, k + 11, ModBlocks.gravewoodLeaves, 0);
		this.setBlock(world, i + 8, j + 41, k + 12, ModBlocks.gravewoodLeaves, 0);
		this.setBlock(world, i + 8, j + 41, k + 13, ModBlocks.gravewood, 1);
		this.setBlock(world, i + 8, j + 41, k + 14, ModBlocks.gravewood, 1);
		this.setBlock(world, i + 8, j + 41, k + 15, ModBlocks.gravewoodLeaves, 0);
		this.setBlock(world, i + 8, j + 41, k + 16, ModBlocks.gravewoodLeaves, 0);
		this.setBlock(world, i + 8, j + 41, k + 17, ModBlocks.gravewoodLeaves, 0);
		this.setBlock(world, i + 8, j + 41, k + 18, ModBlocks.gravewood, 1);
		this.setBlock(world, i + 8, j + 41, k + 19, ModBlocks.gravewoodLeaves, 0);
		this.setBlock(world, i + 8, j + 41, k + 20, ModBlocks.gravewood, 1);
		this.setBlock(world, i + 8, j + 41, k + 21, ModBlocks.gravewood, 1);
		this.setBlock(world, i + 8, j + 41, k + 22, ModBlocks.gravewood, 1);
		this.setBlock(world, i + 8, j + 41, k + 23, ModBlocks.gravewood, 1);
		this.setBlock(world, i + 8, j + 41, k + 24, ModBlocks.gravewoodLeaves, 0);
		this.setBlock(world, i + 8, j + 41, k + 25, ModBlocks.gravewoodLeaves, 0);
		this.setBlock(world, i + 8, j + 41, k + 26, ModBlocks.gravewoodLeaves, 0);
		this.setBlock(world, i + 8, j + 41, k + 27, ModBlocks.gravewoodLeaves, 0);
		this.setBlock(world, i + 8, j + 41, k + 28, ModBlocks.gravewoodLeaves, 0);
		this.setBlock(world, i + 8, j + 41, k + 29, ModBlocks.gravewoodLeaves, 0);
		this.setBlock(world, i + 8, j + 41, k + 30, ModBlocks.gravewoodLeaves, 0);
		this.setBlock(world, i + 8, j + 41, k + 31, ModBlocks.gravewood, 1);
		this.setBlock(world, i + 8, j + 41, k + 32, ModBlocks.gravewood, 1);
		this.setBlock(world, i + 8, j + 41, k + 33, ModBlocks.gravewood, 1);
		this.setBlock(world, i + 8, j + 41, k + 34, ModBlocks.gravewood, 1);
		this.setBlock(world, i + 8, j + 41, k + 35, ModBlocks.gravewood, 1);
		this.setBlock(world, i + 8, j + 41, k + 36, ModBlocks.gravewoodLeaves, 0);
		this.setBlock(world, i + 8, j + 41, k + 37, ModBlocks.gravewoodLeaves, 0);
		this.setBlock(world, i + 8, j + 42, k + 7, ModBlocks.gravewoodLeaves, 0);
		this.setBlock(world, i + 8, j + 42, k + 8, ModBlocks.gravewoodLeaves, 0);
		this.setBlock(world, i + 8, j + 42, k + 9, ModBlocks.gravewoodLeaves, 0);
		this.setBlock(world, i + 8, j + 42, k + 10, ModBlocks.gravewoodLeaves, 0);
		this.setBlock(world, i + 8, j + 42, k + 11, ModBlocks.gravewoodLeaves, 0);
		this.setBlock(world, i + 8, j + 42, k + 12, ModBlocks.gravewoodLeaves, 0);
		this.setBlock(world, i + 8, j + 42, k + 13, ModBlocks.gravewoodLeaves, 0);
		this.setBlock(world, i + 8, j + 42, k + 14, ModBlocks.gravewood, 1);
		this.setBlock(world, i + 8, j + 42, k + 15, ModBlocks.gravewoodLeaves, 0);
		this.setBlock(world, i + 8, j + 42, k + 16, ModBlocks.gravewoodLeaves, 0);
		this.setBlock(world, i + 8, j + 42, k + 17, ModBlocks.gravewoodLeaves, 0);
		this.setBlock(world, i + 8, j + 42, k + 18, ModBlocks.gravewood, 1);
		this.setBlock(world, i + 8, j + 42, k + 19, ModBlocks.gravewoodLeaves, 0);
		this.setBlock(world, i + 8, j + 42, k + 20, ModBlocks.gravewood, 1);
		this.setBlock(world, i + 8, j + 42, k + 21, ModBlocks.gravewood, 1);
		this.setBlock(world, i + 8, j + 42, k + 22, ModBlocks.gravewood, 1);
		this.setBlock(world, i + 8, j + 42, k + 23, ModBlocks.gravewood, 1);
		this.setBlock(world, i + 8, j + 42, k + 24, ModBlocks.gravewood, 1);
		this.setBlock(world, i + 8, j + 42, k + 25, ModBlocks.gravewoodLeaves, 0);
		this.setBlock(world, i + 8, j + 42, k + 26, ModBlocks.gravewoodLeaves, 0);
		this.setBlock(world, i + 8, j + 42, k + 27, ModBlocks.gravewoodLeaves, 0);
		this.setBlock(world, i + 8, j + 42, k + 28, ModBlocks.gravewoodLeaves, 0);
		this.setBlock(world, i + 8, j + 42, k + 29, ModBlocks.gravewoodLeaves, 0);
		this.setBlock(world, i + 8, j + 42, k + 30, ModBlocks.gravewoodLeaves, 0);
		this.setBlock(world, i + 8, j + 42, k + 31, ModBlocks.gravewoodLeaves, 0);
		this.setBlock(world, i + 8, j + 42, k + 32, ModBlocks.gravewood, 1);
		this.setBlock(world, i + 8, j + 42, k + 33, ModBlocks.gravewood, 1);
		this.setBlock(world, i + 8, j + 42, k + 34, ModBlocks.gravewoodLeaves, 0);
		this.setBlock(world, i + 8, j + 42, k + 35, ModBlocks.gravewoodLeaves, 0);
		this.setBlock(world, i + 8, j + 42, k + 36, ModBlocks.gravewoodLeaves, 0);
		this.setBlock(world, i + 8, j + 42, k + 37, ModBlocks.gravewoodLeaves, 0);
		this.setBlock(world, i + 8, j + 42, k + 38, ModBlocks.gravewoodLeaves, 0);
		this.setBlock(world, i + 8, j + 42, k + 39, ModBlocks.gravewoodLeaves, 0);
		this.setBlock(world, i + 8, j + 43, k + 7, ModBlocks.gravewoodLeaves, 0);
		this.setBlock(world, i + 8, j + 43, k + 8, ModBlocks.gravewoodLeaves, 0);
		this.setBlock(world, i + 8, j + 43, k + 9, ModBlocks.gravewood, 1);
		this.setBlock(world, i + 8, j + 43, k + 10, ModBlocks.gravewoodLeaves, 0);
		this.setBlock(world, i + 8, j + 43, k + 11, ModBlocks.gravewoodLeaves, 0);
		this.setBlock(world, i + 8, j + 43, k + 12, ModBlocks.gravewoodLeaves, 0);
		this.setBlock(world, i + 8, j + 43, k + 13, ModBlocks.gravewoodLeaves, 0);
		this.setBlock(world, i + 8, j + 43, k + 14, ModBlocks.gravewoodLeaves, 0);
		this.setBlock(world, i + 8, j + 43, k + 15, ModBlocks.gravewoodLeaves, 0);
		this.setBlock(world, i + 8, j + 43, k + 16, ModBlocks.gravewoodLeaves, 0);
		this.setBlock(world, i + 8, j + 43, k + 17, ModBlocks.gravewoodLeaves, 0);
		this.setBlock(world, i + 8, j + 43, k + 18, ModBlocks.gravewoodLeaves, 0);
		this.setBlock(world, i + 8, j + 43, k + 19, ModBlocks.gravewoodLeaves, 0);
		this.setBlock(world, i + 8, j + 43, k + 20, ModBlocks.gravewoodLeaves, 0);
		this.setBlock(world, i + 8, j + 43, k + 21, ModBlocks.gravewoodLeaves, 0);
		this.setBlock(world, i + 8, j + 43, k + 22, ModBlocks.gravewood, 1);
		this.setBlock(world, i + 8, j + 43, k + 23, ModBlocks.gravewoodLeaves, 0);
		this.setBlock(world, i + 8, j + 43, k + 24, ModBlocks.gravewoodLeaves, 0);
		this.setBlock(world, i + 8, j + 43, k + 25, ModBlocks.gravewoodLeaves, 0);
		this.setBlock(world, i + 8, j + 43, k + 26, ModBlocks.gravewood, 1);
		this.setBlock(world, i + 8, j + 43, k + 27, ModBlocks.gravewoodLeaves, 0);
		this.setBlock(world, i + 8, j + 43, k + 29, ModBlocks.gravewoodLeaves, 0);
		this.setBlock(world, i + 8, j + 43, k + 30, ModBlocks.gravewoodLeaves, 0);
		this.setBlock(world, i + 8, j + 43, k + 31, ModBlocks.gravewoodLeaves, 0);
		this.setBlock(world, i + 8, j + 43, k + 32, ModBlocks.gravewoodLeaves, 0);
		this.setBlock(world, i + 8, j + 43, k + 33, ModBlocks.gravewoodLeaves, 0);
		this.setBlock(world, i + 8, j + 43, k + 34, ModBlocks.gravewoodLeaves, 0);
		this.setBlock(world, i + 8, j + 43, k + 35, ModBlocks.gravewoodLeaves, 0);
		this.setBlock(world, i + 8, j + 43, k + 36, ModBlocks.gravewoodLeaves, 0);
		this.setBlock(world, i + 8, j + 43, k + 37, ModBlocks.gravewoodLeaves, 0);
		this.setBlock(world, i + 8, j + 43, k + 38, ModBlocks.gravewoodLeaves, 0);
		this.setBlock(world, i + 8, j + 43, k + 39, ModBlocks.gravewoodLeaves, 0);
		this.setBlock(world, i + 8, j + 44, k + 9, ModBlocks.gravewoodLeaves, 0);
		this.setBlock(world, i + 8, j + 44, k + 10, ModBlocks.gravewood, 1);
		this.setBlock(world, i + 8, j + 44, k + 11, ModBlocks.gravewoodLeaves, 0);
		this.setBlock(world, i + 8, j + 44, k + 12, ModBlocks.gravewood, 1);
		this.setBlock(world, i + 8, j + 44, k + 13, ModBlocks.gravewoodLeaves, 0);
		this.setBlock(world, i + 8, j + 44, k + 14, ModBlocks.gravewoodLeaves, 0);
		this.setBlock(world, i + 8, j + 44, k + 15, ModBlocks.gravewoodLeaves, 0);
		this.setBlock(world, i + 8, j + 44, k + 16, ModBlocks.gravewoodLeaves, 0);
		this.setBlock(world, i + 8, j + 44, k + 18, ModBlocks.gravewoodLeaves, 0);
		this.setBlock(world, i + 8, j + 44, k + 19, ModBlocks.gravewoodLeaves, 0);
		this.setBlock(world, i + 8, j + 44, k + 20, ModBlocks.gravewood, 1);
		this.setBlock(world, i + 8, j + 44, k + 21, ModBlocks.gravewoodLeaves, 0);
		this.setBlock(world, i + 8, j + 44, k + 22, ModBlocks.gravewoodLeaves, 0);
		this.setBlock(world, i + 8, j + 44, k + 23, ModBlocks.gravewood, 1);
		this.setBlock(world, i + 8, j + 44, k + 24, ModBlocks.gravewoodLeaves, 0);
		this.setBlock(world, i + 8, j + 44, k + 25, ModBlocks.gravewoodLeaves, 0);
		this.setBlock(world, i + 8, j + 44, k + 26, ModBlocks.gravewoodLeaves, 0);
		this.setBlock(world, i + 8, j + 44, k + 32, ModBlocks.gravewoodLeaves, 0);
		this.setBlock(world, i + 8, j + 44, k + 33, ModBlocks.gravewoodLeaves, 0);
		this.setBlock(world, i + 8, j + 44, k + 34, ModBlocks.gravewoodLeaves, 0);
		this.setBlock(world, i + 8, j + 44, k + 35, ModBlocks.gravewoodLeaves, 0);
		this.setBlock(world, i + 8, j + 44, k + 37, ModBlocks.gravewoodLeaves, 0);
		this.setBlock(world, i + 8, j + 44, k + 38, ModBlocks.gravewoodLeaves, 0);
		this.setBlock(world, i + 8, j + 44, k + 39, ModBlocks.gravewoodLeaves, 0);
		this.setBlock(world, i + 8, j + 45, k + 10, ModBlocks.gravewoodLeaves, 0);
		this.setBlock(world, i + 8, j + 45, k + 11, ModBlocks.gravewoodLeaves, 0);
		this.setBlock(world, i + 8, j + 45, k + 12, ModBlocks.gravewoodLeaves, 0);
		this.setBlock(world, i + 8, j + 45, k + 13, ModBlocks.gravewoodLeaves, 0);
		this.setBlock(world, i + 8, j + 45, k + 14, ModBlocks.gravewoodLeaves, 0);
		this.setBlock(world, i + 8, j + 45, k + 20, ModBlocks.gravewoodLeaves, 0);
		this.setBlock(world, i + 8, j + 45, k + 21, ModBlocks.gravewoodLeaves, 0);
		this.setBlock(world, i + 8, j + 45, k + 22, ModBlocks.gravewoodLeaves, 0);
		this.setBlock(world, i + 8, j + 45, k + 23, ModBlocks.gravewoodLeaves, 0);
		this.setBlock(world, i + 9, j + 37, k + 29, ModBlocks.gravewood, 1);
		this.setBlock(world, i + 9, j + 37, k + 30, ModBlocks.gravewood, 1);
		this.setBlock(world, i + 9, j + 37, k + 31, ModBlocks.gravewood, 1);
		this.setBlock(world, i + 9, j + 38, k + 10, ModBlocks.gravewood, 1);
		this.setBlock(world, i + 9, j + 38, k + 17, ModBlocks.gravewood, 1);
		this.setBlock(world, i + 9, j + 38, k + 18, ModBlocks.gravewoodLeaves, 0);
		this.setBlock(world, i + 9, j + 38, k + 19, ModBlocks.gravewood, 1);
		this.setBlock(world, i + 9, j + 38, k + 20, ModBlocks.gravewoodLeaves, 0);
		this.setBlock(world, i + 9, j + 38, k + 21, ModBlocks.gravewoodLeaves, 0);
		this.setBlock(world, i + 9, j + 38, k + 22, ModBlocks.gravewood, 1);
		this.setBlock(world, i + 9, j + 38, k + 23, ModBlocks.gravewood, 1);
		this.setBlock(world, i + 9, j + 38, k + 24, ModBlocks.gravewood, 1);
		this.setBlock(world, i + 9, j + 38, k + 25, ModBlocks.gravewoodLeaves, 0);
		this.setBlock(world, i + 9, j + 38, k + 27, ModBlocks.gravewoodLeaves, 0);
		this.setBlock(world, i + 9, j + 38, k + 28, ModBlocks.gravewood, 1);
		this.setBlock(world, i + 9, j + 38, k + 29, ModBlocks.gravewoodLeaves, 0);
		this.setBlock(world, i + 9, j + 38, k + 30, ModBlocks.gravewood, 1);
		this.setBlock(world, i + 9, j + 38, k + 31, ModBlocks.gravewood, 1);
		this.setBlock(world, i + 9, j + 38, k + 32, ModBlocks.gravewood, 1);
		this.setBlock(world, i + 9, j + 39, k + 8, ModBlocks.gravewood, 1);
		this.setBlock(world, i + 9, j + 39, k + 9, ModBlocks.gravewood, 1);
		this.setBlock(world, i + 9, j + 39, k + 10, ModBlocks.gravewood, 1);
		this.setBlock(world, i + 9, j + 39, k + 11, ModBlocks.gravewood, 1);
		this.setBlock(world, i + 9, j + 39, k + 12, ModBlocks.gravewood, 1);
		this.setBlock(world, i + 9, j + 39, k + 16, ModBlocks.gravewoodLeaves, 0);
		this.setBlock(world, i + 9, j + 39, k + 17, ModBlocks.gravewood, 1);
		this.setBlock(world, i + 9, j + 39, k + 18, ModBlocks.gravewoodLeaves, 0);
		this.setBlock(world, i + 9, j + 39, k + 19, ModBlocks.gravewoodLeaves, 0);
		this.setBlock(world, i + 9, j + 39, k + 20, ModBlocks.gravewoodLeaves, 0);
		this.setBlock(world, i + 9, j + 39, k + 21, ModBlocks.gravewood, 1);
		this.setBlock(world, i + 9, j + 39, k + 22, ModBlocks.gravewood, 1);
		this.setBlock(world, i + 9, j + 39, k + 23, ModBlocks.gravewood, 1);
		this.setBlock(world, i + 9, j + 39, k + 24, ModBlocks.gravewoodLeaves, 0);
		this.setBlock(world, i + 9, j + 39, k + 25, ModBlocks.gravewoodLeaves, 0);
		this.setBlock(world, i + 9, j + 39, k + 26, ModBlocks.gravewoodLeaves, 0);
		this.setBlock(world, i + 9, j + 39, k + 27, ModBlocks.gravewoodLeaves, 0);
		this.setBlock(world, i + 9, j + 39, k + 28, ModBlocks.gravewoodLeaves, 0);
		this.setBlock(world, i + 9, j + 39, k + 29, ModBlocks.gravewood, 1);
		this.setBlock(world, i + 9, j + 39, k + 30, ModBlocks.gravewood, 1);
		this.setBlock(world, i + 9, j + 39, k + 31, ModBlocks.gravewood, 1);
		this.setBlock(world, i + 9, j + 39, k + 32, ModBlocks.gravewood, 1);
		this.setBlock(world, i + 9, j + 39, k + 33, ModBlocks.gravewood, 1);
		this.setBlock(world, i + 9, j + 39, k + 34, ModBlocks.gravewood, 1);
		this.setBlock(world, i + 9, j + 39, k + 35, ModBlocks.gravewood, 1);
		this.setBlock(world, i + 9, j + 40, k + 7, ModBlocks.gravewoodLeaves, 0);
		this.setBlock(world, i + 9, j + 40, k + 8, ModBlocks.gravewood, 1);
		this.setBlock(world, i + 9, j + 40, k + 9, ModBlocks.gravewood, 1);
		this.setBlock(world, i + 9, j + 40, k + 10, ModBlocks.gravewood, 1);
		this.setBlock(world, i + 9, j + 40, k + 11, ModBlocks.gravewood, 1);
		this.setBlock(world, i + 9, j + 40, k + 12, ModBlocks.gravewood, 1);
		this.setBlock(world, i + 9, j + 40, k + 13, ModBlocks.gravewood, 1);
		this.setBlock(world, i + 9, j + 40, k + 14, ModBlocks.gravewood, 1);
		this.setBlock(world, i + 9, j + 40, k + 15, ModBlocks.gravewoodLeaves, 0);
		this.setBlock(world, i + 9, j + 40, k + 16, ModBlocks.gravewoodLeaves, 0);
		this.setBlock(world, i + 9, j + 40, k + 17, ModBlocks.gravewoodLeaves, 0);
		this.setBlock(world, i + 9, j + 40, k + 18, ModBlocks.gravewoodLeaves, 0);
		this.setBlock(world, i + 9, j + 40, k + 19, ModBlocks.gravewoodLeaves, 0);
		this.setBlock(world, i + 9, j + 40, k + 20, ModBlocks.gravewoodLeaves, 0);
		this.setBlock(world, i + 9, j + 40, k + 21, ModBlocks.gravewood, 1);
		this.setBlock(world, i + 9, j + 40, k + 22, ModBlocks.gravewood, 1);
		this.setBlock(world, i + 9, j + 40, k + 23, ModBlocks.gravewood, 1);
		this.setBlock(world, i + 9, j + 40, k + 24, ModBlocks.gravewoodLeaves, 0);
		this.setBlock(world, i + 9, j + 40, k + 25, ModBlocks.gravewoodLeaves, 0);
		this.setBlock(world, i + 9, j + 40, k + 26, ModBlocks.gravewoodLeaves, 0);
		this.setBlock(world, i + 9, j + 40, k + 27, ModBlocks.gravewoodLeaves, 0);
		this.setBlock(world, i + 9, j + 40, k + 28, ModBlocks.gravewoodLeaves, 0);
		this.setBlock(world, i + 9, j + 40, k + 29, ModBlocks.gravewoodLeaves, 0);
		this.setBlock(world, i + 9, j + 40, k + 30, ModBlocks.gravewood, 1);
		this.setBlock(world, i + 9, j + 40, k + 31, ModBlocks.gravewood, 1);
		this.setBlock(world, i + 9, j + 40, k + 32, ModBlocks.gravewood, 1);
		this.setBlock(world, i + 9, j + 40, k + 33, ModBlocks.gravewood, 1);
		this.setBlock(world, i + 9, j + 40, k + 34, ModBlocks.gravewood, 1);
		this.setBlock(world, i + 9, j + 40, k + 35, ModBlocks.gravewoodLeaves, 0);
		this.setBlock(world, i + 9, j + 40, k + 36, ModBlocks.gravewoodLeaves, 0);
		this.setBlock(world, i + 9, j + 41, k + 6, ModBlocks.gravewoodLeaves, 0);
		this.setBlock(world, i + 9, j + 41, k + 7, ModBlocks.gravewoodLeaves, 0);
		this.setBlock(world, i + 9, j + 41, k + 8, ModBlocks.gravewood, 1);
		this.setBlock(world, i + 9, j + 41, k + 9, ModBlocks.gravewood, 1);
		this.setBlock(world, i + 9, j + 41, k + 10, ModBlocks.gravewood, 1);
		this.setBlock(world, i + 9, j + 41, k + 11, ModBlocks.gravewood, 1);
		this.setBlock(world, i + 9, j + 41, k + 12, ModBlocks.gravewood, 1);
		this.setBlock(world, i + 9, j + 41, k + 13, ModBlocks.gravewood, 1);
		this.setBlock(world, i + 9, j + 41, k + 14, ModBlocks.gravewood, 1);
		this.setBlock(world, i + 9, j + 41, k + 15, ModBlocks.gravewoodLeaves, 0);
		this.setBlock(world, i + 9, j + 41, k + 16, ModBlocks.gravewoodLeaves, 0);
		this.setBlock(world, i + 9, j + 41, k + 17, ModBlocks.gravewood, 1);
		this.setBlock(world, i + 9, j + 41, k + 18, ModBlocks.gravewoodLeaves, 0);
		this.setBlock(world, i + 9, j + 41, k + 19, ModBlocks.gravewood, 1);
		this.setBlock(world, i + 9, j + 41, k + 20, ModBlocks.gravewoodLeaves, 0);
		this.setBlock(world, i + 9, j + 41, k + 21, ModBlocks.gravewood, 1);
		this.setBlock(world, i + 9, j + 41, k + 22, ModBlocks.gravewood, 1);
		this.setBlock(world, i + 9, j + 41, k + 23, ModBlocks.gravewood, 1);
		this.setBlock(world, i + 9, j + 41, k + 24, ModBlocks.gravewoodLeaves, 0);
		this.setBlock(world, i + 9, j + 41, k + 25, ModBlocks.gravewoodLeaves, 0);
		this.setBlock(world, i + 9, j + 41, k + 26, ModBlocks.gravewoodLeaves, 0);
		this.setBlock(world, i + 9, j + 41, k + 27, ModBlocks.gravewood, 1);
		this.setBlock(world, i + 9, j + 41, k + 28, ModBlocks.gravewoodLeaves, 0);
		this.setBlock(world, i + 9, j + 41, k + 29, ModBlocks.gravewoodLeaves, 0);
		this.setBlock(world, i + 9, j + 41, k + 30, ModBlocks.gravewood, 1);
		this.setBlock(world, i + 9, j + 41, k + 31, ModBlocks.gravewood, 1);
		this.setBlock(world, i + 9, j + 41, k + 32, ModBlocks.gravewood, 1);
		this.setBlock(world, i + 9, j + 41, k + 33, ModBlocks.gravewood, 1);
		this.setBlock(world, i + 9, j + 41, k + 34, ModBlocks.gravewood, 1);
		this.setBlock(world, i + 9, j + 41, k + 35, ModBlocks.gravewood, 1);
		this.setBlock(world, i + 9, j + 41, k + 36, ModBlocks.gravewoodLeaves, 0);
		this.setBlock(world, i + 9, j + 41, k + 37, ModBlocks.gravewoodLeaves, 0);
		this.setBlock(world, i + 9, j + 41, k + 38, ModBlocks.gravewoodLeaves, 0);
		this.setBlock(world, i + 9, j + 42, k + 6, ModBlocks.gravewoodLeaves, 0);
		this.setBlock(world, i + 9, j + 42, k + 7, ModBlocks.gravewoodLeaves, 0);
		this.setBlock(world, i + 9, j + 42, k + 8, ModBlocks.gravewoodLeaves, 0);
		this.setBlock(world, i + 9, j + 42, k + 9, ModBlocks.gravewoodLeaves, 0);
		this.setBlock(world, i + 9, j + 42, k + 10, ModBlocks.gravewoodLeaves, 0);
		this.setBlock(world, i + 9, j + 42, k + 11, ModBlocks.gravewoodLeaves, 0);
		this.setBlock(world, i + 9, j + 42, k + 12, ModBlocks.gravewoodLeaves, 0);
		this.setBlock(world, i + 9, j + 42, k + 13, ModBlocks.gravewoodLeaves, 0);
		this.setBlock(world, i + 9, j + 42, k + 14, ModBlocks.gravewood, 1);
		this.setBlock(world, i + 9, j + 42, k + 15, ModBlocks.gravewoodLeaves, 0);
		this.setBlock(world, i + 9, j + 42, k + 16, ModBlocks.gravewoodLeaves, 0);
		this.setBlock(world, i + 9, j + 42, k + 17, ModBlocks.gravewood, 1);
		this.setBlock(world, i + 9, j + 42, k + 18, ModBlocks.gravewoodLeaves, 0);
		this.setBlock(world, i + 9, j + 42, k + 19, ModBlocks.gravewoodLeaves, 0);
		this.setBlock(world, i + 9, j + 42, k + 20, ModBlocks.gravewoodLeaves, 0);
		this.setBlock(world, i + 9, j + 42, k + 21, ModBlocks.gravewoodLeaves, 0);
		this.setBlock(world, i + 9, j + 42, k + 22, ModBlocks.gravewoodLeaves, 0);
		this.setBlock(world, i + 9, j + 42, k + 23, ModBlocks.gravewoodLeaves, 0);
		this.setBlock(world, i + 9, j + 42, k + 24, ModBlocks.gravewoodLeaves, 0);
		this.setBlock(world, i + 9, j + 42, k + 25, ModBlocks.gravewoodLeaves, 0);
		this.setBlock(world, i + 9, j + 42, k + 26, ModBlocks.gravewoodLeaves, 0);
		this.setBlock(world, i + 9, j + 42, k + 27, ModBlocks.gravewoodLeaves, 0);
		this.setBlock(world, i + 9, j + 42, k + 28, ModBlocks.gravewoodLeaves, 0);
		this.setBlock(world, i + 9, j + 42, k + 29, ModBlocks.gravewoodLeaves, 0);
		this.setBlock(world, i + 9, j + 42, k + 30, ModBlocks.gravewoodLeaves, 0);
		this.setBlock(world, i + 9, j + 42, k + 31, ModBlocks.gravewoodLeaves, 0);
		this.setBlock(world, i + 9, j + 42, k + 32, ModBlocks.gravewood, 1);
		this.setBlock(world, i + 9, j + 42, k + 33, ModBlocks.gravewoodLeaves, 0);
		this.setBlock(world, i + 9, j + 42, k + 34, ModBlocks.gravewoodLeaves, 0);
		this.setBlock(world, i + 9, j + 42, k + 35, ModBlocks.gravewoodLeaves, 0);
		this.setBlock(world, i + 9, j + 42, k + 36, ModBlocks.gravewoodLeaves, 0);
		this.setBlock(world, i + 9, j + 42, k + 37, ModBlocks.gravewoodLeaves, 0);
		this.setBlock(world, i + 9, j + 42, k + 38, ModBlocks.gravewoodLeaves, 0);
		this.setBlock(world, i + 9, j + 42, k + 39, ModBlocks.gravewoodLeaves, 0);
		this.setBlock(world, i + 9, j + 42, k + 40, ModBlocks.gravewood, 1);
		this.setBlock(world, i + 9, j + 42, k + 41, ModBlocks.gravewoodLeaves, 0);
		this.setBlock(world, i + 9, j + 43, k + 7, ModBlocks.gravewoodLeaves, 0);
		this.setBlock(world, i + 9, j + 43, k + 8, ModBlocks.gravewoodLeaves, 0);
		this.setBlock(world, i + 9, j + 43, k + 9, ModBlocks.gravewoodLeaves, 0);
		this.setBlock(world, i + 9, j + 43, k + 10, ModBlocks.gravewoodLeaves, 0);
		this.setBlock(world, i + 9, j + 43, k + 11, ModBlocks.gravewoodLeaves, 0);
		this.setBlock(world, i + 9, j + 43, k + 12, ModBlocks.gravewood, 1);
		this.setBlock(world, i + 9, j + 43, k + 13, ModBlocks.gravewoodLeaves, 0);
		this.setBlock(world, i + 9, j + 43, k + 14, ModBlocks.gravewoodLeaves, 0);
		this.setBlock(world, i + 9, j + 43, k + 15, ModBlocks.gravewoodLeaves, 0);
		this.setBlock(world, i + 9, j + 43, k + 16, ModBlocks.gravewoodLeaves, 0);
		this.setBlock(world, i + 9, j + 43, k + 17, ModBlocks.gravewoodLeaves, 0);
		this.setBlock(world, i + 9, j + 43, k + 18, ModBlocks.gravewoodLeaves, 0);
		this.setBlock(world, i + 9, j + 43, k + 19, ModBlocks.gravewoodLeaves, 0);
		this.setBlock(world, i + 9, j + 43, k + 20, ModBlocks.gravewoodLeaves, 0);
		this.setBlock(world, i + 9, j + 43, k + 21, ModBlocks.gravewoodLeaves, 0);
		this.setBlock(world, i + 9, j + 43, k + 22, ModBlocks.gravewoodLeaves, 0);
		this.setBlock(world, i + 9, j + 43, k + 23, ModBlocks.gravewood, 1);
		this.setBlock(world, i + 9, j + 43, k + 24, ModBlocks.gravewood, 1);
		this.setBlock(world, i + 9, j + 43, k + 25, ModBlocks.gravewoodLeaves, 0);
		this.setBlock(world, i + 9, j + 43, k + 26, ModBlocks.gravewoodLeaves, 0);
		this.setBlock(world, i + 9, j + 43, k + 30, ModBlocks.gravewoodLeaves, 0);
		this.setBlock(world, i + 9, j + 43, k + 31, ModBlocks.gravewoodLeaves, 0);
		this.setBlock(world, i + 9, j + 43, k + 32, ModBlocks.gravewood, 1);
		this.setBlock(world, i + 9, j + 43, k + 33, ModBlocks.gravewoodLeaves, 0);
		this.setBlock(world, i + 9, j + 43, k + 34, ModBlocks.gravewoodLeaves, 0);
		this.setBlock(world, i + 9, j + 43, k + 35, ModBlocks.gravewoodLeaves, 0);
		this.setBlock(world, i + 9, j + 43, k + 36, ModBlocks.gravewoodLeaves, 0);
		this.setBlock(world, i + 9, j + 43, k + 37, ModBlocks.gravewoodLeaves, 0);
		this.setBlock(world, i + 9, j + 43, k + 38, ModBlocks.gravewoodLeaves, 0);
		this.setBlock(world, i + 9, j + 43, k + 39, ModBlocks.gravewoodLeaves, 0);
		this.setBlock(world, i + 9, j + 43, k + 40, ModBlocks.gravewoodLeaves, 0);
		this.setBlock(world, i + 9, j + 43, k + 41, ModBlocks.gravewoodLeaves, 0);
		this.setBlock(world, i + 9, j + 44, k + 7, ModBlocks.gravewoodLeaves, 0);
		this.setBlock(world, i + 9, j + 44, k + 10, ModBlocks.gravewoodLeaves, 0);
		this.setBlock(world, i + 9, j + 44, k + 11, ModBlocks.gravewoodLeaves, 0);
		this.setBlock(world, i + 9, j + 44, k + 12, ModBlocks.gravewoodLeaves, 0);
		this.setBlock(world, i + 9, j + 44, k + 13, ModBlocks.gravewoodLeaves, 0);
		this.setBlock(world, i + 9, j + 44, k + 14, ModBlocks.gravewoodLeaves, 0);
		this.setBlock(world, i + 9, j + 44, k + 15, ModBlocks.gravewoodLeaves, 0);
		this.setBlock(world, i + 9, j + 44, k + 20, ModBlocks.gravewoodLeaves, 0);
		this.setBlock(world, i + 9, j + 44, k + 21, ModBlocks.gravewoodLeaves, 0);
		this.setBlock(world, i + 9, j + 44, k + 22, ModBlocks.gravewoodLeaves, 0);
		this.setBlock(world, i + 9, j + 44, k + 23, ModBlocks.gravewoodLeaves, 0);
		this.setBlock(world, i + 9, j + 44, k + 24, ModBlocks.gravewoodLeaves, 0);
		this.setBlock(world, i + 9, j + 44, k + 25, ModBlocks.gravewoodLeaves, 0);
		this.setBlock(world, i + 9, j + 44, k + 32, ModBlocks.gravewoodLeaves, 0);
		this.setBlock(world, i + 9, j + 44, k + 33, ModBlocks.gravewoodLeaves, 0);
		this.setBlock(world, i + 9, j + 44, k + 34, ModBlocks.gravewoodLeaves, 0);
		this.setBlock(world, i + 9, j + 44, k + 35, ModBlocks.gravewoodLeaves, 0);
		this.setBlock(world, i + 9, j + 44, k + 36, ModBlocks.gravewoodLeaves, 0);
		this.setBlock(world, i + 9, j + 44, k + 37, ModBlocks.gravewoodLeaves, 0);
		this.setBlock(world, i + 9, j + 44, k + 38, ModBlocks.gravewoodLeaves, 0);
		this.setBlock(world, i + 9, j + 44, k + 39, ModBlocks.gravewoodLeaves, 0);
		this.setBlock(world, i + 9, j + 44, k + 40, ModBlocks.gravewoodLeaves, 0);
		this.setBlock(world, i + 9, j + 44, k + 41, ModBlocks.gravewoodLeaves, 0);
		this.setBlock(world, i + 9, j + 45, k + 11, ModBlocks.gravewoodLeaves, 0);
		this.setBlock(world, i + 9, j + 45, k + 12, ModBlocks.gravewoodLeaves, 0);
		this.setBlock(world, i + 9, j + 45, k + 13, ModBlocks.gravewoodLeaves, 0);
		this.setBlock(world, i + 9, j + 45, k + 14, ModBlocks.gravewoodLeaves, 0);
		this.setBlock(world, i + 9, j + 45, k + 38, ModBlocks.gravewoodLeaves, 0);
		this.setBlock(world, i + 9, j + 45, k + 39, ModBlocks.gravewoodLeaves, 0);
		this.setBlock(world, i + 9, j + 45, k + 40, ModBlocks.gravewoodLeaves, 0);
		this.setBlock(world, i + 10, j + 37, k + 28, ModBlocks.gravewood, 1);
		this.setBlock(world, i + 10, j + 37, k + 29, ModBlocks.gravewood, 1);
		this.setBlock(world, i + 10, j + 37, k + 30, ModBlocks.gravewood, 1);
		this.setBlock(world, i + 10, j + 37, k + 31, ModBlocks.gravewood, 1);
		this.setBlock(world, i + 10, j + 38, k + 9, ModBlocks.gravewood, 1);
		this.setBlock(world, i + 10, j + 38, k + 10, ModBlocks.gravewood, 1);
		this.setBlock(world, i + 10, j + 38, k + 11, ModBlocks.gravewood, 1);
		this.setBlock(world, i + 10, j + 38, k + 12, ModBlocks.gravewood, 1);
		this.setBlock(world, i + 10, j + 38, k + 17, ModBlocks.gravewoodLeaves, 0);
		this.setBlock(world, i + 10, j + 38, k + 18, ModBlocks.gravewoodLeaves, 0);
		this.setBlock(world, i + 10, j + 38, k + 19, ModBlocks.gravewood, 1);
		this.setBlock(world, i + 10, j + 38, k + 20, ModBlocks.gravewoodLeaves, 0);
		this.setBlock(world, i + 10, j + 38, k + 21, ModBlocks.gravewood, 1);
		this.setBlock(world, i + 10, j + 38, k + 22, ModBlocks.gravewood, 1);
		this.setBlock(world, i + 10, j + 38, k + 23, ModBlocks.gravewood, 1);
		this.setBlock(world, i + 10, j + 38, k + 24, ModBlocks.gravewood, 1);
		this.setBlock(world, i + 10, j + 38, k + 25, ModBlocks.gravewood, 1);
		this.setBlock(world, i + 10, j + 38, k + 26, ModBlocks.gravewoodLeaves, 0);
		this.setBlock(world, i + 10, j + 38, k + 27, ModBlocks.gravewoodLeaves, 0);
		this.setBlock(world, i + 10, j + 38, k + 28, ModBlocks.gravewoodLeaves, 0);
		this.setBlock(world, i + 10, j + 38, k + 29, ModBlocks.gravewood, 1);
		this.setBlock(world, i + 10, j + 38, k + 30, ModBlocks.gravewood, 1);
		this.setBlock(world, i + 10, j + 38, k + 31, ModBlocks.gravewood, 1);
		this.setBlock(world, i + 10, j + 38, k + 32, ModBlocks.gravewood, 1);
		this.setBlock(world, i + 10, j + 39, k + 7, ModBlocks.gravewood, 1);
		this.setBlock(world, i + 10, j + 39, k + 8, ModBlocks.gravewood, 1);
		this.setBlock(world, i + 10, j + 39, k + 9, ModBlocks.gravewood, 1);
		this.setBlock(world, i + 10, j + 39, k + 10, ModBlocks.gravewood, 1);
		this.setBlock(world, i + 10, j + 39, k + 11, ModBlocks.gravewood, 1);
		this.setBlock(world, i + 10, j + 39, k + 12, ModBlocks.gravewood, 1);
		this.setBlock(world, i + 10, j + 39, k + 13, ModBlocks.gravewood, 1);
		this.setBlock(world, i + 10, j + 39, k + 14, ModBlocks.gravewood, 1);
		this.setBlock(world, i + 10, j + 39, k + 15, ModBlocks.gravewood, 1);
		this.setBlock(world, i + 10, j + 39, k + 16, ModBlocks.gravewoodLeaves, 0);
		this.setBlock(world, i + 10, j + 39, k + 17, ModBlocks.gravewoodLeaves, 0);
		this.setBlock(world, i + 10, j + 39, k + 18, ModBlocks.gravewoodLeaves, 0);
		this.setBlock(world, i + 10, j + 39, k + 19, ModBlocks.gravewoodLeaves, 0);
		this.setBlock(world, i + 10, j + 39, k + 20, ModBlocks.gravewoodLeaves, 0);
		this.setBlock(world, i + 10, j + 39, k + 21, ModBlocks.gravewood, 1);
		this.setBlock(world, i + 10, j + 39, k + 22, ModBlocks.gravewood, 1);
		this.setBlock(world, i + 10, j + 39, k + 23, ModBlocks.gravewood, 1);
		this.setBlock(world, i + 10, j + 39, k + 24, ModBlocks.gravewood, 1);
		this.setBlock(world, i + 10, j + 39, k + 25, ModBlocks.gravewoodLeaves, 0);
		this.setBlock(world, i + 10, j + 39, k + 26, ModBlocks.gravewoodLeaves, 0);
		this.setBlock(world, i + 10, j + 39, k + 27, ModBlocks.gravewoodLeaves, 0);
		this.setBlock(world, i + 10, j + 39, k + 28, ModBlocks.gravewoodLeaves, 0);
		this.setBlock(world, i + 10, j + 39, k + 29, ModBlocks.gravewood, 1);
		this.setBlock(world, i + 10, j + 39, k + 30, ModBlocks.gravewood, 1);
		this.setBlock(world, i + 10, j + 39, k + 31, ModBlocks.gravewood, 1);
		this.setBlock(world, i + 10, j + 39, k + 32, ModBlocks.gravewood, 1);
		this.setBlock(world, i + 10, j + 39, k + 33, ModBlocks.gravewood, 1);
		this.setBlock(world, i + 10, j + 39, k + 34, ModBlocks.gravewood, 1);
		this.setBlock(world, i + 10, j + 40, k + 6, ModBlocks.gravewoodLeaves, 0);
		this.setBlock(world, i + 10, j + 40, k + 7, ModBlocks.gravewood, 1);
		this.setBlock(world, i + 10, j + 40, k + 8, ModBlocks.gravewood, 1);
		this.setBlock(world, i + 10, j + 40, k + 9, ModBlocks.gravewood, 1);
		this.setBlock(world, i + 10, j + 40, k + 10, ModBlocks.gravewood, 1);
		this.setBlock(world, i + 10, j + 40, k + 11, ModBlocks.gravewood, 1);
		this.setBlock(world, i + 10, j + 40, k + 12, ModBlocks.gravewood, 1);
		this.setBlock(world, i + 10, j + 40, k + 13, ModBlocks.gravewood, 1);
		this.setBlock(world, i + 10, j + 40, k + 14, ModBlocks.gravewoodLeaves, 0);
		this.setBlock(world, i + 10, j + 40, k + 15, ModBlocks.gravewoodLeaves, 0);
		this.setBlock(world, i + 10, j + 40, k + 16, ModBlocks.gravewoodLeaves, 0);
		this.setBlock(world, i + 10, j + 40, k + 17, ModBlocks.gravewoodLeaves, 0);
		this.setBlock(world, i + 10, j + 40, k + 18, ModBlocks.gravewoodLeaves, 0);
		this.setBlock(world, i + 10, j + 40, k + 19, ModBlocks.gravewood, 1);
		this.setBlock(world, i + 10, j + 40, k + 20, ModBlocks.gravewood, 1);
		this.setBlock(world, i + 10, j + 40, k + 21, ModBlocks.gravewood, 1);
		this.setBlock(world, i + 10, j + 40, k + 22, ModBlocks.gravewood, 1);
		this.setBlock(world, i + 10, j + 40, k + 23, ModBlocks.gravewood, 1);
		this.setBlock(world, i + 10, j + 40, k + 24, ModBlocks.gravewood, 1);
		this.setBlock(world, i + 10, j + 40, k + 25, ModBlocks.gravewoodLeaves, 0);
		this.setBlock(world, i + 10, j + 40, k + 26, ModBlocks.gravewood, 1);
		this.setBlock(world, i + 10, j + 40, k + 27, ModBlocks.gravewoodLeaves, 0);
		this.setBlock(world, i + 10, j + 40, k + 28, ModBlocks.gravewoodLeaves, 0);
		this.setBlock(world, i + 10, j + 40, k + 29, ModBlocks.gravewood, 1);
		this.setBlock(world, i + 10, j + 40, k + 30, ModBlocks.gravewood, 1);
		this.setBlock(world, i + 10, j + 40, k + 31, ModBlocks.gravewood, 1);
		this.setBlock(world, i + 10, j + 40, k + 32, ModBlocks.gravewood, 1);
		this.setBlock(world, i + 10, j + 40, k + 33, ModBlocks.gravewood, 1);
		this.setBlock(world, i + 10, j + 40, k + 34, ModBlocks.gravewood, 1);
		this.setBlock(world, i + 10, j + 40, k + 35, ModBlocks.gravewoodLeaves, 0);
		this.setBlock(world, i + 10, j + 41, k + 6, ModBlocks.gravewoodLeaves, 0);
		this.setBlock(world, i + 10, j + 41, k + 7, ModBlocks.gravewoodLeaves, 0);
		this.setBlock(world, i + 10, j + 41, k + 8, ModBlocks.gravewoodLeaves, 0);
		this.setBlock(world, i + 10, j + 41, k + 9, ModBlocks.gravewood, 1);
		this.setBlock(world, i + 10, j + 41, k + 10, ModBlocks.gravewood, 1);
		this.setBlock(world, i + 10, j + 41, k + 11, ModBlocks.gravewood, 1);
		this.setBlock(world, i + 10, j + 41, k + 12, ModBlocks.gravewood, 1);
		this.setBlock(world, i + 10, j + 41, k + 13, ModBlocks.gravewood, 1);
		this.setBlock(world, i + 10, j + 41, k + 14, ModBlocks.gravewoodLeaves, 0);
		this.setBlock(world, i + 10, j + 41, k + 15, ModBlocks.gravewoodLeaves, 0);
		this.setBlock(world, i + 10, j + 41, k + 16, ModBlocks.gravewood, 1);
		this.setBlock(world, i + 10, j + 41, k + 17, ModBlocks.gravewoodLeaves, 0);
		this.setBlock(world, i + 10, j + 41, k + 18, ModBlocks.gravewoodLeaves, 0);
		this.setBlock(world, i + 10, j + 41, k + 19, ModBlocks.gravewoodLeaves, 0);
		this.setBlock(world, i + 10, j + 41, k + 20, ModBlocks.gravewood, 1);
		this.setBlock(world, i + 10, j + 41, k + 21, ModBlocks.gravewood, 1);
		this.setBlock(world, i + 10, j + 41, k + 22, ModBlocks.gravewood, 1);
		this.setBlock(world, i + 10, j + 41, k + 23, ModBlocks.gravewood, 1);
		this.setBlock(world, i + 10, j + 41, k + 24, ModBlocks.gravewoodLeaves, 0);
		this.setBlock(world, i + 10, j + 41, k + 25, ModBlocks.gravewoodLeaves, 0);
		this.setBlock(world, i + 10, j + 41, k + 26, ModBlocks.gravewoodLeaves, 0);
		this.setBlock(world, i + 10, j + 41, k + 27, ModBlocks.gravewoodLeaves, 0);
		this.setBlock(world, i + 10, j + 41, k + 28, ModBlocks.gravewoodLeaves, 0);
		this.setBlock(world, i + 10, j + 41, k + 29, ModBlocks.gravewoodLeaves, 0);
		this.setBlock(world, i + 10, j + 41, k + 30, ModBlocks.gravewoodLeaves, 0);
		this.setBlock(world, i + 10, j + 41, k + 31, ModBlocks.gravewood, 1);
		this.setBlock(world, i + 10, j + 41, k + 32, ModBlocks.gravewood, 1);
		this.setBlock(world, i + 10, j + 41, k + 33, ModBlocks.gravewood, 1);
		this.setBlock(world, i + 10, j + 41, k + 34, ModBlocks.gravewoodLeaves, 0);
		this.setBlock(world, i + 10, j + 41, k + 35, ModBlocks.gravewoodLeaves, 0);
		this.setBlock(world, i + 10, j + 41, k + 36, ModBlocks.gravewoodLeaves, 0);
		this.setBlock(world, i + 10, j + 41, k + 37, ModBlocks.gravewoodLeaves, 0);
		this.setBlock(world, i + 10, j + 41, k + 38, ModBlocks.gravewoodLeaves, 0);
		this.setBlock(world, i + 10, j + 41, k + 39, ModBlocks.gravewoodLeaves, 0);
		this.setBlock(world, i + 10, j + 42, k + 5, ModBlocks.gravewoodLeaves, 0);
		this.setBlock(world, i + 10, j + 42, k + 6, ModBlocks.gravewoodLeaves, 0);
		this.setBlock(world, i + 10, j + 42, k + 7, ModBlocks.gravewoodLeaves, 0);
		this.setBlock(world, i + 10, j + 42, k + 8, ModBlocks.gravewoodLeaves, 0);
		this.setBlock(world, i + 10, j + 42, k + 9, ModBlocks.gravewood, 1);
		this.setBlock(world, i + 10, j + 42, k + 10, ModBlocks.gravewoodLeaves, 0);
		this.setBlock(world, i + 10, j + 42, k + 11, ModBlocks.gravewoodLeaves, 0);
		this.setBlock(world, i + 10, j + 42, k + 12, ModBlocks.gravewood, 1);
		this.setBlock(world, i + 10, j + 42, k + 13, ModBlocks.gravewood, 1);
		this.setBlock(world, i + 10, j + 42, k + 14, ModBlocks.gravewoodLeaves, 0);
		this.setBlock(world, i + 10, j + 42, k + 15, ModBlocks.gravewoodLeaves, 0);
		this.setBlock(world, i + 10, j + 42, k + 16, ModBlocks.gravewoodLeaves, 0);
		this.setBlock(world, i + 10, j + 42, k + 17, ModBlocks.gravewoodLeaves, 0);
		this.setBlock(world, i + 10, j + 42, k + 18, ModBlocks.gravewoodLeaves, 0);
		this.setBlock(world, i + 10, j + 42, k + 19, ModBlocks.gravewoodLeaves, 0);
		this.setBlock(world, i + 10, j + 42, k + 20, ModBlocks.gravewood, 1);
		this.setBlock(world, i + 10, j + 42, k + 21, ModBlocks.gravewoodLeaves, 0);
		this.setBlock(world, i + 10, j + 42, k + 22, ModBlocks.gravewood, 1);
		this.setBlock(world, i + 10, j + 42, k + 23, ModBlocks.gravewoodLeaves, 0);
		this.setBlock(world, i + 10, j + 42, k + 24, ModBlocks.gravewoodLeaves, 0);
		this.setBlock(world, i + 10, j + 42, k + 25, ModBlocks.gravewood, 1);
		this.setBlock(world, i + 10, j + 42, k + 26, ModBlocks.gravewoodLeaves, 0);
		this.setBlock(world, i + 10, j + 42, k + 27, ModBlocks.gravewoodLeaves, 0);
		this.setBlock(world, i + 10, j + 42, k + 28, ModBlocks.gravewoodLeaves, 0);
		this.setBlock(world, i + 10, j + 42, k + 29, ModBlocks.gravewoodLeaves, 0);
		this.setBlock(world, i + 10, j + 42, k + 30, ModBlocks.gravewoodLeaves, 0);
		this.setBlock(world, i + 10, j + 42, k + 31, ModBlocks.gravewoodLeaves, 0);
		this.setBlock(world, i + 10, j + 42, k + 32, ModBlocks.gravewoodLeaves, 0);
		this.setBlock(world, i + 10, j + 42, k + 33, ModBlocks.gravewoodLeaves, 0);
		this.setBlock(world, i + 10, j + 42, k + 34, ModBlocks.gravewoodLeaves, 0);
		this.setBlock(world, i + 10, j + 42, k + 35, ModBlocks.gravewoodLeaves, 0);
		this.setBlock(world, i + 10, j + 42, k + 36, ModBlocks.gravewoodLeaves, 0);
		this.setBlock(world, i + 10, j + 42, k + 37, ModBlocks.gravewoodLeaves, 0);
		this.setBlock(world, i + 10, j + 42, k + 38, ModBlocks.gravewoodLeaves, 0);
		this.setBlock(world, i + 10, j + 42, k + 39, ModBlocks.gravewoodLeaves, 0);
		this.setBlock(world, i + 10, j + 42, k + 40, ModBlocks.gravewood, 1);
		this.setBlock(world, i + 10, j + 42, k + 41, ModBlocks.gravewoodLeaves, 0);
		this.setBlock(world, i + 10, j + 43, k + 5, ModBlocks.gravewoodLeaves, 0);
		this.setBlock(world, i + 10, j + 43, k + 6, ModBlocks.gravewoodLeaves, 0);
		this.setBlock(world, i + 10, j + 43, k + 7, ModBlocks.gravewoodLeaves, 0);
		this.setBlock(world, i + 10, j + 43, k + 8, ModBlocks.gravewoodLeaves, 0);
		this.setBlock(world, i + 10, j + 43, k + 9, ModBlocks.gravewoodLeaves, 0);
		this.setBlock(world, i + 10, j + 43, k + 10, ModBlocks.gravewoodLeaves, 0);
		this.setBlock(world, i + 10, j + 43, k + 11, ModBlocks.gravewoodLeaves, 0);
		this.setBlock(world, i + 10, j + 43, k + 12, ModBlocks.gravewood, 1);
		this.setBlock(world, i + 10, j + 43, k + 13, ModBlocks.gravewoodLeaves, 0);
		this.setBlock(world, i + 10, j + 43, k + 14, ModBlocks.gravewoodLeaves, 0);
		this.setBlock(world, i + 10, j + 43, k + 15, ModBlocks.gravewoodLeaves, 0);
		this.setBlock(world, i + 10, j + 43, k + 16, ModBlocks.gravewoodLeaves, 0);
		this.setBlock(world, i + 10, j + 43, k + 17, ModBlocks.gravewoodLeaves, 0);
		this.setBlock(world, i + 10, j + 43, k + 18, ModBlocks.gravewoodLeaves, 0);
		this.setBlock(world, i + 10, j + 43, k + 19, ModBlocks.gravewoodLeaves, 0);
		this.setBlock(world, i + 10, j + 43, k + 20, ModBlocks.gravewoodLeaves, 0);
		this.setBlock(world, i + 10, j + 43, k + 21, ModBlocks.gravewoodLeaves, 0);
		this.setBlock(world, i + 10, j + 43, k + 22, ModBlocks.gravewoodLeaves, 0);
		this.setBlock(world, i + 10, j + 43, k + 23, ModBlocks.gravewoodLeaves, 0);
		this.setBlock(world, i + 10, j + 43, k + 24, ModBlocks.gravewoodLeaves, 0);
		this.setBlock(world, i + 10, j + 43, k + 25, ModBlocks.gravewoodLeaves, 0);
		this.setBlock(world, i + 10, j + 43, k + 30, ModBlocks.gravewoodLeaves, 0);
		this.setBlock(world, i + 10, j + 43, k + 31, ModBlocks.gravewoodLeaves, 0);
		this.setBlock(world, i + 10, j + 43, k + 32, ModBlocks.gravewoodLeaves, 0);
		this.setBlock(world, i + 10, j + 43, k + 33, ModBlocks.gravewoodLeaves, 0);
		this.setBlock(world, i + 10, j + 43, k + 34, ModBlocks.gravewoodLeaves, 0);
		this.setBlock(world, i + 10, j + 43, k + 35, ModBlocks.gravewoodLeaves, 0);
		this.setBlock(world, i + 10, j + 43, k + 36, ModBlocks.gravewoodLeaves, 0);
		this.setBlock(world, i + 10, j + 43, k + 37, ModBlocks.gravewoodLeaves, 0);
		this.setBlock(world, i + 10, j + 43, k + 38, ModBlocks.gravewoodLeaves, 0);
		this.setBlock(world, i + 10, j + 43, k + 39, ModBlocks.gravewoodLeaves, 0);
		this.setBlock(world, i + 10, j + 43, k + 40, ModBlocks.gravewood, 1);
		this.setBlock(world, i + 10, j + 43, k + 41, ModBlocks.gravewood, 1);
		this.setBlock(world, i + 10, j + 43, k + 42, ModBlocks.gravewoodLeaves, 4);
		this.setBlock(world, i + 10, j + 44, k + 7, ModBlocks.gravewoodLeaves, 0);
		this.setBlock(world, i + 10, j + 44, k + 8, ModBlocks.gravewoodLeaves, 0);
		this.setBlock(world, i + 10, j + 44, k + 10, ModBlocks.gravewoodLeaves, 0);
		this.setBlock(world, i + 10, j + 44, k + 11, ModBlocks.gravewoodLeaves, 0);
		this.setBlock(world, i + 10, j + 44, k + 12, ModBlocks.gravewoodLeaves, 0);
		this.setBlock(world, i + 10, j + 44, k + 13, ModBlocks.gravewoodLeaves, 0);
		this.setBlock(world, i + 10, j + 44, k + 14, ModBlocks.gravewoodLeaves, 0);
		this.setBlock(world, i + 10, j + 44, k + 15, ModBlocks.gravewoodLeaves, 0);
		this.setBlock(world, i + 10, j + 44, k + 32, ModBlocks.gravewoodLeaves, 0);
		this.setBlock(world, i + 10, j + 44, k + 33, ModBlocks.gravewoodLeaves, 0);
		this.setBlock(world, i + 10, j + 44, k + 34, ModBlocks.gravewoodLeaves, 0);
		this.setBlock(world, i + 10, j + 44, k + 35, ModBlocks.gravewoodLeaves, 0);
		this.setBlock(world, i + 10, j + 44, k + 36, ModBlocks.gravewoodLeaves, 0);
		this.setBlock(world, i + 10, j + 44, k + 37, ModBlocks.gravewoodLeaves, 0);
		this.setBlock(world, i + 10, j + 44, k + 38, ModBlocks.gravewoodLeaves, 0);
		this.setBlock(world, i + 10, j + 44, k + 39, ModBlocks.gravewoodLeaves, 0);
		this.setBlock(world, i + 10, j + 44, k + 40, ModBlocks.gravewoodLeaves, 0);
		this.setBlock(world, i + 10, j + 44, k + 41, ModBlocks.gravewoodLeaves, 0);
		this.setBlock(world, i + 10, j + 44, k + 42, ModBlocks.gravewoodLeaves, 4);
		this.setBlock(world, i + 10, j + 45, k + 38, ModBlocks.gravewoodLeaves, 0);
		this.setBlock(world, i + 10, j + 45, k + 39, ModBlocks.gravewoodLeaves, 0);
		this.setBlock(world, i + 10, j + 45, k + 40, ModBlocks.gravewoodLeaves, 0);
		this.setBlock(world, i + 11, j + 36, k + 28, ModBlocks.gravewood, 1);
		this.setBlock(world, i + 11, j + 36, k + 29, ModBlocks.gravewood, 1);
		this.setBlock(world, i + 11, j + 36, k + 30, ModBlocks.gravewood, 1);
		this.setBlock(world, i + 11, j + 36, k + 31, ModBlocks.gravewood, 1);
		this.setBlock(world, i + 11, j + 37, k + 11, ModBlocks.gravewood, 1);
		this.setBlock(world, i + 11, j + 37, k + 12, ModBlocks.gravewood, 1);
		this.setBlock(world, i + 11, j + 37, k + 13, ModBlocks.gravewood, 1);
		this.setBlock(world, i + 11, j + 37, k + 22, ModBlocks.gravewood, 1);
		this.setBlock(world, i + 11, j + 37, k + 23, ModBlocks.gravewood, 1);
		this.setBlock(world, i + 11, j + 37, k + 24, ModBlocks.gravewood, 1);
		this.setBlock(world, i + 11, j + 37, k + 25, ModBlocks.gravewood, 1);
		this.setBlock(world, i + 11, j + 37, k + 26, ModBlocks.gravewoodLeaves, 0);
		this.setBlock(world, i + 11, j + 37, k + 27, ModBlocks.gravewood, 1);
		this.setBlock(world, i + 11, j + 37, k + 28, ModBlocks.gravewood, 1);
		this.setBlock(world, i + 11, j + 37, k + 29, ModBlocks.gravewood, 1);
		this.setBlock(world, i + 11, j + 37, k + 30, ModBlocks.gravewood, 1);
		this.setBlock(world, i + 11, j + 37, k + 31, ModBlocks.gravewood, 1);
		this.setBlock(world, i + 11, j + 38, k + 8, ModBlocks.gravewood, 1);
		this.setBlock(world, i + 11, j + 38, k + 9, ModBlocks.gravewood, 1);
		this.setBlock(world, i + 11, j + 38, k + 10, ModBlocks.gravewood, 1);
		this.setBlock(world, i + 11, j + 38, k + 11, ModBlocks.gravewood, 1);
		this.setBlock(world, i + 11, j + 38, k + 12, ModBlocks.gravewood, 1);
		this.setBlock(world, i + 11, j + 38, k + 13, ModBlocks.gravewood, 1);
		this.setBlock(world, i + 11, j + 38, k + 14, ModBlocks.gravewood, 1);
		this.setBlock(world, i + 11, j + 38, k + 15, ModBlocks.gravewood, 1);
		this.setBlock(world, i + 11, j + 38, k + 16, ModBlocks.gravewoodLeaves, 0);
		this.setBlock(world, i + 11, j + 38, k + 17, ModBlocks.gravewoodLeaves, 0);
		this.setBlock(world, i + 11, j + 38, k + 18, ModBlocks.gravewoodLeaves, 0);
		this.setBlock(world, i + 11, j + 38, k + 19, ModBlocks.gravewoodLeaves, 0);
		this.setBlock(world, i + 11, j + 38, k + 20, ModBlocks.gravewoodLeaves, 0);
		this.setBlock(world, i + 11, j + 38, k + 21, ModBlocks.gravewoodLeaves, 0);
		this.setBlock(world, i + 11, j + 38, k + 22, ModBlocks.gravewood, 1);
		this.setBlock(world, i + 11, j + 38, k + 23, ModBlocks.gravewood, 1);
		this.setBlock(world, i + 11, j + 38, k + 24, ModBlocks.gravewood, 1);
		this.setBlock(world, i + 11, j + 38, k + 25, ModBlocks.gravewood, 1);
		this.setBlock(world, i + 11, j + 38, k + 26, ModBlocks.gravewoodLeaves, 0);
		this.setBlock(world, i + 11, j + 38, k + 27, ModBlocks.gravewoodLeaves, 0);
		this.setBlock(world, i + 11, j + 38, k + 28, ModBlocks.gravewood, 1);
		this.setBlock(world, i + 11, j + 38, k + 29, ModBlocks.gravewood, 1);
		this.setBlock(world, i + 11, j + 38, k + 30, ModBlocks.gravewood, 1);
		this.setBlock(world, i + 11, j + 38, k + 31, ModBlocks.gravewood, 1);
		this.setBlock(world, i + 11, j + 38, k + 32, ModBlocks.gravewood, 1);
		this.setBlock(world, i + 11, j + 39, k + 7, ModBlocks.gravewood, 1);
		this.setBlock(world, i + 11, j + 39, k + 8, ModBlocks.gravewood, 1);
		this.setBlock(world, i + 11, j + 39, k + 9, ModBlocks.gravewood, 1);
		this.setBlock(world, i + 11, j + 39, k + 10, ModBlocks.gravewood, 1);
		this.setBlock(world, i + 11, j + 39, k + 11, ModBlocks.gravewood, 1);
		this.setBlock(world, i + 11, j + 39, k + 12, ModBlocks.gravewood, 1);
		this.setBlock(world, i + 11, j + 39, k + 13, ModBlocks.gravewood, 1);
		this.setBlock(world, i + 11, j + 39, k + 14, ModBlocks.gravewood, 1);
		this.setBlock(world, i + 11, j + 39, k + 15, ModBlocks.gravewood, 1);
		this.setBlock(world, i + 11, j + 39, k + 16, ModBlocks.gravewood, 1);
		this.setBlock(world, i + 11, j + 39, k + 17, ModBlocks.gravewoodLeaves, 0);
		this.setBlock(world, i + 11, j + 39, k + 18, ModBlocks.gravewood, 1);
		this.setBlock(world, i + 11, j + 39, k + 19, ModBlocks.gravewoodLeaves, 0);
		this.setBlock(world, i + 11, j + 39, k + 20, ModBlocks.gravewoodLeaves, 0);
		this.setBlock(world, i + 11, j + 39, k + 21, ModBlocks.gravewood, 1);
		this.setBlock(world, i + 11, j + 39, k + 22, ModBlocks.gravewood, 1);
		this.setBlock(world, i + 11, j + 39, k + 23, ModBlocks.gravewood, 1);
		this.setBlock(world, i + 11, j + 39, k + 24, ModBlocks.gravewood, 1);
		this.setBlock(world, i + 11, j + 39, k + 25, ModBlocks.gravewoodLeaves, 0);
		this.setBlock(world, i + 11, j + 39, k + 26, ModBlocks.gravewoodLeaves, 0);
		this.setBlock(world, i + 11, j + 39, k + 27, ModBlocks.gravewood, 1);
		this.setBlock(world, i + 11, j + 39, k + 28, ModBlocks.gravewood, 1);
		this.setBlock(world, i + 11, j + 39, k + 29, ModBlocks.gravewood, 1);
		this.setBlock(world, i + 11, j + 39, k + 30, ModBlocks.gravewood, 1);
		this.setBlock(world, i + 11, j + 39, k + 31, ModBlocks.gravewood, 1);
		this.setBlock(world, i + 11, j + 39, k + 32, ModBlocks.gravewood, 1);
		this.setBlock(world, i + 11, j + 39, k + 33, ModBlocks.gravewood, 1);
		this.setBlock(world, i + 11, j + 40, k + 6, ModBlocks.gravewoodLeaves, 0);
		this.setBlock(world, i + 11, j + 40, k + 7, ModBlocks.gravewood, 1);
		this.setBlock(world, i + 11, j + 40, k + 8, ModBlocks.gravewood, 1);
		this.setBlock(world, i + 11, j + 40, k + 9, ModBlocks.gravewood, 1);
		this.setBlock(world, i + 11, j + 40, k + 10, ModBlocks.gravewood, 1);
		this.setBlock(world, i + 11, j + 40, k + 11, ModBlocks.gravewood, 1);
		this.setBlock(world, i + 11, j + 40, k + 12, ModBlocks.gravewood, 1);
		this.setBlock(world, i + 11, j + 40, k + 13, ModBlocks.gravewood, 1);
		this.setBlock(world, i + 11, j + 40, k + 14, ModBlocks.gravewood, 1);
		this.setBlock(world, i + 11, j + 40, k + 15, ModBlocks.gravewoodLeaves, 0);
		this.setBlock(world, i + 11, j + 40, k + 16, ModBlocks.gravewoodLeaves, 0);
		this.setBlock(world, i + 11, j + 40, k + 17, ModBlocks.gravewood, 1);
		this.setBlock(world, i + 11, j + 40, k + 18, ModBlocks.gravewoodLeaves, 0);
		this.setBlock(world, i + 11, j + 40, k + 19, ModBlocks.gravewoodLeaves, 0);
		this.setBlock(world, i + 11, j + 40, k + 20, ModBlocks.gravewoodLeaves, 0);
		this.setBlock(world, i + 11, j + 40, k + 21, ModBlocks.gravewood, 1);
		this.setBlock(world, i + 11, j + 40, k + 22, ModBlocks.gravewood, 1);
		this.setBlock(world, i + 11, j + 40, k + 23, ModBlocks.gravewood, 1);
		this.setBlock(world, i + 11, j + 40, k + 24, ModBlocks.gravewoodLeaves, 0);
		this.setBlock(world, i + 11, j + 40, k + 25, ModBlocks.gravewoodLeaves, 0);
		this.setBlock(world, i + 11, j + 40, k + 26, ModBlocks.gravewoodLeaves, 0);
		this.setBlock(world, i + 11, j + 40, k + 27, ModBlocks.gravewood, 1);
		this.setBlock(world, i + 11, j + 40, k + 28, ModBlocks.gravewoodLeaves, 0);
		this.setBlock(world, i + 11, j + 40, k + 29, ModBlocks.gravewoodLeaves, 0);
		this.setBlock(world, i + 11, j + 40, k + 30, ModBlocks.gravewood, 1);
		this.setBlock(world, i + 11, j + 40, k + 31, ModBlocks.gravewood, 1);
		this.setBlock(world, i + 11, j + 40, k + 32, ModBlocks.gravewood, 1);
		this.setBlock(world, i + 11, j + 40, k + 33, ModBlocks.gravewood, 1);
		this.setBlock(world, i + 11, j + 40, k + 34, ModBlocks.gravewood, 1);
		this.setBlock(world, i + 11, j + 40, k + 35, ModBlocks.gravewoodLeaves, 0);
		this.setBlock(world, i + 11, j + 40, k + 36, ModBlocks.gravewoodLeaves, 0);
		this.setBlock(world, i + 11, j + 40, k + 37, ModBlocks.gravewoodLeaves, 0);
		this.setBlock(world, i + 11, j + 41, k + 5, ModBlocks.gravewoodLeaves, 0);
		this.setBlock(world, i + 11, j + 41, k + 6, ModBlocks.gravewoodLeaves, 0);
		this.setBlock(world, i + 11, j + 41, k + 7, ModBlocks.gravewoodLeaves, 0);
		this.setBlock(world, i + 11, j + 41, k + 8, ModBlocks.gravewoodLeaves, 0);
		this.setBlock(world, i + 11, j + 41, k + 9, ModBlocks.gravewood, 1);
		this.setBlock(world, i + 11, j + 41, k + 10, ModBlocks.gravewood, 1);
		this.setBlock(world, i + 11, j + 41, k + 11, ModBlocks.gravewood, 1);
		this.setBlock(world, i + 11, j + 41, k + 12, ModBlocks.gravewood, 1);
		this.setBlock(world, i + 11, j + 41, k + 13, ModBlocks.gravewood, 1);
		this.setBlock(world, i + 11, j + 41, k + 14, ModBlocks.gravewoodLeaves, 0);
		this.setBlock(world, i + 11, j + 41, k + 15, ModBlocks.gravewoodLeaves, 0);
		this.setBlock(world, i + 11, j + 41, k + 16, ModBlocks.gravewoodLeaves, 0);
		this.setBlock(world, i + 11, j + 41, k + 17, ModBlocks.gravewoodLeaves, 0);
		this.setBlock(world, i + 11, j + 41, k + 18, ModBlocks.gravewoodLeaves, 0);
		this.setBlock(world, i + 11, j + 41, k + 19, ModBlocks.gravewoodLeaves, 0);
		this.setBlock(world, i + 11, j + 41, k + 20, ModBlocks.gravewoodLeaves, 0);
		this.setBlock(world, i + 11, j + 41, k + 21, ModBlocks.gravewood, 1);
		this.setBlock(world, i + 11, j + 41, k + 22, ModBlocks.gravewood, 1);
		this.setBlock(world, i + 11, j + 41, k + 23, ModBlocks.gravewood, 1);
		this.setBlock(world, i + 11, j + 41, k + 24, ModBlocks.gravewoodLeaves, 0);
		this.setBlock(world, i + 11, j + 41, k + 25, ModBlocks.gravewoodLeaves, 0);
		this.setBlock(world, i + 11, j + 41, k + 26, ModBlocks.gravewoodLeaves, 0);
		this.setBlock(world, i + 11, j + 41, k + 27, ModBlocks.gravewoodLeaves, 0);
		this.setBlock(world, i + 11, j + 41, k + 28, ModBlocks.gravewoodLeaves, 0);
		this.setBlock(world, i + 11, j + 41, k + 29, ModBlocks.gravewoodLeaves, 0);
		this.setBlock(world, i + 11, j + 41, k + 30, ModBlocks.gravewood, 1);
		this.setBlock(world, i + 11, j + 41, k + 31, ModBlocks.gravewood, 1);
		this.setBlock(world, i + 11, j + 41, k + 32, ModBlocks.gravewood, 1);
		this.setBlock(world, i + 11, j + 41, k + 33, ModBlocks.gravewood, 1);
		this.setBlock(world, i + 11, j + 41, k + 34, ModBlocks.gravewoodLeaves, 0);
		this.setBlock(world, i + 11, j + 41, k + 35, ModBlocks.gravewoodLeaves, 0);
		this.setBlock(world, i + 11, j + 41, k + 36, ModBlocks.gravewoodLeaves, 0);
		this.setBlock(world, i + 11, j + 41, k + 37, ModBlocks.gravewoodLeaves, 0);
		this.setBlock(world, i + 11, j + 41, k + 38, ModBlocks.gravewoodLeaves, 0);
		this.setBlock(world, i + 11, j + 41, k + 39, ModBlocks.gravewood, 1);
		this.setBlock(world, i + 11, j + 41, k + 40, ModBlocks.gravewoodLeaves, 0);
		this.setBlock(world, i + 11, j + 42, k + 4, ModBlocks.gravewoodLeaves, 0);
		this.setBlock(world, i + 11, j + 42, k + 5, ModBlocks.gravewoodLeaves, 0);
		this.setBlock(world, i + 11, j + 42, k + 6, ModBlocks.gravewoodLeaves, 0);
		this.setBlock(world, i + 11, j + 42, k + 7, ModBlocks.gravewoodLeaves, 0);
		this.setBlock(world, i + 11, j + 42, k + 8, ModBlocks.gravewoodLeaves, 0);
		this.setBlock(world, i + 11, j + 42, k + 9, ModBlocks.gravewoodLeaves, 0);
		this.setBlock(world, i + 11, j + 42, k + 10, ModBlocks.gravewood, 1);
		this.setBlock(world, i + 11, j + 42, k + 11, ModBlocks.gravewoodLeaves, 0);
		this.setBlock(world, i + 11, j + 42, k + 12, ModBlocks.gravewood, 1);
		this.setBlock(world, i + 11, j + 42, k + 13, ModBlocks.gravewoodLeaves, 0);
		this.setBlock(world, i + 11, j + 42, k + 14, ModBlocks.gravewoodLeaves, 0);
		this.setBlock(world, i + 11, j + 42, k + 15, ModBlocks.gravewoodLeaves, 0);
		this.setBlock(world, i + 11, j + 42, k + 16, ModBlocks.gravewoodLeaves, 0);
		this.setBlock(world, i + 11, j + 42, k + 17, ModBlocks.gravewoodLeaves, 0);
		this.setBlock(world, i + 11, j + 42, k + 18, ModBlocks.gravewoodLeaves, 0);
		this.setBlock(world, i + 11, j + 42, k + 19, ModBlocks.gravewoodLeaves, 0);
		this.setBlock(world, i + 11, j + 42, k + 20, ModBlocks.gravewoodLeaves, 0);
