/*
*** MADE BY MRPONYCAPTAIN'S .SCHEMATIC TO .JAVA CONVERTING TOOL v2.0 ***
*/

package com.DavidM1A2.AfraidOfTheDark.common.worldGeneration.darkForestDungeon;

import java.util.Random;

import net.minecraft.block.Block;
import net.minecraft.init.Blocks;
import net.minecraft.util.BlockPos;
import net.minecraft.world.World;

import com.DavidM1A2.AfraidOfTheDark.common.initializeMod.ModBlocks;

public class TreeBranchyType1
{
    public static int width = 52;
    public static int height = 52;
    
    
	public TreeBranchyType1(World world, Random rand, int x, int y, int z)
	{
		this.generate(world, rand, x, y, z);
	}

	public void setBlock(World world, int x, int y, int z, Block block, int metadata)
	{
		world.setBlockState(new BlockPos(x, y, z), block.getStateFromMeta(metadata));
	}

	public boolean generate(World world, Random rand, int i, int j, int k)
	{
		this.setBlock(world, i + 0, j + 49, k + 17, ModBlocks.gravewoodLeaves, 0);
		this.setBlock(world, i + 0, j + 49, k + 18, ModBlocks.gravewoodLeaves, 0);
		this.setBlock(world, i + 0, j + 49, k + 19, ModBlocks.gravewoodLeaves, 0);
		this.setBlock(world, i + 0, j + 49, k + 20, ModBlocks.gravewoodLeaves, 0);
		this.setBlock(world, i + 0, j + 50, k + 22, ModBlocks.gravewoodLeaves, 0);
		this.setBlock(world, i + 0, j + 50, k + 23, ModBlocks.gravewoodLeaves, 0);
		this.setBlock(world, i + 0, j + 50, k + 24, ModBlocks.gravewoodLeaves, 0);
		this.setBlock(world, i + 0, j + 50, k + 25, ModBlocks.gravewoodLeaves, 0);
		this.setBlock(world, i + 0, j + 50, k + 26, ModBlocks.gravewoodLeaves, 0);
		this.setBlock(world, i + 1, j + 48, k + 17, ModBlocks.gravewoodLeaves, 0);
		this.setBlock(world, i + 1, j + 48, k + 18, ModBlocks.gravewood, 1);
		this.setBlock(world, i + 1, j + 48, k + 19, ModBlocks.gravewood, 1);
		this.setBlock(world, i + 1, j + 48, k + 20, ModBlocks.gravewoodLeaves, 0);
		this.setBlock(world, i + 1, j + 49, k + 16, ModBlocks.gravewoodLeaves, 0);
		this.setBlock(world, i + 1, j + 49, k + 17, ModBlocks.gravewoodLeaves, 0);
		this.setBlock(world, i + 1, j + 49, k + 18, ModBlocks.gravewoodLeaves, 0);
		this.setBlock(world, i + 1, j + 49, k + 19, ModBlocks.gravewoodLeaves, 0);
		this.setBlock(world, i + 1, j + 49, k + 20, ModBlocks.gravewood, 1);
		this.setBlock(world, i + 1, j + 49, k + 21, ModBlocks.gravewoodLeaves, 0);
		this.setBlock(world, i + 1, j + 49, k + 22, ModBlocks.gravewoodLeaves, 0);
		this.setBlock(world, i + 1, j + 49, k + 23, ModBlocks.gravewoodLeaves, 0);
		this.setBlock(world, i + 1, j + 49, k + 24, ModBlocks.gravewoodLeaves, 0);
		this.setBlock(world, i + 1, j + 49, k + 25, ModBlocks.gravewoodLeaves, 0);
		this.setBlock(world, i + 1, j + 49, k + 26, ModBlocks.gravewoodLeaves, 0);
		this.setBlock(world, i + 1, j + 50, k + 17, ModBlocks.gravewoodLeaves, 0);
		this.setBlock(world, i + 1, j + 50, k + 18, ModBlocks.gravewoodLeaves, 0);
		this.setBlock(world, i + 1, j + 50, k + 19, ModBlocks.gravewoodLeaves, 0);
		this.setBlock(world, i + 1, j + 50, k + 20, ModBlocks.gravewoodLeaves, 0);
		this.setBlock(world, i + 1, j + 50, k + 21, ModBlocks.gravewoodLeaves, 0);
		this.setBlock(world, i + 1, j + 50, k + 22, ModBlocks.gravewoodLeaves, 0);
		this.setBlock(world, i + 1, j + 50, k + 23, ModBlocks.gravewoodLeaves, 0);
		this.setBlock(world, i + 1, j + 50, k + 24, ModBlocks.gravewoodLeaves, 0);
		this.setBlock(world, i + 1, j + 50, k + 25, ModBlocks.gravewoodLeaves, 0);
		this.setBlock(world, i + 1, j + 50, k + 26, ModBlocks.gravewoodLeaves, 0);
		this.setBlock(world, i + 1, j + 50, k + 27, ModBlocks.gravewoodLeaves, 0);
		this.setBlock(world, i + 1, j + 50, k + 28, ModBlocks.gravewoodLeaves, 0);
		this.setBlock(world, i + 1, j + 51, k + 22, ModBlocks.gravewoodLeaves, 0);
		this.setBlock(world, i + 1, j + 51, k + 23, ModBlocks.gravewoodLeaves, 0);
		this.setBlock(world, i + 1, j + 51, k + 24, ModBlocks.gravewoodLeaves, 0);
		this.setBlock(world, i + 1, j + 51, k + 25, ModBlocks.gravewoodLeaves, 0);
		this.setBlock(world, i + 1, j + 51, k + 26, ModBlocks.gravewoodLeaves, 0);
		this.setBlock(world, i + 1, j + 52, k + 33, ModBlocks.gravewoodLeaves, 8);
		this.setBlock(world, i + 1, j + 52, k + 34, ModBlocks.gravewoodLeaves, 0);
		this.setBlock(world, i + 1, j + 52, k + 35, ModBlocks.gravewoodLeaves, 0);
		this.setBlock(world, i + 2, j + 47, k + 20, ModBlocks.gravewoodLeaves, 0);
		this.setBlock(world, i + 2, j + 47, k + 21, ModBlocks.gravewoodLeaves, 0);
		this.setBlock(world, i + 2, j + 47, k + 22, ModBlocks.gravewood, 1);
		this.setBlock(world, i + 2, j + 48, k + 17, ModBlocks.gravewoodLeaves, 0);
		this.setBlock(world, i + 2, j + 48, k + 19, ModBlocks.gravewoodLeaves, 0);
		this.setBlock(world, i + 2, j + 48, k + 20, ModBlocks.gravewoodLeaves, 0);
		this.setBlock(world, i + 2, j + 48, k + 21, ModBlocks.gravewoodLeaves, 0);
		this.setBlock(world, i + 2, j + 48, k + 22, ModBlocks.gravewoodLeaves, 0);
		this.setBlock(world, i + 2, j + 48, k + 23, ModBlocks.gravewoodLeaves, 0);
		this.setBlock(world, i + 2, j + 48, k + 25, ModBlocks.gravewoodLeaves, 0);
		this.setBlock(world, i + 2, j + 48, k + 26, ModBlocks.gravewoodLeaves, 0);
		this.setBlock(world, i + 2, j + 48, k + 27, ModBlocks.gravewoodLeaves, 0);
		this.setBlock(world, i + 2, j + 49, k + 14, ModBlocks.gravewoodLeaves, 8);
		this.setBlock(world, i + 2, j + 49, k + 15, ModBlocks.gravewoodLeaves, 8);
		this.setBlock(world, i + 2, j + 49, k + 16, ModBlocks.gravewoodLeaves, 0);
		this.setBlock(world, i + 2, j + 49, k + 17, ModBlocks.gravewoodLeaves, 0);
		this.setBlock(world, i + 2, j + 49, k + 18, ModBlocks.gravewoodLeaves, 0);
		this.setBlock(world, i + 2, j + 49, k + 19, ModBlocks.gravewoodLeaves, 0);
		this.setBlock(world, i + 2, j + 49, k + 20, ModBlocks.gravewoodLeaves, 0);
		this.setBlock(world, i + 2, j + 49, k + 21, ModBlocks.gravewoodLeaves, 0);
		this.setBlock(world, i + 2, j + 49, k + 22, ModBlocks.gravewoodLeaves, 0);
		this.setBlock(world, i + 2, j + 49, k + 23, ModBlocks.gravewoodLeaves, 0);
		this.setBlock(world, i + 2, j + 49, k + 24, ModBlocks.gravewood, 1);
		this.setBlock(world, i + 2, j + 49, k + 25, ModBlocks.gravewoodLeaves, 0);
		this.setBlock(world, i + 2, j + 49, k + 26, ModBlocks.gravewoodLeaves, 0);
		this.setBlock(world, i + 2, j + 49, k + 27, ModBlocks.gravewoodLeaves, 0);
		this.setBlock(world, i + 2, j + 49, k + 28, ModBlocks.gravewood, 1);
		this.setBlock(world, i + 2, j + 50, k + 19, ModBlocks.gravewoodLeaves, 0);
		this.setBlock(world, i + 2, j + 50, k + 20, ModBlocks.gravewoodLeaves, 0);
		this.setBlock(world, i + 2, j + 50, k + 21, ModBlocks.gravewoodLeaves, 0);
		this.setBlock(world, i + 2, j + 50, k + 22, ModBlocks.gravewoodLeaves, 0);
		this.setBlock(world, i + 2, j + 50, k + 23, ModBlocks.gravewoodLeaves, 0);
		this.setBlock(world, i + 2, j + 50, k + 24, ModBlocks.gravewoodLeaves, 0);
		this.setBlock(world, i + 2, j + 50, k + 25, ModBlocks.gravewoodLeaves, 0);
		this.setBlock(world, i + 2, j + 50, k + 26, ModBlocks.gravewoodLeaves, 0);
		this.setBlock(world, i + 2, j + 50, k + 27, ModBlocks.gravewoodLeaves, 0);
		this.setBlock(world, i + 2, j + 50, k + 28, ModBlocks.gravewoodLeaves, 0);
		this.setBlock(world, i + 2, j + 50, k + 29, ModBlocks.gravewoodLeaves, 0);
		this.setBlock(world, i + 2, j + 51, k + 20, ModBlocks.gravewoodLeaves, 0);
		this.setBlock(world, i + 2, j + 51, k + 21, ModBlocks.gravewoodLeaves, 0);
		this.setBlock(world, i + 2, j + 51, k + 22, ModBlocks.gravewoodLeaves, 0);
		this.setBlock(world, i + 2, j + 51, k + 24, ModBlocks.gravewoodLeaves, 0);
		this.setBlock(world, i + 2, j + 51, k + 25, ModBlocks.gravewood, 1);
		this.setBlock(world, i + 2, j + 51, k + 26, ModBlocks.gravewoodLeaves, 0);
		this.setBlock(world, i + 2, j + 51, k + 27, ModBlocks.gravewoodLeaves, 0);
		this.setBlock(world, i + 2, j + 51, k + 28, ModBlocks.gravewoodLeaves, 0);
		this.setBlock(world, i + 2, j + 51, k + 31, ModBlocks.gravewoodLeaves, 0);
		this.setBlock(world, i + 2, j + 51, k + 33, ModBlocks.gravewoodLeaves, 0);
		this.setBlock(world, i + 2, j + 51, k + 34, ModBlocks.gravewoodLeaves, 0);
		this.setBlock(world, i + 2, j + 51, k + 35, ModBlocks.gravewoodLeaves, 0);
		this.setBlock(world, i + 2, j + 52, k + 25, ModBlocks.gravewoodLeaves, 0);
		this.setBlock(world, i + 2, j + 52, k + 26, ModBlocks.gravewoodLeaves, 0);
		this.setBlock(world, i + 2, j + 52, k + 27, ModBlocks.gravewoodLeaves, 0);
		this.setBlock(world, i + 2, j + 52, k + 32, ModBlocks.gravewoodLeaves, 8);
		this.setBlock(world, i + 2, j + 52, k + 33, ModBlocks.gravewoodLeaves, 0);
		this.setBlock(world, i + 2, j + 52, k + 34, ModBlocks.gravewoodLeaves, 0);
		this.setBlock(world, i + 2, j + 52, k + 35, ModBlocks.gravewoodLeaves, 0);
		this.setBlock(world, i + 2, j + 52, k + 36, ModBlocks.gravewoodLeaves, 0);
		this.setBlock(world, i + 2, j + 53, k + 33, ModBlocks.gravewoodLeaves, 8);
		this.setBlock(world, i + 2, j + 53, k + 34, ModBlocks.gravewoodLeaves, 0);
		this.setBlock(world, i + 2, j + 53, k + 35, ModBlocks.gravewoodLeaves, 0);
		this.setBlock(world, i + 3, j + 46, k + 16, ModBlocks.gravewoodLeaves, 0);
		this.setBlock(world, i + 3, j + 46, k + 17, ModBlocks.gravewoodLeaves, 0);
		this.setBlock(world, i + 3, j + 46, k + 18, ModBlocks.gravewoodLeaves, 0);
		this.setBlock(world, i + 3, j + 47, k + 15, ModBlocks.gravewoodLeaves, 0);
		this.setBlock(world, i + 3, j + 47, k + 16, ModBlocks.gravewoodLeaves, 0);
		this.setBlock(world, i + 3, j + 47, k + 17, ModBlocks.gravewoodLeaves, 0);
		this.setBlock(world, i + 3, j + 47, k + 18, ModBlocks.gravewood, 1);
		this.setBlock(world, i + 3, j + 47, k + 19, ModBlocks.gravewoodLeaves, 0);
		this.setBlock(world, i + 3, j + 47, k + 20, ModBlocks.gravewoodLeaves, 0);
		this.setBlock(world, i + 3, j + 47, k + 21, ModBlocks.gravewoodLeaves, 0);
		this.setBlock(world, i + 3, j + 47, k + 22, ModBlocks.gravewoodLeaves, 0);
		this.setBlock(world, i + 3, j + 47, k + 23, ModBlocks.gravewood, 1);
		this.setBlock(world, i + 3, j + 48, k + 14, ModBlocks.gravewoodLeaves, 0);
		this.setBlock(world, i + 3, j + 48, k + 15, ModBlocks.gravewoodLeaves, 0);
		this.setBlock(world, i + 3, j + 48, k + 16, ModBlocks.gravewoodLeaves, 0);
		this.setBlock(world, i + 3, j + 48, k + 17, ModBlocks.gravewoodLeaves, 0);
		this.setBlock(world, i + 3, j + 48, k + 18, ModBlocks.gravewoodLeaves, 0);
		this.setBlock(world, i + 3, j + 48, k + 19, ModBlocks.gravewoodLeaves, 0);
		this.setBlock(world, i + 3, j + 48, k + 20, ModBlocks.gravewoodLeaves, 0);
		this.setBlock(world, i + 3, j + 48, k + 21, ModBlocks.gravewoodLeaves, 0);
		this.setBlock(world, i + 3, j + 48, k + 22, ModBlocks.gravewood, 1);
		this.setBlock(world, i + 3, j + 48, k + 23, ModBlocks.gravewoodLeaves, 0);
		this.setBlock(world, i + 3, j + 48, k + 24, ModBlocks.gravewood, 1);
		this.setBlock(world, i + 3, j + 48, k + 25, ModBlocks.gravewoodLeaves, 0);
		this.setBlock(world, i + 3, j + 48, k + 26, ModBlocks.gravewoodLeaves, 0);
		this.setBlock(world, i + 3, j + 48, k + 27, ModBlocks.gravewoodLeaves, 0);
		this.setBlock(world, i + 3, j + 48, k + 28, ModBlocks.gravewoodLeaves, 0);
		this.setBlock(world, i + 3, j + 49, k + 13, ModBlocks.gravewoodLeaves, 0);
		this.setBlock(world, i + 3, j + 49, k + 14, ModBlocks.gravewoodLeaves, 8);
		this.setBlock(world, i + 3, j + 49, k + 15, ModBlocks.gravewoodLeaves, 0);
		this.setBlock(world, i + 3, j + 49, k + 16, ModBlocks.gravewoodLeaves, 0);
		this.setBlock(world, i + 3, j + 49, k + 17, ModBlocks.gravewoodLeaves, 0);
		this.setBlock(world, i + 3, j + 49, k + 18, ModBlocks.gravewoodLeaves, 0);
		this.setBlock(world, i + 3, j + 49, k + 19, ModBlocks.gravewoodLeaves, 0);
		this.setBlock(world, i + 3, j + 49, k + 20, ModBlocks.gravewood, 1);
		this.setBlock(world, i + 3, j + 49, k + 21, ModBlocks.gravewoodLeaves, 0);
		this.setBlock(world, i + 3, j + 49, k + 22, ModBlocks.gravewoodLeaves, 0);
		this.setBlock(world, i + 3, j + 49, k + 23, ModBlocks.gravewoodLeaves, 0);
		this.setBlock(world, i + 3, j + 49, k + 24, ModBlocks.gravewoodLeaves, 0);
		this.setBlock(world, i + 3, j + 49, k + 25, ModBlocks.gravewoodLeaves, 0);
		this.setBlock(world, i + 3, j + 49, k + 26, ModBlocks.gravewoodLeaves, 0);
		this.setBlock(world, i + 3, j + 49, k + 27, ModBlocks.gravewoodLeaves, 0);
		this.setBlock(world, i + 3, j + 49, k + 28, ModBlocks.gravewoodLeaves, 0);
		this.setBlock(world, i + 3, j + 49, k + 29, ModBlocks.gravewoodLeaves, 0);
		this.setBlock(world, i + 3, j + 50, k + 14, ModBlocks.gravewoodLeaves, 0);
		this.setBlock(world, i + 3, j + 50, k + 15, ModBlocks.gravewoodLeaves, 8);
		this.setBlock(world, i + 3, j + 50, k + 16, ModBlocks.gravewoodLeaves, 0);
		this.setBlock(world, i + 3, j + 50, k + 17, ModBlocks.gravewoodLeaves, 0);
		this.setBlock(world, i + 3, j + 50, k + 18, ModBlocks.gravewoodLeaves, 0);
		this.setBlock(world, i + 3, j + 50, k + 19, ModBlocks.gravewoodLeaves, 0);
		this.setBlock(world, i + 3, j + 50, k + 20, ModBlocks.gravewoodLeaves, 0);
		this.setBlock(world, i + 3, j + 50, k + 21, ModBlocks.gravewoodLeaves, 0);
		this.setBlock(world, i + 3, j + 50, k + 22, ModBlocks.gravewoodLeaves, 0);
		this.setBlock(world, i + 3, j + 50, k + 23, ModBlocks.gravewoodLeaves, 0);
		this.setBlock(world, i + 3, j + 50, k + 24, ModBlocks.gravewoodLeaves, 0);
		this.setBlock(world, i + 3, j + 50, k + 25, ModBlocks.gravewoodLeaves, 0);
		this.setBlock(world, i + 3, j + 50, k + 26, ModBlocks.gravewoodLeaves, 0);
		this.setBlock(world, i + 3, j + 50, k + 27, ModBlocks.gravewoodLeaves, 0);
		this.setBlock(world, i + 3, j + 50, k + 28, ModBlocks.gravewoodLeaves, 0);
		this.setBlock(world, i + 3, j + 50, k + 29, ModBlocks.gravewoodLeaves, 0);
		this.setBlock(world, i + 3, j + 50, k + 30, ModBlocks.gravewood, 1);
		this.setBlock(world, i + 3, j + 50, k + 31, ModBlocks.gravewoodLeaves, 0);
		this.setBlock(world, i + 3, j + 51, k + 19, ModBlocks.gravewoodLeaves, 0);
		this.setBlock(world, i + 3, j + 51, k + 20, ModBlocks.gravewoodLeaves, 0);
		this.setBlock(world, i + 3, j + 51, k + 21, ModBlocks.gravewoodLeaves, 0);
		this.setBlock(world, i + 3, j + 51, k + 22, ModBlocks.gravewoodLeaves, 0);
		this.setBlock(world, i + 3, j + 51, k + 23, ModBlocks.gravewoodLeaves, 0);
		this.setBlock(world, i + 3, j + 51, k + 24, ModBlocks.gravewoodLeaves, 0);
		this.setBlock(world, i + 3, j + 51, k + 25, ModBlocks.gravewood, 1);
		this.setBlock(world, i + 3, j + 51, k + 26, ModBlocks.gravewoodLeaves, 0);
		this.setBlock(world, i + 3, j + 51, k + 27, ModBlocks.gravewoodLeaves, 0);
		this.setBlock(world, i + 3, j + 51, k + 28, ModBlocks.gravewoodLeaves, 0);
		this.setBlock(world, i + 3, j + 51, k + 29, ModBlocks.gravewoodLeaves, 0);
		this.setBlock(world, i + 3, j + 51, k + 30, ModBlocks.gravewoodLeaves, 0);
		this.setBlock(world, i + 3, j + 51, k + 31, ModBlocks.gravewoodLeaves, 0);
		this.setBlock(world, i + 3, j + 51, k + 32, ModBlocks.gravewoodLeaves, 0);
		this.setBlock(world, i + 3, j + 51, k + 33, ModBlocks.gravewoodLeaves, 0);
		this.setBlock(world, i + 3, j + 51, k + 35, ModBlocks.gravewoodLeaves, 0);
		this.setBlock(world, i + 3, j + 52, k + 24, ModBlocks.gravewoodLeaves, 0);
		this.setBlock(world, i + 3, j + 52, k + 25, ModBlocks.gravewoodLeaves, 0);
		this.setBlock(world, i + 3, j + 52, k + 26, ModBlocks.gravewoodLeaves, 0);
		this.setBlock(world, i + 3, j + 52, k + 27, ModBlocks.gravewoodLeaves, 0);
		this.setBlock(world, i + 3, j + 52, k + 28, ModBlocks.gravewoodLeaves, 0);
		this.setBlock(world, i + 3, j + 52, k + 31, ModBlocks.gravewoodLeaves, 0);
		this.setBlock(world, i + 3, j + 52, k + 33, ModBlocks.gravewoodLeaves, 0);
		this.setBlock(world, i + 3, j + 52, k + 34, ModBlocks.gravewoodLeaves, 0);
		this.setBlock(world, i + 3, j + 52, k + 35, ModBlocks.gravewoodLeaves, 0);
		this.setBlock(world, i + 3, j + 52, k + 36, ModBlocks.gravewoodLeaves, 0);
		this.setBlock(world, i + 3, j + 53, k + 35, ModBlocks.gravewoodLeaves, 0);
		this.setBlock(world, i + 4, j + 46, k + 15, ModBlocks.gravewood, 1);
		this.setBlock(world, i + 4, j + 46, k + 16, ModBlocks.gravewoodLeaves, 0);
		this.setBlock(world, i + 4, j + 46, k + 17, ModBlocks.gravewoodLeaves, 0);
		this.setBlock(world, i + 4, j + 46, k + 18, ModBlocks.gravewoodLeaves, 0);
		this.setBlock(world, i + 4, j + 46, k + 19, ModBlocks.gravewoodLeaves, 0);
		this.setBlock(world, i + 4, j + 46, k + 21, ModBlocks.gravewoodLeaves, 0);
		this.setBlock(world, i + 4, j + 46, k + 22, ModBlocks.gravewoodLeaves, 0);
		this.setBlock(world, i + 4, j + 46, k + 23, ModBlocks.gravewoodLeaves, 0);
		this.setBlock(world, i + 4, j + 46, k + 24, ModBlocks.gravewoodLeaves, 0);
		this.setBlock(world, i + 4, j + 47, k + 15, ModBlocks.gravewoodLeaves, 0);
		this.setBlock(world, i + 4, j + 47, k + 16, ModBlocks.gravewoodLeaves, 0);
		this.setBlock(world, i + 4, j + 47, k + 17, ModBlocks.gravewoodLeaves, 0);
		this.setBlock(world, i + 4, j + 47, k + 18, ModBlocks.gravewoodLeaves, 0);
		this.setBlock(world, i + 4, j + 47, k + 19, ModBlocks.gravewoodLeaves, 0);
		this.setBlock(world, i + 4, j + 47, k + 20, ModBlocks.gravewoodLeaves, 0);
		this.setBlock(world, i + 4, j + 47, k + 21, ModBlocks.gravewoodLeaves, 0);
		this.setBlock(world, i + 4, j + 47, k + 22, ModBlocks.gravewoodLeaves, 0);
		this.setBlock(world, i + 4, j + 47, k + 23, ModBlocks.gravewoodLeaves, 0);
		this.setBlock(world, i + 4, j + 47, k + 24, ModBlocks.gravewoodLeaves, 0);
		this.setBlock(world, i + 4, j + 47, k + 25, ModBlocks.gravewoodLeaves, 0);
		this.setBlock(world, i + 4, j + 47, k + 26, ModBlocks.gravewood, 1);
		this.setBlock(world, i + 4, j + 47, k + 27, ModBlocks.gravewoodLeaves, 0);
		this.setBlock(world, i + 4, j + 47, k + 28, ModBlocks.gravewood, 1);
		this.setBlock(world, i + 4, j + 47, k + 29, ModBlocks.gravewoodLeaves, 0);
		this.setBlock(world, i + 4, j + 48, k + 14, ModBlocks.gravewoodLeaves, 0);
		this.setBlock(world, i + 4, j + 48, k + 15, ModBlocks.gravewoodLeaves, 0);
		this.setBlock(world, i + 4, j + 48, k + 16, ModBlocks.gravewoodLeaves, 0);
		this.setBlock(world, i + 4, j + 48, k + 17, ModBlocks.gravewoodLeaves, 0);
		this.setBlock(world, i + 4, j + 48, k + 18, ModBlocks.gravewoodLeaves, 0);
		this.setBlock(world, i + 4, j + 48, k + 19, ModBlocks.gravewoodLeaves, 0);
		this.setBlock(world, i + 4, j + 48, k + 20, ModBlocks.gravewoodLeaves, 0);
		this.setBlock(world, i + 4, j + 48, k + 21, ModBlocks.gravewoodLeaves, 0);
		this.setBlock(world, i + 4, j + 48, k + 22, ModBlocks.gravewoodLeaves, 0);
		this.setBlock(world, i + 4, j + 48, k + 23, ModBlocks.gravewoodLeaves, 0);
		this.setBlock(world, i + 4, j + 48, k + 24, ModBlocks.gravewoodLeaves, 0);
		this.setBlock(world, i + 4, j + 48, k + 25, ModBlocks.gravewoodLeaves, 0);
		this.setBlock(world, i + 4, j + 48, k + 26, ModBlocks.gravewoodLeaves, 0);
		this.setBlock(world, i + 4, j + 48, k + 27, ModBlocks.gravewoodLeaves, 0);
		this.setBlock(world, i + 4, j + 48, k + 28, ModBlocks.gravewoodLeaves, 0);
		this.setBlock(world, i + 4, j + 48, k + 29, ModBlocks.gravewoodLeaves, 0);
		this.setBlock(world, i + 4, j + 48, k + 30, ModBlocks.gravewoodLeaves, 0);
		this.setBlock(world, i + 4, j + 49, k + 14, ModBlocks.gravewoodLeaves, 0);
		this.setBlock(world, i + 4, j + 49, k + 15, ModBlocks.gravewoodLeaves, 0);
		this.setBlock(world, i + 4, j + 49, k + 16, ModBlocks.gravewoodLeaves, 0);
		this.setBlock(world, i + 4, j + 49, k + 17, ModBlocks.gravewoodLeaves, 0);
		this.setBlock(world, i + 4, j + 49, k + 18, ModBlocks.gravewood, 1);
		this.setBlock(world, i + 4, j + 49, k + 19, ModBlocks.gravewoodLeaves, 0);
		this.setBlock(world, i + 4, j + 49, k + 20, ModBlocks.gravewoodLeaves, 0);
		this.setBlock(world, i + 4, j + 49, k + 21, ModBlocks.gravewoodLeaves, 0);
		this.setBlock(world, i + 4, j + 49, k + 22, ModBlocks.gravewoodLeaves, 0);
		this.setBlock(world, i + 4, j + 49, k + 23, ModBlocks.gravewoodLeaves, 0);
		this.setBlock(world, i + 4, j + 49, k + 24, ModBlocks.gravewoodLeaves, 0);
		this.setBlock(world, i + 4, j + 49, k + 25, ModBlocks.gravewoodLeaves, 0);
		this.setBlock(world, i + 4, j + 49, k + 26, ModBlocks.gravewoodLeaves, 0);
		this.setBlock(world, i + 4, j + 49, k + 27, ModBlocks.gravewoodLeaves, 0);
		this.setBlock(world, i + 4, j + 49, k + 28, ModBlocks.gravewoodLeaves, 0);
		this.setBlock(world, i + 4, j + 49, k + 29, ModBlocks.gravewoodLeaves, 0);
		this.setBlock(world, i + 4, j + 49, k + 30, ModBlocks.gravewoodLeaves, 0);
		this.setBlock(world, i + 4, j + 49, k + 32, ModBlocks.gravewoodLeaves, 0);
		this.setBlock(world, i + 4, j + 49, k + 33, ModBlocks.gravewoodLeaves, 0);
		this.setBlock(world, i + 4, j + 49, k + 34, ModBlocks.gravewoodLeaves, 0);
		this.setBlock(world, i + 4, j + 50, k + 15, ModBlocks.gravewoodLeaves, 0);
		this.setBlock(world, i + 4, j + 50, k + 16, ModBlocks.gravewoodLeaves, 0);
		this.setBlock(world, i + 4, j + 50, k + 17, ModBlocks.gravewoodLeaves, 0);
		this.setBlock(world, i + 4, j + 50, k + 18, ModBlocks.gravewoodLeaves, 0);
		this.setBlock(world, i + 4, j + 50, k + 19, ModBlocks.gravewoodLeaves, 0);
		this.setBlock(world, i + 4, j + 50, k + 20, ModBlocks.gravewood, 1);
		this.setBlock(world, i + 4, j + 50, k + 21, ModBlocks.gravewoodLeaves, 0);
		this.setBlock(world, i + 4, j + 50, k + 22, ModBlocks.gravewoodLeaves, 0);
		this.setBlock(world, i + 4, j + 50, k + 23, ModBlocks.gravewood, 1);
		this.setBlock(world, i + 4, j + 50, k + 24, ModBlocks.gravewoodLeaves, 0);
		this.setBlock(world, i + 4, j + 50, k + 25, ModBlocks.gravewoodLeaves, 0);
		this.setBlock(world, i + 4, j + 50, k + 26, ModBlocks.gravewoodLeaves, 0);
		this.setBlock(world, i + 4, j + 50, k + 27, ModBlocks.gravewoodLeaves, 0);
		this.setBlock(world, i + 4, j + 50, k + 28, ModBlocks.gravewood, 1);
		this.setBlock(world, i + 4, j + 50, k + 29, ModBlocks.gravewoodLeaves, 0);
		this.setBlock(world, i + 4, j + 50, k + 30, ModBlocks.gravewoodLeaves, 0);
		this.setBlock(world, i + 4, j + 50, k + 31, ModBlocks.gravewoodLeaves, 0);
		this.setBlock(world, i + 4, j + 50, k + 32, ModBlocks.gravewoodLeaves, 0);
		this.setBlock(world, i + 4, j + 50, k + 33, ModBlocks.gravewoodLeaves, 0);
		this.setBlock(world, i + 4, j + 50, k + 34, ModBlocks.gravewoodLeaves, 0);
		this.setBlock(world, i + 4, j + 50, k + 35, ModBlocks.gravewoodLeaves, 0);
		this.setBlock(world, i + 4, j + 51, k + 19, ModBlocks.gravewoodLeaves, 0);
		this.setBlock(world, i + 4, j + 51, k + 20, ModBlocks.gravewoodLeaves, 0);
		this.setBlock(world, i + 4, j + 51, k + 21, ModBlocks.gravewoodLeaves, 0);
		this.setBlock(world, i + 4, j + 51, k + 22, ModBlocks.gravewoodLeaves, 0);
		this.setBlock(world, i + 4, j + 51, k + 23, ModBlocks.gravewoodLeaves, 0);
		this.setBlock(world, i + 4, j + 51, k + 24, ModBlocks.gravewoodLeaves, 0);
		this.setBlock(world, i + 4, j + 51, k + 25, ModBlocks.gravewoodLeaves, 0);
		this.setBlock(world, i + 4, j + 51, k + 26, ModBlocks.gravewoodLeaves, 0);
		this.setBlock(world, i + 4, j + 51, k + 27, ModBlocks.gravewoodLeaves, 0);
		this.setBlock(world, i + 4, j + 51, k + 28, ModBlocks.gravewoodLeaves, 0);
		this.setBlock(world, i + 4, j + 51, k + 29, ModBlocks.gravewoodLeaves, 0);
		this.setBlock(world, i + 4, j + 51, k + 30, ModBlocks.gravewoodLeaves, 0);
		this.setBlock(world, i + 4, j + 51, k + 31, ModBlocks.gravewood, 1);
		this.setBlock(world, i + 4, j + 51, k + 32, ModBlocks.gravewoodLeaves, 0);
		this.setBlock(world, i + 4, j + 51, k + 33, ModBlocks.gravewoodLeaves, 0);
		this.setBlock(world, i + 4, j + 51, k + 34, ModBlocks.gravewoodLeaves, 0);
		this.setBlock(world, i + 4, j + 51, k + 35, ModBlocks.gravewoodLeaves, 0);
		this.setBlock(world, i + 4, j + 52, k + 21, ModBlocks.gravewoodLeaves, 0);
		this.setBlock(world, i + 4, j + 52, k + 24, ModBlocks.gravewoodLeaves, 0);
		this.setBlock(world, i + 4, j + 52, k + 25, ModBlocks.gravewoodLeaves, 0);
		this.setBlock(world, i + 4, j + 52, k + 26, ModBlocks.gravewoodLeaves, 0);
		this.setBlock(world, i + 4, j + 52, k + 27, ModBlocks.gravewoodLeaves, 0);
		this.setBlock(world, i + 4, j + 52, k + 28, ModBlocks.gravewoodLeaves, 0);
		this.setBlock(world, i + 4, j + 52, k + 31, ModBlocks.gravewoodLeaves, 0);
		this.setBlock(world, i + 4, j + 52, k + 32, ModBlocks.gravewoodLeaves, 0);
		this.setBlock(world, i + 4, j + 52, k + 33, ModBlocks.gravewoodLeaves, 0);
		this.setBlock(world, i + 4, j + 52, k + 34, ModBlocks.gravewoodLeaves, 0);
		this.setBlock(world, i + 4, j + 52, k + 35, ModBlocks.gravewoodLeaves, 0);
		this.setBlock(world, i + 4, j + 52, k + 36, ModBlocks.gravewoodLeaves, 0);
		this.setBlock(world, i + 4, j + 53, k + 26, ModBlocks.gravewoodLeaves, 0);
		this.setBlock(world, i + 4, j + 53, k + 32, ModBlocks.gravewoodLeaves, 0);
		this.setBlock(world, i + 4, j + 53, k + 33, ModBlocks.gravewoodLeaves, 0);
		this.setBlock(world, i + 4, j + 53, k + 34, ModBlocks.gravewoodLeaves, 0);
		this.setBlock(world, i + 4, j + 53, k + 35, ModBlocks.gravewoodLeaves, 0);
		this.setBlock(world, i + 5, j + 45, k + 16, ModBlocks.gravewoodLeaves, 0);
		this.setBlock(world, i + 5, j + 45, k + 17, ModBlocks.gravewoodLeaves, 0);
		this.setBlock(world, i + 5, j + 45, k + 18, ModBlocks.gravewoodLeaves, 0);
		this.setBlock(world, i + 5, j + 45, k + 19, ModBlocks.gravewood, 1);
		this.setBlock(world, i + 5, j + 45, k + 20, ModBlocks.gravewoodLeaves, 0);
		this.setBlock(world, i + 5, j + 45, k + 21, ModBlocks.gravewoodLeaves, 0);
		this.setBlock(world, i + 5, j + 46, k + 15, ModBlocks.gravewoodLeaves, 0);
		this.setBlock(world, i + 5, j + 46, k + 16, ModBlocks.gravewoodLeaves, 0);
		this.setBlock(world, i + 5, j + 46, k + 17, ModBlocks.gravewoodLeaves, 0);
		this.setBlock(world, i + 5, j + 46, k + 18, ModBlocks.gravewoodLeaves, 0);
		this.setBlock(world, i + 5, j + 46, k + 19, ModBlocks.gravewoodLeaves, 0);
		this.setBlock(world, i + 5, j + 46, k + 20, ModBlocks.gravewoodLeaves, 0);
		this.setBlock(world, i + 5, j + 46, k + 21, ModBlocks.gravewoodLeaves, 0);
		this.setBlock(world, i + 5, j + 46, k + 22, ModBlocks.gravewoodLeaves, 0);
		this.setBlock(world, i + 5, j + 46, k + 23, ModBlocks.gravewoodLeaves, 0);
		this.setBlock(world, i + 5, j + 46, k + 24, ModBlocks.gravewoodLeaves, 0);
		this.setBlock(world, i + 5, j + 46, k + 25, ModBlocks.gravewoodLeaves, 0);
		this.setBlock(world, i + 5, j + 47, k + 14, ModBlocks.gravewoodLeaves, 0);
		this.setBlock(world, i + 5, j + 47, k + 15, ModBlocks.gravewoodLeaves, 0);
		this.setBlock(world, i + 5, j + 47, k + 16, ModBlocks.gravewoodLeaves, 0);
		this.setBlock(world, i + 5, j + 47, k + 17, ModBlocks.gravewoodLeaves, 0);
		this.setBlock(world, i + 5, j + 47, k + 18, ModBlocks.gravewoodLeaves, 0);
		this.setBlock(world, i + 5, j + 47, k + 19, ModBlocks.gravewoodLeaves, 0);
		this.setBlock(world, i + 5, j + 47, k + 20, ModBlocks.gravewoodLeaves, 0);
		this.setBlock(world, i + 5, j + 47, k + 21, ModBlocks.gravewoodLeaves, 0);
		this.setBlock(world, i + 5, j + 47, k + 22, ModBlocks.gravewoodLeaves, 0);
		this.setBlock(world, i + 5, j + 47, k + 23, ModBlocks.gravewoodLeaves, 0);
		this.setBlock(world, i + 5, j + 47, k + 24, ModBlocks.gravewoodLeaves, 0);
		this.setBlock(world, i + 5, j + 47, k + 25, ModBlocks.gravewoodLeaves, 0);
		this.setBlock(world, i + 5, j + 47, k + 26, ModBlocks.gravewoodLeaves, 0);
		this.setBlock(world, i + 5, j + 47, k + 27, ModBlocks.gravewoodLeaves, 0);
		this.setBlock(world, i + 5, j + 47, k + 28, ModBlocks.gravewoodLeaves, 0);
		this.setBlock(world, i + 5, j + 47, k + 29, ModBlocks.gravewoodLeaves, 0);
		this.setBlock(world, i + 5, j + 47, k + 30, ModBlocks.gravewood, 1);
		this.setBlock(world, i + 5, j + 48, k + 13, ModBlocks.gravewoodLeaves, 0);
		this.setBlock(world, i + 5, j + 48, k + 14, ModBlocks.gravewoodLeaves, 0);
		this.setBlock(world, i + 5, j + 48, k + 15, ModBlocks.gravewoodLeaves, 0);
		this.setBlock(world, i + 5, j + 48, k + 16, ModBlocks.gravewoodLeaves, 0);
		this.setBlock(world, i + 5, j + 48, k + 17, ModBlocks.gravewoodLeaves, 0);
		this.setBlock(world, i + 5, j + 48, k + 18, ModBlocks.gravewoodLeaves, 0);
		this.setBlock(world, i + 5, j + 48, k + 19, ModBlocks.gravewoodLeaves, 0);
		this.setBlock(world, i + 5, j + 48, k + 20, ModBlocks.gravewoodLeaves, 0);
		this.setBlock(world, i + 5, j + 48, k + 21, ModBlocks.gravewoodLeaves, 0);
		this.setBlock(world, i + 5, j + 48, k + 22, ModBlocks.gravewoodLeaves, 0);
		this.setBlock(world, i + 5, j + 48, k + 23, ModBlocks.gravewoodLeaves, 0);
		this.setBlock(world, i + 5, j + 48, k + 24, ModBlocks.gravewoodLeaves, 0);
		this.setBlock(world, i + 5, j + 48, k + 25, ModBlocks.gravewoodLeaves, 0);
		this.setBlock(world, i + 5, j + 48, k + 26, ModBlocks.gravewoodLeaves, 0);
		this.setBlock(world, i + 5, j + 48, k + 27, ModBlocks.gravewoodLeaves, 0);
		this.setBlock(world, i + 5, j + 48, k + 28, ModBlocks.gravewoodLeaves, 0);
		this.setBlock(world, i + 5, j + 48, k + 29, ModBlocks.gravewoodLeaves, 0);
		this.setBlock(world, i + 5, j + 48, k + 30, ModBlocks.gravewoodLeaves, 0);
		this.setBlock(world, i + 5, j + 49, k + 14, ModBlocks.gravewoodLeaves, 0);
		this.setBlock(world, i + 5, j + 49, k + 15, ModBlocks.gravewoodLeaves, 0);
		this.setBlock(world, i + 5, j + 49, k + 16, ModBlocks.gravewoodLeaves, 0);
		this.setBlock(world, i + 5, j + 49, k + 17, ModBlocks.gravewoodLeaves, 0);
		this.setBlock(world, i + 5, j + 49, k + 18, ModBlocks.gravewoodLeaves, 0);
		this.setBlock(world, i + 5, j + 49, k + 19, ModBlocks.gravewood, 1);
		this.setBlock(world, i + 5, j + 49, k + 20, ModBlocks.gravewood, 1);
		this.setBlock(world, i + 5, j + 49, k + 21, ModBlocks.gravewood, 1);
		this.setBlock(world, i + 5, j + 49, k + 22, ModBlocks.gravewoodLeaves, 0);
		this.setBlock(world, i + 5, j + 49, k + 23, ModBlocks.gravewoodLeaves, 0);
		this.setBlock(world, i + 5, j + 49, k + 24, ModBlocks.gravewoodLeaves, 0);
		this.setBlock(world, i + 5, j + 49, k + 25, ModBlocks.gravewoodLeaves, 0);
		this.setBlock(world, i + 5, j + 49, k + 26, ModBlocks.gravewoodLeaves, 0);
		this.setBlock(world, i + 5, j + 49, k + 27, ModBlocks.gravewoodLeaves, 0);
		this.setBlock(world, i + 5, j + 49, k + 28, ModBlocks.gravewoodLeaves, 0);
		this.setBlock(world, i + 5, j + 49, k + 29, ModBlocks.gravewoodLeaves, 0);
		this.setBlock(world, i + 5, j + 49, k + 30, ModBlocks.gravewoodLeaves, 0);
		this.setBlock(world, i + 5, j + 49, k + 31, ModBlocks.gravewoodLeaves, 0);
		this.setBlock(world, i + 5, j + 49, k + 32, ModBlocks.gravewoodLeaves, 0);
		this.setBlock(world, i + 5, j + 49, k + 33, ModBlocks.gravewoodLeaves, 0);
		this.setBlock(world, i + 5, j + 49, k + 34, ModBlocks.gravewoodLeaves, 0);
		this.setBlock(world, i + 5, j + 49, k + 35, ModBlocks.gravewoodLeaves, 0);
		this.setBlock(world, i + 5, j + 50, k + 15, ModBlocks.gravewoodLeaves, 0);
		this.setBlock(world, i + 5, j + 50, k + 16, ModBlocks.gravewoodLeaves, 0);
		this.setBlock(world, i + 5, j + 50, k + 17, ModBlocks.gravewoodLeaves, 0);
		this.setBlock(world, i + 5, j + 50, k + 18, ModBlocks.gravewoodLeaves, 0);
		this.setBlock(world, i + 5, j + 50, k + 19, ModBlocks.gravewoodLeaves, 0);
		this.setBlock(world, i + 5, j + 50, k + 20, ModBlocks.gravewoodLeaves, 0);
		this.setBlock(world, i + 5, j + 50, k + 21, ModBlocks.gravewoodLeaves, 0);
		this.setBlock(world, i + 5, j + 50, k + 22, ModBlocks.gravewoodLeaves, 0);
		this.setBlock(world, i + 5, j + 50, k + 23, ModBlocks.gravewoodLeaves, 0);
		this.setBlock(world, i + 5, j + 50, k + 24, ModBlocks.gravewoodLeaves, 0);
		this.setBlock(world, i + 5, j + 50, k + 25, ModBlocks.gravewood, 1);
		this.setBlock(world, i + 5, j + 50, k + 26, ModBlocks.gravewoodLeaves, 0);
		this.setBlock(world, i + 5, j + 50, k + 27, ModBlocks.gravewoodLeaves, 0);
		this.setBlock(world, i + 5, j + 50, k + 28, ModBlocks.gravewoodLeaves, 0);
		this.setBlock(world, i + 5, j + 50, k + 29, ModBlocks.gravewoodLeaves, 0);
		this.setBlock(world, i + 5, j + 50, k + 30, ModBlocks.gravewoodLeaves, 0);
		this.setBlock(world, i + 5, j + 50, k + 31, ModBlocks.gravewoodLeaves, 0);
		this.setBlock(world, i + 5, j + 50, k + 32, ModBlocks.gravewoodLeaves, 0);
		this.setBlock(world, i + 5, j + 50, k + 33, ModBlocks.gravewoodLeaves, 0);
		this.setBlock(world, i + 5, j + 50, k + 34, ModBlocks.gravewoodLeaves, 0);
		this.setBlock(world, i + 5, j + 50, k + 35, ModBlocks.gravewoodLeaves, 0);
		this.setBlock(world, i + 5, j + 51, k + 17, ModBlocks.gravewoodLeaves, 0);
		this.setBlock(world, i + 5, j + 51, k + 19, ModBlocks.gravewoodLeaves, 0);
		this.setBlock(world, i + 5, j + 51, k + 20, ModBlocks.gravewoodLeaves, 0);
		this.setBlock(world, i + 5, j + 51, k + 21, ModBlocks.gravewoodLeaves, 0);
		this.setBlock(world, i + 5, j + 51, k + 22, ModBlocks.gravewoodLeaves, 0);
		this.setBlock(world, i + 5, j + 51, k + 23, ModBlocks.gravewoodLeaves, 0);
		this.setBlock(world, i + 5, j + 51, k + 24, ModBlocks.gravewoodLeaves, 0);
		this.setBlock(world, i + 5, j + 51, k + 25, ModBlocks.gravewoodLeaves, 0);
		this.setBlock(world, i + 5, j + 51, k + 26, ModBlocks.gravewoodLeaves, 0);
		this.setBlock(world, i + 5, j + 51, k + 27, ModBlocks.gravewoodLeaves, 0);
		this.setBlock(world, i + 5, j + 51, k + 28, ModBlocks.gravewood, 1);
		this.setBlock(world, i + 5, j + 51, k + 29, ModBlocks.gravewoodLeaves, 0);
		this.setBlock(world, i + 5, j + 51, k + 30, ModBlocks.gravewoodLeaves, 0);
		this.setBlock(world, i + 5, j + 51, k + 31, ModBlocks.gravewood, 1);
		this.setBlock(world, i + 5, j + 51, k + 32, ModBlocks.gravewoodLeaves, 0);
		this.setBlock(world, i + 5, j + 51, k + 33, ModBlocks.gravewoodLeaves, 0);
		this.setBlock(world, i + 5, j + 51, k + 34, ModBlocks.gravewood, 1);
		this.setBlock(world, i + 5, j + 51, k + 35, ModBlocks.gravewoodLeaves, 0);
		this.setBlock(world, i + 5, j + 51, k + 36, ModBlocks.gravewoodLeaves, 0);
		this.setBlock(world, i + 5, j + 52, k + 20, ModBlocks.gravewoodLeaves, 0);
		this.setBlock(world, i + 5, j + 52, k + 21, ModBlocks.gravewoodLeaves, 0);
		this.setBlock(world, i + 5, j + 52, k + 22, ModBlocks.gravewoodLeaves, 0);
		this.setBlock(world, i + 5, j + 52, k + 24, ModBlocks.gravewoodLeaves, 0);
		this.setBlock(world, i + 5, j + 52, k + 25, ModBlocks.gravewoodLeaves, 0);
		this.setBlock(world, i + 5, j + 52, k + 26, ModBlocks.gravewoodLeaves, 0);
		this.setBlock(world, i + 5, j + 52, k + 27, ModBlocks.gravewoodLeaves, 0);
		this.setBlock(world, i + 5, j + 52, k + 28, ModBlocks.gravewoodLeaves, 0);
		this.setBlock(world, i + 5, j + 52, k + 31, ModBlocks.gravewoodLeaves, 0);
		this.setBlock(world, i + 5, j + 52, k + 32, ModBlocks.gravewoodLeaves, 0);
		this.setBlock(world, i + 5, j + 52, k + 33, ModBlocks.gravewoodLeaves, 0);
		this.setBlock(world, i + 5, j + 52, k + 34, ModBlocks.gravewood, 1);
		this.setBlock(world, i + 5, j + 52, k + 35, ModBlocks.gravewood, 1);
		this.setBlock(world, i + 5, j + 52, k + 36, ModBlocks.gravewoodLeaves, 0);
		this.setBlock(world, i + 5, j + 52, k + 37, ModBlocks.gravewoodLeaves, 0);
		this.setBlock(world, i + 5, j + 53, k + 31, ModBlocks.gravewoodLeaves, 0);
		this.setBlock(world, i + 5, j + 53, k + 32, ModBlocks.gravewoodLeaves, 0);
		this.setBlock(world, i + 5, j + 53, k + 33, ModBlocks.gravewoodLeaves, 0);
		this.setBlock(world, i + 5, j + 53, k + 34, ModBlocks.gravewoodLeaves, 0);
		this.setBlock(world, i + 5, j + 53, k + 35, ModBlocks.gravewoodLeaves, 0);
		this.setBlock(world, i + 5, j + 53, k + 36, ModBlocks.gravewoodLeaves, 0);
		this.setBlock(world, i + 6, j + 45, k + 15, ModBlocks.gravewoodLeaves, 0);
		this.setBlock(world, i + 6, j + 45, k + 16, ModBlocks.gravewoodLeaves, 0);
		this.setBlock(world, i + 6, j + 45, k + 17, ModBlocks.gravewoodLeaves, 0);
		this.setBlock(world, i + 6, j + 45, k + 18, ModBlocks.gravewoodLeaves, 0);
		this.setBlock(world, i + 6, j + 45, k + 19, ModBlocks.gravewoodLeaves, 0);
		this.setBlock(world, i + 6, j + 45, k + 20, ModBlocks.gravewoodLeaves, 0);
		this.setBlock(world, i + 6, j + 45, k + 21, ModBlocks.gravewoodLeaves, 0);
		this.setBlock(world, i + 6, j + 45, k + 22, ModBlocks.gravewoodLeaves, 0);
		this.setBlock(world, i + 6, j + 45, k + 23, ModBlocks.gravewoodLeaves, 0);
		this.setBlock(world, i + 6, j + 46, k + 15, ModBlocks.gravewoodLeaves, 0);
		this.setBlock(world, i + 6, j + 46, k + 16, ModBlocks.gravewoodLeaves, 0);
		this.setBlock(world, i + 6, j + 46, k + 17, ModBlocks.gravewood, 1);
		this.setBlock(world, i + 6, j + 46, k + 18, ModBlocks.gravewoodLeaves, 0);
		this.setBlock(world, i + 6, j + 46, k + 19, ModBlocks.gravewoodLeaves, 0);
		this.setBlock(world, i + 6, j + 46, k + 20, ModBlocks.gravewoodLeaves, 0);
		this.setBlock(world, i + 6, j + 46, k + 21, ModBlocks.gravewood, 1);
		this.setBlock(world, i + 6, j + 46, k + 22, ModBlocks.gravewood, 1);
		this.setBlock(world, i + 6, j + 46, k + 23, ModBlocks.gravewood, 1);
		this.setBlock(world, i + 6, j + 46, k + 24, ModBlocks.gravewoodLeaves, 0);
		this.setBlock(world, i + 6, j + 46, k + 25, ModBlocks.gravewoodLeaves, 0);
		this.setBlock(world, i + 6, j + 46, k + 28, ModBlocks.gravewoodLeaves, 0);
		this.setBlock(world, i + 6, j + 47, k + 14, ModBlocks.gravewoodLeaves, 0);
		this.setBlock(world, i + 6, j + 47, k + 15, ModBlocks.gravewoodLeaves, 0);
		this.setBlock(world, i + 6, j + 47, k + 16, ModBlocks.gravewoodLeaves, 0);
		this.setBlock(world, i + 6, j + 47, k + 17, ModBlocks.gravewoodLeaves, 0);
		this.setBlock(world, i + 6, j + 47, k + 18, ModBlocks.gravewoodLeaves, 0);
		this.setBlock(world, i + 6, j + 47, k + 19, ModBlocks.gravewoodLeaves, 0);
		this.setBlock(world, i + 6, j + 47, k + 20, ModBlocks.gravewoodLeaves, 0);
		this.setBlock(world, i + 6, j + 47, k + 21, ModBlocks.gravewoodLeaves, 0);
		this.setBlock(world, i + 6, j + 47, k + 22, ModBlocks.gravewoodLeaves, 0);
		this.setBlock(world, i + 6, j + 47, k + 23, ModBlocks.gravewoodLeaves, 0);
		this.setBlock(world, i + 6, j + 47, k + 24, ModBlocks.gravewoodLeaves, 0);
		this.setBlock(world, i + 6, j + 47, k + 25, ModBlocks.gravewoodLeaves, 0);
		this.setBlock(world, i + 6, j + 47, k + 26, ModBlocks.gravewoodLeaves, 0);
		this.setBlock(world, i + 6, j + 47, k + 27, ModBlocks.gravewoodLeaves, 0);
		this.setBlock(world, i + 6, j + 47, k + 28, ModBlocks.gravewoodLeaves, 0);
		this.setBlock(world, i + 6, j + 47, k + 29, ModBlocks.gravewoodLeaves, 0);
		this.setBlock(world, i + 6, j + 47, k + 30, ModBlocks.gravewoodLeaves, 0);
		this.setBlock(world, i + 6, j + 48, k + 13, ModBlocks.gravewoodLeaves, 0);
		this.setBlock(world, i + 6, j + 48, k + 14, ModBlocks.gravewoodLeaves, 0);
		this.setBlock(world, i + 6, j + 48, k + 15, ModBlocks.gravewoodLeaves, 0);
		this.setBlock(world, i + 6, j + 48, k + 16, ModBlocks.gravewoodLeaves, 0);
		this.setBlock(world, i + 6, j + 48, k + 17, ModBlocks.gravewoodLeaves, 0);
		this.setBlock(world, i + 6, j + 48, k + 18, ModBlocks.gravewoodLeaves, 0);
		this.setBlock(world, i + 6, j + 48, k + 19, ModBlocks.gravewoodLeaves, 0);
		this.setBlock(world, i + 6, j + 48, k + 20, ModBlocks.gravewoodLeaves, 0);
		this.setBlock(world, i + 6, j + 48, k + 21, ModBlocks.gravewoodLeaves, 0);
		this.setBlock(world, i + 6, j + 48, k + 22, ModBlocks.gravewoodLeaves, 0);
		this.setBlock(world, i + 6, j + 48, k + 23, ModBlocks.gravewoodLeaves, 0);
		this.setBlock(world, i + 6, j + 48, k + 24, ModBlocks.gravewoodLeaves, 0);
		this.setBlock(world, i + 6, j + 48, k + 25, ModBlocks.gravewoodLeaves, 0);
		this.setBlock(world, i + 6, j + 48, k + 26, ModBlocks.gravewoodLeaves, 0);
		this.setBlock(world, i + 6, j + 48, k + 27, ModBlocks.gravewood, 1);
		this.setBlock(world, i + 6, j + 48, k + 28, ModBlocks.gravewoodLeaves, 0);
		this.setBlock(world, i + 6, j + 48, k + 29, ModBlocks.gravewoodLeaves, 0);
		this.setBlock(world, i + 6, j + 48, k + 30, ModBlocks.gravewoodLeaves, 0);
		this.setBlock(world, i + 6, j + 48, k + 31, ModBlocks.gravewoodLeaves, 0);
		this.setBlock(world, i + 6, j + 48, k + 32, ModBlocks.gravewoodLeaves, 0);
		this.setBlock(world, i + 6, j + 48, k + 33, ModBlocks.gravewoodLeaves, 0);
		this.setBlock(world, i + 6, j + 49, k + 14, ModBlocks.gravewoodLeaves, 0);
		this.setBlock(world, i + 6, j + 49, k + 15, ModBlocks.gravewoodLeaves, 0);
		this.setBlock(world, i + 6, j + 49, k + 16, ModBlocks.gravewoodLeaves, 0);
		this.setBlock(world, i + 6, j + 49, k + 17, ModBlocks.gravewoodLeaves, 0);
		this.setBlock(world, i + 6, j + 49, k + 18, ModBlocks.gravewoodLeaves, 0);
		this.setBlock(world, i + 6, j + 49, k + 19, ModBlocks.gravewoodLeaves, 0);
		this.setBlock(world, i + 6, j + 49, k + 20, ModBlocks.gravewoodLeaves, 0);
		this.setBlock(world, i + 6, j + 49, k + 21, ModBlocks.gravewoodLeaves, 0);
		this.setBlock(world, i + 6, j + 49, k + 22, ModBlocks.gravewood, 1);
		this.setBlock(world, i + 6, j + 49, k + 23, ModBlocks.gravewoodLeaves, 0);
		this.setBlock(world, i + 6, j + 49, k + 24, ModBlocks.gravewoodLeaves, 0);
		this.setBlock(world, i + 6, j + 49, k + 25, ModBlocks.gravewood, 1);
		this.setBlock(world, i + 6, j + 49, k + 26, ModBlocks.gravewoodLeaves, 0);
		this.setBlock(world, i + 6, j + 49, k + 27, ModBlocks.gravewoodLeaves, 0);
		this.setBlock(world, i + 6, j + 49, k + 28, ModBlocks.gravewoodLeaves, 0);
		this.setBlock(world, i + 6, j + 49, k + 29, ModBlocks.gravewoodLeaves, 0);
		this.setBlock(world, i + 6, j + 49, k + 30, ModBlocks.gravewoodLeaves, 0);
		this.setBlock(world, i + 6, j + 49, k + 31, ModBlocks.gravewoodLeaves, 0);
		this.setBlock(world, i + 6, j + 49, k + 32, ModBlocks.gravewoodLeaves, 0);
		this.setBlock(world, i + 6, j + 49, k + 33, ModBlocks.gravewoodLeaves, 0);
		this.setBlock(world, i + 6, j + 49, k + 34, ModBlocks.gravewoodLeaves, 0);
		this.setBlock(world, i + 6, j + 49, k + 35, ModBlocks.gravewoodLeaves, 0);
		this.setBlock(world, i + 6, j + 50, k + 15, ModBlocks.gravewoodLeaves, 0);
		this.setBlock(world, i + 6, j + 50, k + 16, ModBlocks.gravewoodLeaves, 0);
		this.setBlock(world, i + 6, j + 50, k + 17, ModBlocks.gravewoodLeaves, 0);
		this.setBlock(world, i + 6, j + 50, k + 18, ModBlocks.gravewoodLeaves, 0);
		this.setBlock(world, i + 6, j + 50, k + 19, ModBlocks.gravewoodLeaves, 0);
		this.setBlock(world, i + 6, j + 50, k + 20, ModBlocks.gravewoodLeaves, 0);
		this.setBlock(world, i + 6, j + 50, k + 21, ModBlocks.gravewood, 1);
		this.setBlock(world, i + 6, j + 50, k + 22, ModBlocks.gravewoodLeaves, 0);
		this.setBlock(world, i + 6, j + 50, k + 23, ModBlocks.gravewoodLeaves, 0);
		this.setBlock(world, i + 6, j + 50, k + 24, ModBlocks.gravewoodLeaves, 0);
		this.setBlock(world, i + 6, j + 50, k + 25, ModBlocks.gravewoodLeaves, 0);
		this.setBlock(world, i + 6, j + 50, k + 26, ModBlocks.gravewoodLeaves, 0);
		this.setBlock(world, i + 6, j + 50, k + 27, ModBlocks.gravewoodLeaves, 0);
		this.setBlock(world, i + 6, j + 50, k + 28, ModBlocks.gravewoodLeaves, 0);
		this.setBlock(world, i + 6, j + 50, k + 29, ModBlocks.gravewoodLeaves, 0);
		this.setBlock(world, i + 6, j + 50, k + 30, ModBlocks.gravewoodLeaves, 0);
		this.setBlock(world, i + 6, j + 50, k + 31, ModBlocks.gravewoodLeaves, 0);
		this.setBlock(world, i + 6, j + 50, k + 32, ModBlocks.gravewoodLeaves, 0);
		this.setBlock(world, i + 6, j + 50, k + 33, ModBlocks.gravewoodLeaves, 0);
		this.setBlock(world, i + 6, j + 50, k + 34, ModBlocks.gravewoodLeaves, 0);
		this.setBlock(world, i + 6, j + 50, k + 35, ModBlocks.gravewoodLeaves, 0);
		this.setBlock(world, i + 6, j + 51, k + 19, ModBlocks.gravewoodLeaves, 0);
		this.setBlock(world, i + 6, j + 51, k + 20, ModBlocks.gravewoodLeaves, 0);
		this.setBlock(world, i + 6, j + 51, k + 21, ModBlocks.gravewoodLeaves, 0);
		this.setBlock(world, i + 6, j + 51, k + 22, ModBlocks.gravewoodLeaves, 0);
		this.setBlock(world, i + 6, j + 51, k + 23, ModBlocks.gravewoodLeaves, 0);
		this.setBlock(world, i + 6, j + 51, k + 24, ModBlocks.gravewoodLeaves, 0);
		this.setBlock(world, i + 6, j + 51, k + 25, ModBlocks.gravewoodLeaves, 0);
		this.setBlock(world, i + 6, j + 51, k + 26, ModBlocks.gravewood, 1);
		this.setBlock(world, i + 6, j + 51, k + 27, ModBlocks.gravewoodLeaves, 0);
		this.setBlock(world, i + 6, j + 51, k + 28, ModBlocks.gravewoodLeaves, 0);
		this.setBlock(world, i + 6, j + 51, k + 29, ModBlocks.gravewoodLeaves, 0);
		this.setBlock(world, i + 6, j + 51, k + 30, ModBlocks.gravewoodLeaves, 0);
		this.setBlock(world, i + 6, j + 51, k + 31, ModBlocks.gravewood, 1);
		this.setBlock(world, i + 6, j + 51, k + 32, ModBlocks.gravewoodLeaves, 0);
		this.setBlock(world, i + 6, j + 51, k + 33, ModBlocks.gravewoodLeaves, 0);
		this.setBlock(world, i + 6, j + 51, k + 34, ModBlocks.gravewoodLeaves, 0);
		this.setBlock(world, i + 6, j + 51, k + 35, ModBlocks.gravewoodLeaves, 0);
		this.setBlock(world, i + 6, j + 51, k + 36, ModBlocks.gravewood, 1);
		this.setBlock(world, i + 6, j + 52, k + 19, ModBlocks.gravewoodLeaves, 0);
		this.setBlock(world, i + 6, j + 52, k + 20, ModBlocks.gravewoodLeaves, 0);
		this.setBlock(world, i + 6, j + 52, k + 21, ModBlocks.gravewoodLeaves, 0);
		this.setBlock(world, i + 6, j + 52, k + 22, ModBlocks.gravewoodLeaves, 0);
		this.setBlock(world, i + 6, j + 52, k + 23, ModBlocks.gravewoodLeaves, 0);
		this.setBlock(world, i + 6, j + 52, k + 25, ModBlocks.gravewoodLeaves, 0);
		this.setBlock(world, i + 6, j + 52, k + 26, ModBlocks.gravewoodLeaves, 0);
		this.setBlock(world, i + 6, j + 52, k + 27, ModBlocks.gravewoodLeaves, 0);
		this.setBlock(world, i + 6, j + 52, k + 28, ModBlocks.gravewoodLeaves, 0);
		this.setBlock(world, i + 6, j + 52, k + 30, ModBlocks.gravewoodLeaves, 0);
		this.setBlock(world, i + 6, j + 52, k + 31, ModBlocks.gravewoodLeaves, 0);
		this.setBlock(world, i + 6, j + 52, k + 32, ModBlocks.gravewoodLeaves, 0);
		this.setBlock(world, i + 6, j + 52, k + 33, ModBlocks.gravewoodLeaves, 0);
		this.setBlock(world, i + 6, j + 52, k + 34, ModBlocks.gravewoodLeaves, 0);
		this.setBlock(world, i + 6, j + 52, k + 35, ModBlocks.gravewoodLeaves, 0);
		this.setBlock(world, i + 6, j + 52, k + 36, ModBlocks.gravewoodLeaves, 0);
		this.setBlock(world, i + 6, j + 52, k + 37, ModBlocks.gravewoodLeaves, 0);
		this.setBlock(world, i + 6, j + 53, k + 31, ModBlocks.gravewoodLeaves, 0);
		this.setBlock(world, i + 6, j + 53, k + 32, ModBlocks.gravewoodLeaves, 0);
		this.setBlock(world, i + 6, j + 53, k + 33, ModBlocks.gravewoodLeaves, 0);
		this.setBlock(world, i + 6, j + 53, k + 34, ModBlocks.gravewoodLeaves, 0);
		this.setBlock(world, i + 6, j + 53, k + 35, ModBlocks.gravewoodLeaves, 0);
		this.setBlock(world, i + 6, j + 53, k + 36, ModBlocks.gravewoodLeaves, 0);
		this.setBlock(world, i + 6, j + 54, k + 33, ModBlocks.gravewoodLeaves, 0);
		this.setBlock(world, i + 7, j + 44, k + 17, ModBlocks.gravewoodLeaves, 0);
		this.setBlock(world, i + 7, j + 44, k + 20, ModBlocks.gravewoodLeaves, 0);
		this.setBlock(world, i + 7, j + 45, k + 15, ModBlocks.gravewoodLeaves, 0);
		this.setBlock(world, i + 7, j + 45, k + 16, ModBlocks.gravewoodLeaves, 0);
		this.setBlock(world, i + 7, j + 45, k + 17, ModBlocks.gravewood, 1);
		this.setBlock(world, i + 7, j + 45, k + 18, ModBlocks.gravewoodLeaves, 0);
		this.setBlock(world, i + 7, j + 45, k + 19, ModBlocks.gravewoodLeaves, 0);
		this.setBlock(world, i + 7, j + 45, k + 20, ModBlocks.gravewoodLeaves, 0);
		this.setBlock(world, i + 7, j + 45, k + 21, ModBlocks.gravewoodLeaves, 0);
		this.setBlock(world, i + 7, j + 45, k + 22, ModBlocks.gravewoodLeaves, 0);
		this.setBlock(world, i + 7, j + 46, k + 15, ModBlocks.gravewoodLeaves, 0);
		this.setBlock(world, i + 7, j + 46, k + 16, ModBlocks.gravewood, 1);
		this.setBlock(world, i + 7, j + 46, k + 17, ModBlocks.gravewood, 1);
		this.setBlock(world, i + 7, j + 46, k + 18, ModBlocks.gravewood, 1);
		this.setBlock(world, i + 7, j + 46, k + 19, ModBlocks.gravewood, 1);
		this.setBlock(world, i + 7, j + 46, k + 20, ModBlocks.gravewoodLeaves, 0);
		this.setBlock(world, i + 7, j + 46, k + 21, ModBlocks.gravewoodLeaves, 0);
		this.setBlock(world, i + 7, j + 46, k + 22, ModBlocks.gravewoodLeaves, 0);
		this.setBlock(world, i + 7, j + 46, k + 23, ModBlocks.gravewoodLeaves, 0);
		this.setBlock(world, i + 7, j + 46, k + 24, ModBlocks.gravewoodLeaves, 0);
		this.setBlock(world, i + 7, j + 46, k + 25, ModBlocks.gravewood, 1);
		this.setBlock(world, i + 7, j + 47, k + 14, ModBlocks.gravewoodLeaves, 0);
		this.setBlock(world, i + 7, j + 47, k + 15, ModBlocks.gravewoodLeaves, 0);
		this.setBlock(world, i + 7, j + 47, k + 16, ModBlocks.gravewood, 1);
		this.setBlock(world, i + 7, j + 47, k + 17, ModBlocks.gravewood, 1);
		this.setBlock(world, i + 7, j + 47, k + 18, ModBlocks.gravewoodLeaves, 0);
		this.setBlock(world, i + 7, j + 47, k + 19, ModBlocks.gravewoodLeaves, 0);
		this.setBlock(world, i + 7, j + 47, k + 20, ModBlocks.gravewoodLeaves, 0);
		this.setBlock(world, i + 7, j + 47, k + 21, ModBlocks.gravewoodLeaves, 0);
		this.setBlock(world, i + 7, j + 47, k + 22, ModBlocks.gravewoodLeaves, 0);
		this.setBlock(world, i + 7, j + 47, k + 23, ModBlocks.gravewoodLeaves, 0);
		this.setBlock(world, i + 7, j + 47, k + 24, ModBlocks.gravewoodLeaves, 0);
		this.setBlock(world, i + 7, j + 47, k + 25, ModBlocks.gravewoodLeaves, 0);
		this.setBlock(world, i + 7, j + 47, k + 26, ModBlocks.gravewoodLeaves, 0);
		this.setBlock(world, i + 7, j + 47, k + 27, ModBlocks.gravewood, 1);
		this.setBlock(world, i + 7, j + 47, k + 28, ModBlocks.gravewoodLeaves, 0);
		this.setBlock(world, i + 7, j + 47, k + 29, ModBlocks.gravewoodLeaves, 0);
		this.setBlock(world, i + 7, j + 47, k + 30, ModBlocks.gravewoodLeaves, 0);
		this.setBlock(world, i + 7, j + 47, k + 31, ModBlocks.gravewoodLeaves, 0);
		this.setBlock(world, i + 7, j + 48, k + 13, ModBlocks.gravewoodLeaves, 0);
		this.setBlock(world, i + 7, j + 48, k + 14, ModBlocks.gravewoodLeaves, 0);
		this.setBlock(world, i + 7, j + 48, k + 15, ModBlocks.gravewoodLeaves, 0);
		this.setBlock(world, i + 7, j + 48, k + 16, ModBlocks.gravewoodLeaves, 0);
		this.setBlock(world, i + 7, j + 48, k + 17, ModBlocks.gravewoodLeaves, 0);
		this.setBlock(world, i + 7, j + 48, k + 18, ModBlocks.gravewoodLeaves, 0);
		this.setBlock(world, i + 7, j + 48, k + 19, ModBlocks.gravewood, 1);
		this.setBlock(world, i + 7, j + 48, k + 20, ModBlocks.gravewoodLeaves, 0);
		this.setBlock(world, i + 7, j + 48, k + 21, ModBlocks.gravewoodLeaves, 0);
		this.setBlock(world, i + 7, j + 48, k + 22, ModBlocks.gravewood, 1);
		this.setBlock(world, i + 7, j + 48, k + 23, ModBlocks.gravewoodLeaves, 0);
		this.setBlock(world, i + 7, j + 48, k + 24, ModBlocks.gravewoodLeaves, 0);
		this.setBlock(world, i + 7, j + 48, k + 25, ModBlocks.gravewoodLeaves, 0);
		this.setBlock(world, i + 7, j + 48, k + 26, ModBlocks.gravewoodLeaves, 0);
		this.setBlock(world, i + 7, j + 48, k + 27, ModBlocks.gravewoodLeaves, 0);
		this.setBlock(world, i + 7, j + 48, k + 28, ModBlocks.gravewoodLeaves, 0);
		this.setBlock(world, i + 7, j + 48, k + 29, ModBlocks.gravewoodLeaves, 0);
		this.setBlock(world, i + 7, j + 48, k + 30, ModBlocks.gravewoodLeaves, 0);
		this.setBlock(world, i + 7, j + 48, k + 31, ModBlocks.gravewoodLeaves, 0);
		this.setBlock(world, i + 7, j + 48, k + 32, ModBlocks.gravewoodLeaves, 0);
		this.setBlock(world, i + 7, j + 48, k + 33, ModBlocks.gravewood, 1);
		this.setBlock(world, i + 7, j + 49, k + 14, ModBlocks.gravewoodLeaves, 0);
		this.setBlock(world, i + 7, j + 49, k + 15, ModBlocks.gravewoodLeaves, 0);
		this.setBlock(world, i + 7, j + 49, k + 16, ModBlocks.gravewoodLeaves, 0);
		this.setBlock(world, i + 7, j + 49, k + 17, ModBlocks.gravewoodLeaves, 0);
		this.setBlock(world, i + 7, j + 49, k + 18, ModBlocks.gravewoodLeaves, 0);
		this.setBlock(world, i + 7, j + 49, k + 19, ModBlocks.gravewoodLeaves, 0);
		this.setBlock(world, i + 7, j + 49, k + 20, ModBlocks.gravewoodLeaves, 0);
		this.setBlock(world, i + 7, j + 49, k + 21, ModBlocks.gravewoodLeaves, 0);
		this.setBlock(world, i + 7, j + 49, k + 22, ModBlocks.gravewoodLeaves, 0);
		this.setBlock(world, i + 7, j + 49, k + 23, ModBlocks.gravewoodLeaves, 0);
		this.setBlock(world, i + 7, j + 49, k + 24, ModBlocks.gravewoodLeaves, 0);
		this.setBlock(world, i + 7, j + 49, k + 25, ModBlocks.gravewoodLeaves, 0);
		this.setBlock(world, i + 7, j + 49, k + 26, ModBlocks.gravewoodLeaves, 0);
		this.setBlock(world, i + 7, j + 49, k + 27, ModBlocks.gravewoodLeaves, 0);
		this.setBlock(world, i + 7, j + 49, k + 28, ModBlocks.gravewoodLeaves, 0);
		this.setBlock(world, i + 7, j + 49, k + 29, ModBlocks.gravewoodLeaves, 0);
		this.setBlock(world, i + 7, j + 49, k + 30, ModBlocks.gravewoodLeaves, 0);
		this.setBlock(world, i + 7, j + 49, k + 31, ModBlocks.gravewoodLeaves, 0);
		this.setBlock(world, i + 7, j + 49, k + 32, ModBlocks.gravewoodLeaves, 0);
		this.setBlock(world, i + 7, j + 49, k + 33, ModBlocks.gravewood, 1);
		this.setBlock(world, i + 7, j + 49, k + 34, ModBlocks.gravewood, 1);
		this.setBlock(world, i + 7, j + 49, k + 35, ModBlocks.gravewoodLeaves, 0);
		this.setBlock(world, i + 7, j + 50, k + 15, ModBlocks.gravewoodLeaves, 0);
		this.setBlock(world, i + 7, j + 50, k + 16, ModBlocks.gravewoodLeaves, 0);
		this.setBlock(world, i + 7, j + 50, k + 17, ModBlocks.gravewoodLeaves, 0);
		this.setBlock(world, i + 7, j + 50, k + 18, ModBlocks.gravewoodLeaves, 0);
		this.setBlock(world, i + 7, j + 50, k + 19, ModBlocks.gravewoodLeaves, 0);
		this.setBlock(world, i + 7, j + 50, k + 20, ModBlocks.gravewoodLeaves, 0);
		this.setBlock(world, i + 7, j + 50, k + 21, ModBlocks.gravewoodLeaves, 0);
		this.setBlock(world, i + 7, j + 50, k + 22, ModBlocks.gravewoodLeaves, 0);
		this.setBlock(world, i + 7, j + 50, k + 23, ModBlocks.gravewoodLeaves, 0);
		this.setBlock(world, i + 7, j + 50, k + 24, ModBlocks.gravewoodLeaves, 0);
		this.setBlock(world, i + 7, j + 50, k + 25, ModBlocks.gravewoodLeaves, 0);
		this.setBlock(world, i + 7, j + 50, k + 26, ModBlocks.gravewoodLeaves, 0);
		this.setBlock(world, i + 7, j + 50, k + 27, ModBlocks.gravewoodLeaves, 0);
		this.setBlock(world, i + 7, j + 50, k + 28, ModBlocks.gravewoodLeaves, 0);
		this.setBlock(world, i + 7, j + 50, k + 29, ModBlocks.gravewoodLeaves, 0);
		this.setBlock(world, i + 7, j + 50, k + 30, ModBlocks.gravewoodLeaves, 0);
		this.setBlock(world, i + 7, j + 50, k + 31, ModBlocks.gravewoodLeaves, 0);
		this.setBlock(world, i + 7, j + 50, k + 32, ModBlocks.gravewood, 1);
		this.setBlock(world, i + 7, j + 50, k + 33, ModBlocks.gravewoodLeaves, 0);
		this.setBlock(world, i + 7, j + 50, k + 34, ModBlocks.gravewoodLeaves, 0);
		this.setBlock(world, i + 7, j + 50, k + 35, ModBlocks.gravewoodLeaves, 0);
		this.setBlock(world, i + 7, j + 51, k + 19, ModBlocks.gravewoodLeaves, 0);
		this.setBlock(world, i + 7, j + 51, k + 20, ModBlocks.gravewoodLeaves, 0);
		this.setBlock(world, i + 7, j + 51, k + 21, ModBlocks.gravewood, 1);
		this.setBlock(world, i + 7, j + 51, k + 22, ModBlocks.gravewoodLeaves, 0);
		this.setBlock(world, i + 7, j + 51, k + 23, ModBlocks.gravewoodLeaves, 0);
		this.setBlock(world, i + 7, j + 51, k + 24, ModBlocks.gravewoodLeaves, 0);
		this.setBlock(world, i + 7, j + 51, k + 25, ModBlocks.gravewoodLeaves, 0);
		this.setBlock(world, i + 7, j + 51, k + 26, ModBlocks.gravewoodLeaves, 0);
		this.setBlock(world, i + 7, j + 51, k + 27, ModBlocks.gravewoodLeaves, 0);
		this.setBlock(world, i + 7, j + 51, k + 28, ModBlocks.gravewoodLeaves, 0);
		this.setBlock(world, i + 7, j + 51, k + 29, ModBlocks.gravewoodLeaves, 0);
		this.setBlock(world, i + 7, j + 51, k + 30, ModBlocks.gravewoodLeaves, 0);
		this.setBlock(world, i + 7, j + 51, k + 31, ModBlocks.gravewoodLeaves, 0);
		this.setBlock(world, i + 7, j + 51, k + 32, ModBlocks.gravewoodLeaves, 0);
		this.setBlock(world, i + 7, j + 51, k + 33, ModBlocks.gravewoodLeaves, 0);
		this.setBlock(world, i + 7, j + 51, k + 34, ModBlocks.gravewoodLeaves, 0);
		this.setBlock(world, i + 7, j + 51, k + 35, ModBlocks.gravewoodLeaves, 0);
		this.setBlock(world, i + 7, j + 51, k + 36, ModBlocks.gravewoodLeaves, 0);
		this.setBlock(world, i + 7, j + 52, k + 19, ModBlocks.gravewoodLeaves, 0);
		this.setBlock(world, i + 7, j + 52, k + 20, ModBlocks.gravewoodLeaves, 0);
		this.setBlock(world, i + 7, j + 52, k + 21, ModBlocks.gravewoodLeaves, 0);
		this.setBlock(world, i + 7, j + 52, k + 22, ModBlocks.gravewoodLeaves, 0);
		this.setBlock(world, i + 7, j + 52, k + 23, ModBlocks.gravewoodLeaves, 0);
		this.setBlock(world, i + 7, j + 52, k + 29, ModBlocks.gravewoodLeaves, 0);
		this.setBlock(world, i + 7, j + 52, k + 30, ModBlocks.gravewoodLeaves, 0);
		this.setBlock(world, i + 7, j + 52, k + 31, ModBlocks.gravewoodLeaves, 0);
		this.setBlock(world, i + 7, j + 52, k + 32, ModBlocks.gravewoodLeaves, 0);
		this.setBlock(world, i + 7, j + 52, k + 33, ModBlocks.gravewoodLeaves, 0);
		this.setBlock(world, i + 7, j + 52, k + 34, ModBlocks.gravewoodLeaves, 0);
		this.setBlock(world, i + 7, j + 52, k + 35, ModBlocks.gravewoodLeaves, 0);
		this.setBlock(world, i + 7, j + 52, k + 36, ModBlocks.gravewoodLeaves, 0);
		this.setBlock(world, i + 7, j + 52, k + 37, ModBlocks.gravewoodLeaves, 0);
		this.setBlock(world, i + 7, j + 53, k + 21, ModBlocks.gravewoodLeaves, 0);
		this.setBlock(world, i + 7, j + 53, k + 31, ModBlocks.gravewoodLeaves, 0);
		this.setBlock(world, i + 7, j + 53, k + 32, ModBlocks.gravewoodLeaves, 0);
		this.setBlock(world, i + 7, j + 53, k + 33, ModBlocks.gravewoodLeaves, 0);
		this.setBlock(world, i + 7, j + 53, k + 34, ModBlocks.gravewoodLeaves, 0);
		this.setBlock(world, i + 7, j + 53, k + 35, ModBlocks.gravewoodLeaves, 0);
		this.setBlock(world, i + 7, j + 53, k + 36, ModBlocks.gravewoodLeaves, 0);
		this.setBlock(world, i + 7, j + 54, k + 32, ModBlocks.gravewoodLeaves, 0);
		this.setBlock(world, i + 7, j + 54, k + 33, ModBlocks.gravewoodLeaves, 0);
		this.setBlock(world, i + 7, j + 54, k + 34, ModBlocks.gravewoodLeaves, 0);
		this.setBlock(world, i + 8, j + 45, k + 15, ModBlocks.gravewoodLeaves, 0);
		this.setBlock(world, i + 8, j + 45, k + 16, ModBlocks.gravewoodLeaves, 0);
		this.setBlock(world, i + 8, j + 45, k + 17, ModBlocks.gravewood, 1);
		this.setBlock(world, i + 8, j + 45, k + 18, ModBlocks.gravewood, 1);
		this.setBlock(world, i + 8, j + 45, k + 19, ModBlocks.gravewood, 1);
		this.setBlock(world, i + 8, j + 45, k + 20, ModBlocks.gravewoodLeaves, 0);
		this.setBlock(world, i + 8, j + 45, k + 21, ModBlocks.gravewoodLeaves, 0);
		this.setBlock(world, i + 8, j + 45, k + 22, ModBlocks.gravewoodLeaves, 0);
		this.setBlock(world, i + 8, j + 46, k + 14, ModBlocks.gravewoodLeaves, 0);
		this.setBlock(world, i + 8, j + 46, k + 15, ModBlocks.gravewoodLeaves, 0);
		this.setBlock(world, i + 8, j + 46, k + 16, ModBlocks.gravewood, 1);
		this.setBlock(world, i + 8, j + 46, k + 17, ModBlocks.gravewood, 1);
		this.setBlock(world, i + 8, j + 46, k + 18, ModBlocks.gravewood, 1);
		this.setBlock(world, i + 8, j + 46, k + 19, ModBlocks.gravewood, 1);
		this.setBlock(world, i + 8, j + 46, k + 20, ModBlocks.gravewoodLeaves, 0);
		this.setBlock(world, i + 8, j + 46, k + 21, ModBlocks.gravewoodLeaves, 0);
		this.setBlock(world, i + 8, j + 46, k + 22, ModBlocks.gravewood, 1);
		this.setBlock(world, i + 8, j + 46, k + 23, ModBlocks.gravewoodLeaves, 0);
		this.setBlock(world, i + 8, j + 46, k + 24, ModBlocks.gravewoodLeaves, 0);
		this.setBlock(world, i + 8, j + 46, k + 25, ModBlocks.gravewoodLeaves, 0);
		this.setBlock(world, i + 8, j + 46, k + 26, ModBlocks.gravewoodLeaves, 0);
		this.setBlock(world, i + 8, j + 46, k + 27, ModBlocks.gravewoodLeaves, 0);
		this.setBlock(world, i + 8, j + 46, k + 28, ModBlocks.gravewoodLeaves, 0);
		this.setBlock(world, i + 8, j + 46, k + 29, ModBlocks.gravewoodLeaves, 0);
		this.setBlock(world, i + 8, j + 47, k + 14, ModBlocks.gravewoodLeaves, 0);
		this.setBlock(world, i + 8, j + 47, k + 15, ModBlocks.gravewoodLeaves, 0);
		this.setBlock(world, i + 8, j + 47, k + 16, ModBlocks.gravewoodLeaves, 0);
		this.setBlock(world, i + 8, j + 47, k + 17, ModBlocks.gravewood, 1);
		this.setBlock(world, i + 8, j + 47, k + 18, ModBlocks.gravewood, 1);
		this.setBlock(world, i + 8, j + 47, k + 19, ModBlocks.gravewoodLeaves, 0);
		this.setBlock(world, i + 8, j + 47, k + 20, ModBlocks.gravewoodLeaves, 0);
		this.setBlock(world, i + 8, j + 47, k + 21, ModBlocks.gravewoodLeaves, 0);
		this.setBlock(world, i + 8, j + 47, k + 22, ModBlocks.gravewoodLeaves, 0);
		this.setBlock(world, i + 8, j + 47, k + 23, ModBlocks.gravewoodLeaves, 0);
		this.setBlock(world, i + 8, j + 47, k + 24, ModBlocks.gravewoodLeaves, 0);
		this.setBlock(world, i + 8, j + 47, k + 25, ModBlocks.gravewood, 1);
		this.setBlock(world, i + 8, j + 47, k + 26, ModBlocks.gravewood, 1);
		this.setBlock(world, i + 8, j + 47, k + 27, ModBlocks.gravewoodLeaves, 0);
		this.setBlock(world, i + 8, j + 47, k + 28, ModBlocks.gravewood, 1);
		this.setBlock(world, i + 8, j + 47, k + 29, ModBlocks.gravewoodLeaves, 0);
		this.setBlock(world, i + 8, j + 47, k + 30, ModBlocks.gravewoodLeaves, 0);
		this.setBlock(world, i + 8, j + 47, k + 31, ModBlocks.gravewood, 1);
		this.setBlock(world, i + 8, j + 48, k + 13, ModBlocks.gravewoodLeaves, 0);
		this.setBlock(world, i + 8, j + 48, k + 14, ModBlocks.gravewood, 1);
		this.setBlock(world, i + 8, j + 48, k + 15, ModBlocks.gravewood, 1);
		this.setBlock(world, i + 8, j + 48, k + 16, ModBlocks.gravewoodLeaves, 0);
		this.setBlock(world, i + 8, j + 48, k + 17, ModBlocks.gravewoodLeaves, 0);
		this.setBlock(world, i + 8, j + 48, k + 18, ModBlocks.gravewoodLeaves, 0);
		this.setBlock(world, i + 8, j + 48, k + 19, ModBlocks.gravewoodLeaves, 0);
		this.setBlock(world, i + 8, j + 48, k + 20, ModBlocks.gravewood, 1);
		this.setBlock(world, i + 8, j + 48, k + 21, ModBlocks.gravewoodLeaves, 0);
		this.setBlock(world, i + 8, j + 48, k + 22, ModBlocks.gravewoodLeaves, 0);
		this.setBlock(world, i + 8, j + 48, k + 23, ModBlocks.gravewoodLeaves, 0);
		this.setBlock(world, i + 8, j + 48, k + 24, ModBlocks.gravewoodLeaves, 0);
		this.setBlock(world, i + 8, j + 48, k + 25, ModBlocks.gravewood, 1);
		this.setBlock(world, i + 8, j + 48, k + 26, ModBlocks.gravewood, 1);
		this.setBlock(world, i + 8, j + 48, k + 27, ModBlocks.gravewood, 1);
		this.setBlock(world, i + 8, j + 48, k + 28, ModBlocks.gravewoodLeaves, 0);
		this.setBlock(world, i + 8, j + 48, k + 29, ModBlocks.gravewoodLeaves, 0);
		this.setBlock(world, i + 8, j + 48, k + 30, ModBlocks.gravewoodLeaves, 0);
		this.setBlock(world, i + 8, j + 48, k + 31, ModBlocks.gravewood, 1);
		this.setBlock(world, i + 8, j + 48, k + 32, ModBlocks.gravewoodLeaves, 0);
		this.setBlock(world, i + 8, j + 48, k + 33, ModBlocks.gravewood, 1);
		this.setBlock(world, i + 8, j + 48, k + 34, ModBlocks.gravewood, 1);
		this.setBlock(world, i + 8, j + 49, k + 14, ModBlocks.gravewoodLeaves, 0);
		this.setBlock(world, i + 8, j + 49, k + 15, ModBlocks.gravewood, 1);
		this.setBlock(world, i + 8, j + 49, k + 16, ModBlocks.gravewoodLeaves, 0);
		this.setBlock(world, i + 8, j + 49, k + 17, ModBlocks.gravewoodLeaves, 0);
		this.setBlock(world, i + 8, j + 49, k + 18, ModBlocks.gravewood, 1);
		this.setBlock(world, i + 8, j + 49, k + 19, ModBlocks.gravewoodLeaves, 0);
		this.setBlock(world, i + 8, j + 49, k + 20, ModBlocks.gravewoodLeaves, 0);
		this.setBlock(world, i + 8, j + 49, k + 21, ModBlocks.gravewood, 1);
		this.setBlock(world, i + 8, j + 49, k + 22, ModBlocks.gravewoodLeaves, 0);
		this.setBlock(world, i + 8, j + 49, k + 23, ModBlocks.gravewoodLeaves, 0);
		this.setBlock(world, i + 8, j + 49, k + 24, ModBlocks.gravewoodLeaves, 0);
		this.setBlock(world, i + 8, j + 49, k + 25, ModBlocks.gravewoodLeaves, 0);
		this.setBlock(world, i + 8, j + 49, k + 26, ModBlocks.gravewoodLeaves, 0);
		this.setBlock(world, i + 8, j + 49, k + 27, ModBlocks.gravewoodLeaves, 0);
		this.setBlock(world, i + 8, j + 49, k + 28, ModBlocks.gravewoodLeaves, 0);
		this.setBlock(world, i + 8, j + 49, k + 29, ModBlocks.gravewoodLeaves, 0);
		this.setBlock(world, i + 8, j + 49, k + 30, ModBlocks.gravewoodLeaves, 0);
		this.setBlock(world, i + 8, j + 49, k + 31, ModBlocks.gravewood, 1);
		this.setBlock(world, i + 8, j + 49, k + 32, ModBlocks.gravewood, 1);
		this.setBlock(world, i + 8, j + 49, k + 33, ModBlocks.gravewood, 1);
		this.setBlock(world, i + 8, j + 49, k + 34, ModBlocks.gravewood, 1);
		this.setBlock(world, i + 8, j + 49, k + 35, ModBlocks.gravewood, 1);
		this.setBlock(world, i + 8, j + 50, k + 14, ModBlocks.gravewoodLeaves, 0);
		this.setBlock(world, i + 8, j + 50, k + 15, ModBlocks.gravewoodLeaves, 0);
		this.setBlock(world, i + 8, j + 50, k + 16, ModBlocks.gravewoodLeaves, 0);
		this.setBlock(world, i + 8, j + 50, k + 17, ModBlocks.gravewoodLeaves, 0);
		this.setBlock(world, i + 8, j + 50, k + 18, ModBlocks.gravewoodLeaves, 0);
		this.setBlock(world, i + 8, j + 50, k + 19, ModBlocks.gravewoodLeaves, 0);
		this.setBlock(world, i + 8, j + 50, k + 20, ModBlocks.gravewoodLeaves, 0);
		this.setBlock(world, i + 8, j + 50, k + 21, ModBlocks.gravewoodLeaves, 0);
		this.setBlock(world, i + 8, j + 50, k + 22, ModBlocks.gravewoodLeaves, 0);
		this.setBlock(world, i + 8, j + 50, k + 23, ModBlocks.gravewoodLeaves, 0);
		this.setBlock(world, i + 8, j + 50, k + 24, ModBlocks.gravewoodLeaves, 0);
		this.setBlock(world, i + 8, j + 50, k + 25, ModBlocks.gravewoodLeaves, 0);
		this.setBlock(world, i + 8, j + 50, k + 26, ModBlocks.gravewoodLeaves, 0);
		this.setBlock(world, i + 8, j + 50, k + 27, ModBlocks.gravewood, 1);
		this.setBlock(world, i + 8, j + 50, k + 28, ModBlocks.gravewoodLeaves, 0);
		this.setBlock(world, i + 8, j + 50, k + 29, ModBlocks.gravewoodLeaves, 0);
		this.setBlock(world, i + 8, j + 50, k + 30, ModBlocks.gravewoodLeaves, 0);
		this.setBlock(world, i + 8, j + 50, k + 31, ModBlocks.gravewoodLeaves, 0);
		this.setBlock(world, i + 8, j + 50, k + 32, ModBlocks.gravewoodLeaves, 0);
		this.setBlock(world, i + 8, j + 50, k + 33, ModBlocks.gravewood, 1);
		this.setBlock(world, i + 8, j + 50, k + 34, ModBlocks.gravewood, 1);
		this.setBlock(world, i + 8, j + 50, k + 35, ModBlocks.gravewoodLeaves, 0);
		this.setBlock(world, i + 8, j + 51, k + 19, ModBlocks.gravewoodLeaves, 0);
		this.setBlock(world, i + 8, j + 51, k + 20, ModBlocks.gravewoodLeaves, 0);
		this.setBlock(world, i + 8, j + 51, k + 21, ModBlocks.gravewoodLeaves, 0);
		this.setBlock(world, i + 8, j + 51, k + 22, ModBlocks.gravewoodLeaves, 0);
		this.setBlock(world, i + 8, j + 51, k + 23, ModBlocks.gravewoodLeaves, 0);
		this.setBlock(world, i + 8, j + 51, k + 24, ModBlocks.gravewoodLeaves, 0);
		this.setBlock(world, i + 8, j + 51, k + 25, ModBlocks.gravewoodLeaves, 0);
		this.setBlock(world, i + 8, j + 51, k + 26, ModBlocks.gravewoodLeaves, 0);
		this.setBlock(world, i + 8, j + 51, k + 27, ModBlocks.gravewoodLeaves, 0);
		this.setBlock(world, i + 8, j + 51, k + 28, ModBlocks.gravewoodLeaves, 0);
		this.setBlock(world, i + 8, j + 51, k + 29, ModBlocks.gravewoodLeaves, 0);
		this.setBlock(world, i + 8, j + 51, k + 30, ModBlocks.gravewoodLeaves, 0);
		this.setBlock(world, i + 8, j + 51, k + 31, ModBlocks.gravewoodLeaves, 0);
		this.setBlock(world, i + 8, j + 51, k + 32, ModBlocks.gravewoodLeaves, 0);
		this.setBlock(world, i + 8, j + 51, k + 33, ModBlocks.gravewoodLeaves, 0);
		this.setBlock(world, i + 8, j + 51, k + 34, ModBlocks.gravewoodLeaves, 0);
		this.setBlock(world, i + 8, j + 51, k + 35, ModBlocks.gravewoodLeaves, 0);
		this.setBlock(world, i + 8, j + 51, k + 36, ModBlocks.gravewoodLeaves, 0);
		this.setBlock(world, i + 8, j + 52, k + 19, ModBlocks.gravewoodLeaves, 0);
		this.setBlock(world, i + 8, j + 52, k + 20, ModBlocks.gravewoodLeaves, 0);
		this.setBlock(world, i + 8, j + 52, k + 21, ModBlocks.gravewoodLeaves, 0);
		this.setBlock(world, i + 8, j + 52, k + 22, ModBlocks.gravewoodLeaves, 0);
		this.setBlock(world, i + 8, j + 52, k + 23, ModBlocks.gravewoodLeaves, 0);
		this.setBlock(world, i + 8, j + 52, k + 25, ModBlocks.gravewoodLeaves, 0);
		this.setBlock(world, i + 8, j + 52, k + 29, ModBlocks.gravewoodLeaves, 0);
		this.setBlock(world, i + 8, j + 52, k + 30, ModBlocks.gravewoodLeaves, 0);
		this.setBlock(world, i + 8, j + 52, k + 31, ModBlocks.gravewoodLeaves, 0);
		this.setBlock(world, i + 8, j + 52, k + 32, ModBlocks.gravewoodLeaves, 0);
		this.setBlock(world, i + 8, j + 52, k + 33, ModBlocks.gravewoodLeaves, 0);
		this.setBlock(world, i + 8, j + 52, k + 34, ModBlocks.gravewoodLeaves, 0);
		this.setBlock(world, i + 8, j + 52, k + 35, ModBlocks.gravewoodLeaves, 0);
		this.setBlock(world, i + 8, j + 52, k + 36, ModBlocks.gravewoodLeaves, 0);
		this.setBlock(world, i + 8, j + 52, k + 37, ModBlocks.gravewoodLeaves, 0);
		this.setBlock(world, i + 8, j + 53, k + 31, ModBlocks.gravewoodLeaves, 0);
		this.setBlock(world, i + 8, j + 53, k + 32, ModBlocks.gravewoodLeaves, 0);
		this.setBlock(world, i + 8, j + 53, k + 33, ModBlocks.gravewoodLeaves, 0);
		this.setBlock(world, i + 8, j + 53, k + 34, ModBlocks.gravewoodLeaves, 0);
		this.setBlock(world, i + 8, j + 53, k + 35, ModBlocks.gravewoodLeaves, 0);
		this.setBlock(world, i + 8, j + 53, k + 36, ModBlocks.gravewoodLeaves, 0);
		this.setBlock(world, i + 8, j + 54, k + 31, ModBlocks.gravewoodLeaves, 0);
		this.setBlock(world, i + 8, j + 54, k + 32, ModBlocks.gravewoodLeaves, 0);
		this.setBlock(world, i + 8, j + 54, k + 33, ModBlocks.gravewoodLeaves, 0);
		this.setBlock(world, i + 8, j + 54, k + 34, ModBlocks.gravewoodLeaves, 0);
		this.setBlock(world, i + 8, j + 54, k + 35, ModBlocks.gravewoodLeaves, 0);
		this.setBlock(world, i + 9, j + 43, k + 20, ModBlocks.gravewoodLeaves, 0);
		this.setBlock(world, i + 9, j + 43, k + 21, ModBlocks.gravewoodLeaves, 0);
		this.setBlock(world, i + 9, j + 43, k + 22, ModBlocks.gravewoodLeaves, 0);
		this.setBlock(world, i + 9, j + 44, k + 18, ModBlocks.gravewood, 1);
		this.setBlock(world, i + 9, j + 44, k + 19, ModBlocks.gravewood, 1);
		this.setBlock(world, i + 9, j + 44, k + 20, ModBlocks.gravewoodLeaves, 0);
		this.setBlock(world, i + 9, j + 44, k + 21, ModBlocks.gravewoodLeaves, 0);
		this.setBlock(world, i + 9, j + 44, k + 22, ModBlocks.gravewoodLeaves, 0);
		this.setBlock(world, i + 9, j + 44, k + 23, ModBlocks.gravewoodLeaves, 0);
		this.setBlock(world, i + 9, j + 44, k + 24, ModBlocks.gravewoodLeaves, 0);
		this.setBlock(world, i + 9, j + 44, k + 25, ModBlocks.gravewoodLeaves, 0);
		this.setBlock(world, i + 9, j + 44, k + 26, ModBlocks.gravewoodLeaves, 0);
		this.setBlock(world, i + 9, j + 45, k + 16, ModBlocks.gravewoodLeaves, 0);
		this.setBlock(world, i + 9, j + 45, k + 17, ModBlocks.gravewood, 1);
		this.setBlock(world, i + 9, j + 45, k + 18, ModBlocks.gravewood, 1);
		this.setBlock(world, i + 9, j + 45, k + 19, ModBlocks.gravewood, 1);
		this.setBlock(world, i + 9, j + 45, k + 20, ModBlocks.gravewood, 1);
		this.setBlock(world, i + 9, j + 45, k + 21, ModBlocks.gravewoodLeaves, 0);
		this.setBlock(world, i + 9, j + 45, k + 22, ModBlocks.gravewoodLeaves, 0);
		this.setBlock(world, i + 9, j + 45, k + 23, ModBlocks.gravewood, 1);
		this.setBlock(world, i + 9, j + 45, k + 24, ModBlocks.gravewood, 1);
		this.setBlock(world, i + 9, j + 45, k + 25, ModBlocks.gravewoodLeaves, 0);
		this.setBlock(world, i + 9, j + 45, k + 26, ModBlocks.gravewoodLeaves, 0);
		this.setBlock(world, i + 9, j + 45, k + 27, ModBlocks.gravewoodLeaves, 0);
		this.setBlock(world, i + 9, j + 46, k + 14, ModBlocks.gravewood, 1);
		this.setBlock(world, i + 9, j + 46, k + 15, ModBlocks.gravewoodLeaves, 0);
		this.setBlock(world, i + 9, j + 46, k + 16, ModBlocks.gravewoodLeaves, 0);
		this.setBlock(world, i + 9, j + 46, k + 17, ModBlocks.gravewood, 1);
		this.setBlock(world, i + 9, j + 46, k + 18, ModBlocks.gravewood, 1);
		this.setBlock(world, i + 9, j + 46, k + 19, ModBlocks.gravewood, 1);
		this.setBlock(world, i + 9, j + 46, k + 20, ModBlocks.gravewoodLeaves, 0);
		this.setBlock(world, i + 9, j + 46, k + 21, ModBlocks.gravewoodLeaves, 0);
		this.setBlock(world, i + 9, j + 46, k + 22, ModBlocks.gravewood, 1);
		this.setBlock(world, i + 9, j + 46, k + 23, ModBlocks.gravewoodLeaves, 0);
		this.setBlock(world, i + 9, j + 46, k + 24, ModBlocks.gravewoodLeaves, 0);
		this.setBlock(world, i + 9, j + 46, k + 25, ModBlocks.gravewoodLeaves, 0);
		this.setBlock(world, i + 9, j + 46, k + 26, ModBlocks.gravewoodLeaves, 0);
		this.setBlock(world, i + 9, j + 46, k + 27, ModBlocks.gravewoodLeaves, 0);
		this.setBlock(world, i + 9, j + 46, k + 28, ModBlocks.gravewoodLeaves, 0);
		this.setBlock(world, i + 9, j + 46, k + 29, ModBlocks.gravewoodLeaves, 0);
		this.setBlock(world, i + 9, j + 47, k + 13, ModBlocks.gravewoodLeaves, 0);
		this.setBlock(world, i + 9, j + 47, k + 14, ModBlocks.gravewoodLeaves, 0);
		this.setBlock(world, i + 9, j + 47, k + 15, ModBlocks.gravewoodLeaves, 0);
		this.setBlock(world, i + 9, j + 47, k + 16, ModBlocks.gravewoodLeaves, 0);
		this.setBlock(world, i + 9, j + 47, k + 17, ModBlocks.gravewoodLeaves, 0);
		this.setBlock(world, i + 9, j + 47, k + 18, ModBlocks.gravewood, 1);
		this.setBlock(world, i + 9, j + 47, k + 19, ModBlocks.gravewoodLeaves, 0);
		this.setBlock(world, i + 9, j + 47, k + 20, ModBlocks.gravewood, 1);
		this.setBlock(world, i + 9, j + 47, k + 21, ModBlocks.gravewoodLeaves, 0);
		this.setBlock(world, i + 9, j + 47, k + 22, ModBlocks.gravewood, 1);
		this.setBlock(world, i + 9, j + 47, k + 23, ModBlocks.gravewoodLeaves, 0);
		this.setBlock(world, i + 9, j + 47, k + 24, ModBlocks.gravewood, 1);
		this.setBlock(world, i + 9, j + 47, k + 25, ModBlocks.gravewood, 1);
		this.setBlock(world, i + 9, j + 47, k + 26, ModBlocks.gravewood, 1);
		this.setBlock(world, i + 9, j + 47, k + 27, ModBlocks.gravewood, 1);
		this.setBlock(world, i + 9, j + 47, k + 28, ModBlocks.gravewoodLeaves, 0);
		this.setBlock(world, i + 9, j + 47, k + 29, ModBlocks.gravewoodLeaves, 0);
		this.setBlock(world, i + 9, j + 47, k + 30, ModBlocks.gravewoodLeaves, 0);
		this.setBlock(world, i + 9, j + 47, k + 31, ModBlocks.gravewood, 1);
		this.setBlock(world, i + 9, j + 48, k + 12, ModBlocks.gravewoodLeaves, 0);
		this.setBlock(world, i + 9, j + 48, k + 13, ModBlocks.gravewoodLeaves, 0);
		this.setBlock(world, i + 9, j + 48, k + 14, ModBlocks.gravewoodLeaves, 0);
		this.setBlock(world, i + 9, j + 48, k + 15, ModBlocks.gravewoodLeaves, 0);
		this.setBlock(world, i + 9, j + 48, k + 16, ModBlocks.gravewoodLeaves, 0);
		this.setBlock(world, i + 9, j + 48, k + 17, ModBlocks.gravewoodLeaves, 0);
		this.setBlock(world, i + 9, j + 48, k + 18, ModBlocks.gravewoodLeaves, 0);
		this.setBlock(world, i + 9, j + 48, k + 19, ModBlocks.gravewoodLeaves, 0);
		this.setBlock(world, i + 9, j + 48, k + 20, ModBlocks.gravewoodLeaves, 0);
		this.setBlock(world, i + 9, j + 48, k + 21, ModBlocks.gravewoodLeaves, 0);
		this.setBlock(world, i + 9, j + 48, k + 22, ModBlocks.gravewoodLeaves, 0);
		this.setBlock(world, i + 9, j + 48, k + 23, ModBlocks.gravewoodLeaves, 0);
		this.setBlock(world, i + 9, j + 48, k + 24, ModBlocks.gravewoodLeaves, 0);
		this.setBlock(world, i + 9, j + 48, k + 25, ModBlocks.gravewoodLeaves, 0);
		this.setBlock(world, i + 9, j + 48, k + 26, ModBlocks.gravewoodLeaves, 0);
		this.setBlock(world, i + 9, j + 48, k + 27, ModBlocks.gravewoodLeaves, 0);
		this.setBlock(world, i + 9, j + 48, k + 28, ModBlocks.gravewoodLeaves, 0);
		this.setBlock(world, i + 9, j + 48, k + 29, ModBlocks.gravewood, 1);
		this.setBlock(world, i + 9, j + 48, k + 30, ModBlocks.gravewood, 1);
		this.setBlock(world, i + 9, j + 48, k + 31, ModBlocks.gravewood, 1);
		this.setBlock(world, i + 9, j + 48, k + 32, ModBlocks.gravewood, 1);
		this.setBlock(world, i + 9, j + 48, k + 33, ModBlocks.gravewood, 1);
		this.setBlock(world, i + 9, j + 49, k + 13, ModBlocks.gravewoodLeaves, 0);
		this.setBlock(world, i + 9, j + 49, k + 14, ModBlocks.gravewoodLeaves, 0);
		this.setBlock(world, i + 9, j + 49, k + 15, ModBlocks.gravewoodLeaves, 0);
		this.setBlock(world, i + 9, j + 49, k + 16, ModBlocks.gravewoodLeaves, 0);
		this.setBlock(world, i + 9, j + 49, k + 17, ModBlocks.gravewood, 1);
		this.setBlock(world, i + 9, j + 49, k + 18, ModBlocks.gravewoodLeaves, 0);
		this.setBlock(world, i + 9, j + 49, k + 19, ModBlocks.gravewoodLeaves, 0);
		this.setBlock(world, i + 9, j + 49, k + 20, ModBlocks.gravewood, 1);
		this.setBlock(world, i + 9, j + 49, k + 21, ModBlocks.gravewood, 1);
		this.setBlock(world, i + 9, j + 49, k + 22, ModBlocks.gravewoodLeaves, 0);
		this.setBlock(world, i + 9, j + 49, k + 23, ModBlocks.gravewood, 1);
		this.setBlock(world, i + 9, j + 49, k + 24, ModBlocks.gravewoodLeaves, 0);
		this.setBlock(world, i + 9, j + 49, k + 25, ModBlocks.gravewoodLeaves, 0);
		this.setBlock(world, i + 9, j + 49, k + 26, ModBlocks.gravewoodLeaves, 0);
		this.setBlock(world, i + 9, j + 49, k + 27, ModBlocks.gravewoodLeaves, 0);
		this.setBlock(world, i + 9, j + 49, k + 28, ModBlocks.gravewoodLeaves, 0);
		this.setBlock(world, i + 9, j + 49, k + 29, ModBlocks.gravewoodLeaves, 0);
		this.setBlock(world, i + 9, j + 49, k + 30, ModBlocks.gravewood, 1);
		this.setBlock(world, i + 9, j + 49, k + 31, ModBlocks.gravewood, 1);
		this.setBlock(world, i + 9, j + 49, k + 32, ModBlocks.gravewood, 1);
		this.setBlock(world, i + 9, j + 49, k + 33, ModBlocks.gravewood, 1);
		this.setBlock(world, i + 9, j + 49, k + 34, ModBlocks.gravewood, 1);
		this.setBlock(world, i + 9, j + 50, k + 14, ModBlocks.gravewoodLeaves, 0);
		this.setBlock(world, i + 9, j + 50, k + 15, ModBlocks.gravewoodLeaves, 0);
		this.setBlock(world, i + 9, j + 50, k + 16, ModBlocks.gravewoodLeaves, 0);
		this.setBlock(world, i + 9, j + 50, k + 17, ModBlocks.gravewoodLeaves, 0);
		this.setBlock(world, i + 9, j + 50, k + 18, ModBlocks.gravewoodLeaves, 0);
		this.setBlock(world, i + 9, j + 50, k + 19, ModBlocks.gravewoodLeaves, 0);
		this.setBlock(world, i + 9, j + 50, k + 20, ModBlocks.gravewoodLeaves, 0);
		this.setBlock(world, i + 9, j + 50, k + 21, ModBlocks.gravewoodLeaves, 0);
		this.setBlock(world, i + 9, j + 50, k + 22, ModBlocks.gravewoodLeaves, 0);
		this.setBlock(world, i + 9, j + 50, k + 23, ModBlocks.gravewoodLeaves, 0);
		this.setBlock(world, i + 9, j + 50, k + 24, ModBlocks.gravewoodLeaves, 0);
		this.setBlock(world, i + 9, j + 50, k + 25, ModBlocks.gravewoodLeaves, 0);
		this.setBlock(world, i + 9, j + 50, k + 26, ModBlocks.gravewoodLeaves, 0);
		this.setBlock(world, i + 9, j + 50, k + 27, ModBlocks.gravewoodLeaves, 0);
		this.setBlock(world, i + 9, j + 50, k + 28, ModBlocks.gravewoodLeaves, 0);
		this.setBlock(world, i + 9, j + 50, k + 29, ModBlocks.gravewoodLeaves, 0);
		this.setBlock(world, i + 9, j + 50, k + 30, ModBlocks.gravewoodLeaves, 0);
		this.setBlock(world, i + 9, j + 50, k + 31, ModBlocks.gravewood, 1);
		this.setBlock(world, i + 9, j + 50, k + 32, ModBlocks.gravewood, 1);
		this.setBlock(world, i + 9, j + 50, k + 33, ModBlocks.gravewood, 1);
		this.setBlock(world, i + 9, j + 50, k + 34, ModBlocks.gravewoodLeaves, 0);
		this.setBlock(world, i + 9, j + 50, k + 35, ModBlocks.gravewoodLeaves, 0);
		this.setBlock(world, i + 9, j + 51, k + 15, ModBlocks.gravewoodLeaves, 0);
		this.setBlock(world, i + 9, j + 51, k + 16, ModBlocks.gravewoodLeaves, 0);
		this.setBlock(world, i + 9, j + 51, k + 17, ModBlocks.gravewoodLeaves, 0);
		this.setBlock(world, i + 9, j + 51, k + 19, ModBlocks.gravewoodLeaves, 0);
		this.setBlock(world, i + 9, j + 51, k + 20, ModBlocks.gravewoodLeaves, 0);
		this.setBlock(world, i + 9, j + 51, k + 21, ModBlocks.gravewoodLeaves, 0);
		this.setBlock(world, i + 9, j + 51, k + 22, ModBlocks.gravewoodLeaves, 0);
		this.setBlock(world, i + 9, j + 51, k + 23, ModBlocks.gravewoodLeaves, 0);
		this.setBlock(world, i + 9, j + 51, k + 24, ModBlocks.gravewoodLeaves, 0);
		this.setBlock(world, i + 9, j + 51, k + 25, ModBlocks.gravewoodLeaves, 0);
		this.setBlock(world, i + 9, j + 51, k + 26, ModBlocks.gravewoodLeaves, 0);
		this.setBlock(world, i + 9, j + 51, k + 27, ModBlocks.gravewoodLeaves, 0);
		this.setBlock(world, i + 9, j + 51, k + 28, ModBlocks.gravewoodLeaves, 0);
		this.setBlock(world, i + 9, j + 51, k + 29, ModBlocks.gravewoodLeaves, 0);
		this.setBlock(world, i + 9, j + 51, k + 30, ModBlocks.gravewoodLeaves, 0);
		this.setBlock(world, i + 9, j + 51, k + 31, ModBlocks.gravewoodLeaves, 0);
		this.setBlock(world, i + 9, j + 51, k + 32, ModBlocks.gravewoodLeaves, 0);
		this.setBlock(world, i + 9, j + 51, k + 33, ModBlocks.gravewoodLeaves, 0);
		this.setBlock(world, i + 9, j + 51, k + 34, ModBlocks.gravewoodLeaves, 0);
		this.setBlock(world, i + 9, j + 51, k + 35, ModBlocks.gravewoodLeaves, 0);
		this.setBlock(world, i + 9, j + 51, k + 36, ModBlocks.gravewoodLeaves, 0);
		this.setBlock(world, i + 9, j + 52, k + 20, ModBlocks.gravewoodLeaves, 0);
		this.setBlock(world, i + 9, j + 52, k + 21, ModBlocks.gravewoodLeaves, 0);
		this.setBlock(world, i + 9, j + 52, k + 22, ModBlocks.gravewoodLeaves, 0);
		this.setBlock(world, i + 9, j + 52, k + 29, ModBlocks.gravewoodLeaves, 0);
		this.setBlock(world, i + 9, j + 52, k + 30, ModBlocks.gravewoodLeaves, 0);
		this.setBlock(world, i + 9, j + 52, k + 31, ModBlocks.gravewood, 1);
		this.setBlock(world, i + 9, j + 52, k + 32, ModBlocks.gravewoodLeaves, 0);
		this.setBlock(world, i + 9, j + 52, k + 33, ModBlocks.gravewood, 1);
		this.setBlock(world, i + 9, j + 52, k + 34, ModBlocks.gravewood, 1);
		this.setBlock(world, i + 9, j + 52, k + 35, ModBlocks.gravewoodLeaves, 0);
		this.setBlock(world, i + 9, j + 52, k + 36, ModBlocks.gravewoodLeaves, 0);
		this.setBlock(world, i + 9, j + 52, k + 37, ModBlocks.gravewoodLeaves, 0);
		this.setBlock(world, i + 9, j + 53, k + 31, ModBlocks.gravewoodLeaves, 0);
		this.setBlock(world, i + 9, j + 53, k + 32, ModBlocks.gravewoodLeaves, 0);
		this.setBlock(world, i + 9, j + 53, k + 33, ModBlocks.gravewoodLeaves, 0);
		this.setBlock(world, i + 9, j + 53, k + 34, ModBlocks.gravewoodLeaves, 0);
		this.setBlock(world, i + 9, j + 53, k + 35, ModBlocks.gravewoodLeaves, 0);
		this.setBlock(world, i + 9, j + 53, k + 36, ModBlocks.gravewoodLeaves, 0);
		this.setBlock(world, i + 9, j + 54, k + 31, ModBlocks.gravewoodLeaves, 0);
		this.setBlock(world, i + 9, j + 54, k + 32, ModBlocks.gravewoodLeaves, 0);
		this.setBlock(world, i + 9, j + 54, k + 33, ModBlocks.gravewoodLeaves, 0);
		this.setBlock(world, i + 9, j + 54, k + 34, ModBlocks.gravewoodLeaves, 0);
		this.setBlock(world, i + 9, j + 54, k + 35, ModBlocks.gravewoodLeaves, 0);
		this.setBlock(world, i + 9, j + 55, k + 33, ModBlocks.gravewoodLeaves, 0);
		this.setBlock(world, i + 10, j + 43, k + 19, ModBlocks.gravewoodLeaves, 0);
		this.setBlock(world, i + 10, j + 43, k + 20, ModBlocks.gravewoodLeaves, 0);
		this.setBlock(world, i + 10, j + 43, k + 21, ModBlocks.gravewoodLeaves, 0);
		this.setBlock(world, i + 10, j + 43, k + 22, ModBlocks.gravewoodLeaves, 0);
		this.setBlock(world, i + 10, j + 43, k + 23, ModBlocks.gravewoodLeaves, 0);
		this.setBlock(world, i + 10, j + 44, k + 19, ModBlocks.gravewood, 1);
		this.setBlock(world, i + 10, j + 44, k + 20, ModBlocks.gravewood, 1);
		this.setBlock(world, i + 10, j + 44, k + 21, ModBlocks.gravewood, 1);
		this.setBlock(world, i + 10, j + 44, k + 22, ModBlocks.gravewoodLeaves, 0);
		this.setBlock(world, i + 10, j + 44, k + 23, ModBlocks.gravewoodLeaves, 0);
		this.setBlock(world, i + 10, j + 44, k + 24, ModBlocks.gravewoodLeaves, 0);
		this.setBlock(world, i + 10, j + 44, k + 25, ModBlocks.gravewoodLeaves, 0);
		this.setBlock(world, i + 10, j + 44, k + 26, ModBlocks.gravewoodLeaves, 0);
		this.setBlock(world, i + 10, j + 44, k + 27, ModBlocks.gravewood, 1);
		this.setBlock(world, i + 10, j + 45, k + 18, ModBlocks.gravewood, 1);
		this.setBlock(world, i + 10, j + 45, k + 19, ModBlocks.gravewood, 1);
		this.setBlock(world, i + 10, j + 45, k + 20, ModBlocks.gravewood, 1);
		this.setBlock(world, i + 10, j + 45, k + 21, ModBlocks.gravewood, 1);
		this.setBlock(world, i + 10, j + 45, k + 22, ModBlocks.gravewoodLeaves, 0);
		this.setBlock(world, i + 10, j + 45, k + 23, ModBlocks.gravewoodLeaves, 0);
		this.setBlock(world, i + 10, j + 45, k + 24, ModBlocks.gravewoodLeaves, 0);
		this.setBlock(world, i + 10, j + 45, k + 25, ModBlocks.gravewood, 1);
		this.setBlock(world, i + 10, j + 45, k + 26, ModBlocks.gravewoodLeaves, 0);
		this.setBlock(world, i + 10, j + 45, k + 27, ModBlocks.gravewoodLeaves, 0);
		this.setBlock(world, i + 10, j + 46, k + 14, ModBlocks.gravewoodLeaves, 0);
		this.setBlock(world, i + 10, j + 46, k + 15, ModBlocks.gravewoodLeaves, 0);
		this.setBlock(world, i + 10, j + 46, k + 16, ModBlocks.gravewoodLeaves, 0);
		this.setBlock(world, i + 10, j + 46, k + 17, ModBlocks.gravewood, 1);
		this.setBlock(world, i + 10, j + 46, k + 18, ModBlocks.gravewood, 1);
		this.setBlock(world, i + 10, j + 46, k + 19, ModBlocks.gravewood, 1);
		this.setBlock(world, i + 10, j + 46, k + 20, ModBlocks.gravewood, 1);
		this.setBlock(world, i + 10, j + 46, k + 21, ModBlocks.gravewoodLeaves, 0);
		this.setBlock(world, i + 10, j + 46, k + 22, ModBlocks.gravewoodLeaves, 0);
		this.setBlock(world, i + 10, j + 46, k + 23, ModBlocks.gravewoodLeaves, 0);
		this.setBlock(world, i + 10, j + 46, k + 24, ModBlocks.gravewoodLeaves, 0);
		this.setBlock(world, i + 10, j + 46, k + 25, ModBlocks.gravewoodLeaves, 0);
		this.setBlock(world, i + 10, j + 46, k + 26, ModBlocks.gravewoodLeaves, 0);
		this.setBlock(world, i + 10, j + 46, k + 27, ModBlocks.gravewoodLeaves, 0);
		this.setBlock(world, i + 10, j + 46, k + 28, ModBlocks.gravewoodLeaves, 0);
		this.setBlock(world, i + 10, j + 46, k + 29, ModBlocks.gravewoodLeaves, 0);
		this.setBlock(world, i + 10, j + 47, k + 13, ModBlocks.gravewoodLeaves, 0);
		this.setBlock(world, i + 10, j + 47, k + 14, ModBlocks.gravewoodLeaves, 0);
		this.setBlock(world, i + 10, j + 47, k + 15, ModBlocks.gravewoodLeaves, 0);
		this.setBlock(world, i + 10, j + 47, k + 16, ModBlocks.gravewoodLeaves, 0);
		this.setBlock(world, i + 10, j + 47, k + 17, ModBlocks.gravewoodLeaves, 0);
		this.setBlock(world, i + 10, j + 47, k + 18, ModBlocks.gravewoodLeaves, 0);
		this.setBlock(world, i + 10, j + 47, k + 19, ModBlocks.gravewoodLeaves, 0);
		this.setBlock(world, i + 10, j + 47, k + 20, ModBlocks.gravewood, 1);
		this.setBlock(world, i + 10, j + 47, k + 21, ModBlocks.gravewoodLeaves, 0);
		this.setBlock(world, i + 10, j + 47, k + 22, ModBlocks.gravewoodLeaves, 0);
		this.setBlock(world, i + 10, j + 47, k + 23, ModBlocks.gravewoodLeaves, 0);
		this.setBlock(world, i + 10, j + 47, k + 24, ModBlocks.gravewoodLeaves, 0);
		this.setBlock(world, i + 10, j + 47, k + 25, ModBlocks.gravewoodLeaves, 0);
		this.setBlock(world, i + 10, j + 47, k + 26, ModBlocks.gravewoodLeaves, 0);
		this.setBlock(world, i + 10, j + 47, k + 27, ModBlocks.gravewood, 1);
		this.setBlock(world, i + 10, j + 47, k + 28, ModBlocks.gravewood, 1);
		this.setBlock(world, i + 10, j + 47, k + 29, ModBlocks.gravewood, 1);
		this.setBlock(world, i + 10, j + 47, k + 30, ModBlocks.gravewood, 1);
		this.setBlock(world, i + 10, j + 47, k + 31, ModBlocks.gravewood, 1);
		this.setBlock(world, i + 10, j + 48, k + 12, ModBlocks.gravewoodLeaves, 0);
		this.setBlock(world, i + 10, j + 48, k + 13, ModBlocks.gravewoodLeaves, 0);
		this.setBlock(world, i + 10, j + 48, k + 14, ModBlocks.gravewoodLeaves, 0);
		this.setBlock(world, i + 10, j + 48, k + 15, ModBlocks.gravewoodLeaves, 0);
		this.setBlock(world, i + 10, j + 48, k + 16, ModBlocks.gravewood, 1);
		this.setBlock(world, i + 10, j + 48, k + 17, ModBlocks.gravewoodLeaves, 0);
		this.setBlock(world, i + 10, j + 48, k + 18, ModBlocks.gravewoodLeaves, 0);
		this.setBlock(world, i + 10, j + 48, k + 19, ModBlocks.gravewoodLeaves, 0);
		this.setBlock(world, i + 10, j + 48, k + 20, ModBlocks.gravewoodLeaves, 0);
		this.setBlock(world, i + 10, j + 48, k + 21, ModBlocks.gravewoodLeaves, 0);
		this.setBlock(world, i + 10, j + 48, k + 22, ModBlocks.gravewoodLeaves, 0);
		this.setBlock(world, i + 10, j + 48, k + 23, ModBlocks.gravewoodLeaves, 0);
		this.setBlock(world, i + 10, j + 48, k + 24, ModBlocks.gravewoodLeaves, 0);
		this.setBlock(world, i + 10, j + 48, k + 25, ModBlocks.gravewoodLeaves, 0);
		this.setBlock(world, i + 10, j + 48, k + 26, ModBlocks.gravewoodLeaves, 0);
		this.setBlock(world, i + 10, j + 48, k + 27, ModBlocks.gravewood, 1);
		this.setBlock(world, i + 10, j + 48, k + 28, ModBlocks.gravewood, 1);
		this.setBlock(world, i + 10, j + 48, k + 29, ModBlocks.gravewood, 1);
		this.setBlock(world, i + 10, j + 48, k + 30, ModBlocks.gravewood, 1);
		this.setBlock(world, i + 10, j + 48, k + 31, ModBlocks.gravewood, 1);
		this.setBlock(world, i + 10, j + 48, k + 32, ModBlocks.gravewood, 1);
		this.setBlock(world, i + 10, j + 48, k + 33, ModBlocks.gravewoodLeaves, 0);
		this.setBlock(world, i + 10, j + 49, k + 13, ModBlocks.gravewoodLeaves, 0);
		this.setBlock(world, i + 10, j + 49, k + 14, ModBlocks.gravewoodLeaves, 0);
		this.setBlock(world, i + 10, j + 49, k + 15, ModBlocks.gravewood, 1);
		this.setBlock(world, i + 10, j + 49, k + 16, ModBlocks.gravewoodLeaves, 0);
		this.setBlock(world, i + 10, j + 49, k + 17, ModBlocks.gravewoodLeaves, 0);
		this.setBlock(world, i + 10, j + 49, k + 18, ModBlocks.gravewoodLeaves, 0);
		this.setBlock(world, i + 10, j + 49, k + 19, ModBlocks.gravewoodLeaves, 0);
		this.setBlock(world, i + 10, j + 49, k + 20, ModBlocks.gravewoodLeaves, 0);
		this.setBlock(world, i + 10, j + 49, k + 21, ModBlocks.gravewoodLeaves, 0);
		this.setBlock(world, i + 10, j + 49, k + 22, ModBlocks.gravewoodLeaves, 0);
		this.setBlock(world, i + 10, j + 49, k + 23, ModBlocks.gravewoodLeaves, 0);
		this.setBlock(world, i + 10, j + 49, k + 24, ModBlocks.gravewoodLeaves, 0);
		this.setBlock(world, i + 10, j + 49, k + 25, ModBlocks.gravewoodLeaves, 0);
		this.setBlock(world, i + 10, j + 49, k + 26, ModBlocks.gravewoodLeaves, 0);
		this.setBlock(world, i + 10, j + 49, k + 27, ModBlocks.gravewoodLeaves, 0);
		this.setBlock(world, i + 10, j + 49, k + 28, ModBlocks.gravewoodLeaves, 0);
		this.setBlock(world, i + 10, j + 49, k + 29, ModBlocks.gravewood, 1);
		this.setBlock(world, i + 10, j + 49, k + 30, ModBlocks.gravewood, 1);
		this.setBlock(world, i + 10, j + 49, k + 31, ModBlocks.gravewood, 1);
		this.setBlock(world, i + 10, j + 49, k + 32, ModBlocks.gravewood, 1);
		this.setBlock(world, i + 10, j + 49, k + 33, ModBlocks.gravewood, 1);
		this.setBlock(world, i + 10, j + 50, k + 14, ModBlocks.gravewood, 1);
		this.setBlock(world, i + 10, j + 50, k + 15, ModBlocks.gravewoodLeaves, 0);
		this.setBlock(world, i + 10, j + 50, k + 16, ModBlocks.gravewoodLeaves, 0);
		this.setBlock(world, i + 10, j + 50, k + 17, ModBlocks.gravewoodLeaves, 0);
		this.setBlock(world, i + 10, j + 50, k + 18, ModBlocks.gravewoodLeaves, 0);
		this.setBlock(world, i + 10, j + 50, k + 19, ModBlocks.gravewoodLeaves, 0);
		this.setBlock(world, i + 10, j + 50, k + 20, ModBlocks.gravewoodLeaves, 0);
		this.setBlock(world, i + 10, j + 50, k + 21, ModBlocks.gravewoodLeaves, 0);
		this.setBlock(world, i + 10, j + 50, k + 22, ModBlocks.gravewoodLeaves, 0);
		this.setBlock(world, i + 10, j + 50, k + 23, ModBlocks.gravewoodLeaves, 0);
		this.setBlock(world, i + 10, j + 50, k + 24, ModBlocks.gravewoodLeaves, 0);
		this.setBlock(world, i + 10, j + 50, k + 25, ModBlocks.gravewoodLeaves, 0);
		this.setBlock(world, i + 10, j + 50, k + 26, ModBlocks.gravewood, 1);
		this.setBlock(world, i + 10, j + 50, k + 27, ModBlocks.gravewoodLeaves, 0);
		this.setBlock(world, i + 10, j + 50, k + 28, ModBlocks.gravewoodLeaves, 0);
		this.setBlock(world, i + 10, j + 50, k + 29, ModBlocks.gravewood, 1);
		this.setBlock(world, i + 10, j + 50, k + 30, ModBlocks.gravewoodLeaves, 0);
		this.setBlock(world, i + 10, j + 50, k + 31, ModBlocks.gravewoodLeaves, 0);
		this.setBlock(world, i + 10, j + 50, k + 32, ModBlocks.gravewoodLeaves, 0);
		this.setBlock(world, i + 10, j + 50, k + 33, ModBlocks.gravewoodLeaves, 0);
		this.setBlock(world, i + 10, j + 50, k + 34, ModBlocks.gravewoodLeaves, 0);
		this.setBlock(world, i + 10, j + 50, k + 35, ModBlocks.gravewood, 1);
		this.setBlock(world, i + 10, j + 51, k + 14, ModBlocks.gravewoodLeaves, 0);
		this.setBlock(world, i + 10, j + 51, k + 15, ModBlocks.gravewoodLeaves, 0);
		this.setBlock(world, i + 10, j + 51, k + 16, ModBlocks.gravewoodLeaves, 0);
		this.setBlock(world, i + 10, j + 51, k + 17, ModBlocks.gravewoodLeaves, 0);
		this.setBlock(world, i + 10, j + 51, k + 18, ModBlocks.gravewoodLeaves, 0);
		this.setBlock(world, i + 10, j + 51, k + 19, ModBlocks.gravewoodLeaves, 0);
		this.setBlock(world, i + 10, j + 51, k + 20, ModBlocks.gravewoodLeaves, 0);
		this.setBlock(world, i + 10, j + 51, k + 21, ModBlocks.gravewoodLeaves, 0);
		this.setBlock(world, i + 10, j + 51, k + 24, ModBlocks.gravewoodLeaves, 0);
		this.setBlock(world, i + 10, j + 51, k + 25, ModBlocks.gravewoodLeaves, 0);
		this.setBlock(world, i + 10, j + 51, k + 26, ModBlocks.gravewoodLeaves, 0);
		this.setBlock(world, i + 10, j + 51, k + 27, ModBlocks.gravewoodLeaves, 0);
		this.setBlock(world, i + 10, j + 51, k + 28, ModBlocks.gravewoodLeaves, 0);
		this.setBlock(world, i + 10, j + 51, k + 29, ModBlocks.gravewoodLeaves, 0);
		this.setBlock(world, i + 10, j + 51, k + 30, ModBlocks.gravewood, 1);
		this.setBlock(world, i + 10, j + 51, k + 31, ModBlocks.gravewoodLeaves, 0);
		this.setBlock(world, i + 10, j + 51, k + 32, ModBlocks.gravewoodLeaves, 0);
		this.setBlock(world, i + 10, j + 51, k + 33, ModBlocks.gravewoodLeaves, 0);
		this.setBlock(world, i + 10, j + 51, k + 34, ModBlocks.gravewoodLeaves, 0);
		this.setBlock(world, i + 10, j + 51, k + 35, ModBlocks.gravewoodLeaves, 0);
		this.setBlock(world, i + 10, j + 51, k + 36, ModBlocks.gravewoodLeaves, 0);
		this.setBlock(world, i + 10, j + 52, k + 29, ModBlocks.gravewoodLeaves, 0);
		this.setBlock(world, i + 10, j + 52, k + 30, ModBlocks.gravewoodLeaves, 0);
		this.setBlock(world, i + 10, j + 52, k + 31, ModBlocks.gravewood, 1);
		this.setBlock(world, i + 10, j + 52, k + 32, ModBlocks.gravewoodLeaves, 0);
		this.setBlock(world, i + 10, j + 52, k + 33, ModBlocks.gravewoodLeaves, 0);
		this.setBlock(world, i + 10, j + 52, k + 34, ModBlocks.gravewoodLeaves, 0);
		this.setBlock(world, i + 10, j + 52, k + 35, ModBlocks.gravewoodLeaves, 0);
		this.setBlock(world, i + 10, j + 52, k + 36, ModBlocks.gravewoodLeaves, 0);
		this.setBlock(world, i + 10, j + 52, k + 37, ModBlocks.gravewoodLeaves, 0);
		this.setBlock(world, i + 10, j + 53, k + 31, ModBlocks.gravewoodLeaves, 0);
		this.setBlock(world, i + 10, j + 53, k + 32, ModBlocks.gravewoodLeaves, 0);
		this.setBlock(world, i + 10, j + 53, k + 33, ModBlocks.gravewoodLeaves, 0);
		this.setBlock(world, i + 10, j + 53, k + 34, ModBlocks.gravewoodLeaves, 0);
		this.setBlock(world, i + 10, j + 53, k + 35, ModBlocks.gravewoodLeaves, 0);
		this.setBlock(world, i + 10, j + 53, k + 36, ModBlocks.gravewoodLeaves, 0);
		this.setBlock(world, i + 10, j + 54, k + 31, ModBlocks.gravewoodLeaves, 0);
		this.setBlock(world, i + 10, j + 54, k + 32, ModBlocks.gravewoodLeaves, 0);
		this.setBlock(world, i + 10, j + 54, k + 33, ModBlocks.gravewoodLeaves, 0);
		this.setBlock(world, i + 10, j + 54, k + 34, ModBlocks.gravewoodLeaves, 0);
		this.setBlock(world, i + 10, j + 54, k + 35, ModBlocks.gravewoodLeaves, 0);
		this.setBlock(world, i + 11, j + 39, k + 24, ModBlocks.gravewood, 1);
		this.setBlock(world, i + 11, j + 41, k + 24, ModBlocks.gravewood, 1);
		this.setBlock(world, i + 11, j + 42, k + 21, ModBlocks.gravewoodLeaves, 0);
		this.setBlock(world, i + 11, j + 43, k + 19, ModBlocks.gravewoodLeaves, 0);
		this.setBlock(world, i + 11, j + 43, k + 20, ModBlocks.gravewood, 1);
		this.setBlock(world, i + 11, j + 43, k + 21, ModBlocks.gravewood, 1);
		this.setBlock(world, i + 11, j + 43, k + 22, ModBlocks.gravewoodLeaves, 0);
		this.setBlock(world, i + 11, j + 43, k + 23, ModBlocks.gravewoodLeaves, 0);
		this.setBlock(world, i + 11, j + 43, k + 24, ModBlocks.gravewood, 1);
		this.setBlock(world, i + 11, j + 43, k + 25, ModBlocks.gravewood, 1);
		this.setBlock(world, i + 11, j + 44, k + 19, ModBlocks.gravewoodLeaves, 0);
		this.setBlock(world, i + 11, j + 44, k + 20, ModBlocks.gravewood, 1);
		this.setBlock(world, i + 11, j + 44, k + 21, ModBlocks.gravewood, 1);
		this.setBlock(world, i + 11, j + 44, k + 22, ModBlocks.gravewood, 1);
		this.setBlock(world, i + 11, j + 44, k + 23, ModBlocks.gravewood, 1);
		this.setBlock(world, i + 11, j + 44, k + 24, ModBlocks.gravewoodLeaves, 0);
		this.setBlock(world, i + 11, j + 44, k + 25, ModBlocks.gravewoodLeaves, 0);
		this.setBlock(world, i + 11, j + 44, k + 26, ModBlocks.gravewoodLeaves, 0);
		this.setBlock(world, i + 11, j + 44, k + 27, ModBlocks.gravewoodLeaves, 0);
		this.setBlock(world, i + 11, j + 45, k + 18, ModBlocks.gravewoodLeaves, 0);
		this.setBlock(world, i + 11, j + 45, k + 19, ModBlocks.gravewood, 1);
		this.setBlock(world, i + 11, j + 45, k + 20, ModBlocks.gravewood, 1);
		this.setBlock(world, i + 11, j + 45, k + 21, ModBlocks.gravewood, 1);
		this.setBlock(world, i + 11, j + 45, k + 22, ModBlocks.gravewood, 1);
		this.setBlock(world, i + 11, j + 45, k + 23, ModBlocks.gravewoodLeaves, 0);
		this.setBlock(world, i + 11, j + 45, k + 24, ModBlocks.gravewood, 1);
		this.setBlock(world, i + 11, j + 45, k + 25, ModBlocks.gravewood, 1);
		this.setBlock(world, i + 11, j + 45, k + 26, ModBlocks.gravewoodLeaves, 0);
		this.setBlock(world, i + 11, j + 45, k + 27, ModBlocks.gravewoodLeaves, 0);
		this.setBlock(world, i + 11, j + 46, k + 15, ModBlocks.gravewoodLeaves, 0);
		this.setBlock(world, i + 11, j + 46, k + 16, ModBlocks.gravewoodLeaves, 0);
		this.setBlock(world, i + 11, j + 46, k + 17, ModBlocks.gravewoodLeaves, 0);
		this.setBlock(world, i + 11, j + 46, k + 19, ModBlocks.gravewoodLeaves, 0);
		this.setBlock(world, i + 11, j + 46, k + 20, ModBlocks.gravewood, 1);
		this.setBlock(world, i + 11, j + 46, k + 21, ModBlocks.gravewood, 1);
		this.setBlock(world, i + 11, j + 46, k + 22, ModBlocks.gravewoodLeaves, 0);
		this.setBlock(world, i + 11, j + 46, k + 23, ModBlocks.gravewoodLeaves, 0);
		this.setBlock(world, i + 11, j + 46, k + 24, ModBlocks.gravewoodLeaves, 0);
		this.setBlock(world, i + 11, j + 46, k + 25, ModBlocks.gravewood, 1);
		this.setBlock(world, i + 11, j + 46, k + 26, ModBlocks.gravewood, 1);
		this.setBlock(world, i + 11, j + 46, k + 27, ModBlocks.gravewood, 1);
		this.setBlock(world, i + 11, j + 46, k + 28, ModBlocks.gravewood, 1);
		this.setBlock(world, i + 11, j + 46, k + 29, ModBlocks.gravewood, 1);
		this.setBlock(world, i + 11, j + 47, k + 14, ModBlocks.gravewoodLeaves, 0);
		this.setBlock(world, i + 11, j + 47, k + 15, ModBlocks.gravewoodLeaves, 0);
		this.setBlock(world, i + 11, j + 47, k + 16, ModBlocks.gravewoodLeaves, 0);
		this.setBlock(world, i + 11, j + 47, k + 17, ModBlocks.gravewoodLeaves, 0);
		this.setBlock(world, i + 11, j + 47, k + 18, ModBlocks.gravewood, 1);
		this.setBlock(world, i + 11, j + 47, k + 19, ModBlocks.gravewoodLeaves, 0);
		this.setBlock(world, i + 11, j + 47, k + 20, ModBlocks.gravewoodLeaves, 0);
		this.setBlock(world, i + 11, j + 47, k + 21, ModBlocks.gravewoodLeaves, 0);
		this.setBlock(world, i + 11, j + 47, k + 22, ModBlocks.gravewoodLeaves, 0);
		this.setBlock(world, i + 11, j + 47, k + 23, ModBlocks.gravewoodLeaves, 0);
		this.setBlock(world, i + 11, j + 47, k + 24, ModBlocks.gravewoodLeaves, 0);
		this.setBlock(world, i + 11, j + 47, k + 25, ModBlocks.gravewoodLeaves, 0);
		this.setBlock(world, i + 11, j + 47, k + 26, ModBlocks.gravewood, 1);
		this.setBlock(world, i + 11, j + 47, k + 27, ModBlocks.gravewood, 1);
		this.setBlock(world, i + 11, j + 47, k + 28, ModBlocks.gravewood, 1);
		this.setBlock(world, i + 11, j + 47, k + 29, ModBlocks.gravewood, 1);
		this.setBlock(world, i + 11, j + 47, k + 30, ModBlocks.gravewood, 1);
		this.setBlock(world, i + 11, j + 47, k + 31, ModBlocks.gravewoodLeaves, 0);
		this.setBlock(world, i + 11, j + 48, k + 13, ModBlocks.gravewoodLeaves, 0);
		this.setBlock(world, i + 11, j + 48, k + 14, ModBlocks.gravewoodLeaves, 0);
		this.setBlock(world, i + 11, j + 48, k + 15, ModBlocks.gravewoodLeaves, 0);
		this.setBlock(world, i + 11, j + 48, k + 16, ModBlocks.gravewoodLeaves, 0);
		this.setBlock(world, i + 11, j + 48, k + 17, ModBlocks.gravewood, 1);
		this.setBlock(world, i + 11, j + 48, k + 18, ModBlocks.gravewoodLeaves, 0);
		this.setBlock(world, i + 11, j + 48, k + 19, ModBlocks.gravewoodLeaves, 0);
		this.setBlock(world, i + 11, j + 48, k + 20, ModBlocks.gravewoodLeaves, 0);
		this.setBlock(world, i + 11, j + 48, k + 21, ModBlocks.gravewoodLeaves, 0);
		this.setBlock(world, i + 11, j + 48, k + 22, ModBlocks.gravewoodLeaves, 0);
		this.setBlock(world, i + 11, j + 48, k + 23, ModBlocks.gravewoodLeaves, 0);
		this.setBlock(world, i + 11, j + 48, k + 24, ModBlocks.gravewood, 1);
		this.setBlock(world, i + 11, j + 48, k + 25, ModBlocks.gravewoodLeaves, 0);
		this.setBlock(world, i + 11, j + 48, k + 26, ModBlocks.gravewoodLeaves, 0);
		this.setBlock(world, i + 11, j + 48, k + 27, ModBlocks.gravewood, 1);
		this.setBlock(world, i + 11, j + 48, k + 28, ModBlocks.gravewood, 1);
		this.setBlock(world, i + 11, j + 48, k + 29, ModBlocks.gravewood, 1);
		this.setBlock(world, i + 11, j + 48, k + 30, ModBlocks.gravewood, 1);
