/*
*** MADE BY MRPONYCAPTAIN'S .SCHEMATIC TO .JAVA CONVERTING TOOL v2.0 ***
*/

package com.DavidM1A2.AfraidOfTheDark.common.worldGeneration.darkForestDungeon;

import java.util.Random;
import net.minecraft.block.Block;
import net.minecraft.init.Blocks;
import net.minecraft.tileentity.TileEntity;
import net.minecraft.tileentity.TileEntityChest;
import net.minecraft.tileentity.TileEntityMobSpawner;
import net.minecraft.util.BlockPos;
import net.minecraft.util.WeightedRandomChestContent;
import net.minecraft.world.World;
import java.util.Random;

public class TreeLargeDonut
{
	public TreeLargeDonut(World world, Random rand, int x, int y, int z) 
	{
		this.generate(world, rand, x, y, z);
	}

	public void setBlock(World world, int x, int y, int z, Block block, int metadata)
	{
		world.setBlockState(new BlockPos(x, y, z), block.getStateFromMeta(metadata));
	}

	public boolean generate(World world, Random rand, int i, int j, int k) {
		this.setBlock(world, i + 0, j + 41, k + 32, Blocks.leaves, 0);
		this.setBlock(world, i + 0, j + 41, k + 33, Blocks.leaves, 0);
		this.setBlock(world, i + 0, j + 41, k + 34, Blocks.leaves, 0);
		this.setBlock(world, i + 1, j + 40, k + 32, Blocks.log, 1);
		this.setBlock(world, i + 1, j + 41, k + 31, Blocks.leaves, 0);
		this.setBlock(world, i + 1, j + 41, k + 32, Blocks.leaves, 0);
		this.setBlock(world, i + 1, j + 41, k + 33, Blocks.leaves, 0);
		this.setBlock(world, i + 1, j + 41, k + 34, Blocks.log, 1);
		this.setBlock(world, i + 1, j + 41, k + 35, Blocks.leaves, 0);
		this.setBlock(world, i + 1, j + 42, k + 31, Blocks.leaves, 0);
		this.setBlock(world, i + 1, j + 42, k + 32, Blocks.leaves, 0);
		this.setBlock(world, i + 1, j + 42, k + 33, Blocks.leaves, 0);
		this.setBlock(world, i + 1, j + 42, k + 34, Blocks.leaves, 0);
		this.setBlock(world, i + 1, j + 42, k + 35, Blocks.leaves, 0);
		this.setBlock(world, i + 2, j + 39, k + 32, Blocks.leaves, 0);
		this.setBlock(world, i + 2, j + 39, k + 33, Blocks.leaves, 0);
		this.setBlock(world, i + 2, j + 40, k + 19, Blocks.leaves, 8);
		this.setBlock(world, i + 2, j + 40, k + 20, Blocks.leaves, 0);
		this.setBlock(world, i + 2, j + 40, k + 21, Blocks.leaves, 0);
		this.setBlock(world, i + 2, j + 40, k + 22, Blocks.leaves, 0);
		this.setBlock(world, i + 2, j + 40, k + 29, Blocks.leaves, 0);
		this.setBlock(world, i + 2, j + 40, k + 30, Blocks.leaves, 0);
		this.setBlock(world, i + 2, j + 40, k + 31, Blocks.leaves, 0);
		this.setBlock(world, i + 2, j + 40, k + 32, Blocks.log, 1);
		this.setBlock(world, i + 2, j + 40, k + 33, Blocks.leaves, 0);
		this.setBlock(world, i + 2, j + 40, k + 34, Blocks.leaves, 0);
		this.setBlock(world, i + 2, j + 40, k + 35, Blocks.leaves, 0);
		this.setBlock(world, i + 2, j + 41, k + 19, Blocks.leaves, 0);
		this.setBlock(world, i + 2, j + 41, k + 20, Blocks.leaves, 0);
		this.setBlock(world, i + 2, j + 41, k + 21, Blocks.leaves, 0);
		this.setBlock(world, i + 2, j + 41, k + 22, Blocks.leaves, 0);
		this.setBlock(world, i + 2, j + 41, k + 29, Blocks.leaves, 0);
		this.setBlock(world, i + 2, j + 41, k + 30, Blocks.leaves, 0);
		this.setBlock(world, i + 2, j + 41, k + 31, Blocks.leaves, 0);
		this.setBlock(world, i + 2, j + 41, k + 32, Blocks.leaves, 0);
		this.setBlock(world, i + 2, j + 41, k + 33, Blocks.leaves, 0);
		this.setBlock(world, i + 2, j + 41, k + 34, Blocks.leaves, 0);
		this.setBlock(world, i + 2, j + 41, k + 35, Blocks.leaves, 0);
		this.setBlock(world, i + 2, j + 41, k + 36, Blocks.leaves, 0);
		this.setBlock(world, i + 2, j + 41, k + 37, Blocks.leaves, 0);
		this.setBlock(world, i + 2, j + 42, k + 20, Blocks.leaves, 0);
		this.setBlock(world, i + 2, j + 42, k + 21, Blocks.leaves, 0);
		this.setBlock(world, i + 2, j + 42, k + 22, Blocks.leaves, 0);
		this.setBlock(world, i + 2, j + 42, k + 29, Blocks.leaves, 0);
		this.setBlock(world, i + 2, j + 42, k + 30, Blocks.leaves, 0);
		this.setBlock(world, i + 2, j + 42, k + 31, Blocks.leaves, 0);
		this.setBlock(world, i + 2, j + 42, k + 32, Blocks.leaves, 0);
		this.setBlock(world, i + 2, j + 42, k + 33, Blocks.leaves, 0);
		this.setBlock(world, i + 2, j + 42, k + 34, Blocks.log, 1);
		this.setBlock(world, i + 2, j + 42, k + 35, Blocks.leaves, 0);
		this.setBlock(world, i + 2, j + 42, k + 36, Blocks.leaves, 0);
		this.setBlock(world, i + 2, j + 42, k + 37, Blocks.leaves, 0);
		this.setBlock(world, i + 2, j + 43, k + 29, Blocks.leaves, 8);
		this.setBlock(world, i + 2, j + 43, k + 30, Blocks.leaves, 0);
		this.setBlock(world, i + 2, j + 43, k + 31, Blocks.leaves, 0);
		this.setBlock(world, i + 2, j + 43, k + 32, Blocks.leaves, 0);
		this.setBlock(world, i + 2, j + 43, k + 33, Blocks.leaves, 0);
		this.setBlock(world, i + 2, j + 43, k + 34, Blocks.leaves, 0);
		this.setBlock(world, i + 2, j + 43, k + 35, Blocks.leaves, 0);
		this.setBlock(world, i + 2, j + 43, k + 36, Blocks.leaves, 0);
		this.setBlock(world, i + 2, j + 43, k + 37, Blocks.leaves, 0);
		this.setBlock(world, i + 3, j + 39, k + 19, Blocks.leaves, 0);
		this.setBlock(world, i + 3, j + 39, k + 20, Blocks.leaves, 0);
		this.setBlock(world, i + 3, j + 39, k + 21, Blocks.leaves, 0);
		this.setBlock(world, i + 3, j + 39, k + 22, Blocks.log, 1);
		this.setBlock(world, i + 3, j + 39, k + 23, Blocks.leaves, 0);
		this.setBlock(world, i + 3, j + 39, k + 24, Blocks.leaves, 0);
		this.setBlock(world, i + 3, j + 39, k + 25, Blocks.leaves, 0);
		this.setBlock(world, i + 3, j + 39, k + 26, Blocks.leaves, 0);
		this.setBlock(world, i + 3, j + 39, k + 31, Blocks.leaves, 0);
		this.setBlock(world, i + 3, j + 39, k + 32, Blocks.log, 1);
		this.setBlock(world, i + 3, j + 39, k + 33, Blocks.log, 1);
		this.setBlock(world, i + 3, j + 39, k + 34, Blocks.log, 1);
		this.setBlock(world, i + 3, j + 40, k + 20, Blocks.leaves, 0);
		this.setBlock(world, i + 3, j + 40, k + 21, Blocks.leaves, 0);
		this.setBlock(world, i + 3, j + 40, k + 22, Blocks.leaves, 0);
		this.setBlock(world, i + 3, j + 40, k + 23, Blocks.leaves, 0);
		this.setBlock(world, i + 3, j + 40, k + 24, Blocks.log, 1);
		this.setBlock(world, i + 3, j + 40, k + 25, Blocks.leaves, 0);
		this.setBlock(world, i + 3, j + 40, k + 29, Blocks.leaves, 0);
		this.setBlock(world, i + 3, j + 40, k + 30, Blocks.leaves, 0);
		this.setBlock(world, i + 3, j + 40, k + 31, Blocks.log, 1);
		this.setBlock(world, i + 3, j + 40, k + 32, Blocks.log, 1);
		this.setBlock(world, i + 3, j + 40, k + 33, Blocks.log, 1);
		this.setBlock(world, i + 3, j + 40, k + 34, Blocks.leaves, 0);
		this.setBlock(world, i + 3, j + 40, k + 35, Blocks.leaves, 0);
		this.setBlock(world, i + 3, j + 40, k + 36, Blocks.leaves, 0);
		this.setBlock(world, i + 3, j + 41, k + 19, Blocks.leaves, 0);
		this.setBlock(world, i + 3, j + 41, k + 20, Blocks.leaves, 0);
		this.setBlock(world, i + 3, j + 41, k + 21, Blocks.leaves, 0);
		this.setBlock(world, i + 3, j + 41, k + 22, Blocks.log, 1);
		this.setBlock(world, i + 3, j + 41, k + 23, Blocks.leaves, 0);
		this.setBlock(world, i + 3, j + 41, k + 24, Blocks.leaves, 0);
		this.setBlock(world, i + 3, j + 41, k + 30, Blocks.leaves, 0);
		this.setBlock(world, i + 3, j + 41, k + 31, Blocks.leaves, 0);
		this.setBlock(world, i + 3, j + 41, k + 32, Blocks.log, 1);
		this.setBlock(world, i + 3, j + 41, k + 33, Blocks.leaves, 0);
		this.setBlock(world, i + 3, j + 41, k + 34, Blocks.leaves, 0);
		this.setBlock(world, i + 3, j + 41, k + 35, Blocks.leaves, 0);
		this.setBlock(world, i + 3, j + 41, k + 36, Blocks.leaves, 0);
		this.setBlock(world, i + 3, j + 41, k + 37, Blocks.leaves, 0);
		this.setBlock(world, i + 3, j + 41, k + 38, Blocks.leaves, 0);
		this.setBlock(world, i + 3, j + 42, k + 20, Blocks.leaves, 0);
		this.setBlock(world, i + 3, j + 42, k + 21, Blocks.leaves, 0);
		this.setBlock(world, i + 3, j + 42, k + 22, Blocks.leaves, 0);
		this.setBlock(world, i + 3, j + 42, k + 29, Blocks.leaves, 0);
		this.setBlock(world, i + 3, j + 42, k + 30, Blocks.leaves, 0);
		this.setBlock(world, i + 3, j + 42, k + 31, Blocks.leaves, 0);
		this.setBlock(world, i + 3, j + 42, k + 32, Blocks.leaves, 0);
		this.setBlock(world, i + 3, j + 42, k + 33, Blocks.leaves, 0);
		this.setBlock(world, i + 3, j + 42, k + 34, Blocks.leaves, 0);
		this.setBlock(world, i + 3, j + 42, k + 35, Blocks.leaves, 0);
		this.setBlock(world, i + 3, j + 42, k + 36, Blocks.leaves, 0);
		this.setBlock(world, i + 3, j + 42, k + 37, Blocks.leaves, 0);
		this.setBlock(world, i + 3, j + 42, k + 38, Blocks.leaves, 0);
		this.setBlock(world, i + 3, j + 43, k + 21, Blocks.leaves, 0);
		this.setBlock(world, i + 3, j + 43, k + 22, Blocks.leaves, 0);
		this.setBlock(world, i + 3, j + 43, k + 29, Blocks.leaves, 0);
		this.setBlock(world, i + 3, j + 43, k + 30, Blocks.leaves, 0);
		this.setBlock(world, i + 3, j + 43, k + 31, Blocks.leaves, 0);
		this.setBlock(world, i + 3, j + 43, k + 32, Blocks.leaves, 0);
		this.setBlock(world, i + 3, j + 43, k + 33, Blocks.leaves, 0);
		this.setBlock(world, i + 3, j + 43, k + 34, Blocks.leaves, 0);
		this.setBlock(world, i + 3, j + 43, k + 35, Blocks.leaves, 0);
		this.setBlock(world, i + 3, j + 43, k + 36, Blocks.leaves, 0);
		this.setBlock(world, i + 3, j + 43, k + 37, Blocks.leaves, 0);
		this.setBlock(world, i + 3, j + 43, k + 38, Blocks.leaves, 0);
		this.setBlock(world, i + 4, j + 38, k + 22, Blocks.leaves, 0);
		this.setBlock(world, i + 4, j + 38, k + 25, Blocks.log, 1);
		this.setBlock(world, i + 4, j + 39, k + 19, Blocks.leaves, 0);
		this.setBlock(world, i + 4, j + 39, k + 20, Blocks.leaves, 0);
		this.setBlock(world, i + 4, j + 39, k + 21, Blocks.leaves, 0);
		this.setBlock(world, i + 4, j + 39, k + 22, Blocks.leaves, 0);
		this.setBlock(world, i + 4, j + 39, k + 23, Blocks.leaves, 0);
		this.setBlock(world, i + 4, j + 39, k + 24, Blocks.leaves, 0);
		this.setBlock(world, i + 4, j + 39, k + 25, Blocks.leaves, 0);
		this.setBlock(world, i + 4, j + 39, k + 26, Blocks.leaves, 0);
		this.setBlock(world, i + 4, j + 39, k + 31, Blocks.log, 1);
		this.setBlock(world, i + 4, j + 39, k + 32, Blocks.log, 1);
		this.setBlock(world, i + 4, j + 39, k + 33, Blocks.log, 1);
		this.setBlock(world, i + 4, j + 39, k + 34, Blocks.log, 1);
		this.setBlock(world, i + 4, j + 40, k + 19, Blocks.leaves, 0);
		this.setBlock(world, i + 4, j + 40, k + 20, Blocks.leaves, 0);
		this.setBlock(world, i + 4, j + 40, k + 21, Blocks.leaves, 0);
		this.setBlock(world, i + 4, j + 40, k + 22, Blocks.log, 1);
		this.setBlock(world, i + 4, j + 40, k + 23, Blocks.leaves, 0);
		this.setBlock(world, i + 4, j + 40, k + 24, Blocks.leaves, 0);
		this.setBlock(world, i + 4, j + 40, k + 25, Blocks.leaves, 0);
		this.setBlock(world, i + 4, j + 40, k + 29, Blocks.leaves, 0);
		this.setBlock(world, i + 4, j + 40, k + 30, Blocks.leaves, 0);
		this.setBlock(world, i + 4, j + 40, k + 31, Blocks.log, 1);
		this.setBlock(world, i + 4, j + 40, k + 32, Blocks.log, 1);
		this.setBlock(world, i + 4, j + 40, k + 33, Blocks.log, 1);
		this.setBlock(world, i + 4, j + 40, k + 34, Blocks.log, 1);
		this.setBlock(world, i + 4, j + 40, k + 35, Blocks.leaves, 0);
		this.setBlock(world, i + 4, j + 40, k + 36, Blocks.log, 1);
		this.setBlock(world, i + 4, j + 40, k + 37, Blocks.leaves, 0);
		this.setBlock(world, i + 4, j + 40, k + 38, Blocks.leaves, 0);
		this.setBlock(world, i + 4, j + 41, k + 14, Blocks.leaves, 0);
		this.setBlock(world, i + 4, j + 41, k + 19, Blocks.leaves, 0);
		this.setBlock(world, i + 4, j + 41, k + 20, Blocks.leaves, 0);
		this.setBlock(world, i + 4, j + 41, k + 21, Blocks.log, 1);
		this.setBlock(world, i + 4, j + 41, k + 22, Blocks.log, 1);
		this.setBlock(world, i + 4, j + 41, k + 23, Blocks.log, 1);
		this.setBlock(world, i + 4, j + 41, k + 24, Blocks.leaves, 0);
		this.setBlock(world, i + 4, j + 41, k + 25, Blocks.leaves, 0);
		this.setBlock(world, i + 4, j + 41, k + 29, Blocks.leaves, 0);
		this.setBlock(world, i + 4, j + 41, k + 30, Blocks.leaves, 0);
		this.setBlock(world, i + 4, j + 41, k + 31, Blocks.leaves, 0);
		this.setBlock(world, i + 4, j + 41, k + 32, Blocks.log, 1);
		this.setBlock(world, i + 4, j + 41, k + 33, Blocks.log, 1);
		this.setBlock(world, i + 4, j + 41, k + 34, Blocks.leaves, 0);
		this.setBlock(world, i + 4, j + 41, k + 35, Blocks.leaves, 0);
		this.setBlock(world, i + 4, j + 41, k + 36, Blocks.leaves, 0);
		this.setBlock(world, i + 4, j + 41, k + 37, Blocks.leaves, 0);
		this.setBlock(world, i + 4, j + 41, k + 38, Blocks.leaves, 0);
		this.setBlock(world, i + 4, j + 41, k + 39, Blocks.leaves, 0);
		this.setBlock(world, i + 4, j + 41, k + 40, Blocks.leaves, 0);
		this.setBlock(world, i + 4, j + 42, k + 14, Blocks.leaves, 0);
		this.setBlock(world, i + 4, j + 42, k + 20, Blocks.leaves, 0);
		this.setBlock(world, i + 4, j + 42, k + 21, Blocks.leaves, 0);
		this.setBlock(world, i + 4, j + 42, k + 22, Blocks.log, 1);
		this.setBlock(world, i + 4, j + 42, k + 23, Blocks.leaves, 0);
		this.setBlock(world, i + 4, j + 42, k + 29, Blocks.leaves, 0);
		this.setBlock(world, i + 4, j + 42, k + 30, Blocks.leaves, 0);
		this.setBlock(world, i + 4, j + 42, k + 31, Blocks.leaves, 0);
		this.setBlock(world, i + 4, j + 42, k + 32, Blocks.leaves, 0);
		this.setBlock(world, i + 4, j + 42, k + 33, Blocks.leaves, 0);
		this.setBlock(world, i + 4, j + 42, k + 34, Blocks.leaves, 0);
		this.setBlock(world, i + 4, j + 42, k + 35, Blocks.leaves, 0);
		this.setBlock(world, i + 4, j + 42, k + 36, Blocks.leaves, 0);
		this.setBlock(world, i + 4, j + 42, k + 37, Blocks.leaves, 0);
		this.setBlock(world, i + 4, j + 42, k + 38, Blocks.leaves, 0);
		this.setBlock(world, i + 4, j + 42, k + 39, Blocks.leaves, 0);
		this.setBlock(world, i + 4, j + 42, k + 40, Blocks.leaves, 0);
		this.setBlock(world, i + 4, j + 43, k + 21, Blocks.leaves, 0);
		this.setBlock(world, i + 4, j + 43, k + 22, Blocks.leaves, 0);
		this.setBlock(world, i + 4, j + 43, k + 30, Blocks.leaves, 0);
		this.setBlock(world, i + 4, j + 43, k + 31, Blocks.leaves, 0);
		this.setBlock(world, i + 4, j + 43, k + 32, Blocks.leaves, 0);
		this.setBlock(world, i + 4, j + 43, k + 33, Blocks.leaves, 0);
		this.setBlock(world, i + 4, j + 43, k + 34, Blocks.leaves, 0);
		this.setBlock(world, i + 4, j + 43, k + 35, Blocks.leaves, 0);
		this.setBlock(world, i + 4, j + 43, k + 36, Blocks.leaves, 0);
		this.setBlock(world, i + 4, j + 43, k + 37, Blocks.leaves, 0);
		this.setBlock(world, i + 4, j + 43, k + 38, Blocks.leaves, 0);
		this.setBlock(world, i + 4, j + 43, k + 39, Blocks.leaves, 0);
		this.setBlock(world, i + 4, j + 43, k + 40, Blocks.leaves, 0);
		this.setBlock(world, i + 5, j + 38, k + 20, Blocks.leaves, 0);
		this.setBlock(world, i + 5, j + 39, k + 13, Blocks.leaves, 0);
		this.setBlock(world, i + 5, j + 39, k + 14, Blocks.leaves, 0);
		this.setBlock(world, i + 5, j + 39, k + 16, Blocks.leaves, 0);
		this.setBlock(world, i + 5, j + 39, k + 17, Blocks.leaves, 0);
		this.setBlock(world, i + 5, j + 39, k + 18, Blocks.leaves, 0);
		this.setBlock(world, i + 5, j + 39, k + 19, Blocks.leaves, 0);
		this.setBlock(world, i + 5, j + 39, k + 20, Blocks.leaves, 0);
		this.setBlock(world, i + 5, j + 39, k + 21, Blocks.leaves, 0);
		this.setBlock(world, i + 5, j + 39, k + 22, Blocks.leaves, 0);
		this.setBlock(world, i + 5, j + 39, k + 23, Blocks.leaves, 0);
		this.setBlock(world, i + 5, j + 39, k + 24, Blocks.leaves, 0);
		this.setBlock(world, i + 5, j + 39, k + 25, Blocks.leaves, 0);
		this.setBlock(world, i + 5, j + 39, k + 26, Blocks.leaves, 0);
		this.setBlock(world, i + 5, j + 39, k + 30, Blocks.leaves, 0);
		this.setBlock(world, i + 5, j + 39, k + 31, Blocks.log, 1);
		this.setBlock(world, i + 5, j + 39, k + 32, Blocks.log, 1);
		this.setBlock(world, i + 5, j + 39, k + 33, Blocks.log, 1);
		this.setBlock(world, i + 5, j + 39, k + 34, Blocks.log, 1);
		this.setBlock(world, i + 5, j + 39, k + 38, Blocks.leaves, 0);
		this.setBlock(world, i + 5, j + 39, k + 39, Blocks.leaves, 0);
		this.setBlock(world, i + 5, j + 39, k + 40, Blocks.log, 1);
		this.setBlock(world, i + 5, j + 40, k + 12, Blocks.leaves, 0);
		this.setBlock(world, i + 5, j + 40, k + 13, Blocks.log, 1);
		this.setBlock(world, i + 5, j + 40, k + 14, Blocks.leaves, 0);
		this.setBlock(world, i + 5, j + 40, k + 15, Blocks.log, 1);
		this.setBlock(world, i + 5, j + 40, k + 16, Blocks.log, 1);
		this.setBlock(world, i + 5, j + 40, k + 18, Blocks.leaves, 0);
		this.setBlock(world, i + 5, j + 40, k + 19, Blocks.leaves, 0);
		this.setBlock(world, i + 5, j + 40, k + 20, Blocks.leaves, 0);
		this.setBlock(world, i + 5, j + 40, k + 21, Blocks.leaves, 0);
		this.setBlock(world, i + 5, j + 40, k + 22, Blocks.log, 1);
		this.setBlock(world, i + 5, j + 40, k + 23, Blocks.leaves, 0);
		this.setBlock(world, i + 5, j + 40, k + 24, Blocks.leaves, 0);
		this.setBlock(world, i + 5, j + 40, k + 25, Blocks.leaves, 0);
		this.setBlock(world, i + 5, j + 40, k + 26, Blocks.leaves, 0);
		this.setBlock(world, i + 5, j + 40, k + 27, Blocks.leaves, 0);
		this.setBlock(world, i + 5, j + 40, k + 28, Blocks.log, 1);
		this.setBlock(world, i + 5, j + 40, k + 29, Blocks.leaves, 0);
		this.setBlock(world, i + 5, j + 40, k + 30, Blocks.leaves, 0);
		this.setBlock(world, i + 5, j + 40, k + 31, Blocks.leaves, 0);
		this.setBlock(world, i + 5, j + 40, k + 32, Blocks.log, 1);
		this.setBlock(world, i + 5, j + 40, k + 33, Blocks.log, 1);
		this.setBlock(world, i + 5, j + 40, k + 34, Blocks.leaves, 0);
		this.setBlock(world, i + 5, j + 40, k + 35, Blocks.leaves, 0);
		this.setBlock(world, i + 5, j + 40, k + 36, Blocks.log, 1);
		this.setBlock(world, i + 5, j + 40, k + 37, Blocks.leaves, 0);
		this.setBlock(world, i + 5, j + 40, k + 38, Blocks.leaves, 0);
		this.setBlock(world, i + 5, j + 40, k + 39, Blocks.leaves, 0);
		this.setBlock(world, i + 5, j + 40, k + 40, Blocks.leaves, 0);
		this.setBlock(world, i + 5, j + 41, k + 12, Blocks.leaves, 0);
		this.setBlock(world, i + 5, j + 41, k + 13, Blocks.leaves, 0);
		this.setBlock(world, i + 5, j + 41, k + 14, Blocks.leaves, 0);
		this.setBlock(world, i + 5, j + 41, k + 15, Blocks.log, 1);
		this.setBlock(world, i + 5, j + 41, k + 16, Blocks.leaves, 0);
		this.setBlock(world, i + 5, j + 41, k + 18, Blocks.leaves, 0);
		this.setBlock(world, i + 5, j + 41, k + 19, Blocks.leaves, 0);
		this.setBlock(world, i + 5, j + 41, k + 20, Blocks.leaves, 0);
		this.setBlock(world, i + 5, j + 41, k + 21, Blocks.log, 1);
		this.setBlock(world, i + 5, j + 41, k + 22, Blocks.log, 1);
		this.setBlock(world, i + 5, j + 41, k + 23, Blocks.log, 1);
		this.setBlock(world, i + 5, j + 41, k + 24, Blocks.leaves, 0);
		this.setBlock(world, i + 5, j + 41, k + 25, Blocks.leaves, 0);
		this.setBlock(world, i + 5, j + 41, k + 26, Blocks.leaves, 0);
		this.setBlock(world, i + 5, j + 41, k + 28, Blocks.leaves, 0);
		this.setBlock(world, i + 5, j + 41, k + 29, Blocks.leaves, 0);
		this.setBlock(world, i + 5, j + 41, k + 30, Blocks.leaves, 0);
		this.setBlock(world, i + 5, j + 41, k + 31, Blocks.log, 1);
		this.setBlock(world, i + 5, j + 41, k + 32, Blocks.leaves, 0);
		this.setBlock(world, i + 5, j + 41, k + 33, Blocks.leaves, 0);
		this.setBlock(world, i + 5, j + 41, k + 34, Blocks.leaves, 0);
		this.setBlock(world, i + 5, j + 41, k + 35, Blocks.leaves, 0);
		this.setBlock(world, i + 5, j + 41, k + 36, Blocks.leaves, 0);
		this.setBlock(world, i + 5, j + 41, k + 37, Blocks.leaves, 0);
		this.setBlock(world, i + 5, j + 41, k + 38, Blocks.log, 1);
		this.setBlock(world, i + 5, j + 41, k + 39, Blocks.log, 1);
		this.setBlock(world, i + 5, j + 41, k + 40, Blocks.log, 1);
		this.setBlock(world, i + 5, j + 41, k + 41, Blocks.leaves, 0);
		this.setBlock(world, i + 5, j + 42, k + 12, Blocks.leaves, 0);
		this.setBlock(world, i + 5, j + 42, k + 13, Blocks.log, 1);
		this.setBlock(world, i + 5, j + 42, k + 14, Blocks.leaves, 0);
		this.setBlock(world, i + 5, j + 42, k + 15, Blocks.leaves, 0);
		this.setBlock(world, i + 5, j + 42, k + 20, Blocks.leaves, 0);
		this.setBlock(world, i + 5, j + 42, k + 21, Blocks.leaves, 0);
		this.setBlock(world, i + 5, j + 42, k + 22, Blocks.log, 1);
		this.setBlock(world, i + 5, j + 42, k + 23, Blocks.leaves, 0);
		this.setBlock(world, i + 5, j + 42, k + 29, Blocks.leaves, 0);
		this.setBlock(world, i + 5, j + 42, k + 30, Blocks.log, 1);
		this.setBlock(world, i + 5, j + 42, k + 31, Blocks.leaves, 0);
		this.setBlock(world, i + 5, j + 42, k + 32, Blocks.leaves, 0);
		this.setBlock(world, i + 5, j + 42, k + 33, Blocks.leaves, 0);
		this.setBlock(world, i + 5, j + 42, k + 34, Blocks.leaves, 0);
		this.setBlock(world, i + 5, j + 42, k + 35, Blocks.leaves, 0);
		this.setBlock(world, i + 5, j + 42, k + 36, Blocks.log, 1);
		this.setBlock(world, i + 5, j + 42, k + 37, Blocks.leaves, 0);
		this.setBlock(world, i + 5, j + 42, k + 38, Blocks.leaves, 0);
		this.setBlock(world, i + 5, j + 42, k + 39, Blocks.leaves, 0);
		this.setBlock(world, i + 5, j + 42, k + 40, Blocks.leaves, 0);
		this.setBlock(world, i + 5, j + 42, k + 41, Blocks.log, 1);
		this.setBlock(world, i + 5, j + 43, k + 12, Blocks.leaves, 0);
		this.setBlock(world, i + 5, j + 43, k + 13, Blocks.leaves, 0);
		this.setBlock(world, i + 5, j + 43, k + 14, Blocks.leaves, 0);
		this.setBlock(world, i + 5, j + 43, k + 21, Blocks.leaves, 0);
		this.setBlock(world, i + 5, j + 43, k + 22, Blocks.leaves, 0);
		this.setBlock(world, i + 5, j + 43, k + 29, Blocks.leaves, 0);
		this.setBlock(world, i + 5, j + 43, k + 30, Blocks.leaves, 0);
		this.setBlock(world, i + 5, j + 43, k + 31, Blocks.leaves, 0);
		this.setBlock(world, i + 5, j + 43, k + 32, Blocks.leaves, 0);
		this.setBlock(world, i + 5, j + 43, k + 33, Blocks.leaves, 0);
		this.setBlock(world, i + 5, j + 43, k + 34, Blocks.log, 1);
		this.setBlock(world, i + 5, j + 43, k + 35, Blocks.leaves, 0);
		this.setBlock(world, i + 5, j + 43, k + 36, Blocks.log, 1);
		this.setBlock(world, i + 5, j + 43, k + 37, Blocks.leaves, 0);
		this.setBlock(world, i + 5, j + 43, k + 38, Blocks.leaves, 0);
		this.setBlock(world, i + 5, j + 43, k + 39, Blocks.leaves, 0);
		this.setBlock(world, i + 5, j + 43, k + 40, Blocks.leaves, 0);
		this.setBlock(world, i + 5, j + 43, k + 41, Blocks.leaves, 0);
		this.setBlock(world, i + 5, j + 44, k + 22, Blocks.leaves, 0);
		this.setBlock(world, i + 5, j + 44, k + 32, Blocks.leaves, 0);
		this.setBlock(world, i + 5, j + 44, k + 33, Blocks.leaves, 0);
		this.setBlock(world, i + 5, j + 44, k + 34, Blocks.leaves, 0);
		this.setBlock(world, i + 5, j + 44, k + 35, Blocks.leaves, 0);
		this.setBlock(world, i + 5, j + 44, k + 36, Blocks.leaves, 0);
		this.setBlock(world, i + 5, j + 44, k + 37, Blocks.leaves, 0);
		this.setBlock(world, i + 5, j + 44, k + 38, Blocks.leaves, 0);
		this.setBlock(world, i + 5, j + 44, k + 39, Blocks.leaves, 0);
		this.setBlock(world, i + 5, j + 44, k + 40, Blocks.leaves, 0);
		this.setBlock(world, i + 6, j + 38, k + 16, Blocks.leaves, 0);
		this.setBlock(world, i + 6, j + 38, k + 18, Blocks.leaves, 0);
		this.setBlock(world, i + 6, j + 38, k + 19, Blocks.leaves, 0);
		this.setBlock(world, i + 6, j + 38, k + 20, Blocks.log, 1);
		this.setBlock(world, i + 6, j + 38, k + 32, Blocks.log, 1);
		this.setBlock(world, i + 6, j + 38, k + 33, Blocks.log, 1);
		this.setBlock(world, i + 6, j + 38, k + 34, Blocks.log, 1);
		this.setBlock(world, i + 6, j + 39, k + 12, Blocks.leaves, 0);
		this.setBlock(world, i + 6, j + 39, k + 13, Blocks.leaves, 0);
		this.setBlock(world, i + 6, j + 39, k + 14, Blocks.leaves, 0);
		this.setBlock(world, i + 6, j + 39, k + 15, Blocks.leaves, 0);
		this.setBlock(world, i + 6, j + 39, k + 16, Blocks.leaves, 0);
		this.setBlock(world, i + 6, j + 39, k + 17, Blocks.leaves, 0);
		this.setBlock(world, i + 6, j + 39, k + 18, Blocks.leaves, 0);
		this.setBlock(world, i + 6, j + 39, k + 19, Blocks.leaves, 0);
		this.setBlock(world, i + 6, j + 39, k + 20, Blocks.leaves, 0);
		this.setBlock(world, i + 6, j + 39, k + 21, Blocks.log, 1);
		this.setBlock(world, i + 6, j + 39, k + 22, Blocks.log, 1);
		this.setBlock(world, i + 6, j + 39, k + 23, Blocks.log, 1);
		this.setBlock(world, i + 6, j + 39, k + 24, Blocks.leaves, 0);
		this.setBlock(world, i + 6, j + 39, k + 25, Blocks.leaves, 0);
		this.setBlock(world, i + 6, j + 39, k + 26, Blocks.leaves, 0);
		this.setBlock(world, i + 6, j + 39, k + 30, Blocks.log, 1);
		this.setBlock(world, i + 6, j + 39, k + 31, Blocks.leaves, 0);
		this.setBlock(world, i + 6, j + 39, k + 32, Blocks.log, 1);
		this.setBlock(world, i + 6, j + 39, k + 33, Blocks.log, 1);
		this.setBlock(world, i + 6, j + 39, k + 34, Blocks.log, 1);
		this.setBlock(world, i + 6, j + 39, k + 35, Blocks.leaves, 0);
		this.setBlock(world, i + 6, j + 39, k + 38, Blocks.log, 1);
		this.setBlock(world, i + 6, j + 39, k + 39, Blocks.leaves, 0);
		this.setBlock(world, i + 6, j + 39, k + 40, Blocks.leaves, 0);
		this.setBlock(world, i + 6, j + 40, k + 11, Blocks.leaves, 0);
		this.setBlock(world, i + 6, j + 40, k + 12, Blocks.leaves, 0);
		this.setBlock(world, i + 6, j + 40, k + 13, Blocks.leaves, 0);
		this.setBlock(world, i + 6, j + 40, k + 14, Blocks.leaves, 0);
		this.setBlock(world, i + 6, j + 40, k + 15, Blocks.leaves, 0);
		this.setBlock(world, i + 6, j + 40, k + 16, Blocks.leaves, 0);
		this.setBlock(world, i + 6, j + 40, k + 17, Blocks.leaves, 0);
		this.setBlock(world, i + 6, j + 40, k + 18, Blocks.leaves, 0);
		this.setBlock(world, i + 6, j + 40, k + 19, Blocks.leaves, 0);
		this.setBlock(world, i + 6, j + 40, k + 20, Blocks.log, 1);
		this.setBlock(world, i + 6, j + 40, k + 21, Blocks.log, 1);
		this.setBlock(world, i + 6, j + 40, k + 22, Blocks.log, 1);
		this.setBlock(world, i + 6, j + 40, k + 23, Blocks.log, 1);
		this.setBlock(world, i + 6, j + 40, k + 24, Blocks.leaves, 0);
		this.setBlock(world, i + 6, j + 40, k + 25, Blocks.leaves, 0);
		this.setBlock(world, i + 6, j + 40, k + 26, Blocks.leaves, 0);
		this.setBlock(world, i + 6, j + 40, k + 27, Blocks.log, 1);
		this.setBlock(world, i + 6, j + 40, k + 28, Blocks.log, 1);
		this.setBlock(world, i + 6, j + 40, k + 29, Blocks.leaves, 0);
		this.setBlock(world, i + 6, j + 40, k + 30, Blocks.leaves, 0);
		this.setBlock(world, i + 6, j + 40, k + 31, Blocks.leaves, 0);
		this.setBlock(world, i + 6, j + 40, k + 32, Blocks.leaves, 0);
		this.setBlock(world, i + 6, j + 40, k + 33, Blocks.log, 1);
		this.setBlock(world, i + 6, j + 40, k + 34, Blocks.log, 1);
		this.setBlock(world, i + 6, j + 40, k + 35, Blocks.leaves, 0);
		this.setBlock(world, i + 6, j + 40, k + 36, Blocks.leaves, 0);
		this.setBlock(world, i + 6, j + 40, k + 37, Blocks.leaves, 0);
		this.setBlock(world, i + 6, j + 40, k + 38, Blocks.leaves, 0);
		this.setBlock(world, i + 6, j + 40, k + 39, Blocks.log, 1);
		this.setBlock(world, i + 6, j + 40, k + 40, Blocks.leaves, 0);
		this.setBlock(world, i + 6, j + 40, k + 41, Blocks.leaves, 0);
		this.setBlock(world, i + 6, j + 40, k + 42, Blocks.log, 1);
		this.setBlock(world, i + 6, j + 41, k + 10, Blocks.leaves, 0);
		this.setBlock(world, i + 6, j + 41, k + 11, Blocks.leaves, 0);
		this.setBlock(world, i + 6, j + 41, k + 12, Blocks.leaves, 0);
		this.setBlock(world, i + 6, j + 41, k + 13, Blocks.log, 1);
		this.setBlock(world, i + 6, j + 41, k + 14, Blocks.leaves, 0);
		this.setBlock(world, i + 6, j + 41, k + 15, Blocks.leaves, 0);
		this.setBlock(world, i + 6, j + 41, k + 16, Blocks.leaves, 0);
		this.setBlock(world, i + 6, j + 41, k + 17, Blocks.leaves, 0);
		this.setBlock(world, i + 6, j + 41, k + 18, Blocks.leaves, 0);
		this.setBlock(world, i + 6, j + 41, k + 19, Blocks.leaves, 0);
		this.setBlock(world, i + 6, j + 41, k + 20, Blocks.leaves, 0);
		this.setBlock(world, i + 6, j + 41, k + 21, Blocks.log, 1);
		this.setBlock(world, i + 6, j + 41, k + 22, Blocks.log, 1);
		this.setBlock(world, i + 6, j + 41, k + 23, Blocks.log, 1);
		this.setBlock(world, i + 6, j + 41, k + 24, Blocks.leaves, 0);
		this.setBlock(world, i + 6, j + 41, k + 25, Blocks.leaves, 0);
		this.setBlock(world, i + 6, j + 41, k + 27, Blocks.leaves, 0);
		this.setBlock(world, i + 6, j + 41, k + 28, Blocks.leaves, 0);
		this.setBlock(world, i + 6, j + 41, k + 29, Blocks.leaves, 0);
		this.setBlock(world, i + 6, j + 41, k + 30, Blocks.leaves, 0);
		this.setBlock(world, i + 6, j + 41, k + 31, Blocks.leaves, 0);
		this.setBlock(world, i + 6, j + 41, k + 32, Blocks.leaves, 0);
		this.setBlock(world, i + 6, j + 41, k + 33, Blocks.leaves, 0);
		this.setBlock(world, i + 6, j + 41, k + 34, Blocks.leaves, 0);
		this.setBlock(world, i + 6, j + 41, k + 35, Blocks.log, 1);
		this.setBlock(world, i + 6, j + 41, k + 36, Blocks.leaves, 0);
		this.setBlock(world, i + 6, j + 41, k + 37, Blocks.leaves, 0);
		this.setBlock(world, i + 6, j + 41, k + 38, Blocks.log, 1);
		this.setBlock(world, i + 6, j + 41, k + 39, Blocks.leaves, 0);
		this.setBlock(world, i + 6, j + 41, k + 40, Blocks.leaves, 0);
		this.setBlock(world, i + 6, j + 41, k + 41, Blocks.leaves, 0);
		this.setBlock(world, i + 6, j + 41, k + 42, Blocks.log, 1);
		this.setBlock(world, i + 6, j + 41, k + 43, Blocks.leaves, 0);
		this.setBlock(world, i + 6, j + 42, k + 10, Blocks.leaves, 0);
		this.setBlock(world, i + 6, j + 42, k + 11, Blocks.leaves, 0);
		this.setBlock(world, i + 6, j + 42, k + 12, Blocks.leaves, 0);
		this.setBlock(world, i + 6, j + 42, k + 13, Blocks.leaves, 0);
		this.setBlock(world, i + 6, j + 42, k + 14, Blocks.leaves, 0);
		this.setBlock(world, i + 6, j + 42, k + 15, Blocks.leaves, 0);
		this.setBlock(world, i + 6, j + 42, k + 19, Blocks.leaves, 0);
		this.setBlock(world, i + 6, j + 42, k + 20, Blocks.leaves, 0);
		this.setBlock(world, i + 6, j + 42, k + 21, Blocks.leaves, 0);
		this.setBlock(world, i + 6, j + 42, k + 22, Blocks.log, 1);
		this.setBlock(world, i + 6, j + 42, k + 23, Blocks.leaves, 0);
		this.setBlock(world, i + 6, j + 42, k + 24, Blocks.leaves, 0);
		this.setBlock(world, i + 6, j + 42, k + 28, Blocks.leaves, 0);
		this.setBlock(world, i + 6, j + 42, k + 29, Blocks.leaves, 0);
		this.setBlock(world, i + 6, j + 42, k + 30, Blocks.leaves, 0);
		this.setBlock(world, i + 6, j + 42, k + 31, Blocks.leaves, 0);
		this.setBlock(world, i + 6, j + 42, k + 32, Blocks.leaves, 0);
		this.setBlock(world, i + 6, j + 42, k + 33, Blocks.leaves, 0);
		this.setBlock(world, i + 6, j + 42, k + 34, Blocks.leaves, 0);
		this.setBlock(world, i + 6, j + 42, k + 35, Blocks.log, 1);
		this.setBlock(world, i + 6, j + 42, k + 36, Blocks.leaves, 0);
		this.setBlock(world, i + 6, j + 42, k + 37, Blocks.leaves, 0);
		this.setBlock(world, i + 6, j + 42, k + 38, Blocks.leaves, 0);
		this.setBlock(world, i + 6, j + 42, k + 39, Blocks.leaves, 0);
		this.setBlock(world, i + 6, j + 42, k + 40, Blocks.leaves, 0);
		this.setBlock(world, i + 6, j + 42, k + 41, Blocks.leaves, 0);
		this.setBlock(world, i + 6, j + 42, k + 42, Blocks.leaves, 0);
		this.setBlock(world, i + 6, j + 42, k + 43, Blocks.leaves, 0);
		this.setBlock(world, i + 6, j + 43, k + 10, Blocks.leaves, 0);
		this.setBlock(world, i + 6, j + 43, k + 11, Blocks.leaves, 0);
		this.setBlock(world, i + 6, j + 43, k + 12, Blocks.leaves, 0);
		this.setBlock(world, i + 6, j + 43, k + 13, Blocks.leaves, 0);
		this.setBlock(world, i + 6, j + 43, k + 14, Blocks.leaves, 0);
		this.setBlock(world, i + 6, j + 43, k + 15, Blocks.leaves, 0);
		this.setBlock(world, i + 6, j + 43, k + 21, Blocks.leaves, 0);
		this.setBlock(world, i + 6, j + 43, k + 22, Blocks.leaves, 0);
		this.setBlock(world, i + 6, j + 43, k + 23, Blocks.leaves, 0);
		this.setBlock(world, i + 6, j + 43, k + 29, Blocks.leaves, 0);
		this.setBlock(world, i + 6, j + 43, k + 30, Blocks.leaves, 0);
		this.setBlock(world, i + 6, j + 43, k + 31, Blocks.leaves, 0);
		this.setBlock(world, i + 6, j + 43, k + 32, Blocks.leaves, 0);
		this.setBlock(world, i + 6, j + 43, k + 33, Blocks.leaves, 0);
		this.setBlock(world, i + 6, j + 43, k + 34, Blocks.leaves, 0);
		this.setBlock(world, i + 6, j + 43, k + 35, Blocks.leaves, 0);
		this.setBlock(world, i + 6, j + 43, k + 36, Blocks.leaves, 0);
		this.setBlock(world, i + 6, j + 43, k + 37, Blocks.leaves, 0);
		this.setBlock(world, i + 6, j + 43, k + 38, Blocks.leaves, 0);
		this.setBlock(world, i + 6, j + 43, k + 39, Blocks.log, 1);
		this.setBlock(world, i + 6, j + 43, k + 40, Blocks.leaves, 0);
		this.setBlock(world, i + 6, j + 43, k + 41, Blocks.log, 1);
		this.setBlock(world, i + 6, j + 43, k + 42, Blocks.leaves, 0);
		this.setBlock(world, i + 6, j + 43, k + 43, Blocks.leaves, 0);
		this.setBlock(world, i + 6, j + 44, k + 21, Blocks.leaves, 0);
		this.setBlock(world, i + 6, j + 44, k + 22, Blocks.leaves, 0);
		this.setBlock(world, i + 6, j + 44, k + 23, Blocks.leaves, 0);
		this.setBlock(world, i + 6, j + 44, k + 32, Blocks.leaves, 0);
		this.setBlock(world, i + 6, j + 44, k + 33, Blocks.leaves, 0);
		this.setBlock(world, i + 6, j + 44, k + 34, Blocks.leaves, 0);
		this.setBlock(world, i + 6, j + 44, k + 35, Blocks.leaves, 0);
		this.setBlock(world, i + 6, j + 44, k + 36, Blocks.leaves, 0);
		this.setBlock(world, i + 6, j + 44, k + 37, Blocks.leaves, 0);
		this.setBlock(world, i + 6, j + 44, k + 38, Blocks.leaves, 0);
		this.setBlock(world, i + 6, j + 44, k + 39, Blocks.leaves, 0);
		this.setBlock(world, i + 6, j + 44, k + 40, Blocks.leaves, 0);
		this.setBlock(world, i + 6, j + 44, k + 41, Blocks.leaves, 0);
		this.setBlock(world, i + 6, j + 44, k + 42, Blocks.leaves, 0);
		this.setBlock(world, i + 6, j + 44, k + 43, Blocks.leaves, 0);
		this.setBlock(world, i + 7, j + 37, k + 18, Blocks.leaves, 0);
		this.setBlock(world, i + 7, j + 37, k + 19, Blocks.leaves, 0);
		this.setBlock(world, i + 7, j + 37, k + 33, Blocks.log, 1);
		this.setBlock(world, i + 7, j + 38, k + 15, Blocks.log, 1);
		this.setBlock(world, i + 7, j + 38, k + 16, Blocks.leaves, 0);
		this.setBlock(world, i + 7, j + 38, k + 17, Blocks.leaves, 0);
		this.setBlock(world, i + 7, j + 38, k + 18, Blocks.leaves, 0);
		this.setBlock(world, i + 7, j + 38, k + 19, Blocks.leaves, 0);
		this.setBlock(world, i + 7, j + 38, k + 20, Blocks.log, 1);
		this.setBlock(world, i + 7, j + 38, k + 21, Blocks.leaves, 0);
		this.setBlock(world, i + 7, j + 38, k + 32, Blocks.log, 1);
		this.setBlock(world, i + 7, j + 38, k + 33, Blocks.log, 1);
		this.setBlock(world, i + 7, j + 38, k + 34, Blocks.log, 1);
		this.setBlock(world, i + 7, j + 39, k + 11, Blocks.leaves, 0);
		this.setBlock(world, i + 7, j + 39, k + 12, Blocks.log, 1);
		this.setBlock(world, i + 7, j + 39, k + 13, Blocks.log, 1);
		this.setBlock(world, i + 7, j + 39, k + 14, Blocks.leaves, 0);
		this.setBlock(world, i + 7, j + 39, k + 15, Blocks.leaves, 0);
		this.setBlock(world, i + 7, j + 39, k + 16, Blocks.leaves, 0);
		this.setBlock(world, i + 7, j + 39, k + 17, Blocks.log, 1);
		this.setBlock(world, i + 7, j + 39, k + 18, Blocks.leaves, 0);
		this.setBlock(world, i + 7, j + 39, k + 19, Blocks.leaves, 0);
		this.setBlock(world, i + 7, j + 39, k + 20, Blocks.log, 1);
		this.setBlock(world, i + 7, j + 39, k + 21, Blocks.log, 1);
		this.setBlock(world, i + 7, j + 39, k + 22, Blocks.log, 1);
		this.setBlock(world, i + 7, j + 39, k + 23, Blocks.log, 1);
		this.setBlock(world, i + 7, j + 39, k + 24, Blocks.leaves, 0);
		this.setBlock(world, i + 7, j + 39, k + 25, Blocks.leaves, 0);
		this.setBlock(world, i + 7, j + 39, k + 26, Blocks.leaves, 0);
		this.setBlock(world, i + 7, j + 39, k + 30, Blocks.leaves, 0);
		this.setBlock(world, i + 7, j + 39, k + 31, Blocks.leaves, 0);
		this.setBlock(world, i + 7, j + 39, k + 32, Blocks.leaves, 0);
		this.setBlock(world, i + 7, j + 39, k + 33, Blocks.log, 1);
		this.setBlock(world, i + 7, j + 39, k + 34, Blocks.leaves, 0);
		this.setBlock(world, i + 7, j + 39, k + 35, Blocks.leaves, 0);
		this.setBlock(world, i + 7, j + 39, k + 36, Blocks.leaves, 0);
		this.setBlock(world, i + 7, j + 39, k + 37, Blocks.log, 1);
		this.setBlock(world, i + 7, j + 39, k + 38, Blocks.leaves, 0);
		this.setBlock(world, i + 7, j + 39, k + 39, Blocks.leaves, 0);
		this.setBlock(world, i + 7, j + 39, k + 40, Blocks.leaves, 0);
		this.setBlock(world, i + 7, j + 40, k + 10, Blocks.leaves, 0);
		this.setBlock(world, i + 7, j + 40, k + 11, Blocks.log, 1);
		this.setBlock(world, i + 7, j + 40, k + 12, Blocks.log, 1);
		this.setBlock(world, i + 7, j + 40, k + 13, Blocks.leaves, 0);
		this.setBlock(world, i + 7, j + 40, k + 14, Blocks.leaves, 0);
		this.setBlock(world, i + 7, j + 40, k + 15, Blocks.leaves, 0);
		this.setBlock(world, i + 7, j + 40, k + 16, Blocks.leaves, 0);
		this.setBlock(world, i + 7, j + 40, k + 17, Blocks.leaves, 0);
		this.setBlock(world, i + 7, j + 40, k + 18, Blocks.leaves, 0);
		this.setBlock(world, i + 7, j + 40, k + 19, Blocks.leaves, 0);
		this.setBlock(world, i + 7, j + 40, k + 20, Blocks.log, 1);
		this.setBlock(world, i + 7, j + 40, k + 21, Blocks.log, 1);
		this.setBlock(world, i + 7, j + 40, k + 22, Blocks.log, 1);
		this.setBlock(world, i + 7, j + 40, k + 23, Blocks.log, 1);
		this.setBlock(world, i + 7, j + 40, k + 24, Blocks.leaves, 0);
		this.setBlock(world, i + 7, j + 40, k + 25, Blocks.leaves, 0);
		this.setBlock(world, i + 7, j + 40, k + 26, Blocks.leaves, 0);
		this.setBlock(world, i + 7, j + 40, k + 27, Blocks.leaves, 0);
		this.setBlock(world, i + 7, j + 40, k + 28, Blocks.leaves, 0);
		this.setBlock(world, i + 7, j + 40, k + 29, Blocks.leaves, 0);
		this.setBlock(world, i + 7, j + 40, k + 30, Blocks.leaves, 0);
		this.setBlock(world, i + 7, j + 40, k + 31, Blocks.leaves, 0);
		this.setBlock(world, i + 7, j + 40, k + 32, Blocks.leaves, 0);
		this.setBlock(world, i + 7, j + 40, k + 33, Blocks.leaves, 0);
		this.setBlock(world, i + 7, j + 40, k + 34, Blocks.leaves, 0);
		this.setBlock(world, i + 7, j + 40, k + 35, Blocks.leaves, 0);
		this.setBlock(world, i + 7, j + 40, k + 36, Blocks.leaves, 0);
		this.setBlock(world, i + 7, j + 40, k + 37, Blocks.log, 1);
		this.setBlock(world, i + 7, j + 40, k + 38, Blocks.log, 1);
		this.setBlock(world, i + 7, j + 40, k + 39, Blocks.leaves, 0);
		this.setBlock(world, i + 7, j + 40, k + 40, Blocks.leaves, 0);
		this.setBlock(world, i + 7, j + 40, k + 41, Blocks.leaves, 0);
		this.setBlock(world, i + 7, j + 40, k + 42, Blocks.log, 1);
		this.setBlock(world, i + 7, j + 40, k + 43, Blocks.leaves, 0);
		this.setBlock(world, i + 7, j + 41, k + 9, Blocks.leaves, 0);
		this.setBlock(world, i + 7, j + 41, k + 10, Blocks.log, 1);
		this.setBlock(world, i + 7, j + 41, k + 11, Blocks.leaves, 0);
		this.setBlock(world, i + 7, j + 41, k + 12, Blocks.leaves, 0);
		this.setBlock(world, i + 7, j + 41, k + 13, Blocks.leaves, 0);
		this.setBlock(world, i + 7, j + 41, k + 14, Blocks.leaves, 0);
		this.setBlock(world, i + 7, j + 41, k + 15, Blocks.log, 1);
		this.setBlock(world, i + 7, j + 41, k + 16, Blocks.log, 1);
		this.setBlock(world, i + 7, j + 41, k + 17, Blocks.leaves, 0);
		this.setBlock(world, i + 7, j + 41, k + 18, Blocks.leaves, 0);
		this.setBlock(world, i + 7, j + 41, k + 19, Blocks.leaves, 0);
		this.setBlock(world, i + 7, j + 41, k + 20, Blocks.leaves, 0);
		this.setBlock(world, i + 7, j + 41, k + 21, Blocks.leaves, 0);
		this.setBlock(world, i + 7, j + 41, k + 22, Blocks.log, 1);
		this.setBlock(world, i + 7, j + 41, k + 23, Blocks.log, 1);
		this.setBlock(world, i + 7, j + 41, k + 24, Blocks.leaves, 0);
		this.setBlock(world, i + 7, j + 41, k + 25, Blocks.leaves, 0);
		this.setBlock(world, i + 7, j + 41, k + 26, Blocks.leaves, 0);
		this.setBlock(world, i + 7, j + 41, k + 27, Blocks.leaves, 0);
		this.setBlock(world, i + 7, j + 41, k + 28, Blocks.leaves, 0);
		this.setBlock(world, i + 7, j + 41, k + 29, Blocks.leaves, 0);
		this.setBlock(world, i + 7, j + 41, k + 30, Blocks.leaves, 0);
		this.setBlock(world, i + 7, j + 41, k + 31, Blocks.leaves, 0);
		this.setBlock(world, i + 7, j + 41, k + 32, Blocks.leaves, 0);
		this.setBlock(world, i + 7, j + 41, k + 33, Blocks.leaves, 0);
		this.setBlock(world, i + 7, j + 41, k + 34, Blocks.leaves, 0);
		this.setBlock(world, i + 7, j + 41, k + 35, Blocks.leaves, 0);
		this.setBlock(world, i + 7, j + 41, k + 36, Blocks.leaves, 0);
		this.setBlock(world, i + 7, j + 41, k + 37, Blocks.log, 1);
		this.setBlock(world, i + 7, j + 41, k + 38, Blocks.log, 1);
		this.setBlock(world, i + 7, j + 41, k + 39, Blocks.leaves, 0);
		this.setBlock(world, i + 7, j + 41, k + 40, Blocks.leaves, 0);
		this.setBlock(world, i + 7, j + 41, k + 41, Blocks.leaves, 0);
		this.setBlock(world, i + 7, j + 41, k + 42, Blocks.leaves, 0);
		this.setBlock(world, i + 7, j + 41, k + 43, Blocks.leaves, 0);
		this.setBlock(world, i + 7, j + 42, k + 10, Blocks.leaves, 0);
		this.setBlock(world, i + 7, j + 42, k + 11, Blocks.log, 1);
		this.setBlock(world, i + 7, j + 42, k + 12, Blocks.log, 1);
		this.setBlock(world, i + 7, j + 42, k + 13, Blocks.leaves, 0);
		this.setBlock(world, i + 7, j + 42, k + 14, Blocks.log, 1);
		this.setBlock(world, i + 7, j + 42, k + 15, Blocks.leaves, 0);
		this.setBlock(world, i + 7, j + 42, k + 16, Blocks.leaves, 0);
		this.setBlock(world, i + 7, j + 42, k + 17, Blocks.leaves, 0);
		this.setBlock(world, i + 7, j + 42, k + 19, Blocks.leaves, 0);
		this.setBlock(world, i + 7, j + 42, k + 20, Blocks.leaves, 0);
		this.setBlock(world, i + 7, j + 42, k + 21, Blocks.leaves, 0);
		this.setBlock(world, i + 7, j + 42, k + 22, Blocks.log, 1);
		this.setBlock(world, i + 7, j + 42, k + 23, Blocks.leaves, 0);
		this.setBlock(world, i + 7, j + 42, k + 24, Blocks.leaves, 0);
		this.setBlock(world, i + 7, j + 42, k + 28, Blocks.leaves, 0);
		this.setBlock(world, i + 7, j + 42, k + 29, Blocks.log, 1);
		this.setBlock(world, i + 7, j + 42, k + 30, Blocks.leaves, 0);
		this.setBlock(world, i + 7, j + 42, k + 31, Blocks.leaves, 0);
		this.setBlock(world, i + 7, j + 42, k + 32, Blocks.leaves, 0);
		this.setBlock(world, i + 7, j + 42, k + 33, Blocks.leaves, 0);
		this.setBlock(world, i + 7, j + 42, k + 34, Blocks.leaves, 0);
		this.setBlock(world, i + 7, j + 42, k + 35, Blocks.leaves, 0);
		this.setBlock(world, i + 7, j + 42, k + 36, Blocks.leaves, 0);
		this.setBlock(world, i + 7, j + 42, k + 37, Blocks.leaves, 0);
		this.setBlock(world, i + 7, j + 42, k + 38, Blocks.log, 1);
		this.setBlock(world, i + 7, j + 42, k + 39, Blocks.leaves, 0);
		this.setBlock(world, i + 7, j + 42, k + 40, Blocks.leaves, 0);
		this.setBlock(world, i + 7, j + 42, k + 41, Blocks.leaves, 0);
		this.setBlock(world, i + 7, j + 42, k + 42, Blocks.leaves, 0);
		this.setBlock(world, i + 7, j + 42, k + 43, Blocks.leaves, 0);
		this.setBlock(world, i + 7, j + 43, k + 10, Blocks.leaves, 0);
		this.setBlock(world, i + 7, j + 43, k + 11, Blocks.leaves, 0);
		this.setBlock(world, i + 7, j + 43, k + 12, Blocks.leaves, 0);
		this.setBlock(world, i + 7, j + 43, k + 13, Blocks.leaves, 0);
		this.setBlock(world, i + 7, j + 43, k + 14, Blocks.leaves, 0);
		this.setBlock(world, i + 7, j + 43, k + 15, Blocks.leaves, 0);
		this.setBlock(world, i + 7, j + 43, k + 16, Blocks.leaves, 0);
		this.setBlock(world, i + 7, j + 43, k + 20, Blocks.leaves, 0);
		this.setBlock(world, i + 7, j + 43, k + 21, Blocks.leaves, 0);
		this.setBlock(world, i + 7, j + 43, k + 22, Blocks.log, 1);
		this.setBlock(world, i + 7, j + 43, k + 23, Blocks.log, 1);
		this.setBlock(world, i + 7, j + 43, k + 24, Blocks.leaves, 0);
		this.setBlock(world, i + 7, j + 43, k + 28, Blocks.leaves, 0);
		this.setBlock(world, i + 7, j + 43, k + 29, Blocks.leaves, 0);
		this.setBlock(world, i + 7, j + 43, k + 30, Blocks.leaves, 0);
		this.setBlock(world, i + 7, j + 43, k + 31, Blocks.leaves, 0);
		this.setBlock(world, i + 7, j + 43, k + 32, Blocks.leaves, 0);
		this.setBlock(world, i + 7, j + 43, k + 33, Blocks.log, 1);
		this.setBlock(world, i + 7, j + 43, k + 34, Blocks.leaves, 0);
		this.setBlock(world, i + 7, j + 43, k + 35, Blocks.leaves, 0);
		this.setBlock(world, i + 7, j + 43, k + 36, Blocks.leaves, 0);
		this.setBlock(world, i + 7, j + 43, k + 37, Blocks.leaves, 0);
		this.setBlock(world, i + 7, j + 43, k + 38, Blocks.leaves, 0);
		this.setBlock(world, i + 7, j + 43, k + 39, Blocks.leaves, 0);
		this.setBlock(world, i + 7, j + 43, k + 40, Blocks.leaves, 0);
		this.setBlock(world, i + 7, j + 43, k + 41, Blocks.leaves, 0);
		this.setBlock(world, i + 7, j + 43, k + 42, Blocks.leaves, 0);
		this.setBlock(world, i + 7, j + 43, k + 43, Blocks.leaves, 0);
		this.setBlock(world, i + 7, j + 44, k + 21, Blocks.leaves, 0);
		this.setBlock(world, i + 7, j + 44, k + 22, Blocks.leaves, 0);
		this.setBlock(world, i + 7, j + 44, k + 23, Blocks.leaves, 0);
		this.setBlock(world, i + 7, j + 44, k + 32, Blocks.leaves, 0);
		this.setBlock(world, i + 7, j + 44, k + 33, Blocks.leaves, 0);
		this.setBlock(world, i + 7, j + 44, k + 34, Blocks.leaves, 0);
		this.setBlock(world, i + 7, j + 44, k + 35, Blocks.leaves, 0);
		this.setBlock(world, i + 7, j + 44, k + 36, Blocks.leaves, 0);
		this.setBlock(world, i + 7, j + 44, k + 37, Blocks.leaves, 0);
		this.setBlock(world, i + 7, j + 44, k + 38, Blocks.leaves, 0);
		this.setBlock(world, i + 7, j + 44, k + 39, Blocks.leaves, 0);
		this.setBlock(world, i + 7, j + 44, k + 40, Blocks.leaves, 0);
		this.setBlock(world, i + 7, j + 44, k + 41, Blocks.leaves, 0);
		this.setBlock(world, i + 7, j + 44, k + 42, Blocks.leaves, 0);
		this.setBlock(world, i + 7, j + 44, k + 43, Blocks.leaves, 0);
		this.setBlock(world, i + 8, j + 37, k + 17, Blocks.leaves, 0);
		this.setBlock(world, i + 8, j + 37, k + 18, Blocks.leaves, 0);
		this.setBlock(world, i + 8, j + 37, k + 19, Blocks.leaves, 0);
		this.setBlock(world, i + 8, j + 37, k + 20, Blocks.leaves, 0);
		this.setBlock(world, i + 8, j + 37, k + 33, Blocks.log, 1);
		this.setBlock(world, i + 8, j + 38, k + 13, Blocks.leaves, 0);
		this.setBlock(world, i + 8, j + 38, k + 14, Blocks.leaves, 0);
		this.setBlock(world, i + 8, j + 38, k + 15, Blocks.leaves, 0);
		this.setBlock(world, i + 8, j + 38, k + 16, Blocks.leaves, 0);
		this.setBlock(world, i + 8, j + 38, k + 17, Blocks.leaves, 0);
		this.setBlock(world, i + 8, j + 38, k + 18, Blocks.leaves, 0);
		this.setBlock(world, i + 8, j + 38, k + 19, Blocks.leaves, 0);
		this.setBlock(world, i + 8, j + 38, k + 20, Blocks.leaves, 0);
		this.setBlock(world, i + 8, j + 38, k + 21, Blocks.leaves, 0);
		this.setBlock(world, i + 8, j + 38, k + 22, Blocks.log, 1);
		this.setBlock(world, i + 8, j + 38, k + 23, Blocks.log, 1);
		this.setBlock(world, i + 8, j + 38, k + 24, Blocks.leaves, 0);
		this.setBlock(world, i + 8, j + 38, k + 32, Blocks.log, 1);
		this.setBlock(world, i + 8, j + 38, k + 33, Blocks.log, 1);
		this.setBlock(world, i + 8, j + 38, k + 34, Blocks.log, 1);
		this.setBlock(world, i + 8, j + 38, k + 35, Blocks.leaves, 0);
		this.setBlock(world, i + 8, j + 38, k + 36, Blocks.log, 1);
		this.setBlock(world, i + 8, j + 39, k + 11, Blocks.leaves, 0);
		this.setBlock(world, i + 8, j + 39, k + 12, Blocks.log, 1);
		this.setBlock(world, i + 8, j + 39, k + 13, Blocks.leaves, 0);
		this.setBlock(world, i + 8, j + 39, k + 14, Blocks.leaves, 0);
		this.setBlock(world, i + 8, j + 39, k + 15, Blocks.leaves, 0);
		this.setBlock(world, i + 8, j + 39, k + 16, Blocks.log, 1);
		this.setBlock(world, i + 8, j + 39, k + 17, Blocks.leaves, 0);
		this.setBlock(world, i + 8, j + 39, k + 18, Blocks.leaves, 0);
		this.setBlock(world, i + 8, j + 39, k + 19, Blocks.leaves, 0);
		this.setBlock(world, i + 8, j + 39, k + 20, Blocks.leaves, 0);
		this.setBlock(world, i + 8, j + 39, k + 21, Blocks.log, 1);
		this.setBlock(world, i + 8, j + 39, k + 22, Blocks.log, 1);
		this.setBlock(world, i + 8, j + 39, k + 23, Blocks.log, 1);
		this.setBlock(world, i + 8, j + 39, k + 24, Blocks.leaves, 0);
		this.setBlock(world, i + 8, j + 39, k + 25, Blocks.leaves, 0);
		this.setBlock(world, i + 8, j + 39, k + 26, Blocks.leaves, 0);
		this.setBlock(world, i + 8, j + 39, k + 27, Blocks.leaves, 0);
		this.setBlock(world, i + 8, j + 39, k + 28, Blocks.leaves, 0);
		this.setBlock(world, i + 8, j + 39, k + 29, Blocks.leaves, 0);
		this.setBlock(world, i + 8, j + 39, k + 30, Blocks.leaves, 0);
		this.setBlock(world, i + 8, j + 39, k + 31, Blocks.leaves, 0);
		this.setBlock(world, i + 8, j + 39, k + 32, Blocks.leaves, 0);
		this.setBlock(world, i + 8, j + 39, k + 33, Blocks.log, 1);
		this.setBlock(world, i + 8, j + 39, k + 34, Blocks.leaves, 0);
		this.setBlock(world, i + 8, j + 39, k + 35, Blocks.leaves, 0);
		this.setBlock(world, i + 8, j + 39, k + 36, Blocks.leaves, 0);
		this.setBlock(world, i + 8, j + 39, k + 37, Blocks.log, 1);
		this.setBlock(world, i + 8, j + 39, k + 38, Blocks.log, 1);
		this.setBlock(world, i + 8, j + 39, k + 39, Blocks.leaves, 0);
		this.setBlock(world, i + 8, j + 40, k + 10, Blocks.leaves, 0);
		this.setBlock(world, i + 8, j + 40, k + 11, Blocks.leaves, 0);
		this.setBlock(world, i + 8, j + 40, k + 12, Blocks.leaves, 0);
		this.setBlock(world, i + 8, j + 40, k + 13, Blocks.leaves, 0);
		this.setBlock(world, i + 8, j + 40, k + 14, Blocks.leaves, 0);
		this.setBlock(world, i + 8, j + 40, k + 15, Blocks.leaves, 0);
		this.setBlock(world, i + 8, j + 40, k + 16, Blocks.leaves, 0);
		this.setBlock(world, i + 8, j + 40, k + 17, Blocks.leaves, 0);
		this.setBlock(world, i + 8, j + 40, k + 18, Blocks.leaves, 0);
		this.setBlock(world, i + 8, j + 40, k + 19, Blocks.leaves, 0);
		this.setBlock(world, i + 8, j + 40, k + 20, Blocks.leaves, 0);
		this.setBlock(world, i + 8, j + 40, k + 21, Blocks.leaves, 0);
		this.setBlock(world, i + 8, j + 40, k + 22, Blocks.log, 1);
		this.setBlock(world, i + 8, j + 40, k + 23, Blocks.leaves, 0);
		this.setBlock(world, i + 8, j + 40, k + 24, Blocks.leaves, 0);
		this.setBlock(world, i + 8, j + 40, k + 25, Blocks.leaves, 0);
		this.setBlock(world, i + 8, j + 40, k + 26, Blocks.leaves, 0);
		this.setBlock(world, i + 8, j + 40, k + 27, Blocks.leaves, 0);
		this.setBlock(world, i + 8, j + 40, k + 28, Blocks.leaves, 0);
		this.setBlock(world, i + 8, j + 40, k + 29, Blocks.leaves, 0);
		this.setBlock(world, i + 8, j + 40, k + 30, Blocks.leaves, 0);
		this.setBlock(world, i + 8, j + 40, k + 31, Blocks.leaves, 0);
		this.setBlock(world, i + 8, j + 40, k + 32, Blocks.leaves, 0);
		this.setBlock(world, i + 8, j + 40, k + 33, Blocks.leaves, 0);
		this.setBlock(world, i + 8, j + 40, k + 34, Blocks.leaves, 0);
		this.setBlock(world, i + 8, j + 40, k + 35, Blocks.leaves, 0);
		this.setBlock(world, i + 8, j + 40, k + 36, Blocks.log, 1);
		this.setBlock(world, i + 8, j + 40, k + 37, Blocks.log, 1);
		this.setBlock(world, i + 8, j + 40, k + 38, Blocks.log, 1);
		this.setBlock(world, i + 8, j + 40, k + 39, Blocks.leaves, 0);
		this.setBlock(world, i + 8, j + 40, k + 40, Blocks.leaves, 0);
		this.setBlock(world, i + 8, j + 40, k + 41, Blocks.leaves, 0);
		this.setBlock(world, i + 8, j + 40, k + 42, Blocks.leaves, 0);
		this.setBlock(world, i + 8, j + 40, k + 43, Blocks.leaves, 0);
		this.setBlock(world, i + 8, j + 41, k + 9, Blocks.leaves, 0);
		this.setBlock(world, i + 8, j + 41, k + 10, Blocks.leaves, 0);
		this.setBlock(world, i + 8, j + 41, k + 11, Blocks.leaves, 0);
		this.setBlock(world, i + 8, j + 41, k + 12, Blocks.leaves, 0);
		this.setBlock(world, i + 8, j + 41, k + 13, Blocks.leaves, 0);
		this.setBlock(world, i + 8, j + 41, k + 14, Blocks.leaves, 0);
		this.setBlock(world, i + 8, j + 41, k + 15, Blocks.leaves, 0);
		this.setBlock(world, i + 8, j + 41, k + 16, Blocks.leaves, 0);
		this.setBlock(world, i + 8, j + 41, k + 17, Blocks.log, 1);
		this.setBlock(world, i + 8, j + 41, k + 18, Blocks.leaves, 0);
		this.setBlock(world, i + 8, j + 41, k + 19, Blocks.log, 1);
		this.setBlock(world, i + 8, j + 41, k + 20, Blocks.leaves, 0);
		this.setBlock(world, i + 8, j + 41, k + 21, Blocks.leaves, 0);
		this.setBlock(world, i + 8, j + 41, k + 22, Blocks.leaves, 0);
		this.setBlock(world, i + 8, j + 41, k + 23, Blocks.leaves, 0);
		this.setBlock(world, i + 8, j + 41, k + 24, Blocks.leaves, 0);
		this.setBlock(world, i + 8, j + 41, k + 25, Blocks.leaves, 0);
		this.setBlock(world, i + 8, j + 41, k + 26, Blocks.leaves, 0);
		this.setBlock(world, i + 8, j + 41, k + 27, Blocks.log, 1);
		this.setBlock(world, i + 8, j + 41, k + 28, Blocks.leaves, 0);
		this.setBlock(world, i + 8, j + 41, k + 29, Blocks.leaves, 0);
		this.setBlock(world, i + 8, j + 41, k + 30, Blocks.leaves, 0);
		this.setBlock(world, i + 8, j + 41, k + 31, Blocks.leaves, 0);
		this.setBlock(world, i + 8, j + 41, k + 32, Blocks.leaves, 0);
		this.setBlock(world, i + 8, j + 41, k + 33, Blocks.leaves, 0);
		this.setBlock(world, i + 8, j + 41, k + 34, Blocks.leaves, 0);
		this.setBlock(world, i + 8, j + 41, k + 35, Blocks.leaves, 0);
		this.setBlock(world, i + 8, j + 41, k + 36, Blocks.leaves, 0);
		this.setBlock(world, i + 8, j + 41, k + 37, Blocks.log, 1);
		this.setBlock(world, i + 8, j + 41, k + 38, Blocks.log, 1);
		this.setBlock(world, i + 8, j + 41, k + 39, Blocks.leaves, 0);
		this.setBlock(world, i + 8, j + 41, k + 40, Blocks.leaves, 0);
		this.setBlock(world, i + 8, j + 41, k + 41, Blocks.leaves, 0);
		this.setBlock(world, i + 8, j + 41, k + 42, Blocks.log, 1);
		this.setBlock(world, i + 8, j + 41, k + 43, Blocks.leaves, 0);
		this.setBlock(world, i + 8, j + 42, k + 10, Blocks.leaves, 0);
		this.setBlock(world, i + 8, j + 42, k + 11, Blocks.log, 1);
		this.setBlock(world, i + 8, j + 42, k + 12, Blocks.leaves, 0);
		this.setBlock(world, i + 8, j + 42, k + 13, Blocks.leaves, 0);
		this.setBlock(world, i + 8, j + 42, k + 14, Blocks.leaves, 0);
		this.setBlock(world, i + 8, j + 42, k + 15, Blocks.log, 1);
		this.setBlock(world, i + 8, j + 42, k + 16, Blocks.log, 1);
		this.setBlock(world, i + 8, j + 42, k + 17, Blocks.leaves, 0);
		this.setBlock(world, i + 8, j + 42, k + 18, Blocks.leaves, 0);
		this.setBlock(world, i + 8, j + 42, k + 19, Blocks.leaves, 0);
		this.setBlock(world, i + 8, j + 42, k + 20, Blocks.leaves, 0);
		this.setBlock(world, i + 8, j + 42, k + 21, Blocks.leaves, 0);
		this.setBlock(world, i + 8, j + 42, k + 22, Blocks.leaves, 0);
		this.setBlock(world, i + 8, j + 42, k + 23, Blocks.leaves, 0);
		this.setBlock(world, i + 8, j + 42, k + 24, Blocks.leaves, 0);
		this.setBlock(world, i + 8, j + 42, k + 25, Blocks.leaves, 0);
		this.setBlock(world, i + 8, j + 42, k + 26, Blocks.leaves, 0);
		this.setBlock(world, i + 8, j + 42, k + 27, Blocks.leaves, 0);
		this.setBlock(world, i + 8, j + 42, k + 28, Blocks.leaves, 0);
		this.setBlock(world, i + 8, j + 42, k + 29, Blocks.leaves, 0);
		this.setBlock(world, i + 8, j + 42, k + 30, Blocks.leaves, 0);
		this.setBlock(world, i + 8, j + 42, k + 31, Blocks.leaves, 0);
		this.setBlock(world, i + 8, j + 42, k + 32, Blocks.leaves, 0);
		this.setBlock(world, i + 8, j + 42, k + 33, Blocks.leaves, 0);
		this.setBlock(world, i + 8, j + 42, k + 34, Blocks.log, 1);
		this.setBlock(world, i + 8, j + 42, k + 35, Blocks.leaves, 0);
		this.setBlock(world, i + 8, j + 42, k + 36, Blocks.leaves, 0);
		this.setBlock(world, i + 8, j + 42, k + 37, Blocks.leaves, 0);
		this.setBlock(world, i + 8, j + 42, k + 38, Blocks.leaves, 0);
		this.setBlock(world, i + 8, j + 42, k + 39, Blocks.leaves, 0);
		this.setBlock(world, i + 8, j + 42, k + 40, Blocks.leaves, 0);
		this.setBlock(world, i + 8, j + 42, k + 41, Blocks.leaves, 0);
		this.setBlock(world, i + 8, j + 42, k + 42, Blocks.leaves, 0);
		this.setBlock(world, i + 8, j + 42, k + 43, Blocks.leaves, 0);
		this.setBlock(world, i + 8, j + 43, k + 11, Blocks.leaves, 0);
		this.setBlock(world, i + 8, j + 43, k + 12, Blocks.leaves, 0);
		this.setBlock(world, i + 8, j + 43, k + 13, Blocks.leaves, 0);
		this.setBlock(world, i + 8, j + 43, k + 14, Blocks.leaves, 0);
		this.setBlock(world, i + 8, j + 43, k + 15, Blocks.leaves, 0);
		this.setBlock(world, i + 8, j + 43, k + 16, Blocks.leaves, 0);
		this.setBlock(world, i + 8, j + 43, k + 20, Blocks.leaves, 0);
		this.setBlock(world, i + 8, j + 43, k + 21, Blocks.leaves, 0);
		this.setBlock(world, i + 8, j + 43, k + 22, Blocks.leaves, 0);
		this.setBlock(world, i + 8, j + 43, k + 23, Blocks.leaves, 0);
		this.setBlock(world, i + 8, j + 43, k + 24, Blocks.leaves, 0);
		this.setBlock(world, i + 8, j + 43, k + 25, Blocks.leaves, 0);
		this.setBlock(world, i + 8, j + 43, k + 27, Blocks.leaves, 0);
		this.setBlock(world, i + 8, j + 43, k + 28, Blocks.leaves, 0);
		this.setBlock(world, i + 8, j + 43, k + 29, Blocks.leaves, 0);
		this.setBlock(world, i + 8, j + 43, k + 30, Blocks.leaves, 0);
		this.setBlock(world, i + 8, j + 43, k + 31, Blocks.leaves, 0);
		this.setBlock(world, i + 8, j + 43, k + 32, Blocks.leaves, 0);
		this.setBlock(world, i + 8, j + 43, k + 33, Blocks.leaves, 0);
		this.setBlock(world, i + 8, j + 43, k + 34, Blocks.leaves, 0);
		this.setBlock(world, i + 8, j + 43, k + 35, Blocks.leaves, 0);
		this.setBlock(world, i + 8, j + 43, k + 36, Blocks.leaves, 0);
		this.setBlock(world, i + 8, j + 43, k + 37, Blocks.log, 1);
		this.setBlock(world, i + 8, j + 43, k + 38, Blocks.leaves, 0);
		this.setBlock(world, i + 8, j + 43, k + 39, Blocks.leaves, 0);
		this.setBlock(world, i + 8, j + 43, k + 40, Blocks.leaves, 0);
		this.setBlock(world, i + 8, j + 43, k + 41, Blocks.leaves, 0);
		this.setBlock(world, i + 8, j + 43, k + 42, Blocks.leaves, 0);
		this.setBlock(world, i + 8, j + 43, k + 43, Blocks.log, 1);
		this.setBlock(world, i + 8, j + 44, k + 20, Blocks.leaves, 0);
		this.setBlock(world, i + 8, j + 44, k + 21, Blocks.leaves, 0);
		this.setBlock(world, i + 8, j + 44, k + 22, Blocks.leaves, 0);
		this.setBlock(world, i + 8, j + 44, k + 23, Blocks.leaves, 0);
		this.setBlock(world, i + 8, j + 44, k + 24, Blocks.leaves, 0);
		this.setBlock(world, i + 8, j + 44, k + 32, Blocks.leaves, 0);
		this.setBlock(world, i + 8, j + 44, k + 33, Blocks.leaves, 0);
		this.setBlock(world, i + 8, j + 44, k + 34, Blocks.leaves, 0);
		this.setBlock(world, i + 8, j + 44, k + 35, Blocks.leaves, 0);
		this.setBlock(world, i + 8, j + 44, k + 36, Blocks.leaves, 0);
		this.setBlock(world, i + 8, j + 44, k + 37, Blocks.leaves, 0);
		this.setBlock(world, i + 8, j + 44, k + 38, Blocks.leaves, 0);
		this.setBlock(world, i + 8, j + 44, k + 39, Blocks.leaves, 0);
		this.setBlock(world, i + 8, j + 44, k + 40, Blocks.leaves, 0);
		this.setBlock(world, i + 8, j + 44, k + 41, Blocks.leaves, 0);
		this.setBlock(world, i + 8, j + 44, k + 42, Blocks.leaves, 0);
		this.setBlock(world, i + 8, j + 44, k + 43, Blocks.leaves, 0);
		this.setBlock(world, i + 9, j + 36, k + 19, Blocks.leaves, 0);
		this.setBlock(world, i + 9, j + 36, k + 20, Blocks.leaves, 0);
		this.setBlock(world, i + 9, j + 36, k + 21, Blocks.log, 1);
		this.setBlock(world, i + 9, j + 36, k + 33, Blocks.log, 1);
		this.setBlock(world, i + 9, j + 37, k + 16, Blocks.leaves, 0);
		this.setBlock(world, i + 9, j + 37, k + 18, Blocks.leaves, 0);
		this.setBlock(world, i + 9, j + 37, k + 19, Blocks.leaves, 0);
		this.setBlock(world, i + 9, j + 37, k + 20, Blocks.leaves, 0);
		this.setBlock(world, i + 9, j + 37, k + 21, Blocks.log, 1);
		this.setBlock(world, i + 9, j + 37, k + 22, Blocks.log, 1);
		this.setBlock(world, i + 9, j + 37, k + 23, Blocks.log, 1);
		this.setBlock(world, i + 9, j + 37, k + 32, Blocks.log, 1);
		this.setBlock(world, i + 9, j + 37, k + 33, Blocks.log, 1);
		this.setBlock(world, i + 9, j + 37, k + 34, Blocks.log, 1);
		this.setBlock(world, i + 9, j + 38, k + 13, Blocks.leaves, 0);
		this.setBlock(world, i + 9, j + 38, k + 15, Blocks.log, 1);
		this.setBlock(world, i + 9, j + 38, k + 16, Blocks.leaves, 0);
		this.setBlock(world, i + 9, j + 38, k + 17, Blocks.leaves, 0);
		this.setBlock(world, i + 9, j + 38, k + 18, Blocks.leaves, 0);
		this.setBlock(world, i + 9, j + 38, k + 19, Blocks.log, 1);
		this.setBlock(world, i + 9, j + 38, k + 20, Blocks.leaves, 0);
		this.setBlock(world, i + 9, j + 38, k + 21, Blocks.log, 1);
		this.setBlock(world, i + 9, j + 38, k + 22, Blocks.log, 1);
		this.setBlock(world, i + 9, j + 38, k + 23, Blocks.log, 1);
		this.setBlock(world, i + 9, j + 38, k + 24, Blocks.leaves, 0);
		this.setBlock(world, i + 9, j + 38, k + 28, Blocks.leaves, 0);
		this.setBlock(world, i + 9, j + 38, k + 29, Blocks.log, 1);
		this.setBlock(world, i + 9, j + 38, k + 30, Blocks.leaves, 0);
		this.setBlock(world, i + 9, j + 38, k + 31, Blocks.leaves, 0);
		this.setBlock(world, i + 9, j + 38, k + 32, Blocks.log, 1);
		this.setBlock(world, i + 9, j + 38, k + 33, Blocks.log, 1);
		this.setBlock(world, i + 9, j + 38, k + 34, Blocks.log, 1);
		this.setBlock(world, i + 9, j + 38, k + 35, Blocks.log, 1);
		this.setBlock(world, i + 9, j + 38, k + 36, Blocks.log, 1);
		this.setBlock(world, i + 9, j + 38, k + 37, Blocks.log, 1);
		this.setBlock(world, i + 9, j + 39, k + 11, Blocks.leaves, 0);
		this.setBlock(world, i + 9, j + 39, k + 12, Blocks.leaves, 0);
		this.setBlock(world, i + 9, j + 39, k + 13, Blocks.log, 1);
		this.setBlock(world, i + 9, j + 39, k + 14, Blocks.leaves, 0);
		this.setBlock(world, i + 9, j + 39, k + 15, Blocks.leaves, 0);
		this.setBlock(world, i + 9, j + 39, k + 16, Blocks.leaves, 0);
		this.setBlock(world, i + 9, j + 39, k + 17, Blocks.log, 1);
		this.setBlock(world, i + 9, j + 39, k + 18, Blocks.leaves, 0);
		this.setBlock(world, i + 9, j + 39, k + 19, Blocks.leaves, 0);
		this.setBlock(world, i + 9, j + 39, k + 20, Blocks.leaves, 0);
		this.setBlock(world, i + 9, j + 39, k + 21, Blocks.log, 1);
		this.setBlock(world, i + 9, j + 39, k + 22, Blocks.log, 1);
		this.setBlock(world, i + 9, j + 39, k + 23, Blocks.log, 1);
		this.setBlock(world, i + 9, j + 39, k + 24, Blocks.log, 1);
		this.setBlock(world, i + 9, j + 39, k + 25, Blocks.leaves, 0);
		this.setBlock(world, i + 9, j + 39, k + 26, Blocks.leaves, 0);
		this.setBlock(world, i + 9, j + 39, k + 27, Blocks.leaves, 0);
		this.setBlock(world, i + 9, j + 39, k + 28, Blocks.leaves, 0);
		this.setBlock(world, i + 9, j + 39, k + 29, Blocks.leaves, 0);
		this.setBlock(world, i + 9, j + 39, k + 30, Blocks.leaves, 0);
		this.setBlock(world, i + 9, j + 39, k + 31, Blocks.leaves, 0);
		this.setBlock(world, i + 9, j + 39, k + 32, Blocks.leaves, 0);
		this.setBlock(world, i + 9, j + 39, k + 33, Blocks.log, 1);
		this.setBlock(world, i + 9, j + 39, k + 34, Blocks.leaves, 0);
		this.setBlock(world, i + 9, j + 39, k + 35, Blocks.leaves, 0);
		this.setBlock(world, i + 9, j + 39, k + 36, Blocks.log, 1);
		this.setBlock(world, i + 9, j + 39, k + 37, Blocks.log, 1);
		this.setBlock(world, i + 9, j + 39, k + 38, Blocks.log, 1);
		this.setBlock(world, i + 9, j + 40, k + 10, Blocks.leaves, 0);
		this.setBlock(world, i + 9, j + 40, k + 11, Blocks.leaves, 0);
		this.setBlock(world, i + 9, j + 40, k + 12, Blocks.log, 1);
		this.setBlock(world, i + 9, j + 40, k + 13, Blocks.log, 1);
		this.setBlock(world, i + 9, j + 40, k + 14, Blocks.log, 1);
		this.setBlock(world, i + 9, j + 40, k + 15, Blocks.log, 1);
		this.setBlock(world, i + 9, j + 40, k + 16, Blocks.leaves, 0);
		this.setBlock(world, i + 9, j + 40, k + 17, Blocks.leaves, 0);
		this.setBlock(world, i + 9, j + 40, k + 18, Blocks.leaves, 0);
		this.setBlock(world, i + 9, j + 40, k + 19, Blocks.log, 1);
		this.setBlock(world, i + 9, j + 40, k + 20, Blocks.leaves, 0);
		this.setBlock(world, i + 9, j + 40, k + 21, Blocks.leaves, 0);
		this.setBlock(world, i + 9, j + 40, k + 22, Blocks.log, 1);
		this.setBlock(world, i + 9, j + 40, k + 23, Blocks.leaves, 0);
		this.setBlock(world, i + 9, j + 40, k + 24, Blocks.leaves, 0);
		this.setBlock(world, i + 9, j + 40, k + 25, Blocks.leaves, 0);
		this.setBlock(world, i + 9, j + 40, k + 26, Blocks.leaves, 0);
		this.setBlock(world, i + 9, j + 40, k + 27, Blocks.leaves, 0);
		this.setBlock(world, i + 9, j + 40, k + 28, Blocks.leaves, 0);
		this.setBlock(world, i + 9, j + 40, k + 29, Blocks.leaves, 0);
		this.setBlock(world, i + 9, j + 40, k + 30, Blocks.leaves, 0);
		this.setBlock(world, i + 9, j + 40, k + 31, Blocks.leaves, 0);
		this.setBlock(world, i + 9, j + 40, k + 32, Blocks.log, 1);
		this.setBlock(world, i + 9, j + 40, k + 33, Blocks.log, 1);
		this.setBlock(world, i + 9, j + 40, k + 34, Blocks.leaves, 0);
		this.setBlock(world, i + 9, j + 40, k + 35, Blocks.leaves, 0);
		this.setBlock(world, i + 9, j + 40, k + 36, Blocks.log, 1);
		this.setBlock(world, i + 9, j + 40, k + 37, Blocks.log, 1);
		this.setBlock(world, i + 9, j + 40, k + 38, Blocks.log, 1);
		this.setBlock(world, i + 9, j + 40, k + 39, Blocks.log, 1);
		this.setBlock(world, i + 9, j + 40, k + 40, Blocks.log, 1);
		this.setBlock(world, i + 9, j + 40, k + 41, Blocks.leaves, 0);
		this.setBlock(world, i + 9, j + 40, k + 42, Blocks.log, 1);
		this.setBlock(world, i + 9, j + 40, k + 43, Blocks.leaves, 0);
		this.setBlock(world, i + 9, j + 41, k + 8, Blocks.leaves, 0);
		this.setBlock(world, i + 9, j + 41, k + 9, Blocks.leaves, 0);
		this.setBlock(world, i + 9, j + 41, k + 10, Blocks.leaves, 0);
		this.setBlock(world, i + 9, j + 41, k + 11, Blocks.leaves, 0);
		this.setBlock(world, i + 9, j + 41, k + 12, Blocks.leaves, 0);
		this.setBlock(world, i + 9, j + 41, k + 13, Blocks.leaves, 0);
		this.setBlock(world, i + 9, j + 41, k + 14, Blocks.log, 1);
		this.setBlock(world, i + 9, j + 41, k + 15, Blocks.leaves, 0);
		this.setBlock(world, i + 9, j + 41, k + 16, Blocks.leaves, 0);
		this.setBlock(world, i + 9, j + 41, k + 17, Blocks.leaves, 0);
		this.setBlock(world, i + 9, j + 41, k + 18, Blocks.log, 1);
		this.setBlock(world, i + 9, j + 41, k + 19, Blocks.leaves, 0);
		this.setBlock(world, i + 9, j + 41, k + 20, Blocks.leaves, 0);
		this.setBlock(world, i + 9, j + 41, k + 21, Blocks.leaves, 0);
		this.setBlock(world, i + 9, j + 41, k + 22, Blocks.leaves, 0);
		this.setBlock(world, i + 9, j + 41, k + 23, Blocks.leaves, 0);
		this.setBlock(world, i + 9, j + 41, k + 24, Blocks.leaves, 0);
		this.setBlock(world, i + 9, j + 41, k + 25, Blocks.leaves, 0);
		this.setBlock(world, i + 9, j + 41, k + 26, Blocks.leaves, 0);
		this.setBlock(world, i + 9, j + 41, k + 27, Blocks.leaves, 0);
		this.setBlock(world, i + 9, j + 41, k + 28, Blocks.leaves, 0);
		this.setBlock(world, i + 9, j + 41, k + 29, Blocks.leaves, 0);
		this.setBlock(world, i + 9, j + 41, k + 30, Blocks.leaves, 0);
		this.setBlock(world, i + 9, j + 41, k + 31, Blocks.leaves, 0);
		this.setBlock(world, i + 9, j + 41, k + 32, Blocks.leaves, 0);
		this.setBlock(world, i + 9, j + 41, k + 33, Blocks.leaves, 0);
		this.setBlock(world, i + 9, j + 41, k + 34, Blocks.leaves, 0);
		this.setBlock(world, i + 9, j + 41, k + 35, Blocks.leaves, 0);
		this.setBlock(world, i + 9, j + 41, k + 36, Blocks.leaves, 0);
		this.setBlock(world, i + 9, j + 41, k + 37, Blocks.log, 1);
		this.setBlock(world, i + 9, j + 41, k + 38, Blocks.log, 1);
		this.setBlock(world, i + 9, j + 41, k + 39, Blocks.leaves, 0);
		this.setBlock(world, i + 9, j + 41, k + 40, Blocks.leaves, 0);
		this.setBlock(world, i + 9, j + 41, k + 41, Blocks.leaves, 0);
		this.setBlock(world, i + 9, j + 41, k + 42, Blocks.leaves, 0);
		this.setBlock(world, i + 9, j + 41, k + 43, Blocks.leaves, 0);
		this.setBlock(world, i + 9, j + 41, k + 44, Blocks.leaves, 0);
		this.setBlock(world, i + 9, j + 42, k + 10, Blocks.leaves, 0);
		this.setBlock(world, i + 9, j + 42, k + 11, Blocks.leaves, 0);
		this.setBlock(world, i + 9, j + 42, k + 12, Blocks.leaves, 0);
		this.setBlock(world, i + 9, j + 42, k + 13, Blocks.leaves, 0);
		this.setBlock(world, i + 9, j + 42, k + 14, Blocks.leaves, 0);
		this.setBlock(world, i + 9, j + 42, k + 15, Blocks.leaves, 0);
		this.setBlock(world, i + 9, j + 42, k + 16, Blocks.leaves, 0);
		this.setBlock(world, i + 9, j + 42, k + 17, Blocks.leaves, 0);
		this.setBlock(world, i + 9, j + 42, k + 18, Blocks.leaves, 0);
		this.setBlock(world, i + 9, j + 42, k + 19, Blocks.leaves, 0);
		this.setBlock(world, i + 9, j + 42, k + 20, Blocks.leaves, 0);
		this.setBlock(world, i + 9, j + 42, k + 21, Blocks.leaves, 0);
		this.setBlock(world, i + 9, j + 42, k + 22, Blocks.leaves, 0);
		this.setBlock(world, i + 9, j + 42, k + 23, Blocks.leaves, 0);
		this.setBlock(world, i + 9, j + 42, k + 24, Blocks.leaves, 0);
		this.setBlock(world, i + 9, j + 42, k + 25, Blocks.log, 1);
		this.setBlock(world, i + 9, j + 42, k + 26, Blocks.leaves, 0);
		this.setBlock(world, i + 9, j + 42, k + 27, Blocks.leaves, 0);
		this.setBlock(world, i + 9, j + 42, k + 28, Blocks.leaves, 0);
		this.setBlock(world, i + 9, j + 42, k + 29, Blocks.leaves, 0);
		this.setBlock(world, i + 9, j + 42, k + 30, Blocks.leaves, 0);
		this.setBlock(world, i + 9, j + 42, k + 31, Blocks.leaves, 0);
		this.setBlock(world, i + 9, j + 42, k + 32, Blocks.leaves, 0);
		this.setBlock(world, i + 9, j + 42, k + 33, Blocks.leaves, 0);
		this.setBlock(world, i + 9, j + 42, k + 34, Blocks.leaves, 0);
		this.setBlock(world, i + 9, j + 42, k + 35, Blocks.leaves, 0);
		this.setBlock(world, i + 9, j + 42, k + 36, Blocks.log, 1);
		this.setBlock(world, i + 9, j + 42, k + 37, Blocks.leaves, 0);
		this.setBlock(world, i + 9, j + 42, k + 38, Blocks.leaves, 0);
		this.setBlock(world, i + 9, j + 42, k + 39, Blocks.leaves, 0);
		this.setBlock(world, i + 9, j + 42, k + 40, Blocks.log, 1);
		this.setBlock(world, i + 9, j + 42, k + 41, Blocks.leaves, 0);
		this.setBlock(world, i + 9, j + 42, k + 42, Blocks.log, 1);
		this.setBlock(world, i + 9, j + 42, k + 43, Blocks.leaves, 0);
		this.setBlock(world, i + 9, j + 42, k + 44, Blocks.log, 1);
		this.setBlock(world, i + 9, j + 43, k + 13, Blocks.leaves, 0);
		this.setBlock(world, i + 9, j + 43, k + 14, Blocks.leaves, 0);
		this.setBlock(world, i + 9, j + 43, k + 15, Blocks.leaves, 0);
		this.setBlock(world, i + 9, j + 43, k + 16, Blocks.leaves, 0);
		this.setBlock(world, i + 9, j + 43, k + 17, Blocks.leaves, 0);
		this.setBlock(world, i + 9, j + 43, k + 18, Blocks.leaves, 0);
		this.setBlock(world, i + 9, j + 43, k + 19, Blocks.leaves, 0);
		this.setBlock(world, i + 9, j + 43, k + 20, Blocks.leaves, 0);
		this.setBlock(world, i + 9, j + 43, k + 21, Blocks.leaves, 0);
		this.setBlock(world, i + 9, j + 43, k + 22, Blocks.leaves, 0);
		this.setBlock(world, i + 9, j + 43, k + 23, Blocks.leaves, 0);
		this.setBlock(world, i + 9, j + 43, k + 24, Blocks.leaves, 0);
		this.setBlock(world, i + 9, j + 43, k + 25, Blocks.leaves, 0);
		this.setBlock(world, i + 9, j + 43, k + 26, Blocks.leaves, 0);
		this.setBlock(world, i + 9, j + 43, k + 27, Blocks.leaves, 0);
		this.setBlock(world, i + 9, j + 43, k + 28, Blocks.leaves, 0);
		this.setBlock(world, i + 9, j + 43, k + 29, Blocks.leaves, 0);
		this.setBlock(world, i + 9, j + 43, k + 30, Blocks.leaves, 0);
		this.setBlock(world, i + 9, j + 43, k + 31, Blocks.leaves, 0);
		this.setBlock(world, i + 9, j + 43, k + 32, Blocks.leaves, 0);
		this.setBlock(world, i + 9, j + 43, k + 33, Blocks.leaves, 0);
		this.setBlock(world, i + 9, j + 43, k + 34, Blocks.leaves, 0);
		this.setBlock(world, i + 9, j + 43, k + 35, Blocks.leaves, 0);
		this.setBlock(world, i + 9, j + 43, k + 36, Blocks.leaves, 0);
		this.setBlock(world, i + 9, j + 43, k + 37, Blocks.leaves, 0);
		this.setBlock(world, i + 9, j + 43, k + 38, Blocks.leaves, 0);
		this.setBlock(world, i + 9, j + 43, k + 39, Blocks.leaves, 0);
		this.setBlock(world, i + 9, j + 43, k + 40, Blocks.log, 1);
		this.setBlock(world, i + 9, j + 43, k + 41, Blocks.leaves, 0);
		this.setBlock(world, i + 9, j + 43, k + 42, Blocks.leaves, 0);
		this.setBlock(world, i + 9, j + 43, k + 43, Blocks.leaves, 0);
		this.setBlock(world, i + 9, j + 43, k + 44, Blocks.leaves, 0);
		this.setBlock(world, i + 9, j + 44, k + 13, Blocks.leaves, 0);
		this.setBlock(world, i + 9, j + 44, k + 14, Blocks.leaves, 0);
		this.setBlock(world, i + 9, j + 44, k + 16, Blocks.leaves, 0);
		this.setBlock(world, i + 9, j + 44, k + 17, Blocks.leaves, 0);
		this.setBlock(world, i + 9, j + 44, k + 19, Blocks.leaves, 0);
		this.setBlock(world, i + 9, j + 44, k + 20, Blocks.leaves, 0);
		this.setBlock(world, i + 9, j + 44, k + 21, Blocks.leaves, 0);
		this.setBlock(world, i + 9, j + 44, k + 22, Blocks.leaves, 0);
		this.setBlock(world, i + 9, j + 44, k + 23, Blocks.leaves, 0);
		this.setBlock(world, i + 9, j + 44, k + 24, Blocks.leaves, 0);
		this.setBlock(world, i + 9, j + 44, k + 25, Blocks.leaves, 0);
		this.setBlock(world, i + 9, j + 44, k + 32, Blocks.leaves, 0);
		this.setBlock(world, i + 9, j + 44, k + 33, Blocks.leaves, 0);
		this.setBlock(world, i + 9, j + 44, k + 34, Blocks.leaves, 0);
		this.setBlock(world, i + 9, j + 44, k + 35, Blocks.leaves, 0);
		this.setBlock(world, i + 9, j + 44, k + 36, Blocks.leaves, 0);
		this.setBlock(world, i + 9, j + 44, k + 37, Blocks.leaves, 0);
		this.setBlock(world, i + 9, j + 44, k + 38, Blocks.leaves, 0);
		this.setBlock(world, i + 9, j + 44, k + 39, Blocks.leaves, 0);
		this.setBlock(world, i + 9, j + 44, k + 40, Blocks.leaves, 0);
		this.setBlock(world, i + 9, j + 44, k + 41, Blocks.leaves, 0);
		this.setBlock(world, i + 9, j + 44, k + 42, Blocks.leaves, 0);
		this.setBlock(world, i + 9, j + 44, k + 43, Blocks.leaves, 0);
		this.setBlock(world, i + 9, j + 44, k + 44, Blocks.leaves, 0);
		this.setBlock(world, i + 10, j + 36, k + 19, Blocks.leaves, 0);
		this.setBlock(world, i + 10, j + 36, k + 20, Blocks.log, 1);
		this.setBlock(world, i + 10, j + 36, k + 21, Blocks.log, 1);
		this.setBlock(world, i + 10, j + 36, k + 33, Blocks.log, 1);
		this.setBlock(world, i + 10, j + 37, k + 16, Blocks.leaves, 0);
		this.setBlock(world, i + 10, j + 37, k + 17, Blocks.leaves, 0);
		this.setBlock(world, i + 10, j + 37, k + 18, Blocks.leaves, 0);
		this.setBlock(world, i + 10, j + 37, k + 19, Blocks.leaves, 0);
		this.setBlock(world, i + 10, j + 37, k + 20, Blocks.log, 1);
		this.setBlock(world, i + 10, j + 37, k + 21, Blocks.log, 1);
		this.setBlock(world, i + 10, j + 37, k + 22, Blocks.log, 1);
		this.setBlock(world, i + 10, j + 37, k + 23, Blocks.log, 1);
		this.setBlock(world, i + 10, j + 37, k + 30, Blocks.log, 1);
		this.setBlock(world, i + 10, j + 37, k + 32, Blocks.log, 1);
		this.setBlock(world, i + 10, j + 37, k + 33, Blocks.log, 1);
		this.setBlock(world, i + 10, j + 37, k + 34, Blocks.log, 1);
		this.setBlock(world, i + 10, j + 37, k + 35, Blocks.log, 1);
		this.setBlock(world, i + 10, j + 38, k + 15, Blocks.leaves, 0);
		this.setBlock(world, i + 10, j + 38, k + 16, Blocks.log, 1);
		this.setBlock(world, i + 10, j + 38, k + 17, Blocks.leaves, 0);
		this.setBlock(world, i + 10, j + 38, k + 18, Blocks.leaves, 0);
		this.setBlock(world, i + 10, j + 38, k + 19, Blocks.leaves, 0);
		this.setBlock(world, i + 10, j + 38, k + 20, Blocks.log, 1);
		this.setBlock(world, i + 10, j + 38, k + 21, Blocks.log, 1);
		this.setBlock(world, i + 10, j + 38, k + 22, Blocks.log, 1);
		this.setBlock(world, i + 10, j + 38, k + 23, Blocks.log, 1);
		this.setBlock(world, i + 10, j + 38, k + 24, Blocks.log, 1);
		this.setBlock(world, i + 10, j + 38, k + 29, Blocks.leaves, 0);
		this.setBlock(world, i + 10, j + 38, k + 30, Blocks.leaves, 0);
		this.setBlock(world, i + 10, j + 38, k + 31, Blocks.log, 1);
		this.setBlock(world, i + 10, j + 38, k + 32, Blocks.leaves, 0);
		this.setBlock(world, i + 10, j + 38, k + 33, Blocks.log, 1);
		this.setBlock(world, i + 10, j + 38, k + 34, Blocks.log, 1);
		this.setBlock(world, i + 10, j + 38, k + 35, Blocks.log, 1);
		this.setBlock(world, i + 10, j + 38, k + 36, Blocks.log, 1);
		this.setBlock(world, i + 10, j + 38, k + 37, Blocks.log, 1);
		this.setBlock(world, i + 10, j + 39, k + 12, Blocks.leaves, 0);
		this.setBlock(world, i + 10, j + 39, k + 13, Blocks.log, 1);
		this.setBlock(world, i + 10, j + 39, k + 14, Blocks.log, 1);
		this.setBlock(world, i + 10, j + 39, k + 15, Blocks.log, 1);
		this.setBlock(world, i + 10, j + 39, k + 16, Blocks.log, 1);
		this.setBlock(world, i + 10, j + 39, k + 17, Blocks.leaves, 0);
		this.setBlock(world, i + 10, j + 39, k + 18, Blocks.leaves, 0);
		this.setBlock(world, i + 10, j + 39, k + 19, Blocks.leaves, 0);
		this.setBlock(world, i + 10, j + 39, k + 20, Blocks.log, 1);
		this.setBlock(world, i + 10, j + 39, k + 21, Blocks.log, 1);
		this.setBlock(world, i + 10, j + 39, k + 22, Blocks.log, 1);
		this.setBlock(world, i + 10, j + 39, k + 23, Blocks.leaves, 0);
		this.setBlock(world, i + 10, j + 39, k + 24, Blocks.leaves, 0);
		this.setBlock(world, i + 10, j + 39, k + 25, Blocks.leaves, 0);
		this.setBlock(world, i + 10, j + 39, k + 26, Blocks.leaves, 0);
		this.setBlock(world, i + 10, j + 39, k + 27, Blocks.leaves, 0);
		this.setBlock(world, i + 10, j + 39, k + 28, Blocks.leaves, 0);
		this.setBlock(world, i + 10, j + 39, k + 29, Blocks.leaves, 0);
		this.setBlock(world, i + 10, j + 39, k + 30, Blocks.leaves, 0);
		this.setBlock(world, i + 10, j + 39, k + 31, Blocks.leaves, 0);
		this.setBlock(world, i + 10, j + 39, k + 32, Blocks.log, 1);
		this.setBlock(world, i + 10, j + 39, k + 33, Blocks.leaves, 0);
		this.setBlock(world, i + 10, j + 39, k + 34, Blocks.leaves, 0);
		this.setBlock(world, i + 10, j + 39, k + 35, Blocks.log, 1);
		this.setBlock(world, i + 10, j + 39, k + 36, Blocks.log, 1);
		this.setBlock(world, i + 10, j + 39, k + 37, Blocks.log, 1);
		this.setBlock(world, i + 10, j + 39, k + 38, Blocks.log, 1);
		this.setBlock(world, i + 10, j + 39, k + 39, Blocks.leaves, 0);
		this.setBlock(world, i + 10, j + 40, k + 9, Blocks.leaves, 0);
		this.setBlock(world, i + 10, j + 40, k + 10, Blocks.leaves, 0);
		this.setBlock(world, i + 10, j + 40, k + 11, Blocks.leaves, 0);
		this.setBlock(world, i + 10, j + 40, k + 12, Blocks.leaves, 0);
		this.setBlock(world, i + 10, j + 40, k + 13, Blocks.log, 1);
		this.setBlock(world, i + 10, j + 40, k + 14, Blocks.log, 1);
		this.setBlock(world, i + 10, j + 40, k + 15, Blocks.log, 1);
		this.setBlock(world, i + 10, j + 40, k + 16, Blocks.leaves, 0);
		this.setBlock(world, i + 10, j + 40, k + 17, Blocks.leaves, 0);
		this.setBlock(world, i + 10, j + 40, k + 18, Blocks.leaves, 0);
		this.setBlock(world, i + 10, j + 40, k + 19, Blocks.leaves, 0);
		this.setBlock(world, i + 10, j + 40, k + 20, Blocks.leaves, 0);
		this.setBlock(world, i + 10, j + 40, k + 21, Blocks.leaves, 0);
		this.setBlock(world, i + 10, j + 40, k + 22, Blocks.leaves, 0);
		this.setBlock(world, i + 10, j + 40, k + 23, Blocks.leaves, 0);
		this.setBlock(world, i + 10, j + 40, k + 24, Blocks.leaves, 0);
		this.setBlock(world, i + 10, j + 40, k + 25, Blocks.leaves, 0);
		this.setBlock(world, i + 10, j + 40, k + 26, Blocks.leaves, 0);
		this.setBlock(world, i + 10, j + 40, k + 27, Blocks.leaves, 0);
		this.setBlock(world, i + 10, j + 40, k + 28, Blocks.log, 1);
		this.setBlock(world, i + 10, j + 40, k + 29, Blocks.log, 1);
		this.setBlock(world, i + 10, j + 40, k + 30, Blocks.log, 1);
		this.setBlock(world, i + 10, j + 40, k + 31, Blocks.leaves, 0);
		this.setBlock(world, i + 10, j + 40, k + 32, Blocks.leaves, 0);
		this.setBlock(world, i + 10, j + 40, k + 33, Blocks.leaves, 0);
		this.setBlock(world, i + 10, j + 40, k + 34, Blocks.leaves, 0);
		this.setBlock(world, i + 10, j + 40, k + 35, Blocks.leaves, 0);
		this.setBlock(world, i + 10, j + 40, k + 36, Blocks.log, 1);
		this.setBlock(world, i + 10, j + 40, k + 37, Blocks.log, 1);
		this.setBlock(world, i + 10, j + 40, k + 38, Blocks.leaves, 0);
		this.setBlock(world, i + 10, j + 40, k + 39, Blocks.leaves, 0);
		this.setBlock(world, i + 10, j + 40, k + 40, Blocks.leaves, 0);
		this.setBlock(world, i + 10, j + 40, k + 41, Blocks.log, 1);
		this.setBlock(world, i + 10, j + 40, k + 42, Blocks.leaves, 0);
		this.setBlock(world, i + 10, j + 40, k + 43, Blocks.leaves, 0);
		this.setBlock(world, i + 10, j + 40, k + 44, Blocks.leaves, 0);
		this.setBlock(world, i + 10, j + 40, k + 45, Blocks.leaves, 0);
		this.setBlock(world, i + 10, j + 40, k + 46, Blocks.leaves, 0);
		this.setBlock(world, i + 10, j + 41, k + 6, Blocks.leaves, 0);
		this.setBlock(world, i + 10, j + 41, k + 7, Blocks.leaves, 0);
		this.setBlock(world, i + 10, j + 41, k + 8, Blocks.leaves, 0);
		this.setBlock(world, i + 10, j + 41, k + 9, Blocks.leaves, 0);
		this.setBlock(world, i + 10, j + 41, k + 10, Blocks.leaves, 0);
		this.setBlock(world, i + 10, j + 41, k + 11, Blocks.leaves, 0);
		this.setBlock(world, i + 10, j + 41, k + 12, Blocks.leaves, 0);
		this.setBlock(world, i + 10, j + 41, k + 13, Blocks.leaves, 0);
		this.setBlock(world, i + 10, j + 41, k + 14, Blocks.log, 1);
		this.setBlock(world, i + 10, j + 41, k + 15, Blocks.leaves, 0);
		this.setBlock(world, i + 10, j + 41, k + 16, Blocks.leaves, 0);
		this.setBlock(world, i + 10, j + 41, k + 17, Blocks.leaves, 0);
		this.setBlock(world, i + 10, j + 41, k + 18, Blocks.leaves, 0);
		this.setBlock(world, i + 10, j + 41, k + 19, Blocks.leaves, 0);
		this.setBlock(world, i + 10, j + 41, k + 20, Blocks.leaves, 0);
		this.setBlock(world, i + 10, j + 41, k + 21, Blocks.leaves, 0);
		this.setBlock(world, i + 10, j + 41, k + 22, Blocks.leaves, 0);
		this.setBlock(world, i + 10, j + 41, k + 23, Blocks.leaves, 0);
		this.setBlock(world, i + 10, j + 41, k + 24, Blocks.log, 1);
		this.setBlock(world, i + 10, j + 41, k + 25, Blocks.leaves, 0);
		this.setBlock(world, i + 10, j + 41, k + 26, Blocks.leaves, 0);
		this.setBlock(world, i + 10, j + 41, k + 27, Blocks.leaves, 0);
		this.setBlock(world, i + 10, j + 41, k + 28, Blocks.leaves, 0);
		this.setBlock(world, i + 10, j + 41, k + 29, Blocks.leaves, 0);
		this.setBlock(world, i + 10, j + 41, k + 30, Blocks.leaves, 0);
		this.setBlock(world, i + 10, j + 41, k + 31, Blocks.leaves, 0);
		this.setBlock(world, i + 10, j + 41, k + 32, Blocks.leaves, 0);
		this.setBlock(world, i + 10, j + 41, k + 33, Blocks.leaves, 0);
		this.setBlock(world, i + 10, j + 41, k + 34, Blocks.leaves, 0);
		this.setBlock(world, i + 10, j + 41, k + 35, Blocks.leaves, 0);
		this.setBlock(world, i + 10, j + 41, k + 36, Blocks.leaves, 0);
		this.setBlock(world, i + 10, j + 41, k + 37, Blocks.leaves, 0);
		this.setBlock(world, i + 10, j + 41, k + 38, Blocks.leaves, 0);
		this.setBlock(world, i + 10, j + 41, k + 39, Blocks.leaves, 0);
		this.setBlock(world, i + 10, j + 41, k + 40, Blocks.leaves, 0);
		this.setBlock(world, i + 10, j + 41, k + 41, Blocks.leaves, 0);
		this.setBlock(world, i + 10, j + 41, k + 42, Blocks.leaves, 0);
		this.setBlock(world, i + 10, j + 41, k + 43, Blocks.leaves, 0);
		this.setBlock(world, i + 10, j + 41, k + 44, Blocks.leaves, 0);
		this.setBlock(world, i + 10, j + 41, k + 45, Blocks.leaves, 0);
		this.setBlock(world, i + 10, j + 41, k + 46, Blocks.leaves, 0);
		this.setBlock(world, i + 10, j + 41, k + 47, Blocks.log, 1);
		this.setBlock(world, i + 10, j + 42, k + 6, Blocks.leaves, 0);
		this.setBlock(world, i + 10, j + 42, k + 7, Blocks.leaves, 0);
		this.setBlock(world, i + 10, j + 42, k + 9, Blocks.leaves, 0);
		this.setBlock(world, i + 10, j + 42, k + 10, Blocks.leaves, 0);
		this.setBlock(world, i + 10, j + 42, k + 12, Blocks.leaves, 0);
		this.setBlock(world, i + 10, j + 42, k + 13, Blocks.leaves, 0);
		this.setBlock(world, i + 10, j + 42, k + 14, Blocks.leaves, 0);
		this.setBlock(world, i + 10, j + 42, k + 15, Blocks.leaves, 0);
		this.setBlock(world, i + 10, j + 42, k + 16, Blocks.leaves, 0);
		this.setBlock(world, i + 10, j + 42, k + 17, Blocks.leaves, 0);
		this.setBlock(world, i + 10, j + 42, k + 18, Blocks.leaves, 0);
		this.setBlock(world, i + 10, j + 42, k + 19, Blocks.leaves, 0);
		this.setBlock(world, i + 10, j + 42, k + 20, Blocks.leaves, 0);
		this.setBlock(world, i + 10, j + 42, k + 21, Blocks.leaves, 0);
		this.setBlock(world, i + 10, j + 42, k + 22, Blocks.leaves, 0);
		this.setBlock(world, i + 10, j + 42, k + 23, Blocks.log, 1);
		this.setBlock(world, i + 10, j + 42, k + 24, Blocks.leaves, 0);
		this.setBlock(world, i + 10, j + 42, k + 25, Blocks.leaves, 0);
		this.setBlock(world, i + 10, j + 42, k + 26, Blocks.leaves, 0);
		this.setBlock(world, i + 10, j + 42, k + 27, Blocks.leaves, 0);
		this.setBlock(world, i + 10, j + 42, k + 28, Blocks.leaves, 0);
		this.setBlock(world, i + 10, j + 42, k + 29, Blocks.leaves, 0);
		this.setBlock(world, i + 10, j + 42, k + 30, Blocks.leaves, 0);
		this.setBlock(world, i + 10, j + 42, k + 31, Blocks.leaves, 0);
		this.setBlock(world, i + 10, j + 42, k + 32, Blocks.leaves, 0);
		this.setBlock(world, i + 10, j + 42, k + 33, Blocks.leaves, 0);
		this.setBlock(world, i + 10, j + 42, k + 34, Blocks.leaves, 0);
		this.setBlock(world, i + 10, j + 42, k + 35, Blocks.leaves, 0);
		this.setBlock(world, i + 10, j + 42, k + 36, Blocks.leaves, 0);
		this.setBlock(world, i + 10, j + 42, k + 37, Blocks.leaves, 0);
		this.setBlock(world, i + 10, j + 42, k + 38, Blocks.leaves, 0);
		this.setBlock(world, i + 10, j + 42, k + 39, Blocks.leaves, 0);
		this.setBlock(world, i + 10, j + 42, k + 40, Blocks.leaves, 0);
		this.setBlock(world, i + 10, j + 42, k + 41, Blocks.leaves, 0);
		this.setBlock(world, i + 10, j + 42, k + 42, Blocks.log, 1);
		this.setBlock(world, i + 10, j + 42, k + 43, Blocks.leaves, 0);
		this.setBlock(world, i + 10, j + 42, k + 44, Blocks.leaves, 0);
		this.setBlock(world, i + 10, j + 42, k + 45, Blocks.leaves, 0);
		this.setBlock(world, i + 10, j + 42, k + 46, Blocks.log, 1);
		this.setBlock(world, i + 10, j + 42, k + 47, Blocks.leaves, 0);
		this.setBlock(world, i + 10, j + 43, k + 6, Blocks.leaves, 0);
		this.setBlock(world, i + 10, j + 43, k + 13, Blocks.leaves, 0);
		this.setBlock(world, i + 10, j + 43, k + 14, Blocks.leaves, 0);
		this.setBlock(world, i + 10, j + 43, k + 15, Blocks.leaves, 0);
		this.setBlock(world, i + 10, j + 43, k + 16, Blocks.leaves, 0);
		this.setBlock(world, i + 10, j + 43, k + 17, Blocks.leaves, 0);
		this.setBlock(world, i + 10, j + 43, k + 18, Blocks.leaves, 0);
		this.setBlock(world, i + 10, j + 43, k + 19, Blocks.leaves, 0);
		this.setBlock(world, i + 10, j + 43, k + 20, Blocks.leaves, 0);
		this.setBlock(world, i + 10, j + 43, k + 21, Blocks.log, 1);
		this.setBlock(world, i + 10, j + 43, k + 22, Blocks.leaves, 0);
		this.setBlock(world, i + 10, j + 43, k + 23, Blocks.leaves, 0);
		this.setBlock(world, i + 10, j + 43, k + 24, Blocks.log, 1);
		this.setBlock(world, i + 10, j + 43, k + 25, Blocks.leaves, 0);
		this.setBlock(world, i + 10, j + 43, k + 26, Blocks.leaves, 0);
		this.setBlock(world, i + 10, j + 43, k + 27, Blocks.leaves, 0);
		this.setBlock(world, i + 10, j + 43, k + 28, Blocks.leaves, 0);
		this.setBlock(world, i + 10, j + 43, k + 29, Blocks.leaves, 0);
		this.setBlock(world, i + 10, j + 43, k + 30, Blocks.leaves, 0);
		this.setBlock(world, i + 10, j + 43, k + 31, Blocks.leaves, 0);
		this.setBlock(world, i + 10, j + 43, k + 32, Blocks.leaves, 0);
		this.setBlock(world, i + 10, j + 43, k + 33, Blocks.leaves, 0);
		this.setBlock(world, i + 10, j + 43, k + 34, Blocks.leaves, 0);
		this.setBlock(world, i + 10, j + 43, k + 35, Blocks.log, 1);
		this.setBlock(world, i + 10, j + 43, k + 36, Blocks.leaves, 0);
		this.setBlock(world, i + 10, j + 43, k + 37, Blocks.leaves, 0);
		this.setBlock(world, i + 10, j + 43, k + 38, Blocks.leaves, 0);
		this.setBlock(world, i + 10, j + 43, k + 39, Blocks.leaves, 0);
		this.setBlock(world, i + 10, j + 43, k + 40, Blocks.leaves, 0);
		this.setBlock(world, i + 10, j + 43, k + 41, Blocks.log, 1);
		this.setBlock(world, i + 10, j + 43, k + 42, Blocks.leaves, 0);
		this.setBlock(world, i + 10, j + 43, k + 43, Blocks.log, 1);
		this.setBlock(world, i + 10, j + 43, k + 44, Blocks.leaves, 0);
		this.setBlock(world, i + 10, j + 43, k + 45, Blocks.leaves, 0);
		this.setBlock(world, i + 10, j + 43, k + 46, Blocks.log, 1);
		this.setBlock(world, i + 10, j + 43, k + 47, Blocks.leaves, 0);
		this.setBlock(world, i + 10, j + 44, k + 14, Blocks.leaves, 0);
		this.setBlock(world, i + 10, j + 44, k + 15, Blocks.leaves, 0);
		this.setBlock(world, i + 10, j + 44, k + 16, Blocks.leaves, 0);
		this.setBlock(world, i + 10, j + 44, k + 17, Blocks.leaves, 8);
		this.setBlock(world, i + 10, j + 44, k + 18, Blocks.leaves, 0);
		this.setBlock(world, i + 10, j + 44, k + 19, Blocks.leaves, 0);
		this.setBlock(world, i + 10, j + 44, k + 20, Blocks.leaves, 0);
		this.setBlock(world, i + 10, j + 44, k + 21, Blocks.leaves, 0);
		this.setBlock(world, i + 10, j + 44, k + 22, Blocks.leaves, 0);
		this.setBlock(world, i + 10, j + 44, k + 23, Blocks.leaves, 0);
		this.setBlock(world, i + 10, j + 44, k + 24, Blocks.leaves, 0);
		this.setBlock(world, i + 10, j + 44, k + 25, Blocks.leaves, 0);
		this.setBlock(world, i + 10, j + 44, k + 31, Blocks.leaves, 0);
		this.setBlock(world, i + 10, j + 44, k + 32, Blocks.leaves, 0);
		this.setBlock(world, i + 10, j + 44, k + 33, Blocks.leaves, 0);
		this.setBlock(world, i + 10, j + 44, k + 34, Blocks.log, 1);
		this.setBlock(world, i + 10, j + 44, k + 35, Blocks.leaves, 0);
		this.setBlock(world, i + 10, j + 44, k + 36, Blocks.leaves, 0);
		this.setBlock(world, i + 10, j + 44, k + 37, Blocks.leaves, 0);
		this.setBlock(world, i + 10, j + 44, k + 38, Blocks.leaves, 0);
		this.setBlock(world, i + 10, j + 44, k + 39, Blocks.leaves, 0);
		this.setBlock(world, i + 10, j + 44, k + 40, Blocks.leaves, 0);
		this.setBlock(world, i + 10, j + 44, k + 41, Blocks.leaves, 0);
		this.setBlock(world, i + 10, j + 44, k + 42, Blocks.leaves, 0);
		this.setBlock(world, i + 10, j + 44, k + 43, Blocks.leaves, 0);
		this.setBlock(world, i + 10, j + 44, k + 44, Blocks.leaves, 0);
		this.setBlock(world, i + 10, j + 44, k + 45, Blocks.leaves, 0);
		this.setBlock(world, i + 10, j + 44, k + 46, Blocks.leaves, 0);
		this.setBlock(world, i + 10, j + 45, k + 34, Blocks.leaves, 0);
		this.setBlock(world, i + 10, j + 45, k + 35, Blocks.leaves, 0);
		this.setBlock(world, i + 10, j + 45, k + 36, Blocks.leaves, 0);
		this.setBlock(world, i + 10, j + 45, k + 37, Blocks.leaves, 0);
		this.setBlock(world, i + 11, j + 35, k + 33, Blocks.log, 1);
		this.setBlock(world, i + 11, j + 36, k + 19, Blocks.leaves, 0);
		this.setBlock(world, i + 11, j + 36, k + 20, Blocks.log, 1);
		this.setBlock(world, i + 11, j + 36, k + 21, Blocks.log, 1);
		this.setBlock(world, i + 11, j + 36, k + 22, Blocks.log, 1);
		this.setBlock(world, i + 11, j + 36, k + 32, Blocks.log, 1);
		this.setBlock(world, i + 11, j + 36, k + 33, Blocks.log, 1);
		this.setBlock(world, i + 11, j + 36, k + 34, Blocks.log, 1);
		this.setBlock(world, i + 11, j + 36, k + 35, Blocks.log, 1);
		this.setBlock(world, i + 11, j + 37, k + 16, Blocks.leaves, 0);
		this.setBlock(world, i + 11, j + 37, k + 17, Blocks.leaves, 0);
		this.setBlock(world, i + 11, j + 37, k + 18, Blocks.leaves, 0);
		this.setBlock(world, i + 11, j + 37, k + 19, Blocks.log, 1);
		this.setBlock(world, i + 11, j + 37, k + 20, Blocks.log, 1);
		this.setBlock(world, i + 11, j + 37, k + 21, Blocks.log, 1);
		this.setBlock(world, i + 11, j + 37, k + 22, Blocks.log, 1);
		this.setBlock(world, i + 11, j + 37, k + 23, Blocks.log, 1);
		this.setBlock(world, i + 11, j + 37, k + 30, Blocks.log, 1);
		this.setBlock(world, i + 11, j + 37, k + 32, Blocks.log, 1);
		this.setBlock(world, i + 11, j + 37, k + 33, Blocks.log, 1);
		this.setBlock(world, i + 11, j + 37, k + 34, Blocks.log, 1);
		this.setBlock(world, i + 11, j + 37, k + 35, Blocks.log, 1);
		this.setBlock(world, i + 11, j + 37, k + 36, Blocks.log, 1);
		this.setBlock(world, i + 11, j + 38, k + 15, Blocks.log, 1);
		this.setBlock(world, i + 11, j + 38, k + 16, Blocks.log, 1);
		this.setBlock(world, i + 11, j + 38, k + 17, Blocks.log, 1);
		this.setBlock(world, i + 11, j + 38, k + 18, Blocks.leaves, 0);
		this.setBlock(world, i + 11, j + 38, k + 19, Blocks.leaves, 0);
		this.setBlock(world, i + 11, j + 38, k + 20, Blocks.leaves, 0);
		this.setBlock(world, i + 11, j + 38, k + 21, Blocks.log, 1);
		this.setBlock(world, i + 11, j + 38, k + 22, Blocks.log, 1);
		this.setBlock(world, i + 11, j + 38, k + 23, Blocks.leaves, 0);
		this.setBlock(world, i + 11, j + 38, k + 24, Blocks.leaves, 0);
		this.setBlock(world, i + 11, j + 38, k + 27, Blocks.log, 1);
		this.setBlock(world, i + 11, j + 38, k + 28, Blocks.leaves, 0);
		this.setBlock(world, i + 11, j + 38, k + 29, Blocks.log, 1);
		this.setBlock(world, i + 11, j + 38, k + 30, Blocks.log, 1);
		this.setBlock(world, i + 11, j + 38, k + 31, Blocks.leaves, 0);
		this.setBlock(world, i + 11, j + 38, k + 32, Blocks.leaves, 0);
		this.setBlock(world, i + 11, j + 38, k + 33, Blocks.log, 1);
		this.setBlock(world, i + 11, j + 38, k + 34, Blocks.log, 1);
		this.setBlock(world, i + 11, j + 38, k + 35, Blocks.log, 1);
		this.setBlock(world, i + 11, j + 38, k + 36, Blocks.log, 1);
		this.setBlock(world, i + 11, j + 38, k + 37, Blocks.log, 1);
		this.setBlock(world, i + 11, j + 39, k + 12, Blocks.leaves, 0);
		this.setBlock(world, i + 11, j + 39, k + 13, Blocks.log, 1);
		this.setBlock(world, i + 11, j + 39, k + 14, Blocks.log, 1);
		this.setBlock(world, i + 11, j + 39, k + 15, Blocks.log, 1);
		this.setBlock(world, i + 11, j + 39, k + 16, Blocks.log, 1);
		this.setBlock(world, i + 11, j + 39, k + 17, Blocks.leaves, 0);
		this.setBlock(world, i + 11, j + 39, k + 18, Blocks.leaves, 0);
		this.setBlock(world, i + 11, j + 39, k + 19, Blocks.leaves, 0);
		this.setBlock(world, i + 11, j + 39, k + 20, Blocks.log, 1);
		this.setBlock(world, i + 11, j + 39, k + 21, Blocks.leaves, 0);
		this.setBlock(world, i + 11, j + 39, k + 22, Blocks.leaves, 0);
		this.setBlock(world, i + 11, j + 39, k + 23, Blocks.leaves, 0);
		this.setBlock(world, i + 11, j + 39, k + 24, Blocks.leaves, 0);
		this.setBlock(world, i + 11, j + 39, k + 25, Blocks.leaves, 0);
		this.setBlock(world, i + 11, j + 39, k + 26, Blocks.log, 1);
		this.setBlock(world, i + 11, j + 39, k + 27, Blocks.log, 1);
		this.setBlock(world, i + 11, j + 39, k + 28, Blocks.log, 1);
		this.setBlock(world, i + 11, j + 39, k + 29, Blocks.log, 1);
		this.setBlock(world, i + 11, j + 39, k + 30, Blocks.leaves, 0);
		this.setBlock(world, i + 11, j + 39, k + 31, Blocks.leaves, 0);
		this.setBlock(world, i + 11, j + 39, k + 32, Blocks.leaves, 0);
		this.setBlock(world, i + 11, j + 39, k + 33, Blocks.leaves, 0);
		this.setBlock(world, i + 11, j + 39, k + 34, Blocks.leaves, 0);
		this.setBlock(world, i + 11, j + 39, k + 35, Blocks.log, 1);
		this.setBlock(world, i + 11, j + 39, k + 36, Blocks.log, 1);
		this.setBlock(world, i + 11, j + 39, k + 37, Blocks.log, 1);
		this.setBlock(world, i + 11, j + 39, k + 38, Blocks.log, 1);
		this.setBlock(world, i + 11, j + 39, k + 39, Blocks.leaves, 0);
		this.setBlock(world, i + 11, j + 40, k + 7, Blocks.leaves, 0);
		this.setBlock(world, i + 11, j + 40, k + 8, Blocks.leaves, 0);
		this.setBlock(world, i + 11, j + 40, k + 9, Blocks.leaves, 0);
		this.setBlock(world, i + 11, j + 40, k + 10, Blocks.leaves, 0);
		this.setBlock(world, i + 11, j + 40, k + 11, Blocks.leaves, 0);
		this.setBlock(world, i + 11, j + 40, k + 12, Blocks.leaves, 0);
		this.setBlock(world, i + 11, j + 40, k + 13, Blocks.log, 1);
		this.setBlock(world, i + 11, j + 40, k + 14, Blocks.log, 1);
		this.setBlock(world, i + 11, j + 40, k + 15, Blocks.log, 1);
		this.setBlock(world, i + 11, j + 40, k + 16, Blocks.leaves, 0);
		this.setBlock(world, i + 11, j + 40, k + 17, Blocks.leaves, 0);
		this.setBlock(world, i + 11, j + 40, k + 18, Blocks.leaves, 0);
		this.setBlock(world, i + 11, j + 40, k + 19, Blocks.leaves, 0);
		this.setBlock(world, i + 11, j + 40, k + 20, Blocks.leaves, 0);
		this.setBlock(world, i + 11, j + 40, k + 21, Blocks.leaves, 0);
		this.setBlock(world, i + 11, j + 40, k + 22, Blocks.leaves, 0);
		this.setBlock(world, i + 11, j + 40, k + 23, Blocks.leaves, 0);
		this.setBlock(world, i + 11, j + 40, k + 24, Blocks.leaves, 0);
		this.setBlock(world, i + 11, j + 40, k + 25, Blocks.leaves, 0);
		this.setBlock(world, i + 11, j + 40, k + 26, Blocks.leaves, 0);
		this.setBlock(world, i + 11, j + 40, k + 27, Blocks.leaves, 0);
		this.setBlock(world, i + 11, j + 40, k + 28, Blocks.leaves, 0);
		this.setBlock(world, i + 11, j + 40, k + 29, Blocks.leaves, 0);
		this.setBlock(world, i + 11, j + 40, k + 30, Blocks.log, 1);
		this.setBlock(world, i + 11, j + 40, k + 31, Blocks.leaves, 0);
		this.setBlock(world, i + 11, j + 40, k + 32, Blocks.leaves, 0);
		this.setBlock(world, i + 11, j + 40, k + 33, Blocks.leaves, 0);
		this.setBlock(world, i + 11, j + 40, k + 34, Blocks.leaves, 0);
		this.setBlock(world, i + 11, j + 40, k + 35, Blocks.leaves, 0);
		this.setBlock(world, i + 11, j + 40, k + 36, Blocks.leaves, 0);
		this.setBlock(world, i + 11, j + 40, k + 37, Blocks.leaves, 0);
		this.setBlock(world, i + 11, j + 40, k + 38, Blocks.leaves, 0);
		this.setBlock(world, i + 11, j + 40, k + 39, Blocks.leaves, 0);
		this.setBlock(world, i + 11, j + 40, k + 40, Blocks.leaves, 0);
		this.setBlock(world, i + 11, j + 40, k + 41, Blocks.leaves, 0);
		this.setBlock(world, i + 11, j + 40, k + 42, Blocks.leaves, 0);
		this.setBlock(world, i + 11, j + 40, k + 43, Blocks.log, 1);
		this.setBlock(world, i + 11, j + 40, k + 44, Blocks.leaves, 0);
		this.setBlock(world, i + 11, j + 40, k + 45, Blocks.leaves, 0);
		this.setBlock(world, i + 11, j + 40, k + 46, Blocks.leaves, 0);
		this.setBlock(world, i + 11, j + 40, k + 47, Blocks.leaves, 0);
		this.setBlock(world, i + 11, j + 41, k + 6, Blocks.leaves, 0);
		this.setBlock(world, i + 11, j + 41, k + 7, Blocks.leaves, 0);
		this.setBlock(world, i + 11, j + 41, k + 8, Blocks.leaves, 0);
		this.setBlock(world, i + 11, j + 41, k + 9, Blocks.leaves, 0);
		this.setBlock(world, i + 11, j + 41, k + 10, Blocks.leaves, 0);
		this.setBlock(world, i + 11, j + 41, k + 11, Blocks.leaves, 0);
		this.setBlock(world, i + 11, j + 41, k + 12, Blocks.leaves, 0);
		this.setBlock(world, i + 11, j + 41, k + 13, Blocks.leaves, 0);
		this.setBlock(world, i + 11, j + 41, k + 14, Blocks.log, 1);
		this.setBlock(world, i + 11, j + 41, k + 15, Blocks.leaves, 0);
		this.setBlock(world, i + 11, j + 41, k + 16, Blocks.leaves, 0);
		this.setBlock(world, i + 11, j + 41, k + 17, Blocks.leaves, 0);
		this.setBlock(world, i + 11, j + 41, k + 18, Blocks.leaves, 0);
		this.setBlock(world, i + 11, j + 41, k + 19, Blocks.leaves, 0);
		this.setBlock(world, i + 11, j + 41, k + 20, Blocks.leaves, 0);
		this.setBlock(world, i + 11, j + 41, k + 21, Blocks.log, 1);
		this.setBlock(world, i + 11, j + 41, k + 22, Blocks.leaves, 0);
		this.setBlock(world, i + 11, j + 41, k + 23, Blocks.leaves, 0);
		this.setBlock(world, i + 11, j + 41, k + 24, Blocks.leaves, 0);
		this.setBlock(world, i + 11, j + 41, k + 25, Blocks.leaves, 0);
		this.setBlock(world, i + 11, j + 41, k + 26, Blocks.leaves, 0);
		this.setBlock(world, i + 11, j + 41, k + 27, Blocks.leaves, 0);
		this.setBlock(world, i + 11, j + 41, k + 28, Blocks.leaves, 0);
		this.setBlock(world, i + 11, j + 41, k + 29, Blocks.leaves, 0);
		this.setBlock(world, i + 11, j + 41, k + 30, Blocks.leaves, 0);
		this.setBlock(world, i + 11, j + 41, k + 31, Blocks.leaves, 0);
		this.setBlock(world, i + 11, j + 41, k + 32, Blocks.leaves, 0);
		this.setBlock(world, i + 11, j + 41, k + 33, Blocks.leaves, 0);
		this.setBlock(world, i + 11, j + 41, k + 34, Blocks.leaves, 0);
		this.setBlock(world, i + 11, j + 41, k + 35, Blocks.leaves, 0);

		generate2(world, rand, i, j, k);
		return true;
	}

	public boolean generate2(World world, Random rand, int i, int j, int k) {
		this.setBlock(world, i + 11, j + 41, k + 36, Blocks.leaves, 0);
		this.setBlock(world, i + 11, j + 41, k + 37, Blocks.leaves, 0);
		this.setBlock(world, i + 11, j + 41, k + 38, Blocks.leaves, 0);
		this.setBlock(world, i + 11, j + 41, k + 39, Blocks.leaves, 0);
		this.setBlock(world, i + 11, j + 41, k + 40, Blocks.leaves, 0);
		this.setBlock(world, i + 11, j + 41, k + 41, Blocks.log, 1);
		this.setBlock(world, i + 11, j + 41, k + 42, Blocks.log, 1);
		this.setBlock(world, i + 11, j + 41, k + 43, Blocks.leaves, 0);
		this.setBlock(world, i + 11, j + 41, k + 44, Blocks.leaves, 0);
		this.setBlock(world, i + 11, j + 41, k + 45, Blocks.log, 1);
		this.setBlock(world, i + 11, j + 41, k + 46, Blocks.leaves, 0);
		this.setBlock(world, i + 11, j + 41, k + 47, Blocks.leaves, 0);
		this.setBlock(world, i + 11, j + 42, k + 5, Blocks.log, 1);
		this.setBlock(world, i + 11, j + 42, k + 6, Blocks.leaves, 0);
		this.setBlock(world, i + 11, j + 42, k + 7, Blocks.leaves, 0);
		this.setBlock(world, i + 11, j + 42, k + 8, Blocks.leaves, 0);
		this.setBlock(world, i + 11, j + 42, k + 9, Blocks.leaves, 0);
		this.setBlock(world, i + 11, j + 42, k + 10, Blocks.leaves, 0);
		this.setBlock(world, i + 11, j + 42, k + 11, Blocks.leaves, 0);
		this.setBlock(world, i + 11, j + 42, k + 12, Blocks.leaves, 0);
		this.setBlock(world, i + 11, j + 42, k + 13, Blocks.leaves, 0);
		this.setBlock(world, i + 11, j + 42, k + 14, Blocks.leaves, 0);
		this.setBlock(world, i + 11, j + 42, k + 15, Blocks.leaves, 0);
		this.setBlock(world, i + 11, j + 42, k + 16, Blocks.leaves, 0);
		this.setBlock(world, i + 11, j + 42, k + 17, Blocks.leaves, 0);
		this.setBlock(world, i + 11, j + 42, k + 18, Blocks.leaves, 0);
		this.setBlock(world, i + 11, j + 42, k + 19, Blocks.leaves, 0);
		this.setBlock(world, i + 11, j + 42, k + 20, Blocks.leaves, 0);
		this.setBlock(world, i + 11, j + 42, k + 21, Blocks.leaves, 0);
		this.setBlock(world, i + 11, j + 42, k + 22, Blocks.leaves, 0);
		this.setBlock(world, i + 11, j + 42, k + 23, Blocks.leaves, 0);
