/*
*** MADE BY MRPONYCAPTAIN'S .SCHEMATIC TO .JAVA CONVERTING TOOL v2.0 ***
*/

package com.DavidM1A2.AfraidOfTheDark.common.worldGeneration.darkForestDungeon;

import java.util.Random;
import net.minecraft.block.Block;
import net.minecraft.init.Blocks;
import net.minecraft.tileentity.TileEntity;
import net.minecraft.tileentity.TileEntityChest;
import net.minecraft.tileentity.TileEntityMobSpawner;
import net.minecraft.util.BlockPos;
import net.minecraft.util.WeightedRandomChestContent;
import net.minecraft.world.World;
import java.util.Random;

public class TreeSmall
{
	public TreeSmall(World world, Random rand, int x, int y, int z) 
	{
		this.generate(world, rand, x, y, z);
	}

	public void setBlock(World world, int x, int y, int z, Block block, int metadata)
	{
		world.setBlockState(new BlockPos(x, y, z), block.getStateFromMeta(metadata));
	}
	
	public boolean generate(World world, Random rand, int i, int j, int k) {
		this.setBlock(world, i + 0, j + 36, k + 7, Blocks.leaves, 0);
		this.setBlock(world, i + 0, j + 36, k + 9, Blocks.leaves, 0);
		this.setBlock(world, i + 1, j + 31, k + 26, Blocks.leaves, 0);
		this.setBlock(world, i + 1, j + 35, k + 6, Blocks.leaves, 0);
		this.setBlock(world, i + 1, j + 35, k + 7, Blocks.log, 1);
		this.setBlock(world, i + 1, j + 35, k + 8, Blocks.leaves, 0);
		this.setBlock(world, i + 1, j + 35, k + 9, Blocks.leaves, 0);
		this.setBlock(world, i + 1, j + 35, k + 10, Blocks.leaves, 0);
		this.setBlock(world, i + 1, j + 35, k + 12, Blocks.leaves, 0);
		this.setBlock(world, i + 1, j + 36, k + 6, Blocks.leaves, 0);
		this.setBlock(world, i + 1, j + 36, k + 7, Blocks.leaves, 0);
		this.setBlock(world, i + 1, j + 36, k + 8, Blocks.leaves, 0);
		this.setBlock(world, i + 1, j + 36, k + 9, Blocks.leaves, 0);
		this.setBlock(world, i + 1, j + 36, k + 10, Blocks.leaves, 0);
		this.setBlock(world, i + 1, j + 37, k + 9, Blocks.leaves, 0);
		this.setBlock(world, i + 1, j + 37, k + 10, Blocks.leaves, 0);
		this.setBlock(world, i + 2, j + 30, k + 25, Blocks.leaves, 0);
		this.setBlock(world, i + 2, j + 30, k + 26, Blocks.log, 1);
		this.setBlock(world, i + 2, j + 30, k + 27, Blocks.leaves, 0);
		this.setBlock(world, i + 2, j + 31, k + 25, Blocks.leaves, 0);
		this.setBlock(world, i + 2, j + 31, k + 26, Blocks.leaves, 0);
		this.setBlock(world, i + 2, j + 31, k + 27, Blocks.leaves, 0);
		this.setBlock(world, i + 2, j + 32, k + 25, Blocks.leaves, 0);
		this.setBlock(world, i + 2, j + 32, k + 26, Blocks.leaves, 0);
		this.setBlock(world, i + 2, j + 32, k + 27, Blocks.leaves, 0);
		this.setBlock(world, i + 2, j + 32, k + 29, Blocks.leaves, 0);
		this.setBlock(world, i + 2, j + 34, k + 5, Blocks.leaves, 0);
		this.setBlock(world, i + 2, j + 34, k + 6, Blocks.leaves, 0);
		this.setBlock(world, i + 2, j + 34, k + 7, Blocks.leaves, 0);
		this.setBlock(world, i + 2, j + 34, k + 8, Blocks.leaves, 0);
		this.setBlock(world, i + 2, j + 34, k + 9, Blocks.leaves, 0);
		this.setBlock(world, i + 2, j + 34, k + 11, Blocks.leaves, 0);
		this.setBlock(world, i + 2, j + 34, k + 12, Blocks.leaves, 0);
		this.setBlock(world, i + 2, j + 34, k + 13, Blocks.leaves, 0);
		this.setBlock(world, i + 2, j + 35, k + 5, Blocks.leaves, 0);
		this.setBlock(world, i + 2, j + 35, k + 6, Blocks.leaves, 0);
		this.setBlock(world, i + 2, j + 35, k + 7, Blocks.log, 1);
		this.setBlock(world, i + 2, j + 35, k + 8, Blocks.log, 1);
		this.setBlock(world, i + 2, j + 35, k + 9, Blocks.log, 1);
		this.setBlock(world, i + 2, j + 35, k + 10, Blocks.leaves, 0);
		this.setBlock(world, i + 2, j + 35, k + 11, Blocks.leaves, 0);
		this.setBlock(world, i + 2, j + 35, k + 12, Blocks.leaves, 0);
		this.setBlock(world, i + 2, j + 35, k + 13, Blocks.leaves, 0);
		this.setBlock(world, i + 2, j + 36, k + 5, Blocks.leaves, 0);
		this.setBlock(world, i + 2, j + 36, k + 6, Blocks.leaves, 0);
		this.setBlock(world, i + 2, j + 36, k + 7, Blocks.leaves, 0);
		this.setBlock(world, i + 2, j + 36, k + 8, Blocks.leaves, 0);
		this.setBlock(world, i + 2, j + 36, k + 9, Blocks.leaves, 0);
		this.setBlock(world, i + 2, j + 36, k + 10, Blocks.leaves, 0);
		this.setBlock(world, i + 2, j + 36, k + 11, Blocks.leaves, 0);
		this.setBlock(world, i + 2, j + 36, k + 12, Blocks.leaves, 0);
		this.setBlock(world, i + 2, j + 36, k + 13, Blocks.leaves, 0);
		this.setBlock(world, i + 2, j + 37, k + 7, Blocks.leaves, 0);
		this.setBlock(world, i + 2, j + 37, k + 8, Blocks.leaves, 0);
		this.setBlock(world, i + 2, j + 37, k + 9, Blocks.leaves, 0);
		this.setBlock(world, i + 2, j + 37, k + 10, Blocks.leaves, 0);
		this.setBlock(world, i + 3, j + 29, k + 26, Blocks.log, 1);
		this.setBlock(world, i + 3, j + 30, k + 25, Blocks.leaves, 0);
		this.setBlock(world, i + 3, j + 30, k + 26, Blocks.leaves, 0);
		this.setBlock(world, i + 3, j + 30, k + 27, Blocks.leaves, 0);
		this.setBlock(world, i + 3, j + 31, k + 24, Blocks.leaves, 0);
		this.setBlock(world, i + 3, j + 31, k + 25, Blocks.leaves, 0);
		this.setBlock(world, i + 3, j + 31, k + 26, Blocks.leaves, 0);
		this.setBlock(world, i + 3, j + 31, k + 27, Blocks.leaves, 0);
		this.setBlock(world, i + 3, j + 31, k + 28, Blocks.leaves, 0);
		this.setBlock(world, i + 3, j + 31, k + 29, Blocks.leaves, 0);
		this.setBlock(world, i + 3, j + 31, k + 30, Blocks.leaves, 0);
		this.setBlock(world, i + 3, j + 32, k + 24, Blocks.leaves, 0);
		this.setBlock(world, i + 3, j + 32, k + 25, Blocks.leaves, 0);
		this.setBlock(world, i + 3, j + 32, k + 26, Blocks.leaves, 0);
		this.setBlock(world, i + 3, j + 32, k + 27, Blocks.leaves, 0);
		this.setBlock(world, i + 3, j + 32, k + 28, Blocks.leaves, 0);
		this.setBlock(world, i + 3, j + 32, k + 29, Blocks.leaves, 0);
		this.setBlock(world, i + 3, j + 32, k + 30, Blocks.leaves, 0);
		this.setBlock(world, i + 3, j + 33, k + 6, Blocks.leaves, 0);
		this.setBlock(world, i + 3, j + 33, k + 8, Blocks.leaves, 0);
		this.setBlock(world, i + 3, j + 33, k + 12, Blocks.leaves, 0);
		this.setBlock(world, i + 3, j + 33, k + 24, Blocks.leaves, 0);
		this.setBlock(world, i + 3, j + 33, k + 25, Blocks.leaves, 0);
		this.setBlock(world, i + 3, j + 33, k + 26, Blocks.leaves, 0);
		this.setBlock(world, i + 3, j + 33, k + 28, Blocks.leaves, 0);
		this.setBlock(world, i + 3, j + 33, k + 29, Blocks.leaves, 0);
		this.setBlock(world, i + 3, j + 33, k + 30, Blocks.leaves, 0);
		this.setBlock(world, i + 3, j + 34, k + 5, Blocks.leaves, 0);
		this.setBlock(world, i + 3, j + 34, k + 6, Blocks.log, 1);
		this.setBlock(world, i + 3, j + 34, k + 7, Blocks.leaves, 0);
		this.setBlock(world, i + 3, j + 34, k + 8, Blocks.leaves, 0);
		this.setBlock(world, i + 3, j + 34, k + 9, Blocks.leaves, 0);
		this.setBlock(world, i + 3, j + 34, k + 10, Blocks.leaves, 0);
		this.setBlock(world, i + 3, j + 34, k + 11, Blocks.leaves, 0);
		this.setBlock(world, i + 3, j + 34, k + 12, Blocks.leaves, 0);
		this.setBlock(world, i + 3, j + 34, k + 13, Blocks.leaves, 0);
		this.setBlock(world, i + 3, j + 35, k + 4, Blocks.leaves, 0);
		this.setBlock(world, i + 3, j + 35, k + 5, Blocks.leaves, 0);
		this.setBlock(world, i + 3, j + 35, k + 6, Blocks.leaves, 0);
		this.setBlock(world, i + 3, j + 35, k + 7, Blocks.leaves, 0);
		this.setBlock(world, i + 3, j + 35, k + 8, Blocks.leaves, 0);
		this.setBlock(world, i + 3, j + 35, k + 9, Blocks.leaves, 0);
		this.setBlock(world, i + 3, j + 35, k + 10, Blocks.leaves, 0);
		this.setBlock(world, i + 3, j + 35, k + 11, Blocks.leaves, 0);
		this.setBlock(world, i + 3, j + 35, k + 12, Blocks.leaves, 0);
		this.setBlock(world, i + 3, j + 35, k + 13, Blocks.leaves, 0);
		this.setBlock(world, i + 3, j + 35, k + 14, Blocks.leaves, 0);
		this.setBlock(world, i + 3, j + 36, k + 5, Blocks.leaves, 0);
		this.setBlock(world, i + 3, j + 36, k + 6, Blocks.leaves, 0);
		this.setBlock(world, i + 3, j + 36, k + 7, Blocks.leaves, 0);
		this.setBlock(world, i + 3, j + 36, k + 8, Blocks.leaves, 0);
		this.setBlock(world, i + 3, j + 36, k + 9, Blocks.log, 1);
		this.setBlock(world, i + 3, j + 36, k + 10, Blocks.leaves, 0);
		this.setBlock(world, i + 3, j + 36, k + 11, Blocks.leaves, 0);
		this.setBlock(world, i + 3, j + 36, k + 12, Blocks.leaves, 0);
		this.setBlock(world, i + 3, j + 36, k + 13, Blocks.leaves, 0);
		this.setBlock(world, i + 3, j + 36, k + 14, Blocks.leaves, 0);
		this.setBlock(world, i + 3, j + 37, k + 7, Blocks.leaves, 0);
		this.setBlock(world, i + 3, j + 37, k + 8, Blocks.leaves, 0);
		this.setBlock(world, i + 3, j + 37, k + 9, Blocks.leaves, 0);
		this.setBlock(world, i + 3, j + 37, k + 10, Blocks.leaves, 0);
		this.setBlock(world, i + 3, j + 37, k + 12, Blocks.leaves, 0);
		this.setBlock(world, i + 3, j + 38, k + 8, Blocks.leaves, 0);
		this.setBlock(world, i + 3, j + 38, k + 9, Blocks.leaves, 0);
		this.setBlock(world, i + 4, j + 30, k + 25, Blocks.leaves, 0);
		this.setBlock(world, i + 4, j + 30, k + 26, Blocks.leaves, 0);
		this.setBlock(world, i + 4, j + 30, k + 27, Blocks.leaves, 0);
		this.setBlock(world, i + 4, j + 30, k + 29, Blocks.log, 1);
		this.setBlock(world, i + 4, j + 31, k + 24, Blocks.log, 1);
		this.setBlock(world, i + 4, j + 31, k + 25, Blocks.leaves, 0);
		this.setBlock(world, i + 4, j + 31, k + 26, Blocks.log, 1);
		this.setBlock(world, i + 4, j + 31, k + 27, Blocks.leaves, 0);
		this.setBlock(world, i + 4, j + 31, k + 28, Blocks.leaves, 0);
		this.setBlock(world, i + 4, j + 31, k + 29, Blocks.leaves, 0);
		this.setBlock(world, i + 4, j + 31, k + 30, Blocks.leaves, 0);
		this.setBlock(world, i + 4, j + 31, k + 31, Blocks.log, 1);
		this.setBlock(world, i + 4, j + 32, k + 23, Blocks.leaves, 0);
		this.setBlock(world, i + 4, j + 32, k + 24, Blocks.leaves, 0);
		this.setBlock(world, i + 4, j + 32, k + 25, Blocks.leaves, 0);
		this.setBlock(world, i + 4, j + 32, k + 26, Blocks.leaves, 0);
		this.setBlock(world, i + 4, j + 32, k + 27, Blocks.leaves, 0);
		this.setBlock(world, i + 4, j + 32, k + 28, Blocks.leaves, 0);
		this.setBlock(world, i + 4, j + 32, k + 29, Blocks.leaves, 0);
		this.setBlock(world, i + 4, j + 32, k + 30, Blocks.leaves, 0);
		this.setBlock(world, i + 4, j + 32, k + 31, Blocks.leaves, 0);
		this.setBlock(world, i + 4, j + 33, k + 7, Blocks.leaves, 0);
		this.setBlock(world, i + 4, j + 33, k + 11, Blocks.leaves, 0);
		this.setBlock(world, i + 4, j + 33, k + 24, Blocks.leaves, 0);
		this.setBlock(world, i + 4, j + 33, k + 25, Blocks.leaves, 0);
		this.setBlock(world, i + 4, j + 33, k + 26, Blocks.leaves, 0);
		this.setBlock(world, i + 4, j + 33, k + 27, Blocks.leaves, 0);
		this.setBlock(world, i + 4, j + 33, k + 28, Blocks.leaves, 0);
		this.setBlock(world, i + 4, j + 33, k + 29, Blocks.leaves, 0);
		this.setBlock(world, i + 4, j + 33, k + 30, Blocks.leaves, 0);
		this.setBlock(world, i + 4, j + 34, k + 3, Blocks.leaves, 0);
		this.setBlock(world, i + 4, j + 34, k + 4, Blocks.leaves, 0);
		this.setBlock(world, i + 4, j + 34, k + 5, Blocks.leaves, 0);
		this.setBlock(world, i + 4, j + 34, k + 6, Blocks.log, 1);
		this.setBlock(world, i + 4, j + 34, k + 7, Blocks.log, 1);
		this.setBlock(world, i + 4, j + 34, k + 8, Blocks.leaves, 0);
		this.setBlock(world, i + 4, j + 34, k + 9, Blocks.leaves, 0);
		this.setBlock(world, i + 4, j + 34, k + 10, Blocks.leaves, 0);
		this.setBlock(world, i + 4, j + 34, k + 11, Blocks.leaves, 0);
		this.setBlock(world, i + 4, j + 34, k + 12, Blocks.leaves, 0);
		this.setBlock(world, i + 4, j + 34, k + 13, Blocks.leaves, 0);
		this.setBlock(world, i + 4, j + 34, k + 17, Blocks.leaves, 0);
		this.setBlock(world, i + 4, j + 34, k + 25, Blocks.leaves, 0);
		this.setBlock(world, i + 4, j + 34, k + 29, Blocks.leaves, 0);
		this.setBlock(world, i + 4, j + 35, k + 3, Blocks.log, 1);
		this.setBlock(world, i + 4, j + 35, k + 4, Blocks.leaves, 0);
		this.setBlock(world, i + 4, j + 35, k + 5, Blocks.leaves, 0);
		this.setBlock(world, i + 4, j + 35, k + 6, Blocks.leaves, 0);
		this.setBlock(world, i + 4, j + 35, k + 7, Blocks.leaves, 0);
		this.setBlock(world, i + 4, j + 35, k + 8, Blocks.leaves, 0);
		this.setBlock(world, i + 4, j + 35, k + 9, Blocks.log, 1);
		this.setBlock(world, i + 4, j + 35, k + 10, Blocks.leaves, 0);
		this.setBlock(world, i + 4, j + 35, k + 11, Blocks.leaves, 0);
		this.setBlock(world, i + 4, j + 35, k + 12, Blocks.leaves, 0);
		this.setBlock(world, i + 4, j + 35, k + 13, Blocks.log, 1);
		this.setBlock(world, i + 4, j + 35, k + 14, Blocks.leaves, 0);
		this.setBlock(world, i + 4, j + 35, k + 15, Blocks.leaves, 0);
		this.setBlock(world, i + 4, j + 36, k + 3, Blocks.leaves, 0);
		this.setBlock(world, i + 4, j + 36, k + 5, Blocks.leaves, 0);
		this.setBlock(world, i + 4, j + 36, k + 6, Blocks.leaves, 0);
		this.setBlock(world, i + 4, j + 36, k + 7, Blocks.leaves, 0);
		this.setBlock(world, i + 4, j + 36, k + 8, Blocks.leaves, 0);
		this.setBlock(world, i + 4, j + 36, k + 9, Blocks.leaves, 0);
		this.setBlock(world, i + 4, j + 36, k + 10, Blocks.leaves, 0);
		this.setBlock(world, i + 4, j + 36, k + 11, Blocks.log, 1);
		this.setBlock(world, i + 4, j + 36, k + 12, Blocks.leaves, 0);
		this.setBlock(world, i + 4, j + 36, k + 13, Blocks.log, 1);
		this.setBlock(world, i + 4, j + 36, k + 14, Blocks.leaves, 0);
		this.setBlock(world, i + 4, j + 36, k + 15, Blocks.leaves, 0);
		this.setBlock(world, i + 4, j + 37, k + 6, Blocks.leaves, 0);
		this.setBlock(world, i + 4, j + 37, k + 7, Blocks.leaves, 0);
		this.setBlock(world, i + 4, j + 37, k + 8, Blocks.leaves, 0);
		this.setBlock(world, i + 4, j + 37, k + 9, Blocks.leaves, 0);
		this.setBlock(world, i + 4, j + 37, k + 10, Blocks.leaves, 0);
		this.setBlock(world, i + 4, j + 37, k + 11, Blocks.leaves, 0);
		this.setBlock(world, i + 4, j + 37, k + 13, Blocks.leaves, 0);
		this.setBlock(world, i + 4, j + 37, k + 14, Blocks.leaves, 0);
		this.setBlock(world, i + 4, j + 37, k + 15, Blocks.leaves, 0);
		this.setBlock(world, i + 4, j + 38, k + 8, Blocks.leaves, 0);
		this.setBlock(world, i + 4, j + 38, k + 9, Blocks.leaves, 0);
		this.setBlock(world, i + 4, j + 38, k + 10, Blocks.leaves, 0);
		this.setBlock(world, i + 4, j + 38, k + 11, Blocks.leaves, 0);
		this.setBlock(world, i + 5, j + 30, k + 27, Blocks.leaves, 0);
		this.setBlock(world, i + 5, j + 30, k + 28, Blocks.leaves, 0);
		this.setBlock(world, i + 5, j + 30, k + 29, Blocks.leaves, 0);
		this.setBlock(world, i + 5, j + 30, k + 30, Blocks.leaves, 0);
		this.setBlock(world, i + 5, j + 30, k + 31, Blocks.leaves, 0);
		this.setBlock(world, i + 5, j + 30, k + 32, Blocks.leaves, 0);
		this.setBlock(world, i + 5, j + 31, k + 24, Blocks.leaves, 0);
		this.setBlock(world, i + 5, j + 31, k + 25, Blocks.leaves, 0);
		this.setBlock(world, i + 5, j + 31, k + 26, Blocks.log, 1);
		this.setBlock(world, i + 5, j + 31, k + 27, Blocks.leaves, 0);
		this.setBlock(world, i + 5, j + 31, k + 28, Blocks.leaves, 0);
		this.setBlock(world, i + 5, j + 31, k + 29, Blocks.leaves, 0);
		this.setBlock(world, i + 5, j + 31, k + 30, Blocks.leaves, 0);
		this.setBlock(world, i + 5, j + 31, k + 31, Blocks.leaves, 0);
		this.setBlock(world, i + 5, j + 31, k + 32, Blocks.leaves, 0);
		this.setBlock(world, i + 5, j + 32, k + 6, Blocks.log, 1);
		this.setBlock(world, i + 5, j + 32, k + 7, Blocks.log, 1);
		this.setBlock(world, i + 5, j + 32, k + 8, Blocks.leaves, 0);
		this.setBlock(world, i + 5, j + 32, k + 20, Blocks.leaves, 0);
		this.setBlock(world, i + 5, j + 32, k + 24, Blocks.leaves, 0);
		this.setBlock(world, i + 5, j + 32, k + 25, Blocks.leaves, 0);
		this.setBlock(world, i + 5, j + 32, k + 26, Blocks.leaves, 0);
		this.setBlock(world, i + 5, j + 32, k + 27, Blocks.log, 1);
		this.setBlock(world, i + 5, j + 32, k + 28, Blocks.log, 1);
		this.setBlock(world, i + 5, j + 32, k + 29, Blocks.leaves, 0);
		this.setBlock(world, i + 5, j + 32, k + 30, Blocks.leaves, 0);
		this.setBlock(world, i + 5, j + 32, k + 31, Blocks.leaves, 0);
		this.setBlock(world, i + 5, j + 32, k + 32, Blocks.leaves, 0);
		this.setBlock(world, i + 5, j + 33, k + 4, Blocks.leaves, 0);
		this.setBlock(world, i + 5, j + 33, k + 6, Blocks.leaves, 0);
		this.setBlock(world, i + 5, j + 33, k + 7, Blocks.leaves, 0);
		this.setBlock(world, i + 5, j + 33, k + 8, Blocks.leaves, 0);
		this.setBlock(world, i + 5, j + 33, k + 10, Blocks.leaves, 0);
		this.setBlock(world, i + 5, j + 33, k + 15, Blocks.leaves, 0);
		this.setBlock(world, i + 5, j + 33, k + 16, Blocks.leaves, 0);
		this.setBlock(world, i + 5, j + 33, k + 17, Blocks.leaves, 0);
		this.setBlock(world, i + 5, j + 33, k + 18, Blocks.log, 1);
		this.setBlock(world, i + 5, j + 33, k + 24, Blocks.leaves, 0);
		this.setBlock(world, i + 5, j + 33, k + 25, Blocks.leaves, 0);
		this.setBlock(world, i + 5, j + 33, k + 26, Blocks.leaves, 0);
		this.setBlock(world, i + 5, j + 33, k + 27, Blocks.leaves, 0);
		this.setBlock(world, i + 5, j + 33, k + 28, Blocks.log, 1);
		this.setBlock(world, i + 5, j + 33, k + 29, Blocks.leaves, 0);
		this.setBlock(world, i + 5, j + 33, k + 30, Blocks.leaves, 0);
		this.setBlock(world, i + 5, j + 34, k + 3, Blocks.leaves, 0);
		this.setBlock(world, i + 5, j + 34, k + 4, Blocks.leaves, 0);
		this.setBlock(world, i + 5, j + 34, k + 5, Blocks.leaves, 0);
		this.setBlock(world, i + 5, j + 34, k + 6, Blocks.leaves, 0);
		this.setBlock(world, i + 5, j + 34, k + 7, Blocks.leaves, 0);
		this.setBlock(world, i + 5, j + 34, k + 8, Blocks.log, 1);
		this.setBlock(world, i + 5, j + 34, k + 9, Blocks.leaves, 0);
		this.setBlock(world, i + 5, j + 34, k + 10, Blocks.leaves, 0);
		this.setBlock(world, i + 5, j + 34, k + 11, Blocks.leaves, 0);
		this.setBlock(world, i + 5, j + 34, k + 12, Blocks.leaves, 0);
		this.setBlock(world, i + 5, j + 34, k + 13, Blocks.leaves, 0);
		this.setBlock(world, i + 5, j + 34, k + 14, Blocks.leaves, 0);
		this.setBlock(world, i + 5, j + 34, k + 16, Blocks.leaves, 0);
		this.setBlock(world, i + 5, j + 34, k + 17, Blocks.leaves, 0);
		this.setBlock(world, i + 5, j + 34, k + 18, Blocks.leaves, 0);
		this.setBlock(world, i + 5, j + 34, k + 28, Blocks.leaves, 0);
		this.setBlock(world, i + 5, j + 34, k + 29, Blocks.leaves, 0);
		this.setBlock(world, i + 5, j + 34, k + 30, Blocks.leaves, 0);
		this.setBlock(world, i + 5, j + 35, k + 2, Blocks.leaves, 0);
		this.setBlock(world, i + 5, j + 35, k + 3, Blocks.leaves, 0);
		this.setBlock(world, i + 5, j + 35, k + 4, Blocks.leaves, 0);
		this.setBlock(world, i + 5, j + 35, k + 5, Blocks.log, 1);
		this.setBlock(world, i + 5, j + 35, k + 6, Blocks.leaves, 0);
		this.setBlock(world, i + 5, j + 35, k + 7, Blocks.log, 1);
		this.setBlock(world, i + 5, j + 35, k + 8, Blocks.leaves, 0);
		this.setBlock(world, i + 5, j + 35, k + 9, Blocks.log, 1);
		this.setBlock(world, i + 5, j + 35, k + 10, Blocks.leaves, 0);
		this.setBlock(world, i + 5, j + 35, k + 11, Blocks.leaves, 0);
		this.setBlock(world, i + 5, j + 35, k + 12, Blocks.leaves, 0);
		this.setBlock(world, i + 5, j + 35, k + 13, Blocks.leaves, 0);
		this.setBlock(world, i + 5, j + 35, k + 14, Blocks.leaves, 0);
		this.setBlock(world, i + 5, j + 35, k + 15, Blocks.leaves, 0);
		this.setBlock(world, i + 5, j + 35, k + 16, Blocks.leaves, 0);
		this.setBlock(world, i + 5, j + 35, k + 17, Blocks.leaves, 0);
		this.setBlock(world, i + 5, j + 35, k + 18, Blocks.leaves, 0);
		this.setBlock(world, i + 5, j + 35, k + 28, Blocks.leaves, 0);
		this.setBlock(world, i + 5, j + 35, k + 29, Blocks.leaves, 0);
		this.setBlock(world, i + 5, j + 35, k + 30, Blocks.leaves, 0);
		this.setBlock(world, i + 5, j + 36, k + 3, Blocks.leaves, 0);
		this.setBlock(world, i + 5, j + 36, k + 4, Blocks.leaves, 0);
		this.setBlock(world, i + 5, j + 36, k + 5, Blocks.leaves, 0);
		this.setBlock(world, i + 5, j + 36, k + 6, Blocks.log, 1);
		this.setBlock(world, i + 5, j + 36, k + 7, Blocks.leaves, 0);
		this.setBlock(world, i + 5, j + 36, k + 8, Blocks.leaves, 0);
		this.setBlock(world, i + 5, j + 36, k + 9, Blocks.leaves, 0);
		this.setBlock(world, i + 5, j + 36, k + 10, Blocks.leaves, 0);
		this.setBlock(world, i + 5, j + 36, k + 11, Blocks.leaves, 0);
		this.setBlock(world, i + 5, j + 36, k + 12, Blocks.leaves, 0);
		this.setBlock(world, i + 5, j + 36, k + 13, Blocks.leaves, 0);
		this.setBlock(world, i + 5, j + 36, k + 14, Blocks.log, 1);
		this.setBlock(world, i + 5, j + 36, k + 15, Blocks.leaves, 0);
		this.setBlock(world, i + 5, j + 36, k + 16, Blocks.leaves, 0);
		this.setBlock(world, i + 5, j + 37, k + 5, Blocks.leaves, 0);
		this.setBlock(world, i + 5, j + 37, k + 6, Blocks.leaves, 0);
		this.setBlock(world, i + 5, j + 37, k + 7, Blocks.leaves, 0);
		this.setBlock(world, i + 5, j + 37, k + 8, Blocks.log, 1);
		this.setBlock(world, i + 5, j + 37, k + 9, Blocks.leaves, 0);
		this.setBlock(world, i + 5, j + 37, k + 10, Blocks.leaves, 0);
		this.setBlock(world, i + 5, j + 37, k + 11, Blocks.leaves, 0);
		this.setBlock(world, i + 5, j + 37, k + 12, Blocks.leaves, 0);
		this.setBlock(world, i + 5, j + 37, k + 13, Blocks.leaves, 0);
		this.setBlock(world, i + 5, j + 37, k + 14, Blocks.leaves, 0);
		this.setBlock(world, i + 5, j + 37, k + 15, Blocks.leaves, 0);
		this.setBlock(world, i + 5, j + 38, k + 8, Blocks.leaves, 0);
		this.setBlock(world, i + 5, j + 38, k + 9, Blocks.leaves, 0);
		this.setBlock(world, i + 5, j + 38, k + 10, Blocks.leaves, 0);
		this.setBlock(world, i + 5, j + 38, k + 11, Blocks.leaves, 0);
		this.setBlock(world, i + 5, j + 38, k + 12, Blocks.leaves, 0);
		this.setBlock(world, i + 5, j + 38, k + 14, Blocks.leaves, 0);
		this.setBlock(world, i + 6, j + 29, k + 28, Blocks.leaves, 0);
		this.setBlock(world, i + 6, j + 29, k + 31, Blocks.leaves, 0);
		this.setBlock(world, i + 6, j + 30, k + 25, Blocks.leaves, 0);
		this.setBlock(world, i + 6, j + 30, k + 27, Blocks.leaves, 0);
		this.setBlock(world, i + 6, j + 30, k + 28, Blocks.leaves, 0);
		this.setBlock(world, i + 6, j + 30, k + 29, Blocks.leaves, 0);
		this.setBlock(world, i + 6, j + 30, k + 30, Blocks.log, 1);
		this.setBlock(world, i + 6, j + 30, k + 31, Blocks.log, 1);
		this.setBlock(world, i + 6, j + 30, k + 32, Blocks.leaves, 0);
		this.setBlock(world, i + 6, j + 31, k + 6, Blocks.log, 1);
		this.setBlock(world, i + 6, j + 31, k + 7, Blocks.log, 1);
		this.setBlock(world, i + 6, j + 31, k + 19, Blocks.leaves, 0);
		this.setBlock(world, i + 6, j + 31, k + 20, Blocks.leaves, 0);
		this.setBlock(world, i + 6, j + 31, k + 21, Blocks.leaves, 0);
		this.setBlock(world, i + 6, j + 31, k + 24, Blocks.log, 1);
		this.setBlock(world, i + 6, j + 31, k + 25, Blocks.leaves, 0);
		this.setBlock(world, i + 6, j + 31, k + 26, Blocks.leaves, 0);
		this.setBlock(world, i + 6, j + 31, k + 27, Blocks.log, 1);
		this.setBlock(world, i + 6, j + 31, k + 28, Blocks.log, 1);
		this.setBlock(world, i + 6, j + 31, k + 29, Blocks.leaves, 0);
		this.setBlock(world, i + 6, j + 31, k + 30, Blocks.leaves, 0);
		this.setBlock(world, i + 6, j + 31, k + 31, Blocks.leaves, 0);
		this.setBlock(world, i + 6, j + 31, k + 32, Blocks.leaves, 0);
		this.setBlock(world, i + 6, j + 31, k + 33, Blocks.leaves, 0);
		this.setBlock(world, i + 6, j + 32, k + 5, Blocks.log, 1);
		this.setBlock(world, i + 6, j + 32, k + 6, Blocks.log, 1);
		this.setBlock(world, i + 6, j + 32, k + 7, Blocks.log, 1);
		this.setBlock(world, i + 6, j + 32, k + 8, Blocks.log, 1);
		this.setBlock(world, i + 6, j + 32, k + 14, Blocks.leaves, 0);
		this.setBlock(world, i + 6, j + 32, k + 15, Blocks.leaves, 0);
		this.setBlock(world, i + 6, j + 32, k + 16, Blocks.leaves, 0);
		this.setBlock(world, i + 6, j + 32, k + 17, Blocks.leaves, 0);
		this.setBlock(world, i + 6, j + 32, k + 18, Blocks.leaves, 0);
		this.setBlock(world, i + 6, j + 32, k + 19, Blocks.leaves, 0);
		this.setBlock(world, i + 6, j + 32, k + 20, Blocks.leaves, 0);
		this.setBlock(world, i + 6, j + 32, k + 21, Blocks.leaves, 0);
		this.setBlock(world, i + 6, j + 32, k + 23, Blocks.leaves, 0);
		this.setBlock(world, i + 6, j + 32, k + 24, Blocks.leaves, 0);
		this.setBlock(world, i + 6, j + 32, k + 25, Blocks.leaves, 0);
		this.setBlock(world, i + 6, j + 32, k + 26, Blocks.log, 1);
		this.setBlock(world, i + 6, j + 32, k + 27, Blocks.log, 1);
		this.setBlock(world, i + 6, j + 32, k + 28, Blocks.log, 1);
		this.setBlock(world, i + 6, j + 32, k + 29, Blocks.log, 1);
		this.setBlock(world, i + 6, j + 32, k + 30, Blocks.leaves, 0);
		this.setBlock(world, i + 6, j + 32, k + 31, Blocks.log, 1);
		this.setBlock(world, i + 6, j + 32, k + 32, Blocks.leaves, 0);
		this.setBlock(world, i + 6, j + 32, k + 33, Blocks.leaves, 0);
		this.setBlock(world, i + 6, j + 33, k + 5, Blocks.log, 1);
		this.setBlock(world, i + 6, j + 33, k + 6, Blocks.log, 1);
		this.setBlock(world, i + 6, j + 33, k + 7, Blocks.log, 1);
		this.setBlock(world, i + 6, j + 33, k + 8, Blocks.leaves, 0);
		this.setBlock(world, i + 6, j + 33, k + 9, Blocks.leaves, 0);
		this.setBlock(world, i + 6, j + 33, k + 11, Blocks.leaves, 0);
		this.setBlock(world, i + 6, j + 33, k + 13, Blocks.leaves, 0);
		this.setBlock(world, i + 6, j + 33, k + 14, Blocks.log, 1);
		this.setBlock(world, i + 6, j + 33, k + 15, Blocks.log, 1);
		this.setBlock(world, i + 6, j + 33, k + 16, Blocks.leaves, 0);
		this.setBlock(world, i + 6, j + 33, k + 17, Blocks.leaves, 0);
		this.setBlock(world, i + 6, j + 33, k + 18, Blocks.log, 1);
		this.setBlock(world, i + 6, j + 33, k + 19, Blocks.leaves, 0);
		this.setBlock(world, i + 6, j + 33, k + 20, Blocks.leaves, 0);
		this.setBlock(world, i + 6, j + 33, k + 21, Blocks.leaves, 0);
		this.setBlock(world, i + 6, j + 33, k + 24, Blocks.leaves, 0);
		this.setBlock(world, i + 6, j + 33, k + 25, Blocks.leaves, 0);
		this.setBlock(world, i + 6, j + 33, k + 26, Blocks.leaves, 0);
		this.setBlock(world, i + 6, j + 33, k + 27, Blocks.log, 1);
		this.setBlock(world, i + 6, j + 33, k + 28, Blocks.log, 1);
		this.setBlock(world, i + 6, j + 33, k + 29, Blocks.log, 1);
		this.setBlock(world, i + 6, j + 33, k + 30, Blocks.leaves, 0);
		this.setBlock(world, i + 6, j + 33, k + 31, Blocks.leaves, 0);
		this.setBlock(world, i + 6, j + 33, k + 32, Blocks.leaves, 0);
		this.setBlock(world, i + 6, j + 33, k + 33, Blocks.leaves, 0);
		this.setBlock(world, i + 6, j + 34, k + 3, Blocks.leaves, 0);
		this.setBlock(world, i + 6, j + 34, k + 4, Blocks.leaves, 0);
		this.setBlock(world, i + 6, j + 34, k + 5, Blocks.leaves, 0);
		this.setBlock(world, i + 6, j + 34, k + 6, Blocks.leaves, 0);
		this.setBlock(world, i + 6, j + 34, k + 7, Blocks.log, 1);
		this.setBlock(world, i + 6, j + 34, k + 8, Blocks.log, 1);
		this.setBlock(world, i + 6, j + 34, k + 9, Blocks.leaves, 0);
		this.setBlock(world, i + 6, j + 34, k + 10, Blocks.log, 1);
		this.setBlock(world, i + 6, j + 34, k + 11, Blocks.log, 1);
		this.setBlock(world, i + 6, j + 34, k + 12, Blocks.leaves, 0);
		this.setBlock(world, i + 6, j + 34, k + 13, Blocks.leaves, 0);
		this.setBlock(world, i + 6, j + 34, k + 14, Blocks.leaves, 0);
		this.setBlock(world, i + 6, j + 34, k + 15, Blocks.leaves, 0);
		this.setBlock(world, i + 6, j + 34, k + 16, Blocks.leaves, 0);
		this.setBlock(world, i + 6, j + 34, k + 17, Blocks.leaves, 0);
		this.setBlock(world, i + 6, j + 34, k + 18, Blocks.leaves, 0);
		this.setBlock(world, i + 6, j + 34, k + 19, Blocks.leaves, 0);
		this.setBlock(world, i + 6, j + 34, k + 25, Blocks.leaves, 0);
		this.setBlock(world, i + 6, j + 34, k + 26, Blocks.leaves, 0);
		this.setBlock(world, i + 6, j + 34, k + 27, Blocks.leaves, 0);
		this.setBlock(world, i + 6, j + 34, k + 28, Blocks.log, 1);
		this.setBlock(world, i + 6, j + 34, k + 29, Blocks.leaves, 0);
		this.setBlock(world, i + 6, j + 34, k + 30, Blocks.leaves, 0);
		this.setBlock(world, i + 6, j + 34, k + 31, Blocks.leaves, 0);
		this.setBlock(world, i + 6, j + 35, k + 3, Blocks.leaves, 0);
		this.setBlock(world, i + 6, j + 35, k + 4, Blocks.leaves, 0);
		this.setBlock(world, i + 6, j + 35, k + 5, Blocks.leaves, 0);
		this.setBlock(world, i + 6, j + 35, k + 6, Blocks.leaves, 0);
		this.setBlock(world, i + 6, j + 35, k + 7, Blocks.leaves, 0);
		this.setBlock(world, i + 6, j + 35, k + 8, Blocks.leaves, 0);
		this.setBlock(world, i + 6, j + 35, k + 9, Blocks.leaves, 0);
		this.setBlock(world, i + 6, j + 35, k + 10, Blocks.log, 1);
		this.setBlock(world, i + 6, j + 35, k + 11, Blocks.log, 1);
		this.setBlock(world, i + 6, j + 35, k + 12, Blocks.log, 1);
		this.setBlock(world, i + 6, j + 35, k + 13, Blocks.leaves, 0);
		this.setBlock(world, i + 6, j + 35, k + 14, Blocks.leaves, 0);
		this.setBlock(world, i + 6, j + 35, k + 15, Blocks.leaves, 0);
		this.setBlock(world, i + 6, j + 35, k + 16, Blocks.leaves, 0);
		this.setBlock(world, i + 6, j + 35, k + 17, Blocks.leaves, 0);
		this.setBlock(world, i + 6, j + 35, k + 18, Blocks.leaves, 0);
		this.setBlock(world, i + 6, j + 35, k + 28, Blocks.leaves, 0);
		this.setBlock(world, i + 6, j + 35, k + 29, Blocks.leaves, 0);
		this.setBlock(world, i + 6, j + 35, k + 30, Blocks.leaves, 0);
		this.setBlock(world, i + 6, j + 36, k + 4, Blocks.leaves, 0);
		this.setBlock(world, i + 6, j + 36, k + 5, Blocks.leaves, 0);
		this.setBlock(world, i + 6, j + 36, k + 6, Blocks.leaves, 0);
		this.setBlock(world, i + 6, j + 36, k + 7, Blocks.log, 1);
		this.setBlock(world, i + 6, j + 36, k + 8, Blocks.leaves, 0);
		this.setBlock(world, i + 6, j + 36, k + 9, Blocks.leaves, 0);
		this.setBlock(world, i + 6, j + 36, k + 10, Blocks.leaves, 0);
		this.setBlock(world, i + 6, j + 36, k + 11, Blocks.leaves, 0);
		this.setBlock(world, i + 6, j + 36, k + 12, Blocks.leaves, 0);
		this.setBlock(world, i + 6, j + 36, k + 13, Blocks.leaves, 0);
		this.setBlock(world, i + 6, j + 36, k + 14, Blocks.leaves, 0);
		this.setBlock(world, i + 6, j + 36, k + 15, Blocks.leaves, 0);
		this.setBlock(world, i + 6, j + 36, k + 17, Blocks.leaves, 0);
		this.setBlock(world, i + 6, j + 36, k + 29, Blocks.leaves, 0);
		this.setBlock(world, i + 6, j + 37, k + 6, Blocks.leaves, 0);
		this.setBlock(world, i + 6, j + 37, k + 7, Blocks.leaves, 0);
		this.setBlock(world, i + 6, j + 37, k + 8, Blocks.leaves, 0);
		this.setBlock(world, i + 6, j + 37, k + 9, Blocks.leaves, 0);
		this.setBlock(world, i + 6, j + 37, k + 10, Blocks.leaves, 0);
		this.setBlock(world, i + 6, j + 37, k + 11, Blocks.leaves, 0);
		this.setBlock(world, i + 6, j + 37, k + 12, Blocks.leaves, 0);
		this.setBlock(world, i + 6, j + 37, k + 13, Blocks.leaves, 0);
		this.setBlock(world, i + 6, j + 37, k + 14, Blocks.leaves, 0);
		this.setBlock(world, i + 6, j + 37, k + 15, Blocks.leaves, 0);
		this.setBlock(world, i + 6, j + 38, k + 8, Blocks.leaves, 0);
		this.setBlock(world, i + 6, j + 38, k + 9, Blocks.leaves, 0);
		this.setBlock(world, i + 6, j + 38, k + 10, Blocks.leaves, 0);
		this.setBlock(world, i + 6, j + 38, k + 11, Blocks.log, 1);
		this.setBlock(world, i + 6, j + 38, k + 12, Blocks.leaves, 0);
		this.setBlock(world, i + 6, j + 39, k + 11, Blocks.leaves, 0);
		this.setBlock(world, i + 7, j + 30, k + 20, Blocks.leaves, 0);
		this.setBlock(world, i + 7, j + 30, k + 27, Blocks.leaves, 0);
		this.setBlock(world, i + 7, j + 30, k + 28, Blocks.leaves, 0);
		this.setBlock(world, i + 7, j + 30, k + 29, Blocks.leaves, 0);
		this.setBlock(world, i + 7, j + 30, k + 30, Blocks.leaves, 0);
		this.setBlock(world, i + 7, j + 30, k + 31, Blocks.leaves, 0);
		this.setBlock(world, i + 7, j + 30, k + 32, Blocks.log, 1);
		this.setBlock(world, i + 7, j + 31, k + 7, Blocks.log, 1);
		this.setBlock(world, i + 7, j + 31, k + 15, Blocks.leaves, 0);
		this.setBlock(world, i + 7, j + 31, k + 16, Blocks.leaves, 0);
		this.setBlock(world, i + 7, j + 31, k + 17, Blocks.log, 1);
		this.setBlock(world, i + 7, j + 31, k + 19, Blocks.leaves, 0);
		this.setBlock(world, i + 7, j + 31, k + 20, Blocks.leaves, 0);
		this.setBlock(world, i + 7, j + 31, k + 21, Blocks.leaves, 0);
		this.setBlock(world, i + 7, j + 31, k + 24, Blocks.leaves, 0);
		this.setBlock(world, i + 7, j + 31, k + 25, Blocks.leaves, 0);
		this.setBlock(world, i + 7, j + 31, k + 26, Blocks.log, 1);
		this.setBlock(world, i + 7, j + 31, k + 27, Blocks.log, 1);
		this.setBlock(world, i + 7, j + 31, k + 28, Blocks.leaves, 0);
		this.setBlock(world, i + 7, j + 31, k + 29, Blocks.leaves, 0);
		this.setBlock(world, i + 7, j + 31, k + 30, Blocks.leaves, 0);
		this.setBlock(world, i + 7, j + 31, k + 31, Blocks.leaves, 0);
		this.setBlock(world, i + 7, j + 31, k + 32, Blocks.leaves, 0);
		this.setBlock(world, i + 7, j + 31, k + 33, Blocks.leaves, 0);
		this.setBlock(world, i + 7, j + 32, k + 6, Blocks.log, 1);
		this.setBlock(world, i + 7, j + 32, k + 7, Blocks.log, 1);
		this.setBlock(world, i + 7, j + 32, k + 8, Blocks.log, 1);
		this.setBlock(world, i + 7, j + 32, k + 9, Blocks.log, 1);
		this.setBlock(world, i + 7, j + 32, k + 10, Blocks.log, 1);
		this.setBlock(world, i + 7, j + 32, k + 14, Blocks.leaves, 0);
		this.setBlock(world, i + 7, j + 32, k + 15, Blocks.log, 1);
		this.setBlock(world, i + 7, j + 32, k + 16, Blocks.log, 1);
		this.setBlock(world, i + 7, j + 32, k + 17, Blocks.log, 1);
		this.setBlock(world, i + 7, j + 32, k + 18, Blocks.log, 1);
		this.setBlock(world, i + 7, j + 32, k + 19, Blocks.leaves, 0);
		this.setBlock(world, i + 7, j + 32, k + 20, Blocks.leaves, 0);
		this.setBlock(world, i + 7, j + 32, k + 21, Blocks.leaves, 0);
		this.setBlock(world, i + 7, j + 32, k + 22, Blocks.leaves, 0);
		this.setBlock(world, i + 7, j + 32, k + 24, Blocks.leaves, 0);
		this.setBlock(world, i + 7, j + 32, k + 25, Blocks.leaves, 0);
		this.setBlock(world, i + 7, j + 32, k + 26, Blocks.log, 1);
		this.setBlock(world, i + 7, j + 32, k + 27, Blocks.log, 1);
		this.setBlock(world, i + 7, j + 32, k + 28, Blocks.log, 1);
		this.setBlock(world, i + 7, j + 32, k + 29, Blocks.log, 1);
		this.setBlock(world, i + 7, j + 32, k + 30, Blocks.leaves, 0);
		this.setBlock(world, i + 7, j + 32, k + 31, Blocks.log, 1);
		this.setBlock(world, i + 7, j + 32, k + 32, Blocks.leaves, 0);
		this.setBlock(world, i + 7, j + 32, k + 33, Blocks.leaves, 0);
		this.setBlock(world, i + 7, j + 32, k + 34, Blocks.leaves, 0);
		this.setBlock(world, i + 7, j + 33, k + 4, Blocks.leaves, 0);
		this.setBlock(world, i + 7, j + 33, k + 6, Blocks.log, 1);
		this.setBlock(world, i + 7, j + 33, k + 7, Blocks.log, 1);
		this.setBlock(world, i + 7, j + 33, k + 8, Blocks.leaves, 0);
		this.setBlock(world, i + 7, j + 33, k + 10, Blocks.log, 1);
		this.setBlock(world, i + 7, j + 33, k + 13, Blocks.leaves, 0);
		this.setBlock(world, i + 7, j + 33, k + 14, Blocks.log, 1);
		this.setBlock(world, i + 7, j + 33, k + 15, Blocks.leaves, 0);
		this.setBlock(world, i + 7, j + 33, k + 16, Blocks.leaves, 0);
		this.setBlock(world, i + 7, j + 33, k + 17, Blocks.leaves, 0);
		this.setBlock(world, i + 7, j + 33, k + 18, Blocks.log, 1);
		this.setBlock(world, i + 7, j + 33, k + 19, Blocks.leaves, 0);
		this.setBlock(world, i + 7, j + 33, k + 20, Blocks.leaves, 0);
		this.setBlock(world, i + 7, j + 33, k + 21, Blocks.leaves, 0);
		this.setBlock(world, i + 7, j + 33, k + 24, Blocks.leaves, 0);
		this.setBlock(world, i + 7, j + 33, k + 25, Blocks.leaves, 0);
		this.setBlock(world, i + 7, j + 33, k + 26, Blocks.log, 1);
		this.setBlock(world, i + 7, j + 33, k + 27, Blocks.log, 1);
		this.setBlock(world, i + 7, j + 33, k + 28, Blocks.log, 1);
		this.setBlock(world, i + 7, j + 33, k + 29, Blocks.leaves, 0);
		this.setBlock(world, i + 7, j + 33, k + 30, Blocks.leaves, 0);
		this.setBlock(world, i + 7, j + 33, k + 31, Blocks.leaves, 0);
		this.setBlock(world, i + 7, j + 33, k + 32, Blocks.leaves, 0);
		this.setBlock(world, i + 7, j + 33, k + 33, Blocks.leaves, 0);
		this.setBlock(world, i + 7, j + 34, k + 3, Blocks.leaves, 0);
		this.setBlock(world, i + 7, j + 34, k + 4, Blocks.leaves, 0);
		this.setBlock(world, i + 7, j + 34, k + 5, Blocks.leaves, 0);
		this.setBlock(world, i + 7, j + 34, k + 6, Blocks.log, 1);
		this.setBlock(world, i + 7, j + 34, k + 7, Blocks.log, 1);
		this.setBlock(world, i + 7, j + 34, k + 8, Blocks.leaves, 0);
		this.setBlock(world, i + 7, j + 34, k + 9, Blocks.leaves, 0);
		this.setBlock(world, i + 7, j + 34, k + 10, Blocks.leaves, 0);
		this.setBlock(world, i + 7, j + 34, k + 11, Blocks.leaves, 0);
		this.setBlock(world, i + 7, j + 34, k + 12, Blocks.log, 1);
		this.setBlock(world, i + 7, j + 34, k + 13, Blocks.leaves, 0);
		this.setBlock(world, i + 7, j + 34, k + 14, Blocks.leaves, 0);
		this.setBlock(world, i + 7, j + 34, k + 15, Blocks.leaves, 0);
		this.setBlock(world, i + 7, j + 34, k + 16, Blocks.leaves, 0);
		this.setBlock(world, i + 7, j + 34, k + 17, Blocks.leaves, 0);
		this.setBlock(world, i + 7, j + 34, k + 18, Blocks.leaves, 0);
		this.setBlock(world, i + 7, j + 34, k + 19, Blocks.leaves, 0);
		this.setBlock(world, i + 7, j + 34, k + 20, Blocks.leaves, 0);
		this.setBlock(world, i + 7, j + 34, k + 25, Blocks.leaves, 0);
		this.setBlock(world, i + 7, j + 34, k + 26, Blocks.leaves, 0);
		this.setBlock(world, i + 7, j + 34, k + 27, Blocks.leaves, 0);
		this.setBlock(world, i + 7, j + 34, k + 28, Blocks.leaves, 0);
		this.setBlock(world, i + 7, j + 34, k + 29, Blocks.leaves, 0);
		this.setBlock(world, i + 7, j + 34, k + 30, Blocks.leaves, 0);
		this.setBlock(world, i + 7, j + 34, k + 32, Blocks.leaves, 0);
		this.setBlock(world, i + 7, j + 35, k + 2, Blocks.leaves, 0);
		this.setBlock(world, i + 7, j + 35, k + 3, Blocks.leaves, 0);
		this.setBlock(world, i + 7, j + 35, k + 4, Blocks.leaves, 0);
		this.setBlock(world, i + 7, j + 35, k + 5, Blocks.leaves, 0);
		this.setBlock(world, i + 7, j + 35, k + 6, Blocks.leaves, 0);
		this.setBlock(world, i + 7, j + 35, k + 7, Blocks.leaves, 0);
		this.setBlock(world, i + 7, j + 35, k + 8, Blocks.leaves, 0);
		this.setBlock(world, i + 7, j + 35, k + 9, Blocks.leaves, 0);
		this.setBlock(world, i + 7, j + 35, k + 10, Blocks.leaves, 0);
		this.setBlock(world, i + 7, j + 35, k + 11, Blocks.leaves, 0);
		this.setBlock(world, i + 7, j + 35, k + 12, Blocks.leaves, 0);
		this.setBlock(world, i + 7, j + 35, k + 13, Blocks.leaves, 0);
		this.setBlock(world, i + 7, j + 35, k + 14, Blocks.leaves, 0);
		this.setBlock(world, i + 7, j + 35, k + 15, Blocks.leaves, 0);
		this.setBlock(world, i + 7, j + 35, k + 16, Blocks.leaves, 0);
		this.setBlock(world, i + 7, j + 35, k + 17, Blocks.leaves, 0);
		this.setBlock(world, i + 7, j + 35, k + 18, Blocks.leaves, 0);
		this.setBlock(world, i + 7, j + 35, k + 26, Blocks.leaves, 0);
		this.setBlock(world, i + 7, j + 35, k + 28, Blocks.leaves, 0);
		this.setBlock(world, i + 7, j + 35, k + 29, Blocks.leaves, 0);
		this.setBlock(world, i + 7, j + 35, k + 30, Blocks.leaves, 0);
		this.setBlock(world, i + 7, j + 36, k + 4, Blocks.leaves, 0);
		this.setBlock(world, i + 7, j + 36, k + 5, Blocks.leaves, 0);
		this.setBlock(world, i + 7, j + 36, k + 6, Blocks.leaves, 0);
		this.setBlock(world, i + 7, j + 36, k + 7, Blocks.leaves, 0);
		this.setBlock(world, i + 7, j + 36, k + 8, Blocks.leaves, 0);
		this.setBlock(world, i + 7, j + 36, k + 9, Blocks.leaves, 0);
		this.setBlock(world, i + 7, j + 36, k + 10, Blocks.leaves, 0);
		this.setBlock(world, i + 7, j + 36, k + 11, Blocks.leaves, 0);
		this.setBlock(world, i + 7, j + 36, k + 12, Blocks.leaves, 0);
		this.setBlock(world, i + 7, j + 36, k + 13, Blocks.leaves, 0);
		this.setBlock(world, i + 7, j + 36, k + 14, Blocks.leaves, 0);
		this.setBlock(world, i + 7, j + 37, k + 6, Blocks.leaves, 0);
		this.setBlock(world, i + 7, j + 37, k + 7, Blocks.leaves, 0);
		this.setBlock(world, i + 7, j + 37, k + 8, Blocks.leaves, 0);
		this.setBlock(world, i + 7, j + 37, k + 9, Blocks.leaves, 0);
		this.setBlock(world, i + 7, j + 37, k + 10, Blocks.leaves, 0);
		this.setBlock(world, i + 7, j + 37, k + 11, Blocks.leaves, 0);
		this.setBlock(world, i + 7, j + 37, k + 12, Blocks.leaves, 0);
		this.setBlock(world, i + 7, j + 38, k + 8, Blocks.leaves, 0);
		this.setBlock(world, i + 7, j + 38, k + 10, Blocks.leaves, 0);
		this.setBlock(world, i + 7, j + 38, k + 11, Blocks.leaves, 0);
		this.setBlock(world, i + 7, j + 38, k + 12, Blocks.leaves, 0);
		this.setBlock(world, i + 8, j + 0, k + 17, Blocks.log, 0);
		this.setBlock(world, i + 8, j + 29, k + 29, Blocks.leaves, 0);
		this.setBlock(world, i + 8, j + 30, k + 16, Blocks.log, 1);
		this.setBlock(world, i + 8, j + 30, k + 26, Blocks.log, 1);
		this.setBlock(world, i + 8, j + 30, k + 28, Blocks.leaves, 0);
		this.setBlock(world, i + 8, j + 30, k + 29, Blocks.leaves, 0);
		this.setBlock(world, i + 8, j + 30, k + 30, Blocks.leaves, 0);
		this.setBlock(world, i + 8, j + 31, k + 7, Blocks.log, 1);
		this.setBlock(world, i + 8, j + 31, k + 8, Blocks.log, 1);
		this.setBlock(world, i + 8, j + 31, k + 9, Blocks.log, 1);
		this.setBlock(world, i + 8, j + 31, k + 10, Blocks.log, 1);
		this.setBlock(world, i + 8, j + 31, k + 11, Blocks.log, 1);
		this.setBlock(world, i + 8, j + 31, k + 15, Blocks.leaves, 0);
		this.setBlock(world, i + 8, j + 31, k + 16, Blocks.leaves, 0);
		this.setBlock(world, i + 8, j + 31, k + 17, Blocks.leaves, 0);
		this.setBlock(world, i + 8, j + 31, k + 18, Blocks.leaves, 0);
		this.setBlock(world, i + 8, j + 31, k + 19, Blocks.log, 1);
		this.setBlock(world, i + 8, j + 31, k + 20, Blocks.leaves, 0);
		this.setBlock(world, i + 8, j + 31, k + 21, Blocks.log, 1);
		this.setBlock(world, i + 8, j + 31, k + 25, Blocks.log, 1);
		this.setBlock(world, i + 8, j + 31, k + 26, Blocks.log, 1);
		this.setBlock(world, i + 8, j + 31, k + 27, Blocks.log, 1);
		this.setBlock(world, i + 8, j + 31, k + 28, Blocks.log, 1);
		this.setBlock(world, i + 8, j + 31, k + 29, Blocks.leaves, 0);
		this.setBlock(world, i + 8, j + 31, k + 30, Blocks.leaves, 0);
		this.setBlock(world, i + 8, j + 31, k + 31, Blocks.leaves, 0);
		this.setBlock(world, i + 8, j + 31, k + 32, Blocks.leaves, 0);
		this.setBlock(world, i + 8, j + 31, k + 33, Blocks.leaves, 0);
		this.setBlock(world, i + 8, j + 32, k + 6, Blocks.log, 1);
		this.setBlock(world, i + 8, j + 32, k + 7, Blocks.log, 1);
		this.setBlock(world, i + 8, j + 32, k + 8, Blocks.log, 1);
		this.setBlock(world, i + 8, j + 32, k + 9, Blocks.log, 1);
		this.setBlock(world, i + 8, j + 32, k + 10, Blocks.log, 1);
		this.setBlock(world, i + 8, j + 32, k + 11, Blocks.log, 1);
		this.setBlock(world, i + 8, j + 32, k + 14, Blocks.leaves, 0);
		this.setBlock(world, i + 8, j + 32, k + 15, Blocks.leaves, 0);
		this.setBlock(world, i + 8, j + 32, k + 16, Blocks.leaves, 0);
		this.setBlock(world, i + 8, j + 32, k + 17, Blocks.leaves, 0);
		this.setBlock(world, i + 8, j + 32, k + 18, Blocks.leaves, 0);
		this.setBlock(world, i + 8, j + 32, k + 19, Blocks.log, 1);
		this.setBlock(world, i + 8, j + 32, k + 20, Blocks.leaves, 0);
		this.setBlock(world, i + 8, j + 32, k + 21, Blocks.leaves, 0);
		this.setBlock(world, i + 8, j + 32, k + 25, Blocks.leaves, 0);
		this.setBlock(world, i + 8, j + 32, k + 26, Blocks.log, 1);
		this.setBlock(world, i + 8, j + 32, k + 27, Blocks.log, 1);
		this.setBlock(world, i + 8, j + 32, k + 28, Blocks.log, 1);
		this.setBlock(world, i + 8, j + 32, k + 29, Blocks.leaves, 0);
		this.setBlock(world, i + 8, j + 32, k + 30, Blocks.log, 1);
		this.setBlock(world, i + 8, j + 32, k + 31, Blocks.leaves, 0);
		this.setBlock(world, i + 8, j + 32, k + 32, Blocks.leaves, 0);
		this.setBlock(world, i + 8, j + 32, k + 33, Blocks.leaves, 0);
		this.setBlock(world, i + 8, j + 33, k + 5, Blocks.leaves, 0);
		this.setBlock(world, i + 8, j + 33, k + 7, Blocks.log, 1);
		this.setBlock(world, i + 8, j + 33, k + 8, Blocks.log, 1);
		this.setBlock(world, i + 8, j + 33, k + 9, Blocks.log, 1);
		this.setBlock(world, i + 8, j + 33, k + 10, Blocks.log, 1);
		this.setBlock(world, i + 8, j + 33, k + 11, Blocks.log, 1);
		this.setBlock(world, i + 8, j + 33, k + 14, Blocks.leaves, 0);
		this.setBlock(world, i + 8, j + 33, k + 15, Blocks.leaves, 0);
		this.setBlock(world, i + 8, j + 33, k + 16, Blocks.leaves, 0);
		this.setBlock(world, i + 8, j + 33, k + 17, Blocks.leaves, 0);
		this.setBlock(world, i + 8, j + 33, k + 18, Blocks.leaves, 0);
		this.setBlock(world, i + 8, j + 33, k + 19, Blocks.leaves, 0);
		this.setBlock(world, i + 8, j + 33, k + 20, Blocks.leaves, 0);
		this.setBlock(world, i + 8, j + 33, k + 21, Blocks.leaves, 0);
		this.setBlock(world, i + 8, j + 33, k + 25, Blocks.leaves, 0);
		this.setBlock(world, i + 8, j + 33, k + 26, Blocks.log, 1);
		this.setBlock(world, i + 8, j + 33, k + 27, Blocks.log, 1);
		this.setBlock(world, i + 8, j + 33, k + 28, Blocks.leaves, 0);
		this.setBlock(world, i + 8, j + 33, k + 29, Blocks.leaves, 0);
		this.setBlock(world, i + 8, j + 33, k + 30, Blocks.leaves, 0);
		this.setBlock(world, i + 8, j + 33, k + 31, Blocks.leaves, 0);
		this.setBlock(world, i + 8, j + 33, k + 32, Blocks.leaves, 0);
		this.setBlock(world, i + 8, j + 33, k + 33, Blocks.leaves, 0);
		this.setBlock(world, i + 8, j + 34, k + 3, Blocks.leaves, 0);
		this.setBlock(world, i + 8, j + 34, k + 4, Blocks.leaves, 0);
		this.setBlock(world, i + 8, j + 34, k + 5, Blocks.leaves, 0);
		this.setBlock(world, i + 8, j + 34, k + 6, Blocks.leaves, 0);
		this.setBlock(world, i + 8, j + 34, k + 7, Blocks.leaves, 0);
		this.setBlock(world, i + 8, j + 34, k + 8, Blocks.leaves, 0);
		this.setBlock(world, i + 8, j + 34, k + 9, Blocks.leaves, 0);
		this.setBlock(world, i + 8, j + 34, k + 10, Blocks.log, 1);
		this.setBlock(world, i + 8, j + 34, k + 11, Blocks.leaves, 0);
		this.setBlock(world, i + 8, j + 34, k + 12, Blocks.leaves, 0);
		this.setBlock(world, i + 8, j + 34, k + 13, Blocks.leaves, 0);
		this.setBlock(world, i + 8, j + 34, k + 14, Blocks.log, 1);
		this.setBlock(world, i + 8, j + 34, k + 15, Blocks.leaves, 0);
		this.setBlock(world, i + 8, j + 34, k + 16, Blocks.leaves, 0);
		this.setBlock(world, i + 8, j + 34, k + 17, Blocks.leaves, 0);
		this.setBlock(world, i + 8, j + 34, k + 18, Blocks.leaves, 0);
		this.setBlock(world, i + 8, j + 34, k + 19, Blocks.leaves, 0);
		this.setBlock(world, i + 8, j + 34, k + 25, Blocks.leaves, 0);
		this.setBlock(world, i + 8, j + 34, k + 26, Blocks.leaves, 0);
		this.setBlock(world, i + 8, j + 34, k + 27, Blocks.log, 1);
		this.setBlock(world, i + 8, j + 34, k + 28, Blocks.leaves, 0);
		this.setBlock(world, i + 8, j + 34, k + 29, Blocks.leaves, 0);
		this.setBlock(world, i + 8, j + 34, k + 30, Blocks.leaves, 0);
		this.setBlock(world, i + 8, j + 35, k + 3, Blocks.leaves, 0);
		this.setBlock(world, i + 8, j + 35, k + 4, Blocks.leaves, 0);
		this.setBlock(world, i + 8, j + 35, k + 5, Blocks.leaves, 0);
		this.setBlock(world, i + 8, j + 35, k + 6, Blocks.log, 1);
		this.setBlock(world, i + 8, j + 35, k + 7, Blocks.leaves, 0);
		this.setBlock(world, i + 8, j + 35, k + 8, Blocks.leaves, 0);
		this.setBlock(world, i + 8, j + 35, k + 9, Blocks.log, 1);
		this.setBlock(world, i + 8, j + 35, k + 10, Blocks.leaves, 0);
		this.setBlock(world, i + 8, j + 35, k + 11, Blocks.log, 1);
		this.setBlock(world, i + 8, j + 35, k + 12, Blocks.leaves, 0);
		this.setBlock(world, i + 8, j + 35, k + 13, Blocks.leaves, 0);
		this.setBlock(world, i + 8, j + 35, k + 14, Blocks.leaves, 0);
		this.setBlock(world, i + 8, j + 35, k + 15, Blocks.leaves, 0);
		this.setBlock(world, i + 8, j + 35, k + 16, Blocks.leaves, 0);
		this.setBlock(world, i + 8, j + 35, k + 17, Blocks.leaves, 0);
		this.setBlock(world, i + 8, j + 35, k + 18, Blocks.leaves, 0);
		this.setBlock(world, i + 8, j + 35, k + 27, Blocks.leaves, 0);
		this.setBlock(world, i + 8, j + 35, k + 28, Blocks.leaves, 0);
		this.setBlock(world, i + 8, j + 35, k + 29, Blocks.leaves, 0);
		this.setBlock(world, i + 8, j + 36, k + 4, Blocks.leaves, 0);
		this.setBlock(world, i + 8, j + 36, k + 5, Blocks.leaves, 0);
		this.setBlock(world, i + 8, j + 36, k + 6, Blocks.leaves, 0);
		this.setBlock(world, i + 8, j + 36, k + 7, Blocks.leaves, 0);
		this.setBlock(world, i + 8, j + 36, k + 8, Blocks.leaves, 0);
		this.setBlock(world, i + 8, j + 36, k + 9, Blocks.leaves, 0);
		this.setBlock(world, i + 8, j + 36, k + 10, Blocks.leaves, 0);
		this.setBlock(world, i + 8, j + 36, k + 11, Blocks.leaves, 0);
		this.setBlock(world, i + 8, j + 36, k + 12, Blocks.leaves, 0);
		this.setBlock(world, i + 8, j + 36, k + 13, Blocks.leaves, 0);
		this.setBlock(world, i + 8, j + 36, k + 14, Blocks.leaves, 0);
		this.setBlock(world, i + 8, j + 36, k + 15, Blocks.leaves, 0);
		this.setBlock(world, i + 8, j + 36, k + 16, Blocks.leaves, 0);
		this.setBlock(world, i + 8, j + 36, k + 17, Blocks.leaves, 8);
		this.setBlock(world, i + 8, j + 36, k + 18, Blocks.leaves, 0);
		this.setBlock(world, i + 8, j + 37, k + 6, Blocks.leaves, 0);
		this.setBlock(world, i + 8, j + 37, k + 7, Blocks.leaves, 0);
		this.setBlock(world, i + 8, j + 37, k + 8, Blocks.leaves, 0);
		this.setBlock(world, i + 8, j + 37, k + 9, Blocks.leaves, 0);
		this.setBlock(world, i + 8, j + 37, k + 10, Blocks.leaves, 0);
		this.setBlock(world, i + 8, j + 37, k + 11, Blocks.leaves, 0);
		this.setBlock(world, i + 8, j + 38, k + 10, Blocks.leaves, 0);
		this.setBlock(world, i + 9, j + 0, k + 16, Blocks.log, 0);
		this.setBlock(world, i + 9, j + 0, k + 17, Blocks.log, 0);
		this.setBlock(world, i + 9, j + 0, k + 18, Blocks.log, 0);
		this.setBlock(world, i + 9, j + 1, k + 17, Blocks.log, 0);
		this.setBlock(world, i + 9, j + 30, k + 10, Blocks.log, 1);
		this.setBlock(world, i + 9, j + 30, k + 18, Blocks.leaves, 0);
		this.setBlock(world, i + 9, j + 30, k + 20, Blocks.leaves, 0);
		this.setBlock(world, i + 9, j + 30, k + 25, Blocks.log, 1);
		this.setBlock(world, i + 9, j + 30, k + 26, Blocks.log, 1);
		this.setBlock(world, i + 9, j + 30, k + 27, Blocks.log, 1);
		this.setBlock(world, i + 9, j + 30, k + 28, Blocks.log, 1);
		this.setBlock(world, i + 9, j + 30, k + 29, Blocks.leaves, 0);
		this.setBlock(world, i + 9, j + 30, k + 30, Blocks.leaves, 0);
		this.setBlock(world, i + 9, j + 31, k + 8, Blocks.log, 1);
		this.setBlock(world, i + 9, j + 31, k + 9, Blocks.log, 1);
		this.setBlock(world, i + 9, j + 31, k + 10, Blocks.log, 1);
		this.setBlock(world, i + 9, j + 31, k + 11, Blocks.log, 1);
		this.setBlock(world, i + 9, j + 31, k + 12, Blocks.log, 1);
		this.setBlock(world, i + 9, j + 31, k + 15, Blocks.leaves, 0);
		this.setBlock(world, i + 9, j + 31, k + 16, Blocks.leaves, 0);
		this.setBlock(world, i + 9, j + 31, k + 17, Blocks.log, 1);
		this.setBlock(world, i + 9, j + 31, k + 18, Blocks.leaves, 0);
		this.setBlock(world, i + 9, j + 31, k + 19, Blocks.leaves, 0);
		this.setBlock(world, i + 9, j + 31, k + 20, Blocks.log, 1);
		this.setBlock(world, i + 9, j + 31, k + 21, Blocks.leaves, 0);
		this.setBlock(world, i + 9, j + 31, k + 25, Blocks.log, 1);
		this.setBlock(world, i + 9, j + 31, k + 26, Blocks.log, 1);
		this.setBlock(world, i + 9, j + 31, k + 27, Blocks.log, 1);
		this.setBlock(world, i + 9, j + 31, k + 28, Blocks.log, 1);
		this.setBlock(world, i + 9, j + 31, k + 29, Blocks.leaves, 0);
		this.setBlock(world, i + 9, j + 31, k + 30, Blocks.leaves, 0);
		this.setBlock(world, i + 9, j + 31, k + 31, Blocks.leaves, 0);
		this.setBlock(world, i + 9, j + 32, k + 7, Blocks.log, 1);
		this.setBlock(world, i + 9, j + 32, k + 8, Blocks.log, 1);
		this.setBlock(world, i + 9, j + 32, k + 9, Blocks.log, 1);
		this.setBlock(world, i + 9, j + 32, k + 10, Blocks.log, 1);
		this.setBlock(world, i + 9, j + 32, k + 11, Blocks.log, 1);
		this.setBlock(world, i + 9, j + 32, k + 12, Blocks.log, 1);
		this.setBlock(world, i + 9, j + 32, k + 15, Blocks.leaves, 0);
		this.setBlock(world, i + 9, j + 32, k + 16, Blocks.log, 1);
		this.setBlock(world, i + 9, j + 32, k + 17, Blocks.leaves, 0);
		this.setBlock(world, i + 9, j + 32, k + 18, Blocks.leaves, 0);
		this.setBlock(world, i + 9, j + 32, k + 19, Blocks.log, 1);
		this.setBlock(world, i + 9, j + 32, k + 20, Blocks.leaves, 0);
		this.setBlock(world, i + 9, j + 32, k + 21, Blocks.leaves, 0);
		this.setBlock(world, i + 9, j + 32, k + 22, Blocks.leaves, 0);
		this.setBlock(world, i + 9, j + 32, k + 25, Blocks.leaves, 0);
		this.setBlock(world, i + 9, j + 32, k + 26, Blocks.log, 1);
		this.setBlock(world, i + 9, j + 32, k + 27, Blocks.log, 1);
		this.setBlock(world, i + 9, j + 32, k + 28, Blocks.log, 1);
		this.setBlock(world, i + 9, j + 32, k + 29, Blocks.leaves, 0);
		this.setBlock(world, i + 9, j + 32, k + 30, Blocks.leaves, 0);
		this.setBlock(world, i + 9, j + 32, k + 31, Blocks.log, 1);
		this.setBlock(world, i + 9, j + 32, k + 32, Blocks.leaves, 0);
		this.setBlock(world, i + 9, j + 33, k + 8, Blocks.log, 1);
		this.setBlock(world, i + 9, j + 33, k + 9, Blocks.log, 1);
		this.setBlock(world, i + 9, j + 33, k + 10, Blocks.log, 1);
		this.setBlock(world, i + 9, j + 33, k + 11, Blocks.log, 1);
		this.setBlock(world, i + 9, j + 33, k + 12, Blocks.log, 1);
		this.setBlock(world, i + 9, j + 33, k + 14, Blocks.leaves, 0);
		this.setBlock(world, i + 9, j + 33, k + 15, Blocks.log, 1);
		this.setBlock(world, i + 9, j + 33, k + 16, Blocks.log, 1);
		this.setBlock(world, i + 9, j + 33, k + 17, Blocks.leaves, 0);
		this.setBlock(world, i + 9, j + 33, k + 18, Blocks.leaves, 0);
		this.setBlock(world, i + 9, j + 33, k + 19, Blocks.leaves, 0);
		this.setBlock(world, i + 9, j + 33, k + 20, Blocks.leaves, 0);
		this.setBlock(world, i + 9, j + 33, k + 21, Blocks.leaves, 0);
		this.setBlock(world, i + 9, j + 33, k + 24, Blocks.leaves, 0);
		this.setBlock(world, i + 9, j + 33, k + 25, Blocks.leaves, 0);
		this.setBlock(world, i + 9, j + 33, k + 26, Blocks.leaves, 0);
		this.setBlock(world, i + 9, j + 33, k + 27, Blocks.log, 1);
		this.setBlock(world, i + 9, j + 33, k + 28, Blocks.leaves, 0);
		this.setBlock(world, i + 9, j + 33, k + 29, Blocks.log, 1);
		this.setBlock(world, i + 9, j + 33, k + 30, Blocks.leaves, 0);
		this.setBlock(world, i + 9, j + 33, k + 31, Blocks.leaves, 0);
		this.setBlock(world, i + 9, j + 33, k + 32, Blocks.leaves, 0);
		this.setBlock(world, i + 9, j + 34, k + 4, Blocks.leaves, 0);
		this.setBlock(world, i + 9, j + 34, k + 5, Blocks.leaves, 0);
		this.setBlock(world, i + 9, j + 34, k + 6, Blocks.log, 1);
		this.setBlock(world, i + 9, j + 34, k + 7, Blocks.leaves, 0);
		this.setBlock(world, i + 9, j + 34, k + 8, Blocks.leaves, 0);
		this.setBlock(world, i + 9, j + 34, k + 9, Blocks.leaves, 0);
		this.setBlock(world, i + 9, j + 34, k + 10, Blocks.log, 1);
		this.setBlock(world, i + 9, j + 34, k + 11, Blocks.log, 1);
		this.setBlock(world, i + 9, j + 34, k + 12, Blocks.log, 1);
		this.setBlock(world, i + 9, j + 34, k + 13, Blocks.leaves, 0);
		this.setBlock(world, i + 9, j + 34, k + 14, Blocks.log, 1);
		this.setBlock(world, i + 9, j + 34, k + 15, Blocks.leaves, 0);
		this.setBlock(world, i + 9, j + 34, k + 16, Blocks.leaves, 0);
		this.setBlock(world, i + 9, j + 34, k + 17, Blocks.leaves, 0);
		this.setBlock(world, i + 9, j + 34, k + 18, Blocks.leaves, 0);
		this.setBlock(world, i + 9, j + 34, k + 19, Blocks.leaves, 0);
		this.setBlock(world, i + 9, j + 34, k + 20, Blocks.leaves, 0);
		this.setBlock(world, i + 9, j + 34, k + 21, Blocks.leaves, 0);
		this.setBlock(world, i + 9, j + 34, k + 25, Blocks.leaves, 0);
		this.setBlock(world, i + 9, j + 34, k + 26, Blocks.leaves, 0);
		this.setBlock(world, i + 9, j + 34, k + 27, Blocks.log, 1);
		this.setBlock(world, i + 9, j + 34, k + 28, Blocks.log, 1);
		this.setBlock(world, i + 9, j + 34, k + 29, Blocks.log, 1);
		this.setBlock(world, i + 9, j + 34, k + 30, Blocks.leaves, 0);
		this.setBlock(world, i + 9, j + 34, k + 31, Blocks.leaves, 0);
		this.setBlock(world, i + 9, j + 34, k + 32, Blocks.leaves, 0);
		this.setBlock(world, i + 9, j + 35, k + 4, Blocks.leaves, 0);
		this.setBlock(world, i + 9, j + 35, k + 5, Blocks.leaves, 0);
		this.setBlock(world, i + 9, j + 35, k + 6, Blocks.leaves, 0);
		this.setBlock(world, i + 9, j + 35, k + 7, Blocks.leaves, 0);
		this.setBlock(world, i + 9, j + 35, k + 8, Blocks.log, 1);
		this.setBlock(world, i + 9, j + 35, k + 9, Blocks.log, 1);
		this.setBlock(world, i + 9, j + 35, k + 10, Blocks.log, 1);
		this.setBlock(world, i + 9, j + 35, k + 11, Blocks.log, 1);
		this.setBlock(world, i + 9, j + 35, k + 12, Blocks.leaves, 0);
		this.setBlock(world, i + 9, j + 35, k + 13, Blocks.leaves, 0);
		this.setBlock(world, i + 9, j + 35, k + 14, Blocks.log, 1);
		this.setBlock(world, i + 9, j + 35, k + 15, Blocks.leaves, 0);
		this.setBlock(world, i + 9, j + 35, k + 16, Blocks.leaves, 0);
		this.setBlock(world, i + 9, j + 35, k + 17, Blocks.leaves, 0);
		this.setBlock(world, i + 9, j + 35, k + 18, Blocks.leaves, 0);
		this.setBlock(world, i + 9, j + 35, k + 19, Blocks.leaves, 0);
		this.setBlock(world, i + 9, j + 35, k + 26, Blocks.leaves, 0);
		this.setBlock(world, i + 9, j + 35, k + 27, Blocks.leaves, 0);
		this.setBlock(world, i + 9, j + 35, k + 28, Blocks.leaves, 0);
		this.setBlock(world, i + 9, j + 35, k + 29, Blocks.leaves, 0);
		this.setBlock(world, i + 9, j + 36, k + 4, Blocks.leaves, 0);
		this.setBlock(world, i + 9, j + 36, k + 5, Blocks.leaves, 0);
		this.setBlock(world, i + 9, j + 36, k + 6, Blocks.leaves, 0);
		this.setBlock(world, i + 9, j + 36, k + 7, Blocks.leaves, 0);
		this.setBlock(world, i + 9, j + 36, k + 8, Blocks.leaves, 0);
		this.setBlock(world, i + 9, j + 36, k + 9, Blocks.leaves, 0);
		this.setBlock(world, i + 9, j + 36, k + 10, Blocks.leaves, 0);
		this.setBlock(world, i + 9, j + 36, k + 11, Blocks.leaves, 0);
		this.setBlock(world, i + 9, j + 36, k + 12, Blocks.leaves, 0);
		this.setBlock(world, i + 9, j + 36, k + 13, Blocks.leaves, 0);
		this.setBlock(world, i + 9, j + 36, k + 14, Blocks.leaves, 0);
		this.setBlock(world, i + 9, j + 36, k + 17, Blocks.leaves, 0);
		this.setBlock(world, i + 9, j + 36, k + 18, Blocks.leaves, 0);
		this.setBlock(world, i + 9, j + 36, k + 28, Blocks.leaves, 0);
		this.setBlock(world, i + 9, j + 37, k + 7, Blocks.leaves, 0);
		this.setBlock(world, i + 9, j + 37, k + 8, Blocks.leaves, 0);
		this.setBlock(world, i + 9, j + 37, k + 9, Blocks.leaves, 0);
		this.setBlock(world, i + 9, j + 37, k + 10, Blocks.leaves, 0);
		this.setBlock(world, i + 9, j + 37, k + 11, Blocks.leaves, 0);
		this.setBlock(world, i + 9, j + 37, k + 12, Blocks.leaves, 0);
		this.setBlock(world, i + 9, j + 37, k + 14, Blocks.leaves, 0);
		this.setBlock(world, i + 9, j + 37, k + 17, Blocks.leaves, 8);
		this.setBlock(world, i + 10, j + 0, k + 16, Blocks.log, 0);
		this.setBlock(world, i + 10, j + 0, k + 17, Blocks.log, 0);
		this.setBlock(world, i + 10, j + 0, k + 18, Blocks.log, 0);
		this.setBlock(world, i + 10, j + 1, k + 17, Blocks.log, 0);
		this.setBlock(world, i + 10, j + 29, k + 19, Blocks.log, 1);
		this.setBlock(world, i + 10, j + 29, k + 25, Blocks.log, 1);
		this.setBlock(world, i + 10, j + 29, k + 26, Blocks.log, 1);
		this.setBlock(world, i + 10, j + 30, k + 11, Blocks.log, 1);
		this.setBlock(world, i + 10, j + 30, k + 16, Blocks.log, 1);
		this.setBlock(world, i + 10, j + 30, k + 17, Blocks.log, 1);
		this.setBlock(world, i + 10, j + 30, k + 18, Blocks.log, 1);
		this.setBlock(world, i + 10, j + 30, k + 24, Blocks.log, 1);
		this.setBlock(world, i + 10, j + 30, k + 25, Blocks.log, 1);
		this.setBlock(world, i + 10, j + 30, k + 26, Blocks.log, 1);
		this.setBlock(world, i + 10, j + 30, k + 27, Blocks.log, 1);
		this.setBlock(world, i + 10, j + 31, k + 9, Blocks.log, 1);
		this.setBlock(world, i + 10, j + 31, k + 10, Blocks.log, 1);
		this.setBlock(world, i + 10, j + 31, k + 11, Blocks.log, 1);
		this.setBlock(world, i + 10, j + 31, k + 12, Blocks.log, 1);
		this.setBlock(world, i + 10, j + 31, k + 16, Blocks.log, 1);
		this.setBlock(world, i + 10, j + 31, k + 17, Blocks.log, 1);
		this.setBlock(world, i + 10, j + 31, k + 18, Blocks.log, 1);
		this.setBlock(world, i + 10, j + 31, k + 19, Blocks.leaves, 0);
		this.setBlock(world, i + 10, j + 31, k + 20, Blocks.leaves, 0);
		this.setBlock(world, i + 10, j + 31, k + 21, Blocks.leaves, 0);
		this.setBlock(world, i + 10, j + 31, k + 25, Blocks.log, 1);
		this.setBlock(world, i + 10, j + 31, k + 26, Blocks.log, 1);
		this.setBlock(world, i + 10, j + 31, k + 27, Blocks.log, 1);
		this.setBlock(world, i + 10, j + 31, k + 29, Blocks.leaves, 0);
		this.setBlock(world, i + 10, j + 31, k + 30, Blocks.leaves, 0);
		this.setBlock(world, i + 10, j + 31, k + 31, Blocks.log, 1);
		this.setBlock(world, i + 10, j + 32, k + 8, Blocks.log, 1);
		this.setBlock(world, i + 10, j + 32, k + 9, Blocks.log, 1);
		this.setBlock(world, i + 10, j + 32, k + 10, Blocks.log, 1);
		this.setBlock(world, i + 10, j + 32, k + 11, Blocks.log, 1);
		this.setBlock(world, i + 10, j + 32, k + 12, Blocks.log, 1);
		this.setBlock(world, i + 10, j + 32, k + 13, Blocks.log, 1);
		this.setBlock(world, i + 10, j + 32, k + 16, Blocks.log, 1);
		this.setBlock(world, i + 10, j + 32, k + 17, Blocks.log, 1);
		this.setBlock(world, i + 10, j + 32, k + 18, Blocks.log, 1);
		this.setBlock(world, i + 10, j + 32, k + 19, Blocks.log, 1);
		this.setBlock(world, i + 10, j + 32, k + 20, Blocks.leaves, 0);
		this.setBlock(world, i + 10, j + 32, k + 21, Blocks.leaves, 0);
		this.setBlock(world, i + 10, j + 32, k + 25, Blocks.log, 1);
		this.setBlock(world, i + 10, j + 32, k + 26, Blocks.log, 1);
		this.setBlock(world, i + 10, j + 32, k + 27, Blocks.log, 1);
		this.setBlock(world, i + 10, j + 32, k + 28, Blocks.leaves, 0);
		this.setBlock(world, i + 10, j + 32, k + 29, Blocks.leaves, 0);
		this.setBlock(world, i + 10, j + 32, k + 30, Blocks.leaves, 0);
		this.setBlock(world, i + 10, j + 32, k + 31, Blocks.leaves, 0);
		this.setBlock(world, i + 10, j + 32, k + 32, Blocks.leaves, 0);
		this.setBlock(world, i + 10, j + 33, k + 9, Blocks.log, 1);
		this.setBlock(world, i + 10, j + 33, k + 10, Blocks.log, 1);
		this.setBlock(world, i + 10, j + 33, k + 11, Blocks.log, 1);
		this.setBlock(world, i + 10, j + 33, k + 12, Blocks.log, 1);
		this.setBlock(world, i + 10, j + 33, k + 16, Blocks.leaves, 0);
		this.setBlock(world, i + 10, j + 33, k + 17, Blocks.leaves, 0);
		this.setBlock(world, i + 10, j + 33, k + 18, Blocks.leaves, 0);
		this.setBlock(world, i + 10, j + 33, k + 19, Blocks.leaves, 0);
		this.setBlock(world, i + 10, j + 33, k + 20, Blocks.log, 1);
		this.setBlock(world, i + 10, j + 33, k + 21, Blocks.leaves, 0);
		this.setBlock(world, i + 10, j + 33, k + 22, Blocks.leaves, 0);
		this.setBlock(world, i + 10, j + 33, k + 25, Blocks.leaves, 0);
		this.setBlock(world, i + 10, j + 33, k + 26, Blocks.log, 1);
		this.setBlock(world, i + 10, j + 33, k + 27, Blocks.leaves, 0);
		this.setBlock(world, i + 10, j + 33, k + 28, Blocks.leaves, 0);
		this.setBlock(world, i + 10, j + 33, k + 29, Blocks.leaves, 0);
		this.setBlock(world, i + 10, j + 33, k + 30, Blocks.leaves, 0);
		this.setBlock(world, i + 10, j + 33, k + 31, Blocks.leaves, 0);
		this.setBlock(world, i + 10, j + 33, k + 32, Blocks.leaves, 0);
		this.setBlock(world, i + 10, j + 33, k + 33, Blocks.leaves, 0);
		this.setBlock(world, i + 10, j + 34, k + 7, Blocks.leaves, 0);
		this.setBlock(world, i + 10, j + 34, k + 8, Blocks.leaves, 0);
		this.setBlock(world, i + 10, j + 34, k + 9, Blocks.log, 1);
		this.setBlock(world, i + 10, j + 34, k + 10, Blocks.leaves, 0);
		this.setBlock(world, i + 10, j + 34, k + 11, Blocks.log, 1);
		this.setBlock(world, i + 10, j + 34, k + 12, Blocks.leaves, 0);
		this.setBlock(world, i + 10, j + 34, k + 13, Blocks.leaves, 0);
		this.setBlock(world, i + 10, j + 34, k + 14, Blocks.leaves, 0);
		this.setBlock(world, i + 10, j + 34, k + 15, Blocks.leaves, 0);
		this.setBlock(world, i + 10, j + 34, k + 16, Blocks.leaves, 0);
		this.setBlock(world, i + 10, j + 34, k + 17, Blocks.leaves, 0);
		this.setBlock(world, i + 10, j + 34, k + 18, Blocks.log, 1);
		this.setBlock(world, i + 10, j + 34, k + 19, Blocks.leaves, 0);
		this.setBlock(world, i + 10, j + 34, k + 20, Blocks.leaves, 0);
		this.setBlock(world, i + 10, j + 34, k + 21, Blocks.leaves, 0);
		this.setBlock(world, i + 10, j + 34, k + 25, Blocks.leaves, 0);
		this.setBlock(world, i + 10, j + 34, k + 26, Blocks.leaves, 0);
		this.setBlock(world, i + 10, j + 34, k + 27, Blocks.log, 1);
		this.setBlock(world, i + 10, j + 34, k + 28, Blocks.log, 1);
		this.setBlock(world, i + 10, j + 34, k + 29, Blocks.leaves, 0);
		this.setBlock(world, i + 10, j + 34, k + 30, Blocks.leaves, 0);
		this.setBlock(world, i + 10, j + 34, k + 31, Blocks.leaves, 0);
		this.setBlock(world, i + 10, j + 34, k + 32, Blocks.leaves, 0);
		this.setBlock(world, i + 10, j + 35, k + 5, Blocks.leaves, 0);
		this.setBlock(world, i + 10, j + 35, k + 7, Blocks.leaves, 0);
		this.setBlock(world, i + 10, j + 35, k + 8, Blocks.log, 1);
		this.setBlock(world, i + 10, j + 35, k + 9, Blocks.leaves, 0);
		this.setBlock(world, i + 10, j + 35, k + 10, Blocks.leaves, 0);
		this.setBlock(world, i + 10, j + 35, k + 11, Blocks.leaves, 0);
		this.setBlock(world, i + 10, j + 35, k + 12, Blocks.leaves, 0);
		this.setBlock(world, i + 10, j + 35, k + 13, Blocks.leaves, 0);
		this.setBlock(world, i + 10, j + 35, k + 14, Blocks.leaves, 0);
		this.setBlock(world, i + 10, j + 35, k + 15, Blocks.leaves, 0);
		this.setBlock(world, i + 10, j + 35, k + 16, Blocks.leaves, 0);
		this.setBlock(world, i + 10, j + 35, k + 17, Blocks.leaves, 0);
		this.setBlock(world, i + 10, j + 35, k + 18, Blocks.leaves, 0);
		this.setBlock(world, i + 10, j + 35, k + 20, Blocks.leaves, 0);
		this.setBlock(world, i + 10, j + 35, k + 27, Blocks.leaves, 0);
		this.setBlock(world, i + 10, j + 35, k + 28, Blocks.leaves, 0);
		this.setBlock(world, i + 10, j + 35, k + 29, Blocks.leaves, 0);
		this.setBlock(world, i + 10, j + 35, k + 31, Blocks.leaves, 0);
		this.setBlock(world, i + 10, j + 36, k + 7, Blocks.leaves, 0);
		this.setBlock(world, i + 10, j + 36, k + 8, Blocks.leaves, 0);
		this.setBlock(world, i + 10, j + 36, k + 9, Blocks.leaves, 0);
		this.setBlock(world, i + 10, j + 36, k + 10, Blocks.leaves, 0);
		this.setBlock(world, i + 10, j + 36, k + 11, Blocks.leaves, 0);
		this.setBlock(world, i + 10, j + 36, k + 12, Blocks.leaves, 0);
		this.setBlock(world, i + 10, j + 36, k + 13, Blocks.leaves, 0);
		this.setBlock(world, i + 10, j + 36, k + 14, Blocks.leaves, 0);
		this.setBlock(world, i + 10, j + 36, k + 15, Blocks.leaves, 0);
		this.setBlock(world, i + 10, j + 37, k + 8, Blocks.leaves, 0);
		this.setBlock(world, i + 10, j + 37, k + 9, Blocks.leaves, 0);
		this.setBlock(world, i + 10, j + 37, k + 10, Blocks.leaves, 0);
		this.setBlock(world, i + 10, j + 38, k + 9, Blocks.leaves, 0);
		this.setBlock(world, i + 11, j + 0, k + 16, Blocks.log, 0);
		this.setBlock(world, i + 11, j + 0, k + 17, Blocks.log, 0);
		this.setBlock(world, i + 11, j + 0, k + 18, Blocks.log, 0);
		this.setBlock(world, i + 11, j + 1, k + 17, Blocks.log, 0);
		this.setBlock(world, i + 11, j + 1, k + 30, Blocks.log, 0);
		this.setBlock(world, i + 11, j + 28, k + 18, Blocks.log, 1);
		this.setBlock(world, i + 11, j + 28, k + 19, Blocks.log, 1);
		this.setBlock(world, i + 11, j + 28, k + 20, Blocks.log, 1);
		this.setBlock(world, i + 11, j + 29, k + 17, Blocks.log, 1);
		this.setBlock(world, i + 11, j + 29, k + 18, Blocks.log, 1);
		this.setBlock(world, i + 11, j + 29, k + 19, Blocks.log, 1);
		this.setBlock(world, i + 11, j + 29, k + 20, Blocks.log, 1);
		this.setBlock(world, i + 11, j + 29, k + 23, Blocks.log, 1);
		this.setBlock(world, i + 11, j + 29, k + 24, Blocks.log, 1);
		this.setBlock(world, i + 11, j + 29, k + 25, Blocks.log, 1);
		this.setBlock(world, i + 11, j + 30, k + 16, Blocks.log, 1);
		this.setBlock(world, i + 11, j + 30, k + 17, Blocks.log, 1);
		this.setBlock(world, i + 11, j + 30, k + 18, Blocks.log, 1);
		this.setBlock(world, i + 11, j + 30, k + 19, Blocks.log, 1);
		this.setBlock(world, i + 11, j + 30, k + 20, Blocks.log, 1);
		this.setBlock(world, i + 11, j + 30, k + 24, Blocks.log, 1);
		this.setBlock(world, i + 11, j + 30, k + 25, Blocks.log, 1);
		this.setBlock(world, i + 11, j + 30, k + 26, Blocks.log, 1);
		this.setBlock(world, i + 11, j + 31, k + 10, Blocks.log, 1);
		this.setBlock(world, i + 11, j + 31, k + 11, Blocks.log, 1);
		this.setBlock(world, i + 11, j + 31, k + 12, Blocks.log, 1);
		this.setBlock(world, i + 11, j + 31, k + 15, Blocks.log, 1);
		this.setBlock(world, i + 11, j + 31, k + 16, Blocks.log, 1);
		this.setBlock(world, i + 11, j + 31, k + 17, Blocks.log, 1);
		this.setBlock(world, i + 11, j + 31, k + 18, Blocks.log, 1);
		this.setBlock(world, i + 11, j + 31, k + 19, Blocks.log, 1);
		this.setBlock(world, i + 11, j + 31, k + 25, Blocks.log, 1);
		this.setBlock(world, i + 11, j + 31, k + 26, Blocks.log, 1);
		this.setBlock(world, i + 11, j + 31, k + 28, Blocks.leaves, 0);
		this.setBlock(world, i + 11, j + 32, k + 10, Blocks.log, 1);
		this.setBlock(world, i + 11, j + 32, k + 11, Blocks.log, 1);
		this.setBlock(world, i + 11, j + 32, k + 12, Blocks.log, 1);
		this.setBlock(world, i + 11, j + 32, k + 15, Blocks.leaves, 0);
		this.setBlock(world, i + 11, j + 32, k + 16, Blocks.log, 1);
		this.setBlock(world, i + 11, j + 32, k + 17, Blocks.log, 1);
		this.setBlock(world, i + 11, j + 32, k + 18, Blocks.log, 1);
		this.setBlock(world, i + 11, j + 32, k + 19, Blocks.log, 1);
		this.setBlock(world, i + 11, j + 32, k + 20, Blocks.leaves, 0);
		this.setBlock(world, i + 11, j + 32, k + 21, Blocks.leaves, 0);
		this.setBlock(world, i + 11, j + 32, k + 27, Blocks.leaves, 0);
		this.setBlock(world, i + 11, j + 32, k + 28, Blocks.leaves, 0);
		this.setBlock(world, i + 11, j + 32, k + 29, Blocks.leaves, 0);
		this.setBlock(world, i + 11, j + 32, k + 30, Blocks.leaves, 0);
		this.setBlock(world, i + 11, j + 32, k + 31, Blocks.leaves, 0);
		this.setBlock(world, i + 11, j + 32, k + 32, Blocks.log, 1);
		this.setBlock(world, i + 11, j + 33, k + 10, Blocks.log, 1);
		this.setBlock(world, i + 11, j + 33, k + 11, Blocks.log, 1);
		this.setBlock(world, i + 11, j + 33, k + 12, Blocks.log, 1);
		this.setBlock(world, i + 11, j + 33, k + 15, Blocks.leaves, 0);
		this.setBlock(world, i + 11, j + 33, k + 16, Blocks.leaves, 0);
		this.setBlock(world, i + 11, j + 33, k + 17, Blocks.log, 1);
		this.setBlock(world, i + 11, j + 33, k + 18, Blocks.leaves, 0);
		this.setBlock(world, i + 11, j + 33, k + 19, Blocks.leaves, 0);
		this.setBlock(world, i + 11, j + 33, k + 20, Blocks.leaves, 0);
		this.setBlock(world, i + 11, j + 33, k + 21, Blocks.leaves, 0);
		this.setBlock(world, i + 11, j + 33, k + 26, Blocks.leaves, 0);
		this.setBlock(world, i + 11, j + 33, k + 27, Blocks.leaves, 0);
		this.setBlock(world, i + 11, j + 33, k + 28, Blocks.leaves, 0);
		this.setBlock(world, i + 11, j + 33, k + 29, Blocks.leaves, 0);
		this.setBlock(world, i + 11, j + 33, k + 30, Blocks.leaves, 0);
		this.setBlock(world, i + 11, j + 33, k + 31, Blocks.leaves, 0);
		this.setBlock(world, i + 11, j + 33, k + 32, Blocks.leaves, 0);
		this.setBlock(world, i + 11, j + 34, k + 15, Blocks.leaves, 0);
		this.setBlock(world, i + 11, j + 34, k + 16, Blocks.leaves, 0);
		this.setBlock(world, i + 11, j + 34, k + 17, Blocks.log, 1);
		this.setBlock(world, i + 11, j + 34, k + 18, Blocks.leaves, 0);
		this.setBlock(world, i + 11, j + 34, k + 19, Blocks.leaves, 0);
		this.setBlock(world, i + 11, j + 34, k + 20, Blocks.leaves, 12);
		this.setBlock(world, i + 11, j + 34, k + 21, Blocks.leaves, 0);
		this.setBlock(world, i + 11, j + 34, k + 27, Blocks.leaves, 0);
		this.setBlock(world, i + 11, j + 34, k + 28, Blocks.leaves, 0);
		this.setBlock(world, i + 11, j + 34, k + 29, Blocks.leaves, 0);
		this.setBlock(world, i + 11, j + 34, k + 30, Blocks.leaves, 0);
		this.setBlock(world, i + 11, j + 34, k + 31, Blocks.leaves, 0);
		this.setBlock(world, i + 11, j + 34, k + 32, Blocks.leaves, 0);
		this.setBlock(world, i + 11, j + 35, k + 8, Blocks.leaves, 0);
		this.setBlock(world, i + 11, j + 35, k + 9, Blocks.leaves, 0);
		this.setBlock(world, i + 11, j + 35, k + 10, Blocks.log, 1);
		this.setBlock(world, i + 11, j + 35, k + 12, Blocks.leaves, 0);
		this.setBlock(world, i + 11, j + 35, k + 14, Blocks.leaves, 0);
		this.setBlock(world, i + 11, j + 35, k + 15, Blocks.leaves, 0);
		this.setBlock(world, i + 11, j + 35, k + 16, Blocks.leaves, 0);
		this.setBlock(world, i + 11, j + 35, k + 17, Blocks.leaves, 0);
		this.setBlock(world, i + 11, j + 35, k + 28, Blocks.leaves, 0);
		this.setBlock(world, i + 11, j + 36, k + 8, Blocks.leaves, 0);
		this.setBlock(world, i + 11, j + 36, k + 9, Blocks.leaves, 0);
		this.setBlock(world, i + 11, j + 36, k + 10, Blocks.leaves, 0);
		this.setBlock(world, i + 11, j + 37, k + 8, Blocks.leaves, 0);
		this.setBlock(world, i + 11, j + 37, k + 9, Blocks.leaves, 0);
		this.setBlock(world, i + 11, j + 37, k + 10, Blocks.leaves, 0);
		this.setBlock(world, i + 11, j + 42, k + 20, Blocks.leaves, 0);
		this.setBlock(world, i + 12, j + 0, k + 15, Blocks.log, 0);
		this.setBlock(world, i + 12, j + 0, k + 16, Blocks.log, 0);
		this.setBlock(world, i + 12, j + 0, k + 17, Blocks.log, 0);
		this.setBlock(world, i + 12, j + 0, k + 18, Blocks.log, 0);
		this.setBlock(world, i + 12, j + 0, k + 30, Blocks.log, 0);
		this.setBlock(world, i + 12, j + 1, k + 17, Blocks.log, 0);
		this.setBlock(world, i + 12, j + 1, k + 29, Blocks.log, 0);
		this.setBlock(world, i + 12, j + 1, k + 30, Blocks.log, 0);
		this.setBlock(world, i + 12, j + 1, k + 31, Blocks.log, 0);
		this.setBlock(world, i + 12, j + 2, k + 17, Blocks.log, 0);
		this.setBlock(world, i + 12, j + 2, k + 18, Blocks.log, 0);
		this.setBlock(world, i + 12, j + 2, k + 30, Blocks.log, 0);
		this.setBlock(world, i + 12, j + 26, k + 21, Blocks.log, 1);
		this.setBlock(world, i + 12, j + 27, k + 19, Blocks.log, 1);
		this.setBlock(world, i + 12, j + 27, k + 20, Blocks.log, 1);
		this.setBlock(world, i + 12, j + 27, k + 21, Blocks.log, 1);
		this.setBlock(world, i + 12, j + 27, k + 23, Blocks.log, 1);
		this.setBlock(world, i + 12, j + 28, k + 18, Blocks.log, 1);
		this.setBlock(world, i + 12, j + 28, k + 19, Blocks.log, 1);
		this.setBlock(world, i + 12, j + 28, k + 20, Blocks.log, 1);
		this.setBlock(world, i + 12, j + 28, k + 21, Blocks.log, 1);
		this.setBlock(world, i + 12, j + 28, k + 23, Blocks.log, 1);
		this.setBlock(world, i + 12, j + 28, k + 24, Blocks.log, 1);
		this.setBlock(world, i + 12, j + 28, k + 25, Blocks.log, 1);
		this.setBlock(world, i + 12, j + 29, k + 17, Blocks.log, 1);
		this.setBlock(world, i + 12, j + 29, k + 18, Blocks.log, 1);
		this.setBlock(world, i + 12, j + 29, k + 19, Blocks.log, 1);
		this.setBlock(world, i + 12, j + 29, k + 20, Blocks.log, 1);
		this.setBlock(world, i + 12, j + 29, k + 21, Blocks.log, 1);
		this.setBlock(world, i + 12, j + 29, k + 22, Blocks.log, 1);
		this.setBlock(world, i + 12, j + 29, k + 23, Blocks.log, 1);
		this.setBlock(world, i + 12, j + 29, k + 24, Blocks.log, 1);
		this.setBlock(world, i + 12, j + 29, k + 25, Blocks.log, 1);
		this.setBlock(world, i + 12, j + 29, k + 26, Blocks.log, 1);
		this.setBlock(world, i + 12, j + 30, k + 11, Blocks.log, 1);
		this.setBlock(world, i + 12, j + 30, k + 16, Blocks.log, 1);
		this.setBlock(world, i + 12, j + 30, k + 17, Blocks.log, 1);
		this.setBlock(world, i + 12, j + 30, k + 18, Blocks.log, 1);
		this.setBlock(world, i + 12, j + 30, k + 19, Blocks.log, 1);
		this.setBlock(world, i + 12, j + 30, k + 20, Blocks.log, 1);
		this.setBlock(world, i + 12, j + 30, k + 23, Blocks.log, 1);
		this.setBlock(world, i + 12, j + 30, k + 24, Blocks.log, 1);
		this.setBlock(world, i + 12, j + 30, k + 25, Blocks.log, 1);
		this.setBlock(world, i + 12, j + 30, k + 26, Blocks.log, 1);
		this.setBlock(world, i + 12, j + 31, k + 10, Blocks.log, 1);
		this.setBlock(world, i + 12, j + 31, k + 11, Blocks.log, 1);
		this.setBlock(world, i + 12, j + 31, k + 12, Blocks.log, 1);
		this.setBlock(world, i + 12, j + 31, k + 15, Blocks.leaves, 0);
		this.setBlock(world, i + 12, j + 31, k + 16, Blocks.log, 1);
		this.setBlock(world, i + 12, j + 31, k + 17, Blocks.log, 1);
		this.setBlock(world, i + 12, j + 31, k + 18, Blocks.log, 1);
		this.setBlock(world, i + 12, j + 31, k + 19, Blocks.log, 1);
		this.setBlock(world, i + 12, j + 31, k + 25, Blocks.log, 1);
		this.setBlock(world, i + 12, j + 32, k + 9, Blocks.log, 1);
		this.setBlock(world, i + 12, j + 32, k + 10, Blocks.log, 1);
		this.setBlock(world, i + 12, j + 32, k + 11, Blocks.log, 1);
		this.setBlock(world, i + 12, j + 32, k + 12, Blocks.log, 1);
		this.setBlock(world, i + 12, j + 32, k + 13, Blocks.log, 1);
		this.setBlock(world, i + 12, j + 32, k + 14, Blocks.leaves, 0);
		this.setBlock(world, i + 12, j + 32, k + 15, Blocks.leaves, 0);
		this.setBlock(world, i + 12, j + 32, k + 16, Blocks.log, 1);
		this.setBlock(world, i + 12, j + 32, k + 17, Blocks.log, 1);
		this.setBlock(world, i + 12, j + 32, k + 18, Blocks.log, 1);
		this.setBlock(world, i + 12, j + 32, k + 19, Blocks.leaves, 0);
		this.setBlock(world, i + 12, j + 32, k + 27, Blocks.leaves, 0);
		this.setBlock(world, i + 12, j + 32, k + 28, Blocks.leaves, 0);
		this.setBlock(world, i + 12, j + 32, k + 29, Blocks.leaves, 0);
		this.setBlock(world, i + 12, j + 33, k + 10, Blocks.log, 1);
		this.setBlock(world, i + 12, j + 33, k + 11, Blocks.log, 1);
		this.setBlock(world, i + 12, j + 33, k + 12, Blocks.log, 1);
		this.setBlock(world, i + 12, j + 33, k + 15, Blocks.log, 1);
		this.setBlock(world, i + 12, j + 33, k + 16, Blocks.leaves, 0);
		this.setBlock(world, i + 12, j + 33, k + 17, Blocks.leaves, 0);
		this.setBlock(world, i + 12, j + 33, k + 18, Blocks.leaves, 0);
		this.setBlock(world, i + 12, j + 33, k + 19, Blocks.leaves, 0);
		this.setBlock(world, i + 12, j + 33, k + 20, Blocks.leaves, 0);
		this.setBlock(world, i + 12, j + 33, k + 27, Blocks.leaves, 0);
		this.setBlock(world, i + 12, j + 33, k + 28, Blocks.leaves, 0);
		this.setBlock(world, i + 12, j + 33, k + 29, Blocks.leaves, 0);
		this.setBlock(world, i + 12, j + 33, k + 31, Blocks.leaves, 0);
		this.setBlock(world, i + 12, j + 34, k + 11, Blocks.log, 1);
		this.setBlock(world, i + 12, j + 34, k + 14, Blocks.leaves, 0);
		this.setBlock(world, i + 12, j + 34, k + 15, Blocks.log, 1);
		this.setBlock(world, i + 12, j + 34, k + 16, Blocks.log, 1);
		this.setBlock(world, i + 12, j + 34, k + 17, Blocks.leaves, 0);
		this.setBlock(world, i + 12, j + 34, k + 18, Blocks.leaves, 0);
		this.setBlock(world, i + 12, j + 34, k + 27, Blocks.leaves, 0);
		this.setBlock(world, i + 12, j + 34, k + 28, Blocks.leaves, 0);
		this.setBlock(world, i + 12, j + 34, k + 29, Blocks.leaves, 0);
		this.setBlock(world, i + 12, j + 35, k + 15, Blocks.leaves, 0);
		this.setBlock(world, i + 12, j + 35, k + 16, Blocks.leaves, 0);
		this.setBlock(world, i + 12, j + 35, k + 17, Blocks.leaves, 0);
		this.setBlock(world, i + 12, j + 36, k + 9, Blocks.leaves, 0);
		this.setBlock(world, i + 12, j + 36, k + 16, Blocks.leaves, 0);
		this.setBlock(world, i + 12, j + 41, k + 19, Blocks.leaves, 0);
		this.setBlock(world, i + 12, j + 41, k + 20, Blocks.leaves, 0);
		this.setBlock(world, i + 12, j + 41, k + 21, Blocks.leaves, 0);
		this.setBlock(world, i + 12, j + 42, k + 17, Blocks.leaves, 0);
		this.setBlock(world, i + 12, j + 42, k + 19, Blocks.log, 1);
		this.setBlock(world, i + 12, j + 42, k + 20, Blocks.leaves, 0);
		this.setBlock(world, i + 12, j + 42, k + 21, Blocks.leaves, 0);
		this.setBlock(world, i + 12, j + 42, k + 25, Blocks.leaves, 0);
		this.setBlock(world, i + 12, j + 43, k + 19, Blocks.leaves, 0);
		this.setBlock(world, i + 12, j + 43, k + 20, Blocks.leaves, 0);
		this.setBlock(world, i + 12, j + 43, k + 21, Blocks.leaves, 0);
		this.setBlock(world, i + 12, j + 43, k + 22, Blocks.leaves, 0);
		this.setBlock(world, i + 13, j + 0, k + 14, Blocks.log, 0);
		this.setBlock(world, i + 13, j + 0, k + 15, Blocks.log, 0);
		this.setBlock(world, i + 13, j + 0, k + 16, Blocks.log, 0);
		this.setBlock(world, i + 13, j + 0, k + 17, Blocks.log, 0);
		this.setBlock(world, i + 13, j + 0, k + 18, Blocks.log, 0);
		this.setBlock(world, i + 13, j + 0, k + 29, Blocks.log, 0);
		this.setBlock(world, i + 13, j + 0, k + 30, Blocks.log, 0);
		this.setBlock(world, i + 13, j + 1, k + 15, Blocks.log, 0);
		this.setBlock(world, i + 13, j + 1, k + 16, Blocks.log, 0);
		this.setBlock(world, i + 13, j + 1, k + 17, Blocks.log, 0);
		this.setBlock(world, i + 13, j + 1, k + 18, Blocks.log, 0);
		this.setBlock(world, i + 13, j + 1, k + 28, Blocks.log, 0);
		this.setBlock(world, i + 13, j + 1, k + 29, Blocks.log, 0);
		this.setBlock(world, i + 13, j + 1, k + 30, Blocks.log, 0);
		this.setBlock(world, i + 13, j + 1, k + 31, Blocks.log, 0);
		this.setBlock(world, i + 13, j + 2, k + 16, Blocks.log, 0);
		this.setBlock(world, i + 13, j + 2, k + 17, Blocks.log, 0);
		this.setBlock(world, i + 13, j + 2, k + 18, Blocks.log, 0);
		this.setBlock(world, i + 13, j + 2, k + 19, Blocks.log, 0);
		this.setBlock(world, i + 13, j + 2, k + 29, Blocks.log, 0);
		this.setBlock(world, i + 13, j + 2, k + 30, Blocks.log, 0);
		this.setBlock(world, i + 13, j + 3, k + 17, Blocks.log, 0);
		this.setBlock(world, i + 13, j + 3, k + 18, Blocks.log, 0);
		this.setBlock(world, i + 13, j + 19, k + 20, Blocks.log, 1);
		this.setBlock(world, i + 13, j + 19, k + 21, Blocks.log, 1);
		this.setBlock(world, i + 13, j + 19, k + 22, Blocks.log, 1);
		this.setBlock(world, i + 13, j + 20, k + 20, Blocks.log, 1);
		this.setBlock(world, i + 13, j + 20, k + 21, Blocks.log, 1);
		this.setBlock(world, i + 13, j + 20, k + 22, Blocks.log, 1);
		this.setBlock(world, i + 13, j + 21, k + 20, Blocks.log, 1);
		this.setBlock(world, i + 13, j + 21, k + 21, Blocks.log, 1);
		this.setBlock(world, i + 13, j + 21, k + 22, Blocks.log, 1);
		this.setBlock(world, i + 13, j + 22, k + 20, Blocks.log, 1);
		this.setBlock(world, i + 13, j + 22, k + 21, Blocks.log, 1);
		this.setBlock(world, i + 13, j + 22, k + 22, Blocks.log, 1);
		this.setBlock(world, i + 13, j + 23, k + 20, Blocks.log, 1);
		this.setBlock(world, i + 13, j + 23, k + 21, Blocks.log, 1);
		this.setBlock(world, i + 13, j + 23, k + 22, Blocks.log, 1);
		this.setBlock(world, i + 13, j + 24, k + 19, Blocks.log, 1);
		this.setBlock(world, i + 13, j + 24, k + 20, Blocks.log, 1);
		this.setBlock(world, i + 13, j + 24, k + 21, Blocks.log, 1);
		this.setBlock(world, i + 13, j + 24, k + 22, Blocks.log, 1);
		this.setBlock(world, i + 13, j + 25, k + 19, Blocks.log, 1);
		this.setBlock(world, i + 13, j + 25, k + 20, Blocks.log, 1);
		this.setBlock(world, i + 13, j + 25, k + 21, Blocks.log, 1);
		this.setBlock(world, i + 13, j + 25, k + 22, Blocks.log, 1);
		this.setBlock(world, i + 13, j + 25, k + 23, Blocks.log, 1);
		this.setBlock(world, i + 13, j + 26, k + 19, Blocks.log, 1);
		this.setBlock(world, i + 13, j + 26, k + 20, Blocks.log, 1);
		this.setBlock(world, i + 13, j + 26, k + 21, Blocks.log, 1);
		this.setBlock(world, i + 13, j + 26, k + 22, Blocks.log, 1);
		this.setBlock(world, i + 13, j + 26, k + 23, Blocks.log, 1);
		this.setBlock(world, i + 13, j + 27, k + 19, Blocks.log, 1);
		this.setBlock(world, i + 13, j + 27, k + 20, Blocks.log, 1);
		this.setBlock(world, i + 13, j + 27, k + 21, Blocks.log, 1);
		this.setBlock(world, i + 13, j + 27, k + 22, Blocks.log, 1);
		this.setBlock(world, i + 13, j + 27, k + 23, Blocks.log, 1);
		this.setBlock(world, i + 13, j + 27, k + 24, Blocks.log, 1);
		this.setBlock(world, i + 13, j + 28, k + 18, Blocks.log, 1);
		this.setBlock(world, i + 13, j + 28, k + 19, Blocks.log, 1);
		this.setBlock(world, i + 13, j + 28, k + 20, Blocks.log, 1);
		this.setBlock(world, i + 13, j + 28, k + 21, Blocks.log, 1);
		this.setBlock(world, i + 13, j + 28, k + 22, Blocks.log, 1);
		this.setBlock(world, i + 13, j + 28, k + 23, Blocks.log, 1);
		this.setBlock(world, i + 13, j + 28, k + 24, Blocks.log, 1);
		this.setBlock(world, i + 13, j + 28, k + 25, Blocks.log, 1);
		this.setBlock(world, i + 13, j + 29, k + 17, Blocks.log, 1);
		this.setBlock(world, i + 13, j + 29, k + 18, Blocks.log, 1);
		this.setBlock(world, i + 13, j + 29, k + 19, Blocks.log, 1);
		this.setBlock(world, i + 13, j + 29, k + 20, Blocks.log, 1);
		this.setBlock(world, i + 13, j + 29, k + 21, Blocks.log, 1);
		this.setBlock(world, i + 13, j + 29, k + 22, Blocks.log, 1);
		this.setBlock(world, i + 13, j + 29, k + 23, Blocks.log, 1);
		this.setBlock(world, i + 13, j + 29, k + 24, Blocks.log, 1);
		this.setBlock(world, i + 13, j + 29, k + 25, Blocks.log, 1);
		this.setBlock(world, i + 13, j + 30, k + 17, Blocks.log, 1);
		this.setBlock(world, i + 13, j + 30, k + 18, Blocks.log, 1);
		this.setBlock(world, i + 13, j + 30, k + 19, Blocks.log, 1);
		this.setBlock(world, i + 13, j + 30, k + 20, Blocks.log, 1);
		this.setBlock(world, i + 13, j + 30, k + 23, Blocks.log, 1);
		this.setBlock(world, i + 13, j + 30, k + 25, Blocks.log, 1);
		this.setBlock(world, i + 13, j + 31, k + 8, Blocks.log, 1);
		this.setBlock(world, i + 13, j + 31, k + 9, Blocks.log, 1);
		this.setBlock(world, i + 13, j + 31, k + 10, Blocks.log, 1);
		this.setBlock(world, i + 13, j + 31, k + 11, Blocks.log, 1);
		this.setBlock(world, i + 13, j + 31, k + 12, Blocks.log, 1);
		this.setBlock(world, i + 13, j + 31, k + 15, Blocks.leaves, 0);
		this.setBlock(world, i + 13, j + 31, k + 16, Blocks.leaves, 0);
		this.setBlock(world, i + 13, j + 31, k + 17, Blocks.log, 1);
		this.setBlock(world, i + 13, j + 31, k + 18, Blocks.log, 1);
		this.setBlock(world, i + 13, j + 31, k + 19, Blocks.log, 1);
		this.setBlock(world, i + 13, j + 32, k + 8, Blocks.log, 1);
		this.setBlock(world, i + 13, j + 32, k + 9, Blocks.log, 1);
		this.setBlock(world, i + 13, j + 32, k + 10, Blocks.log, 1);
		this.setBlock(world, i + 13, j + 32, k + 11, Blocks.log, 1);
		this.setBlock(world, i + 13, j + 32, k + 12, Blocks.log, 1);
		this.setBlock(world, i + 13, j + 32, k + 15, Blocks.leaves, 0);
		this.setBlock(world, i + 13, j + 32, k + 16, Blocks.leaves, 0);
		this.setBlock(world, i + 13, j + 32, k + 17, Blocks.leaves, 0);
		this.setBlock(world, i + 13, j + 32, k + 18, Blocks.leaves, 0);
		this.setBlock(world, i + 13, j + 32, k + 19, Blocks.leaves, 0);
		this.setBlock(world, i + 13, j + 32, k + 20, Blocks.leaves, 0);
		this.setBlock(world, i + 13, j + 33, k + 8, Blocks.log, 1);
		this.setBlock(world, i + 13, j + 33, k + 9, Blocks.log, 1);
		this.setBlock(world, i + 13, j + 33, k + 10, Blocks.log, 1);
		this.setBlock(world, i + 13, j + 33, k + 11, Blocks.log, 1);
		this.setBlock(world, i + 13, j + 33, k + 12, Blocks.log, 1);
		this.setBlock(world, i + 13, j + 33, k + 15, Blocks.leaves, 0);
		this.setBlock(world, i + 13, j + 33, k + 16, Blocks.leaves, 0);
		this.setBlock(world, i + 13, j + 33, k + 17, Blocks.leaves, 0);
		this.setBlock(world, i + 13, j + 33, k + 18, Blocks.leaves, 0);
		this.setBlock(world, i + 13, j + 33, k + 19, Blocks.leaves, 0);
		this.setBlock(world, i + 13, j + 33, k + 28, Blocks.leaves, 0);
		this.setBlock(world, i + 13, j + 34, k + 15, Blocks.log, 1);
		this.setBlock(world, i + 13, j + 34, k + 16, Blocks.leaves, 0);
		this.setBlock(world, i + 13, j + 34, k + 17, Blocks.leaves, 0);
		this.setBlock(world, i + 13, j + 34, k + 18, Blocks.leaves, 0);
		this.setBlock(world, i + 13, j + 34, k + 30, Blocks.leaves, 0);
		this.setBlock(world, i + 13, j + 34, k + 32, Blocks.leaves, 0);
		this.setBlock(world, i + 13, j + 35, k + 15, Blocks.leaves, 0);
		this.setBlock(world, i + 13, j + 35, k + 16, Blocks.leaves, 0);
		this.setBlock(world, i + 13, j + 35, k + 17, Blocks.leaves, 0);
		this.setBlock(world, i + 13, j + 40, k + 20, Blocks.leaves, 0);
		this.setBlock(world, i + 13, j + 41, k + 16, Blocks.leaves, 0);
		this.setBlock(world, i + 13, j + 41, k + 17, Blocks.leaves, 0);
		this.setBlock(world, i + 13, j + 41, k + 18, Blocks.log, 1);
		this.setBlock(world, i + 13, j + 41, k + 19, Blocks.leaves, 0);
		this.setBlock(world, i + 13, j + 41, k + 20, Blocks.leaves, 0);
		this.setBlock(world, i + 13, j + 41, k + 21, Blocks.leaves, 0);
		this.setBlock(world, i + 13, j + 41, k + 24, Blocks.leaves, 0);
		this.setBlock(world, i + 13, j + 41, k + 25, Blocks.leaves, 0);
		this.setBlock(world, i + 13, j + 41, k + 26, Blocks.leaves, 0);
		this.setBlock(world, i + 13, j + 42, k + 16, Blocks.leaves, 0);
		this.setBlock(world, i + 13, j + 42, k + 17, Blocks.log, 1);
		this.setBlock(world, i + 13, j + 42, k + 18, Blocks.leaves, 0);
		this.setBlock(world, i + 13, j + 42, k + 19, Blocks.leaves, 0);
		this.setBlock(world, i + 13, j + 42, k + 20, Blocks.leaves, 0);
		this.setBlock(world, i + 13, j + 42, k + 21, Blocks.log, 1);
		this.setBlock(world, i + 13, j + 42, k + 22, Blocks.log, 1);
		this.setBlock(world, i + 13, j + 42, k + 23, Blocks.log, 1);
		this.setBlock(world, i + 13, j + 42, k + 24, Blocks.leaves, 0);
		this.setBlock(world, i + 13, j + 42, k + 25, Blocks.leaves, 0);
		this.setBlock(world, i + 13, j + 42, k + 26, Blocks.leaves, 0);
		this.setBlock(world, i + 13, j + 43, k + 16, Blocks.leaves, 0);
		this.setBlock(world, i + 13, j + 43, k + 17, Blocks.leaves, 0);
		this.setBlock(world, i + 13, j + 43, k + 18, Blocks.leaves, 0);
		this.setBlock(world, i + 13, j + 43, k + 19, Blocks.leaves, 0);
		this.setBlock(world, i + 13, j + 43, k + 20, Blocks.leaves, 0);
		this.setBlock(world, i + 13, j + 43, k + 21, Blocks.log, 1);
		this.setBlock(world, i + 13, j + 43, k + 22, Blocks.leaves, 0);
		this.setBlock(world, i + 13, j + 43, k + 23, Blocks.leaves, 0);
		this.setBlock(world, i + 13, j + 43, k + 24, Blocks.leaves, 0);
		this.setBlock(world, i + 13, j + 43, k + 25, Blocks.leaves, 0);
		this.setBlock(world, i + 13, j + 43, k + 26, Blocks.leaves, 0);
		this.setBlock(world, i + 13, j + 44, k + 20, Blocks.leaves, 0);
		this.setBlock(world, i + 13, j + 44, k + 21, Blocks.leaves, 0);
		this.setBlock(world, i + 13, j + 44, k + 22, Blocks.leaves, 0);
		this.setBlock(world, i + 13, j + 44, k + 23, Blocks.leaves, 0);
		this.setBlock(world, i + 14, j + 0, k + 14, Blocks.log, 0);
		this.setBlock(world, i + 14, j + 0, k + 15, Blocks.log, 0);
		this.setBlock(world, i + 14, j + 0, k + 16, Blocks.log, 0);
		this.setBlock(world, i + 14, j + 0, k + 17, Blocks.log, 0);
		this.setBlock(world, i + 14, j + 0, k + 18, Blocks.log, 0);
		this.setBlock(world, i + 14, j + 0, k + 29, Blocks.log, 0);
		this.setBlock(world, i + 14, j + 1, k + 15, Blocks.log, 0);
		this.setBlock(world, i + 14, j + 1, k + 16, Blocks.log, 0);
		this.setBlock(world, i + 14, j + 1, k + 17, Blocks.log, 0);
		this.setBlock(world, i + 14, j + 1, k + 18, Blocks.log, 0);
		this.setBlock(world, i + 14, j + 1, k + 19, Blocks.log, 0);
		this.setBlock(world, i + 14, j + 1, k + 27, Blocks.log, 0);
		this.setBlock(world, i + 14, j + 1, k + 28, Blocks.log, 0);
		this.setBlock(world, i + 14, j + 1, k + 29, Blocks.log, 0);
		this.setBlock(world, i + 14, j + 1, k + 30, Blocks.log, 0);
		this.setBlock(world, i + 14, j + 2, k + 17, Blocks.log, 0);
		this.setBlock(world, i + 14, j + 2, k + 18, Blocks.log, 0);
		this.setBlock(world, i + 14, j + 2, k + 19, Blocks.log, 0);
		this.setBlock(world, i + 14, j + 2, k + 20, Blocks.log, 0);
		this.setBlock(world, i + 14, j + 2, k + 29, Blocks.log, 0);
		this.setBlock(world, i + 14, j + 3, k + 18, Blocks.log, 0);
		this.setBlock(world, i + 14, j + 3, k + 19, Blocks.log, 0);
		this.setBlock(world, i + 14, j + 3, k + 20, Blocks.log, 0);
		this.setBlock(world, i + 14, j + 3, k + 21, Blocks.log, 0);
		this.setBlock(world, i + 14, j + 16, k + 21, Blocks.log, 1);
		this.setBlock(world, i + 14, j + 16, k + 22, Blocks.log, 1);
		this.setBlock(world, i + 14, j + 16, k + 23, Blocks.log, 1);
		this.setBlock(world, i + 14, j + 17, k + 21, Blocks.log, 1);
		this.setBlock(world, i + 14, j + 17, k + 22, Blocks.log, 1);
		this.setBlock(world, i + 14, j + 17, k + 23, Blocks.log, 1);
		this.setBlock(world, i + 14, j + 18, k + 20, Blocks.log, 1);
		this.setBlock(world, i + 14, j + 18, k + 21, Blocks.log, 1);
		this.setBlock(world, i + 14, j + 18, k + 22, Blocks.log, 1);
		this.setBlock(world, i + 14, j + 19, k + 19, Blocks.log, 1);
		this.setBlock(world, i + 14, j + 19, k + 20, Blocks.log, 1);
		this.setBlock(world, i + 14, j + 19, k + 21, Blocks.log, 1);
		this.setBlock(world, i + 14, j + 19, k + 22, Blocks.log, 1);
		this.setBlock(world, i + 14, j + 19, k + 23, Blocks.log, 1);
		this.setBlock(world, i + 14, j + 20, k + 19, Blocks.log, 1);
		this.setBlock(world, i + 14, j + 20, k + 20, Blocks.log, 1);
		this.setBlock(world, i + 14, j + 20, k + 21, Blocks.log, 1);
		this.setBlock(world, i + 14, j + 20, k + 22, Blocks.log, 1);
		this.setBlock(world, i + 14, j + 20, k + 23, Blocks.log, 1);
		this.setBlock(world, i + 14, j + 21, k + 19, Blocks.log, 1);
		this.setBlock(world, i + 14, j + 21, k + 20, Blocks.log, 1);
		this.setBlock(world, i + 14, j + 21, k + 21, Blocks.log, 1);
		this.setBlock(world, i + 14, j + 21, k + 22, Blocks.log, 1);
		this.setBlock(world, i + 14, j + 21, k + 23, Blocks.log, 1);
		this.setBlock(world, i + 14, j + 22, k + 19, Blocks.log, 1);
		this.setBlock(world, i + 14, j + 22, k + 20, Blocks.log, 1);
		this.setBlock(world, i + 14, j + 22, k + 21, Blocks.log, 1);
		this.setBlock(world, i + 14, j + 22, k + 22, Blocks.log, 1);
		this.setBlock(world, i + 14, j + 22, k + 23, Blocks.log, 1);
		this.setBlock(world, i + 14, j + 23, k + 19, Blocks.log, 1);
		this.setBlock(world, i + 14, j + 23, k + 20, Blocks.log, 1);
		this.setBlock(world, i + 14, j + 23, k + 21, Blocks.log, 1);
		this.setBlock(world, i + 14, j + 23, k + 22, Blocks.log, 1);
		this.setBlock(world, i + 14, j + 23, k + 23, Blocks.log, 1);
		this.setBlock(world, i + 14, j + 24, k + 18, Blocks.log, 1);
		this.setBlock(world, i + 14, j + 24, k + 19, Blocks.log, 1);
		this.setBlock(world, i + 14, j + 24, k + 20, Blocks.log, 1);
		this.setBlock(world, i + 14, j + 24, k + 21, Blocks.log, 1);
		this.setBlock(world, i + 14, j + 24, k + 22, Blocks.log, 1);
		this.setBlock(world, i + 14, j + 24, k + 23, Blocks.log, 1);
		this.setBlock(world, i + 14, j + 25, k + 18, Blocks.log, 1);
		this.setBlock(world, i + 14, j + 25, k + 19, Blocks.log, 1);
		this.setBlock(world, i + 14, j + 25, k + 20, Blocks.log, 1);
		this.setBlock(world, i + 14, j + 25, k + 21, Blocks.log, 1);
		this.setBlock(world, i + 14, j + 25, k + 22, Blocks.log, 1);
		this.setBlock(world, i + 14, j + 25, k + 23, Blocks.log, 1);
		this.setBlock(world, i + 14, j + 26, k + 18, Blocks.log, 1);
		this.setBlock(world, i + 14, j + 26, k + 19, Blocks.log, 1);
		this.setBlock(world, i + 14, j + 26, k + 20, Blocks.log, 1);
		this.setBlock(world, i + 14, j + 26, k + 21, Blocks.log, 1);
		this.setBlock(world, i + 14, j + 26, k + 22, Blocks.log, 1);
		this.setBlock(world, i + 14, j + 26, k + 23, Blocks.log, 1);
		this.setBlock(world, i + 14, j + 27, k + 19, Blocks.log, 1);
		this.setBlock(world, i + 14, j + 27, k + 20, Blocks.log, 1);
		this.setBlock(world, i + 14, j + 27, k + 21, Blocks.log, 1);
		this.setBlock(world, i + 14, j + 27, k + 22, Blocks.log, 1);
		this.setBlock(world, i + 14, j + 27, k + 23, Blocks.log, 1);
		this.setBlock(world, i + 14, j + 28, k + 19, Blocks.log, 1);
		this.setBlock(world, i + 14, j + 28, k + 20, Blocks.log, 1);
		this.setBlock(world, i + 14, j + 28, k + 21, Blocks.log, 1);
		this.setBlock(world, i + 14, j + 28, k + 22, Blocks.log, 1);
		this.setBlock(world, i + 14, j + 28, k + 23, Blocks.log, 1);
		this.setBlock(world, i + 14, j + 28, k + 24, Blocks.log, 1);
		this.setBlock(world, i + 14, j + 29, k + 19, Blocks.log, 1);
		this.setBlock(world, i + 14, j + 29, k + 20, Blocks.log, 1);
		this.setBlock(world, i + 14, j + 29, k + 21, Blocks.log, 1);
		this.setBlock(world, i + 14, j + 29, k + 23, Blocks.log, 1);
		this.setBlock(world, i + 14, j + 29, k + 24, Blocks.log, 1);
		this.setBlock(world, i + 14, j + 30, k + 9, Blocks.log, 1);
		this.setBlock(world, i + 14, j + 30, k + 11, Blocks.log, 1);
		this.setBlock(world, i + 14, j + 30, k + 18, Blocks.log, 1);
		this.setBlock(world, i + 14, j + 30, k + 25, Blocks.log, 1);
		this.setBlock(world, i + 14, j + 31, k + 8, Blocks.log, 1);
		this.setBlock(world, i + 14, j + 31, k + 9, Blocks.log, 1);
		this.setBlock(world, i + 14, j + 31, k + 10, Blocks.log, 1);
		this.setBlock(world, i + 14, j + 31, k + 11, Blocks.log, 1);
		this.setBlock(world, i + 14, j + 31, k + 12, Blocks.log, 1);
		this.setBlock(world, i + 14, j + 31, k + 17, Blocks.log, 1);
		this.setBlock(world, i + 14, j + 31, k + 18, Blocks.leaves, 0);
		this.setBlock(world, i + 14, j + 31, k + 19, Blocks.leaves, 0);
		this.setBlock(world, i + 14, j + 32, k + 7, Blocks.log, 1);
		this.setBlock(world, i + 14, j + 32, k + 8, Blocks.log, 1);
		this.setBlock(world, i + 14, j + 32, k + 9, Blocks.log, 1);
		this.setBlock(world, i + 14, j + 32, k + 10, Blocks.log, 1);
		this.setBlock(world, i + 14, j + 32, k + 11, Blocks.log, 1);
		this.setBlock(world, i + 14, j + 32, k + 12, Blocks.log, 1);
		this.setBlock(world, i + 14, j + 32, k + 13, Blocks.log, 1);
		this.setBlock(world, i + 14, j + 32, k + 16, Blocks.leaves, 0);
		this.setBlock(world, i + 14, j + 32, k + 17, Blocks.leaves, 0);
		this.setBlock(world, i + 14, j + 32, k + 18, Blocks.log, 1);
		this.setBlock(world, i + 14, j + 32, k + 19, Blocks.leaves, 0);
		this.setBlock(world, i + 14, j + 33, k + 8, Blocks.log, 1);
		this.setBlock(world, i + 14, j + 33, k + 9, Blocks.log, 1);
		this.setBlock(world, i + 14, j + 33, k + 10, Blocks.log, 1);
		this.setBlock(world, i + 14, j + 33, k + 11, Blocks.log, 1);
		this.setBlock(world, i + 14, j + 33, k + 12, Blocks.log, 1);
		this.setBlock(world, i + 14, j + 33, k + 17, Blocks.leaves, 0);
		this.setBlock(world, i + 14, j + 33, k + 18, Blocks.leaves, 0);
		this.setBlock(world, i + 14, j + 33, k + 19, Blocks.leaves, 0);
		this.setBlock(world, i + 14, j + 33, k + 29, Blocks.leaves, 0);
		this.setBlock(world, i + 14, j + 33, k + 30, Blocks.leaves, 0);
		this.setBlock(world, i + 14, j + 33, k + 31, Blocks.log, 1);
		this.setBlock(world, i + 14, j + 33, k + 32, Blocks.leaves, 0);
		this.setBlock(world, i + 14, j + 33, k + 33, Blocks.leaves, 0);
		this.setBlock(world, i + 14, j + 34, k + 9, Blocks.log, 1);
		this.setBlock(world, i + 14, j + 34, k + 11, Blocks.log, 1);
		this.setBlock(world, i + 14, j + 34, k + 16, Blocks.leaves, 0);
		this.setBlock(world, i + 14, j + 34, k + 29, Blocks.leaves, 0);

		generate2(world, rand, i, j, k);
		return true;
	}

	public boolean generate2(World world, Random rand, int i, int j, int k) {
		this.setBlock(world, i + 14, j + 34, k + 30, Blocks.leaves, 0);
		this.setBlock(world, i + 14, j + 34, k + 31, Blocks.log, 1);
		this.setBlock(world, i + 14, j + 34, k + 32, Blocks.leaves, 0);
		this.setBlock(world, i + 14, j + 34, k + 33, Blocks.leaves, 0);
		this.setBlock(world, i + 14, j + 35, k + 28, Blocks.leaves, 0);
		this.setBlock(world, i + 14, j + 35, k + 29, Blocks.leaves, 0);
		this.setBlock(world, i + 14, j + 35, k + 30, Blocks.leaves, 0);
		this.setBlock(world, i + 14, j + 35, k + 31, Blocks.leaves, 0);
		this.setBlock(world, i + 14, j + 35, k + 32, Blocks.leaves, 0);
		this.setBlock(world, i + 14, j + 35, k + 33, Blocks.leaves, 0);
		this.setBlock(world, i + 14, j + 40, k + 17, Blocks.log, 1);
		this.setBlock(world, i + 14, j + 40, k + 19, Blocks.leaves, 0);
		this.setBlock(world, i + 14, j + 40, k + 25, Blocks.leaves, 0);
		this.setBlock(world, i + 14, j + 41, k + 15, Blocks.leaves, 0);
		this.setBlock(world, i + 14, j + 41, k + 16, Blocks.leaves, 0);
		this.setBlock(world, i + 14, j + 41, k + 17, Blocks.leaves, 0);
		this.setBlock(world, i + 14, j + 41, k + 18, Blocks.leaves, 0);
		this.setBlock(world, i + 14, j + 41, k + 19, Blocks.leaves, 0);
		this.setBlock(world, i + 14, j + 41, k + 20, Blocks.leaves, 0);
		this.setBlock(world, i + 14, j + 41, k + 21, Blocks.leaves, 0);
		this.setBlock(world, i + 14, j + 41, k + 22, Blocks.leaves, 0);
		this.setBlock(world, i + 14, j + 41, k + 23, Blocks.leaves, 0);
		this.setBlock(world, i + 14, j + 41, k + 24, Blocks.leaves, 0);
		this.setBlock(world, i + 14, j + 41, k + 25, Blocks.log, 1);
		this.setBlock(world, i + 14, j + 41, k + 26, Blocks.log, 1);
		this.setBlock(world, i + 14, j + 42, k + 15, Blocks.leaves, 0);
		this.setBlock(world, i + 14, j + 42, k + 16, Blocks.leaves, 0);
		this.setBlock(world, i + 14, j + 42, k + 17, Blocks.leaves, 0);
		this.setBlock(world, i + 14, j + 42, k + 18, Blocks.leaves, 0);
		this.setBlock(world, i + 14, j + 42, k + 19, Blocks.leaves, 0);
		this.setBlock(world, i + 14, j + 42, k + 20, Blocks.leaves, 0);
		this.setBlock(world, i + 14, j + 42, k + 21, Blocks.leaves, 0);
		this.setBlock(world, i + 14, j + 42, k + 22, Blocks.leaves, 0);
		this.setBlock(world, i + 14, j + 42, k + 23, Blocks.leaves, 0);
		this.setBlock(world, i + 14, j + 42, k + 24, Blocks.leaves, 0);
		this.setBlock(world, i + 14, j + 42, k + 25, Blocks.leaves, 0);
		this.setBlock(world, i + 14, j + 42, k + 26, Blocks.leaves, 0);
		this.setBlock(world, i + 14, j + 42, k + 27, Blocks.leaves, 0);
		this.setBlock(world, i + 14, j + 43, k + 15, Blocks.leaves, 0);
		this.setBlock(world, i + 14, j + 43, k + 16, Blocks.leaves, 0);
		this.setBlock(world, i + 14, j + 43, k + 17, Blocks.leaves, 0);
		this.setBlock(world, i + 14, j + 43, k + 18, Blocks.leaves, 0);
		this.setBlock(world, i + 14, j + 43, k + 19, Blocks.leaves, 0);
		this.setBlock(world, i + 14, j + 43, k + 20, Blocks.leaves, 0);
