/*
*** MADE BY MRPONYCAPTAIN'S .SCHEMATIC TO .JAVA CONVERTING TOOL v2.0 ***
*/

package com.DavidM1A2.AfraidOfTheDark.common.worldGeneration.darkForestDungeon;

import java.util.Random;
import net.minecraft.block.Block;
import net.minecraft.init.Blocks;
import net.minecraft.tileentity.TileEntity;
import net.minecraft.tileentity.TileEntityChest;
import net.minecraft.tileentity.TileEntityMobSpawner;
import net.minecraft.util.BlockPos;
import net.minecraft.util.WeightedRandomChestContent;
import net.minecraft.world.World;
import java.util.Random;

public class TreeBranchyType2
{
	public TreeBranchyType2(World world, Random rand, int x, int y, int z) 
	{
		this.generate(world, rand, x, y, z);
	}

	public void setBlock(World world, int x, int y, int z, Block block, int metadata)
	{
		world.setBlockState(new BlockPos(x, y, z), block.getStateFromMeta(metadata));
	}

	public boolean generate(World world, Random rand, int i, int j, int k) {
		this.setBlock(world, i + 0, j + 49, k + 28, Blocks.leaves, 0);
		this.setBlock(world, i + 1, j + 48, k + 28, Blocks.leaves, 0);
		this.setBlock(world, i + 1, j + 49, k + 27, Blocks.leaves, 0);
		this.setBlock(world, i + 1, j + 49, k + 28, Blocks.leaves, 0);
		this.setBlock(world, i + 1, j + 49, k + 29, Blocks.leaves, 0);
		this.setBlock(world, i + 1, j + 50, k + 21, Blocks.leaves, 0);
		this.setBlock(world, i + 1, j + 50, k + 22, Blocks.leaves, 0);
		this.setBlock(world, i + 1, j + 50, k + 28, Blocks.leaves, 0);
		this.setBlock(world, i + 2, j + 48, k + 27, Blocks.leaves, 0);
		this.setBlock(world, i + 2, j + 48, k + 28, Blocks.leaves, 0);
		this.setBlock(world, i + 2, j + 48, k + 29, Blocks.leaves, 0);
		this.setBlock(world, i + 2, j + 49, k + 21, Blocks.leaves, 0);
		this.setBlock(world, i + 2, j + 49, k + 22, Blocks.leaves, 0);
		this.setBlock(world, i + 2, j + 49, k + 24, Blocks.log, 1);
		this.setBlock(world, i + 2, j + 49, k + 26, Blocks.leaves, 0);
		this.setBlock(world, i + 2, j + 49, k + 27, Blocks.leaves, 0);
		this.setBlock(world, i + 2, j + 49, k + 28, Blocks.log, 1);
		this.setBlock(world, i + 2, j + 49, k + 29, Blocks.leaves, 0);
		this.setBlock(world, i + 2, j + 49, k + 30, Blocks.leaves, 0);
		this.setBlock(world, i + 2, j + 50, k + 20, Blocks.leaves, 0);
		this.setBlock(world, i + 2, j + 50, k + 21, Blocks.leaves, 0);
		this.setBlock(world, i + 2, j + 50, k + 22, Blocks.leaves, 0);
		this.setBlock(world, i + 2, j + 50, k + 23, Blocks.leaves, 0);
		this.setBlock(world, i + 2, j + 50, k + 24, Blocks.leaves, 0);
		this.setBlock(world, i + 2, j + 50, k + 27, Blocks.leaves, 0);
		this.setBlock(world, i + 2, j + 50, k + 28, Blocks.leaves, 0);
		this.setBlock(world, i + 2, j + 50, k + 29, Blocks.leaves, 0);
		this.setBlock(world, i + 2, j + 51, k + 21, Blocks.leaves, 0);
		this.setBlock(world, i + 2, j + 51, k + 22, Blocks.leaves, 0);
		this.setBlock(world, i + 3, j + 47, k + 28, Blocks.leaves, 0);
		this.setBlock(world, i + 3, j + 48, k + 23, Blocks.log, 1);
		this.setBlock(world, i + 3, j + 48, k + 24, Blocks.leaves, 0);
		this.setBlock(world, i + 3, j + 48, k + 25, Blocks.log, 1);
		this.setBlock(world, i + 3, j + 48, k + 26, Blocks.leaves, 0);
		this.setBlock(world, i + 3, j + 48, k + 27, Blocks.leaves, 0);
		this.setBlock(world, i + 3, j + 48, k + 28, Blocks.leaves, 0);
		this.setBlock(world, i + 3, j + 48, k + 29, Blocks.leaves, 0);
		this.setBlock(world, i + 3, j + 48, k + 30, Blocks.log, 1);
		this.setBlock(world, i + 3, j + 49, k + 20, Blocks.leaves, 0);
		this.setBlock(world, i + 3, j + 49, k + 21, Blocks.leaves, 0);
		this.setBlock(world, i + 3, j + 49, k + 22, Blocks.leaves, 0);
		this.setBlock(world, i + 3, j + 49, k + 23, Blocks.log, 1);
		this.setBlock(world, i + 3, j + 49, k + 24, Blocks.leaves, 0);
		this.setBlock(world, i + 3, j + 49, k + 25, Blocks.leaves, 0);
		this.setBlock(world, i + 3, j + 49, k + 26, Blocks.leaves, 0);
		this.setBlock(world, i + 3, j + 49, k + 27, Blocks.leaves, 0);
		this.setBlock(world, i + 3, j + 49, k + 28, Blocks.leaves, 0);
		this.setBlock(world, i + 3, j + 49, k + 29, Blocks.leaves, 0);
		this.setBlock(world, i + 3, j + 49, k + 30, Blocks.leaves, 0);
		this.setBlock(world, i + 3, j + 49, k + 31, Blocks.leaves, 0);
		this.setBlock(world, i + 3, j + 50, k + 19, Blocks.leaves, 0);
		this.setBlock(world, i + 3, j + 50, k + 20, Blocks.leaves, 0);
		this.setBlock(world, i + 3, j + 50, k + 21, Blocks.log, 1);
		this.setBlock(world, i + 3, j + 50, k + 22, Blocks.leaves, 0);
		this.setBlock(world, i + 3, j + 50, k + 23, Blocks.leaves, 0);
		this.setBlock(world, i + 3, j + 50, k + 24, Blocks.leaves, 0);
		this.setBlock(world, i + 3, j + 50, k + 25, Blocks.leaves, 0);
		this.setBlock(world, i + 3, j + 50, k + 26, Blocks.leaves, 0);
		this.setBlock(world, i + 3, j + 50, k + 27, Blocks.leaves, 0);
		this.setBlock(world, i + 3, j + 50, k + 28, Blocks.leaves, 0);
		this.setBlock(world, i + 3, j + 50, k + 29, Blocks.leaves, 0);
		this.setBlock(world, i + 3, j + 50, k + 30, Blocks.leaves, 0);
		this.setBlock(world, i + 3, j + 51, k + 20, Blocks.leaves, 0);
		this.setBlock(world, i + 3, j + 51, k + 21, Blocks.leaves, 0);
		this.setBlock(world, i + 3, j + 51, k + 22, Blocks.leaves, 0);
		this.setBlock(world, i + 3, j + 51, k + 24, Blocks.leaves, 0);
		this.setBlock(world, i + 3, j + 51, k + 28, Blocks.leaves, 0);
		this.setBlock(world, i + 4, j + 47, k + 22, Blocks.leaves, 0);
		this.setBlock(world, i + 4, j + 47, k + 23, Blocks.leaves, 0);
		this.setBlock(world, i + 4, j + 47, k + 24, Blocks.leaves, 0);
		this.setBlock(world, i + 4, j + 47, k + 27, Blocks.leaves, 0);
		this.setBlock(world, i + 4, j + 47, k + 28, Blocks.leaves, 0);
		this.setBlock(world, i + 4, j + 47, k + 29, Blocks.leaves, 0);
		this.setBlock(world, i + 4, j + 48, k + 21, Blocks.leaves, 0);
		this.setBlock(world, i + 4, j + 48, k + 22, Blocks.leaves, 0);
		this.setBlock(world, i + 4, j + 48, k + 23, Blocks.log, 1);
		this.setBlock(world, i + 4, j + 48, k + 24, Blocks.leaves, 0);
		this.setBlock(world, i + 4, j + 48, k + 25, Blocks.leaves, 0);
		this.setBlock(world, i + 4, j + 48, k + 26, Blocks.leaves, 0);
		this.setBlock(world, i + 4, j + 48, k + 27, Blocks.leaves, 0);
		this.setBlock(world, i + 4, j + 48, k + 28, Blocks.leaves, 0);
		this.setBlock(world, i + 4, j + 48, k + 29, Blocks.leaves, 0);
		this.setBlock(world, i + 4, j + 48, k + 30, Blocks.leaves, 0);
		this.setBlock(world, i + 4, j + 49, k + 19, Blocks.leaves, 0);
		this.setBlock(world, i + 4, j + 49, k + 20, Blocks.leaves, 0);
		this.setBlock(world, i + 4, j + 49, k + 21, Blocks.leaves, 0);
		this.setBlock(world, i + 4, j + 49, k + 22, Blocks.leaves, 0);
		this.setBlock(world, i + 4, j + 49, k + 23, Blocks.leaves, 0);
		this.setBlock(world, i + 4, j + 49, k + 24, Blocks.leaves, 0);
		this.setBlock(world, i + 4, j + 49, k + 25, Blocks.leaves, 0);
		this.setBlock(world, i + 4, j + 49, k + 26, Blocks.leaves, 0);
		this.setBlock(world, i + 4, j + 49, k + 27, Blocks.leaves, 0);
		this.setBlock(world, i + 4, j + 49, k + 28, Blocks.leaves, 0);
		this.setBlock(world, i + 4, j + 49, k + 29, Blocks.leaves, 0);
		this.setBlock(world, i + 4, j + 49, k + 30, Blocks.leaves, 0);
		this.setBlock(world, i + 4, j + 49, k + 31, Blocks.leaves, 0);
		this.setBlock(world, i + 4, j + 50, k + 18, Blocks.leaves, 0);
		this.setBlock(world, i + 4, j + 50, k + 19, Blocks.log, 1);
		this.setBlock(world, i + 4, j + 50, k + 20, Blocks.leaves, 0);
		this.setBlock(world, i + 4, j + 50, k + 21, Blocks.leaves, 0);
		this.setBlock(world, i + 4, j + 50, k + 22, Blocks.log, 1);
		this.setBlock(world, i + 4, j + 50, k + 23, Blocks.leaves, 0);
		this.setBlock(world, i + 4, j + 50, k + 24, Blocks.leaves, 0);
		this.setBlock(world, i + 4, j + 50, k + 25, Blocks.leaves, 0);
		this.setBlock(world, i + 4, j + 50, k + 26, Blocks.leaves, 0);
		this.setBlock(world, i + 4, j + 50, k + 27, Blocks.leaves, 0);
		this.setBlock(world, i + 4, j + 50, k + 28, Blocks.leaves, 0);
		this.setBlock(world, i + 4, j + 50, k + 29, Blocks.leaves, 0);
		this.setBlock(world, i + 4, j + 50, k + 30, Blocks.leaves, 0);
		this.setBlock(world, i + 4, j + 51, k + 19, Blocks.leaves, 0);
		this.setBlock(world, i + 4, j + 51, k + 20, Blocks.leaves, 0);
		this.setBlock(world, i + 4, j + 51, k + 21, Blocks.leaves, 0);
		this.setBlock(world, i + 4, j + 51, k + 22, Blocks.leaves, 0);
		this.setBlock(world, i + 4, j + 51, k + 23, Blocks.leaves, 0);
		this.setBlock(world, i + 4, j + 51, k + 24, Blocks.leaves, 0);
		this.setBlock(world, i + 4, j + 51, k + 27, Blocks.leaves, 8);
		this.setBlock(world, i + 4, j + 51, k + 28, Blocks.leaves, 0);
		this.setBlock(world, i + 4, j + 51, k + 29, Blocks.leaves, 8);
		this.setBlock(world, i + 4, j + 52, k + 21, Blocks.leaves, 0);
		this.setBlock(world, i + 5, j + 47, k + 21, Blocks.leaves, 0);
		this.setBlock(world, i + 5, j + 47, k + 22, Blocks.leaves, 0);
		this.setBlock(world, i + 5, j + 47, k + 23, Blocks.leaves, 0);
		this.setBlock(world, i + 5, j + 47, k + 24, Blocks.leaves, 0);
		this.setBlock(world, i + 5, j + 47, k + 25, Blocks.leaves, 0);
		this.setBlock(world, i + 5, j + 47, k + 26, Blocks.leaves, 0);
		this.setBlock(world, i + 5, j + 47, k + 27, Blocks.leaves, 0);
		this.setBlock(world, i + 5, j + 47, k + 28, Blocks.leaves, 0);
		this.setBlock(world, i + 5, j + 47, k + 29, Blocks.leaves, 0);
		this.setBlock(world, i + 5, j + 47, k + 30, Blocks.leaves, 0);
		this.setBlock(world, i + 5, j + 48, k + 21, Blocks.leaves, 0);
		this.setBlock(world, i + 5, j + 48, k + 22, Blocks.leaves, 0);
		this.setBlock(world, i + 5, j + 48, k + 23, Blocks.leaves, 0);
		this.setBlock(world, i + 5, j + 48, k + 24, Blocks.leaves, 0);
		this.setBlock(world, i + 5, j + 48, k + 25, Blocks.log, 1);
		this.setBlock(world, i + 5, j + 48, k + 26, Blocks.leaves, 0);
		this.setBlock(world, i + 5, j + 48, k + 27, Blocks.leaves, 0);
		this.setBlock(world, i + 5, j + 48, k + 28, Blocks.leaves, 0);
		this.setBlock(world, i + 5, j + 48, k + 29, Blocks.leaves, 0);
		this.setBlock(world, i + 5, j + 48, k + 30, Blocks.leaves, 0);
		this.setBlock(world, i + 5, j + 48, k + 31, Blocks.leaves, 0);
		this.setBlock(world, i + 5, j + 48, k + 32, Blocks.leaves, 0);
		this.setBlock(world, i + 5, j + 49, k + 20, Blocks.leaves, 0);
		this.setBlock(world, i + 5, j + 49, k + 21, Blocks.leaves, 0);
		this.setBlock(world, i + 5, j + 49, k + 22, Blocks.leaves, 0);
		this.setBlock(world, i + 5, j + 49, k + 23, Blocks.leaves, 0);
		this.setBlock(world, i + 5, j + 49, k + 24, Blocks.leaves, 0);
		this.setBlock(world, i + 5, j + 49, k + 25, Blocks.leaves, 0);
		this.setBlock(world, i + 5, j + 49, k + 26, Blocks.leaves, 0);
		this.setBlock(world, i + 5, j + 49, k + 27, Blocks.leaves, 0);
		this.setBlock(world, i + 5, j + 49, k + 28, Blocks.leaves, 0);
		this.setBlock(world, i + 5, j + 49, k + 29, Blocks.leaves, 0);
		this.setBlock(world, i + 5, j + 49, k + 30, Blocks.leaves, 0);
		this.setBlock(world, i + 5, j + 49, k + 31, Blocks.leaves, 0);
		this.setBlock(world, i + 5, j + 49, k + 32, Blocks.leaves, 0);
		this.setBlock(world, i + 5, j + 49, k + 33, Blocks.leaves, 0);
		this.setBlock(world, i + 5, j + 50, k + 19, Blocks.leaves, 0);
		this.setBlock(world, i + 5, j + 50, k + 20, Blocks.leaves, 0);
		this.setBlock(world, i + 5, j + 50, k + 21, Blocks.leaves, 0);
		this.setBlock(world, i + 5, j + 50, k + 22, Blocks.leaves, 0);
		this.setBlock(world, i + 5, j + 50, k + 23, Blocks.leaves, 0);
		this.setBlock(world, i + 5, j + 50, k + 24, Blocks.leaves, 0);
		this.setBlock(world, i + 5, j + 50, k + 25, Blocks.leaves, 0);
		this.setBlock(world, i + 5, j + 50, k + 26, Blocks.leaves, 0);
		this.setBlock(world, i + 5, j + 50, k + 27, Blocks.leaves, 0);
		this.setBlock(world, i + 5, j + 50, k + 28, Blocks.leaves, 0);
		this.setBlock(world, i + 5, j + 50, k + 29, Blocks.leaves, 0);
		this.setBlock(world, i + 5, j + 50, k + 30, Blocks.leaves, 0);
		this.setBlock(world, i + 5, j + 50, k + 31, Blocks.leaves, 0);
		this.setBlock(world, i + 5, j + 50, k + 32, Blocks.leaves, 0);
		this.setBlock(world, i + 5, j + 51, k + 20, Blocks.leaves, 0);
		this.setBlock(world, i + 5, j + 51, k + 21, Blocks.leaves, 0);
		this.setBlock(world, i + 5, j + 51, k + 22, Blocks.leaves, 0);
		this.setBlock(world, i + 5, j + 51, k + 23, Blocks.leaves, 0);
		this.setBlock(world, i + 5, j + 51, k + 24, Blocks.leaves, 0);
		this.setBlock(world, i + 5, j + 51, k + 25, Blocks.leaves, 0);
		this.setBlock(world, i + 5, j + 51, k + 26, Blocks.leaves, 0);
		this.setBlock(world, i + 5, j + 51, k + 27, Blocks.leaves, 0);
		this.setBlock(world, i + 5, j + 51, k + 28, Blocks.leaves, 0);
		this.setBlock(world, i + 5, j + 51, k + 29, Blocks.leaves, 0);
		this.setBlock(world, i + 5, j + 51, k + 30, Blocks.leaves, 0);
		this.setBlock(world, i + 6, j + 46, k + 23, Blocks.leaves, 0);
		this.setBlock(world, i + 6, j + 46, k + 24, Blocks.leaves, 0);
		this.setBlock(world, i + 6, j + 46, k + 25, Blocks.leaves, 0);
		this.setBlock(world, i + 6, j + 46, k + 26, Blocks.leaves, 0);
		this.setBlock(world, i + 6, j + 46, k + 27, Blocks.leaves, 0);
		this.setBlock(world, i + 6, j + 46, k + 28, Blocks.leaves, 0);
		this.setBlock(world, i + 6, j + 46, k + 29, Blocks.leaves, 0);
		this.setBlock(world, i + 6, j + 47, k + 21, Blocks.leaves, 0);
		this.setBlock(world, i + 6, j + 47, k + 22, Blocks.leaves, 0);
		this.setBlock(world, i + 6, j + 47, k + 23, Blocks.leaves, 0);
		this.setBlock(world, i + 6, j + 47, k + 24, Blocks.leaves, 0);
		this.setBlock(world, i + 6, j + 47, k + 25, Blocks.log, 1);
		this.setBlock(world, i + 6, j + 47, k + 26, Blocks.leaves, 0);
		this.setBlock(world, i + 6, j + 47, k + 27, Blocks.leaves, 0);
		this.setBlock(world, i + 6, j + 47, k + 28, Blocks.leaves, 0);
		this.setBlock(world, i + 6, j + 47, k + 29, Blocks.leaves, 0);
		this.setBlock(world, i + 6, j + 47, k + 30, Blocks.leaves, 0);
		this.setBlock(world, i + 6, j + 47, k + 31, Blocks.leaves, 0);
		this.setBlock(world, i + 6, j + 48, k + 20, Blocks.log, 1);
		this.setBlock(world, i + 6, j + 48, k + 21, Blocks.leaves, 0);
		this.setBlock(world, i + 6, j + 48, k + 22, Blocks.leaves, 0);
		this.setBlock(world, i + 6, j + 48, k + 23, Blocks.leaves, 0);
		this.setBlock(world, i + 6, j + 48, k + 24, Blocks.leaves, 0);
		this.setBlock(world, i + 6, j + 48, k + 25, Blocks.leaves, 0);
		this.setBlock(world, i + 6, j + 48, k + 26, Blocks.leaves, 0);
		this.setBlock(world, i + 6, j + 48, k + 27, Blocks.leaves, 0);
		this.setBlock(world, i + 6, j + 48, k + 28, Blocks.leaves, 0);
		this.setBlock(world, i + 6, j + 48, k + 29, Blocks.leaves, 0);
		this.setBlock(world, i + 6, j + 48, k + 30, Blocks.leaves, 0);
		this.setBlock(world, i + 6, j + 48, k + 31, Blocks.leaves, 0);
		this.setBlock(world, i + 6, j + 48, k + 32, Blocks.leaves, 0);
		this.setBlock(world, i + 6, j + 48, k + 33, Blocks.leaves, 0);
		this.setBlock(world, i + 6, j + 49, k + 19, Blocks.leaves, 0);
		this.setBlock(world, i + 6, j + 49, k + 20, Blocks.leaves, 0);
		this.setBlock(world, i + 6, j + 49, k + 21, Blocks.leaves, 0);
		this.setBlock(world, i + 6, j + 49, k + 22, Blocks.leaves, 0);
		this.setBlock(world, i + 6, j + 49, k + 23, Blocks.leaves, 0);
		this.setBlock(world, i + 6, j + 49, k + 24, Blocks.log, 1);
		this.setBlock(world, i + 6, j + 49, k + 25, Blocks.leaves, 0);
		this.setBlock(world, i + 6, j + 49, k + 26, Blocks.leaves, 0);
		this.setBlock(world, i + 6, j + 49, k + 27, Blocks.leaves, 0);
		this.setBlock(world, i + 6, j + 49, k + 28, Blocks.log, 1);
		this.setBlock(world, i + 6, j + 49, k + 29, Blocks.leaves, 0);
		this.setBlock(world, i + 6, j + 49, k + 30, Blocks.log, 1);
		this.setBlock(world, i + 6, j + 49, k + 31, Blocks.leaves, 0);
		this.setBlock(world, i + 6, j + 49, k + 32, Blocks.leaves, 0);
		this.setBlock(world, i + 6, j + 49, k + 33, Blocks.leaves, 0);
		this.setBlock(world, i + 6, j + 49, k + 34, Blocks.leaves, 0);
		this.setBlock(world, i + 6, j + 50, k + 18, Blocks.leaves, 0);
		this.setBlock(world, i + 6, j + 50, k + 19, Blocks.leaves, 0);
		this.setBlock(world, i + 6, j + 50, k + 20, Blocks.leaves, 0);
		this.setBlock(world, i + 6, j + 50, k + 21, Blocks.leaves, 0);
		this.setBlock(world, i + 6, j + 50, k + 22, Blocks.log, 1);
		this.setBlock(world, i + 6, j + 50, k + 23, Blocks.leaves, 0);
		this.setBlock(world, i + 6, j + 50, k + 24, Blocks.leaves, 0);
		this.setBlock(world, i + 6, j + 50, k + 25, Blocks.leaves, 0);
		this.setBlock(world, i + 6, j + 50, k + 26, Blocks.leaves, 0);
		this.setBlock(world, i + 6, j + 50, k + 27, Blocks.leaves, 0);
		this.setBlock(world, i + 6, j + 50, k + 28, Blocks.leaves, 0);
		this.setBlock(world, i + 6, j + 50, k + 29, Blocks.leaves, 0);
		this.setBlock(world, i + 6, j + 50, k + 30, Blocks.leaves, 0);
		this.setBlock(world, i + 6, j + 50, k + 31, Blocks.leaves, 0);
		this.setBlock(world, i + 6, j + 50, k + 32, Blocks.leaves, 0);
		this.setBlock(world, i + 6, j + 50, k + 33, Blocks.leaves, 0);
		this.setBlock(world, i + 6, j + 51, k + 19, Blocks.leaves, 0);
		this.setBlock(world, i + 6, j + 51, k + 21, Blocks.leaves, 0);
		this.setBlock(world, i + 6, j + 51, k + 22, Blocks.leaves, 0);
		this.setBlock(world, i + 6, j + 51, k + 23, Blocks.leaves, 0);
		this.setBlock(world, i + 6, j + 51, k + 24, Blocks.leaves, 0);
		this.setBlock(world, i + 6, j + 51, k + 25, Blocks.leaves, 0);
		this.setBlock(world, i + 6, j + 51, k + 26, Blocks.leaves, 0);
		this.setBlock(world, i + 6, j + 51, k + 27, Blocks.leaves, 0);
		this.setBlock(world, i + 6, j + 51, k + 28, Blocks.leaves, 0);
		this.setBlock(world, i + 6, j + 51, k + 29, Blocks.leaves, 0);
		this.setBlock(world, i + 6, j + 51, k + 30, Blocks.leaves, 0);
		this.setBlock(world, i + 6, j + 51, k + 31, Blocks.leaves, 0);
		this.setBlock(world, i + 6, j + 52, k + 23, Blocks.leaves, 0);
		this.setBlock(world, i + 6, j + 52, k + 28, Blocks.leaves, 0);
		this.setBlock(world, i + 7, j + 46, k + 22, Blocks.leaves, 0);
		this.setBlock(world, i + 7, j + 46, k + 23, Blocks.leaves, 0);
		this.setBlock(world, i + 7, j + 46, k + 24, Blocks.leaves, 0);
		this.setBlock(world, i + 7, j + 46, k + 25, Blocks.leaves, 0);
		this.setBlock(world, i + 7, j + 46, k + 26, Blocks.leaves, 0);
		this.setBlock(world, i + 7, j + 46, k + 27, Blocks.leaves, 0);
		this.setBlock(world, i + 7, j + 46, k + 28, Blocks.leaves, 0);
		this.setBlock(world, i + 7, j + 46, k + 29, Blocks.leaves, 0);
		this.setBlock(world, i + 7, j + 46, k + 30, Blocks.leaves, 0);
		this.setBlock(world, i + 7, j + 47, k + 21, Blocks.leaves, 0);
		this.setBlock(world, i + 7, j + 47, k + 22, Blocks.leaves, 0);
		this.setBlock(world, i + 7, j + 47, k + 23, Blocks.leaves, 0);
		this.setBlock(world, i + 7, j + 47, k + 24, Blocks.leaves, 0);
		this.setBlock(world, i + 7, j + 47, k + 25, Blocks.leaves, 0);
		this.setBlock(world, i + 7, j + 47, k + 26, Blocks.leaves, 0);
		this.setBlock(world, i + 7, j + 47, k + 27, Blocks.leaves, 0);
		this.setBlock(world, i + 7, j + 47, k + 28, Blocks.log, 1);
		this.setBlock(world, i + 7, j + 47, k + 29, Blocks.leaves, 0);
		this.setBlock(world, i + 7, j + 47, k + 30, Blocks.leaves, 0);
		this.setBlock(world, i + 7, j + 48, k + 20, Blocks.leaves, 0);
		this.setBlock(world, i + 7, j + 48, k + 21, Blocks.log, 1);
		this.setBlock(world, i + 7, j + 48, k + 22, Blocks.leaves, 0);
		this.setBlock(world, i + 7, j + 48, k + 23, Blocks.leaves, 0);
		this.setBlock(world, i + 7, j + 48, k + 24, Blocks.leaves, 0);
		this.setBlock(world, i + 7, j + 48, k + 25, Blocks.log, 1);
		this.setBlock(world, i + 7, j + 48, k + 26, Blocks.leaves, 0);
		this.setBlock(world, i + 7, j + 48, k + 27, Blocks.leaves, 0);
		this.setBlock(world, i + 7, j + 48, k + 28, Blocks.log, 1);
		this.setBlock(world, i + 7, j + 48, k + 29, Blocks.leaves, 0);
		this.setBlock(world, i + 7, j + 48, k + 30, Blocks.log, 1);
		this.setBlock(world, i + 7, j + 48, k + 31, Blocks.leaves, 0);
		this.setBlock(world, i + 7, j + 48, k + 32, Blocks.leaves, 0);
		this.setBlock(world, i + 7, j + 48, k + 33, Blocks.leaves, 0);
		this.setBlock(world, i + 7, j + 49, k + 19, Blocks.leaves, 0);
		this.setBlock(world, i + 7, j + 49, k + 20, Blocks.leaves, 0);
		this.setBlock(world, i + 7, j + 49, k + 21, Blocks.leaves, 0);
		this.setBlock(world, i + 7, j + 49, k + 22, Blocks.leaves, 0);
		this.setBlock(world, i + 7, j + 49, k + 23, Blocks.leaves, 0);
		this.setBlock(world, i + 7, j + 49, k + 24, Blocks.leaves, 0);
		this.setBlock(world, i + 7, j + 49, k + 25, Blocks.leaves, 0);
		this.setBlock(world, i + 7, j + 49, k + 26, Blocks.leaves, 0);
		this.setBlock(world, i + 7, j + 49, k + 27, Blocks.leaves, 0);
		this.setBlock(world, i + 7, j + 49, k + 28, Blocks.log, 1);
		this.setBlock(world, i + 7, j + 49, k + 29, Blocks.log, 1);
		this.setBlock(world, i + 7, j + 49, k + 30, Blocks.leaves, 0);
		this.setBlock(world, i + 7, j + 49, k + 31, Blocks.leaves, 0);
		this.setBlock(world, i + 7, j + 49, k + 32, Blocks.leaves, 0);
		this.setBlock(world, i + 7, j + 49, k + 33, Blocks.leaves, 0);
		this.setBlock(world, i + 7, j + 49, k + 34, Blocks.leaves, 8);
		this.setBlock(world, i + 7, j + 50, k + 18, Blocks.leaves, 0);
		this.setBlock(world, i + 7, j + 50, k + 19, Blocks.log, 1);
		this.setBlock(world, i + 7, j + 50, k + 20, Blocks.leaves, 0);
		this.setBlock(world, i + 7, j + 50, k + 21, Blocks.leaves, 0);
		this.setBlock(world, i + 7, j + 50, k + 22, Blocks.leaves, 0);
		this.setBlock(world, i + 7, j + 50, k + 23, Blocks.leaves, 0);
		this.setBlock(world, i + 7, j + 50, k + 24, Blocks.leaves, 0);
		this.setBlock(world, i + 7, j + 50, k + 25, Blocks.leaves, 0);
		this.setBlock(world, i + 7, j + 50, k + 26, Blocks.leaves, 0);
		this.setBlock(world, i + 7, j + 50, k + 27, Blocks.leaves, 0);
		this.setBlock(world, i + 7, j + 50, k + 28, Blocks.leaves, 0);
		this.setBlock(world, i + 7, j + 50, k + 29, Blocks.leaves, 0);
		this.setBlock(world, i + 7, j + 50, k + 30, Blocks.leaves, 0);
		this.setBlock(world, i + 7, j + 50, k + 31, Blocks.leaves, 0);
		this.setBlock(world, i + 7, j + 50, k + 32, Blocks.leaves, 0);
		this.setBlock(world, i + 7, j + 50, k + 33, Blocks.leaves, 0);
		this.setBlock(world, i + 7, j + 51, k + 19, Blocks.leaves, 0);
		this.setBlock(world, i + 7, j + 51, k + 21, Blocks.leaves, 0);
		this.setBlock(world, i + 7, j + 51, k + 22, Blocks.leaves, 0);
		this.setBlock(world, i + 7, j + 51, k + 23, Blocks.leaves, 0);
		this.setBlock(world, i + 7, j + 51, k + 24, Blocks.leaves, 0);
		this.setBlock(world, i + 7, j + 51, k + 25, Blocks.leaves, 0);
		this.setBlock(world, i + 7, j + 51, k + 26, Blocks.leaves, 0);
		this.setBlock(world, i + 7, j + 51, k + 27, Blocks.leaves, 0);
		this.setBlock(world, i + 7, j + 51, k + 28, Blocks.leaves, 0);
		this.setBlock(world, i + 7, j + 51, k + 29, Blocks.leaves, 0);
		this.setBlock(world, i + 7, j + 51, k + 30, Blocks.leaves, 0);
		this.setBlock(world, i + 8, j + 45, k + 24, Blocks.log, 1);
		this.setBlock(world, i + 8, j + 45, k + 25, Blocks.leaves, 0);
		this.setBlock(world, i + 8, j + 45, k + 26, Blocks.leaves, 0);
		this.setBlock(world, i + 8, j + 45, k + 27, Blocks.leaves, 0);
		this.setBlock(world, i + 8, j + 45, k + 28, Blocks.leaves, 0);
		this.setBlock(world, i + 8, j + 46, k + 21, Blocks.leaves, 0);
		this.setBlock(world, i + 8, j + 46, k + 22, Blocks.leaves, 0);
		this.setBlock(world, i + 8, j + 46, k + 23, Blocks.leaves, 0);
		this.setBlock(world, i + 8, j + 46, k + 24, Blocks.leaves, 0);
		this.setBlock(world, i + 8, j + 46, k + 25, Blocks.leaves, 0);
		this.setBlock(world, i + 8, j + 46, k + 26, Blocks.leaves, 0);
		this.setBlock(world, i + 8, j + 46, k + 27, Blocks.leaves, 0);
		this.setBlock(world, i + 8, j + 46, k + 28, Blocks.leaves, 0);
		this.setBlock(world, i + 8, j + 46, k + 29, Blocks.leaves, 0);
		this.setBlock(world, i + 8, j + 46, k + 30, Blocks.leaves, 0);
		this.setBlock(world, i + 8, j + 47, k + 20, Blocks.log, 1);
		this.setBlock(world, i + 8, j + 47, k + 21, Blocks.leaves, 0);
		this.setBlock(world, i + 8, j + 47, k + 22, Blocks.leaves, 0);
		this.setBlock(world, i + 8, j + 47, k + 23, Blocks.leaves, 0);
		this.setBlock(world, i + 8, j + 47, k + 24, Blocks.leaves, 0);
		this.setBlock(world, i + 8, j + 47, k + 25, Blocks.leaves, 0);
		this.setBlock(world, i + 8, j + 47, k + 26, Blocks.leaves, 0);
		this.setBlock(world, i + 8, j + 47, k + 27, Blocks.log, 1);
		this.setBlock(world, i + 8, j + 47, k + 28, Blocks.leaves, 0);
		this.setBlock(world, i + 8, j + 47, k + 29, Blocks.leaves, 0);
		this.setBlock(world, i + 8, j + 47, k + 30, Blocks.leaves, 0);
		this.setBlock(world, i + 8, j + 47, k + 31, Blocks.leaves, 0);
		this.setBlock(world, i + 8, j + 48, k + 19, Blocks.leaves, 0);
		this.setBlock(world, i + 8, j + 48, k + 20, Blocks.leaves, 0);
		this.setBlock(world, i + 8, j + 48, k + 21, Blocks.leaves, 0);
		this.setBlock(world, i + 8, j + 48, k + 22, Blocks.leaves, 0);
		this.setBlock(world, i + 8, j + 48, k + 23, Blocks.leaves, 0);
		this.setBlock(world, i + 8, j + 48, k + 24, Blocks.leaves, 0);
		this.setBlock(world, i + 8, j + 48, k + 25, Blocks.leaves, 0);
		this.setBlock(world, i + 8, j + 48, k + 26, Blocks.log, 1);
		this.setBlock(world, i + 8, j + 48, k + 27, Blocks.leaves, 0);
		this.setBlock(world, i + 8, j + 48, k + 28, Blocks.leaves, 0);
		this.setBlock(world, i + 8, j + 48, k + 29, Blocks.leaves, 0);
		this.setBlock(world, i + 8, j + 48, k + 30, Blocks.log, 1);
		this.setBlock(world, i + 8, j + 48, k + 31, Blocks.log, 1);
		this.setBlock(world, i + 8, j + 48, k + 32, Blocks.leaves, 0);
		this.setBlock(world, i + 8, j + 49, k + 18, Blocks.log, 1);
		this.setBlock(world, i + 8, j + 49, k + 19, Blocks.leaves, 0);
		this.setBlock(world, i + 8, j + 49, k + 20, Blocks.leaves, 0);
		this.setBlock(world, i + 8, j + 49, k + 21, Blocks.leaves, 0);
		this.setBlock(world, i + 8, j + 49, k + 22, Blocks.leaves, 0);
		this.setBlock(world, i + 8, j + 49, k + 23, Blocks.leaves, 0);
		this.setBlock(world, i + 8, j + 49, k + 24, Blocks.leaves, 0);
		this.setBlock(world, i + 8, j + 49, k + 25, Blocks.leaves, 0);
		this.setBlock(world, i + 8, j + 49, k + 26, Blocks.leaves, 0);
		this.setBlock(world, i + 8, j + 49, k + 27, Blocks.leaves, 0);
		this.setBlock(world, i + 8, j + 49, k + 28, Blocks.log, 1);
		this.setBlock(world, i + 8, j + 49, k + 29, Blocks.leaves, 0);
		this.setBlock(world, i + 8, j + 49, k + 30, Blocks.leaves, 0);
		this.setBlock(world, i + 8, j + 49, k + 31, Blocks.leaves, 0);
		this.setBlock(world, i + 8, j + 49, k + 32, Blocks.leaves, 0);
		this.setBlock(world, i + 8, j + 49, k + 33, Blocks.leaves, 0);
		this.setBlock(world, i + 8, j + 50, k + 17, Blocks.leaves, 0);
		this.setBlock(world, i + 8, j + 50, k + 18, Blocks.leaves, 0);
		this.setBlock(world, i + 8, j + 50, k + 19, Blocks.leaves, 0);
		this.setBlock(world, i + 8, j + 50, k + 20, Blocks.leaves, 0);
		this.setBlock(world, i + 8, j + 50, k + 21, Blocks.leaves, 0);
		this.setBlock(world, i + 8, j + 50, k + 22, Blocks.leaves, 0);
		this.setBlock(world, i + 8, j + 50, k + 23, Blocks.leaves, 0);
		this.setBlock(world, i + 8, j + 50, k + 24, Blocks.leaves, 0);
		this.setBlock(world, i + 8, j + 50, k + 25, Blocks.leaves, 0);
		this.setBlock(world, i + 8, j + 50, k + 26, Blocks.leaves, 0);
		this.setBlock(world, i + 8, j + 50, k + 27, Blocks.leaves, 0);
		this.setBlock(world, i + 8, j + 50, k + 28, Blocks.leaves, 0);
		this.setBlock(world, i + 8, j + 50, k + 29, Blocks.leaves, 0);
		this.setBlock(world, i + 8, j + 50, k + 30, Blocks.leaves, 0);
		this.setBlock(world, i + 8, j + 50, k + 31, Blocks.leaves, 0);
		this.setBlock(world, i + 8, j + 50, k + 32, Blocks.leaves, 0);
		this.setBlock(world, i + 8, j + 51, k + 18, Blocks.leaves, 0);
		this.setBlock(world, i + 8, j + 51, k + 19, Blocks.leaves, 0);
		this.setBlock(world, i + 8, j + 51, k + 20, Blocks.leaves, 0);
		this.setBlock(world, i + 8, j + 51, k + 21, Blocks.leaves, 0);
		this.setBlock(world, i + 8, j + 51, k + 22, Blocks.leaves, 0);
		this.setBlock(world, i + 8, j + 51, k + 23, Blocks.leaves, 0);
		this.setBlock(world, i + 8, j + 51, k + 24, Blocks.leaves, 0);
		this.setBlock(world, i + 8, j + 51, k + 25, Blocks.leaves, 0);
		this.setBlock(world, i + 8, j + 51, k + 27, Blocks.leaves, 0);
		this.setBlock(world, i + 8, j + 51, k + 28, Blocks.leaves, 0);
		this.setBlock(world, i + 8, j + 51, k + 29, Blocks.leaves, 0);
		this.setBlock(world, i + 8, j + 51, k + 31, Blocks.leaves, 0);
		this.setBlock(world, i + 9, j + 44, k + 25, Blocks.log, 1);
		this.setBlock(world, i + 9, j + 44, k + 26, Blocks.log, 1);
		this.setBlock(world, i + 9, j + 45, k + 23, Blocks.leaves, 0);
		this.setBlock(world, i + 9, j + 45, k + 24, Blocks.leaves, 0);
		this.setBlock(world, i + 9, j + 45, k + 25, Blocks.leaves, 0);
		this.setBlock(world, i + 9, j + 45, k + 26, Blocks.leaves, 0);
		this.setBlock(world, i + 9, j + 45, k + 27, Blocks.leaves, 0);
		this.setBlock(world, i + 9, j + 45, k + 28, Blocks.leaves, 0);
		this.setBlock(world, i + 9, j + 46, k + 21, Blocks.leaves, 0);
		this.setBlock(world, i + 9, j + 46, k + 22, Blocks.leaves, 0);
		this.setBlock(world, i + 9, j + 46, k + 23, Blocks.leaves, 0);
		this.setBlock(world, i + 9, j + 46, k + 24, Blocks.leaves, 0);
		this.setBlock(world, i + 9, j + 46, k + 25, Blocks.leaves, 0);
		this.setBlock(world, i + 9, j + 46, k + 26, Blocks.leaves, 0);
		this.setBlock(world, i + 9, j + 46, k + 27, Blocks.log, 1);
		this.setBlock(world, i + 9, j + 46, k + 28, Blocks.leaves, 0);
		this.setBlock(world, i + 9, j + 46, k + 29, Blocks.leaves, 0);
		this.setBlock(world, i + 9, j + 46, k + 30, Blocks.leaves, 0);
		this.setBlock(world, i + 9, j + 47, k + 19, Blocks.leaves, 0);
		this.setBlock(world, i + 9, j + 47, k + 20, Blocks.log, 1);
		this.setBlock(world, i + 9, j + 47, k + 21, Blocks.leaves, 0);
		this.setBlock(world, i + 9, j + 47, k + 22, Blocks.leaves, 0);
		this.setBlock(world, i + 9, j + 47, k + 23, Blocks.leaves, 0);
		this.setBlock(world, i + 9, j + 47, k + 24, Blocks.leaves, 0);
		this.setBlock(world, i + 9, j + 47, k + 25, Blocks.leaves, 0);
		this.setBlock(world, i + 9, j + 47, k + 26, Blocks.leaves, 0);
		this.setBlock(world, i + 9, j + 47, k + 27, Blocks.leaves, 0);
		this.setBlock(world, i + 9, j + 47, k + 28, Blocks.leaves, 0);
		this.setBlock(world, i + 9, j + 47, k + 29, Blocks.leaves, 0);
		this.setBlock(world, i + 9, j + 47, k + 30, Blocks.leaves, 0);
		this.setBlock(world, i + 9, j + 47, k + 31, Blocks.leaves, 0);
		this.setBlock(world, i + 9, j + 47, k + 32, Blocks.log, 1);
		this.setBlock(world, i + 9, j + 48, k + 19, Blocks.leaves, 0);
		this.setBlock(world, i + 9, j + 48, k + 20, Blocks.leaves, 0);
		this.setBlock(world, i + 9, j + 48, k + 21, Blocks.leaves, 0);
		this.setBlock(world, i + 9, j + 48, k + 22, Blocks.leaves, 0);
		this.setBlock(world, i + 9, j + 48, k + 23, Blocks.leaves, 0);
		this.setBlock(world, i + 9, j + 48, k + 24, Blocks.leaves, 0);
		this.setBlock(world, i + 9, j + 48, k + 25, Blocks.log, 1);
		this.setBlock(world, i + 9, j + 48, k + 26, Blocks.leaves, 0);
		this.setBlock(world, i + 9, j + 48, k + 27, Blocks.leaves, 0);
		this.setBlock(world, i + 9, j + 48, k + 28, Blocks.leaves, 0);
		this.setBlock(world, i + 9, j + 48, k + 29, Blocks.leaves, 0);
		this.setBlock(world, i + 9, j + 48, k + 30, Blocks.leaves, 0);
		this.setBlock(world, i + 9, j + 48, k + 31, Blocks.leaves, 0);
		this.setBlock(world, i + 9, j + 48, k + 32, Blocks.leaves, 0);
		this.setBlock(world, i + 9, j + 48, k + 33, Blocks.leaves, 0);
		this.setBlock(world, i + 9, j + 48, k + 34, Blocks.leaves, 0);
		this.setBlock(world, i + 9, j + 49, k + 17, Blocks.leaves, 0);
		this.setBlock(world, i + 9, j + 49, k + 18, Blocks.log, 1);
		this.setBlock(world, i + 9, j + 49, k + 19, Blocks.leaves, 0);
		this.setBlock(world, i + 9, j + 49, k + 20, Blocks.leaves, 0);
		this.setBlock(world, i + 9, j + 49, k + 21, Blocks.leaves, 0);
		this.setBlock(world, i + 9, j + 49, k + 22, Blocks.leaves, 0);
		this.setBlock(world, i + 9, j + 49, k + 23, Blocks.leaves, 0);
		this.setBlock(world, i + 9, j + 49, k + 24, Blocks.leaves, 0);
		this.setBlock(world, i + 9, j + 49, k + 25, Blocks.leaves, 0);
		this.setBlock(world, i + 9, j + 49, k + 26, Blocks.leaves, 0);
		this.setBlock(world, i + 9, j + 49, k + 27, Blocks.leaves, 0);
		this.setBlock(world, i + 9, j + 49, k + 28, Blocks.leaves, 0);
		this.setBlock(world, i + 9, j + 49, k + 29, Blocks.leaves, 0);
		this.setBlock(world, i + 9, j + 49, k + 30, Blocks.leaves, 0);
		this.setBlock(world, i + 9, j + 49, k + 31, Blocks.leaves, 0);
		this.setBlock(world, i + 9, j + 49, k + 32, Blocks.leaves, 0);
		this.setBlock(world, i + 9, j + 49, k + 33, Blocks.leaves, 0);
		this.setBlock(world, i + 9, j + 49, k + 34, Blocks.leaves, 0);
		this.setBlock(world, i + 9, j + 50, k + 16, Blocks.leaves, 0);
		this.setBlock(world, i + 9, j + 50, k + 17, Blocks.leaves, 0);
		this.setBlock(world, i + 9, j + 50, k + 18, Blocks.leaves, 0);
		this.setBlock(world, i + 9, j + 50, k + 19, Blocks.leaves, 0);
		this.setBlock(world, i + 9, j + 50, k + 20, Blocks.leaves, 0);
		this.setBlock(world, i + 9, j + 50, k + 21, Blocks.log, 1);
		this.setBlock(world, i + 9, j + 50, k + 22, Blocks.leaves, 0);
		this.setBlock(world, i + 9, j + 50, k + 23, Blocks.leaves, 0);
		this.setBlock(world, i + 9, j + 50, k + 24, Blocks.leaves, 0);
		this.setBlock(world, i + 9, j + 50, k + 25, Blocks.leaves, 0);
		this.setBlock(world, i + 9, j + 50, k + 26, Blocks.leaves, 0);
		this.setBlock(world, i + 9, j + 50, k + 27, Blocks.leaves, 0);
		this.setBlock(world, i + 9, j + 50, k + 28, Blocks.leaves, 0);
		this.setBlock(world, i + 9, j + 50, k + 29, Blocks.leaves, 0);
		this.setBlock(world, i + 9, j + 50, k + 30, Blocks.leaves, 0);
		this.setBlock(world, i + 9, j + 50, k + 31, Blocks.log, 1);
		this.setBlock(world, i + 9, j + 50, k + 32, Blocks.leaves, 0);
		this.setBlock(world, i + 9, j + 50, k + 33, Blocks.leaves, 0);
		this.setBlock(world, i + 9, j + 50, k + 34, Blocks.leaves, 0);
		this.setBlock(world, i + 9, j + 51, k + 17, Blocks.leaves, 0);
		this.setBlock(world, i + 9, j + 51, k + 18, Blocks.leaves, 0);
		this.setBlock(world, i + 9, j + 51, k + 19, Blocks.leaves, 0);
		this.setBlock(world, i + 9, j + 51, k + 20, Blocks.leaves, 0);
		this.setBlock(world, i + 9, j + 51, k + 21, Blocks.leaves, 0);
		this.setBlock(world, i + 9, j + 51, k + 22, Blocks.leaves, 0);
		this.setBlock(world, i + 9, j + 51, k + 23, Blocks.leaves, 0);
		this.setBlock(world, i + 9, j + 51, k + 27, Blocks.leaves, 0);
		this.setBlock(world, i + 9, j + 51, k + 28, Blocks.leaves, 0);
		this.setBlock(world, i + 9, j + 51, k + 29, Blocks.leaves, 0);
		this.setBlock(world, i + 9, j + 51, k + 30, Blocks.leaves, 0);
		this.setBlock(world, i + 9, j + 51, k + 31, Blocks.leaves, 0);
		this.setBlock(world, i + 9, j + 51, k + 32, Blocks.leaves, 0);
		this.setBlock(world, i + 9, j + 52, k + 19, Blocks.leaves, 0);
		this.setBlock(world, i + 10, j + 43, k + 25, Blocks.log, 1);
		this.setBlock(world, i + 10, j + 43, k + 26, Blocks.log, 1);
		this.setBlock(world, i + 10, j + 43, k + 27, Blocks.log, 1);
		this.setBlock(world, i + 10, j + 44, k + 25, Blocks.log, 1);
		this.setBlock(world, i + 10, j + 44, k + 26, Blocks.leaves, 0);
		this.setBlock(world, i + 10, j + 44, k + 27, Blocks.log, 1);
		this.setBlock(world, i + 10, j + 44, k + 28, Blocks.log, 1);
		this.setBlock(world, i + 10, j + 45, k + 24, Blocks.leaves, 0);
		this.setBlock(world, i + 10, j + 45, k + 25, Blocks.leaves, 0);
		this.setBlock(world, i + 10, j + 45, k + 26, Blocks.leaves, 0);
		this.setBlock(world, i + 10, j + 45, k + 27, Blocks.leaves, 0);
		this.setBlock(world, i + 10, j + 45, k + 28, Blocks.leaves, 0);
		this.setBlock(world, i + 10, j + 46, k + 11, Blocks.leaves, 0);
		this.setBlock(world, i + 10, j + 46, k + 21, Blocks.leaves, 0);
		this.setBlock(world, i + 10, j + 46, k + 22, Blocks.leaves, 0);
		this.setBlock(world, i + 10, j + 46, k + 23, Blocks.leaves, 0);
		this.setBlock(world, i + 10, j + 46, k + 24, Blocks.leaves, 0);
		this.setBlock(world, i + 10, j + 46, k + 25, Blocks.leaves, 0);
		this.setBlock(world, i + 10, j + 46, k + 26, Blocks.leaves, 0);
		this.setBlock(world, i + 10, j + 46, k + 27, Blocks.leaves, 0);
		this.setBlock(world, i + 10, j + 46, k + 28, Blocks.leaves, 0);
		this.setBlock(world, i + 10, j + 46, k + 29, Blocks.log, 1);
		this.setBlock(world, i + 10, j + 47, k + 8, Blocks.leaves, 0);
		this.setBlock(world, i + 10, j + 47, k + 19, Blocks.log, 1);
		this.setBlock(world, i + 10, j + 47, k + 20, Blocks.log, 1);
		this.setBlock(world, i + 10, j + 47, k + 21, Blocks.leaves, 0);
		this.setBlock(world, i + 10, j + 47, k + 22, Blocks.leaves, 0);
		this.setBlock(world, i + 10, j + 47, k + 23, Blocks.leaves, 0);
		this.setBlock(world, i + 10, j + 47, k + 24, Blocks.leaves, 0);
		this.setBlock(world, i + 10, j + 47, k + 25, Blocks.leaves, 0);
		this.setBlock(world, i + 10, j + 47, k + 26, Blocks.leaves, 0);
		this.setBlock(world, i + 10, j + 47, k + 27, Blocks.leaves, 0);
		this.setBlock(world, i + 10, j + 47, k + 28, Blocks.leaves, 0);
		this.setBlock(world, i + 10, j + 47, k + 29, Blocks.leaves, 0);
		this.setBlock(world, i + 10, j + 47, k + 30, Blocks.leaves, 0);
		this.setBlock(world, i + 10, j + 47, k + 31, Blocks.leaves, 0);
		this.setBlock(world, i + 10, j + 47, k + 32, Blocks.leaves, 0);
		this.setBlock(world, i + 10, j + 47, k + 33, Blocks.leaves, 0);
		this.setBlock(world, i + 10, j + 48, k + 19, Blocks.log, 1);
		this.setBlock(world, i + 10, j + 48, k + 20, Blocks.leaves, 0);
		this.setBlock(world, i + 10, j + 48, k + 21, Blocks.leaves, 0);
		this.setBlock(world, i + 10, j + 48, k + 22, Blocks.leaves, 0);
		this.setBlock(world, i + 10, j + 48, k + 23, Blocks.leaves, 0);
		this.setBlock(world, i + 10, j + 48, k + 24, Blocks.leaves, 0);
		this.setBlock(world, i + 10, j + 48, k + 25, Blocks.leaves, 0);
		this.setBlock(world, i + 10, j + 48, k + 26, Blocks.leaves, 0);
		this.setBlock(world, i + 10, j + 48, k + 27, Blocks.log, 1);
		this.setBlock(world, i + 10, j + 48, k + 28, Blocks.leaves, 0);
		this.setBlock(world, i + 10, j + 48, k + 29, Blocks.leaves, 0);
		this.setBlock(world, i + 10, j + 48, k + 30, Blocks.leaves, 0);
		this.setBlock(world, i + 10, j + 48, k + 31, Blocks.leaves, 0);
		this.setBlock(world, i + 10, j + 48, k + 32, Blocks.leaves, 0);
		this.setBlock(world, i + 10, j + 48, k + 33, Blocks.leaves, 0);
		this.setBlock(world, i + 10, j + 48, k + 34, Blocks.leaves, 0);
		this.setBlock(world, i + 10, j + 49, k + 18, Blocks.leaves, 0);
		this.setBlock(world, i + 10, j + 49, k + 19, Blocks.leaves, 0);
		this.setBlock(world, i + 10, j + 49, k + 20, Blocks.leaves, 0);
		this.setBlock(world, i + 10, j + 49, k + 21, Blocks.leaves, 0);
		this.setBlock(world, i + 10, j + 49, k + 22, Blocks.leaves, 0);
		this.setBlock(world, i + 10, j + 49, k + 23, Blocks.leaves, 0);
		this.setBlock(world, i + 10, j + 49, k + 24, Blocks.leaves, 0);
		this.setBlock(world, i + 10, j + 49, k + 25, Blocks.leaves, 0);
		this.setBlock(world, i + 10, j + 49, k + 26, Blocks.log, 1);
		this.setBlock(world, i + 10, j + 49, k + 27, Blocks.leaves, 0);
		this.setBlock(world, i + 10, j + 49, k + 28, Blocks.leaves, 0);
		this.setBlock(world, i + 10, j + 49, k + 29, Blocks.leaves, 0);
		this.setBlock(world, i + 10, j + 49, k + 30, Blocks.leaves, 0);
		this.setBlock(world, i + 10, j + 49, k + 31, Blocks.leaves, 0);
		this.setBlock(world, i + 10, j + 49, k + 32, Blocks.leaves, 0);
		this.setBlock(world, i + 10, j + 49, k + 33, Blocks.leaves, 0);
		this.setBlock(world, i + 10, j + 49, k + 34, Blocks.leaves, 0);
		this.setBlock(world, i + 10, j + 49, k + 35, Blocks.leaves, 0);
		this.setBlock(world, i + 10, j + 50, k + 17, Blocks.leaves, 0);
		this.setBlock(world, i + 10, j + 50, k + 18, Blocks.leaves, 0);
		this.setBlock(world, i + 10, j + 50, k + 19, Blocks.leaves, 0);
		this.setBlock(world, i + 10, j + 50, k + 20, Blocks.log, 1);
		this.setBlock(world, i + 10, j + 50, k + 21, Blocks.leaves, 0);
		this.setBlock(world, i + 10, j + 50, k + 22, Blocks.leaves, 0);
		this.setBlock(world, i + 10, j + 50, k + 23, Blocks.leaves, 0);
		this.setBlock(world, i + 10, j + 50, k + 24, Blocks.leaves, 0);
		this.setBlock(world, i + 10, j + 50, k + 25, Blocks.leaves, 0);
		this.setBlock(world, i + 10, j + 50, k + 26, Blocks.leaves, 0);
		this.setBlock(world, i + 10, j + 50, k + 27, Blocks.leaves, 0);
		this.setBlock(world, i + 10, j + 50, k + 28, Blocks.leaves, 0);
		this.setBlock(world, i + 10, j + 50, k + 29, Blocks.log, 1);
		this.setBlock(world, i + 10, j + 50, k + 30, Blocks.leaves, 0);
		this.setBlock(world, i + 10, j + 50, k + 31, Blocks.leaves, 0);
		this.setBlock(world, i + 10, j + 50, k + 32, Blocks.leaves, 0);
		this.setBlock(world, i + 10, j + 50, k + 33, Blocks.leaves, 0);
		this.setBlock(world, i + 10, j + 50, k + 34, Blocks.leaves, 0);
		this.setBlock(world, i + 10, j + 51, k + 18, Blocks.leaves, 0);
		this.setBlock(world, i + 10, j + 51, k + 19, Blocks.leaves, 0);
		this.setBlock(world, i + 10, j + 51, k + 20, Blocks.leaves, 0);
		this.setBlock(world, i + 10, j + 51, k + 21, Blocks.leaves, 0);
		this.setBlock(world, i + 10, j + 51, k + 22, Blocks.leaves, 0);
		this.setBlock(world, i + 10, j + 51, k + 23, Blocks.leaves, 0);
		this.setBlock(world, i + 10, j + 51, k + 26, Blocks.leaves, 0);
		this.setBlock(world, i + 10, j + 51, k + 27, Blocks.leaves, 0);
		this.setBlock(world, i + 10, j + 51, k + 28, Blocks.leaves, 0);
		this.setBlock(world, i + 10, j + 51, k + 29, Blocks.leaves, 0);
		this.setBlock(world, i + 10, j + 51, k + 30, Blocks.leaves, 0);
		this.setBlock(world, i + 10, j + 51, k + 31, Blocks.leaves, 0);
		this.setBlock(world, i + 10, j + 51, k + 32, Blocks.leaves, 0);
		this.setBlock(world, i + 10, j + 51, k + 33, Blocks.leaves, 0);
		this.setBlock(world, i + 10, j + 52, k + 21, Blocks.leaves, 0);
		this.setBlock(world, i + 11, j + 42, k + 24, Blocks.log, 1);
		this.setBlock(world, i + 11, j + 42, k + 25, Blocks.log, 1);
		this.setBlock(world, i + 11, j + 42, k + 26, Blocks.log, 1);
		this.setBlock(world, i + 11, j + 43, k + 24, Blocks.log, 1);
		this.setBlock(world, i + 11, j + 43, k + 25, Blocks.log, 1);
		this.setBlock(world, i + 11, j + 43, k + 26, Blocks.log, 1);
		this.setBlock(world, i + 11, j + 43, k + 27, Blocks.log, 1);
		this.setBlock(world, i + 11, j + 44, k + 24, Blocks.log, 1);
		this.setBlock(world, i + 11, j + 44, k + 25, Blocks.log, 1);
		this.setBlock(world, i + 11, j + 44, k + 26, Blocks.log, 1);
		this.setBlock(world, i + 11, j + 44, k + 27, Blocks.log, 1);
		this.setBlock(world, i + 11, j + 44, k + 28, Blocks.log, 1);
		this.setBlock(world, i + 11, j + 45, k + 10, Blocks.leaves, 0);
		this.setBlock(world, i + 11, j + 45, k + 11, Blocks.leaves, 0);
		this.setBlock(world, i + 11, j + 45, k + 12, Blocks.leaves, 0);
		this.setBlock(world, i + 11, j + 45, k + 24, Blocks.leaves, 0);
		this.setBlock(world, i + 11, j + 45, k + 25, Blocks.leaves, 0);
		this.setBlock(world, i + 11, j + 45, k + 26, Blocks.leaves, 0);
		this.setBlock(world, i + 11, j + 45, k + 27, Blocks.log, 1);
		this.setBlock(world, i + 11, j + 45, k + 28, Blocks.leaves, 0);
		this.setBlock(world, i + 11, j + 45, k + 29, Blocks.log, 1);
		this.setBlock(world, i + 11, j + 46, k + 7, Blocks.leaves, 0);
		this.setBlock(world, i + 11, j + 46, k + 8, Blocks.leaves, 0);
		this.setBlock(world, i + 11, j + 46, k + 9, Blocks.leaves, 0);
		this.setBlock(world, i + 11, j + 46, k + 10, Blocks.leaves, 0);
		this.setBlock(world, i + 11, j + 46, k + 11, Blocks.leaves, 0);
		this.setBlock(world, i + 11, j + 46, k + 12, Blocks.log, 1);
		this.setBlock(world, i + 11, j + 46, k + 22, Blocks.leaves, 0);
		this.setBlock(world, i + 11, j + 46, k + 23, Blocks.leaves, 0);
		this.setBlock(world, i + 11, j + 46, k + 24, Blocks.leaves, 0);
		this.setBlock(world, i + 11, j + 46, k + 25, Blocks.leaves, 0);
		this.setBlock(world, i + 11, j + 46, k + 26, Blocks.leaves, 0);
		this.setBlock(world, i + 11, j + 46, k + 27, Blocks.leaves, 0);
		this.setBlock(world, i + 11, j + 46, k + 28, Blocks.leaves, 0);
		this.setBlock(world, i + 11, j + 46, k + 29, Blocks.log, 1);
		this.setBlock(world, i + 11, j + 46, k + 30, Blocks.log, 1);
		this.setBlock(world, i + 11, j + 46, k + 31, Blocks.leaves, 0);
		this.setBlock(world, i + 11, j + 47, k + 7, Blocks.leaves, 0);
		this.setBlock(world, i + 11, j + 47, k + 8, Blocks.log, 1);
		this.setBlock(world, i + 11, j + 47, k + 9, Blocks.leaves, 0);
		this.setBlock(world, i + 11, j + 47, k + 10, Blocks.leaves, 0);
		this.setBlock(world, i + 11, j + 47, k + 11, Blocks.leaves, 0);
		this.setBlock(world, i + 11, j + 47, k + 12, Blocks.leaves, 0);
		this.setBlock(world, i + 11, j + 47, k + 19, Blocks.leaves, 0);
		this.setBlock(world, i + 11, j + 47, k + 20, Blocks.leaves, 0);
		this.setBlock(world, i + 11, j + 47, k + 21, Blocks.leaves, 0);
		this.setBlock(world, i + 11, j + 47, k + 22, Blocks.leaves, 0);
		this.setBlock(world, i + 11, j + 47, k + 23, Blocks.log, 1);
		this.setBlock(world, i + 11, j + 47, k + 24, Blocks.leaves, 0);
		this.setBlock(world, i + 11, j + 47, k + 25, Blocks.leaves, 0);
		this.setBlock(world, i + 11, j + 47, k + 26, Blocks.log, 1);
		this.setBlock(world, i + 11, j + 47, k + 27, Blocks.leaves, 0);
		this.setBlock(world, i + 11, j + 47, k + 28, Blocks.leaves, 0);
		this.setBlock(world, i + 11, j + 47, k + 29, Blocks.leaves, 0);
		this.setBlock(world, i + 11, j + 47, k + 30, Blocks.leaves, 0);
		this.setBlock(world, i + 11, j + 47, k + 31, Blocks.leaves, 0);
		this.setBlock(world, i + 11, j + 47, k + 32, Blocks.leaves, 0);
		this.setBlock(world, i + 11, j + 47, k + 33, Blocks.leaves, 0);
		this.setBlock(world, i + 11, j + 48, k + 7, Blocks.leaves, 0);
		this.setBlock(world, i + 11, j + 48, k + 8, Blocks.leaves, 0);
		this.setBlock(world, i + 11, j + 48, k + 9, Blocks.leaves, 0);
		this.setBlock(world, i + 11, j + 48, k + 19, Blocks.leaves, 0);
		this.setBlock(world, i + 11, j + 48, k + 20, Blocks.leaves, 0);
		this.setBlock(world, i + 11, j + 48, k + 21, Blocks.leaves, 0);
		this.setBlock(world, i + 11, j + 48, k + 22, Blocks.leaves, 0);
		this.setBlock(world, i + 11, j + 48, k + 23, Blocks.log, 1);
		this.setBlock(world, i + 11, j + 48, k + 24, Blocks.log, 1);
		this.setBlock(world, i + 11, j + 48, k + 25, Blocks.leaves, 0);
		this.setBlock(world, i + 11, j + 48, k + 26, Blocks.leaves, 0);
		this.setBlock(world, i + 11, j + 48, k + 27, Blocks.leaves, 0);
		this.setBlock(world, i + 11, j + 48, k + 28, Blocks.log, 1);
		this.setBlock(world, i + 11, j + 48, k + 29, Blocks.leaves, 0);
		this.setBlock(world, i + 11, j + 48, k + 30, Blocks.leaves, 0);
		this.setBlock(world, i + 11, j + 48, k + 31, Blocks.log, 1);
		this.setBlock(world, i + 11, j + 48, k + 32, Blocks.leaves, 0);
		this.setBlock(world, i + 11, j + 48, k + 33, Blocks.log, 1);
		this.setBlock(world, i + 11, j + 48, k + 34, Blocks.leaves, 0);
		this.setBlock(world, i + 11, j + 49, k + 17, Blocks.leaves, 0);
		this.setBlock(world, i + 11, j + 49, k + 18, Blocks.leaves, 0);
		this.setBlock(world, i + 11, j + 49, k + 19, Blocks.leaves, 0);
		this.setBlock(world, i + 11, j + 49, k + 20, Blocks.log, 1);
		this.setBlock(world, i + 11, j + 49, k + 21, Blocks.leaves, 0);
		this.setBlock(world, i + 11, j + 49, k + 22, Blocks.leaves, 0);
		this.setBlock(world, i + 11, j + 49, k + 23, Blocks.leaves, 0);
		this.setBlock(world, i + 11, j + 49, k + 24, Blocks.leaves, 0);
		this.setBlock(world, i + 11, j + 49, k + 25, Blocks.leaves, 0);
		this.setBlock(world, i + 11, j + 49, k + 26, Blocks.leaves, 0);
		this.setBlock(world, i + 11, j + 49, k + 27, Blocks.leaves, 0);
		this.setBlock(world, i + 11, j + 49, k + 28, Blocks.log, 1);
		this.setBlock(world, i + 11, j + 49, k + 29, Blocks.leaves, 0);
		this.setBlock(world, i + 11, j + 49, k + 30, Blocks.leaves, 0);
		this.setBlock(world, i + 11, j + 49, k + 31, Blocks.leaves, 0);
		this.setBlock(world, i + 11, j + 49, k + 32, Blocks.leaves, 0);
		this.setBlock(world, i + 11, j + 49, k + 33, Blocks.leaves, 0);
		this.setBlock(world, i + 11, j + 49, k + 34, Blocks.leaves, 0);
		this.setBlock(world, i + 11, j + 50, k + 16, Blocks.leaves, 0);
		this.setBlock(world, i + 11, j + 50, k + 17, Blocks.log, 1);
		this.setBlock(world, i + 11, j + 50, k + 18, Blocks.leaves, 0);
		this.setBlock(world, i + 11, j + 50, k + 19, Blocks.leaves, 0);
		this.setBlock(world, i + 11, j + 50, k + 20, Blocks.leaves, 0);
		this.setBlock(world, i + 11, j + 50, k + 21, Blocks.leaves, 0);
		this.setBlock(world, i + 11, j + 50, k + 22, Blocks.leaves, 0);
		this.setBlock(world, i + 11, j + 50, k + 23, Blocks.leaves, 0);
		this.setBlock(world, i + 11, j + 50, k + 24, Blocks.leaves, 0);
		this.setBlock(world, i + 11, j + 50, k + 25, Blocks.leaves, 0);
		this.setBlock(world, i + 11, j + 50, k + 26, Blocks.leaves, 0);
		this.setBlock(world, i + 11, j + 50, k + 27, Blocks.leaves, 0);
		this.setBlock(world, i + 11, j + 50, k + 28, Blocks.leaves, 0);
		this.setBlock(world, i + 11, j + 50, k + 29, Blocks.leaves, 0);
		this.setBlock(world, i + 11, j + 50, k + 30, Blocks.leaves, 0);
		this.setBlock(world, i + 11, j + 50, k + 31, Blocks.leaves, 0);
		this.setBlock(world, i + 11, j + 50, k + 32, Blocks.leaves, 0);
		this.setBlock(world, i + 11, j + 50, k + 33, Blocks.leaves, 0);
		this.setBlock(world, i + 11, j + 50, k + 34, Blocks.leaves, 0);
		this.setBlock(world, i + 11, j + 51, k + 17, Blocks.leaves, 0);
		this.setBlock(world, i + 11, j + 51, k + 18, Blocks.leaves, 0);
		this.setBlock(world, i + 11, j + 51, k + 19, Blocks.leaves, 0);
		this.setBlock(world, i + 11, j + 51, k + 20, Blocks.leaves, 0);
		this.setBlock(world, i + 11, j + 51, k + 21, Blocks.leaves, 0);
		this.setBlock(world, i + 11, j + 51, k + 22, Blocks.leaves, 0);
		this.setBlock(world, i + 11, j + 51, k + 23, Blocks.leaves, 0);
		this.setBlock(world, i + 11, j + 51, k + 26, Blocks.leaves, 0);
		this.setBlock(world, i + 11, j + 51, k + 27, Blocks.leaves, 0);
		this.setBlock(world, i + 11, j + 51, k + 28, Blocks.leaves, 0);
		this.setBlock(world, i + 11, j + 51, k + 29, Blocks.leaves, 0);
		this.setBlock(world, i + 11, j + 51, k + 30, Blocks.leaves, 0);
		this.setBlock(world, i + 11, j + 51, k + 31, Blocks.leaves, 0);
		this.setBlock(world, i + 11, j + 51, k + 32, Blocks.leaves, 0);
		this.setBlock(world, i + 11, j + 51, k + 33, Blocks.leaves, 0);
		this.setBlock(world, i + 11, j + 52, k + 19, Blocks.leaves, 0);
		this.setBlock(world, i + 11, j + 52, k + 28, Blocks.leaves, 0);
		this.setBlock(world, i + 11, j + 52, k + 31, Blocks.leaves, 0);
		this.setBlock(world, i + 12, j + 41, k + 23, Blocks.log, 1);
		this.setBlock(world, i + 12, j + 41, k + 24, Blocks.log, 1);
		this.setBlock(world, i + 12, j + 41, k + 25, Blocks.log, 1);
		this.setBlock(world, i + 12, j + 42, k + 23, Blocks.log, 1);
		this.setBlock(world, i + 12, j + 42, k + 24, Blocks.log, 1);
		this.setBlock(world, i + 12, j + 42, k + 25, Blocks.log, 1);
		this.setBlock(world, i + 12, j + 42, k + 26, Blocks.log, 1);
		this.setBlock(world, i + 12, j + 43, k + 23, Blocks.log, 1);
		this.setBlock(world, i + 12, j + 43, k + 24, Blocks.log, 1);
		this.setBlock(world, i + 12, j + 43, k + 25, Blocks.log, 1);
		this.setBlock(world, i + 12, j + 43, k + 26, Blocks.log, 1);
		this.setBlock(world, i + 12, j + 43, k + 27, Blocks.log, 1);
		this.setBlock(world, i + 12, j + 44, k + 8, Blocks.leaves, 0);
		this.setBlock(world, i + 12, j + 44, k + 9, Blocks.leaves, 0);
		this.setBlock(world, i + 12, j + 44, k + 10, Blocks.leaves, 0);
		this.setBlock(world, i + 12, j + 44, k + 11, Blocks.leaves, 0);
		this.setBlock(world, i + 12, j + 44, k + 24, Blocks.log, 1);
		this.setBlock(world, i + 12, j + 44, k + 25, Blocks.log, 1);
		this.setBlock(world, i + 12, j + 44, k + 26, Blocks.log, 1);
		this.setBlock(world, i + 12, j + 44, k + 27, Blocks.log, 1);
		this.setBlock(world, i + 12, j + 44, k + 28, Blocks.log, 1);
		this.setBlock(world, i + 12, j + 45, k + 7, Blocks.leaves, 0);
		this.setBlock(world, i + 12, j + 45, k + 8, Blocks.leaves, 0);
		this.setBlock(world, i + 12, j + 45, k + 9, Blocks.leaves, 0);
		this.setBlock(world, i + 12, j + 45, k + 10, Blocks.leaves, 0);
		this.setBlock(world, i + 12, j + 45, k + 11, Blocks.leaves, 0);
		this.setBlock(world, i + 12, j + 45, k + 12, Blocks.log, 1);
		this.setBlock(world, i + 12, j + 45, k + 24, Blocks.leaves, 0);
		this.setBlock(world, i + 12, j + 45, k + 25, Blocks.leaves, 0);
		this.setBlock(world, i + 12, j + 45, k + 26, Blocks.log, 1);
		this.setBlock(world, i + 12, j + 45, k + 27, Blocks.leaves, 0);
		this.setBlock(world, i + 12, j + 45, k + 28, Blocks.log, 1);
		this.setBlock(world, i + 12, j + 46, k + 6, Blocks.leaves, 0);
		this.setBlock(world, i + 12, j + 46, k + 7, Blocks.leaves, 0);
		this.setBlock(world, i + 12, j + 46, k + 8, Blocks.leaves, 0);
		this.setBlock(world, i + 12, j + 46, k + 9, Blocks.leaves, 0);
		this.setBlock(world, i + 12, j + 46, k + 10, Blocks.leaves, 0);
		this.setBlock(world, i + 12, j + 46, k + 11, Blocks.log, 1);
		this.setBlock(world, i + 12, j + 46, k + 12, Blocks.leaves, 0);
		this.setBlock(world, i + 12, j + 46, k + 13, Blocks.leaves, 0);
		this.setBlock(world, i + 12, j + 46, k + 22, Blocks.leaves, 0);
		this.setBlock(world, i + 12, j + 46, k + 23, Blocks.leaves, 0);
		this.setBlock(world, i + 12, j + 46, k + 24, Blocks.leaves, 0);
		this.setBlock(world, i + 12, j + 46, k + 25, Blocks.leaves, 0);
		this.setBlock(world, i + 12, j + 46, k + 26, Blocks.leaves, 0);
		this.setBlock(world, i + 12, j + 46, k + 27, Blocks.log, 1);
		this.setBlock(world, i + 12, j + 46, k + 28, Blocks.leaves, 0);
		this.setBlock(world, i + 12, j + 46, k + 29, Blocks.log, 1);
		this.setBlock(world, i + 12, j + 47, k + 6, Blocks.leaves, 0);
		this.setBlock(world, i + 12, j + 47, k + 7, Blocks.leaves, 0);
		this.setBlock(world, i + 12, j + 47, k + 8, Blocks.leaves, 0);
		this.setBlock(world, i + 12, j + 47, k + 9, Blocks.leaves, 0);
		this.setBlock(world, i + 12, j + 47, k + 10, Blocks.leaves, 0);
		this.setBlock(world, i + 12, j + 47, k + 11, Blocks.log, 1);
		this.setBlock(world, i + 12, j + 47, k + 12, Blocks.leaves, 0);
		this.setBlock(world, i + 12, j + 47, k + 20, Blocks.leaves, 0);
		this.setBlock(world, i + 12, j + 47, k + 21, Blocks.leaves, 0);
		this.setBlock(world, i + 12, j + 47, k + 22, Blocks.leaves, 0);
		this.setBlock(world, i + 12, j + 47, k + 23, Blocks.leaves, 0);
		this.setBlock(world, i + 12, j + 47, k + 24, Blocks.leaves, 0);
		this.setBlock(world, i + 12, j + 47, k + 25, Blocks.log, 1);
		this.setBlock(world, i + 12, j + 47, k + 26, Blocks.leaves, 0);
		this.setBlock(world, i + 12, j + 47, k + 27, Blocks.leaves, 0);
		this.setBlock(world, i + 12, j + 47, k + 28, Blocks.log, 1);
		this.setBlock(world, i + 12, j + 47, k + 29, Blocks.leaves, 0);
		this.setBlock(world, i + 12, j + 47, k + 30, Blocks.leaves, 0);
		this.setBlock(world, i + 12, j + 47, k + 31, Blocks.leaves, 0);
		this.setBlock(world, i + 12, j + 47, k + 32, Blocks.leaves, 0);
		this.setBlock(world, i + 12, j + 47, k + 33, Blocks.leaves, 0);
		this.setBlock(world, i + 12, j + 48, k + 7, Blocks.leaves, 0);
		this.setBlock(world, i + 12, j + 48, k + 8, Blocks.leaves, 0);
		this.setBlock(world, i + 12, j + 48, k + 9, Blocks.leaves, 0);
		this.setBlock(world, i + 12, j + 48, k + 10, Blocks.leaves, 0);
		this.setBlock(world, i + 12, j + 48, k + 11, Blocks.leaves, 0);
		this.setBlock(world, i + 12, j + 48, k + 19, Blocks.leaves, 0);
		this.setBlock(world, i + 12, j + 48, k + 20, Blocks.leaves, 0);
		this.setBlock(world, i + 12, j + 48, k + 21, Blocks.leaves, 0);
		this.setBlock(world, i + 12, j + 48, k + 22, Blocks.leaves, 0);
		this.setBlock(world, i + 12, j + 48, k + 23, Blocks.leaves, 0);
		this.setBlock(world, i + 12, j + 48, k + 24, Blocks.log, 1);
		this.setBlock(world, i + 12, j + 48, k + 25, Blocks.log, 1);
		this.setBlock(world, i + 12, j + 48, k + 26, Blocks.leaves, 0);
		this.setBlock(world, i + 12, j + 48, k + 27, Blocks.leaves, 0);
		this.setBlock(world, i + 12, j + 48, k + 28, Blocks.leaves, 0);
		this.setBlock(world, i + 12, j + 48, k + 29, Blocks.leaves, 0);
		this.setBlock(world, i + 12, j + 48, k + 30, Blocks.leaves, 0);
		this.setBlock(world, i + 12, j + 48, k + 31, Blocks.leaves, 0);
		this.setBlock(world, i + 12, j + 48, k + 32, Blocks.leaves, 0);
		this.setBlock(world, i + 12, j + 48, k + 33, Blocks.leaves, 0);
		this.setBlock(world, i + 12, j + 49, k + 8, Blocks.leaves, 0);
		this.setBlock(world, i + 12, j + 49, k + 17, Blocks.leaves, 0);
		this.setBlock(world, i + 12, j + 49, k + 18, Blocks.leaves, 0);
		this.setBlock(world, i + 12, j + 49, k + 19, Blocks.leaves, 0);
		this.setBlock(world, i + 12, j + 49, k + 20, Blocks.leaves, 0);
		this.setBlock(world, i + 12, j + 49, k + 21, Blocks.leaves, 0);
		this.setBlock(world, i + 12, j + 49, k + 22, Blocks.leaves, 0);
		this.setBlock(world, i + 12, j + 49, k + 23, Blocks.leaves, 0);
		this.setBlock(world, i + 12, j + 49, k + 24, Blocks.leaves, 0);
		this.setBlock(world, i + 12, j + 49, k + 25, Blocks.leaves, 0);
		this.setBlock(world, i + 12, j + 49, k + 26, Blocks.log, 1);
		this.setBlock(world, i + 12, j + 49, k + 27, Blocks.leaves, 0);
		this.setBlock(world, i + 12, j + 49, k + 28, Blocks.leaves, 0);
		this.setBlock(world, i + 12, j + 49, k + 29, Blocks.log, 1);
		this.setBlock(world, i + 12, j + 49, k + 30, Blocks.leaves, 0);
		this.setBlock(world, i + 12, j + 49, k + 31, Blocks.leaves, 0);
		this.setBlock(world, i + 12, j + 49, k + 32, Blocks.leaves, 0);
		this.setBlock(world, i + 12, j + 49, k + 33, Blocks.leaves, 0);
		this.setBlock(world, i + 12, j + 49, k + 34, Blocks.leaves, 0);
		this.setBlock(world, i + 12, j + 50, k + 16, Blocks.leaves, 0);
		this.setBlock(world, i + 12, j + 50, k + 17, Blocks.leaves, 0);
		this.setBlock(world, i + 12, j + 50, k + 18, Blocks.leaves, 0);
		this.setBlock(world, i + 12, j + 50, k + 19, Blocks.leaves, 0);
		this.setBlock(world, i + 12, j + 50, k + 20, Blocks.leaves, 0);
		this.setBlock(world, i + 12, j + 50, k + 21, Blocks.leaves, 0);
		this.setBlock(world, i + 12, j + 50, k + 22, Blocks.leaves, 0);
		this.setBlock(world, i + 12, j + 50, k + 23, Blocks.leaves, 0);
		this.setBlock(world, i + 12, j + 50, k + 24, Blocks.log, 1);
		this.setBlock(world, i + 12, j + 50, k + 25, Blocks.leaves, 0);
		this.setBlock(world, i + 12, j + 50, k + 26, Blocks.log, 1);
		this.setBlock(world, i + 12, j + 50, k + 27, Blocks.leaves, 0);
		this.setBlock(world, i + 12, j + 50, k + 28, Blocks.leaves, 0);
		this.setBlock(world, i + 12, j + 50, k + 29, Blocks.leaves, 0);
		this.setBlock(world, i + 12, j + 50, k + 30, Blocks.leaves, 0);
		this.setBlock(world, i + 12, j + 50, k + 31, Blocks.leaves, 0);
		this.setBlock(world, i + 12, j + 50, k + 32, Blocks.leaves, 0);
		this.setBlock(world, i + 12, j + 50, k + 33, Blocks.leaves, 0);
		this.setBlock(world, i + 12, j + 50, k + 34, Blocks.log, 1);
		this.setBlock(world, i + 12, j + 50, k + 35, Blocks.leaves, 0);
		this.setBlock(world, i + 12, j + 51, k + 17, Blocks.leaves, 0);
		this.setBlock(world, i + 12, j + 51, k + 18, Blocks.leaves, 0);
		this.setBlock(world, i + 12, j + 51, k + 19, Blocks.leaves, 0);
		this.setBlock(world, i + 12, j + 51, k + 20, Blocks.leaves, 0);
		this.setBlock(world, i + 12, j + 51, k + 21, Blocks.leaves, 0);
		this.setBlock(world, i + 12, j + 51, k + 22, Blocks.leaves, 0);
		this.setBlock(world, i + 12, j + 51, k + 23, Blocks.log, 1);
		this.setBlock(world, i + 12, j + 51, k + 24, Blocks.leaves, 0);
		this.setBlock(world, i + 12, j + 51, k + 25, Blocks.leaves, 0);
		this.setBlock(world, i + 12, j + 51, k + 26, Blocks.leaves, 0);
		this.setBlock(world, i + 12, j + 51, k + 27, Blocks.leaves, 0);
		this.setBlock(world, i + 12, j + 51, k + 28, Blocks.leaves, 0);
		this.setBlock(world, i + 12, j + 51, k + 29, Blocks.leaves, 0);
		this.setBlock(world, i + 12, j + 51, k + 30, Blocks.leaves, 0);
		this.setBlock(world, i + 12, j + 51, k + 31, Blocks.leaves, 0);
		this.setBlock(world, i + 12, j + 51, k + 32, Blocks.leaves, 0);
		this.setBlock(world, i + 12, j + 51, k + 33, Blocks.leaves, 0);
		this.setBlock(world, i + 12, j + 51, k + 34, Blocks.leaves, 0);
		this.setBlock(world, i + 12, j + 52, k + 22, Blocks.leaves, 0);
		this.setBlock(world, i + 12, j + 52, k + 23, Blocks.leaves, 0);
		this.setBlock(world, i + 12, j + 52, k + 24, Blocks.leaves, 0);
		this.setBlock(world, i + 13, j + 40, k + 22, Blocks.log, 1);
		this.setBlock(world, i + 13, j + 40, k + 23, Blocks.log, 1);
		this.setBlock(world, i + 13, j + 40, k + 24, Blocks.log, 1);
		this.setBlock(world, i + 13, j + 41, k + 22, Blocks.log, 1);
		this.setBlock(world, i + 13, j + 41, k + 23, Blocks.log, 1);
		this.setBlock(world, i + 13, j + 41, k + 24, Blocks.log, 1);
		this.setBlock(world, i + 13, j + 41, k + 25, Blocks.log, 1);
		this.setBlock(world, i + 13, j + 42, k + 22, Blocks.log, 1);
		this.setBlock(world, i + 13, j + 42, k + 23, Blocks.log, 1);
		this.setBlock(world, i + 13, j + 42, k + 24, Blocks.log, 1);
		this.setBlock(world, i + 13, j + 42, k + 25, Blocks.log, 1);
		this.setBlock(world, i + 13, j + 42, k + 26, Blocks.log, 1);
		this.setBlock(world, i + 13, j + 43, k + 23, Blocks.log, 1);
		this.setBlock(world, i + 13, j + 43, k + 24, Blocks.log, 1);
		this.setBlock(world, i + 13, j + 43, k + 25, Blocks.log, 1);
		this.setBlock(world, i + 13, j + 43, k + 26, Blocks.log, 1);
		this.setBlock(world, i + 13, j + 44, k + 7, Blocks.leaves, 0);
		this.setBlock(world, i + 13, j + 44, k + 8, Blocks.leaves, 0);
		this.setBlock(world, i + 13, j + 44, k + 9, Blocks.log, 1);
		this.setBlock(world, i + 13, j + 44, k + 10, Blocks.leaves, 0);
		this.setBlock(world, i + 13, j + 44, k + 11, Blocks.leaves, 0);
		this.setBlock(world, i + 13, j + 44, k + 24, Blocks.log, 1);
		this.setBlock(world, i + 13, j + 44, k + 25, Blocks.log, 1);
		this.setBlock(world, i + 13, j + 44, k + 26, Blocks.log, 1);
		this.setBlock(world, i + 13, j + 45, k + 5, Blocks.leaves, 0);
		this.setBlock(world, i + 13, j + 45, k + 6, Blocks.leaves, 0);
		this.setBlock(world, i + 13, j + 45, k + 7, Blocks.leaves, 0);
		this.setBlock(world, i + 13, j + 45, k + 8, Blocks.log, 1);
		this.setBlock(world, i + 13, j + 45, k + 9, Blocks.leaves, 0);
		this.setBlock(world, i + 13, j + 45, k + 10, Blocks.leaves, 0);
		this.setBlock(world, i + 13, j + 45, k + 11, Blocks.log, 1);
		this.setBlock(world, i + 13, j + 45, k + 12, Blocks.leaves, 0);
		this.setBlock(world, i + 13, j + 45, k + 13, Blocks.leaves, 0);
		this.setBlock(world, i + 13, j + 45, k + 27, Blocks.log, 1);
		this.setBlock(world, i + 13, j + 46, k + 5, Blocks.leaves, 0);
		this.setBlock(world, i + 13, j + 46, k + 6, Blocks.leaves, 0);
		this.setBlock(world, i + 13, j + 46, k + 7, Blocks.leaves, 0);
		this.setBlock(world, i + 13, j + 46, k + 8, Blocks.leaves, 0);
		this.setBlock(world, i + 13, j + 46, k + 9, Blocks.leaves, 0);
		this.setBlock(world, i + 13, j + 46, k + 10, Blocks.log, 1);
		this.setBlock(world, i + 13, j + 46, k + 11, Blocks.leaves, 0);
		this.setBlock(world, i + 13, j + 46, k + 12, Blocks.leaves, 0);
		this.setBlock(world, i + 13, j + 46, k + 13, Blocks.log, 1);
		this.setBlock(world, i + 13, j + 46, k + 22, Blocks.leaves, 0);
		this.setBlock(world, i + 13, j + 46, k + 23, Blocks.leaves, 0);
		this.setBlock(world, i + 13, j + 46, k + 24, Blocks.leaves, 0);
		this.setBlock(world, i + 13, j + 46, k + 25, Blocks.leaves, 0);
		this.setBlock(world, i + 13, j + 46, k + 26, Blocks.log, 1);
		this.setBlock(world, i + 13, j + 47, k + 3, Blocks.leaves, 0);
		this.setBlock(world, i + 13, j + 47, k + 5, Blocks.leaves, 0);
		this.setBlock(world, i + 13, j + 47, k + 6, Blocks.leaves, 0);
		this.setBlock(world, i + 13, j + 47, k + 7, Blocks.leaves, 0);
		this.setBlock(world, i + 13, j + 47, k + 8, Blocks.leaves, 0);
		this.setBlock(world, i + 13, j + 47, k + 9, Blocks.leaves, 0);
		this.setBlock(world, i + 13, j + 47, k + 10, Blocks.leaves, 0);
		this.setBlock(world, i + 13, j + 47, k + 11, Blocks.leaves, 0);
		this.setBlock(world, i + 13, j + 47, k + 12, Blocks.leaves, 0);
		this.setBlock(world, i + 13, j + 47, k + 13, Blocks.leaves, 0);
		this.setBlock(world, i + 13, j + 47, k + 22, Blocks.log, 1);
		this.setBlock(world, i + 13, j + 47, k + 23, Blocks.leaves, 0);
		this.setBlock(world, i + 13, j + 47, k + 24, Blocks.leaves, 0);
		this.setBlock(world, i + 13, j + 47, k + 25, Blocks.leaves, 0);
		this.setBlock(world, i + 13, j + 47, k + 26, Blocks.leaves, 0);
		this.setBlock(world, i + 13, j + 47, k + 27, Blocks.leaves, 0);
		this.setBlock(world, i + 13, j + 47, k + 28, Blocks.leaves, 0);
		this.setBlock(world, i + 13, j + 47, k + 29, Blocks.leaves, 0);
		this.setBlock(world, i + 13, j + 47, k + 30, Blocks.leaves, 0);
		this.setBlock(world, i + 13, j + 47, k + 31, Blocks.leaves, 0);
		this.setBlock(world, i + 13, j + 47, k + 32, Blocks.leaves, 0);
		this.setBlock(world, i + 13, j + 48, k + 7, Blocks.leaves, 0);
		this.setBlock(world, i + 13, j + 48, k + 8, Blocks.leaves, 0);
		this.setBlock(world, i + 13, j + 48, k + 9, Blocks.leaves, 0);
		this.setBlock(world, i + 13, j + 48, k + 10, Blocks.leaves, 0);
		this.setBlock(world, i + 13, j + 48, k + 11, Blocks.leaves, 0);
		this.setBlock(world, i + 13, j + 48, k + 21, Blocks.leaves, 0);
		this.setBlock(world, i + 13, j + 48, k + 22, Blocks.leaves, 0);
		this.setBlock(world, i + 13, j + 48, k + 23, Blocks.leaves, 0);
		this.setBlock(world, i + 13, j + 48, k + 24, Blocks.leaves, 0);
		this.setBlock(world, i + 13, j + 48, k + 25, Blocks.leaves, 0);
		this.setBlock(world, i + 13, j + 48, k + 26, Blocks.leaves, 0);
		this.setBlock(world, i + 13, j + 48, k + 27, Blocks.log, 1);
		this.setBlock(world, i + 13, j + 48, k + 28, Blocks.leaves, 0);
		this.setBlock(world, i + 13, j + 48, k + 29, Blocks.leaves, 0);
		this.setBlock(world, i + 13, j + 48, k + 30, Blocks.leaves, 0);
		this.setBlock(world, i + 13, j + 48, k + 31, Blocks.log, 1);
		this.setBlock(world, i + 13, j + 48, k + 32, Blocks.leaves, 0);
		this.setBlock(world, i + 13, j + 48, k + 33, Blocks.log, 1);
		this.setBlock(world, i + 13, j + 49, k + 19, Blocks.leaves, 0);
		this.setBlock(world, i + 13, j + 49, k + 20, Blocks.leaves, 0);
		this.setBlock(world, i + 13, j + 49, k + 21, Blocks.leaves, 0);
		this.setBlock(world, i + 13, j + 49, k + 22, Blocks.leaves, 0);
		this.setBlock(world, i + 13, j + 49, k + 23, Blocks.leaves, 0);
		this.setBlock(world, i + 13, j + 49, k + 24, Blocks.leaves, 0);
		this.setBlock(world, i + 13, j + 49, k + 25, Blocks.leaves, 0);
		this.setBlock(world, i + 13, j + 49, k + 26, Blocks.leaves, 0);
		this.setBlock(world, i + 13, j + 49, k + 27, Blocks.log, 1);
		this.setBlock(world, i + 13, j + 49, k + 28, Blocks.leaves, 0);
		this.setBlock(world, i + 13, j + 49, k + 29, Blocks.leaves, 0);
		this.setBlock(world, i + 13, j + 49, k + 30, Blocks.leaves, 0);
		this.setBlock(world, i + 13, j + 49, k + 31, Blocks.leaves, 0);
		this.setBlock(world, i + 13, j + 49, k + 32, Blocks.leaves, 0);
		this.setBlock(world, i + 13, j + 49, k + 33, Blocks.leaves, 0);
		this.setBlock(world, i + 13, j + 49, k + 34, Blocks.leaves, 0);
		this.setBlock(world, i + 13, j + 50, k + 17, Blocks.leaves, 0);
		this.setBlock(world, i + 13, j + 50, k + 19, Blocks.leaves, 0);
		this.setBlock(world, i + 13, j + 50, k + 20, Blocks.leaves, 0);
		this.setBlock(world, i + 13, j + 50, k + 21, Blocks.leaves, 0);
		this.setBlock(world, i + 13, j + 50, k + 22, Blocks.log, 1);
		this.setBlock(world, i + 13, j + 50, k + 23, Blocks.leaves, 0);
		this.setBlock(world, i + 13, j + 50, k + 24, Blocks.leaves, 0);
		this.setBlock(world, i + 13, j + 50, k + 25, Blocks.leaves, 0);
		this.setBlock(world, i + 13, j + 50, k + 26, Blocks.leaves, 0);
		this.setBlock(world, i + 13, j + 50, k + 27, Blocks.log, 1);
		this.setBlock(world, i + 13, j + 50, k + 28, Blocks.log, 1);
		this.setBlock(world, i + 13, j + 50, k + 29, Blocks.leaves, 0);
		this.setBlock(world, i + 13, j + 50, k + 30, Blocks.leaves, 0);
		this.setBlock(world, i + 13, j + 50, k + 31, Blocks.leaves, 0);
		this.setBlock(world, i + 13, j + 50, k + 32, Blocks.leaves, 0);
		this.setBlock(world, i + 13, j + 50, k + 33, Blocks.leaves, 0);
		this.setBlock(world, i + 13, j + 50, k + 34, Blocks.leaves, 0);
		this.setBlock(world, i + 13, j + 50, k + 35, Blocks.leaves, 0);
		this.setBlock(world, i + 13, j + 51, k + 19, Blocks.leaves, 0);
		this.setBlock(world, i + 13, j + 51, k + 20, Blocks.leaves, 0);
		this.setBlock(world, i + 13, j + 51, k + 21, Blocks.leaves, 0);
		this.setBlock(world, i + 13, j + 51, k + 22, Blocks.leaves, 0);
		this.setBlock(world, i + 13, j + 51, k + 23, Blocks.leaves, 0);
		this.setBlock(world, i + 13, j + 51, k + 24, Blocks.leaves, 0);
		this.setBlock(world, i + 13, j + 51, k + 25, Blocks.leaves, 0);
		this.setBlock(world, i + 13, j + 51, k + 26, Blocks.leaves, 0);
		this.setBlock(world, i + 13, j + 51, k + 27, Blocks.leaves, 0);
		this.setBlock(world, i + 13, j + 51, k + 28, Blocks.leaves, 0);
		this.setBlock(world, i + 13, j + 51, k + 29, Blocks.leaves, 0);
		this.setBlock(world, i + 13, j + 51, k + 30, Blocks.leaves, 0);
		this.setBlock(world, i + 13, j + 51, k + 31, Blocks.leaves, 0);
		this.setBlock(world, i + 13, j + 51, k + 32, Blocks.leaves, 0);
		this.setBlock(world, i + 13, j + 51, k + 33, Blocks.leaves, 0);
		this.setBlock(world, i + 13, j + 51, k + 34, Blocks.leaves, 0);
		this.setBlock(world, i + 13, j + 52, k + 21, Blocks.leaves, 0);
		this.setBlock(world, i + 13, j + 52, k + 22, Blocks.leaves, 0);
		this.setBlock(world, i + 13, j + 52, k + 23, Blocks.leaves, 0);
		this.setBlock(world, i + 13, j + 52, k + 24, Blocks.leaves, 0);
		this.setBlock(world, i + 13, j + 52, k + 25, Blocks.leaves, 0);
		this.setBlock(world, i + 13, j + 52, k + 33, Blocks.leaves, 0);
		this.setBlock(world, i + 14, j + 39, k + 23, Blocks.log, 1);
		this.setBlock(world, i + 14, j + 40, k + 21, Blocks.log, 1);
		this.setBlock(world, i + 14, j + 40, k + 22, Blocks.log, 1);
		this.setBlock(world, i + 14, j + 40, k + 23, Blocks.log, 1);
		this.setBlock(world, i + 14, j + 40, k + 24, Blocks.log, 1);
		this.setBlock(world, i + 14, j + 41, k + 21, Blocks.log, 1);
		this.setBlock(world, i + 14, j + 41, k + 22, Blocks.log, 1);
		this.setBlock(world, i + 14, j + 41, k + 23, Blocks.log, 1);
		this.setBlock(world, i + 14, j + 41, k + 24, Blocks.log, 1);
		this.setBlock(world, i + 14, j + 41, k + 25, Blocks.log, 1);
		this.setBlock(world, i + 14, j + 42, k + 21, Blocks.log, 1);
		this.setBlock(world, i + 14, j + 42, k + 22, Blocks.log, 1);
		this.setBlock(world, i + 14, j + 42, k + 23, Blocks.log, 1);
		this.setBlock(world, i + 14, j + 42, k + 24, Blocks.log, 1);
		this.setBlock(world, i + 14, j + 42, k + 25, Blocks.log, 1);
		this.setBlock(world, i + 14, j + 43, k + 6, Blocks.leaves, 0);
		this.setBlock(world, i + 14, j + 43, k + 7, Blocks.leaves, 0);
		this.setBlock(world, i + 14, j + 43, k + 8, Blocks.leaves, 0);
		this.setBlock(world, i + 14, j + 43, k + 9, Blocks.leaves, 0);
		this.setBlock(world, i + 14, j + 43, k + 23, Blocks.log, 1);
		this.setBlock(world, i + 14, j + 43, k + 24, Blocks.log, 1);
		this.setBlock(world, i + 14, j + 43, k + 25, Blocks.log, 1);
		this.setBlock(world, i + 14, j + 44, k + 5, Blocks.leaves, 0);
		this.setBlock(world, i + 14, j + 44, k + 6, Blocks.leaves, 0);
		this.setBlock(world, i + 14, j + 44, k + 7, Blocks.leaves, 0);
		this.setBlock(world, i + 14, j + 44, k + 8, Blocks.leaves, 0);
		this.setBlock(world, i + 14, j + 44, k + 9, Blocks.leaves, 0);
		this.setBlock(world, i + 14, j + 44, k + 10, Blocks.leaves, 0);
		this.setBlock(world, i + 14, j + 44, k + 11, Blocks.leaves, 0);
		this.setBlock(world, i + 14, j + 44, k + 12, Blocks.leaves, 0);
		this.setBlock(world, i + 14, j + 45, k + 5, Blocks.leaves, 0);
		this.setBlock(world, i + 14, j + 45, k + 6, Blocks.leaves, 0);
		this.setBlock(world, i + 14, j + 45, k + 7, Blocks.leaves, 0);
		this.setBlock(world, i + 14, j + 45, k + 8, Blocks.leaves, 0);
		this.setBlock(world, i + 14, j + 45, k + 9, Blocks.leaves, 0);
		this.setBlock(world, i + 14, j + 45, k + 10, Blocks.leaves, 0);
		this.setBlock(world, i + 14, j + 45, k + 11, Blocks.leaves, 0);
		this.setBlock(world, i + 14, j + 45, k + 12, Blocks.leaves, 0);
		this.setBlock(world, i + 14, j + 45, k + 13, Blocks.leaves, 0);
		this.setBlock(world, i + 14, j + 46, k + 2, Blocks.leaves, 0);
		this.setBlock(world, i + 14, j + 46, k + 3, Blocks.leaves, 0);
		this.setBlock(world, i + 14, j + 46, k + 4, Blocks.leaves, 0);
		this.setBlock(world, i + 14, j + 46, k + 5, Blocks.leaves, 0);
		this.setBlock(world, i + 14, j + 46, k + 6, Blocks.leaves, 0);
		this.setBlock(world, i + 14, j + 46, k + 7, Blocks.leaves, 0);
		this.setBlock(world, i + 14, j + 46, k + 8, Blocks.leaves, 0);
		this.setBlock(world, i + 14, j + 46, k + 9, Blocks.leaves, 0);
		this.setBlock(world, i + 14, j + 46, k + 10, Blocks.leaves, 0);
		this.setBlock(world, i + 14, j + 46, k + 11, Blocks.leaves, 0);
		this.setBlock(world, i + 14, j + 46, k + 12, Blocks.leaves, 0);
		this.setBlock(world, i + 14, j + 46, k + 13, Blocks.leaves, 0);
		this.setBlock(world, i + 14, j + 46, k + 14, Blocks.leaves, 0);
		this.setBlock(world, i + 14, j + 46, k + 23, Blocks.leaves, 0);
		this.setBlock(world, i + 14, j + 46, k + 24, Blocks.leaves, 0);
		this.setBlock(world, i + 14, j + 46, k + 25, Blocks.leaves, 0);
		this.setBlock(world, i + 14, j + 46, k + 28, Blocks.leaves, 0);
		this.setBlock(world, i + 14, j + 47, k + 2, Blocks.leaves, 0);
		this.setBlock(world, i + 14, j + 47, k + 3, Blocks.leaves, 0);
		this.setBlock(world, i + 14, j + 47, k + 4, Blocks.log, 1);
		this.setBlock(world, i + 14, j + 47, k + 5, Blocks.leaves, 0);
		this.setBlock(world, i + 14, j + 47, k + 6, Blocks.leaves, 0);
		this.setBlock(world, i + 14, j + 47, k + 7, Blocks.leaves, 0);
		this.setBlock(world, i + 14, j + 47, k + 8, Blocks.leaves, 0);
		this.setBlock(world, i + 14, j + 47, k + 9, Blocks.leaves, 0);
		this.setBlock(world, i + 14, j + 47, k + 10, Blocks.leaves, 0);
		this.setBlock(world, i + 14, j + 47, k + 11, Blocks.leaves, 0);
		this.setBlock(world, i + 14, j + 47, k + 12, Blocks.log, 1);
		this.setBlock(world, i + 14, j + 47, k + 13, Blocks.leaves, 0);
		this.setBlock(world, i + 14, j + 47, k + 22, Blocks.leaves, 0);
		this.setBlock(world, i + 14, j + 47, k + 23, Blocks.leaves, 0);
		this.setBlock(world, i + 14, j + 47, k + 24, Blocks.leaves, 0);
		this.setBlock(world, i + 14, j + 47, k + 25, Blocks.leaves, 0);
		this.setBlock(world, i + 14, j + 47, k + 26, Blocks.log, 1);
		this.setBlock(world, i + 14, j + 47, k + 27, Blocks.leaves, 0);
		this.setBlock(world, i + 14, j + 47, k + 28, Blocks.leaves, 0);
		this.setBlock(world, i + 14, j + 47, k + 29, Blocks.leaves, 0);
		this.setBlock(world, i + 14, j + 47, k + 30, Blocks.log, 1);
		this.setBlock(world, i + 14, j + 48, k + 2, Blocks.leaves, 0);
		this.setBlock(world, i + 14, j + 48, k + 3, Blocks.leaves, 0);
		this.setBlock(world, i + 14, j + 48, k + 4, Blocks.leaves, 0);
		this.setBlock(world, i + 14, j + 48, k + 6, Blocks.leaves, 0);
		this.setBlock(world, i + 14, j + 48, k + 7, Blocks.leaves, 0);
		this.setBlock(world, i + 14, j + 48, k + 8, Blocks.leaves, 0);
		this.setBlock(world, i + 14, j + 48, k + 9, Blocks.log, 1);
		this.setBlock(world, i + 14, j + 48, k + 10, Blocks.leaves, 0);
		this.setBlock(world, i + 14, j + 48, k + 11, Blocks.leaves, 0);
		this.setBlock(world, i + 14, j + 48, k + 12, Blocks.leaves, 0);
		this.setBlock(world, i + 14, j + 48, k + 20, Blocks.leaves, 0);
		this.setBlock(world, i + 14, j + 48, k + 21, Blocks.leaves, 0);
		this.setBlock(world, i + 14, j + 48, k + 22, Blocks.leaves, 0);
		this.setBlock(world, i + 14, j + 48, k + 23, Blocks.leaves, 0);
		this.setBlock(world, i + 14, j + 48, k + 24, Blocks.leaves, 0);
		this.setBlock(world, i + 14, j + 48, k + 25, Blocks.leaves, 0);
		this.setBlock(world, i + 14, j + 48, k + 26, Blocks.leaves, 0);
		this.setBlock(world, i + 14, j + 48, k + 27, Blocks.leaves, 0);
		this.setBlock(world, i + 14, j + 48, k + 28, Blocks.log, 1);
		this.setBlock(world, i + 14, j + 48, k + 29, Blocks.leaves, 0);
		this.setBlock(world, i + 14, j + 48, k + 30, Blocks.leaves, 0);
		this.setBlock(world, i + 14, j + 48, k + 31, Blocks.log, 1);
		this.setBlock(world, i + 14, j + 48, k + 32, Blocks.leaves, 0);
		this.setBlock(world, i + 14, j + 48, k + 33, Blocks.leaves, 0);
		this.setBlock(world, i + 14, j + 49, k + 9, Blocks.leaves, 0);
		this.setBlock(world, i + 14, j + 49, k + 19, Blocks.leaves, 0);
		this.setBlock(world, i + 14, j + 49, k + 20, Blocks.leaves, 0);
		this.setBlock(world, i + 14, j + 49, k + 21, Blocks.leaves, 0);
		this.setBlock(world, i + 14, j + 49, k + 22, Blocks.leaves, 0);
		this.setBlock(world, i + 14, j + 49, k + 23, Blocks.leaves, 0);
		this.setBlock(world, i + 14, j + 49, k + 24, Blocks.leaves, 0);
		this.setBlock(world, i + 14, j + 49, k + 25, Blocks.leaves, 0);
		this.setBlock(world, i + 14, j + 49, k + 26, Blocks.leaves, 0);
		this.setBlock(world, i + 14, j + 49, k + 27, Blocks.leaves, 0);
		this.setBlock(world, i + 14, j + 49, k + 28, Blocks.leaves, 0);
		this.setBlock(world, i + 14, j + 49, k + 29, Blocks.leaves, 0);
		this.setBlock(world, i + 14, j + 49, k + 30, Blocks.leaves, 0);
		this.setBlock(world, i + 14, j + 49, k + 31, Blocks.leaves, 0);
		this.setBlock(world, i + 14, j + 49, k + 32, Blocks.leaves, 0);
		this.setBlock(world, i + 14, j + 49, k + 33, Blocks.leaves, 0);
		this.setBlock(world, i + 14, j + 49, k + 34, Blocks.leaves, 0);
		this.setBlock(world, i + 14, j + 50, k + 18, Blocks.leaves, 0);
		this.setBlock(world, i + 14, j + 50, k + 19, Blocks.log, 1);
		this.setBlock(world, i + 14, j + 50, k + 20, Blocks.leaves, 0);
		this.setBlock(world, i + 14, j + 50, k + 21, Blocks.leaves, 0);
		this.setBlock(world, i + 14, j + 50, k + 22, Blocks.leaves, 0);
		this.setBlock(world, i + 14, j + 50, k + 23, Blocks.log, 1);
		this.setBlock(world, i + 14, j + 50, k + 24, Blocks.leaves, 0);
		this.setBlock(world, i + 14, j + 50, k + 25, Blocks.leaves, 0);
		this.setBlock(world, i + 14, j + 50, k + 26, Blocks.leaves, 0);
		this.setBlock(world, i + 14, j + 50, k + 27, Blocks.leaves, 0);
		this.setBlock(world, i + 14, j + 50, k + 28, Blocks.leaves, 0);
		this.setBlock(world, i + 14, j + 50, k + 29, Blocks.leaves, 0);
		this.setBlock(world, i + 14, j + 50, k + 30, Blocks.leaves, 0);
		this.setBlock(world, i + 14, j + 50, k + 31, Blocks.leaves, 0);
		this.setBlock(world, i + 14, j + 50, k + 32, Blocks.leaves, 0);
		this.setBlock(world, i + 14, j + 50, k + 33, Blocks.leaves, 0);
		this.setBlock(world, i + 14, j + 50, k + 34, Blocks.log, 1);
		this.setBlock(world, i + 14, j + 51, k + 19, Blocks.leaves, 0);
		this.setBlock(world, i + 14, j + 51, k + 20, Blocks.leaves, 0);
		this.setBlock(world, i + 14, j + 51, k + 21, Blocks.leaves, 0);
		this.setBlock(world, i + 14, j + 51, k + 22, Blocks.log, 1);
		this.setBlock(world, i + 14, j + 51, k + 23, Blocks.leaves, 0);
		this.setBlock(world, i + 14, j + 51, k + 24, Blocks.leaves, 0);
		this.setBlock(world, i + 14, j + 51, k + 25, Blocks.log, 1);
		this.setBlock(world, i + 14, j + 51, k + 26, Blocks.leaves, 0);
		this.setBlock(world, i + 14, j + 51, k + 27, Blocks.leaves, 0);
		this.setBlock(world, i + 14, j + 51, k + 28, Blocks.leaves, 0);
		this.setBlock(world, i + 14, j + 51, k + 29, Blocks.leaves, 0);
		this.setBlock(world, i + 14, j + 51, k + 30, Blocks.leaves, 0);
		this.setBlock(world, i + 14, j + 51, k + 32, Blocks.leaves, 0);
		this.setBlock(world, i + 14, j + 51, k + 33, Blocks.leaves, 0);
		this.setBlock(world, i + 14, j + 51, k + 34, Blocks.leaves, 0);
		this.setBlock(world, i + 14, j + 52, k + 20, Blocks.leaves, 0);
		this.setBlock(world, i + 14, j + 52, k + 21, Blocks.leaves, 0);
		this.setBlock(world, i + 14, j + 52, k + 22, Blocks.leaves, 0);
		this.setBlock(world, i + 14, j + 52, k + 23, Blocks.leaves, 0);
		this.setBlock(world, i + 14, j + 52, k + 24, Blocks.leaves, 0);
		this.setBlock(world, i + 14, j + 52, k + 25, Blocks.leaves, 0);
		this.setBlock(world, i + 14, j + 52, k + 28, Blocks.leaves, 0);
		this.setBlock(world, i + 14, j + 53, k + 23, Blocks.leaves, 0);
		this.setBlock(world, i + 15, j + 39, k + 20, Blocks.log, 1);
		this.setBlock(world, i + 15, j + 39, k + 21, Blocks.log, 1);
		this.setBlock(world, i + 15, j + 39, k + 22, Blocks.log, 1);
		this.setBlock(world, i + 15, j + 40, k + 20, Blocks.log, 1);
		this.setBlock(world, i + 15, j + 40, k + 21, Blocks.log, 1);
		this.setBlock(world, i + 15, j + 40, k + 22, Blocks.log, 1);
		this.setBlock(world, i + 15, j + 40, k + 23, Blocks.log, 1);
		this.setBlock(world, i + 15, j + 40, k + 24, Blocks.log, 1);
		this.setBlock(world, i + 15, j + 41, k + 20, Blocks.log, 1);
		this.setBlock(world, i + 15, j + 41, k + 21, Blocks.log, 1);
		this.setBlock(world, i + 15, j + 41, k + 22, Blocks.log, 1);
		this.setBlock(world, i + 15, j + 41, k + 23, Blocks.log, 1);
		this.setBlock(world, i + 15, j + 41, k + 24, Blocks.log, 1);
		this.setBlock(world, i + 15, j + 42, k + 21, Blocks.log, 1);
		this.setBlock(world, i + 15, j + 42, k + 22, Blocks.log, 1);
		this.setBlock(world, i + 15, j + 42, k + 23, Blocks.log, 1);
		this.setBlock(world, i + 15, j + 42, k + 24, Blocks.log, 1);
		this.setBlock(world, i + 15, j + 43, k + 5, Blocks.leaves, 0);
		this.setBlock(world, i + 15, j + 43, k + 6, Blocks.log, 1);
		this.setBlock(world, i + 15, j + 43, k + 7, Blocks.leaves, 0);
		this.setBlock(world, i + 15, j + 43, k + 8, Blocks.leaves, 0);
		this.setBlock(world, i + 15, j + 43, k + 9, Blocks.leaves, 0);
		this.setBlock(world, i + 15, j + 43, k + 22, Blocks.log, 1);
		this.setBlock(world, i + 15, j + 44, k + 4, Blocks.leaves, 0);
		this.setBlock(world, i + 15, j + 44, k + 5, Blocks.leaves, 0);
		this.setBlock(world, i + 15, j + 44, k + 6, Blocks.leaves, 0);
		this.setBlock(world, i + 15, j + 44, k + 7, Blocks.leaves, 0);
		this.setBlock(world, i + 15, j + 44, k + 8, Blocks.leaves, 0);
		this.setBlock(world, i + 15, j + 44, k + 9, Blocks.leaves, 0);
		this.setBlock(world, i + 15, j + 44, k + 10, Blocks.leaves, 0);
		this.setBlock(world, i + 15, j + 44, k + 11, Blocks.leaves, 0);
		this.setBlock(world, i + 15, j + 45, k + 3, Blocks.leaves, 0);
		this.setBlock(world, i + 15, j + 45, k + 4, Blocks.leaves, 0);
		this.setBlock(world, i + 15, j + 45, k + 5, Blocks.leaves, 0);
		this.setBlock(world, i + 15, j + 45, k + 6, Blocks.leaves, 0);
		this.setBlock(world, i + 15, j + 45, k + 7, Blocks.leaves, 0);
		this.setBlock(world, i + 15, j + 45, k + 8, Blocks.leaves, 0);
		this.setBlock(world, i + 15, j + 45, k + 9, Blocks.leaves, 0);
		this.setBlock(world, i + 15, j + 45, k + 10, Blocks.leaves, 0);
		this.setBlock(world, i + 15, j + 45, k + 11, Blocks.leaves, 0);
		this.setBlock(world, i + 15, j + 45, k + 12, Blocks.leaves, 0);
		this.setBlock(world, i + 15, j + 45, k + 13, Blocks.leaves, 0);
		this.setBlock(world, i + 15, j + 46, k + 2, Blocks.leaves, 0);
		this.setBlock(world, i + 15, j + 46, k + 3, Blocks.leaves, 0);
		this.setBlock(world, i + 15, j + 46, k + 4, Blocks.leaves, 0);
		this.setBlock(world, i + 15, j + 46, k + 5, Blocks.leaves, 0);
		this.setBlock(world, i + 15, j + 46, k + 6, Blocks.leaves, 0);
		this.setBlock(world, i + 15, j + 46, k + 7, Blocks.leaves, 0);
		this.setBlock(world, i + 15, j + 46, k + 8, Blocks.leaves, 0);
		this.setBlock(world, i + 15, j + 46, k + 9, Blocks.leaves, 0);
		this.setBlock(world, i + 15, j + 46, k + 10, Blocks.leaves, 0);
		this.setBlock(world, i + 15, j + 46, k + 11, Blocks.log, 1);
		this.setBlock(world, i + 15, j + 46, k + 12, Blocks.leaves, 0);
		this.setBlock(world, i + 15, j + 46, k + 13, Blocks.leaves, 0);
		this.setBlock(world, i + 15, j + 47, k + 1, Blocks.leaves, 0);
		this.setBlock(world, i + 15, j + 47, k + 2, Blocks.leaves, 0);
		this.setBlock(world, i + 15, j + 47, k + 3, Blocks.leaves, 0);
		this.setBlock(world, i + 15, j + 47, k + 4, Blocks.leaves, 0);
		this.setBlock(world, i + 15, j + 47, k + 5, Blocks.leaves, 0);
		this.setBlock(world, i + 15, j + 47, k + 6, Blocks.leaves, 0);
		this.setBlock(world, i + 15, j + 47, k + 7, Blocks.leaves, 0);
		this.setBlock(world, i + 15, j + 47, k + 8, Blocks.log, 1);
		this.setBlock(world, i + 15, j + 47, k + 9, Blocks.leaves, 0);
		this.setBlock(world, i + 15, j + 47, k + 10, Blocks.leaves, 0);
		this.setBlock(world, i + 15, j + 47, k + 11, Blocks.leaves, 0);
		this.setBlock(world, i + 15, j + 47, k + 12, Blocks.leaves, 0);
		this.setBlock(world, i + 15, j + 47, k + 13, Blocks.log, 1);
		this.setBlock(world, i + 15, j + 47, k + 14, Blocks.leaves, 0);
		this.setBlock(world, i + 15, j + 47, k + 26, Blocks.leaves, 0);
		this.setBlock(world, i + 15, j + 47, k + 27, Blocks.leaves, 0);
		this.setBlock(world, i + 15, j + 47, k + 28, Blocks.leaves, 0);
		this.setBlock(world, i + 15, j + 47, k + 29, Blocks.leaves, 0);
		this.setBlock(world, i + 15, j + 47, k + 30, Blocks.leaves, 0);
		this.setBlock(world, i + 15, j + 47, k + 32, Blocks.leaves, 0);
		this.setBlock(world, i + 15, j + 48, k + 2, Blocks.leaves, 0);
		this.setBlock(world, i + 15, j + 48, k + 3, Blocks.leaves, 0);
		this.setBlock(world, i + 15, j + 48, k + 4, Blocks.leaves, 0);
		this.setBlock(world, i + 15, j + 48, k + 5, Blocks.leaves, 0);
		this.setBlock(world, i + 15, j + 48, k + 6, Blocks.leaves, 0);
		this.setBlock(world, i + 15, j + 48, k + 7, Blocks.leaves, 0);
		this.setBlock(world, i + 15, j + 48, k + 8, Blocks.leaves, 0);
		this.setBlock(world, i + 15, j + 48, k + 9, Blocks.log, 1);
		this.setBlock(world, i + 15, j + 48, k + 10, Blocks.log, 1);
		this.setBlock(world, i + 15, j + 48, k + 11, Blocks.leaves, 0);
		this.setBlock(world, i + 15, j + 48, k + 13, Blocks.leaves, 0);
		this.setBlock(world, i + 15, j + 48, k + 21, Blocks.leaves, 0);
		this.setBlock(world, i + 15, j + 48, k + 22, Blocks.leaves, 0);
		this.setBlock(world, i + 15, j + 48, k + 23, Blocks.leaves, 0);
		this.setBlock(world, i + 15, j + 48, k + 24, Blocks.leaves, 0);
		this.setBlock(world, i + 15, j + 48, k + 25, Blocks.leaves, 0);
		this.setBlock(world, i + 15, j + 48, k + 26, Blocks.leaves, 0);
		this.setBlock(world, i + 15, j + 48, k + 27, Blocks.leaves, 0);
		this.setBlock(world, i + 15, j + 48, k + 28, Blocks.leaves, 0);
		this.setBlock(world, i + 15, j + 48, k + 29, Blocks.leaves, 0);
		this.setBlock(world, i + 15, j + 48, k + 30, Blocks.log, 1);
		this.setBlock(world, i + 15, j + 48, k + 31, Blocks.leaves, 0);
		this.setBlock(world, i + 15, j + 48, k + 32, Blocks.leaves, 0);
		this.setBlock(world, i + 15, j + 48, k + 33, Blocks.leaves, 0);
		this.setBlock(world, i + 15, j + 48, k + 34, Blocks.leaves, 0);
		this.setBlock(world, i + 15, j + 49, k + 3, Blocks.leaves, 0);
		this.setBlock(world, i + 15, j + 49, k + 8, Blocks.leaves, 0);
		this.setBlock(world, i + 15, j + 49, k + 9, Blocks.leaves, 0);
		this.setBlock(world, i + 15, j + 49, k + 10, Blocks.leaves, 0);
		this.setBlock(world, i + 15, j + 49, k + 19, Blocks.leaves, 0);
		this.setBlock(world, i + 15, j + 49, k + 20, Blocks.log, 1);
		this.setBlock(world, i + 15, j + 49, k + 21, Blocks.leaves, 0);
		this.setBlock(world, i + 15, j + 49, k + 22, Blocks.leaves, 0);
		this.setBlock(world, i + 15, j + 49, k + 23, Blocks.log, 1);
		this.setBlock(world, i + 15, j + 49, k + 24, Blocks.leaves, 0);
		this.setBlock(world, i + 15, j + 49, k + 25, Blocks.leaves, 0);
		this.setBlock(world, i + 15, j + 49, k + 26, Blocks.log, 1);
		this.setBlock(world, i + 15, j + 49, k + 27, Blocks.leaves, 0);
		this.setBlock(world, i + 15, j + 49, k + 28, Blocks.leaves, 0);
		this.setBlock(world, i + 15, j + 49, k + 29, Blocks.leaves, 0);
		this.setBlock(world, i + 15, j + 49, k + 30, Blocks.leaves, 0);
		this.setBlock(world, i + 15, j + 49, k + 31, Blocks.leaves, 0);
		this.setBlock(world, i + 15, j + 49, k + 32, Blocks.log, 1);
		this.setBlock(world, i + 15, j + 49, k + 33, Blocks.leaves, 0);
		this.setBlock(world, i + 15, j + 49, k + 34, Blocks.leaves, 0);
		this.setBlock(world, i + 15, j + 49, k + 35, Blocks.leaves, 0);
		this.setBlock(world, i + 15, j + 50, k + 19, Blocks.leaves, 0);
		this.setBlock(world, i + 15, j + 50, k + 20, Blocks.leaves, 0);
		this.setBlock(world, i + 15, j + 50, k + 21, Blocks.leaves, 0);
		this.setBlock(world, i + 15, j + 50, k + 22, Blocks.leaves, 0);
		this.setBlock(world, i + 15, j + 50, k + 23, Blocks.leaves, 0);
		this.setBlock(world, i + 15, j + 50, k + 24, Blocks.leaves, 0);
		this.setBlock(world, i + 15, j + 50, k + 25, Blocks.leaves, 0);
		this.setBlock(world, i + 15, j + 50, k + 26, Blocks.leaves, 0);
		this.setBlock(world, i + 15, j + 50, k + 27, Blocks.leaves, 0);
		this.setBlock(world, i + 15, j + 50, k + 28, Blocks.leaves, 0);
		this.setBlock(world, i + 15, j + 50, k + 29, Blocks.leaves, 0);
		this.setBlock(world, i + 15, j + 50, k + 30, Blocks.log, 1);
		this.setBlock(world, i + 15, j + 50, k + 31, Blocks.leaves, 0);
		this.setBlock(world, i + 15, j + 50, k + 32, Blocks.leaves, 0);
		this.setBlock(world, i + 15, j + 50, k + 33, Blocks.leaves, 0);
		this.setBlock(world, i + 15, j + 50, k + 34, Blocks.leaves, 0);
		this.setBlock(world, i + 15, j + 51, k + 19, Blocks.leaves, 0);
		this.setBlock(world, i + 15, j + 51, k + 20, Blocks.leaves, 0);
		this.setBlock(world, i + 15, j + 51, k + 21, Blocks.leaves, 0);
		this.setBlock(world, i + 15, j + 51, k + 22, Blocks.leaves, 0);
		this.setBlock(world, i + 15, j + 51, k + 23, Blocks.leaves, 0);
		this.setBlock(world, i + 15, j + 51, k + 24, Blocks.leaves, 0);
		this.setBlock(world, i + 15, j + 51, k + 25, Blocks.leaves, 0);
		this.setBlock(world, i + 15, j + 51, k + 26, Blocks.leaves, 0);
		this.setBlock(world, i + 15, j + 51, k + 27, Blocks.leaves, 0);
		this.setBlock(world, i + 15, j + 51, k + 28, Blocks.leaves, 0);
		this.setBlock(world, i + 15, j + 51, k + 29, Blocks.leaves, 0);
		this.setBlock(world, i + 15, j + 51, k + 30, Blocks.leaves, 0);
		this.setBlock(world, i + 15, j + 51, k + 32, Blocks.leaves, 0);
		this.setBlock(world, i + 15, j + 52, k + 21, Blocks.leaves, 0);
		this.setBlock(world, i + 15, j + 52, k + 22, Blocks.leaves, 0);
		this.setBlock(world, i + 15, j + 52, k + 23, Blocks.leaves, 0);
		this.setBlock(world, i + 15, j + 52, k + 24, Blocks.leaves, 0);
		this.setBlock(world, i + 15, j + 52, k + 25, Blocks.leaves, 0);
		this.setBlock(world, i + 16, j + 38, k + 19, Blocks.log, 1);
		this.setBlock(world, i + 16, j + 38, k + 20, Blocks.log, 1);
		this.setBlock(world, i + 16, j + 38, k + 21, Blocks.log, 1);
		this.setBlock(world, i + 16, j + 39, k + 19, Blocks.log, 1);
		this.setBlock(world, i + 16, j + 39, k + 20, Blocks.log, 1);
		this.setBlock(world, i + 16, j + 39, k + 21, Blocks.log, 1);
		this.setBlock(world, i + 16, j + 39, k + 22, Blocks.log, 1);
		this.setBlock(world, i + 16, j + 40, k + 19, Blocks.log, 1);
		this.setBlock(world, i + 16, j + 40, k + 20, Blocks.log, 1);
		this.setBlock(world, i + 16, j + 40, k + 21, Blocks.log, 1);
		this.setBlock(world, i + 16, j + 40, k + 22, Blocks.log, 1);
		this.setBlock(world, i + 16, j + 40, k + 23, Blocks.log, 1);
		this.setBlock(world, i + 16, j + 41, k + 20, Blocks.log, 1);
		this.setBlock(world, i + 16, j + 41, k + 21, Blocks.log, 1);
		this.setBlock(world, i + 16, j + 41, k + 22, Blocks.log, 1);
		this.setBlock(world, i + 16, j + 41, k + 23, Blocks.log, 1);
		this.setBlock(world, i + 16, j + 42, k + 7, Blocks.leaves, 0);
		this.setBlock(world, i + 16, j + 42, k + 21, Blocks.log, 1);
		this.setBlock(world, i + 16, j + 42, k + 22, Blocks.log, 1);
		this.setBlock(world, i + 16, j + 42, k + 23, Blocks.log, 1);
		this.setBlock(world, i + 16, j + 43, k + 5, Blocks.leaves, 0);
		this.setBlock(world, i + 16, j + 43, k + 6, Blocks.leaves, 0);
		this.setBlock(world, i + 16, j + 43, k + 7, Blocks.leaves, 0);
		this.setBlock(world, i + 16, j + 43, k + 8, Blocks.leaves, 0);
		this.setBlock(world, i + 16, j + 43, k + 9, Blocks.leaves, 0);
		this.setBlock(world, i + 16, j + 44, k + 3, Blocks.leaves, 0);
		this.setBlock(world, i + 16, j + 44, k + 4, Blocks.leaves, 0);
		this.setBlock(world, i + 16, j + 44, k + 5, Blocks.leaves, 0);
		this.setBlock(world, i + 16, j + 44, k + 6, Blocks.log, 1);
		this.setBlock(world, i + 16, j + 44, k + 7, Blocks.leaves, 0);
		this.setBlock(world, i + 16, j + 44, k + 8, Blocks.leaves, 0);
		this.setBlock(world, i + 16, j + 44, k + 9, Blocks.leaves, 0);
		this.setBlock(world, i + 16, j + 44, k + 10, Blocks.leaves, 0);
		this.setBlock(world, i + 16, j + 44, k + 12, Blocks.log, 1);
		this.setBlock(world, i + 16, j + 45, k + 3, Blocks.leaves, 0);
		this.setBlock(world, i + 16, j + 45, k + 4, Blocks.leaves, 0);
		this.setBlock(world, i + 16, j + 45, k + 5, Blocks.leaves, 0);
		this.setBlock(world, i + 16, j + 45, k + 6, Blocks.leaves, 0);
		this.setBlock(world, i + 16, j + 45, k + 7, Blocks.leaves, 0);
		this.setBlock(world, i + 16, j + 45, k + 8, Blocks.leaves, 0);
		this.setBlock(world, i + 16, j + 45, k + 9, Blocks.leaves, 0);
		this.setBlock(world, i + 16, j + 45, k + 10, Blocks.leaves, 0);
		this.setBlock(world, i + 16, j + 45, k + 11, Blocks.leaves, 0);
		this.setBlock(world, i + 16, j + 45, k + 12, Blocks.leaves, 0);
		this.setBlock(world, i + 16, j + 45, k + 13, Blocks.log, 1);
		this.setBlock(world, i + 16, j + 46, k + 2, Blocks.leaves, 0);
		this.setBlock(world, i + 16, j + 46, k + 3, Blocks.leaves, 0);
		this.setBlock(world, i + 16, j + 46, k + 4, Blocks.leaves, 0);
		this.setBlock(world, i + 16, j + 46, k + 5, Blocks.leaves, 0);
		this.setBlock(world, i + 16, j + 46, k + 6, Blocks.leaves, 0);
		this.setBlock(world, i + 16, j + 46, k + 7, Blocks.leaves, 0);
		this.setBlock(world, i + 16, j + 46, k + 8, Blocks.leaves, 0);
		this.setBlock(world, i + 16, j + 46, k + 9, Blocks.leaves, 0);
		this.setBlock(world, i + 16, j + 46, k + 10, Blocks.leaves, 0);
		this.setBlock(world, i + 16, j + 46, k + 11, Blocks.leaves, 0);
		this.setBlock(world, i + 16, j + 46, k + 12, Blocks.leaves, 0);
		this.setBlock(world, i + 16, j + 46, k + 13, Blocks.leaves, 0);
		this.setBlock(world, i + 16, j + 46, k + 14, Blocks.leaves, 0);
		this.setBlock(world, i + 16, j + 47, k + 2, Blocks.leaves, 0);
		this.setBlock(world, i + 16, j + 47, k + 3, Blocks.leaves, 0);
		this.setBlock(world, i + 16, j + 47, k + 4, Blocks.leaves, 0);
		this.setBlock(world, i + 16, j + 47, k + 5, Blocks.leaves, 0);
		this.setBlock(world, i + 16, j + 47, k + 6, Blocks.leaves, 0);
		this.setBlock(world, i + 16, j + 47, k + 7, Blocks.leaves, 0);
		this.setBlock(world, i + 16, j + 47, k + 8, Blocks.leaves, 0);
		this.setBlock(world, i + 16, j + 47, k + 9, Blocks.log, 1);
		this.setBlock(world, i + 16, j + 47, k + 10, Blocks.leaves, 0);
		this.setBlock(world, i + 16, j + 47, k + 11, Blocks.leaves, 0);
		this.setBlock(world, i + 16, j + 47, k + 12, Blocks.leaves, 0);
		this.setBlock(world, i + 16, j + 47, k + 13, Blocks.leaves, 0);
		this.setBlock(world, i + 16, j + 47, k + 26, Blocks.leaves, 0);
		this.setBlock(world, i + 16, j + 47, k + 27, Blocks.leaves, 0);
		this.setBlock(world, i + 16, j + 47, k + 28, Blocks.leaves, 0);
		this.setBlock(world, i + 16, j + 47, k + 29, Blocks.leaves, 0);
		this.setBlock(world, i + 16, j + 48, k + 2, Blocks.leaves, 0);
		this.setBlock(world, i + 16, j + 48, k + 3, Blocks.leaves, 0);
		this.setBlock(world, i + 16, j + 48, k + 4, Blocks.leaves, 0);
		this.setBlock(world, i + 16, j + 48, k + 5, Blocks.leaves, 0);
		this.setBlock(world, i + 16, j + 48, k + 6, Blocks.leaves, 0);
		this.setBlock(world, i + 16, j + 48, k + 7, Blocks.leaves, 0);
		this.setBlock(world, i + 16, j + 48, k + 8, Blocks.leaves, 0);
		this.setBlock(world, i + 16, j + 48, k + 9, Blocks.leaves, 0);
		this.setBlock(world, i + 16, j + 48, k + 10, Blocks.leaves, 0);
		this.setBlock(world, i + 16, j + 48, k + 11, Blocks.leaves, 0);
		this.setBlock(world, i + 16, j + 48, k + 12, Blocks.leaves, 0);
		this.setBlock(world, i + 16, j + 48, k + 21, Blocks.leaves, 0);
		this.setBlock(world, i + 16, j + 48, k + 22, Blocks.leaves, 0);
		this.setBlock(world, i + 16, j + 48, k + 23, Blocks.leaves, 0);
		this.setBlock(world, i + 16, j + 48, k + 24, Blocks.leaves, 0);
		this.setBlock(world, i + 16, j + 48, k + 25, Blocks.leaves, 0);
		this.setBlock(world, i + 16, j + 48, k + 26, Blocks.leaves, 0);
		this.setBlock(world, i + 16, j + 48, k + 27, Blocks.leaves, 0);
		this.setBlock(world, i + 16, j + 48, k + 28, Blocks.log, 1);
		this.setBlock(world, i + 16, j + 48, k + 29, Blocks.leaves, 0);
		this.setBlock(world, i + 16, j + 48, k + 30, Blocks.leaves, 0);
		this.setBlock(world, i + 16, j + 48, k + 31, Blocks.leaves, 0);
		this.setBlock(world, i + 16, j + 48, k + 32, Blocks.log, 1);
		this.setBlock(world, i + 16, j + 48, k + 33, Blocks.leaves, 0);
		this.setBlock(world, i + 16, j + 49, k + 7, Blocks.leaves, 0);
		this.setBlock(world, i + 16, j + 49, k + 8, Blocks.leaves, 0);
		this.setBlock(world, i + 16, j + 49, k + 9, Blocks.leaves, 0);
		this.setBlock(world, i + 16, j + 49, k + 10, Blocks.leaves, 0);
		this.setBlock(world, i + 16, j + 49, k + 11, Blocks.leaves, 0);
		this.setBlock(world, i + 16, j + 49, k + 19, Blocks.leaves, 0);
		this.setBlock(world, i + 16, j + 49, k + 20, Blocks.leaves, 0);
		this.setBlock(world, i + 16, j + 49, k + 21, Blocks.leaves, 0);
		this.setBlock(world, i + 16, j + 49, k + 22, Blocks.log, 1);
		this.setBlock(world, i + 16, j + 49, k + 23, Blocks.log, 1);
		this.setBlock(world, i + 16, j + 49, k + 24, Blocks.leaves, 0);
		this.setBlock(world, i + 16, j + 49, k + 25, Blocks.log, 1);
		this.setBlock(world, i + 16, j + 49, k + 26, Blocks.leaves, 0);
		this.setBlock(world, i + 16, j + 49, k + 27, Blocks.leaves, 0);
		this.setBlock(world, i + 16, j + 49, k + 28, Blocks.log, 1);
		this.setBlock(world, i + 16, j + 49, k + 29, Blocks.leaves, 0);
		this.setBlock(world, i + 16, j + 49, k + 30, Blocks.log, 1);
		this.setBlock(world, i + 16, j + 49, k + 31, Blocks.leaves, 0);
		this.setBlock(world, i + 16, j + 49, k + 32, Blocks.leaves, 0);
		this.setBlock(world, i + 16, j + 49, k + 33, Blocks.leaves, 0);
		this.setBlock(world, i + 16, j + 49, k + 34, Blocks.leaves, 0);
		this.setBlock(world, i + 16, j + 50, k + 18, Blocks.leaves, 0);
		this.setBlock(world, i + 16, j + 50, k + 19, Blocks.log, 1);
		this.setBlock(world, i + 16, j + 50, k + 20, Blocks.leaves, 0);
		this.setBlock(world, i + 16, j + 50, k + 21, Blocks.leaves, 0);
		this.setBlock(world, i + 16, j + 50, k + 22, Blocks.log, 1);
		this.setBlock(world, i + 16, j + 50, k + 23, Blocks.leaves, 0);
		this.setBlock(world, i + 16, j + 50, k + 24, Blocks.leaves, 0);
		this.setBlock(world, i + 16, j + 50, k + 25, Blocks.leaves, 0);
		this.setBlock(world, i + 16, j + 50, k + 26, Blocks.leaves, 0);
		this.setBlock(world, i + 16, j + 50, k + 27, Blocks.leaves, 0);
		this.setBlock(world, i + 16, j + 50, k + 28, Blocks.log, 1);
		this.setBlock(world, i + 16, j + 50, k + 29, Blocks.log, 1);
		this.setBlock(world, i + 16, j + 50, k + 30, Blocks.leaves, 0);
		this.setBlock(world, i + 16, j + 50, k + 31, Blocks.leaves, 0);
		this.setBlock(world, i + 16, j + 50, k + 32, Blocks.leaves, 0);
		this.setBlock(world, i + 16, j + 50, k + 33, Blocks.leaves, 0);
		this.setBlock(world, i + 16, j + 51, k + 19, Blocks.leaves, 0);
		this.setBlock(world, i + 16, j + 51, k + 20, Blocks.leaves, 0);
		this.setBlock(world, i + 16, j + 51, k + 21, Blocks.leaves, 0);
		this.setBlock(world, i + 16, j + 51, k + 22, Blocks.leaves, 0);
		this.setBlock(world, i + 16, j + 51, k + 23, Blocks.leaves, 0);
		this.setBlock(world, i + 16, j + 51, k + 24, Blocks.leaves, 0);

		generate2(world, rand, i, j, k);
		return true;
	}

	public boolean generate2(World world, Random rand, int i, int j, int k) {
		this.setBlock(world, i + 16, j + 51, k + 25, Blocks.leaves, 0);
		this.setBlock(world, i + 16, j + 51, k + 26, Blocks.leaves, 0);
		this.setBlock(world, i + 16, j + 51, k + 27, Blocks.leaves, 0);
		this.setBlock(world, i + 16, j + 51, k + 28, Blocks.leaves, 0);
		this.setBlock(world, i + 16, j + 51, k + 29, Blocks.leaves, 0);
		this.setBlock(world, i + 16, j + 51, k + 30, Blocks.leaves, 0);
		this.setBlock(world, i + 16, j + 52, k + 21, Blocks.leaves, 0);
		this.setBlock(world, i + 16, j + 52, k + 22, Blocks.leaves, 0);
		this.setBlock(world, i + 16, j + 52, k + 23, Blocks.leaves, 0);
		this.setBlock(world, i + 16, j + 52, k + 24, Blocks.leaves, 0);
		this.setBlock(world, i + 16, j + 52, k + 29, Blocks.leaves, 0);
		this.setBlock(world, i + 17, j + 37, k + 18, Blocks.log, 1);
		this.setBlock(world, i + 17, j + 37, k + 19, Blocks.log, 1);
		this.setBlock(world, i + 17, j + 37, k + 20, Blocks.log, 1);
		this.setBlock(world, i + 17, j + 38, k + 18, Blocks.log, 1);
		this.setBlock(world, i + 17, j + 38, k + 19, Blocks.log, 1);
		this.setBlock(world, i + 17, j + 38, k + 20, Blocks.log, 1);
		this.setBlock(world, i + 17, j + 38, k + 21, Blocks.log, 1);
		this.setBlock(world, i + 17, j + 39, k + 10, Blocks.log, 1);
		this.setBlock(world, i + 17, j + 39, k + 18, Blocks.log, 1);
		this.setBlock(world, i + 17, j + 39, k + 19, Blocks.log, 1);
