package com.DavidM1A2.AfraidOfTheDark.worldGeneration;
import java.util.Random;
import com.DavidM1A2.AfraidOfTheDark.utility.LogHelper;
import cpw.mods.fml.common.IWorldGenerator;
import net.minecraft.block.Block;
import net.minecraft.init.Blocks;
import net.minecraft.world.World;
import net.minecraft.world.chunk.IChunkProvider;
import net.minecraft.world.gen.feature.WorldGenerator;

public class BigTreeModel
{
	public BigTreeModel()
	{
	
	}

	private static void setBlock(World world, int x, int y, int z, Block block, int metadata)
	{
		Block b1 = world.getBlock(x, y, z);

		if(b1.isAir(world, x, y, z) || b1.isLeaves(world, x, y, z))
		{
			world.setBlock(x, y, z, block, metadata, 2);
		}
	}
	
	public static void generate(World world, Random rand, int i, int j, int k) 
	{
		k = k - 10;
		i = i - 10;

		setBlock(world, i + 0, j + 0, k + 36, Blocks.stone, 0);
		setBlock(world, i + 0, j + 0, k + 37, Blocks.stone, 0);
		setBlock(world, i + 0, j + 0, k + 38, Blocks.stone, 0);
		setBlock(world, i + 0, j + 1, k + 38, Blocks.stone, 0);
		setBlock(world, i + 0, j + 72, k + 66, Blocks.leaves, 12);
		setBlock(world, i + 0, j + 73, k + 67, Blocks.leaves, 12);
		setBlock(world, i + 0, j + 74, k + 68, Blocks.leaves, 12);
		setBlock(world, i + 1, j + 0, k + 37, Blocks.stone, 0);
		setBlock(world, i + 1, j + 0, k + 38, Blocks.stone, 0);
		setBlock(world, i + 1, j + 1, k + 38, Blocks.stone, 0);
		setBlock(world, i + 1, j + 70, k + 70, Blocks.leaves, 12);
		setBlock(world, i + 1, j + 70, k + 71, Blocks.leaves, 12);
		setBlock(world, i + 1, j + 70, k + 72, Blocks.leaves, 12);
		setBlock(world, i + 1, j + 71, k + 65, Blocks.leaves, 12);
		setBlock(world, i + 1, j + 71, k + 66, Blocks.leaves, 12);
		setBlock(world, i + 1, j + 71, k + 67, Blocks.leaves, 12);
		setBlock(world, i + 1, j + 71, k + 70, Blocks.leaves, 12);
		setBlock(world, i + 1, j + 71, k + 71, Blocks.leaves, 12);
		setBlock(world, i + 1, j + 71, k + 72, Blocks.leaves, 12);
		setBlock(world, i + 1, j + 72, k + 65, Blocks.leaves, 12);
		setBlock(world, i + 1, j + 72, k + 66, Blocks.leaves, 12);
		setBlock(world, i + 1, j + 72, k + 67, Blocks.leaves, 12);
		setBlock(world, i + 1, j + 72, k + 68, Blocks.leaves, 12);
		setBlock(world, i + 1, j + 72, k + 69, Blocks.leaves, 12);
		setBlock(world, i + 1, j + 72, k + 70, Blocks.leaves, 12);
		setBlock(world, i + 1, j + 72, k + 71, Blocks.leaves, 12);
		setBlock(world, i + 1, j + 72, k + 72, Blocks.leaves, 12);
		setBlock(world, i + 1, j + 73, k + 65, Blocks.leaves, 12);
		setBlock(world, i + 1, j + 73, k + 66, Blocks.leaves, 12);
		setBlock(world, i + 1, j + 73, k + 67, Blocks.leaves, 12);
		setBlock(world, i + 1, j + 73, k + 68, Blocks.leaves, 12);
		setBlock(world, i + 1, j + 73, k + 69, Blocks.leaves, 12);
		setBlock(world, i + 1, j + 73, k + 70, Blocks.leaves, 12);
		setBlock(world, i + 1, j + 73, k + 71, Blocks.leaves, 12);
		setBlock(world, i + 1, j + 73, k + 72, Blocks.leaves, 12);
		setBlock(world, i + 1, j + 73, k + 73, Blocks.leaves, 12);
		setBlock(world, i + 1, j + 74, k + 66, Blocks.leaves, 12);
		setBlock(world, i + 1, j + 74, k + 67, Blocks.leaves, 12);
		setBlock(world, i + 1, j + 74, k + 68, Blocks.leaves, 12);
		setBlock(world, i + 1, j + 74, k + 69, Blocks.leaves, 12);
		setBlock(world, i + 1, j + 74, k + 70, Blocks.leaves, 12);
		setBlock(world, i + 1, j + 74, k + 71, Blocks.leaves, 12);
		setBlock(world, i + 1, j + 74, k + 72, Blocks.leaves, 12);
		setBlock(world, i + 1, j + 74, k + 73, Blocks.leaves, 12);
		setBlock(world, i + 1, j + 75, k + 67, Blocks.leaves, 12);
		setBlock(world, i + 1, j + 75, k + 68, Blocks.leaves, 12);
		setBlock(world, i + 1, j + 75, k + 69, Blocks.leaves, 12);
		setBlock(world, i + 1, j + 75, k + 70, Blocks.leaves, 12);
		setBlock(world, i + 1, j + 75, k + 71, Blocks.leaves, 12);
		setBlock(world, i + 1, j + 75, k + 72, Blocks.leaves, 12);
		setBlock(world, i + 1, j + 75, k + 73, Blocks.leaves, 12);
		setBlock(world, i + 1, j + 76, k + 71, Blocks.leaves, 12);
		setBlock(world, i + 1, j + 76, k + 72, Blocks.leaves, 12);
		setBlock(world, i + 1, j + 76, k + 73, Blocks.leaves, 12);
		setBlock(world, i + 1, j + 77, k + 71, Blocks.leaves, 12);
		setBlock(world, i + 1, j + 77, k + 72, Blocks.leaves, 12);
		setBlock(world, i + 1, j + 77, k + 73, Blocks.leaves, 12);
		setBlock(world, i + 2, j + 0, k + 38, Blocks.stone, 0);
		setBlock(world, i + 2, j + 69, k + 70, Blocks.leaves, 12);
		setBlock(world, i + 2, j + 69, k + 71, Blocks.leaves, 12);
		setBlock(world, i + 2, j + 69, k + 72, Blocks.leaves, 12);
		setBlock(world, i + 2, j + 70, k + 70, Blocks.leaves, 12);
		setBlock(world, i + 2, j + 70, k + 71, Blocks.leaves, 12);
		setBlock(world, i + 2, j + 70, k + 72, Blocks.leaves, 12);
		setBlock(world, i + 2, j + 71, k + 65, Blocks.leaves, 12);
		setBlock(world, i + 2, j + 71, k + 66, Blocks.leaves, 12);
		setBlock(world, i + 2, j + 71, k + 67, Blocks.leaves, 12);
		setBlock(world, i + 2, j + 71, k + 68, Blocks.leaves, 12);
		setBlock(world, i + 2, j + 71, k + 69, Blocks.leaves, 12);
		setBlock(world, i + 2, j + 71, k + 70, Blocks.leaves, 12);
		setBlock(world, i + 2, j + 71, k + 71, Blocks.leaves, 12);
		setBlock(world, i + 2, j + 71, k + 72, Blocks.leaves, 12);
		setBlock(world, i + 2, j + 71, k + 73, Blocks.leaves, 12);
		setBlock(world, i + 2, j + 72, k + 64, Blocks.leaves, 12);
		setBlock(world, i + 2, j + 72, k + 65, Blocks.leaves, 12);
		setBlock(world, i + 2, j + 72, k + 66, Blocks.leaves, 12);
		setBlock(world, i + 2, j + 72, k + 67, Blocks.leaves, 12);
		setBlock(world, i + 2, j + 72, k + 68, Blocks.leaves, 12);
		setBlock(world, i + 2, j + 72, k + 69, Blocks.leaves, 12);
		setBlock(world, i + 2, j + 72, k + 70, Blocks.leaves, 12);
		setBlock(world, i + 2, j + 72, k + 71, Blocks.leaves, 12);
		setBlock(world, i + 2, j + 72, k + 72, Blocks.leaves, 12);
		setBlock(world, i + 2, j + 72, k + 73, Blocks.leaves, 12);
		setBlock(world, i + 2, j + 72, k + 74, Blocks.leaves, 12);
		setBlock(world, i + 2, j + 73, k + 63, Blocks.leaves, 12);
		setBlock(world, i + 2, j + 73, k + 65, Blocks.leaves, 12);
		setBlock(world, i + 2, j + 73, k + 66, Blocks.leaves, 12);
		setBlock(world, i + 2, j + 73, k + 67, Blocks.leaves, 12);
		setBlock(world, i + 2, j + 73, k + 68, Blocks.leaves, 12);
		setBlock(world, i + 2, j + 73, k + 69, Blocks.leaves, 12);
		setBlock(world, i + 2, j + 73, k + 70, Blocks.leaves, 12);
		setBlock(world, i + 2, j + 73, k + 71, Blocks.leaves, 12);
		setBlock(world, i + 2, j + 73, k + 72, Blocks.leaves, 12);
		setBlock(world, i + 2, j + 73, k + 73, Blocks.leaves, 12);
		setBlock(world, i + 2, j + 73, k + 74, Blocks.leaves, 12);
		setBlock(world, i + 2, j + 74, k + 66, Blocks.leaves, 12);
		setBlock(world, i + 2, j + 74, k + 67, Blocks.leaves, 12);
		setBlock(world, i + 2, j + 74, k + 68, Blocks.leaves, 12);
		setBlock(world, i + 2, j + 74, k + 69, Blocks.leaves, 12);
		setBlock(world, i + 2, j + 74, k + 70, Blocks.leaves, 12);
		setBlock(world, i + 2, j + 74, k + 71, Blocks.leaves, 12);
		setBlock(world, i + 2, j + 74, k + 72, Blocks.leaves, 12);
		setBlock(world, i + 2, j + 74, k + 73, Blocks.leaves, 12);
		setBlock(world, i + 2, j + 74, k + 74, Blocks.leaves, 12);
		setBlock(world, i + 2, j + 75, k + 67, Blocks.leaves, 12);
		setBlock(world, i + 2, j + 75, k + 68, Blocks.leaves, 12);
		setBlock(world, i + 2, j + 75, k + 69, Blocks.leaves, 12);
		setBlock(world, i + 2, j + 75, k + 70, Blocks.leaves, 12);
		setBlock(world, i + 2, j + 75, k + 71, Blocks.leaves, 12);
		setBlock(world, i + 2, j + 75, k + 72, Blocks.leaves, 12);
		setBlock(world, i + 2, j + 75, k + 73, Blocks.leaves, 12);
		setBlock(world, i + 2, j + 75, k + 74, Blocks.leaves, 12);
		setBlock(world, i + 2, j + 76, k + 68, Blocks.leaves, 12);
		setBlock(world, i + 2, j + 76, k + 71, Blocks.leaves, 12);
		setBlock(world, i + 2, j + 76, k + 72, Blocks.leaves, 12);
		setBlock(world, i + 2, j + 76, k + 73, Blocks.leaves, 12);
		setBlock(world, i + 2, j + 76, k + 74, Blocks.leaves, 12);
		setBlock(world, i + 2, j + 77, k + 71, Blocks.leaves, 12);
		setBlock(world, i + 2, j + 77, k + 72, Blocks.leaves, 12);
		setBlock(world, i + 2, j + 77, k + 73, Blocks.leaves, 12);
		setBlock(world, i + 3, j + 68, k + 69, Blocks.leaves, 12);
		setBlock(world, i + 3, j + 68, k + 70, Blocks.leaves, 12);
		setBlock(world, i + 3, j + 68, k + 71, Blocks.leaves, 12);
		setBlock(world, i + 3, j + 69, k + 69, Blocks.leaves, 12);
		setBlock(world, i + 3, j + 69, k + 70, Blocks.leaves, 12);
		setBlock(world, i + 3, j + 69, k + 71, Blocks.leaves, 12);
		setBlock(world, i + 3, j + 69, k + 72, Blocks.leaves, 12);
		setBlock(world, i + 3, j + 70, k + 69, Blocks.leaves, 12);
		setBlock(world, i + 3, j + 70, k + 70, Blocks.leaves, 12);
		setBlock(world, i + 3, j + 70, k + 71, Blocks.leaves, 12);
		setBlock(world, i + 3, j + 70, k + 72, Blocks.leaves, 12);
		setBlock(world, i + 3, j + 71, k + 65, Blocks.leaves, 12);
		setBlock(world, i + 3, j + 71, k + 66, Blocks.leaves, 12);
		setBlock(world, i + 3, j + 71, k + 67, Blocks.leaves, 12);
		setBlock(world, i + 3, j + 71, k + 68, Blocks.leaves, 12);
		setBlock(world, i + 3, j + 71, k + 69, Blocks.leaves, 12);
		setBlock(world, i + 3, j + 71, k + 70, Blocks.leaves, 12);
		setBlock(world, i + 3, j + 71, k + 71, Blocks.leaves, 12);
		setBlock(world, i + 3, j + 71, k + 72, Blocks.leaves, 12);
		setBlock(world, i + 3, j + 71, k + 73, Blocks.leaves, 12);
		setBlock(world, i + 3, j + 72, k + 62, Blocks.leaves, 12);
		setBlock(world, i + 3, j + 72, k + 63, Blocks.leaves, 12);
		setBlock(world, i + 3, j + 72, k + 64, Blocks.leaves, 12);
		setBlock(world, i + 3, j + 72, k + 65, Blocks.leaves, 12);
		setBlock(world, i + 3, j + 72, k + 66, Blocks.leaves, 12);
		setBlock(world, i + 3, j + 72, k + 67, Blocks.leaves, 12);
		setBlock(world, i + 3, j + 72, k + 68, Blocks.leaves, 12);
		setBlock(world, i + 3, j + 72, k + 69, Blocks.leaves, 12);
		setBlock(world, i + 3, j + 72, k + 70, Blocks.leaves, 12);
		setBlock(world, i + 3, j + 72, k + 71, Blocks.leaves, 12);
		setBlock(world, i + 3, j + 72, k + 72, Blocks.leaves, 12);
		setBlock(world, i + 3, j + 72, k + 73, Blocks.leaves, 12);
		setBlock(world, i + 3, j + 72, k + 74, Blocks.leaves, 12);
		setBlock(world, i + 3, j + 73, k + 62, Blocks.leaves, 12);
		setBlock(world, i + 3, j + 73, k + 63, Blocks.leaves, 12);
		setBlock(world, i + 3, j + 73, k + 64, Blocks.leaves, 12);
		setBlock(world, i + 3, j + 73, k + 65, Blocks.leaves, 12);
		setBlock(world, i + 3, j + 73, k + 66, Blocks.leaves, 12);
		setBlock(world, i + 3, j + 73, k + 67, Blocks.leaves, 12);
		setBlock(world, i + 3, j + 73, k + 68, Blocks.leaves, 12);
		setBlock(world, i + 3, j + 73, k + 69, Blocks.leaves, 12);
		setBlock(world, i + 3, j + 73, k + 70, Blocks.leaves, 12);
		setBlock(world, i + 3, j + 73, k + 71, Blocks.leaves, 12);
		setBlock(world, i + 3, j + 73, k + 72, Blocks.leaves, 12);
		setBlock(world, i + 3, j + 73, k + 73, Blocks.leaves, 12);
		setBlock(world, i + 3, j + 73, k + 74, Blocks.leaves, 12);
		setBlock(world, i + 3, j + 73, k + 75, Blocks.leaves, 12);
		setBlock(world, i + 3, j + 74, k + 62, Blocks.leaves, 12);
		setBlock(world, i + 3, j + 74, k + 63, Blocks.leaves, 12);
		setBlock(world, i + 3, j + 74, k + 64, Blocks.leaves, 12);
		setBlock(world, i + 3, j + 74, k + 65, Blocks.leaves, 12);
		setBlock(world, i + 3, j + 74, k + 66, Blocks.leaves, 12);
		setBlock(world, i + 3, j + 74, k + 67, Blocks.leaves, 12);
		setBlock(world, i + 3, j + 74, k + 68, Blocks.leaves, 12);
		setBlock(world, i + 3, j + 74, k + 69, Blocks.leaves, 12);
		setBlock(world, i + 3, j + 74, k + 70, Blocks.leaves, 12);
		setBlock(world, i + 3, j + 74, k + 71, Blocks.leaves, 12);
		setBlock(world, i + 3, j + 74, k + 72, Blocks.leaves, 12);
		setBlock(world, i + 3, j + 74, k + 73, Blocks.leaves, 12);
		setBlock(world, i + 3, j + 74, k + 74, Blocks.leaves, 12);
		setBlock(world, i + 3, j + 74, k + 75, Blocks.leaves, 12);
		setBlock(world, i + 3, j + 75, k + 67, Blocks.leaves, 12);
		setBlock(world, i + 3, j + 75, k + 68, Blocks.leaves, 12);
		setBlock(world, i + 3, j + 75, k + 69, Blocks.leaves, 12);
		setBlock(world, i + 3, j + 75, k + 70, Blocks.leaves, 12);
		setBlock(world, i + 3, j + 75, k + 71, Blocks.leaves, 12);
		setBlock(world, i + 3, j + 75, k + 72, Blocks.leaves, 12);
		setBlock(world, i + 3, j + 75, k + 73, Blocks.leaves, 12);
		setBlock(world, i + 3, j + 75, k + 74, Blocks.leaves, 12);
		setBlock(world, i + 3, j + 75, k + 75, Blocks.leaves, 12);
		setBlock(world, i + 3, j + 76, k + 71, Blocks.leaves, 12);
		setBlock(world, i + 3, j + 76, k + 72, Blocks.leaves, 12);
		setBlock(world, i + 3, j + 76, k + 73, Blocks.leaves, 12);
		setBlock(world, i + 3, j + 76, k + 74, Blocks.leaves, 12);
		setBlock(world, i + 3, j + 77, k + 71, Blocks.leaves, 12);
		setBlock(world, i + 3, j + 77, k + 72, Blocks.leaves, 12);
		setBlock(world, i + 3, j + 77, k + 73, Blocks.leaves, 12);
		setBlock(world, i + 4, j + 68, k + 69, Blocks.leaves, 12);
		setBlock(world, i + 4, j + 68, k + 70, Blocks.leaves, 12);
		setBlock(world, i + 4, j + 68, k + 71, Blocks.leaves, 12);
		setBlock(world, i + 4, j + 69, k + 68, Blocks.leaves, 12);
		setBlock(world, i + 4, j + 69, k + 69, Blocks.leaves, 12);
		setBlock(world, i + 4, j + 69, k + 70, Blocks.leaves, 12);
		setBlock(world, i + 4, j + 69, k + 71, Blocks.leaves, 12);
		setBlock(world, i + 4, j + 69, k + 72, Blocks.leaves, 12);
		setBlock(world, i + 4, j + 70, k + 66, Blocks.leaves, 12);
		setBlock(world, i + 4, j + 70, k + 67, Blocks.leaves, 12);
		setBlock(world, i + 4, j + 70, k + 68, Blocks.leaves, 12);
		setBlock(world, i + 4, j + 70, k + 69, Blocks.leaves, 12);
		setBlock(world, i + 4, j + 70, k + 70, Blocks.leaves, 12);
		setBlock(world, i + 4, j + 70, k + 71, Blocks.leaves, 12);
		setBlock(world, i + 4, j + 70, k + 72, Blocks.leaves, 12);
		setBlock(world, i + 4, j + 71, k + 65, Blocks.leaves, 12);
		setBlock(world, i + 4, j + 71, k + 66, Blocks.leaves, 12);
		setBlock(world, i + 4, j + 71, k + 67, Blocks.leaves, 12);
		setBlock(world, i + 4, j + 71, k + 68, Blocks.leaves, 12);
		setBlock(world, i + 4, j + 71, k + 69, Blocks.leaves, 4);
		setBlock(world, i + 4, j + 71, k + 70, Blocks.leaves, 12);
		setBlock(world, i + 4, j + 71, k + 71, Blocks.leaves, 12);
		setBlock(world, i + 4, j + 71, k + 72, Blocks.leaves, 12);
		setBlock(world, i + 4, j + 71, k + 73, Blocks.leaves, 12);
		setBlock(world, i + 4, j + 72, k + 62, Blocks.leaves, 12);
		setBlock(world, i + 4, j + 72, k + 63, Blocks.leaves, 12);
		setBlock(world, i + 4, j + 72, k + 64, Blocks.leaves, 12);
		setBlock(world, i + 4, j + 72, k + 65, Blocks.leaves, 12);
		setBlock(world, i + 4, j + 72, k + 66, Blocks.leaves, 12);
		setBlock(world, i + 4, j + 72, k + 67, Blocks.leaves, 12);
		setBlock(world, i + 4, j + 72, k + 68, Blocks.leaves, 12);
		setBlock(world, i + 4, j + 72, k + 69, Blocks.leaves, 4);
		setBlock(world, i + 4, j + 72, k + 70, Blocks.leaves, 4);
		setBlock(world, i + 4, j + 72, k + 71, Blocks.leaves, 12);
		setBlock(world, i + 4, j + 72, k + 72, Blocks.leaves, 12);
		setBlock(world, i + 4, j + 72, k + 73, Blocks.leaves, 12);
		setBlock(world, i + 4, j + 72, k + 74, Blocks.leaves, 12);
		setBlock(world, i + 4, j + 73, k + 61, Blocks.leaves, 12);
		setBlock(world, i + 4, j + 73, k + 62, Blocks.leaves, 12);
		setBlock(world, i + 4, j + 73, k + 63, Blocks.leaves, 12);
		setBlock(world, i + 4, j + 73, k + 64, Blocks.leaves, 12);
		setBlock(world, i + 4, j + 73, k + 65, Blocks.leaves, 12);
		setBlock(world, i + 4, j + 73, k + 66, Blocks.leaves, 12);
		setBlock(world, i + 4, j + 73, k + 67, Blocks.leaves, 12);
		setBlock(world, i + 4, j + 73, k + 68, Blocks.leaves, 12);
		setBlock(world, i + 4, j + 73, k + 69, Blocks.leaves, 4);
		setBlock(world, i + 4, j + 73, k + 70, Blocks.leaves, 12);
		setBlock(world, i + 4, j + 73, k + 71, Blocks.leaves, 12);
		setBlock(world, i + 4, j + 73, k + 72, Blocks.leaves, 12);
		setBlock(world, i + 4, j + 73, k + 73, Blocks.leaves, 12);
		setBlock(world, i + 4, j + 73, k + 74, Blocks.leaves, 12);
		setBlock(world, i + 4, j + 73, k + 75, Blocks.leaves, 12);
		setBlock(world, i + 4, j + 73, k + 76, Blocks.leaves, 12);
		setBlock(world, i + 4, j + 74, k + 61, Blocks.leaves, 12);
		setBlock(world, i + 4, j + 74, k + 62, Blocks.leaves, 12);
		setBlock(world, i + 4, j + 74, k + 63, Blocks.leaves, 12);
		setBlock(world, i + 4, j + 74, k + 64, Blocks.leaves, 12);
		setBlock(world, i + 4, j + 74, k + 65, Blocks.leaves, 12);
		setBlock(world, i + 4, j + 74, k + 66, Blocks.leaves, 12);
		setBlock(world, i + 4, j + 74, k + 67, Blocks.leaves, 12);
		setBlock(world, i + 4, j + 74, k + 68, Blocks.leaves, 12);
		setBlock(world, i + 4, j + 74, k + 69, Blocks.leaves, 4);
		setBlock(world, i + 4, j + 74, k + 70, Blocks.leaves, 12);
		setBlock(world, i + 4, j + 74, k + 71, Blocks.leaves, 12);
		setBlock(world, i + 4, j + 74, k + 72, Blocks.leaves, 12);
		setBlock(world, i + 4, j + 74, k + 73, Blocks.leaves, 12);
		setBlock(world, i + 4, j + 74, k + 74, Blocks.leaves, 12);
		setBlock(world, i + 4, j + 74, k + 75, Blocks.leaves, 12);
		setBlock(world, i + 4, j + 74, k + 76, Blocks.leaves, 12);
		setBlock(world, i + 4, j + 74, k + 77, Blocks.leaves, 12);
		setBlock(world, i + 4, j + 75, k + 61, Blocks.leaves, 12);
		setBlock(world, i + 4, j + 75, k + 62, Blocks.leaves, 12);
		setBlock(world, i + 4, j + 75, k + 63, Blocks.leaves, 12);
		setBlock(world, i + 4, j + 75, k + 69, Blocks.leaves, 4);
		setBlock(world, i + 4, j + 75, k + 70, Blocks.leaves, 4);
		setBlock(world, i + 4, j + 75, k + 71, Blocks.leaves, 12);
		setBlock(world, i + 4, j + 75, k + 72, Blocks.leaves, 12);
		setBlock(world, i + 4, j + 75, k + 73, Blocks.leaves, 12);
		setBlock(world, i + 4, j + 75, k + 74, Blocks.leaves, 12);
		setBlock(world, i + 4, j + 75, k + 75, Blocks.leaves, 12);
		setBlock(world, i + 4, j + 75, k + 76, Blocks.leaves, 12);
		setBlock(world, i + 4, j + 75, k + 77, Blocks.leaves, 12);
		setBlock(world, i + 4, j + 76, k + 72, Blocks.leaves, 12);
		setBlock(world, i + 4, j + 76, k + 73, Blocks.leaves, 12);
		setBlock(world, i + 4, j + 76, k + 74, Blocks.leaves, 12);
		setBlock(world, i + 4, j + 76, k + 76, Blocks.leaves, 12);
		setBlock(world, i + 4, j + 76, k + 77, Blocks.leaves, 12);
		setBlock(world, i + 4, j + 76, k + 78, Blocks.leaves, 12);
		setBlock(world, i + 4, j + 76, k + 79, Blocks.leaves, 12);
		setBlock(world, i + 5, j + 67, k + 70, Blocks.leaves, 12);
		setBlock(world, i + 5, j + 67, k + 71, Blocks.leaves, 12);
		setBlock(world, i + 5, j + 67, k + 73, Blocks.leaves, 12);
		setBlock(world, i + 5, j + 68, k + 68, Blocks.leaves, 12);
		setBlock(world, i + 5, j + 68, k + 69, Blocks.leaves, 12);
		setBlock(world, i + 5, j + 68, k + 70, Blocks.leaves, 12);
		setBlock(world, i + 5, j + 68, k + 71, Blocks.leaves, 12);
		setBlock(world, i + 5, j + 69, k + 67, Blocks.leaves, 12);
		setBlock(world, i + 5, j + 69, k + 68, Blocks.leaves, 12);
		setBlock(world, i + 5, j + 69, k + 69, Blocks.leaves, 12);
		setBlock(world, i + 5, j + 69, k + 70, Blocks.leaves, 12);
		setBlock(world, i + 5, j + 69, k + 71, Blocks.leaves, 12);
		setBlock(world, i + 5, j + 70, k + 65, Blocks.leaves, 12);
		setBlock(world, i + 5, j + 70, k + 66, Blocks.leaves, 12);
		setBlock(world, i + 5, j + 70, k + 67, Blocks.leaves, 12);
		setBlock(world, i + 5, j + 70, k + 68, Blocks.leaves, 12);
		setBlock(world, i + 5, j + 70, k + 69, Blocks.leaves, 12);
		setBlock(world, i + 5, j + 70, k + 70, Blocks.leaves, 12);
		setBlock(world, i + 5, j + 70, k + 71, Blocks.leaves, 12);
		setBlock(world, i + 5, j + 70, k + 72, Blocks.leaves, 12);
		setBlock(world, i + 5, j + 71, k + 65, Blocks.leaves, 12);
		setBlock(world, i + 5, j + 71, k + 66, Blocks.leaves, 12);
		setBlock(world, i + 5, j + 71, k + 67, Blocks.leaves, 12);
		setBlock(world, i + 5, j + 71, k + 68, Blocks.leaves, 12);
		setBlock(world, i + 5, j + 71, k + 69, Blocks.leaves, 12);
		setBlock(world, i + 5, j + 71, k + 70, Blocks.leaves, 12);
		setBlock(world, i + 5, j + 71, k + 71, Blocks.leaves, 12);
		setBlock(world, i + 5, j + 71, k + 72, Blocks.leaves, 12);
		setBlock(world, i + 5, j + 71, k + 73, Blocks.leaves, 12);
		setBlock(world, i + 5, j + 71, k + 74, Blocks.leaves, 12);
		setBlock(world, i + 5, j + 72, k + 62, Blocks.leaves, 12);
		setBlock(world, i + 5, j + 72, k + 63, Blocks.leaves, 12);
		setBlock(world, i + 5, j + 72, k + 64, Blocks.leaves, 12);
		setBlock(world, i + 5, j + 72, k + 65, Blocks.leaves, 12);
		setBlock(world, i + 5, j + 72, k + 66, Blocks.leaves, 12);
		setBlock(world, i + 5, j + 72, k + 67, Blocks.leaves, 12);
		setBlock(world, i + 5, j + 72, k + 68, Blocks.leaves, 12);
		setBlock(world, i + 5, j + 72, k + 69, Blocks.leaves, 12);
		setBlock(world, i + 5, j + 72, k + 70, Blocks.leaves, 12);
		setBlock(world, i + 5, j + 72, k + 71, Blocks.leaves, 12);
		setBlock(world, i + 5, j + 72, k + 72, Blocks.leaves, 12);
		setBlock(world, i + 5, j + 72, k + 73, Blocks.leaves, 12);
		setBlock(world, i + 5, j + 72, k + 74, Blocks.leaves, 12);
		setBlock(world, i + 5, j + 72, k + 75, Blocks.leaves, 12);
		setBlock(world, i + 5, j + 73, k + 61, Blocks.leaves, 12);
		setBlock(world, i + 5, j + 73, k + 62, Blocks.leaves, 12);
		setBlock(world, i + 5, j + 73, k + 63, Blocks.leaves, 12);
		setBlock(world, i + 5, j + 73, k + 64, Blocks.leaves, 12);
		setBlock(world, i + 5, j + 73, k + 65, Blocks.leaves, 12);
		setBlock(world, i + 5, j + 73, k + 66, Blocks.leaves, 12);
		setBlock(world, i + 5, j + 73, k + 67, Blocks.leaves, 12);
		setBlock(world, i + 5, j + 73, k + 68, Blocks.leaves, 12);
		setBlock(world, i + 5, j + 73, k + 69, Blocks.leaves, 12);
		setBlock(world, i + 5, j + 73, k + 70, Blocks.leaves, 12);
		setBlock(world, i + 5, j + 73, k + 71, Blocks.leaves, 12);
		setBlock(world, i + 5, j + 73, k + 72, Blocks.leaves, 12);
		setBlock(world, i + 5, j + 73, k + 73, Blocks.leaves, 12);
		setBlock(world, i + 5, j + 73, k + 74, Blocks.leaves, 12);
		setBlock(world, i + 5, j + 73, k + 75, Blocks.leaves, 12);
		setBlock(world, i + 5, j + 73, k + 76, Blocks.leaves, 12);
		setBlock(world, i + 5, j + 74, k + 61, Blocks.leaves, 12);
		setBlock(world, i + 5, j + 74, k + 62, Blocks.leaves, 12);
		setBlock(world, i + 5, j + 74, k + 63, Blocks.leaves, 12);
		setBlock(world, i + 5, j + 74, k + 64, Blocks.leaves, 12);
		setBlock(world, i + 5, j + 74, k + 65, Blocks.leaves, 12);
		setBlock(world, i + 5, j + 74, k + 66, Blocks.leaves, 12);
		setBlock(world, i + 5, j + 74, k + 67, Blocks.leaves, 12);
		setBlock(world, i + 5, j + 74, k + 68, Blocks.leaves, 12);
		setBlock(world, i + 5, j + 74, k + 69, Blocks.leaves, 12);
		setBlock(world, i + 5, j + 74, k + 70, Blocks.leaves, 12);
		setBlock(world, i + 5, j + 74, k + 71, Blocks.leaves, 12);
		setBlock(world, i + 5, j + 74, k + 72, Blocks.leaves, 12);
		setBlock(world, i + 5, j + 74, k + 73, Blocks.leaves, 12);
		setBlock(world, i + 5, j + 74, k + 74, Blocks.leaves, 12);
		setBlock(world, i + 5, j + 74, k + 75, Blocks.leaves, 12);
		setBlock(world, i + 5, j + 74, k + 76, Blocks.leaves, 12);
		setBlock(world, i + 5, j + 74, k + 77, Blocks.leaves, 12);
		setBlock(world, i + 5, j + 74, k + 78, Blocks.leaves, 12);
		setBlock(world, i + 5, j + 75, k + 61, Blocks.leaves, 12);
		setBlock(world, i + 5, j + 75, k + 62, Blocks.leaves, 12);
		setBlock(world, i + 5, j + 75, k + 63, Blocks.leaves, 12);
		setBlock(world, i + 5, j + 75, k + 67, Blocks.leaves, 12);
		setBlock(world, i + 5, j + 75, k + 68, Blocks.leaves, 12);
		setBlock(world, i + 5, j + 75, k + 69, Blocks.leaves, 12);
		setBlock(world, i + 5, j + 75, k + 70, Blocks.leaves, 12);
		setBlock(world, i + 5, j + 75, k + 71, Blocks.leaves, 12);
		setBlock(world, i + 5, j + 75, k + 72, Blocks.leaves, 12);
		setBlock(world, i + 5, j + 75, k + 73, Blocks.leaves, 12);
		setBlock(world, i + 5, j + 75, k + 74, Blocks.leaves, 12);
		setBlock(world, i + 5, j + 75, k + 75, Blocks.leaves, 12);
		setBlock(world, i + 5, j + 75, k + 76, Blocks.leaves, 12);
		setBlock(world, i + 5, j + 75, k + 77, Blocks.leaves, 12);
		setBlock(world, i + 5, j + 75, k + 78, Blocks.leaves, 12);
		setBlock(world, i + 5, j + 75, k + 79, Blocks.leaves, 12);
		setBlock(world, i + 5, j + 76, k + 76, Blocks.leaves, 12);
		setBlock(world, i + 5, j + 76, k + 77, Blocks.leaves, 12);
		setBlock(world, i + 5, j + 76, k + 78, Blocks.leaves, 12);
		setBlock(world, i + 5, j + 76, k + 79, Blocks.leaves, 12);
		setBlock(world, i + 5, j + 77, k + 77, Blocks.leaves, 12);
		setBlock(world, i + 5, j + 77, k + 78, Blocks.leaves, 12);
		setBlock(world, i + 6, j + 66, k + 70, Blocks.leaves, 12);
		setBlock(world, i + 6, j + 66, k + 71, Blocks.leaves, 12);
		setBlock(world, i + 6, j + 66, k + 72, Blocks.leaves, 12);
		setBlock(world, i + 6, j + 66, k + 73, Blocks.leaves, 12);
		setBlock(world, i + 6, j + 66, k + 74, Blocks.leaves, 12);
		setBlock(world, i + 6, j + 67, k + 69, Blocks.leaves, 12);
		setBlock(world, i + 6, j + 67, k + 70, Blocks.leaves, 12);
		setBlock(world, i + 6, j + 67, k + 71, Blocks.leaves, 12);
		setBlock(world, i + 6, j + 67, k + 72, Blocks.leaves, 12);
		setBlock(world, i + 6, j + 67, k + 73, Blocks.leaves, 12);
		setBlock(world, i + 6, j + 67, k + 74, Blocks.leaves, 12);
		setBlock(world, i + 6, j + 67, k + 75, Blocks.leaves, 12);
		setBlock(world, i + 6, j + 68, k + 67, Blocks.leaves, 12);
		setBlock(world, i + 6, j + 68, k + 68, Blocks.leaves, 12);
		setBlock(world, i + 6, j + 68, k + 69, Blocks.leaves, 12);
		setBlock(world, i + 6, j + 68, k + 70, Blocks.leaves, 12);
		setBlock(world, i + 6, j + 68, k + 71, Blocks.leaves, 12);
		setBlock(world, i + 6, j + 68, k + 72, Blocks.leaves, 12);
		setBlock(world, i + 6, j + 68, k + 73, Blocks.leaves, 12);
		setBlock(world, i + 6, j + 68, k + 74, Blocks.leaves, 12);
		setBlock(world, i + 6, j + 68, k + 75, Blocks.leaves, 12);
		setBlock(world, i + 6, j + 69, k + 66, Blocks.leaves, 12);
		setBlock(world, i + 6, j + 69, k + 67, Blocks.leaves, 12);
		setBlock(world, i + 6, j + 69, k + 68, Blocks.leaves, 12);
		setBlock(world, i + 6, j + 69, k + 69, Blocks.leaves, 12);
		setBlock(world, i + 6, j + 69, k + 70, Blocks.leaves, 12);
		setBlock(world, i + 6, j + 69, k + 71, Blocks.leaves, 12);
		setBlock(world, i + 6, j + 69, k + 72, Blocks.leaves, 12);
		setBlock(world, i + 6, j + 69, k + 73, Blocks.leaves, 12);
		setBlock(world, i + 6, j + 69, k + 74, Blocks.leaves, 12);
		setBlock(world, i + 6, j + 69, k + 75, Blocks.leaves, 12);
		setBlock(world, i + 6, j + 70, k + 65, Blocks.leaves, 12);
		setBlock(world, i + 6, j + 70, k + 66, Blocks.leaves, 12);
		setBlock(world, i + 6, j + 70, k + 67, Blocks.leaves, 12);
		setBlock(world, i + 6, j + 70, k + 68, Blocks.leaves, 12);
		setBlock(world, i + 6, j + 70, k + 69, Blocks.leaves, 12);
		setBlock(world, i + 6, j + 70, k + 70, Blocks.leaves, 12);
		setBlock(world, i + 6, j + 70, k + 71, Blocks.leaves, 12);
		setBlock(world, i + 6, j + 70, k + 72, Blocks.leaves, 12);
		setBlock(world, i + 6, j + 70, k + 73, Blocks.leaves, 12);
		setBlock(world, i + 6, j + 70, k + 74, Blocks.leaves, 12);
		setBlock(world, i + 6, j + 70, k + 75, Blocks.leaves, 12);
		setBlock(world, i + 6, j + 71, k + 65, Blocks.leaves, 12);
		setBlock(world, i + 6, j + 71, k + 66, Blocks.leaves, 12);
		setBlock(world, i + 6, j + 71, k + 67, Blocks.leaves, 12);
		setBlock(world, i + 6, j + 71, k + 68, Blocks.leaves, 12);
		setBlock(world, i + 6, j + 71, k + 69, Blocks.leaves, 12);
		setBlock(world, i + 6, j + 71, k + 70, Blocks.leaves, 12);
		setBlock(world, i + 6, j + 71, k + 71, Blocks.leaves, 12);
		setBlock(world, i + 6, j + 71, k + 72, Blocks.leaves, 12);
		setBlock(world, i + 6, j + 71, k + 73, Blocks.leaves, 12);
		setBlock(world, i + 6, j + 71, k + 74, Blocks.leaves, 12);
		setBlock(world, i + 6, j + 71, k + 75, Blocks.leaves, 12);
		setBlock(world, i + 6, j + 72, k + 64, Blocks.leaves, 12);
		setBlock(world, i + 6, j + 72, k + 65, Blocks.leaves, 12);
		setBlock(world, i + 6, j + 72, k + 66, Blocks.leaves, 12);
		setBlock(world, i + 6, j + 72, k + 67, Blocks.leaves, 12);
		setBlock(world, i + 6, j + 72, k + 68, Blocks.leaves, 12);
		setBlock(world, i + 6, j + 72, k + 69, Blocks.leaves, 12);
		setBlock(world, i + 6, j + 72, k + 70, Blocks.leaves, 12);
		setBlock(world, i + 6, j + 72, k + 71, Blocks.leaves, 12);
		setBlock(world, i + 6, j + 72, k + 72, Blocks.leaves, 12);
		setBlock(world, i + 6, j + 72, k + 73, Blocks.leaves, 12);
		setBlock(world, i + 6, j + 72, k + 74, Blocks.leaves, 12);
		setBlock(world, i + 6, j + 72, k + 75, Blocks.leaves, 12);
		setBlock(world, i + 6, j + 72, k + 76, Blocks.leaves, 12);
		setBlock(world, i + 6, j + 73, k + 61, Blocks.leaves, 12);
		setBlock(world, i + 6, j + 73, k + 62, Blocks.leaves, 12);
		setBlock(world, i + 6, j + 73, k + 63, Blocks.leaves, 12);
		setBlock(world, i + 6, j + 73, k + 64, Blocks.leaves, 12);
		setBlock(world, i + 6, j + 73, k + 65, Blocks.leaves, 12);
		setBlock(world, i + 6, j + 73, k + 66, Blocks.leaves, 12);
		setBlock(world, i + 6, j + 73, k + 67, Blocks.leaves, 12);
		setBlock(world, i + 6, j + 73, k + 68, Blocks.leaves, 12);
		setBlock(world, i + 6, j + 73, k + 69, Blocks.leaves, 12);
		setBlock(world, i + 6, j + 73, k + 70, Blocks.leaves, 12);
		setBlock(world, i + 6, j + 73, k + 71, Blocks.leaves, 12);
		setBlock(world, i + 6, j + 73, k + 72, Blocks.leaves, 12);
		setBlock(world, i + 6, j + 73, k + 73, Blocks.leaves, 12);
		setBlock(world, i + 6, j + 73, k + 74, Blocks.leaves, 12);
		setBlock(world, i + 6, j + 73, k + 75, Blocks.leaves, 12);
		setBlock(world, i + 6, j + 73, k + 76, Blocks.leaves, 12);
		setBlock(world, i + 6, j + 74, k + 61, Blocks.leaves, 12);
		setBlock(world, i + 6, j + 74, k + 62, Blocks.leaves, 12);
		setBlock(world, i + 6, j + 74, k + 63, Blocks.leaves, 12);
		setBlock(world, i + 6, j + 74, k + 64, Blocks.leaves, 12);
		setBlock(world, i + 6, j + 74, k + 65, Blocks.leaves, 12);
		setBlock(world, i + 6, j + 74, k + 66, Blocks.leaves, 12);
		setBlock(world, i + 6, j + 74, k + 67, Blocks.leaves, 12);
		setBlock(world, i + 6, j + 74, k + 68, Blocks.leaves, 12);
		setBlock(world, i + 6, j + 74, k + 69, Blocks.leaves, 12);
		setBlock(world, i + 6, j + 74, k + 70, Blocks.leaves, 12);
		setBlock(world, i + 6, j + 74, k + 71, Blocks.leaves, 12);
		setBlock(world, i + 6, j + 74, k + 72, Blocks.leaves, 12);
		setBlock(world, i + 6, j + 74, k + 73, Blocks.leaves, 12);
		setBlock(world, i + 6, j + 74, k + 74, Blocks.leaves, 12);
		setBlock(world, i + 6, j + 74, k + 75, Blocks.leaves, 12);
		setBlock(world, i + 6, j + 74, k + 76, Blocks.leaves, 12);
		setBlock(world, i + 6, j + 74, k + 77, Blocks.leaves, 12);
		setBlock(world, i + 6, j + 74, k + 78, Blocks.leaves, 12);
		setBlock(world, i + 6, j + 75, k + 61, Blocks.leaves, 12);
		setBlock(world, i + 6, j + 75, k + 62, Blocks.leaves, 12);
		setBlock(world, i + 6, j + 75, k + 63, Blocks.leaves, 12);
		setBlock(world, i + 6, j + 75, k + 64, Blocks.leaves, 12);
		setBlock(world, i + 6, j + 75, k + 65, Blocks.leaves, 12);
		setBlock(world, i + 6, j + 75, k + 66, Blocks.leaves, 12);
		setBlock(world, i + 6, j + 75, k + 67, Blocks.leaves, 12);
		setBlock(world, i + 6, j + 75, k + 68, Blocks.leaves, 12);
		setBlock(world, i + 6, j + 75, k + 69, Blocks.leaves, 12);
		setBlock(world, i + 6, j + 75, k + 70, Blocks.leaves, 12);
		setBlock(world, i + 6, j + 75, k + 71, Blocks.leaves, 12);
		setBlock(world, i + 6, j + 75, k + 72, Blocks.leaves, 12);
		setBlock(world, i + 6, j + 75, k + 73, Blocks.leaves, 12);
		setBlock(world, i + 6, j + 75, k + 74, Blocks.leaves, 12);
		setBlock(world, i + 6, j + 75, k + 75, Blocks.leaves, 12);
		setBlock(world, i + 6, j + 75, k + 76, Blocks.leaves, 12);
		setBlock(world, i + 6, j + 75, k + 77, Blocks.leaves, 12);
		setBlock(world, i + 6, j + 75, k + 78, Blocks.leaves, 12);
		setBlock(world, i + 6, j + 75, k + 79, Blocks.leaves, 12);
		setBlock(world, i + 6, j + 76, k + 76, Blocks.leaves, 12);
		setBlock(world, i + 6, j + 76, k + 77, Blocks.leaves, 12);
		setBlock(world, i + 6, j + 76, k + 78, Blocks.leaves, 12);
		setBlock(world, i + 6, j + 76, k + 79, Blocks.leaves, 12);
		setBlock(world, i + 6, j + 77, k + 77, Blocks.leaves, 12);
		setBlock(world, i + 6, j + 77, k + 78, Blocks.leaves, 12);
		setBlock(world, i + 7, j + 65, k + 71, Blocks.leaves, 12);
		setBlock(world, i + 7, j + 65, k + 73, Blocks.leaves, 12);
		setBlock(world, i + 7, j + 66, k + 70, Blocks.leaves, 12);
		setBlock(world, i + 7, j + 66, k + 71, Blocks.leaves, 12);
		setBlock(world, i + 7, j + 66, k + 72, Blocks.leaves, 12);
		setBlock(world, i + 7, j + 66, k + 73, Blocks.leaves, 12);
		setBlock(world, i + 7, j + 66, k + 74, Blocks.leaves, 12);
		setBlock(world, i + 7, j + 67, k + 68, Blocks.leaves, 12);
		setBlock(world, i + 7, j + 67, k + 69, Blocks.leaves, 12);
		setBlock(world, i + 7, j + 67, k + 70, Blocks.leaves, 12);
		setBlock(world, i + 7, j + 67, k + 71, Blocks.leaves, 12);
		setBlock(world, i + 7, j + 67, k + 72, Blocks.leaves, 12);
		setBlock(world, i + 7, j + 67, k + 73, Blocks.leaves, 12);
		setBlock(world, i + 7, j + 67, k + 74, Blocks.leaves, 12);
		setBlock(world, i + 7, j + 67, k + 75, Blocks.leaves, 12);
		setBlock(world, i + 7, j + 68, k + 66, Blocks.leaves, 12);
		setBlock(world, i + 7, j + 68, k + 67, Blocks.leaves, 12);
		setBlock(world, i + 7, j + 68, k + 68, Blocks.leaves, 12);
		setBlock(world, i + 7, j + 68, k + 69, Blocks.leaves, 12);
		setBlock(world, i + 7, j + 68, k + 70, Blocks.leaves, 12);
		setBlock(world, i + 7, j + 68, k + 71, Blocks.leaves, 12);
		setBlock(world, i + 7, j + 68, k + 72, Blocks.leaves, 12);
		setBlock(world, i + 7, j + 68, k + 73, Blocks.leaves, 12);
		setBlock(world, i + 7, j + 68, k + 74, Blocks.leaves, 12);
		setBlock(world, i + 7, j + 68, k + 75, Blocks.leaves, 12);
		setBlock(world, i + 7, j + 68, k + 76, Blocks.leaves, 12);
		setBlock(world, i + 7, j + 69, k + 65, Blocks.leaves, 12);
		setBlock(world, i + 7, j + 69, k + 66, Blocks.leaves, 12);
		setBlock(world, i + 7, j + 69, k + 67, Blocks.leaves, 12);
		setBlock(world, i + 7, j + 69, k + 68, Blocks.leaves, 12);
		setBlock(world, i + 7, j + 69, k + 69, Blocks.leaves, 12);
		setBlock(world, i + 7, j + 69, k + 70, Blocks.leaves, 12);
		setBlock(world, i + 7, j + 69, k + 71, Blocks.leaves, 12);
		setBlock(world, i + 7, j + 69, k + 72, Blocks.leaves, 12);
		setBlock(world, i + 7, j + 69, k + 73, Blocks.leaves, 12);
		setBlock(world, i + 7, j + 69, k + 74, Blocks.leaves, 12);
		setBlock(world, i + 7, j + 69, k + 75, Blocks.leaves, 12);
		setBlock(world, i + 7, j + 70, k + 65, Blocks.leaves, 12);
		setBlock(world, i + 7, j + 70, k + 66, Blocks.leaves, 12);
		setBlock(world, i + 7, j + 70, k + 67, Blocks.leaves, 12);
		setBlock(world, i + 7, j + 70, k + 68, Blocks.leaves, 12);
		setBlock(world, i + 7, j + 70, k + 69, Blocks.leaves, 12);
		setBlock(world, i + 7, j + 70, k + 70, Blocks.leaves, 12);
		setBlock(world, i + 7, j + 70, k + 71, Blocks.leaves, 12);
		setBlock(world, i + 7, j + 70, k + 72, Blocks.leaves, 12);
		setBlock(world, i + 7, j + 70, k + 73, Blocks.leaves, 12);
		setBlock(world, i + 7, j + 70, k + 74, Blocks.leaves, 12);
		setBlock(world, i + 7, j + 70, k + 75, Blocks.leaves, 12);
		setBlock(world, i + 7, j + 71, k + 65, Blocks.leaves, 12);
		setBlock(world, i + 7, j + 71, k + 66, Blocks.leaves, 12);
		setBlock(world, i + 7, j + 71, k + 67, Blocks.leaves, 12);
		setBlock(world, i + 7, j + 71, k + 68, Blocks.leaves, 12);
		setBlock(world, i + 7, j + 71, k + 69, Blocks.leaves, 12);
		setBlock(world, i + 7, j + 71, k + 70, Blocks.leaves, 12);
		setBlock(world, i + 7, j + 71, k + 71, Blocks.leaves, 12);
		setBlock(world, i + 7, j + 71, k + 72, Blocks.leaves, 12);
		setBlock(world, i + 7, j + 71, k + 73, Blocks.leaves, 12);
		setBlock(world, i + 7, j + 71, k + 74, Blocks.leaves, 12);
		setBlock(world, i + 7, j + 71, k + 75, Blocks.leaves, 12);
		setBlock(world, i + 7, j + 72, k + 64, Blocks.leaves, 12);
		setBlock(world, i + 7, j + 72, k + 65, Blocks.leaves, 12);
		setBlock(world, i + 7, j + 72, k + 66, Blocks.leaves, 12);
		setBlock(world, i + 7, j + 72, k + 67, Blocks.leaves, 12);
		setBlock(world, i + 7, j + 72, k + 68, Blocks.leaves, 12);
		setBlock(world, i + 7, j + 72, k + 69, Blocks.leaves, 12);
		setBlock(world, i + 7, j + 72, k + 70, Blocks.leaves, 12);
		setBlock(world, i + 7, j + 72, k + 71, Blocks.leaves, 12);
		setBlock(world, i + 7, j + 72, k + 72, Blocks.leaves, 12);
		setBlock(world, i + 7, j + 72, k + 73, Blocks.leaves, 12);
		setBlock(world, i + 7, j + 72, k + 74, Blocks.leaves, 12);
		setBlock(world, i + 7, j + 72, k + 75, Blocks.leaves, 12);
		setBlock(world, i + 7, j + 72, k + 76, Blocks.leaves, 12);
		setBlock(world, i + 7, j + 73, k + 62, Blocks.leaves, 12);
		setBlock(world, i + 7, j + 73, k + 63, Blocks.leaves, 12);
		setBlock(world, i + 7, j + 73, k + 64, Blocks.leaves, 12);
		setBlock(world, i + 7, j + 73, k + 65, Blocks.leaves, 12);
		setBlock(world, i + 7, j + 73, k + 66, Blocks.leaves, 12);
		setBlock(world, i + 7, j + 73, k + 67, Blocks.leaves, 12);
		setBlock(world, i + 7, j + 73, k + 68, Blocks.leaves, 12);
		setBlock(world, i + 7, j + 73, k + 69, Blocks.leaves, 12);
		setBlock(world, i + 7, j + 73, k + 70, Blocks.leaves, 12);
		setBlock(world, i + 7, j + 73, k + 71, Blocks.leaves, 12);
		setBlock(world, i + 7, j + 73, k + 72, Blocks.leaves, 12);
		setBlock(world, i + 7, j + 73, k + 73, Blocks.leaves, 12);
		setBlock(world, i + 7, j + 73, k + 74, Blocks.leaves, 12);
		setBlock(world, i + 7, j + 73, k + 75, Blocks.leaves, 12);
		setBlock(world, i + 7, j + 73, k + 76, Blocks.leaves, 12);
		setBlock(world, i + 7, j + 73, k + 77, Blocks.leaves, 12);
		setBlock(world, i + 7, j + 74, k + 61, Blocks.leaves, 12);
		setBlock(world, i + 7, j + 74, k + 62, Blocks.leaves, 12);
		setBlock(world, i + 7, j + 74, k + 63, Blocks.leaves, 12);
		setBlock(world, i + 7, j + 74, k + 64, Blocks.leaves, 12);
		setBlock(world, i + 7, j + 74, k + 65, Blocks.leaves, 12);
		setBlock(world, i + 7, j + 74, k + 66, Blocks.leaves, 12);
		setBlock(world, i + 7, j + 74, k + 67, Blocks.leaves, 12);
		setBlock(world, i + 7, j + 74, k + 68, Blocks.leaves, 12);
		setBlock(world, i + 7, j + 74, k + 69, Blocks.leaves, 12);
		setBlock(world, i + 7, j + 74, k + 70, Blocks.leaves, 12);
		setBlock(world, i + 7, j + 74, k + 71, Blocks.leaves, 12);
		setBlock(world, i + 7, j + 74, k + 72, Blocks.leaves, 12);
		setBlock(world, i + 7, j + 74, k + 73, Blocks.leaves, 12);
		setBlock(world, i + 7, j + 74, k + 74, Blocks.leaves, 12);
		setBlock(world, i + 7, j + 74, k + 75, Blocks.leaves, 12);
		setBlock(world, i + 7, j + 74, k + 76, Blocks.leaves, 12);
		setBlock(world, i + 7, j + 74, k + 77, Blocks.leaves, 12);
		setBlock(world, i + 7, j + 74, k + 78, Blocks.leaves, 12);
		setBlock(world, i + 7, j + 75, k + 62, Blocks.leaves, 12);
		setBlock(world, i + 7, j + 75, k + 63, Blocks.leaves, 12);
		setBlock(world, i + 7, j + 75, k + 64, Blocks.leaves, 12);
		setBlock(world, i + 7, j + 75, k + 65, Blocks.leaves, 12);
		setBlock(world, i + 7, j + 75, k + 66, Blocks.leaves, 12);
		setBlock(world, i + 7, j + 75, k + 67, Blocks.leaves, 12);
		setBlock(world, i + 7, j + 75, k + 68, Blocks.leaves, 12);
		setBlock(world, i + 7, j + 75, k + 69, Blocks.leaves, 12);
		setBlock(world, i + 7, j + 75, k + 70, Blocks.leaves, 12);
		setBlock(world, i + 7, j + 75, k + 71, Blocks.leaves, 12);
		setBlock(world, i + 7, j + 75, k + 72, Blocks.leaves, 12);
		setBlock(world, i + 7, j + 75, k + 73, Blocks.leaves, 12);
		setBlock(world, i + 7, j + 75, k + 74, Blocks.leaves, 12);
		setBlock(world, i + 7, j + 75, k + 75, Blocks.leaves, 12);
		setBlock(world, i + 7, j + 75, k + 76, Blocks.leaves, 12);
		setBlock(world, i + 7, j + 75, k + 77, Blocks.leaves, 12);
		setBlock(world, i + 7, j + 75, k + 78, Blocks.leaves, 12);
		setBlock(world, i + 7, j + 75, k + 79, Blocks.leaves, 12);
		setBlock(world, i + 7, j + 76, k + 64, Blocks.leaves, 4);
		setBlock(world, i + 7, j + 76, k + 65, Blocks.leaves, 4);
		setBlock(world, i + 7, j + 76, k + 66, Blocks.leaves, 4);
		setBlock(world, i + 7, j + 76, k + 67, Blocks.leaves, 4);
		setBlock(world, i + 7, j + 76, k + 68, Blocks.leaves, 12);
		setBlock(world, i + 7, j + 76, k + 69, Blocks.leaves, 12);
		setBlock(world, i + 7, j + 76, k + 70, Blocks.leaves, 4);
		setBlock(world, i + 7, j + 76, k + 77, Blocks.leaves, 12);
		setBlock(world, i + 7, j + 76, k + 78, Blocks.leaves, 12);
		setBlock(world, i + 7, j + 76, k + 79, Blocks.leaves, 12);
		setBlock(world, i + 7, j + 77, k + 70, Blocks.leaves, 4);
		setBlock(world, i + 7, j + 77, k + 77, Blocks.leaves, 12);
		setBlock(world, i + 7, j + 77, k + 78, Blocks.leaves, 12);
		setBlock(world, i + 8, j + 66, k + 69, Blocks.log, 1);
		setBlock(world, i + 8, j + 66, k + 70, Blocks.leaves, 12);
		setBlock(world, i + 8, j + 66, k + 71, Blocks.leaves, 12);
		setBlock(world, i + 8, j + 66, k + 72, Blocks.leaves, 12);
		setBlock(world, i + 8, j + 66, k + 73, Blocks.leaves, 12);
		setBlock(world, i + 8, j + 66, k + 74, Blocks.leaves, 12);
		setBlock(world, i + 8, j + 67, k + 65, Blocks.leaves, 12);
		setBlock(world, i + 8, j + 67, k + 66, Blocks.leaves, 12);
		setBlock(world, i + 8, j + 67, k + 67, Blocks.leaves, 12);
		setBlock(world, i + 8, j + 67, k + 68, Blocks.leaves, 12);
		setBlock(world, i + 8, j + 67, k + 69, Blocks.leaves, 12);
		setBlock(world, i + 8, j + 67, k + 70, Blocks.leaves, 12);
		setBlock(world, i + 8, j + 67, k + 71, Blocks.leaves, 12);
		setBlock(world, i + 8, j + 67, k + 72, Blocks.leaves, 12);
		setBlock(world, i + 8, j + 67, k + 73, Blocks.leaves, 12);
		setBlock(world, i + 8, j + 67, k + 74, Blocks.leaves, 12);
		setBlock(world, i + 8, j + 67, k + 75, Blocks.leaves, 12);
		setBlock(world, i + 8, j + 68, k + 65, Blocks.leaves, 12);
		setBlock(world, i + 8, j + 68, k + 66, Blocks.leaves, 12);
		setBlock(world, i + 8, j + 68, k + 67, Blocks.leaves, 12);
		setBlock(world, i + 8, j + 68, k + 68, Blocks.leaves, 12);
		setBlock(world, i + 8, j + 68, k + 69, Blocks.leaves, 12);
		setBlock(world, i + 8, j + 68, k + 70, Blocks.leaves, 12);
		setBlock(world, i + 8, j + 68, k + 71, Blocks.log, 1);
		setBlock(world, i + 8, j + 68, k + 72, Blocks.leaves, 12);
		setBlock(world, i + 8, j + 68, k + 73, Blocks.leaves, 12);
		setBlock(world, i + 8, j + 68, k + 74, Blocks.leaves, 12);
		setBlock(world, i + 8, j + 68, k + 75, Blocks.leaves, 12);
		setBlock(world, i + 8, j + 69, k + 65, Blocks.leaves, 12);
		setBlock(world, i + 8, j + 69, k + 66, Blocks.leaves, 12);
		setBlock(world, i + 8, j + 69, k + 67, Blocks.leaves, 12);
		setBlock(world, i + 8, j + 69, k + 68, Blocks.leaves, 12);
		setBlock(world, i + 8, j + 69, k + 69, Blocks.leaves, 12);
		setBlock(world, i + 8, j + 69, k + 70, Blocks.leaves, 12);
		setBlock(world, i + 8, j + 69, k + 71, Blocks.log, 1);
		setBlock(world, i + 8, j + 69, k + 72, Blocks.leaves, 12);
		setBlock(world, i + 8, j + 69, k + 73, Blocks.leaves, 12);
		setBlock(world, i + 8, j + 69, k + 74, Blocks.leaves, 12);
		setBlock(world, i + 8, j + 69, k + 75, Blocks.leaves, 12);
		setBlock(world, i + 8, j + 70, k + 64, Blocks.leaves, 12);
		setBlock(world, i + 8, j + 70, k + 65, Blocks.leaves, 12);
		setBlock(world, i + 8, j + 70, k + 66, Blocks.leaves, 12);
		setBlock(world, i + 8, j + 70, k + 67, Blocks.leaves, 12);
		setBlock(world, i + 8, j + 70, k + 68, Blocks.leaves, 12);
		setBlock(world, i + 8, j + 70, k + 69, Blocks.leaves, 12);
		setBlock(world, i + 8, j + 70, k + 70, Blocks.leaves, 12);
		setBlock(world, i + 8, j + 70, k + 71, Blocks.leaves, 12);
		setBlock(world, i + 8, j + 70, k + 72, Blocks.leaves, 12);
		setBlock(world, i + 8, j + 70, k + 73, Blocks.leaves, 12);
		setBlock(world, i + 8, j + 70, k + 74, Blocks.leaves, 12);
		setBlock(world, i + 8, j + 70, k + 75, Blocks.leaves, 12);
		setBlock(world, i + 8, j + 71, k + 63, Blocks.leaves, 12);
		setBlock(world, i + 8, j + 71, k + 64, Blocks.leaves, 12);
		setBlock(world, i + 8, j + 71, k + 65, Blocks.leaves, 12);
		setBlock(world, i + 8, j + 71, k + 66, Blocks.leaves, 12);
		setBlock(world, i + 8, j + 71, k + 67, Blocks.leaves, 12);
		setBlock(world, i + 8, j + 71, k + 68, Blocks.leaves, 12);
		setBlock(world, i + 8, j + 71, k + 69, Blocks.leaves, 12);
		setBlock(world, i + 8, j + 71, k + 70, Blocks.leaves, 12);
		setBlock(world, i + 8, j + 71, k + 71, Blocks.leaves, 12);
		setBlock(world, i + 8, j + 71, k + 72, Blocks.leaves, 12);
		setBlock(world, i + 8, j + 71, k + 73, Blocks.leaves, 12);
		setBlock(world, i + 8, j + 71, k + 74, Blocks.leaves, 12);
		setBlock(world, i + 8, j + 71, k + 75, Blocks.leaves, 12);
		setBlock(world, i + 8, j + 72, k + 61, Blocks.leaves, 12);
		setBlock(world, i + 8, j + 72, k + 62, Blocks.leaves, 12);
		setBlock(world, i + 8, j + 72, k + 63, Blocks.leaves, 12);
		setBlock(world, i + 8, j + 72, k + 64, Blocks.leaves, 12);
		setBlock(world, i + 8, j + 72, k + 65, Blocks.leaves, 12);
		setBlock(world, i + 8, j + 72, k + 66, Blocks.leaves, 12);
		setBlock(world, i + 8, j + 72, k + 67, Blocks.leaves, 12);
		setBlock(world, i + 8, j + 72, k + 68, Blocks.leaves, 12);
		setBlock(world, i + 8, j + 72, k + 69, Blocks.leaves, 12);
		setBlock(world, i + 8, j + 72, k + 70, Blocks.leaves, 12);
		setBlock(world, i + 8, j + 72, k + 71, Blocks.leaves, 12);
		setBlock(world, i + 8, j + 72, k + 72, Blocks.leaves, 12);
		setBlock(world, i + 8, j + 72, k + 73, Blocks.leaves, 12);
		setBlock(world, i + 8, j + 72, k + 74, Blocks.leaves, 12);
		setBlock(world, i + 8, j + 72, k + 75, Blocks.leaves, 12);
		setBlock(world, i + 8, j + 72, k + 76, Blocks.leaves, 12);
		setBlock(world, i + 8, j + 73, k + 61, Blocks.leaves, 12);
		setBlock(world, i + 8, j + 73, k + 62, Blocks.leaves, 12);
		setBlock(world, i + 8, j + 73, k + 63, Blocks.leaves, 12);
		setBlock(world, i + 8, j + 73, k + 64, Blocks.leaves, 12);
		setBlock(world, i + 8, j + 73, k + 65, Blocks.leaves, 12);
		setBlock(world, i + 8, j + 73, k + 66, Blocks.leaves, 12);
		setBlock(world, i + 8, j + 73, k + 67, Blocks.leaves, 12);
		setBlock(world, i + 8, j + 73, k + 68, Blocks.leaves, 12);
		setBlock(world, i + 8, j + 73, k + 69, Blocks.leaves, 12);
		setBlock(world, i + 8, j + 73, k + 70, Blocks.leaves, 12);
		setBlock(world, i + 8, j + 73, k + 71, Blocks.leaves, 12);
		setBlock(world, i + 8, j + 73, k + 72, Blocks.leaves, 12);
		setBlock(world, i + 8, j + 73, k + 73, Blocks.leaves, 12);
		setBlock(world, i + 8, j + 73, k + 74, Blocks.leaves, 12);
		setBlock(world, i + 8, j + 73, k + 75, Blocks.leaves, 12);
		setBlock(world, i + 8, j + 73, k + 76, Blocks.leaves, 12);
		setBlock(world, i + 8, j + 73, k + 77, Blocks.leaves, 12);
		setBlock(world, i + 8, j + 74, k + 61, Blocks.leaves, 12);
		setBlock(world, i + 8, j + 74, k + 62, Blocks.leaves, 12);
		setBlock(world, i + 8, j + 74, k + 63, Blocks.leaves, 12);
		setBlock(world, i + 8, j + 74, k + 64, Blocks.leaves, 12);
		setBlock(world, i + 8, j + 74, k + 65, Blocks.leaves, 12);
		setBlock(world, i + 8, j + 74, k + 66, Blocks.leaves, 12);
		setBlock(world, i + 8, j + 74, k + 67, Blocks.leaves, 12);
		setBlock(world, i + 8, j + 74, k + 68, Blocks.leaves, 12);
		setBlock(world, i + 8, j + 74, k + 69, Blocks.leaves, 12);
		setBlock(world, i + 8, j + 74, k + 70, Blocks.leaves, 12);
		setBlock(world, i + 8, j + 74, k + 71, Blocks.leaves, 12);
		setBlock(world, i + 8, j + 74, k + 72, Blocks.leaves, 12);
		setBlock(world, i + 8, j + 74, k + 73, Blocks.leaves, 12);
		setBlock(world, i + 8, j + 74, k + 74, Blocks.leaves, 12);
		setBlock(world, i + 8, j + 74, k + 75, Blocks.leaves, 12);
		setBlock(world, i + 8, j + 74, k + 76, Blocks.leaves, 12);
		setBlock(world, i + 8, j + 74, k + 77, Blocks.leaves, 12);
		setBlock(world, i + 8, j + 74, k + 78, Blocks.leaves, 12);
		setBlock(world, i + 8, j + 75, k + 62, Blocks.leaves, 12);
		setBlock(world, i + 8, j + 75, k + 63, Blocks.leaves, 12);
		setBlock(world, i + 8, j + 75, k + 64, Blocks.leaves, 12);
		setBlock(world, i + 8, j + 75, k + 65, Blocks.leaves, 12);
		setBlock(world, i + 8, j + 75, k + 66, Blocks.leaves, 12);
		setBlock(world, i + 8, j + 75, k + 67, Blocks.leaves, 12);
		setBlock(world, i + 8, j + 75, k + 68, Blocks.leaves, 12);
		setBlock(world, i + 8, j + 75, k + 69, Blocks.leaves, 12);
		setBlock(world, i + 8, j + 75, k + 70, Blocks.leaves, 12);
		setBlock(world, i + 8, j + 75, k + 71, Blocks.leaves, 12);
		setBlock(world, i + 8, j + 75, k + 72, Blocks.leaves, 12);
		setBlock(world, i + 8, j + 75, k + 73, Blocks.leaves, 12);
		setBlock(world, i + 8, j + 75, k + 74, Blocks.leaves, 12);
		setBlock(world, i + 8, j + 75, k + 75, Blocks.leaves, 12);
		setBlock(world, i + 8, j + 75, k + 76, Blocks.leaves, 12);
		setBlock(world, i + 8, j + 75, k + 77, Blocks.leaves, 12);
		setBlock(world, i + 8, j + 75, k + 78, Blocks.leaves, 12);
		setBlock(world, i + 8, j + 75, k + 79, Blocks.leaves, 12);
		setBlock(world, i + 8, j + 76, k + 69, Blocks.leaves, 12);
		setBlock(world, i + 8, j + 76, k + 70, Blocks.leaves, 4);
		setBlock(world, i + 8, j + 76, k + 76, Blocks.leaves, 12);
		setBlock(world, i + 8, j + 76, k + 77, Blocks.leaves, 12);
		setBlock(world, i + 8, j + 76, k + 78, Blocks.leaves, 12);
		setBlock(world, i + 8, j + 76, k + 79, Blocks.leaves, 12);
		setBlock(world, i + 8, j + 77, k + 77, Blocks.leaves, 12);
		setBlock(world, i + 8, j + 77, k + 78, Blocks.leaves, 12);
		setBlock(world, i + 9, j + 65, k + 68, Blocks.log, 1);
		setBlock(world, i + 9, j + 66, k + 67, Blocks.leaves, 12);
		setBlock(world, i + 9, j + 66, k + 68, Blocks.log, 1);
		setBlock(world, i + 9, j + 66, k + 69, Blocks.log, 1);
		setBlock(world, i + 9, j + 66, k + 70, Blocks.log, 1);
		setBlock(world, i + 9, j + 66, k + 71, Blocks.leaves, 12);
		setBlock(world, i + 9, j + 66, k + 72, Blocks.leaves, 12);
		setBlock(world, i + 9, j + 66, k + 73, Blocks.leaves, 12);
		setBlock(world, i + 9, j + 67, k + 65, Blocks.leaves, 12);
		setBlock(world, i + 9, j + 67, k + 66, Blocks.leaves, 12);
		setBlock(world, i + 9, j + 67, k + 67, Blocks.leaves, 12);
		setBlock(world, i + 9, j + 67, k + 68, Blocks.leaves, 12);
		setBlock(world, i + 9, j + 67, k + 69, Blocks.leaves, 12);
		setBlock(world, i + 9, j + 67, k + 70, Blocks.log, 1);
		setBlock(world, i + 9, j + 67, k + 71, Blocks.log, 1);
		setBlock(world, i + 9, j + 67, k + 72, Blocks.leaves, 12);
		setBlock(world, i + 9, j + 67, k + 73, Blocks.leaves, 12);
		setBlock(world, i + 9, j + 67, k + 74, Blocks.leaves, 12);
		setBlock(world, i + 9, j + 68, k + 65, Blocks.leaves, 12);
		setBlock(world, i + 9, j + 68, k + 66, Blocks.leaves, 12);
		setBlock(world, i + 9, j + 68, k + 67, Blocks.leaves, 12);
		setBlock(world, i + 9, j + 68, k + 68, Blocks.leaves, 12);
		setBlock(world, i + 9, j + 68, k + 69, Blocks.leaves, 12);
		setBlock(world, i + 9, j + 68, k + 70, Blocks.log, 1);
		setBlock(world, i + 9, j + 68, k + 71, Blocks.log, 1);
		setBlock(world, i + 9, j + 68, k + 72, Blocks.log, 1);
		setBlock(world, i + 9, j + 68, k + 73, Blocks.leaves, 12);
		setBlock(world, i + 9, j + 68, k + 74, Blocks.leaves, 12);
		setBlock(world, i + 9, j + 68, k + 75, Blocks.leaves, 12);
		setBlock(world, i + 9, j + 69, k + 51, Blocks.leaves, 12);
		setBlock(world, i + 9, j + 69, k + 52, Blocks.leaves, 12);
		setBlock(world, i + 9, j + 69, k + 53, Blocks.leaves, 12);
		setBlock(world, i + 9, j + 69, k + 65, Blocks.leaves, 12);
		setBlock(world, i + 9, j + 69, k + 66, Blocks.leaves, 12);
		setBlock(world, i + 9, j + 69, k + 67, Blocks.leaves, 12);
		setBlock(world, i + 9, j + 69, k + 68, Blocks.leaves, 12);
		setBlock(world, i + 9, j + 69, k + 69, Blocks.leaves, 12);
		setBlock(world, i + 9, j + 69, k + 70, Blocks.log, 1);
		setBlock(world, i + 9, j + 69, k + 71, Blocks.log, 1);
		setBlock(world, i + 9, j + 69, k + 72, Blocks.log, 1);
		setBlock(world, i + 9, j + 69, k + 73, Blocks.leaves, 12);
		setBlock(world, i + 9, j + 69, k + 74, Blocks.leaves, 12);
		setBlock(world, i + 9, j + 69, k + 75, Blocks.leaves, 12);
		setBlock(world, i + 9, j + 70, k + 51, Blocks.leaves, 12);
		setBlock(world, i + 9, j + 70, k + 52, Blocks.leaves, 12);
		setBlock(world, i + 9, j + 70, k + 53, Blocks.leaves, 12);
		setBlock(world, i + 9, j + 70, k + 64, Blocks.leaves, 12);
		setBlock(world, i + 9, j + 70, k + 65, Blocks.leaves, 12);
		setBlock(world, i + 9, j + 70, k + 66, Blocks.leaves, 12);
		setBlock(world, i + 9, j + 70, k + 67, Blocks.leaves, 12);
		setBlock(world, i + 9, j + 70, k + 68, Blocks.leaves, 12);
		setBlock(world, i + 9, j + 70, k + 69, Blocks.leaves, 12);
		setBlock(world, i + 9, j + 70, k + 70, Blocks.leaves, 12);
		setBlock(world, i + 9, j + 70, k + 71, Blocks.log, 1);
		setBlock(world, i + 9, j + 70, k + 72, Blocks.leaves, 12);
		setBlock(world, i + 9, j + 70, k + 73, Blocks.leaves, 12);
		setBlock(world, i + 9, j + 70, k + 74, Blocks.leaves, 12);
		setBlock(world, i + 9, j + 70, k + 75, Blocks.leaves, 12);
		setBlock(world, i + 9, j + 71, k + 51, Blocks.leaves, 12);
		setBlock(world, i + 9, j + 71, k + 52, Blocks.leaves, 12);
		setBlock(world, i + 9, j + 71, k + 53, Blocks.leaves, 12);
		setBlock(world, i + 9, j + 71, k + 62, Blocks.leaves, 12);
		setBlock(world, i + 9, j + 71, k + 63, Blocks.leaves, 12);
		setBlock(world, i + 9, j + 71, k + 64, Blocks.leaves, 12);
		setBlock(world, i + 9, j + 71, k + 65, Blocks.leaves, 12);
		setBlock(world, i + 9, j + 71, k + 66, Blocks.leaves, 12);
		setBlock(world, i + 9, j + 71, k + 67, Blocks.leaves, 12);
		setBlock(world, i + 9, j + 71, k + 68, Blocks.leaves, 12);
		setBlock(world, i + 9, j + 71, k + 69, Blocks.leaves, 12);
		setBlock(world, i + 9, j + 71, k + 70, Blocks.leaves, 12);
		setBlock(world, i + 9, j + 71, k + 71, Blocks.leaves, 12);
		setBlock(world, i + 9, j + 71, k + 72, Blocks.leaves, 12);
		setBlock(world, i + 9, j + 71, k + 73, Blocks.leaves, 12);
		setBlock(world, i + 9, j + 71, k + 74, Blocks.leaves, 12);
		setBlock(world, i + 9, j + 71, k + 75, Blocks.leaves, 12);
		setBlock(world, i + 9, j + 72, k + 61, Blocks.leaves, 12);
		setBlock(world, i + 9, j + 72, k + 62, Blocks.leaves, 12);
		setBlock(world, i + 9, j + 72, k + 63, Blocks.leaves, 12);
		setBlock(world, i + 9, j + 72, k + 64, Blocks.leaves, 12);
		setBlock(world, i + 9, j + 72, k + 65, Blocks.leaves, 12);
		setBlock(world, i + 9, j + 72, k + 66, Blocks.leaves, 12);
		setBlock(world, i + 9, j + 72, k + 67, Blocks.leaves, 12);
		setBlock(world, i + 9, j + 72, k + 68, Blocks.leaves, 12);
		setBlock(world, i + 9, j + 72, k + 69, Blocks.leaves, 12);
		setBlock(world, i + 9, j + 72, k + 70, Blocks.leaves, 12);
		setBlock(world, i + 9, j + 72, k + 71, Blocks.leaves, 12);
		setBlock(world, i + 9, j + 72, k + 72, Blocks.leaves, 12);
		setBlock(world, i + 9, j + 72, k + 73, Blocks.leaves, 12);
		setBlock(world, i + 9, j + 72, k + 74, Blocks.leaves, 12);
		setBlock(world, i + 9, j + 72, k + 75, Blocks.leaves, 12);
		setBlock(world, i + 9, j + 72, k + 76, Blocks.leaves, 12);
		setBlock(world, i + 9, j + 73, k + 60, Blocks.leaves, 12);
		setBlock(world, i + 9, j + 73, k + 61, Blocks.leaves, 12);
		setBlock(world, i + 9, j + 73, k + 62, Blocks.leaves, 12);
		setBlock(world, i + 9, j + 73, k + 63, Blocks.leaves, 12);
		setBlock(world, i + 9, j + 73, k + 64, Blocks.leaves, 12);
		setBlock(world, i + 9, j + 73, k + 65, Blocks.leaves, 12);
		setBlock(world, i + 9, j + 73, k + 66, Blocks.leaves, 12);
		setBlock(world, i + 9, j + 73, k + 67, Blocks.leaves, 12);
		setBlock(world, i + 9, j + 73, k + 68, Blocks.leaves, 12);
		setBlock(world, i + 9, j + 73, k + 69, Blocks.leaves, 12);
		setBlock(world, i + 9, j + 73, k + 70, Blocks.leaves, 12);
		setBlock(world, i + 9, j + 73, k + 71, Blocks.leaves, 12);
		setBlock(world, i + 9, j + 73, k + 72, Blocks.leaves, 12);
		setBlock(world, i + 9, j + 73, k + 73, Blocks.leaves, 12);
		setBlock(world, i + 9, j + 73, k + 74, Blocks.leaves, 12);
		setBlock(world, i + 9, j + 73, k + 75, Blocks.leaves, 12);
		setBlock(world, i + 9, j + 73, k + 76, Blocks.leaves, 12);
		setBlock(world, i + 9, j + 73, k + 77, Blocks.leaves, 12);
		setBlock(world, i + 9, j + 74, k + 61, Blocks.leaves, 12);
		setBlock(world, i + 9, j + 74, k + 62, Blocks.leaves, 12);
		setBlock(world, i + 9, j + 74, k + 63, Blocks.leaves, 12);
		setBlock(world, i + 9, j + 74, k + 64, Blocks.leaves, 12);
		setBlock(world, i + 9, j + 74, k + 66, Blocks.leaves, 12);
		setBlock(world, i + 9, j + 74, k + 67, Blocks.leaves, 12);
		setBlock(world, i + 9, j + 74, k + 68, Blocks.leaves, 12);
		setBlock(world, i + 9, j + 74, k + 69, Blocks.leaves, 12);
		setBlock(world, i + 9, j + 74, k + 70, Blocks.leaves, 12);
		setBlock(world, i + 9, j + 74, k + 71, Blocks.leaves, 12);
		setBlock(world, i + 9, j + 74, k + 72, Blocks.leaves, 12);
		setBlock(world, i + 9, j + 74, k + 73, Blocks.leaves, 12);
		setBlock(world, i + 9, j + 74, k + 74, Blocks.leaves, 12);
		setBlock(world, i + 9, j + 74, k + 75, Blocks.leaves, 12);
		setBlock(world, i + 9, j + 74, k + 76, Blocks.leaves, 12);
		setBlock(world, i + 9, j + 74, k + 77, Blocks.leaves, 12);
		setBlock(world, i + 9, j + 74, k + 78, Blocks.leaves, 12);
		setBlock(world, i + 9, j + 75, k + 62, Blocks.leaves, 12);
		setBlock(world, i + 9, j + 75, k + 63, Blocks.leaves, 12);
		setBlock(world, i + 9, j + 75, k + 64, Blocks.leaves, 12);
		setBlock(world, i + 9, j + 75, k + 66, Blocks.leaves, 12);
		setBlock(world, i + 9, j + 75, k + 67, Blocks.leaves, 12);
		setBlock(world, i + 9, j + 75, k + 68, Blocks.leaves, 12);
		setBlock(world, i + 9, j + 75, k + 69, Blocks.leaves, 12);
		setBlock(world, i + 9, j + 75, k + 70, Blocks.leaves, 12);
		setBlock(world, i + 9, j + 75, k + 71, Blocks.leaves, 12);
		setBlock(world, i + 9, j + 75, k + 72, Blocks.leaves, 12);
		setBlock(world, i + 9, j + 75, k + 73, Blocks.leaves, 12);
		setBlock(world, i + 9, j + 75, k + 74, Blocks.leaves, 12);
		setBlock(world, i + 9, j + 75, k + 75, Blocks.leaves, 12);
		setBlock(world, i + 9, j + 75, k + 76, Blocks.leaves, 12);
		setBlock(world, i + 9, j + 75, k + 77, Blocks.leaves, 12);
		setBlock(world, i + 9, j + 75, k + 78, Blocks.leaves, 12);
		setBlock(world, i + 9, j + 75, k + 79, Blocks.leaves, 12);
		setBlock(world, i + 9, j + 76, k + 76, Blocks.leaves, 12);
		setBlock(world, i + 9, j + 76, k + 77, Blocks.leaves, 12);
		setBlock(world, i + 9, j + 76, k + 78, Blocks.leaves, 12);
		setBlock(world, i + 9, j + 76, k + 79, Blocks.leaves, 12);
		setBlock(world, i + 10, j + 64, k + 67, Blocks.log, 1);
		setBlock(world, i + 10, j + 64, k + 68, Blocks.log, 1);
		setBlock(world, i + 10, j + 65, k + 67, Blocks.log, 1);
		setBlock(world, i + 10, j + 65, k + 68, Blocks.log, 1);
		setBlock(world, i + 10, j + 65, k + 69, Blocks.log, 1);
		setBlock(world, i + 10, j + 65, k + 70, Blocks.log, 1);
		setBlock(world, i + 10, j + 65, k + 72, Blocks.leaves, 12);
		setBlock(world, i + 10, j + 66, k + 67, Blocks.log, 1);
		setBlock(world, i + 10, j + 66, k + 68, Blocks.log, 1);
		setBlock(world, i + 10, j + 66, k + 69, Blocks.log, 1);
		setBlock(world, i + 10, j + 66, k + 70, Blocks.log, 1);
		setBlock(world, i + 10, j + 66, k + 71, Blocks.log, 1);
		setBlock(world, i + 10, j + 66, k + 72, Blocks.leaves, 12);
		setBlock(world, i + 10, j + 66, k + 73, Blocks.leaves, 12);
		setBlock(world, i + 10, j + 67, k + 65, Blocks.leaves, 12);
		setBlock(world, i + 10, j + 67, k + 66, Blocks.leaves, 12);
		setBlock(world, i + 10, j + 67, k + 67, Blocks.leaves, 12);
		setBlock(world, i + 10, j + 67, k + 68, Blocks.log, 1);
		setBlock(world, i + 10, j + 67, k + 69, Blocks.log, 1);
		setBlock(world, i + 10, j + 67, k + 70, Blocks.log, 1);
		setBlock(world, i + 10, j + 67, k + 71, Blocks.log, 1);
		setBlock(world, i + 10, j + 67, k + 72, Blocks.leaves, 12);
		setBlock(world, i + 10, j + 67, k + 73, Blocks.leaves, 12);
		setBlock(world, i + 10, j + 67, k + 74, Blocks.leaves, 12);
		setBlock(world, i + 10, j + 68, k + 65, Blocks.leaves, 12);
		setBlock(world, i + 10, j + 68, k + 66, Blocks.leaves, 12);
		setBlock(world, i + 10, j + 68, k + 67, Blocks.leaves, 12);
		setBlock(world, i + 10, j + 68, k + 68, Blocks.leaves, 12);
		setBlock(world, i + 10, j + 68, k + 69, Blocks.log, 1);
		setBlock(world, i + 10, j + 68, k + 70, Blocks.log, 1);
		setBlock(world, i + 10, j + 68, k + 71, Blocks.log, 1);
		setBlock(world, i + 10, j + 68, k + 72, Blocks.log, 1);
		setBlock(world, i + 10, j + 68, k + 73, Blocks.leaves, 12);
		setBlock(world, i + 10, j + 68, k + 74, Blocks.leaves, 12);
		setBlock(world, i + 10, j + 68, k + 75, Blocks.leaves, 12);
		setBlock(world, i + 10, j + 69, k + 49, Blocks.leaves, 12);
		setBlock(world, i + 10, j + 69, k + 50, Blocks.leaves, 12);
		setBlock(world, i + 10, j + 69, k + 51, Blocks.leaves, 12);
		setBlock(world, i + 10, j + 69, k + 52, Blocks.leaves, 12);
		setBlock(world, i + 10, j + 69, k + 53, Blocks.leaves, 12);
		setBlock(world, i + 10, j + 69, k + 64, Blocks.leaves, 12);
		setBlock(world, i + 10, j + 69, k + 65, Blocks.leaves, 12);
		setBlock(world, i + 10, j + 69, k + 66, Blocks.leaves, 12);
		setBlock(world, i + 10, j + 69, k + 67, Blocks.leaves, 12);
		setBlock(world, i + 10, j + 69, k + 68, Blocks.leaves, 12);
		setBlock(world, i + 10, j + 69, k + 69, Blocks.leaves, 12);
		setBlock(world, i + 10, j + 69, k + 70, Blocks.log, 1);
		setBlock(world, i + 10, j + 69, k + 71, Blocks.log, 1);
		setBlock(world, i + 10, j + 69, k + 72, Blocks.leaves, 12);
		setBlock(world, i + 10, j + 69, k + 73, Blocks.leaves, 12);
		setBlock(world, i + 10, j + 69, k + 74, Blocks.leaves, 12);
		setBlock(world, i + 10, j + 69, k + 75, Blocks.leaves, 12);
		setBlock(world, i + 10, j + 70, k + 49, Blocks.leaves, 12);
		setBlock(world, i + 10, j + 70, k + 50, Blocks.leaves, 12);
		setBlock(world, i + 10, j + 70, k + 51, Blocks.leaves, 12);
		setBlock(world, i + 10, j + 70, k + 52, Blocks.leaves, 12);
		setBlock(world, i + 10, j + 70, k + 53, Blocks.leaves, 12);
		setBlock(world, i + 10, j + 70, k + 64, Blocks.leaves, 12);
		setBlock(world, i + 10, j + 70, k + 65, Blocks.leaves, 12);
		setBlock(world, i + 10, j + 70, k + 66, Blocks.leaves, 12);
		setBlock(world, i + 10, j + 70, k + 67, Blocks.leaves, 12);
		setBlock(world, i + 10, j + 70, k + 68, Blocks.leaves, 12);
		setBlock(world, i + 10, j + 70, k + 69, Blocks.leaves, 12);
		setBlock(world, i + 10, j + 70, k + 70, Blocks.leaves, 12);
		setBlock(world, i + 10, j + 70, k + 71, Blocks.leaves, 12);
		setBlock(world, i + 10, j + 70, k + 72, Blocks.leaves, 12);
		setBlock(world, i + 10, j + 70, k + 73, Blocks.leaves, 12);
		setBlock(world, i + 10, j + 70, k + 74, Blocks.leaves, 12);
		setBlock(world, i + 10, j + 70, k + 75, Blocks.leaves, 12);
		setBlock(world, i + 10, j + 71, k + 49, Blocks.leaves, 12);
		setBlock(world, i + 10, j + 71, k + 50, Blocks.leaves, 12);
		setBlock(world, i + 10, j + 71, k + 51, Blocks.leaves, 12);
		setBlock(world, i + 10, j + 71, k + 52, Blocks.leaves, 12);
		setBlock(world, i + 10, j + 71, k + 53, Blocks.leaves, 12);
		setBlock(world, i + 10, j + 71, k + 62, Blocks.leaves, 12);
		setBlock(world, i + 10, j + 71, k + 63, Blocks.leaves, 12);
		setBlock(world, i + 10, j + 71, k + 64, Blocks.leaves, 12);
		setBlock(world, i + 10, j + 71, k + 65, Blocks.leaves, 12);
		setBlock(world, i + 10, j + 71, k + 66, Blocks.leaves, 12);
		setBlock(world, i + 10, j + 71, k + 67, Blocks.leaves, 12);
		setBlock(world, i + 10, j + 71, k + 68, Blocks.leaves, 12);
		setBlock(world, i + 10, j + 71, k + 70, Blocks.leaves, 12);
		setBlock(world, i + 10, j + 71, k + 71, Blocks.leaves, 12);
		setBlock(world, i + 10, j + 71, k + 72, Blocks.leaves, 12);
		setBlock(world, i + 10, j + 71, k + 73, Blocks.leaves, 12);
		setBlock(world, i + 10, j + 71, k + 74, Blocks.leaves, 12);
		setBlock(world, i + 10, j + 71, k + 75, Blocks.leaves, 12);
		setBlock(world, i + 10, j + 71, k + 76, Blocks.leaves, 12);
		setBlock(world, i + 10, j + 72, k + 61, Blocks.leaves, 12);
		setBlock(world, i + 10, j + 72, k + 62, Blocks.leaves, 12);
		setBlock(world, i + 10, j + 72, k + 63, Blocks.leaves, 12);
		setBlock(world, i + 10, j + 72, k + 64, Blocks.leaves, 12);
		setBlock(world, i + 10, j + 72, k + 65, Blocks.leaves, 12);
		setBlock(world, i + 10, j + 72, k + 66, Blocks.leaves, 12);
		setBlock(world, i + 10, j + 72, k + 67, Blocks.leaves, 12);
		setBlock(world, i + 10, j + 72, k + 68, Blocks.leaves, 12);
		setBlock(world, i + 10, j + 72, k + 69, Blocks.leaves, 12);
		setBlock(world, i + 10, j + 72, k + 70, Blocks.leaves, 12);
		setBlock(world, i + 10, j + 72, k + 71, Blocks.leaves, 12);
		setBlock(world, i + 10, j + 72, k + 72, Blocks.leaves, 12);
		setBlock(world, i + 10, j + 72, k + 73, Blocks.leaves, 12);
		setBlock(world, i + 10, j + 72, k + 74, Blocks.leaves, 12);
		setBlock(world, i + 10, j + 72, k + 75, Blocks.leaves, 12);
		setBlock(world, i + 10, j + 72, k + 76, Blocks.leaves, 12);
		setBlock(world, i + 10, j + 73, k + 60, Blocks.leaves, 12);
		setBlock(world, i + 10, j + 73, k + 61, Blocks.leaves, 12);
		setBlock(world, i + 10, j + 73, k + 62, Blocks.leaves, 12);
		setBlock(world, i + 10, j + 73, k + 63, Blocks.leaves, 12);
		setBlock(world, i + 10, j + 73, k + 64, Blocks.leaves, 12);
		setBlock(world, i + 10, j + 73, k + 65, Blocks.leaves, 12);
		setBlock(world, i + 10, j + 73, k + 66, Blocks.leaves, 12);
		setBlock(world, i + 10, j + 73, k + 67, Blocks.leaves, 12);
		setBlock(world, i + 10, j + 73, k + 68, Blocks.leaves, 12);
		setBlock(world, i + 10, j + 73, k + 69, Blocks.leaves, 12);
		setBlock(world, i + 10, j + 73, k + 70, Blocks.leaves, 12);
		setBlock(world, i + 10, j + 73, k + 71, Blocks.leaves, 12);
		setBlock(world, i + 10, j + 73, k + 72, Blocks.leaves, 12);
		setBlock(world, i + 10, j + 73, k + 73, Blocks.leaves, 12);
		setBlock(world, i + 10, j + 73, k + 74, Blocks.leaves, 12);
		setBlock(world, i + 10, j + 73, k + 75, Blocks.leaves, 12);
		setBlock(world, i + 10, j + 73, k + 76, Blocks.leaves, 12);
		setBlock(world, i + 10, j + 73, k + 77, Blocks.leaves, 12);
		setBlock(world, i + 10, j + 74, k + 61, Blocks.leaves, 12);
		setBlock(world, i + 10, j + 74, k + 62, Blocks.leaves, 12);
		setBlock(world, i + 10, j + 74, k + 63, Blocks.leaves, 12);
		setBlock(world, i + 10, j + 74, k + 66, Blocks.leaves, 12);
		setBlock(world, i + 10, j + 74, k + 67, Blocks.leaves, 12);
		setBlock(world, i + 10, j + 74, k + 68, Blocks.leaves, 12);
		setBlock(world, i + 10, j + 74, k + 69, Blocks.leaves, 12);
		setBlock(world, i + 10, j + 74, k + 70, Blocks.leaves, 12);
		setBlock(world, i + 10, j + 74, k + 71, Blocks.leaves, 12);
		setBlock(world, i + 10, j + 74, k + 72, Blocks.leaves, 12);
		setBlock(world, i + 10, j + 74, k + 73, Blocks.leaves, 12);
		setBlock(world, i + 10, j + 74, k + 74, Blocks.leaves, 12);
		setBlock(world, i + 10, j + 74, k + 75, Blocks.leaves, 12);
		setBlock(world, i + 10, j + 74, k + 76, Blocks.leaves, 12);
		setBlock(world, i + 10, j + 74, k + 77, Blocks.leaves, 12);
		setBlock(world, i + 10, j + 74, k + 78, Blocks.leaves, 12);
		setBlock(world, i + 10, j + 75, k + 62, Blocks.leaves, 12);
		setBlock(world, i + 10, j + 75, k + 74, Blocks.leaves, 12);
		setBlock(world, i + 10, j + 75, k + 75, Blocks.leaves, 12);
		setBlock(world, i + 10, j + 75, k + 76, Blocks.leaves, 12);
		setBlock(world, i + 10, j + 75, k + 77, Blocks.leaves, 12);
		setBlock(world, i + 10, j + 75, k + 78, Blocks.leaves, 12);
		setBlock(world, i + 10, j + 76, k + 76, Blocks.leaves, 12);
		setBlock(world, i + 10, j + 76, k + 77, Blocks.leaves, 12);
		setBlock(world, i + 10, j + 76, k + 78, Blocks.leaves, 12);
		setBlock(world, i + 11, j + 59, k + 65, Blocks.log, 1);
		setBlock(world, i + 11, j + 59, k + 66, Blocks.log, 1);
		setBlock(world, i + 11, j + 62, k + 66, Blocks.log, 1);
		setBlock(world, i + 11, j + 63, k + 66, Blocks.log, 1);
		setBlock(world, i + 11, j + 63, k + 67, Blocks.log, 1);
		setBlock(world, i + 11, j + 64, k + 66, Blocks.log, 1);
		setBlock(world, i + 11, j + 64, k + 67, Blocks.log, 1);
		setBlock(world, i + 11, j + 64, k + 68, Blocks.log, 1);
		setBlock(world, i + 11, j + 64, k + 69, Blocks.log, 1);
		setBlock(world, i + 11, j + 64, k + 70, Blocks.log, 1);
		setBlock(world, i + 11, j + 65, k + 66, Blocks.log, 1);
		setBlock(world, i + 11, j + 65, k + 67, Blocks.log, 1);
		setBlock(world, i + 11, j + 65, k + 68, Blocks.log, 1);
		setBlock(world, i + 11, j + 65, k + 69, Blocks.log, 1);
		setBlock(world, i + 11, j + 65, k + 70, Blocks.log, 1);
		setBlock(world, i + 11, j + 65, k + 71, Blocks.log, 1);
		setBlock(world, i + 11, j + 66, k + 67, Blocks.log, 1);
		setBlock(world, i + 11, j + 66, k + 68, Blocks.log, 1);
		setBlock(world, i + 11, j + 66, k + 69, Blocks.log, 1);
		setBlock(world, i + 11, j + 66, k + 70, Blocks.log, 1);
		setBlock(world, i + 11, j + 66, k + 71, Blocks.leaves, 12);
		setBlock(world, i + 11, j + 66, k + 72, Blocks.leaves, 12);
		setBlock(world, i + 11, j + 66, k + 73, Blocks.leaves, 12);
		setBlock(world, i + 11, j + 67, k + 68, Blocks.leaves, 12);
		setBlock(world, i + 11, j + 67, k + 69, Blocks.leaves, 12);
		setBlock(world, i + 11, j + 67, k + 70, Blocks.log, 1);
		setBlock(world, i + 11, j + 67, k + 71, Blocks.leaves, 12);
		setBlock(world, i + 11, j + 67, k + 72, Blocks.leaves, 12);
		setBlock(world, i + 11, j + 67, k + 73, Blocks.leaves, 12);
		setBlock(world, i + 11, j + 67, k + 74, Blocks.leaves, 12);
		setBlock(world, i + 11, j + 68, k + 65, Blocks.leaves, 12);
		setBlock(world, i + 11, j + 68, k + 66, Blocks.leaves, 12);
		setBlock(world, i + 11, j + 68, k + 67, Blocks.leaves, 12);
		setBlock(world, i + 11, j + 68, k + 68, Blocks.leaves, 12);
		setBlock(world, i + 11, j + 68, k + 69, Blocks.leaves, 12);
		setBlock(world, i + 11, j + 68, k + 70, Blocks.log, 1);
		setBlock(world, i + 11, j + 68, k + 71, Blocks.log, 1);
		setBlock(world, i + 11, j + 68, k + 72, Blocks.leaves, 12);
		setBlock(world, i + 11, j + 68, k + 73, Blocks.leaves, 12);
		setBlock(world, i + 11, j + 68, k + 74, Blocks.leaves, 12);
		setBlock(world, i + 11, j + 69, k + 48, Blocks.leaves, 12);
		setBlock(world, i + 11, j + 69, k + 49, Blocks.leaves, 12);
		setBlock(world, i + 11, j + 69, k + 50, Blocks.leaves, 12);
		setBlock(world, i + 11, j + 69, k + 51, Blocks.leaves, 12);
		setBlock(world, i + 11, j + 69, k + 52, Blocks.leaves, 12);
		setBlock(world, i + 11, j + 69, k + 53, Blocks.leaves, 12);
		setBlock(world, i + 11, j + 69, k + 55, Blocks.leaves, 12);
		setBlock(world, i + 11, j + 69, k + 56, Blocks.leaves, 12);
		setBlock(world, i + 11, j + 69, k + 57, Blocks.leaves, 12);
		setBlock(world, i + 11, j + 69, k + 64, Blocks.leaves, 12);
		setBlock(world, i + 11, j + 69, k + 65, Blocks.leaves, 12);
		setBlock(world, i + 11, j + 69, k + 66, Blocks.leaves, 12);
		setBlock(world, i + 11, j + 69, k + 67, Blocks.leaves, 12);
		setBlock(world, i + 11, j + 69, k + 68, Blocks.leaves, 12);
		setBlock(world, i + 11, j + 69, k + 69, Blocks.leaves, 12);
		setBlock(world, i + 11, j + 69, k + 70, Blocks.leaves, 12);
		setBlock(world, i + 11, j + 69, k + 71, Blocks.leaves, 12);
		setBlock(world, i + 11, j + 69, k + 72, Blocks.leaves, 12);
		setBlock(world, i + 11, j + 69, k + 73, Blocks.leaves, 12);
		setBlock(world, i + 11, j + 69, k + 74, Blocks.leaves, 12);
		setBlock(world, i + 11, j + 69, k + 75, Blocks.leaves, 12);
		setBlock(world, i + 11, j + 70, k + 47, Blocks.leaves, 12);
		setBlock(world, i + 11, j + 70, k + 48, Blocks.leaves, 12);
		setBlock(world, i + 11, j + 70, k + 49, Blocks.leaves, 12);
		setBlock(world, i + 11, j + 70, k + 50, Blocks.leaves, 12);
		setBlock(world, i + 11, j + 70, k + 51, Blocks.leaves, 12);
		setBlock(world, i + 11, j + 70, k + 52, Blocks.leaves, 12);
		setBlock(world, i + 11, j + 70, k + 53, Blocks.leaves, 12);
		setBlock(world, i + 11, j + 70, k + 54, Blocks.leaves, 12);
		setBlock(world, i + 11, j + 70, k + 55, Blocks.leaves, 12);
		setBlock(world, i + 11, j + 70, k + 56, Blocks.leaves, 12);
		setBlock(world, i + 11, j + 70, k + 57, Blocks.leaves, 12);
		setBlock(world, i + 11, j + 70, k + 63, Blocks.leaves, 12);
		setBlock(world, i + 11, j + 70, k + 64, Blocks.leaves, 12);
		setBlock(world, i + 11, j + 70, k + 65, Blocks.leaves, 12);
		setBlock(world, i + 11, j + 70, k + 66, Blocks.leaves, 12);
		setBlock(world, i + 11, j + 70, k + 67, Blocks.leaves, 12);
		setBlock(world, i + 11, j + 70, k + 68, Blocks.leaves, 12);
		setBlock(world, i + 11, j + 70, k + 69, Blocks.leaves, 12);
		setBlock(world, i + 11, j + 70, k + 71, Blocks.leaves, 12);
		setBlock(world, i + 11, j + 70, k + 72, Blocks.leaves, 12);
		setBlock(world, i + 11, j + 70, k + 73, Blocks.leaves, 12);
		setBlock(world, i + 11, j + 70, k + 74, Blocks.leaves, 12);
		setBlock(world, i + 11, j + 70, k + 75, Blocks.leaves, 12);
		setBlock(world, i + 11, j + 71, k + 48, Blocks.leaves, 12);
		setBlock(world, i + 11, j + 71, k + 49, Blocks.leaves, 12);
		setBlock(world, i + 11, j + 71, k + 50, Blocks.leaves, 12);
		setBlock(world, i + 11, j + 71, k + 51, Blocks.leaves, 12);
		setBlock(world, i + 11, j + 71, k + 52, Blocks.leaves, 12);
		setBlock(world, i + 11, j + 71, k + 53, Blocks.leaves, 12);
		setBlock(world, i + 11, j + 71, k + 55, Blocks.leaves, 12);
		setBlock(world, i + 11, j + 71, k + 56, Blocks.leaves, 12);
		setBlock(world, i + 11, j + 71, k + 57, Blocks.leaves, 12);
		setBlock(world, i + 11, j + 71, k + 62, Blocks.leaves, 12);
		setBlock(world, i + 11, j + 71, k + 63, Blocks.leaves, 12);
		setBlock(world, i + 11, j + 71, k + 64, Blocks.leaves, 12);
		setBlock(world, i + 11, j + 71, k + 65, Blocks.leaves, 12);
		setBlock(world, i + 11, j + 71, k + 66, Blocks.leaves, 12);
		setBlock(world, i + 11, j + 71, k + 68, Blocks.leaves, 12);
		setBlock(world, i + 11, j + 71, k + 69, Blocks.leaves, 12);
		setBlock(world, i + 11, j + 71, k + 70, Blocks.leaves, 12);
		setBlock(world, i + 11, j + 71, k + 71, Blocks.leaves, 12);
		setBlock(world, i + 11, j + 71, k + 72, Blocks.leaves, 12);
		setBlock(world, i + 11, j + 71, k + 73, Blocks.leaves, 12);
		setBlock(world, i + 11, j + 71, k + 74, Blocks.leaves, 12);
		setBlock(world, i + 11, j + 71, k + 75, Blocks.leaves, 12);
		setBlock(world, i + 11, j + 71, k + 76, Blocks.leaves, 12);
		setBlock(world, i + 11, j + 72, k + 49, Blocks.leaves, 12);
		setBlock(world, i + 11, j + 72, k + 50, Blocks.leaves, 12);
		setBlock(world, i + 11, j + 72, k + 51, Blocks.leaves, 12);
		setBlock(world, i + 11, j + 72, k + 61, Blocks.leaves, 12);
		setBlock(world, i + 11, j + 72, k + 62, Blocks.leaves, 12);
		setBlock(world, i + 11, j + 72, k + 63, Blocks.leaves, 12);
		setBlock(world, i + 11, j + 72, k + 64, Blocks.leaves, 12);
		setBlock(world, i + 11, j + 72, k + 65, Blocks.leaves, 12);
		setBlock(world, i + 11, j + 72, k + 66, Blocks.leaves, 12);
		setBlock(world, i + 11, j + 72, k + 67, Blocks.leaves, 12);
		setBlock(world, i + 11, j + 72, k + 68, Blocks.leaves, 12);
		setBlock(world, i + 11, j + 72, k + 69, Blocks.leaves, 12);
		setBlock(world, i + 11, j + 72, k + 70, Blocks.leaves, 12);
		setBlock(world, i + 11, j + 72, k + 71, Blocks.leaves, 12);
		setBlock(world, i + 11, j + 72, k + 72, Blocks.leaves, 12);
		setBlock(world, i + 11, j + 72, k + 73, Blocks.leaves, 12);
		setBlock(world, i + 11, j + 72, k + 74, Blocks.leaves, 12);
		setBlock(world, i + 11, j + 72, k + 75, Blocks.leaves, 12);
		setBlock(world, i + 11, j + 72, k + 76, Blocks.leaves, 12);
		setBlock(world, i + 11, j + 73, k + 61, Blocks.leaves, 12);
		setBlock(world, i + 11, j + 73, k + 62, Blocks.leaves, 12);
		setBlock(world, i + 11, j + 73, k + 63, Blocks.leaves, 12);
		setBlock(world, i + 11, j + 73, k + 64, Blocks.leaves, 12);
		setBlock(world, i + 11, j + 73, k + 65, Blocks.leaves, 4);
		setBlock(world, i + 11, j + 73, k + 66, Blocks.leaves, 12);
		setBlock(world, i + 11, j + 73, k + 67, Blocks.leaves, 12);
		setBlock(world, i + 11, j + 73, k + 68, Blocks.leaves, 12);
		setBlock(world, i + 11, j + 73, k + 69, Blocks.leaves, 12);
		setBlock(world, i + 11, j + 73, k + 70, Blocks.leaves, 12);
		setBlock(world, i + 11, j + 73, k + 71, Blocks.leaves, 12);
		setBlock(world, i + 11, j + 73, k + 72, Blocks.leaves, 12);
		setBlock(world, i + 11, j + 73, k + 73, Blocks.leaves, 12);
		setBlock(world, i + 11, j + 73, k + 74, Blocks.leaves, 12);
		setBlock(world, i + 11, j + 73, k + 75, Blocks.leaves, 12);
		setBlock(world, i + 11, j + 73, k + 76, Blocks.leaves, 12);
		setBlock(world, i + 11, j + 73, k + 77, Blocks.leaves, 12);
		setBlock(world, i + 11, j + 74, k + 61, Blocks.leaves, 12);
		setBlock(world, i + 11, j + 74, k + 62, Blocks.leaves, 12);
		setBlock(world, i + 11, j + 74, k + 63, Blocks.leaves, 12);
		setBlock(world, i + 11, j + 74, k + 66, Blocks.leaves, 12);
		setBlock(world, i + 11, j + 74, k + 67, Blocks.leaves, 12);
		setBlock(world, i + 11, j + 74, k + 68, Blocks.leaves, 12);
		setBlock(world, i + 11, j + 74, k + 69, Blocks.leaves, 12);
		setBlock(world, i + 11, j + 74, k + 70, Blocks.leaves, 12);
		setBlock(world, i + 11, j + 74, k + 71, Blocks.leaves, 12);
		setBlock(world, i + 11, j + 74, k + 72, Blocks.leaves, 4);
		setBlock(world, i + 11, j + 74, k + 73, Blocks.leaves, 12);
		setBlock(world, i + 11, j + 74, k + 74, Blocks.leaves, 12);
		setBlock(world, i + 11, j + 74, k + 75, Blocks.leaves, 12);
		setBlock(world, i + 11, j + 74, k + 76, Blocks.leaves, 12);
		setBlock(world, i + 11, j + 74, k + 77, Blocks.leaves, 12);
		setBlock(world, i + 11, j + 74, k + 78, Blocks.leaves, 12);
		setBlock(world, i + 11, j + 75, k + 75, Blocks.leaves, 12);
		setBlock(world, i + 11, j + 75, k + 76, Blocks.leaves, 12);
		setBlock(world, i + 11, j + 75, k + 77, Blocks.leaves, 12);
		setBlock(world, i + 11, j + 75, k + 78, Blocks.leaves, 12);
		setBlock(world, i + 11, j + 76, k + 76, Blocks.leaves, 12);
		setBlock(world, i + 11, j + 76, k + 77, Blocks.leaves, 12);
		setBlock(world, i + 11, j + 76, k + 78, Blocks.leaves, 12);
		setBlock(world, i + 12, j + 58, k + 65, Blocks.log, 1);
		setBlock(world, i + 12, j + 58, k + 66, Blocks.log, 1);
		setBlock(world, i + 12, j + 59, k + 64, Blocks.log, 1);
		setBlock(world, i + 12, j + 59, k + 65, Blocks.log, 1);
		setBlock(world, i + 12, j + 59, k + 66, Blocks.log, 1);
		setBlock(world, i + 12, j + 59, k + 67, Blocks.log, 1);
		setBlock(world, i + 12, j + 60, k + 66, Blocks.log, 1);
		setBlock(world, i + 12, j + 61, k + 66, Blocks.log, 1);
		setBlock(world, i + 12, j + 62, k + 65, Blocks.log, 1);
		setBlock(world, i + 12, j + 62, k + 66, Blocks.log, 1);
		setBlock(world, i + 12, j + 62, k + 67, Blocks.log, 1);
		setBlock(world, i + 12, j + 63, k + 65, Blocks.log, 1);
		setBlock(world, i + 12, j + 63, k + 66, Blocks.log, 1);
		setBlock(world, i + 12, j + 63, k + 67, Blocks.log, 1);
		setBlock(world, i + 12, j + 63, k + 68, Blocks.log, 1);
		setBlock(world, i + 12, j + 64, k + 66, Blocks.log, 1);
		setBlock(world, i + 12, j + 64, k + 67, Blocks.log, 1);
		setBlock(world, i + 12, j + 64, k + 68, Blocks.log, 1);
		setBlock(world, i + 12, j + 64, k + 69, Blocks.log, 1);
		setBlock(world, i + 12, j + 65, k + 67, Blocks.log, 1);
		setBlock(world, i + 12, j + 65, k + 68, Blocks.log, 1);
		setBlock(world, i + 12, j + 65, k + 69, Blocks.log, 1);
		setBlock(world, i + 12, j + 65, k + 70, Blocks.log, 1);
		setBlock(world, i + 12, j + 67, k + 70, Blocks.leaves, 12);
		setBlock(world, i + 12, j + 67, k + 71, Blocks.leaves, 12);
		setBlock(world, i + 12, j + 67, k + 72, Blocks.leaves, 12);
		setBlock(world, i + 12, j + 68, k + 65, Blocks.leaves, 12);
		setBlock(world, i + 12, j + 68, k + 67, Blocks.leaves, 12);
		setBlock(world, i + 12, j + 68, k + 68, Blocks.leaves, 12);
		setBlock(world, i + 12, j + 68, k + 69, Blocks.leaves, 12);
		setBlock(world, i + 12, j + 68, k + 70, Blocks.leaves, 12);
		setBlock(world, i + 12, j + 68, k + 71, Blocks.leaves, 12);
		setBlock(world, i + 12, j + 68, k + 72, Blocks.leaves, 12);
		setBlock(world, i + 12, j + 68, k + 73, Blocks.leaves, 12);
		setBlock(world, i + 12, j + 68, k + 74, Blocks.leaves, 12);
		setBlock(world, i + 12, j + 69, k + 46, Blocks.leaves, 12);
		setBlock(world, i + 12, j + 69, k + 47, Blocks.leaves, 12);
		setBlock(world, i + 12, j + 69, k + 48, Blocks.leaves, 12);
		setBlock(world, i + 12, j + 69, k + 49, Blocks.leaves, 12);
		setBlock(world, i + 12, j + 69, k + 50, Blocks.leaves, 12);
		setBlock(world, i + 12, j + 69, k + 51, Blocks.leaves, 12);
		setBlock(world, i + 12, j + 69, k + 52, Blocks.leaves, 12);
		setBlock(world, i + 12, j + 69, k + 53, Blocks.leaves, 12);
		setBlock(world, i + 12, j + 69, k + 54, Blocks.leaves, 12);
		setBlock(world, i + 12, j + 69, k + 55, Blocks.leaves, 12);
		setBlock(world, i + 12, j + 69, k + 56, Blocks.leaves, 12);
		setBlock(world, i + 12, j + 69, k + 57, Blocks.leaves, 12);
		setBlock(world, i + 12, j + 69, k + 64, Blocks.leaves, 12);
		setBlock(world, i + 12, j + 69, k + 65, Blocks.leaves, 12);
		setBlock(world, i + 12, j + 69, k + 66, Blocks.leaves, 12);
		setBlock(world, i + 12, j + 69, k + 67, Blocks.leaves, 12);
		setBlock(world, i + 12, j + 69, k + 68, Blocks.leaves, 12);
		setBlock(world, i + 12, j + 69, k + 69, Blocks.leaves, 12);
		setBlock(world, i + 12, j + 69, k + 70, Blocks.leaves, 12);
		setBlock(world, i + 12, j + 69, k + 71, Blocks.leaves, 12);
		setBlock(world, i + 12, j + 69, k + 72, Blocks.leaves, 12);
		setBlock(world, i + 12, j + 69, k + 73, Blocks.leaves, 12);
		setBlock(world, i + 12, j + 69, k + 74, Blocks.leaves, 12);
		setBlock(world, i + 12, j + 70, k + 46, Blocks.leaves, 12);
		setBlock(world, i + 12, j + 70, k + 47, Blocks.leaves, 12);
		setBlock(world, i + 12, j + 70, k + 48, Blocks.leaves, 12);
		setBlock(world, i + 12, j + 70, k + 49, Blocks.leaves, 12);
		setBlock(world, i + 12, j + 70, k + 50, Blocks.leaves, 12);
		setBlock(world, i + 12, j + 70, k + 51, Blocks.leaves, 12);
		setBlock(world, i + 12, j + 70, k + 52, Blocks.leaves, 12);
		setBlock(world, i + 12, j + 70, k + 53, Blocks.leaves, 12);
		setBlock(world, i + 12, j + 70, k + 54, Blocks.leaves, 12);
		setBlock(world, i + 12, j + 70, k + 55, Blocks.leaves, 12);
		setBlock(world, i + 12, j + 70, k + 56, Blocks.leaves, 12);
		setBlock(world, i + 12, j + 70, k + 57, Blocks.leaves, 12);
		setBlock(world, i + 12, j + 70, k + 63, Blocks.leaves, 12);
		setBlock(world, i + 12, j + 70, k + 64, Blocks.leaves, 12);
		setBlock(world, i + 12, j + 70, k + 65, Blocks.leaves, 12);
		setBlock(world, i + 12, j + 70, k + 66, Blocks.leaves, 12);
		setBlock(world, i + 12, j + 70, k + 67, Blocks.leaves, 12);
		setBlock(world, i + 12, j + 70, k + 68, Blocks.leaves, 12);
		setBlock(world, i + 12, j + 70, k + 69, Blocks.leaves, 12);
		setBlock(world, i + 12, j + 70, k + 71, Blocks.leaves, 12);
		setBlock(world, i + 12, j + 70, k + 72, Blocks.leaves, 12);
		setBlock(world, i + 12, j + 70, k + 73, Blocks.leaves, 12);
		setBlock(world, i + 12, j + 70, k + 74, Blocks.leaves, 12);
		setBlock(world, i + 12, j + 70, k + 75, Blocks.leaves, 12);
		setBlock(world, i + 12, j + 71, k + 46, Blocks.leaves, 12);
		setBlock(world, i + 12, j + 71, k + 47, Blocks.leaves, 12);
		setBlock(world, i + 12, j + 71, k + 48, Blocks.leaves, 12);
		setBlock(world, i + 12, j + 71, k + 49, Blocks.leaves, 12);
		setBlock(world, i + 12, j + 71, k + 50, Blocks.leaves, 12);
		setBlock(world, i + 12, j + 71, k + 51, Blocks.leaves, 12);
		setBlock(world, i + 12, j + 71, k + 52, Blocks.leaves, 12);
		setBlock(world, i + 12, j + 71, k + 53, Blocks.leaves, 12);
		setBlock(world, i + 12, j + 71, k + 54, Blocks.leaves, 12);
		setBlock(world, i + 12, j + 71, k + 55, Blocks.leaves, 12);
		setBlock(world, i + 12, j + 71, k + 56, Blocks.leaves, 12);
		setBlock(world, i + 12, j + 71, k + 57, Blocks.leaves, 12);
		setBlock(world, i + 12, j + 71, k + 62, Blocks.leaves, 12);
		setBlock(world, i + 12, j + 71, k + 63, Blocks.leaves, 12);
		setBlock(world, i + 12, j + 71, k + 64, Blocks.leaves, 12);
		setBlock(world, i + 12, j + 71, k + 65, Blocks.leaves, 12);
		setBlock(world, i + 12, j + 71, k + 66, Blocks.leaves, 12);
		setBlock(world, i + 12, j + 71, k + 67, Blocks.leaves, 12);
		setBlock(world, i + 12, j + 71, k + 68, Blocks.leaves, 12);
		setBlock(world, i + 12, j + 71, k + 69, Blocks.leaves, 12);
		setBlock(world, i + 12, j + 71, k + 70, Blocks.leaves, 12);
		setBlock(world, i + 12, j + 71, k + 71, Blocks.leaves, 12);
		setBlock(world, i + 12, j + 71, k + 72, Blocks.leaves, 12);
		setBlock(world, i + 12, j + 71, k + 73, Blocks.leaves, 12);
		setBlock(world, i + 12, j + 71, k + 74, Blocks.leaves, 12);
		setBlock(world, i + 12, j + 71, k + 75, Blocks.leaves, 12);
		setBlock(world, i + 12, j + 71, k + 76, Blocks.leaves, 12);
		setBlock(world, i + 12, j + 72, k + 47, Blocks.leaves, 12);
		setBlock(world, i + 12, j + 72, k + 48, Blocks.leaves, 12);
		setBlock(world, i + 12, j + 72, k + 49, Blocks.leaves, 12);
		setBlock(world, i + 12, j + 72, k + 50, Blocks.leaves, 12);
		setBlock(world, i + 12, j + 72, k + 51, Blocks.leaves, 12);
		setBlock(world, i + 12, j + 72, k + 52, Blocks.leaves, 12);
		setBlock(world, i + 12, j + 72, k + 62, Blocks.leaves, 12);
		setBlock(world, i + 12, j + 72, k + 63, Blocks.leaves, 12);
		setBlock(world, i + 12, j + 72, k + 64, Blocks.leaves, 12);
		setBlock(world, i + 12, j + 72, k + 65, Blocks.leaves, 12);
		setBlock(world, i + 12, j + 72, k + 66, Blocks.leaves, 12);
		setBlock(world, i + 12, j + 72, k + 67, Blocks.leaves, 12);
		setBlock(world, i + 12, j + 72, k + 68, Blocks.leaves, 12);
		setBlock(world, i + 12, j + 72, k + 69, Blocks.leaves, 12);
		setBlock(world, i + 12, j + 72, k + 70, Blocks.leaves, 12);
		setBlock(world, i + 12, j + 72, k + 71, Blocks.leaves, 12);
		setBlock(world, i + 12, j + 72, k + 72, Blocks.leaves, 12);
		setBlock(world, i + 12, j + 72, k + 73, Blocks.leaves, 12);
		setBlock(world, i + 12, j + 72, k + 74, Blocks.leaves, 12);
		setBlock(world, i + 12, j + 72, k + 75, Blocks.leaves, 12);
		setBlock(world, i + 12, j + 72, k + 76, Blocks.leaves, 12);
		setBlock(world, i + 12, j + 73, k + 47, Blocks.leaves, 12);
		setBlock(world, i + 12, j + 73, k + 48, Blocks.leaves, 12);
		setBlock(world, i + 12, j + 73, k + 49, Blocks.leaves, 12);
		setBlock(world, i + 12, j + 73, k + 62, Blocks.leaves, 12);
		setBlock(world, i + 12, j + 73, k + 63, Blocks.leaves, 12);
		setBlock(world, i + 12, j + 73, k + 64, Blocks.leaves, 12);
		setBlock(world, i + 12, j + 73, k + 65, Blocks.leaves, 4);
		setBlock(world, i + 12, j + 73, k + 66, Blocks.leaves, 4);
		setBlock(world, i + 12, j + 73, k + 67, Blocks.leaves, 12);
		setBlock(world, i + 12, j + 73, k + 68, Blocks.leaves, 12);
		setBlock(world, i + 12, j + 73, k + 69, Blocks.leaves, 12);
		setBlock(world, i + 12, j + 73, k + 70, Blocks.leaves, 12);
		setBlock(world, i + 12, j + 73, k + 71, Blocks.leaves, 12);
		setBlock(world, i + 12, j + 73, k + 72, Blocks.leaves, 12);
		setBlock(world, i + 12, j + 73, k + 73, Blocks.leaves, 12);
		setBlock(world, i + 12, j + 73, k + 74, Blocks.leaves, 12);
		setBlock(world, i + 12, j + 73, k + 75, Blocks.leaves, 12);
		setBlock(world, i + 12, j + 73, k + 76, Blocks.leaves, 12);
		setBlock(world, i + 12, j + 73, k + 77, Blocks.leaves, 12);
		setBlock(world, i + 12, j + 74, k + 69, Blocks.leaves, 12);
		setBlock(world, i + 12, j + 74, k + 70, Blocks.leaves, 12);
		setBlock(world, i + 12, j + 74, k + 71, Blocks.leaves, 12);
		setBlock(world, i + 12, j + 74, k + 72, Blocks.leaves, 12);
		setBlock(world, i + 12, j + 74, k + 74, Blocks.leaves, 12);
		setBlock(world, i + 12, j + 74, k + 75, Blocks.leaves, 12);
		setBlock(world, i + 12, j + 74, k + 76, Blocks.leaves, 12);
		setBlock(world, i + 12, j + 74, k + 77, Blocks.leaves, 12);
		setBlock(world, i + 12, j + 75, k + 75, Blocks.leaves, 4);
		setBlock(world, i + 12, j + 75, k + 76, Blocks.leaves, 12);
		setBlock(world, i + 12, j + 75, k + 77, Blocks.leaves, 12);
		setBlock(world, i + 12, j + 75, k + 78, Blocks.leaves, 12);
		setBlock(world, i + 12, j + 75, k + 92, Blocks.leaves, 12);
		setBlock(world, i + 12, j + 76, k + 77, Blocks.leaves, 4);
		setBlock(world, i + 13, j + 58, k + 65, Blocks.log, 1);
		setBlock(world, i + 13, j + 58, k + 66, Blocks.log, 1);
		setBlock(world, i + 13, j + 59, k + 64, Blocks.log, 1);
		setBlock(world, i + 13, j + 59, k + 65, Blocks.log, 1);
		setBlock(world, i + 13, j + 59, k + 66, Blocks.log, 1);
		setBlock(world, i + 13, j + 59, k + 67, Blocks.log, 1);
		setBlock(world, i + 13, j + 60, k + 65, Blocks.log, 1);
		setBlock(world, i + 13, j + 60, k + 66, Blocks.log, 1);
		setBlock(world, i + 13, j + 60, k + 67, Blocks.log, 1);
		setBlock(world, i + 13, j + 61, k + 65, Blocks.log, 1);
		setBlock(world, i + 13, j + 61, k + 66, Blocks.log, 1);
		setBlock(world, i + 13, j + 61, k + 67, Blocks.log, 1);
		setBlock(world, i + 13, j + 62, k + 65, Blocks.log, 1);
		setBlock(world, i + 13, j + 62, k + 66, Blocks.log, 1);
		setBlock(world, i + 13, j + 62, k + 67, Blocks.log, 1);
		setBlock(world, i + 13, j + 63, k + 66, Blocks.log, 1);
		setBlock(world, i + 13, j + 63, k + 67, Blocks.log, 1);
		setBlock(world, i + 13, j + 64, k + 67, Blocks.log, 1);
		setBlock(world, i + 13, j + 64, k + 68, Blocks.log, 1);
		setBlock(world, i + 13, j + 67, k + 51, Blocks.leaves, 12);
		setBlock(world, i + 13, j + 67, k + 52, Blocks.leaves, 12);
		setBlock(world, i + 13, j + 67, k + 53, Blocks.leaves, 12);
		setBlock(world, i + 13, j + 67, k + 68, Blocks.leaves, 12);
		setBlock(world, i + 13, j + 68, k + 47, Blocks.leaves, 12);
		setBlock(world, i + 13, j + 68, k + 48, Blocks.leaves, 12);
		setBlock(world, i + 13, j + 68, k + 50, Blocks.leaves, 12);
		setBlock(world, i + 13, j + 68, k + 51, Blocks.leaves, 12);
		setBlock(world, i + 13, j + 68, k + 52, Blocks.leaves, 12);
		setBlock(world, i + 13, j + 68, k + 53, Blocks.leaves, 12);
		setBlock(world, i + 13, j + 68, k + 54, Blocks.leaves, 12);
		setBlock(world, i + 13, j + 68, k + 67, Blocks.leaves, 12);
		setBlock(world, i + 13, j + 68, k + 68, Blocks.leaves, 12);
		setBlock(world, i + 13, j + 68, k + 69, Blocks.leaves, 12);
		setBlock(world, i + 13, j + 68, k + 71, Blocks.leaves, 12);
		setBlock(world, i + 13, j + 68, k + 72, Blocks.leaves, 12);
		setBlock(world, i + 13, j + 68, k + 79, Blocks.leaves, 12);
		setBlock(world, i + 13, j + 69, k + 46, Blocks.leaves, 12);
		setBlock(world, i + 13, j + 69, k + 47, Blocks.leaves, 12);
		setBlock(world, i + 13, j + 69, k + 48, Blocks.leaves, 12);
		setBlock(world, i + 13, j + 69, k + 49, Blocks.leaves, 12);
		setBlock(world, i + 13, j + 69, k + 50, Blocks.leaves, 12);
		setBlock(world, i + 13, j + 69, k + 51, Blocks.leaves, 12);
		setBlock(world, i + 13, j + 69, k + 52, Blocks.leaves, 12);
		setBlock(world, i + 13, j + 69, k + 53, Blocks.leaves, 12);
		setBlock(world, i + 13, j + 69, k + 54, Blocks.leaves, 12);
		setBlock(world, i + 13, j + 69, k + 55, Blocks.leaves, 12);
		setBlock(world, i + 13, j + 69, k + 56, Blocks.leaves, 12);
		setBlock(world, i + 13, j + 69, k + 57, Blocks.leaves, 12);
		setBlock(world, i + 13, j + 69, k + 64, Blocks.leaves, 12);
		setBlock(world, i + 13, j + 69, k + 65, Blocks.leaves, 12);
		setBlock(world, i + 13, j + 69, k + 66, Blocks.leaves, 12);
		setBlock(world, i + 13, j + 69, k + 67, Blocks.leaves, 12);
		setBlock(world, i + 13, j + 69, k + 68, Blocks.leaves, 12);
		setBlock(world, i + 13, j + 69, k + 69, Blocks.leaves, 12);
		setBlock(world, i + 13, j + 69, k + 70, Blocks.leaves, 12);
		setBlock(world, i + 13, j + 69, k + 71, Blocks.leaves, 12);
		setBlock(world, i + 13, j + 69, k + 72, Blocks.leaves, 12);
		setBlock(world, i + 13, j + 69, k + 73, Blocks.leaves, 12);
		setBlock(world, i + 13, j + 69, k + 74, Blocks.leaves, 12);
		setBlock(world, i + 13, j + 70, k + 45, Blocks.leaves, 12);
		setBlock(world, i + 13, j + 70, k + 46, Blocks.leaves, 12);
		setBlock(world, i + 13, j + 70, k + 47, Blocks.leaves, 12);
		setBlock(world, i + 13, j + 70, k + 48, Blocks.leaves, 12);
		setBlock(world, i + 13, j + 70, k + 49, Blocks.leaves, 12);
		setBlock(world, i + 13, j + 70, k + 50, Blocks.leaves, 12);
		setBlock(world, i + 13, j + 70, k + 51, Blocks.leaves, 12);
		setBlock(world, i + 13, j + 70, k + 52, Blocks.leaves, 12);
		setBlock(world, i + 13, j + 70, k + 53, Blocks.leaves, 12);
		setBlock(world, i + 13, j + 70, k + 54, Blocks.leaves, 12);
		setBlock(world, i + 13, j + 70, k + 55, Blocks.leaves, 12);
		setBlock(world, i + 13, j + 70, k + 56, Blocks.leaves, 12);
		setBlock(world, i + 13, j + 70, k + 57, Blocks.leaves, 12);
		setBlock(world, i + 13, j + 70, k + 63, Blocks.leaves, 12);
		setBlock(world, i + 13, j + 70, k + 64, Blocks.leaves, 12);
		setBlock(world, i + 13, j + 70, k + 65, Blocks.leaves, 12);
		setBlock(world, i + 13, j + 70, k + 66, Blocks.leaves, 12);
		setBlock(world, i + 13, j + 70, k + 67, Blocks.leaves, 12);
		setBlock(world, i + 13, j + 70, k + 68, Blocks.leaves, 12);
		setBlock(world, i + 13, j + 70, k + 69, Blocks.leaves, 12);
		setBlock(world, i + 13, j + 70, k + 70, Blocks.leaves, 12);
		setBlock(world, i + 13, j + 70, k + 71, Blocks.leaves, 12);
		setBlock(world, i + 13, j + 70, k + 72, Blocks.leaves, 12);
		setBlock(world, i + 13, j + 70, k + 73, Blocks.leaves, 12);
		setBlock(world, i + 13, j + 70, k + 74, Blocks.leaves, 12);
		setBlock(world, i + 13, j + 70, k + 75, Blocks.leaves, 12);
		setBlock(world, i + 13, j + 71, k + 41, Blocks.leaves, 12);
		setBlock(world, i + 13, j + 71, k + 45, Blocks.leaves, 12);
		setBlock(world, i + 13, j + 71, k + 46, Blocks.leaves, 12);

		generate2(world, rand, i, j, k);
		
	}

	private static void generate2(World world, Random rand, int i, int j, int k) {
		setBlock(world, i + 13, j + 71, k + 47, Blocks.leaves, 12);
		setBlock(world, i + 13, j + 71, k + 48, Blocks.leaves, 12);
		setBlock(world, i + 13, j + 71, k + 49, Blocks.leaves, 12);
		setBlock(world, i + 13, j + 71, k + 50, Blocks.leaves, 12);
		setBlock(world, i + 13, j + 71, k + 51, Blocks.leaves, 12);
		setBlock(world, i + 13, j + 71, k + 52, Blocks.leaves, 12);
		setBlock(world, i + 13, j + 71, k + 53, Blocks.leaves, 12);
		setBlock(world, i + 13, j + 71, k + 54, Blocks.leaves, 12);
		setBlock(world, i + 13, j + 71, k + 55, Blocks.leaves, 12);
		setBlock(world, i + 13, j + 71, k + 56, Blocks.leaves, 12);
		setBlock(world, i + 13, j + 71, k + 57, Blocks.leaves, 12);
		setBlock(world, i + 13, j + 71, k + 62, Blocks.leaves, 12);
		setBlock(world, i + 13, j + 71, k + 63, Blocks.leaves, 12);
		setBlock(world, i + 13, j + 71, k + 64, Blocks.leaves, 12);
		setBlock(world, i + 13, j + 71, k + 65, Blocks.leaves, 12);
		setBlock(world, i + 13, j + 71, k + 66, Blocks.leaves, 12);
		setBlock(world, i + 13, j + 71, k + 67, Blocks.leaves, 12);
		setBlock(world, i + 13, j + 71, k + 68, Blocks.leaves, 12);
		setBlock(world, i + 13, j + 71, k + 69, Blocks.leaves, 12);
		setBlock(world, i + 13, j + 71, k + 70, Blocks.leaves, 12);
		setBlock(world, i + 13, j + 71, k + 71, Blocks.leaves, 12);
		setBlock(world, i + 13, j + 71, k + 72, Blocks.leaves, 12);
		setBlock(world, i + 13, j + 71, k + 73, Blocks.leaves, 12);
		setBlock(world, i + 13, j + 71, k + 74, Blocks.leaves, 12);
		setBlock(world, i + 13, j + 71, k + 75, Blocks.leaves, 12);
		setBlock(world, i + 13, j + 72, k + 45, Blocks.leaves, 12);
		setBlock(world, i + 13, j + 72, k + 46, Blocks.leaves, 12);
		setBlock(world, i + 13, j + 72, k + 47, Blocks.leaves, 12);
		setBlock(world, i + 13, j + 72, k + 48, Blocks.leaves, 12);
		setBlock(world, i + 13, j + 72, k + 49, Blocks.leaves, 12);
		setBlock(world, i + 13, j + 72, k + 50, Blocks.leaves, 12);
		setBlock(world, i + 13, j + 72, k + 51, Blocks.leaves, 12);
		setBlock(world, i + 13, j + 72, k + 52, Blocks.leaves, 12);
		setBlock(world, i + 13, j + 72, k + 53, Blocks.leaves, 12);
		setBlock(world, i + 13, j + 72, k + 54, Blocks.leaves, 12);
		setBlock(world, i + 13, j + 72, k + 55, Blocks.leaves, 12);
		setBlock(world, i + 13, j + 72, k + 56, Blocks.leaves, 12);
		setBlock(world, i + 13, j + 72, k + 57, Blocks.leaves, 12);
		setBlock(world, i + 13, j + 72, k + 61, Blocks.leaves, 12);
		setBlock(world, i + 13, j + 72, k + 62, Blocks.leaves, 12);
		setBlock(world, i + 13, j + 72, k + 63, Blocks.leaves, 12);
		setBlock(world, i + 13, j + 72, k + 64, Blocks.leaves, 12);
		setBlock(world, i + 13, j + 72, k + 65, Blocks.leaves, 12);
		setBlock(world, i + 13, j + 72, k + 66, Blocks.leaves, 12);
		setBlock(world, i + 13, j + 72, k + 67, Blocks.leaves, 12);
		setBlock(world, i + 13, j + 72, k + 68, Blocks.leaves, 12);
		setBlock(world, i + 13, j + 72, k + 69, Blocks.leaves, 12);
		setBlock(world, i + 13, j + 72, k + 70, Blocks.leaves, 12);
		setBlock(world, i + 13, j + 72, k + 71, Blocks.leaves, 12);
		setBlock(world, i + 13, j + 72, k + 72, Blocks.leaves, 12);
		setBlock(world, i + 13, j + 72, k + 73, Blocks.leaves, 12);
		setBlock(world, i + 13, j + 72, k + 74, Blocks.leaves, 12);
		setBlock(world, i + 13, j + 72, k + 75, Blocks.leaves, 12);
		setBlock(world, i + 13, j + 73, k + 47, Blocks.leaves, 12);
		setBlock(world, i + 13, j + 73, k + 48, Blocks.leaves, 12);
		setBlock(world, i + 13, j + 73, k + 49, Blocks.leaves, 12);
		setBlock(world, i + 13, j + 73, k + 50, Blocks.leaves, 12);
		setBlock(world, i + 13, j + 73, k + 62, Blocks.leaves, 12);
		setBlock(world, i + 13, j + 73, k + 63, Blocks.leaves, 12);
		setBlock(world, i + 13, j + 73, k + 64, Blocks.leaves, 12);
		setBlock(world, i + 13, j + 73, k + 66, Blocks.leaves, 12);
		setBlock(world, i + 13, j + 73, k + 67, Blocks.leaves, 4);
		setBlock(world, i + 13, j + 73, k + 68, Blocks.leaves, 12);
		setBlock(world, i + 13, j + 73, k + 69, Blocks.leaves, 12);
		setBlock(world, i + 13, j + 73, k + 70, Blocks.leaves, 12);
		setBlock(world, i + 13, j + 73, k + 71, Blocks.leaves, 12);
		setBlock(world, i + 13, j + 73, k + 72, Blocks.leaves, 12);
		setBlock(world, i + 13, j + 73, k + 73, Blocks.leaves, 12);
		setBlock(world, i + 13, j + 73, k + 74, Blocks.leaves, 12);
		setBlock(world, i + 13, j + 73, k + 75, Blocks.leaves, 12);
		setBlock(world, i + 13, j + 73, k + 76, Blocks.leaves, 12);
		setBlock(world, i + 13, j + 73, k + 77, Blocks.leaves, 12);
		setBlock(world, i + 13, j + 73, k + 78, Blocks.leaves, 12);
		setBlock(world, i + 13, j + 74, k + 70, Blocks.leaves, 12);
		setBlock(world, i + 13, j + 74, k + 71, Blocks.leaves, 12);
		setBlock(world, i + 13, j + 74, k + 72, Blocks.leaves, 12);
		setBlock(world, i + 13, j + 74, k + 75, Blocks.leaves, 12);
		setBlock(world, i + 13, j + 74, k + 76, Blocks.leaves, 12);
		setBlock(world, i + 13, j + 74, k + 77, Blocks.leaves, 12);
		setBlock(world, i + 13, j + 74, k + 78, Blocks.leaves, 12);
		setBlock(world, i + 13, j + 74, k + 90, Blocks.leaves, 12);
		setBlock(world, i + 13, j + 74, k + 91, Blocks.leaves, 12);
		setBlock(world, i + 13, j + 74, k + 92, Blocks.leaves, 12);
		setBlock(world, i + 13, j + 74, k + 93, Blocks.leaves, 12);
		setBlock(world, i + 13, j + 75, k + 76, Blocks.leaves, 12);
		setBlock(world, i + 13, j + 75, k + 77, Blocks.leaves, 12);
		setBlock(world, i + 13, j + 75, k + 78, Blocks.leaves, 12);
		setBlock(world, i + 13, j + 75, k + 91, Blocks.leaves, 12);
		setBlock(world, i + 13, j + 75, k + 92, Blocks.leaves, 12);
		setBlock(world, i + 13, j + 75, k + 93, Blocks.leaves, 12);
		setBlock(world, i + 13, j + 76, k + 77, Blocks.leaves, 12);
		setBlock(world, i + 13, j + 76, k + 92, Blocks.leaves, 12);
		setBlock(world, i + 14, j + 57, k + 65, Blocks.log, 1);
		setBlock(world, i + 14, j + 57, k + 66, Blocks.log, 1);
		setBlock(world, i + 14, j + 58, k + 64, Blocks.log, 1);
		setBlock(world, i + 14, j + 58, k + 66, Blocks.log, 1);
		setBlock(world, i + 14, j + 59, k + 64, Blocks.log, 1);
		setBlock(world, i + 14, j + 59, k + 66, Blocks.log, 1);
		setBlock(world, i + 14, j + 60, k + 64, Blocks.log, 1);
		setBlock(world, i + 14, j + 60, k + 65, Blocks.log, 1);
		setBlock(world, i + 14, j + 60, k + 66, Blocks.log, 1);
		setBlock(world, i + 14, j + 61, k + 65, Blocks.log, 1);
		setBlock(world, i + 14, j + 61, k + 66, Blocks.log, 1);
		setBlock(world, i + 14, j + 62, k + 66, Blocks.log, 1);
		setBlock(world, i + 14, j + 66, k + 45, Blocks.leaves, 12);
		setBlock(world, i + 14, j + 66, k + 46, Blocks.leaves, 12);
		setBlock(world, i + 14, j + 66, k + 47, Blocks.leaves, 12);
		setBlock(world, i + 14, j + 67, k + 45, Blocks.leaves, 12);
		setBlock(world, i + 14, j + 67, k + 46, Blocks.leaves, 12);
		setBlock(world, i + 14, j + 67, k + 47, Blocks.leaves, 12);
		setBlock(world, i + 14, j + 67, k + 48, Blocks.leaves, 12);
		setBlock(world, i + 14, j + 67, k + 50, Blocks.leaves, 12);
		setBlock(world, i + 14, j + 67, k + 51, Blocks.leaves, 12);
		setBlock(world, i + 14, j + 67, k + 52, Blocks.leaves, 12);
		setBlock(world, i + 14, j + 67, k + 53, Blocks.leaves, 12);
		setBlock(world, i + 14, j + 67, k + 54, Blocks.leaves, 12);
		setBlock(world, i + 14, j + 67, k + 55, Blocks.leaves, 12);
		setBlock(world, i + 14, j + 67, k + 56, Blocks.leaves, 12);
		setBlock(world, i + 14, j + 67, k + 78, Blocks.leaves, 12);
		setBlock(world, i + 14, j + 67, k + 79, Blocks.leaves, 12);
		setBlock(world, i + 14, j + 67, k + 80, Blocks.leaves, 12);
