package com.DavidM1A2.AfraidOfTheDark.worldGeneration;

import java.util.Random;

import net.minecraft.block.Block;
import net.minecraft.init.Blocks;
import net.minecraft.tileentity.TileEntity;
import net.minecraft.tileentity.TileEntityChest;
import net.minecraft.tileentity.TileEntityMobSpawner;
import net.minecraft.util.BlockPos;
import net.minecraft.util.WeightedRandomChestContent;
import net.minecraft.world.World;

import com.DavidM1A2.AfraidOfTheDark.initializeMod.ModBlocks;

public class CryptModel
{
	private TileEntityChest tileentitychest;

	public void setBlock(World world, int x, int y, int z, Block block, int metadata)
	{
		world.setBlockState(new BlockPos(x, y, z), block.getStateFromMeta(metadata));
	}

	public void setBlockSpawner(World world, int x, int y, int z, Block block, String type)
	{
		world.setBlockState(new BlockPos(x, y, z), Blocks.mob_spawner.getDefaultState(), 2);
		TileEntity tileentity = world.getTileEntity(new BlockPos(x, y, z));

		if (tileentity instanceof TileEntityMobSpawner)
		{
			((TileEntityMobSpawner) tileentity).getSpawnerBaseLogic().setEntityName(type);
		}
	}

	public boolean generate(World world, Random rand, int i, int j, int k)
	{
		this.setBlock(world, i + 0, j + 0, k + 5, Blocks.stonebrick, 3);
		this.setBlock(world, i + 0, j + 0, k + 6, Blocks.stonebrick, 3);
		this.setBlock(world, i + 0, j + 0, k + 7, Blocks.stonebrick, 3);
		this.setBlock(world, i + 0, j + 0, k + 8, Blocks.stonebrick, 3);
		this.setBlock(world, i + 0, j + 0, k + 9, Blocks.stonebrick, 3);
		this.setBlock(world, i + 0, j + 0, k + 13, Blocks.stonebrick, 3);
		this.setBlock(world, i + 0, j + 0, k + 14, Blocks.stonebrick, 3);
		this.setBlock(world, i + 0, j + 0, k + 15, Blocks.stonebrick, 3);
		this.setBlock(world, i + 0, j + 0, k + 16, Blocks.stonebrick, 3);
		this.setBlock(world, i + 0, j + 0, k + 17, Blocks.stonebrick, 3);
		this.setBlock(world, i + 0, j + 0, k + 21, Blocks.stonebrick, 3);
		this.setBlock(world, i + 0, j + 0, k + 22, Blocks.stonebrick, 3);
		this.setBlock(world, i + 0, j + 0, k + 23, Blocks.stonebrick, 3);
		this.setBlock(world, i + 0, j + 0, k + 24, Blocks.stonebrick, 3);
		this.setBlock(world, i + 0, j + 0, k + 25, Blocks.stonebrick, 3);
		this.setBlock(world, i + 0, j + 1, k + 5, Blocks.cobblestone, 0);
		this.setBlock(world, i + 0, j + 1, k + 6, Blocks.mossy_cobblestone, 0);
		this.setBlock(world, i + 0, j + 1, k + 7, Blocks.cobblestone, 0);
		this.setBlock(world, i + 0, j + 1, k + 8, Blocks.mossy_cobblestone, 0);
		this.setBlock(world, i + 0, j + 1, k + 9, Blocks.cobblestone, 0);
		this.setBlock(world, i + 0, j + 1, k + 13, Blocks.cobblestone, 0);
		this.setBlock(world, i + 0, j + 1, k + 14, Blocks.mossy_cobblestone, 0);
		this.setBlock(world, i + 0, j + 1, k + 15, Blocks.cobblestone, 0);
		this.setBlock(world, i + 0, j + 1, k + 16, Blocks.mossy_cobblestone, 0);
		this.setBlock(world, i + 0, j + 1, k + 17, Blocks.cobblestone, 0);
		this.setBlock(world, i + 0, j + 1, k + 21, Blocks.cobblestone, 0);
		this.setBlock(world, i + 0, j + 1, k + 22, Blocks.mossy_cobblestone, 0);
		this.setBlock(world, i + 0, j + 1, k + 23, Blocks.cobblestone, 0);
		this.setBlock(world, i + 0, j + 1, k + 24, Blocks.mossy_cobblestone, 0);
		this.setBlock(world, i + 0, j + 1, k + 25, Blocks.cobblestone, 0);
		this.setBlock(world, i + 0, j + 2, k + 5, Blocks.mossy_cobblestone, 0);
		this.setBlock(world, i + 0, j + 2, k + 6, Blocks.mossy_cobblestone, 0);
		this.setBlock(world, i + 0, j + 2, k + 7, Blocks.cobblestone, 0);
		this.setBlock(world, i + 0, j + 2, k + 8, Blocks.cobblestone, 0);
		this.setBlock(world, i + 0, j + 2, k + 9, Blocks.mossy_cobblestone, 0);
		this.setBlock(world, i + 0, j + 2, k + 13, Blocks.mossy_cobblestone, 0);
		this.setBlock(world, i + 0, j + 2, k + 14, Blocks.mossy_cobblestone, 0);
		this.setBlock(world, i + 0, j + 2, k + 15, Blocks.cobblestone, 0);
		this.setBlock(world, i + 0, j + 2, k + 16, Blocks.cobblestone, 0);
		this.setBlock(world, i + 0, j + 2, k + 17, Blocks.mossy_cobblestone, 0);
		this.setBlock(world, i + 0, j + 2, k + 21, Blocks.mossy_cobblestone, 0);
		this.setBlock(world, i + 0, j + 2, k + 22, Blocks.mossy_cobblestone, 0);
		this.setBlock(world, i + 0, j + 2, k + 23, Blocks.cobblestone, 0);
		this.setBlock(world, i + 0, j + 2, k + 24, Blocks.cobblestone, 0);
		this.setBlock(world, i + 0, j + 2, k + 25, Blocks.mossy_cobblestone, 0);
		this.setBlock(world, i + 0, j + 3, k + 5, Blocks.cobblestone, 0);
		this.setBlock(world, i + 0, j + 3, k + 6, Blocks.cobblestone, 0);
		this.setBlock(world, i + 0, j + 3, k + 7, Blocks.mossy_cobblestone, 0);
		this.setBlock(world, i + 0, j + 3, k + 8, Blocks.mossy_cobblestone, 0);
		this.setBlock(world, i + 0, j + 3, k + 9, Blocks.cobblestone, 0);
		this.setBlock(world, i + 0, j + 3, k + 13, Blocks.cobblestone, 0);
		this.setBlock(world, i + 0, j + 3, k + 14, Blocks.cobblestone, 0);
		this.setBlock(world, i + 0, j + 3, k + 15, Blocks.mossy_cobblestone, 0);
		this.setBlock(world, i + 0, j + 3, k + 16, Blocks.mossy_cobblestone, 0);
		this.setBlock(world, i + 0, j + 3, k + 17, Blocks.cobblestone, 0);
		this.setBlock(world, i + 0, j + 3, k + 21, Blocks.cobblestone, 0);
		this.setBlock(world, i + 0, j + 3, k + 22, Blocks.cobblestone, 0);
		this.setBlock(world, i + 0, j + 3, k + 23, Blocks.mossy_cobblestone, 0);
		this.setBlock(world, i + 0, j + 3, k + 24, Blocks.mossy_cobblestone, 0);
		this.setBlock(world, i + 0, j + 3, k + 25, Blocks.cobblestone, 0);
		this.setBlock(world, i + 0, j + 4, k + 5, Blocks.mossy_cobblestone, 0);
		this.setBlock(world, i + 0, j + 4, k + 6, Blocks.cobblestone, 0);
		this.setBlock(world, i + 0, j + 4, k + 7, Blocks.mossy_cobblestone, 0);
		this.setBlock(world, i + 0, j + 4, k + 8, Blocks.mossy_cobblestone, 0);
		this.setBlock(world, i + 0, j + 4, k + 9, Blocks.cobblestone, 0);
		this.setBlock(world, i + 0, j + 4, k + 13, Blocks.mossy_cobblestone, 0);
		this.setBlock(world, i + 0, j + 4, k + 14, Blocks.cobblestone, 0);
		this.setBlock(world, i + 0, j + 4, k + 15, Blocks.mossy_cobblestone, 0);
		this.setBlock(world, i + 0, j + 4, k + 16, Blocks.mossy_cobblestone, 0);
		this.setBlock(world, i + 0, j + 4, k + 17, Blocks.cobblestone, 0);
		this.setBlock(world, i + 0, j + 4, k + 21, Blocks.mossy_cobblestone, 0);
		this.setBlock(world, i + 0, j + 4, k + 22, Blocks.cobblestone, 0);
		this.setBlock(world, i + 0, j + 4, k + 23, Blocks.mossy_cobblestone, 0);
		this.setBlock(world, i + 0, j + 4, k + 24, Blocks.mossy_cobblestone, 0);
		this.setBlock(world, i + 0, j + 4, k + 25, Blocks.cobblestone, 0);
		this.setBlock(world, i + 0, j + 5, k + 6, Blocks.cobblestone, 0);
		this.setBlock(world, i + 0, j + 5, k + 7, Blocks.cobblestone, 0);
		this.setBlock(world, i + 0, j + 5, k + 8, Blocks.mossy_cobblestone, 0);
		this.setBlock(world, i + 0, j + 5, k + 14, Blocks.cobblestone, 0);
		this.setBlock(world, i + 0, j + 5, k + 15, Blocks.cobblestone, 0);
		this.setBlock(world, i + 0, j + 5, k + 16, Blocks.mossy_cobblestone, 0);
		this.setBlock(world, i + 0, j + 5, k + 22, Blocks.cobblestone, 0);
		this.setBlock(world, i + 0, j + 5, k + 23, Blocks.cobblestone, 0);
		this.setBlock(world, i + 0, j + 5, k + 24, Blocks.mossy_cobblestone, 0);
		this.setBlock(world, i + 1, j + 0, k + 4, Blocks.stonebrick, 3);
		this.setBlock(world, i + 1, j + 0, k + 5, Blocks.stonebrick, 3);
		this.setBlock(world, i + 1, j + 0, k + 6, Blocks.stonebrick, 3);
		this.setBlock(world, i + 1, j + 0, k + 7, Blocks.stonebrick, 3);
		this.setBlock(world, i + 1, j + 0, k + 8, Blocks.stonebrick, 3);
		this.setBlock(world, i + 1, j + 0, k + 9, Blocks.stonebrick, 3);
		this.setBlock(world, i + 1, j + 0, k + 10, Blocks.stonebrick, 3);
		this.setBlock(world, i + 1, j + 0, k + 12, Blocks.stonebrick, 3);
		this.setBlock(world, i + 1, j + 0, k + 13, Blocks.stonebrick, 3);
		this.setBlock(world, i + 1, j + 0, k + 14, Blocks.stonebrick, 3);
		this.setBlock(world, i + 1, j + 0, k + 15, Blocks.stonebrick, 3);
		this.setBlock(world, i + 1, j + 0, k + 16, Blocks.stonebrick, 3);
		this.setBlock(world, i + 1, j + 0, k + 17, Blocks.stonebrick, 3);
		this.setBlock(world, i + 1, j + 0, k + 18, Blocks.stonebrick, 3);
		this.setBlock(world, i + 1, j + 0, k + 20, Blocks.stonebrick, 3);
		this.setBlock(world, i + 1, j + 0, k + 21, Blocks.stonebrick, 3);
		this.setBlock(world, i + 1, j + 0, k + 22, Blocks.stonebrick, 3);
		this.setBlock(world, i + 1, j + 0, k + 23, Blocks.stonebrick, 3);
		this.setBlock(world, i + 1, j + 0, k + 24, Blocks.stonebrick, 3);
		this.setBlock(world, i + 1, j + 0, k + 25, Blocks.stonebrick, 3);
		this.setBlock(world, i + 1, j + 0, k + 26, Blocks.stonebrick, 3);
		this.setBlock(world, i + 1, j + 1, k + 4, Blocks.mossy_cobblestone, 0);
		this.setBlock(world, i + 1, j + 1, k + 5, ModBlocks.gravewoodStairs, 5);
		this.setBlock(world, i + 1, j + 1, k + 6, ModBlocks.gravewoodStairs, 5);
		this.setBlock(world, i + 1, j + 1, k + 7, ModBlocks.gravewoodStairs, 5);
		this.setBlock(world, i + 1, j + 1, k + 8, ModBlocks.gravewoodStairs, 5);
		this.setBlock(world, i + 1, j + 1, k + 9, ModBlocks.gravewoodStairs, 5);
		this.setBlock(world, i + 1, j + 1, k + 10, Blocks.mossy_cobblestone, 0);
		this.setBlock(world, i + 1, j + 1, k + 12, Blocks.mossy_cobblestone, 0);
		this.setBlock(world, i + 1, j + 1, k + 13, ModBlocks.gravewoodStairs, 5);
		this.setBlock(world, i + 1, j + 1, k + 14, ModBlocks.gravewoodStairs, 5);
		this.setBlock(world, i + 1, j + 1, k + 15, ModBlocks.gravewoodStairs, 5);
		this.setBlock(world, i + 1, j + 1, k + 16, ModBlocks.gravewoodStairs, 5);
		this.setBlock(world, i + 1, j + 1, k + 17, ModBlocks.gravewoodStairs, 5);
		this.setBlock(world, i + 1, j + 1, k + 18, Blocks.mossy_cobblestone, 0);
		this.setBlock(world, i + 1, j + 1, k + 20, Blocks.mossy_cobblestone, 0);
		this.setBlock(world, i + 1, j + 1, k + 21, ModBlocks.gravewoodStairs, 5);
		this.setBlock(world, i + 1, j + 1, k + 22, ModBlocks.gravewoodStairs, 5);
		this.setBlock(world, i + 1, j + 1, k + 23, ModBlocks.gravewoodStairs, 5);
		this.setBlock(world, i + 1, j + 1, k + 24, ModBlocks.gravewoodStairs, 5);
		this.setBlock(world, i + 1, j + 1, k + 25, ModBlocks.gravewoodStairs, 5);
		this.setBlock(world, i + 1, j + 1, k + 26, Blocks.mossy_cobblestone, 0);
		this.setBlock(world, i + 1, j + 2, k + 4, Blocks.mossy_cobblestone, 0);
		this.setBlock(world, i + 1, j + 2, k + 5, Blocks.chest, 5);
		tileentitychest = (TileEntityChest) world.getTileEntity(new BlockPos(i + 1, j + 2, k + 5));
		if (tileentitychest != null)
		{
			WeightedRandomChestContent.generateChestContents(new Random(), GraveyardChestLoot.getItems(new Random()), tileentitychest, 1);
		}
		this.setBlock(world, i + 1, j + 2, k + 6, Blocks.chest, 5);
		tileentitychest = (TileEntityChest) world.getTileEntity(new BlockPos(i + 1, j + 2, k + 6));
		if (tileentitychest != null)
		{
			WeightedRandomChestContent.generateChestContents(new Random(), GraveyardChestLoot.getItems(new Random()), tileentitychest, 1);
		}
		this.setBlock(world, i + 1, j + 2, k + 7, Blocks.air, 0);
		this.setBlock(world, i + 1, j + 2, k + 8, Blocks.chest, 5);
		tileentitychest = (TileEntityChest) world.getTileEntity(new BlockPos(i + 1, j + 2, k + 8));
		if (tileentitychest != null)
		{
			WeightedRandomChestContent.generateChestContents(new Random(), GraveyardChestLoot.getItems(new Random()), tileentitychest, 1);
		}
		this.setBlock(world, i + 1, j + 2, k + 9, Blocks.chest, 5);
		tileentitychest = (TileEntityChest) world.getTileEntity(new BlockPos(i + 1, j + 2, k + 9));
		if (tileentitychest != null)
		{
			WeightedRandomChestContent.generateChestContents(new Random(), GraveyardChestLoot.getItems(new Random()), tileentitychest, 1);
		}
		this.setBlock(world, i + 1, j + 2, k + 10, Blocks.cobblestone, 0);
		this.setBlock(world, i + 1, j + 2, k + 12, Blocks.mossy_cobblestone, 0);
		this.setBlock(world, i + 1, j + 2, k + 13, Blocks.chest, 5);
		tileentitychest = (TileEntityChest) world.getTileEntity(new BlockPos(i + 1, j + 2, k + 13));
		if (tileentitychest != null)
		{
			WeightedRandomChestContent.generateChestContents(new Random(), GraveyardChestLoot.getItems(new Random()), tileentitychest, 1);
		}
		this.setBlock(world, i + 1, j + 2, k + 14, Blocks.chest, 5);
		tileentitychest = (TileEntityChest) world.getTileEntity(new BlockPos(i + 1, j + 2, k + 14));
		if (tileentitychest != null)
		{
			WeightedRandomChestContent.generateChestContents(new Random(), GraveyardChestLoot.getItems(new Random()), tileentitychest, 1);
		}
		this.setBlock(world, i + 1, j + 2, k + 15, Blocks.air, 0);
		this.setBlock(world, i + 1, j + 2, k + 16, Blocks.chest, 5);
		tileentitychest = (TileEntityChest) world.getTileEntity(new BlockPos(i + 1, j + 2, k + 16));
		if (tileentitychest != null)
		{
			WeightedRandomChestContent.generateChestContents(new Random(), GraveyardChestLoot.getItems(new Random()), tileentitychest, 1);
		}
		this.setBlock(world, i + 1, j + 2, k + 17, Blocks.chest, 5);
		tileentitychest = (TileEntityChest) world.getTileEntity(new BlockPos(i + 1, j + 2, k + 17));
		if (tileentitychest != null)
		{
			WeightedRandomChestContent.generateChestContents(new Random(), GraveyardChestLoot.getItems(new Random()), tileentitychest, 1);
		}
		this.setBlock(world, i + 1, j + 2, k + 18, Blocks.cobblestone, 0);
		this.setBlock(world, i + 1, j + 2, k + 20, Blocks.mossy_cobblestone, 0);
		this.setBlock(world, i + 1, j + 2, k + 21, Blocks.chest, 5);
		tileentitychest = (TileEntityChest) world.getTileEntity(new BlockPos(i + 1, j + 2, k + 21));
		if (tileentitychest != null)
		{
			WeightedRandomChestContent.generateChestContents(new Random(), GraveyardChestLoot.getItems(new Random()), tileentitychest, 1);
		}
		this.setBlock(world, i + 1, j + 2, k + 22, Blocks.chest, 5);
		tileentitychest = (TileEntityChest) world.getTileEntity(new BlockPos(i + 1, j + 2, k + 22));
		if (tileentitychest != null)
		{
			WeightedRandomChestContent.generateChestContents(new Random(), GraveyardChestLoot.getItems(new Random()), tileentitychest, 1);
		}
		this.setBlock(world, i + 1, j + 2, k + 23, Blocks.air, 0);
		this.setBlock(world, i + 1, j + 2, k + 24, Blocks.chest, 5);
		tileentitychest = (TileEntityChest) world.getTileEntity(new BlockPos(i + 1, j + 2, k + 24));
		if (tileentitychest != null)
		{
			WeightedRandomChestContent.generateChestContents(new Random(), GraveyardChestLoot.getItems(new Random()), tileentitychest, 1);
		}
		this.setBlock(world, i + 1, j + 2, k + 25, Blocks.chest, 5);
		tileentitychest = (TileEntityChest) world.getTileEntity(new BlockPos(i + 1, j + 2, k + 25));
		if (tileentitychest != null)
		{
			WeightedRandomChestContent.generateChestContents(new Random(), GraveyardChestLoot.getItems(new Random()), tileentitychest, 1);
		}
		this.setBlock(world, i + 1, j + 2, k + 26, Blocks.cobblestone, 0);
		this.setBlock(world, i + 1, j + 3, k + 4, Blocks.cobblestone, 0);
		this.setBlock(world, i + 1, j + 3, k + 5, Blocks.air, 0);
		this.setBlock(world, i + 1, j + 3, k + 6, Blocks.air, 0);
		this.setBlock(world, i + 1, j + 3, k + 7, Blocks.air, 0);
		this.setBlock(world, i + 1, j + 3, k + 8, Blocks.air, 0);
		this.setBlock(world, i + 1, j + 3, k + 9, Blocks.air, 0);
		this.setBlock(world, i + 1, j + 3, k + 10, Blocks.mossy_cobblestone, 0);
		this.setBlock(world, i + 1, j + 3, k + 12, Blocks.cobblestone, 0);
		this.setBlock(world, i + 1, j + 3, k + 13, Blocks.air, 0);
		this.setBlock(world, i + 1, j + 3, k + 14, Blocks.air, 0);
		this.setBlock(world, i + 1, j + 3, k + 15, Blocks.air, 0);
		this.setBlock(world, i + 1, j + 3, k + 16, Blocks.air, 0);
		this.setBlock(world, i + 1, j + 3, k + 17, Blocks.air, 0);
		this.setBlock(world, i + 1, j + 3, k + 18, Blocks.mossy_cobblestone, 0);
		this.setBlock(world, i + 1, j + 3, k + 20, Blocks.cobblestone, 0);
		this.setBlock(world, i + 1, j + 3, k + 21, Blocks.air, 0);
		this.setBlock(world, i + 1, j + 3, k + 22, Blocks.air, 0);
		this.setBlock(world, i + 1, j + 3, k + 23, Blocks.air, 0);
		this.setBlock(world, i + 1, j + 3, k + 24, Blocks.air, 0);
		this.setBlock(world, i + 1, j + 3, k + 25, Blocks.air, 0);
		this.setBlock(world, i + 1, j + 3, k + 26, Blocks.mossy_cobblestone, 0);
		this.setBlock(world, i + 1, j + 4, k + 4, Blocks.mossy_cobblestone, 0);
		this.setBlock(world, i + 1, j + 4, k + 5, Blocks.stone_stairs, 7);
		this.setBlock(world, i + 1, j + 4, k + 6, Blocks.air, 0);
		this.setBlock(world, i + 1, j + 4, k + 7, Blocks.air, 0);
		this.setBlock(world, i + 1, j + 4, k + 8, Blocks.air, 0);
		this.setBlock(world, i + 1, j + 4, k + 9, Blocks.stone_stairs, 6);
		this.setBlock(world, i + 1, j + 4, k + 10, Blocks.mossy_cobblestone, 0);
		this.setBlock(world, i + 1, j + 4, k + 12, Blocks.mossy_cobblestone, 0);
		this.setBlock(world, i + 1, j + 4, k + 13, Blocks.stone_stairs, 7);
		this.setBlock(world, i + 1, j + 4, k + 14, Blocks.air, 0);
		this.setBlock(world, i + 1, j + 4, k + 15, Blocks.air, 0);
		this.setBlock(world, i + 1, j + 4, k + 16, Blocks.air, 0);
		this.setBlock(world, i + 1, j + 4, k + 17, Blocks.stone_stairs, 6);
		this.setBlock(world, i + 1, j + 4, k + 18, Blocks.mossy_cobblestone, 0);
		this.setBlock(world, i + 1, j + 4, k + 20, Blocks.mossy_cobblestone, 0);
		this.setBlock(world, i + 1, j + 4, k + 21, Blocks.stone_stairs, 7);
		this.setBlock(world, i + 1, j + 4, k + 22, Blocks.air, 0);
		this.setBlock(world, i + 1, j + 4, k + 23, Blocks.air, 0);
		this.setBlock(world, i + 1, j + 4, k + 24, Blocks.air, 0);
		this.setBlock(world, i + 1, j + 4, k + 25, Blocks.stone_stairs, 6);
		this.setBlock(world, i + 1, j + 4, k + 26, Blocks.mossy_cobblestone, 0);
		this.setBlock(world, i + 1, j + 5, k + 5, Blocks.mossy_cobblestone, 0);
		this.setBlock(world, i + 1, j + 5, k + 6, Blocks.stone_stairs, 7);
		this.setBlock(world, i + 1, j + 5, k + 7, Blocks.air, 0);
		this.setBlock(world, i + 1, j + 5, k + 8, Blocks.stone_stairs, 6);
		this.setBlock(world, i + 1, j + 5, k + 9, Blocks.cobblestone, 0);
		this.setBlock(world, i + 1, j + 5, k + 13, Blocks.mossy_cobblestone, 0);
		this.setBlock(world, i + 1, j + 5, k + 14, Blocks.stone_stairs, 7);
		this.setBlock(world, i + 1, j + 5, k + 15, Blocks.air, 0);
		this.setBlock(world, i + 1, j + 5, k + 16, Blocks.stone_stairs, 6);
		this.setBlock(world, i + 1, j + 5, k + 17, Blocks.cobblestone, 0);
		this.setBlock(world, i + 1, j + 5, k + 21, Blocks.mossy_cobblestone, 0);
		this.setBlock(world, i + 1, j + 5, k + 22, Blocks.stone_stairs, 7);
		this.setBlock(world, i + 1, j + 5, k + 23, Blocks.air, 0);
		this.setBlock(world, i + 1, j + 5, k + 24, Blocks.stone_stairs, 6);
		this.setBlock(world, i + 1, j + 5, k + 25, Blocks.cobblestone, 0);
		this.setBlock(world, i + 1, j + 6, k + 6, Blocks.mossy_cobblestone, 0);
		this.setBlock(world, i + 1, j + 6, k + 7, Blocks.glowstone, 0);
		this.setBlock(world, i + 1, j + 6, k + 8, Blocks.mossy_cobblestone, 0);
		this.setBlock(world, i + 1, j + 6, k + 14, Blocks.mossy_cobblestone, 0);
		this.setBlock(world, i + 1, j + 6, k + 15, Blocks.glowstone, 0);
		this.setBlock(world, i + 1, j + 6, k + 16, Blocks.mossy_cobblestone, 0);
		this.setBlock(world, i + 1, j + 6, k + 22, Blocks.mossy_cobblestone, 0);
		this.setBlock(world, i + 1, j + 6, k + 23, Blocks.glowstone, 0);
		this.setBlock(world, i + 1, j + 6, k + 24, Blocks.mossy_cobblestone, 0);
		this.setBlock(world, i + 2, j + 0, k + 3, Blocks.stonebrick, 3);
		this.setBlock(world, i + 2, j + 0, k + 4, Blocks.stonebrick, 3);
		this.setBlock(world, i + 2, j + 0, k + 5, Blocks.stonebrick, 3);
		this.setBlock(world, i + 2, j + 0, k + 6, Blocks.stonebrick, 3);
		this.setBlock(world, i + 2, j + 0, k + 7, Blocks.stonebrick, 3);
		this.setBlock(world, i + 2, j + 0, k + 8, Blocks.stonebrick, 3);
		this.setBlock(world, i + 2, j + 0, k + 9, Blocks.stonebrick, 3);
		this.setBlock(world, i + 2, j + 0, k + 10, Blocks.stonebrick, 3);
		this.setBlock(world, i + 2, j + 0, k + 11, Blocks.stonebrick, 3);
		this.setBlock(world, i + 2, j + 0, k + 12, Blocks.stonebrick, 3);
		this.setBlock(world, i + 2, j + 0, k + 13, Blocks.stonebrick, 3);
		this.setBlock(world, i + 2, j + 0, k + 14, Blocks.stonebrick, 3);
		this.setBlock(world, i + 2, j + 0, k + 15, Blocks.stonebrick, 3);
		this.setBlock(world, i + 2, j + 0, k + 16, Blocks.stonebrick, 3);
		this.setBlock(world, i + 2, j + 0, k + 17, Blocks.stonebrick, 3);
		this.setBlock(world, i + 2, j + 0, k + 18, Blocks.stonebrick, 3);
		this.setBlock(world, i + 2, j + 0, k + 19, Blocks.stonebrick, 3);
		this.setBlock(world, i + 2, j + 0, k + 20, Blocks.stonebrick, 3);
		this.setBlock(world, i + 2, j + 0, k + 21, Blocks.stonebrick, 3);
		this.setBlock(world, i + 2, j + 0, k + 22, Blocks.stonebrick, 3);
		this.setBlock(world, i + 2, j + 0, k + 23, Blocks.stonebrick, 3);
		this.setBlock(world, i + 2, j + 0, k + 24, Blocks.stonebrick, 3);
		this.setBlock(world, i + 2, j + 0, k + 25, Blocks.stonebrick, 3);
		this.setBlock(world, i + 2, j + 0, k + 26, Blocks.stonebrick, 3);
		this.setBlock(world, i + 2, j + 0, k + 27, Blocks.stonebrick, 3);
		this.setBlock(world, i + 2, j + 1, k + 3, Blocks.cobblestone, 0);
		this.setBlock(world, i + 2, j + 1, k + 4, Blocks.air, 0);
		this.setBlock(world, i + 2, j + 1, k + 5, Blocks.air, 0);
		this.setBlock(world, i + 2, j + 1, k + 6, Blocks.air, 0);
		this.setBlock(world, i + 2, j + 1, k + 7, Blocks.air, 0);
		this.setBlock(world, i + 2, j + 1, k + 8, Blocks.air, 0);
		this.setBlock(world, i + 2, j + 1, k + 9, Blocks.air, 0);
		this.setBlock(world, i + 2, j + 1, k + 10, Blocks.air, 0);
		this.setBlock(world, i + 2, j + 1, k + 11, Blocks.cobblestone, 0);
		this.setBlock(world, i + 2, j + 1, k + 12, Blocks.air, 0);
		this.setBlock(world, i + 2, j + 1, k + 13, Blocks.air, 0);
		this.setBlock(world, i + 2, j + 1, k + 14, Blocks.air, 0);
		this.setBlock(world, i + 2, j + 1, k + 15, Blocks.air, 0);
		this.setBlock(world, i + 2, j + 1, k + 16, Blocks.air, 0);
		this.setBlock(world, i + 2, j + 1, k + 17, Blocks.air, 0);
		this.setBlock(world, i + 2, j + 1, k + 18, Blocks.air, 0);
		this.setBlock(world, i + 2, j + 1, k + 19, Blocks.cobblestone, 0);
		this.setBlock(world, i + 2, j + 1, k + 20, Blocks.air, 0);
		this.setBlock(world, i + 2, j + 1, k + 21, Blocks.air, 0);
		this.setBlock(world, i + 2, j + 1, k + 22, Blocks.air, 0);
		this.setBlock(world, i + 2, j + 1, k + 23, Blocks.air, 0);
		this.setBlock(world, i + 2, j + 1, k + 24, Blocks.air, 0);
		this.setBlock(world, i + 2, j + 1, k + 25, Blocks.air, 0);
		this.setBlock(world, i + 2, j + 1, k + 26, Blocks.air, 0);
		this.setBlock(world, i + 2, j + 1, k + 27, Blocks.mossy_cobblestone, 0);
		this.setBlock(world, i + 2, j + 2, k + 3, Blocks.mossy_cobblestone, 0);
		this.setBlock(world, i + 2, j + 2, k + 4, Blocks.air, 0);
		this.setBlock(world, i + 2, j + 2, k + 5, Blocks.air, 0);
		this.setBlock(world, i + 2, j + 2, k + 6, Blocks.air, 0);
		this.setBlock(world, i + 2, j + 2, k + 7, Blocks.air, 0);
		this.setBlock(world, i + 2, j + 2, k + 8, Blocks.air, 0);
		this.setBlock(world, i + 2, j + 2, k + 9, Blocks.air, 0);
		this.setBlock(world, i + 2, j + 2, k + 10, Blocks.air, 0);
		this.setBlock(world, i + 2, j + 2, k + 11, Blocks.mossy_cobblestone, 0);
		this.setBlock(world, i + 2, j + 2, k + 12, Blocks.air, 0);
		this.setBlock(world, i + 2, j + 2, k + 13, Blocks.air, 0);
		this.setBlock(world, i + 2, j + 2, k + 14, Blocks.air, 0);
		this.setBlock(world, i + 2, j + 2, k + 15, Blocks.air, 0);
		this.setBlock(world, i + 2, j + 2, k + 16, Blocks.air, 0);
		this.setBlock(world, i + 2, j + 2, k + 17, Blocks.air, 0);
		this.setBlock(world, i + 2, j + 2, k + 18, Blocks.air, 0);
		this.setBlock(world, i + 2, j + 2, k + 19, Blocks.mossy_cobblestone, 0);
		this.setBlock(world, i + 2, j + 2, k + 20, Blocks.air, 0);
		this.setBlock(world, i + 2, j + 2, k + 21, Blocks.air, 0);
		this.setBlock(world, i + 2, j + 2, k + 22, Blocks.air, 0);
		this.setBlock(world, i + 2, j + 2, k + 23, Blocks.air, 0);
		this.setBlock(world, i + 2, j + 2, k + 24, Blocks.air, 0);
		this.setBlock(world, i + 2, j + 2, k + 25, Blocks.air, 0);
		this.setBlock(world, i + 2, j + 2, k + 26, Blocks.air, 0);
		this.setBlock(world, i + 2, j + 2, k + 27, Blocks.cobblestone, 0);
		this.setBlock(world, i + 2, j + 3, k + 3, Blocks.mossy_cobblestone, 0);
		this.setBlock(world, i + 2, j + 3, k + 4, Blocks.air, 0);
		this.setBlock(world, i + 2, j + 3, k + 5, Blocks.air, 0);
		this.setBlock(world, i + 2, j + 3, k + 6, Blocks.air, 0);
		this.setBlock(world, i + 2, j + 3, k + 7, Blocks.air, 0);
		this.setBlock(world, i + 2, j + 3, k + 8, Blocks.air, 0);
		this.setBlock(world, i + 2, j + 3, k + 9, Blocks.air, 0);
		this.setBlock(world, i + 2, j + 3, k + 10, Blocks.air, 0);
		this.setBlock(world, i + 2, j + 3, k + 11, Blocks.mossy_cobblestone, 0);
		this.setBlock(world, i + 2, j + 3, k + 12, Blocks.air, 0);
		this.setBlock(world, i + 2, j + 3, k + 13, Blocks.air, 0);
		this.setBlock(world, i + 2, j + 3, k + 14, Blocks.air, 0);
		this.setBlock(world, i + 2, j + 3, k + 15, Blocks.air, 0);
		this.setBlock(world, i + 2, j + 3, k + 16, Blocks.air, 0);
		this.setBlock(world, i + 2, j + 3, k + 17, Blocks.air, 0);
		this.setBlock(world, i + 2, j + 3, k + 18, Blocks.air, 0);
		this.setBlock(world, i + 2, j + 3, k + 19, Blocks.mossy_cobblestone, 0);
		this.setBlock(world, i + 2, j + 3, k + 20, Blocks.air, 0);
		this.setBlock(world, i + 2, j + 3, k + 21, Blocks.air, 0);
		this.setBlock(world, i + 2, j + 3, k + 22, Blocks.air, 0);
		this.setBlock(world, i + 2, j + 3, k + 23, Blocks.air, 0);
		this.setBlock(world, i + 2, j + 3, k + 24, Blocks.air, 0);
		this.setBlock(world, i + 2, j + 3, k + 25, Blocks.air, 0);
		this.setBlock(world, i + 2, j + 3, k + 26, Blocks.air, 0);
		this.setBlock(world, i + 2, j + 3, k + 27, Blocks.mossy_cobblestone, 0);
		this.setBlock(world, i + 2, j + 4, k + 3, Blocks.cobblestone, 0);
		this.setBlock(world, i + 2, j + 4, k + 4, Blocks.stone_stairs, 7);
		this.setBlock(world, i + 2, j + 4, k + 5, Blocks.air, 0);
		this.setBlock(world, i + 2, j + 4, k + 6, Blocks.air, 0);
		this.setBlock(world, i + 2, j + 4, k + 7, Blocks.air, 0);
		this.setBlock(world, i + 2, j + 4, k + 8, Blocks.air, 0);
		this.setBlock(world, i + 2, j + 4, k + 9, Blocks.air, 0);
		this.setBlock(world, i + 2, j + 4, k + 10, Blocks.stone_stairs, 6);
		this.setBlock(world, i + 2, j + 4, k + 11, Blocks.cobblestone, 0);
		this.setBlock(world, i + 2, j + 4, k + 12, Blocks.stone_stairs, 7);
		this.setBlock(world, i + 2, j + 4, k + 13, Blocks.air, 0);
		this.setBlock(world, i + 2, j + 4, k + 14, Blocks.air, 0);
		this.setBlock(world, i + 2, j + 4, k + 15, Blocks.air, 0);
		this.setBlock(world, i + 2, j + 4, k + 16, Blocks.air, 0);
		this.setBlock(world, i + 2, j + 4, k + 17, Blocks.air, 0);
		this.setBlock(world, i + 2, j + 4, k + 18, Blocks.stone_stairs, 6);
		this.setBlock(world, i + 2, j + 4, k + 19, Blocks.cobblestone, 0);
		this.setBlock(world, i + 2, j + 4, k + 20, Blocks.stone_stairs, 7);
		this.setBlock(world, i + 2, j + 4, k + 21, Blocks.air, 0);
		this.setBlock(world, i + 2, j + 4, k + 22, Blocks.air, 0);
		this.setBlock(world, i + 2, j + 4, k + 23, Blocks.air, 0);
		this.setBlock(world, i + 2, j + 4, k + 24, Blocks.air, 0);
		this.setBlock(world, i + 2, j + 4, k + 25, Blocks.air, 0);
		this.setBlock(world, i + 2, j + 4, k + 26, Blocks.stone_stairs, 6);
		this.setBlock(world, i + 2, j + 4, k + 27, Blocks.mossy_cobblestone, 0);
		this.setBlock(world, i + 2, j + 5, k + 4, Blocks.cobblestone, 0);
		this.setBlock(world, i + 2, j + 5, k + 5, Blocks.stone_stairs, 7);
		this.setBlock(world, i + 2, j + 5, k + 6, Blocks.air, 0);
		this.setBlock(world, i + 2, j + 5, k + 7, Blocks.air, 0);
		this.setBlock(world, i + 2, j + 5, k + 8, Blocks.air, 0);
		this.setBlock(world, i + 2, j + 5, k + 9, Blocks.stone_stairs, 6);
		this.setBlock(world, i + 2, j + 5, k + 10, Blocks.cobblestone, 0);
		this.setBlock(world, i + 2, j + 5, k + 12, Blocks.cobblestone, 0);
		this.setBlock(world, i + 2, j + 5, k + 13, Blocks.stone_stairs, 7);
		this.setBlock(world, i + 2, j + 5, k + 14, Blocks.air, 0);
		this.setBlock(world, i + 2, j + 5, k + 15, Blocks.air, 0);
		this.setBlock(world, i + 2, j + 5, k + 16, Blocks.air, 0);
		this.setBlock(world, i + 2, j + 5, k + 17, Blocks.stone_stairs, 6);
		this.setBlock(world, i + 2, j + 5, k + 18, Blocks.cobblestone, 0);
		this.setBlock(world, i + 2, j + 5, k + 20, Blocks.cobblestone, 0);
		this.setBlock(world, i + 2, j + 5, k + 21, Blocks.stone_stairs, 7);
		this.setBlock(world, i + 2, j + 5, k + 22, Blocks.air, 0);
		this.setBlock(world, i + 2, j + 5, k + 23, Blocks.air, 0);
		this.setBlock(world, i + 2, j + 5, k + 24, Blocks.air, 0);
		this.setBlock(world, i + 2, j + 5, k + 25, Blocks.stone_stairs, 6);
		this.setBlock(world, i + 2, j + 5, k + 26, Blocks.cobblestone, 0);
		this.setBlock(world, i + 2, j + 6, k + 5, Blocks.cobblestone, 0);
		this.setBlock(world, i + 2, j + 6, k + 6, Blocks.stone_stairs, 7);
		this.setBlock(world, i + 2, j + 6, k + 7, ModBlocks.gravewoodStairs, 5);
		this.setBlock(world, i + 2, j + 6, k + 8, Blocks.stone_stairs, 6);
		this.setBlock(world, i + 2, j + 6, k + 9, Blocks.cobblestone, 0);
		this.setBlock(world, i + 2, j + 6, k + 13, Blocks.cobblestone, 0);
		this.setBlock(world, i + 2, j + 6, k + 14, Blocks.stone_stairs, 7);
		this.setBlock(world, i + 2, j + 6, k + 15, ModBlocks.gravewoodStairs, 5);
		this.setBlock(world, i + 2, j + 6, k + 16, Blocks.stone_stairs, 6);
		this.setBlock(world, i + 2, j + 6, k + 17, Blocks.cobblestone, 0);
		this.setBlock(world, i + 2, j + 6, k + 21, Blocks.cobblestone, 0);
		this.setBlock(world, i + 2, j + 6, k + 22, Blocks.stone_stairs, 7);
		this.setBlock(world, i + 2, j + 6, k + 23, ModBlocks.gravewoodStairs, 5);
		this.setBlock(world, i + 2, j + 6, k + 24, Blocks.stone_stairs, 6);
		this.setBlock(world, i + 2, j + 6, k + 25, Blocks.cobblestone, 0);
		this.setBlock(world, i + 2, j + 7, k + 6, Blocks.mossy_cobblestone, 0);
		this.setBlock(world, i + 2, j + 7, k + 7, Blocks.mossy_cobblestone, 0);
		this.setBlock(world, i + 2, j + 7, k + 8, Blocks.cobblestone, 0);
		this.setBlock(world, i + 2, j + 7, k + 14, Blocks.mossy_cobblestone, 0);
		this.setBlock(world, i + 2, j + 7, k + 15, Blocks.mossy_cobblestone, 0);
		this.setBlock(world, i + 2, j + 7, k + 16, Blocks.cobblestone, 0);
		this.setBlock(world, i + 2, j + 7, k + 22, Blocks.mossy_cobblestone, 0);
		this.setBlock(world, i + 2, j + 7, k + 23, Blocks.mossy_cobblestone, 0);
		this.setBlock(world, i + 2, j + 7, k + 24, Blocks.cobblestone, 0);
		this.setBlock(world, i + 3, j + 0, k + 2, Blocks.stonebrick, 3);
		this.setBlock(world, i + 3, j + 0, k + 3, Blocks.stonebrick, 3);
		this.setBlock(world, i + 3, j + 0, k + 4, Blocks.mycelium, 0);
		this.setBlock(world, i + 3, j + 0, k + 5, Blocks.mycelium, 0);
		this.setBlock(world, i + 3, j + 0, k + 6, Blocks.cobblestone, 0);
		this.setBlock(world, i + 3, j + 0, k + 7, Blocks.cobblestone, 0);
		this.setBlock(world, i + 3, j + 0, k + 8, Blocks.mycelium, 0);
		this.setBlock(world, i + 3, j + 0, k + 9, Blocks.mycelium, 0);
		this.setBlock(world, i + 3, j + 0, k + 10, Blocks.mycelium, 0);
		this.setBlock(world, i + 3, j + 0, k + 11, Blocks.stonebrick, 3);
		this.setBlock(world, i + 3, j + 0, k + 12, Blocks.mycelium, 0);
		this.setBlock(world, i + 3, j + 0, k + 13, Blocks.mycelium, 0);
		this.setBlock(world, i + 3, j + 0, k + 14, Blocks.mycelium, 0);
		this.setBlock(world, i + 3, j + 0, k + 15, Blocks.mycelium, 0);
		this.setBlock(world, i + 3, j + 0, k + 16, Blocks.mycelium, 0);
		this.setBlock(world, i + 3, j + 0, k + 17, Blocks.mycelium, 0);
		this.setBlock(world, i + 3, j + 0, k + 18, Blocks.mycelium, 0);
		this.setBlock(world, i + 3, j + 0, k + 19, Blocks.stonebrick, 3);
		this.setBlock(world, i + 3, j + 0, k + 20, Blocks.mycelium, 0);
		this.setBlock(world, i + 3, j + 0, k + 21, Blocks.mycelium, 0);
		this.setBlock(world, i + 3, j + 0, k + 22, Blocks.mycelium, 0);
		this.setBlock(world, i + 3, j + 0, k + 23, Blocks.mycelium, 0);
		this.setBlock(world, i + 3, j + 0, k + 24, Blocks.mycelium, 0);
		this.setBlock(world, i + 3, j + 0, k + 25, Blocks.mycelium, 0);
		this.setBlock(world, i + 3, j + 0, k + 26, Blocks.mycelium, 0);
		this.setBlock(world, i + 3, j + 0, k + 27, Blocks.stonebrick, 3);
		this.setBlock(world, i + 3, j + 0, k + 28, Blocks.stonebrick, 3);
		this.setBlock(world, i + 3, j + 1, k + 2, Blocks.mossy_cobblestone, 0);
		this.setBlock(world, i + 3, j + 1, k + 3, Blocks.stonebrick, 3);
		this.setBlock(world, i + 3, j + 1, k + 4, Blocks.air, 0);
		this.setBlock(world, i + 3, j + 1, k + 5, Blocks.air, 0);
		this.setBlock(world, i + 3, j + 1, k + 6, Blocks.air, 0);
		this.setBlock(world, i + 3, j + 1, k + 7, Blocks.air, 0);
		this.setBlock(world, i + 3, j + 1, k + 8, Blocks.air, 0);
		this.setBlock(world, i + 3, j + 1, k + 9, Blocks.air, 0);
		this.setBlock(world, i + 3, j + 1, k + 10, Blocks.air, 0);
		this.setBlock(world, i + 3, j + 1, k + 11, Blocks.stonebrick, 3);
		this.setBlock(world, i + 3, j + 1, k + 12, Blocks.air, 0);
		this.setBlock(world, i + 3, j + 1, k + 13, Blocks.air, 0);
		this.setBlock(world, i + 3, j + 1, k + 14, Blocks.air, 0);
		this.setBlock(world, i + 3, j + 1, k + 15, Blocks.air, 0);
		this.setBlock(world, i + 3, j + 1, k + 16, Blocks.air, 0);
		this.setBlock(world, i + 3, j + 1, k + 17, Blocks.air, 0);
		this.setBlock(world, i + 3, j + 1, k + 18, Blocks.air, 0);
		this.setBlock(world, i + 3, j + 1, k + 19, Blocks.stonebrick, 3);
		this.setBlock(world, i + 3, j + 1, k + 20, Blocks.air, 0);
		this.setBlock(world, i + 3, j + 1, k + 21, Blocks.air, 0);
		this.setBlock(world, i + 3, j + 1, k + 22, Blocks.air, 0);
		this.setBlock(world, i + 3, j + 1, k + 23, Blocks.air, 0);
		this.setBlock(world, i + 3, j + 1, k + 24, Blocks.air, 0);
		this.setBlock(world, i + 3, j + 1, k + 25, Blocks.air, 0);
		this.setBlock(world, i + 3, j + 1, k + 26, Blocks.air, 0);
		this.setBlock(world, i + 3, j + 1, k + 27, Blocks.stonebrick, 3);
		this.setBlock(world, i + 3, j + 1, k + 28, Blocks.cobblestone, 0);
		this.setBlock(world, i + 3, j + 2, k + 2, Blocks.cobblestone, 0);
		this.setBlock(world, i + 3, j + 2, k + 3, Blocks.stonebrick, 3);
		this.setBlock(world, i + 3, j + 2, k + 4, Blocks.air, 0);
		this.setBlock(world, i + 3, j + 2, k + 5, Blocks.air, 0);
		this.setBlock(world, i + 3, j + 2, k + 6, Blocks.air, 0);
		this.setBlock(world, i + 3, j + 2, k + 7, Blocks.air, 0);
		this.setBlock(world, i + 3, j + 2, k + 8, Blocks.air, 0);
		this.setBlock(world, i + 3, j + 2, k + 9, Blocks.air, 0);
		this.setBlock(world, i + 3, j + 2, k + 10, Blocks.air, 0);
		this.setBlock(world, i + 3, j + 2, k + 11, Blocks.stonebrick, 3);
		this.setBlock(world, i + 3, j + 2, k + 12, Blocks.air, 0);
		this.setBlock(world, i + 3, j + 2, k + 13, Blocks.air, 0);
		this.setBlock(world, i + 3, j + 2, k + 14, Blocks.air, 0);
		this.setBlock(world, i + 3, j + 2, k + 15, Blocks.air, 0);
		this.setBlock(world, i + 3, j + 2, k + 16, Blocks.air, 0);
		this.setBlock(world, i + 3, j + 2, k + 17, Blocks.air, 0);
		this.setBlock(world, i + 3, j + 2, k + 18, Blocks.air, 0);
		this.setBlock(world, i + 3, j + 2, k + 19, Blocks.stonebrick, 3);
		this.setBlock(world, i + 3, j + 2, k + 20, Blocks.air, 0);
		this.setBlock(world, i + 3, j + 2, k + 21, Blocks.air, 0);
		this.setBlock(world, i + 3, j + 2, k + 22, Blocks.air, 0);
		this.setBlock(world, i + 3, j + 2, k + 23, Blocks.air, 0);
		this.setBlock(world, i + 3, j + 2, k + 24, Blocks.air, 0);
		this.setBlock(world, i + 3, j + 2, k + 25, Blocks.air, 0);
		this.setBlock(world, i + 3, j + 2, k + 26, Blocks.air, 0);
		this.setBlock(world, i + 3, j + 2, k + 27, Blocks.stonebrick, 3);
		this.setBlock(world, i + 3, j + 2, k + 28, Blocks.mossy_cobblestone, 0);
		this.setBlock(world, i + 3, j + 3, k + 2, Blocks.mossy_cobblestone, 0);
		this.setBlock(world, i + 3, j + 3, k + 3, Blocks.stonebrick, 3);
		this.setBlock(world, i + 3, j + 3, k + 4, Blocks.air, 0);
		this.setBlock(world, i + 3, j + 3, k + 5, Blocks.air, 0);
		this.setBlock(world, i + 3, j + 3, k + 6, Blocks.air, 0);
		this.setBlock(world, i + 3, j + 3, k + 7, Blocks.air, 0);
		this.setBlock(world, i + 3, j + 3, k + 8, Blocks.air, 0);
		this.setBlock(world, i + 3, j + 3, k + 9, Blocks.air, 0);
		this.setBlock(world, i + 3, j + 3, k + 10, Blocks.air, 0);
		this.setBlock(world, i + 3, j + 3, k + 11, Blocks.stonebrick, 3);
		this.setBlock(world, i + 3, j + 3, k + 12, Blocks.air, 0);
		this.setBlock(world, i + 3, j + 3, k + 13, Blocks.air, 0);
		this.setBlock(world, i + 3, j + 3, k + 14, Blocks.air, 0);
		this.setBlock(world, i + 3, j + 3, k + 15, Blocks.air, 0);
		this.setBlock(world, i + 3, j + 3, k + 16, Blocks.air, 0);
		this.setBlock(world, i + 3, j + 3, k + 17, Blocks.air, 0);
		this.setBlock(world, i + 3, j + 3, k + 18, Blocks.air, 0);
		this.setBlock(world, i + 3, j + 3, k + 19, Blocks.stonebrick, 3);
		this.setBlock(world, i + 3, j + 3, k + 20, Blocks.air, 0);
		this.setBlock(world, i + 3, j + 3, k + 21, Blocks.air, 0);
		this.setBlock(world, i + 3, j + 3, k + 22, Blocks.air, 0);
		this.setBlock(world, i + 3, j + 3, k + 23, Blocks.air, 0);
		this.setBlock(world, i + 3, j + 3, k + 24, Blocks.air, 0);
		this.setBlock(world, i + 3, j + 3, k + 25, Blocks.air, 0);
		this.setBlock(world, i + 3, j + 3, k + 26, Blocks.air, 0);
		this.setBlock(world, i + 3, j + 3, k + 27, Blocks.stonebrick, 3);
		this.setBlock(world, i + 3, j + 3, k + 28, Blocks.mossy_cobblestone, 0);
		this.setBlock(world, i + 3, j + 4, k + 2, Blocks.mossy_cobblestone, 0);
		this.setBlock(world, i + 3, j + 4, k + 3, Blocks.stonebrick, 3);
		this.setBlock(world, i + 3, j + 4, k + 4, Blocks.air, 0);
		this.setBlock(world, i + 3, j + 4, k + 5, Blocks.air, 0);
		this.setBlock(world, i + 3, j + 4, k + 6, Blocks.air, 0);
		this.setBlock(world, i + 3, j + 4, k + 7, Blocks.air, 0);
		this.setBlock(world, i + 3, j + 4, k + 8, Blocks.air, 0);
		this.setBlock(world, i + 3, j + 4, k + 9, Blocks.air, 0);
		this.setBlock(world, i + 3, j + 4, k + 10, Blocks.air, 0);
		this.setBlock(world, i + 3, j + 4, k + 11, Blocks.stonebrick, 3);
		this.setBlock(world, i + 3, j + 4, k + 12, Blocks.air, 0);
		this.setBlock(world, i + 3, j + 4, k + 13, Blocks.air, 0);
		this.setBlock(world, i + 3, j + 4, k + 14, Blocks.air, 0);
		this.setBlock(world, i + 3, j + 4, k + 15, Blocks.air, 0);
		this.setBlock(world, i + 3, j + 4, k + 16, Blocks.air, 0);
		this.setBlock(world, i + 3, j + 4, k + 17, Blocks.air, 0);
		this.setBlock(world, i + 3, j + 4, k + 18, Blocks.air, 0);
		this.setBlock(world, i + 3, j + 4, k + 19, Blocks.stonebrick, 3);
		this.setBlock(world, i + 3, j + 4, k + 20, Blocks.air, 0);
		this.setBlock(world, i + 3, j + 4, k + 21, Blocks.air, 0);
		this.setBlock(world, i + 3, j + 4, k + 22, Blocks.air, 0);
		this.setBlock(world, i + 3, j + 4, k + 23, Blocks.air, 0);
		this.setBlock(world, i + 3, j + 4, k + 24, Blocks.air, 0);
		this.setBlock(world, i + 3, j + 4, k + 25, Blocks.air, 0);
		this.setBlock(world, i + 3, j + 4, k + 26, Blocks.air, 0);
		this.setBlock(world, i + 3, j + 4, k + 27, Blocks.stonebrick, 3);
		this.setBlock(world, i + 3, j + 4, k + 28, Blocks.cobblestone, 0);
		this.setBlock(world, i + 3, j + 5, k + 3, Blocks.stonebrick, 3);
		this.setBlock(world, i + 3, j + 5, k + 4, Blocks.stone_brick_stairs, 7);
		this.setBlock(world, i + 3, j + 5, k + 5, Blocks.air, 0);
		this.setBlock(world, i + 3, j + 5, k + 6, Blocks.air, 0);
		this.setBlock(world, i + 3, j + 5, k + 7, Blocks.air, 0);
		this.setBlock(world, i + 3, j + 5, k + 8, Blocks.air, 0);
		this.setBlock(world, i + 3, j + 5, k + 9, Blocks.air, 0);
		this.setBlock(world, i + 3, j + 5, k + 10, Blocks.stone_brick_stairs, 6);
		this.setBlock(world, i + 3, j + 5, k + 11, Blocks.stonebrick, 3);
		this.setBlock(world, i + 3, j + 5, k + 12, Blocks.stone_brick_stairs, 7);
		this.setBlock(world, i + 3, j + 5, k + 13, Blocks.air, 0);
		this.setBlock(world, i + 3, j + 5, k + 14, Blocks.air, 0);
		this.setBlock(world, i + 3, j + 5, k + 15, Blocks.air, 0);
		this.setBlock(world, i + 3, j + 5, k + 16, Blocks.air, 0);
		this.setBlock(world, i + 3, j + 5, k + 17, Blocks.air, 0);
		this.setBlock(world, i + 3, j + 5, k + 18, Blocks.stone_brick_stairs, 6);
		this.setBlock(world, i + 3, j + 5, k + 19, Blocks.stonebrick, 3);
		this.setBlock(world, i + 3, j + 5, k + 20, Blocks.stone_brick_stairs, 7);
		this.setBlock(world, i + 3, j + 5, k + 21, Blocks.air, 0);
		this.setBlock(world, i + 3, j + 5, k + 22, Blocks.air, 0);
		this.setBlock(world, i + 3, j + 5, k + 23, Blocks.air, 0);
		this.setBlock(world, i + 3, j + 5, k + 24, Blocks.air, 0);
		this.setBlock(world, i + 3, j + 5, k + 25, Blocks.air, 0);
		this.setBlock(world, i + 3, j + 5, k + 26, Blocks.stone_brick_stairs, 6);
		this.setBlock(world, i + 3, j + 5, k + 27, Blocks.stonebrick, 3);
		this.setBlock(world, i + 3, j + 6, k + 4, Blocks.stonebrick, 0);
		this.setBlock(world, i + 3, j + 6, k + 5, Blocks.stone_brick_stairs, 7);
		this.setBlock(world, i + 3, j + 6, k + 6, Blocks.air, 0);
		this.setBlock(world, i + 3, j + 6, k + 7, Blocks.air, 0);
		this.setBlock(world, i + 3, j + 6, k + 8, Blocks.air, 0);
		this.setBlock(world, i + 3, j + 6, k + 9, Blocks.stone_brick_stairs, 6);
		this.setBlock(world, i + 3, j + 6, k + 10, Blocks.stonebrick, 0);
		this.setBlock(world, i + 3, j + 6, k + 12, Blocks.stonebrick, 0);
		this.setBlock(world, i + 3, j + 6, k + 13, Blocks.stone_brick_stairs, 7);
		this.setBlock(world, i + 3, j + 6, k + 14, Blocks.air, 0);
		this.setBlock(world, i + 3, j + 6, k + 15, Blocks.air, 0);
		this.setBlock(world, i + 3, j + 6, k + 16, Blocks.air, 0);
		this.setBlock(world, i + 3, j + 6, k + 17, Blocks.stone_brick_stairs, 6);
		this.setBlock(world, i + 3, j + 6, k + 18, Blocks.stonebrick, 0);
		this.setBlock(world, i + 3, j + 6, k + 20, Blocks.stonebrick, 0);
		this.setBlock(world, i + 3, j + 6, k + 21, Blocks.stone_brick_stairs, 7);
		this.setBlock(world, i + 3, j + 6, k + 22, Blocks.air, 0);
		this.setBlock(world, i + 3, j + 6, k + 23, Blocks.air, 0);
		this.setBlock(world, i + 3, j + 6, k + 24, Blocks.air, 0);
		this.setBlock(world, i + 3, j + 6, k + 25, Blocks.stone_brick_stairs, 6);
		this.setBlock(world, i + 3, j + 6, k + 26, Blocks.stonebrick, 0);
		this.setBlock(world, i + 3, j + 7, k + 5, Blocks.stonebrick, 0);
		this.setBlock(world, i + 3, j + 7, k + 6, Blocks.stone_brick_stairs, 7);
		this.setBlock(world, i + 3, j + 7, k + 7, Blocks.air, 0);
		this.setBlock(world, i + 3, j + 7, k + 8, Blocks.stone_brick_stairs, 6);
		this.setBlock(world, i + 3, j + 7, k + 9, Blocks.stonebrick, 0);
		this.setBlock(world, i + 3, j + 7, k + 13, Blocks.stonebrick, 0);
		this.setBlock(world, i + 3, j + 7, k + 14, Blocks.stone_brick_stairs, 7);
		this.setBlock(world, i + 3, j + 7, k + 15, Blocks.air, 0);
		this.setBlock(world, i + 3, j + 7, k + 16, Blocks.stone_brick_stairs, 6);
		this.setBlock(world, i + 3, j + 7, k + 17, Blocks.stonebrick, 0);
		this.setBlock(world, i + 3, j + 7, k + 21, Blocks.stonebrick, 0);
		this.setBlock(world, i + 3, j + 7, k + 22, Blocks.stone_brick_stairs, 7);
		this.setBlock(world, i + 3, j + 7, k + 23, Blocks.air, 0);
		this.setBlock(world, i + 3, j + 7, k + 24, Blocks.stone_brick_stairs, 6);
		this.setBlock(world, i + 3, j + 7, k + 25, Blocks.stonebrick, 0);
		this.setBlock(world, i + 3, j + 8, k + 6, Blocks.stonebrick, 0);
		this.setBlock(world, i + 3, j + 8, k + 7, Blocks.stonebrick, 0);
		this.setBlock(world, i + 3, j + 8, k + 8, Blocks.stonebrick, 0);
		this.setBlock(world, i + 3, j + 8, k + 14, Blocks.stonebrick, 0);
		this.setBlock(world, i + 3, j + 8, k + 15, Blocks.stonebrick, 0);
		this.setBlock(world, i + 3, j + 8, k + 16, Blocks.stonebrick, 0);
		this.setBlock(world, i + 3, j + 8, k + 22, Blocks.stonebrick, 0);
		this.setBlock(world, i + 3, j + 8, k + 23, Blocks.stonebrick, 0);
		this.setBlock(world, i + 3, j + 8, k + 24, Blocks.stonebrick, 0);
		this.setBlock(world, i + 4, j + 0, k + 1, Blocks.stonebrick, 3);
		this.setBlock(world, i + 4, j + 0, k + 2, Blocks.stonebrick, 3);
		this.setBlock(world, i + 4, j + 0, k + 3, Blocks.mycelium, 0);
		this.setBlock(world, i + 4, j + 0, k + 4, Blocks.mycelium, 0);
		this.setBlock(world, i + 4, j + 0, k + 5, Blocks.mycelium, 0);
		this.setBlock(world, i + 4, j + 0, k + 6, Blocks.cobblestone, 0);
		this.setBlock(world, i + 4, j + 0, k + 7, Blocks.mycelium, 0);
		this.setBlock(world, i + 4, j + 0, k + 8, Blocks.mycelium, 0);
		this.setBlock(world, i + 4, j + 0, k + 9, Blocks.mycelium, 0);
		this.setBlock(world, i + 4, j + 0, k + 10, Blocks.mycelium, 0);
		this.setBlock(world, i + 4, j + 0, k + 11, Blocks.mycelium, 0);
		this.setBlock(world, i + 4, j + 0, k + 12, Blocks.mycelium, 0);
		this.setBlock(world, i + 4, j + 0, k + 13, Blocks.mycelium, 0);
		this.setBlock(world, i + 4, j + 0, k + 14, Blocks.mycelium, 0);
		this.setBlock(world, i + 4, j + 0, k + 15, Blocks.mycelium, 0);
		this.setBlock(world, i + 4, j + 0, k + 16, Blocks.mycelium, 0);
		this.setBlock(world, i + 4, j + 0, k + 17, Blocks.mycelium, 0);
		this.setBlock(world, i + 4, j + 0, k + 18, Blocks.mycelium, 0);
		this.setBlock(world, i + 4, j + 0, k + 19, Blocks.mycelium, 0);
		this.setBlock(world, i + 4, j + 0, k + 20, Blocks.mycelium, 0);
		this.setBlock(world, i + 4, j + 0, k + 21, Blocks.mycelium, 0);
		this.setBlock(world, i + 4, j + 0, k + 22, Blocks.mycelium, 0);
		this.setBlock(world, i + 4, j + 0, k + 23, Blocks.mycelium, 0);
		this.setBlock(world, i + 4, j + 0, k + 24, Blocks.mycelium, 0);
		this.setBlock(world, i + 4, j + 0, k + 25, Blocks.cobblestone, 0);
		this.setBlock(world, i + 4, j + 0, k + 26, Blocks.mycelium, 0);
		this.setBlock(world, i + 4, j + 0, k + 27, Blocks.mycelium, 0);
		this.setBlock(world, i + 4, j + 0, k + 28, Blocks.stonebrick, 3);
		this.setBlock(world, i + 4, j + 0, k + 29, Blocks.stonebrick, 3);
		this.setBlock(world, i + 4, j + 1, k + 1, Blocks.mossy_cobblestone, 0);
		this.setBlock(world, i + 4, j + 1, k + 2, Blocks.air, 0);
		this.setBlock(world, i + 4, j + 1, k + 3, Blocks.air, 0);
		this.setBlock(world, i + 4, j + 1, k + 4, Blocks.air, 0);
		this.setBlock(world, i + 4, j + 1, k + 5, Blocks.air, 0);
		this.setBlock(world, i + 4, j + 1, k + 6, Blocks.air, 0);
		this.setBlock(world, i + 4, j + 1, k + 7, Blocks.air, 0);
		this.setBlock(world, i + 4, j + 1, k + 8, Blocks.air, 0);
		this.setBlock(world, i + 4, j + 1, k + 9, Blocks.air, 0);
		this.setBlock(world, i + 4, j + 1, k + 10, Blocks.air, 0);
		this.setBlock(world, i + 4, j + 1, k + 11, Blocks.air, 0);
		this.setBlock(world, i + 4, j + 1, k + 12, Blocks.air, 0);
		this.setBlock(world, i + 4, j + 1, k + 13, Blocks.air, 0);
		this.setBlock(world, i + 4, j + 1, k + 14, Blocks.air, 0);
		this.setBlock(world, i + 4, j + 1, k + 15, Blocks.air, 0);
		this.setBlock(world, i + 4, j + 1, k + 16, Blocks.air, 0);
		this.setBlock(world, i + 4, j + 1, k + 17, Blocks.air, 0);
		this.setBlock(world, i + 4, j + 1, k + 18, Blocks.air, 0);
		this.setBlock(world, i + 4, j + 1, k + 19, Blocks.air, 0);
		this.setBlock(world, i + 4, j + 1, k + 20, Blocks.air, 0);
		this.setBlock(world, i + 4, j + 1, k + 21, Blocks.air, 0);
		this.setBlock(world, i + 4, j + 1, k + 22, Blocks.air, 0);
		this.setBlock(world, i + 4, j + 1, k + 23, Blocks.air, 0);
		this.setBlock(world, i + 4, j + 1, k + 24, Blocks.air, 0);
		this.setBlock(world, i + 4, j + 1, k + 25, Blocks.air, 0);
		this.setBlock(world, i + 4, j + 1, k + 26, Blocks.air, 0);
		this.setBlock(world, i + 4, j + 1, k + 27, Blocks.air, 0);
		this.setBlock(world, i + 4, j + 1, k + 28, Blocks.air, 0);
		this.setBlock(world, i + 4, j + 1, k + 29, Blocks.mossy_cobblestone, 0);
		this.setBlock(world, i + 4, j + 2, k + 1, Blocks.cobblestone, 0);
		this.setBlock(world, i + 4, j + 2, k + 2, Blocks.air, 0);
		this.setBlock(world, i + 4, j + 2, k + 3, Blocks.air, 0);
		this.setBlock(world, i + 4, j + 2, k + 4, Blocks.air, 0);
		this.setBlock(world, i + 4, j + 2, k + 5, Blocks.air, 0);
		this.setBlock(world, i + 4, j + 2, k + 6, Blocks.air, 0);
		this.setBlock(world, i + 4, j + 2, k + 7, Blocks.air, 0);
		this.setBlock(world, i + 4, j + 2, k + 8, Blocks.air, 0);
		this.setBlock(world, i + 4, j + 2, k + 9, Blocks.air, 0);
		this.setBlock(world, i + 4, j + 2, k + 10, Blocks.air, 0);
		this.setBlock(world, i + 4, j + 2, k + 11, Blocks.air, 0);
		this.setBlock(world, i + 4, j + 2, k + 12, Blocks.air, 0);
		this.setBlock(world, i + 4, j + 2, k + 13, Blocks.air, 0);
		this.setBlock(world, i + 4, j + 2, k + 14, Blocks.air, 0);
		this.setBlock(world, i + 4, j + 2, k + 15, Blocks.air, 0);
		this.setBlock(world, i + 4, j + 2, k + 16, Blocks.air, 0);
		this.setBlock(world, i + 4, j + 2, k + 17, Blocks.air, 0);
		this.setBlock(world, i + 4, j + 2, k + 18, Blocks.air, 0);
		this.setBlock(world, i + 4, j + 2, k + 19, Blocks.air, 0);
		this.setBlock(world, i + 4, j + 2, k + 20, Blocks.air, 0);
		this.setBlock(world, i + 4, j + 2, k + 21, Blocks.air, 0);
		this.setBlock(world, i + 4, j + 2, k + 22, Blocks.air, 0);
		this.setBlock(world, i + 4, j + 2, k + 23, Blocks.air, 0);
		this.setBlock(world, i + 4, j + 2, k + 24, Blocks.air, 0);
		this.setBlock(world, i + 4, j + 2, k + 25, Blocks.air, 0);
		this.setBlock(world, i + 4, j + 2, k + 26, Blocks.air, 0);
		this.setBlock(world, i + 4, j + 2, k + 27, Blocks.air, 0);
		this.setBlock(world, i + 4, j + 2, k + 28, Blocks.air, 0);
		this.setBlock(world, i + 4, j + 2, k + 29, Blocks.mossy_cobblestone, 0);
		this.setBlock(world, i + 4, j + 3, k + 1, Blocks.mossy_cobblestone, 0);
		this.setBlock(world, i + 4, j + 3, k + 2, Blocks.air, 0);
		this.setBlock(world, i + 4, j + 3, k + 3, Blocks.air, 0);
		this.setBlock(world, i + 4, j + 3, k + 4, Blocks.air, 0);
		this.setBlock(world, i + 4, j + 3, k + 5, Blocks.air, 0);
		this.setBlock(world, i + 4, j + 3, k + 6, Blocks.air, 0);
		this.setBlock(world, i + 4, j + 3, k + 7, Blocks.air, 0);
		this.setBlock(world, i + 4, j + 3, k + 8, Blocks.air, 0);
		this.setBlock(world, i + 4, j + 3, k + 9, Blocks.air, 0);
		this.setBlock(world, i + 4, j + 3, k + 10, Blocks.air, 0);
		this.setBlock(world, i + 4, j + 3, k + 11, Blocks.air, 0);
		this.setBlock(world, i + 4, j + 3, k + 12, Blocks.air, 0);
		this.setBlock(world, i + 4, j + 3, k + 13, Blocks.air, 0);
		this.setBlock(world, i + 4, j + 3, k + 14, Blocks.air, 0);
		this.setBlock(world, i + 4, j + 3, k + 15, Blocks.air, 0);
		this.setBlock(world, i + 4, j + 3, k + 16, Blocks.air, 0);
		this.setBlock(world, i + 4, j + 3, k + 17, Blocks.air, 0);
		this.setBlock(world, i + 4, j + 3, k + 18, Blocks.air, 0);
		this.setBlock(world, i + 4, j + 3, k + 19, Blocks.air, 0);
		this.setBlock(world, i + 4, j + 3, k + 20, Blocks.air, 0);
		this.setBlock(world, i + 4, j + 3, k + 21, Blocks.air, 0);
		this.setBlock(world, i + 4, j + 3, k + 22, Blocks.air, 0);
		this.setBlock(world, i + 4, j + 3, k + 23, Blocks.air, 0);
		this.setBlock(world, i + 4, j + 3, k + 24, Blocks.air, 0);
		this.setBlock(world, i + 4, j + 3, k + 25, Blocks.air, 0);
		this.setBlock(world, i + 4, j + 3, k + 26, Blocks.air, 0);
		this.setBlock(world, i + 4, j + 3, k + 27, Blocks.air, 0);
		this.setBlock(world, i + 4, j + 3, k + 28, Blocks.air, 0);
		this.setBlock(world, i + 4, j + 3, k + 29, Blocks.cobblestone, 0);
		this.setBlock(world, i + 4, j + 4, k + 1, Blocks.mossy_cobblestone, 0);
		this.setBlock(world, i + 4, j + 4, k + 2, Blocks.stone_stairs, 5);
		this.setBlock(world, i + 4, j + 4, k + 3, Blocks.air, 0);
		this.setBlock(world, i + 4, j + 4, k + 4, Blocks.air, 0);
		this.setBlock(world, i + 4, j + 4, k + 5, Blocks.air, 0);
		this.setBlock(world, i + 4, j + 4, k + 6, Blocks.air, 0);
		this.setBlock(world, i + 4, j + 4, k + 7, Blocks.air, 0);
		this.setBlock(world, i + 4, j + 4, k + 8, Blocks.air, 0);
		this.setBlock(world, i + 4, j + 4, k + 9, Blocks.air, 0);
		this.setBlock(world, i + 4, j + 4, k + 10, Blocks.air, 0);
		this.setBlock(world, i + 4, j + 4, k + 11, Blocks.air, 0);
		this.setBlock(world, i + 4, j + 4, k + 12, Blocks.air, 0);
		this.setBlock(world, i + 4, j + 4, k + 13, Blocks.air, 0);
		this.setBlock(world, i + 4, j + 4, k + 14, Blocks.air, 0);
		this.setBlock(world, i + 4, j + 4, k + 15, Blocks.air, 0);
		this.setBlock(world, i + 4, j + 4, k + 16, Blocks.air, 0);
		this.setBlock(world, i + 4, j + 4, k + 17, Blocks.air, 0);
		this.setBlock(world, i + 4, j + 4, k + 18, Blocks.air, 0);
		this.setBlock(world, i + 4, j + 4, k + 19, Blocks.air, 0);
		this.setBlock(world, i + 4, j + 4, k + 20, Blocks.air, 0);
		this.setBlock(world, i + 4, j + 4, k + 21, Blocks.air, 0);
		this.setBlock(world, i + 4, j + 4, k + 22, Blocks.air, 0);
		this.setBlock(world, i + 4, j + 4, k + 23, Blocks.air, 0);
		this.setBlock(world, i + 4, j + 4, k + 24, Blocks.air, 0);
		this.setBlock(world, i + 4, j + 4, k + 25, Blocks.air, 0);
		this.setBlock(world, i + 4, j + 4, k + 26, Blocks.air, 0);
		this.setBlock(world, i + 4, j + 4, k + 27, Blocks.air, 0);
		this.setBlock(world, i + 4, j + 4, k + 28, Blocks.stone_stairs, 5);
		this.setBlock(world, i + 4, j + 4, k + 29, Blocks.mossy_cobblestone, 0);
		this.setBlock(world, i + 4, j + 5, k + 2, Blocks.cobblestone, 0);
		this.setBlock(world, i + 4, j + 5, k + 3, Blocks.stone_brick_stairs, 5);
		this.setBlock(world, i + 4, j + 5, k + 4, Blocks.air, 0);
		this.setBlock(world, i + 4, j + 5, k + 5, Blocks.air, 0);
		this.setBlock(world, i + 4, j + 5, k + 6, Blocks.air, 0);
		this.setBlock(world, i + 4, j + 5, k + 7, Blocks.air, 0);
		this.setBlock(world, i + 4, j + 5, k + 8, Blocks.air, 0);
		this.setBlock(world, i + 4, j + 5, k + 9, Blocks.air, 0);
		this.setBlock(world, i + 4, j + 5, k + 10, Blocks.air, 0);
		this.setBlock(world, i + 4, j + 5, k + 11, Blocks.stone_brick_stairs, 5);
		this.setBlock(world, i + 4, j + 5, k + 12, Blocks.air, 0);
		this.setBlock(world, i + 4, j + 5, k + 13, Blocks.air, 0);
		this.setBlock(world, i + 4, j + 5, k + 14, Blocks.air, 0);
		this.setBlock(world, i + 4, j + 5, k + 15, Blocks.air, 0);
		this.setBlock(world, i + 4, j + 5, k + 16, Blocks.air, 0);
		this.setBlock(world, i + 4, j + 5, k + 17, Blocks.air, 0);
		this.setBlock(world, i + 4, j + 5, k + 18, Blocks.air, 0);
		this.setBlock(world, i + 4, j + 5, k + 19, Blocks.stone_brick_stairs, 5);
		this.setBlock(world, i + 4, j + 5, k + 20, Blocks.air, 0);
		this.setBlock(world, i + 4, j + 5, k + 21, Blocks.air, 0);
		this.setBlock(world, i + 4, j + 5, k + 22, Blocks.air, 0);
		this.setBlock(world, i + 4, j + 5, k + 23, Blocks.air, 0);
		this.setBlock(world, i + 4, j + 5, k + 24, Blocks.air, 0);
		this.setBlock(world, i + 4, j + 5, k + 25, Blocks.air, 0);
		this.setBlock(world, i + 4, j + 5, k + 26, Blocks.air, 0);
		this.setBlock(world, i + 4, j + 5, k + 27, Blocks.stone_brick_stairs, 5);
		this.setBlock(world, i + 4, j + 5, k + 28, Blocks.cobblestone, 0);
		this.setBlock(world, i + 4, j + 6, k + 3, Blocks.stonebrick, 0);
		this.setBlock(world, i + 4, j + 6, k + 4, Blocks.stone_slab, 13);
		this.setBlock(world, i + 4, j + 6, k + 5, Blocks.air, 0);
		this.setBlock(world, i + 4, j + 6, k + 6, Blocks.air, 0);
		this.setBlock(world, i + 4, j + 6, k + 7, Blocks.air, 0);
		this.setBlock(world, i + 4, j + 6, k + 8, Blocks.air, 0);
		this.setBlock(world, i + 4, j + 6, k + 9, Blocks.air, 0);
		this.setBlock(world, i + 4, j + 6, k + 10, Blocks.stone_slab, 13);
		this.setBlock(world, i + 4, j + 6, k + 11, Blocks.stonebrick, 0);
		this.setBlock(world, i + 4, j + 6, k + 12, Blocks.stone_slab, 13);
		this.setBlock(world, i + 4, j + 6, k + 13, Blocks.air, 0);
		this.setBlock(world, i + 4, j + 6, k + 14, Blocks.air, 0);
		this.setBlock(world, i + 4, j + 6, k + 15, Blocks.air, 0);
		this.setBlock(world, i + 4, j + 6, k + 16, Blocks.air, 0);
		this.setBlock(world, i + 4, j + 6, k + 17, Blocks.air, 0);
		this.setBlock(world, i + 4, j + 6, k + 18, Blocks.stone_slab, 13);
		this.setBlock(world, i + 4, j + 6, k + 19, Blocks.stonebrick, 0);
		this.setBlock(world, i + 4, j + 6, k + 20, Blocks.stone_slab, 13);
		this.setBlock(world, i + 4, j + 6, k + 21, Blocks.air, 0);
		this.setBlock(world, i + 4, j + 6, k + 22, Blocks.air, 0);
		this.setBlock(world, i + 4, j + 6, k + 23, Blocks.air, 0);
		this.setBlock(world, i + 4, j + 6, k + 24, Blocks.air, 0);
		this.setBlock(world, i + 4, j + 6, k + 25, Blocks.air, 0);
		this.setBlock(world, i + 4, j + 6, k + 26, Blocks.stone_slab, 13);
		this.setBlock(world, i + 4, j + 6, k + 27, Blocks.stonebrick, 0);
		this.setBlock(world, i + 4, j + 7, k + 4, Blocks.stonebrick, 0);
		this.setBlock(world, i + 4, j + 7, k + 5, Blocks.stone_brick_stairs, 7);
		this.setBlock(world, i + 4, j + 7, k + 6, Blocks.air, 0);
		this.setBlock(world, i + 4, j + 7, k + 7, Blocks.air, 0);
		this.setBlock(world, i + 4, j + 7, k + 8, Blocks.air, 0);
		this.setBlock(world, i + 4, j + 7, k + 9, Blocks.stone_brick_stairs, 6);
		this.setBlock(world, i + 4, j + 7, k + 10, Blocks.stonebrick, 0);
		this.setBlock(world, i + 4, j + 7, k + 12, Blocks.stonebrick, 0);
		this.setBlock(world, i + 4, j + 7, k + 13, Blocks.stone_brick_stairs, 7);
		this.setBlock(world, i + 4, j + 7, k + 14, Blocks.air, 0);
		this.setBlock(world, i + 4, j + 7, k + 15, Blocks.air, 0);
		this.setBlock(world, i + 4, j + 7, k + 16, Blocks.air, 0);
		this.setBlock(world, i + 4, j + 7, k + 17, Blocks.stone_brick_stairs, 6);
		this.setBlock(world, i + 4, j + 7, k + 18, Blocks.stonebrick, 0);
		this.setBlock(world, i + 4, j + 7, k + 20, Blocks.stonebrick, 0);
		this.setBlock(world, i + 4, j + 7, k + 21, Blocks.stone_brick_stairs, 7);
		this.setBlock(world, i + 4, j + 7, k + 22, Blocks.air, 0);
		this.setBlock(world, i + 4, j + 7, k + 23, Blocks.air, 0);
		this.setBlock(world, i + 4, j + 7, k + 24, Blocks.air, 0);
		this.setBlock(world, i + 4, j + 7, k + 25, Blocks.stone_brick_stairs, 6);
		this.setBlock(world, i + 4, j + 7, k + 26, Blocks.stonebrick, 0);
		this.setBlock(world, i + 4, j + 8, k + 5, Blocks.stonebrick, 0);
		this.setBlock(world, i + 4, j + 8, k + 6, Blocks.stone_brick_stairs, 7);
		this.setBlock(world, i + 4, j + 8, k + 7, Blocks.air, 0);
		this.setBlock(world, i + 4, j + 8, k + 8, Blocks.stone_brick_stairs, 6);
		this.setBlock(world, i + 4, j + 8, k + 9, Blocks.stonebrick, 0);
		this.setBlock(world, i + 4, j + 8, k + 13, Blocks.stonebrick, 0);
		this.setBlock(world, i + 4, j + 8, k + 14, Blocks.stone_brick_stairs, 7);
		this.setBlock(world, i + 4, j + 8, k + 15, Blocks.air, 0);
		this.setBlock(world, i + 4, j + 8, k + 16, Blocks.stone_brick_stairs, 6);
		this.setBlock(world, i + 4, j + 8, k + 17, Blocks.stonebrick, 0);
		this.setBlock(world, i + 4, j + 8, k + 21, Blocks.stonebrick, 0);
		this.setBlock(world, i + 4, j + 8, k + 22, Blocks.stone_brick_stairs, 7);
		this.setBlock(world, i + 4, j + 8, k + 23, Blocks.air, 0);
		this.setBlock(world, i + 4, j + 8, k + 24, Blocks.stone_brick_stairs, 6);
		this.setBlock(world, i + 4, j + 8, k + 25, Blocks.stonebrick, 0);
		this.setBlock(world, i + 4, j + 9, k + 6, Blocks.stonebrick, 0);
		this.setBlock(world, i + 4, j + 9, k + 7, Blocks.stonebrick, 0);
		this.setBlock(world, i + 4, j + 9, k + 8, Blocks.stonebrick, 0);
		this.setBlock(world, i + 4, j + 9, k + 14, Blocks.stonebrick, 0);
		this.setBlock(world, i + 4, j + 9, k + 15, Blocks.stonebrick, 0);
		this.setBlock(world, i + 4, j + 9, k + 16, Blocks.stonebrick, 0);
		this.setBlock(world, i + 4, j + 9, k + 22, Blocks.stonebrick, 0);
		this.setBlock(world, i + 4, j + 9, k + 23, Blocks.stonebrick, 0);
		this.setBlock(world, i + 4, j + 9, k + 24, Blocks.stonebrick, 0);
		this.setBlock(world, i + 5, j + 0, k + 0, Blocks.stonebrick, 3);
		this.setBlock(world, i + 5, j + 0, k + 1, Blocks.stonebrick, 3);
		this.setBlock(world, i + 5, j + 0, k + 2, Blocks.stonebrick, 3);
		this.setBlock(world, i + 5, j + 0, k + 3, Blocks.mycelium, 0);
		this.setBlock(world, i + 5, j + 0, k + 4, Blocks.mycelium, 0);
		this.setBlock(world, i + 5, j + 0, k + 5, Blocks.mycelium, 0);
		this.setBlock(world, i + 5, j + 0, k + 6, Blocks.mycelium, 0);
		this.setBlock(world, i + 5, j + 0, k + 7, Blocks.mycelium, 0);
		this.setBlock(world, i + 5, j + 0, k + 8, Blocks.mycelium, 0);
		this.setBlock(world, i + 5, j + 0, k + 9, Blocks.mycelium, 0);
		this.setBlock(world, i + 5, j + 0, k + 10, Blocks.stonebrick, 3);
		this.setBlock(world, i + 5, j + 0, k + 11, Blocks.cobblestone, 0);
		this.setBlock(world, i + 5, j + 0, k + 12, Blocks.mycelium, 0);
		this.setBlock(world, i + 5, j + 0, k + 13, Blocks.mycelium, 0);
		this.setBlock(world, i + 5, j + 0, k + 14, Blocks.mycelium, 0);
		this.setBlock(world, i + 5, j + 0, k + 15, Blocks.mycelium, 0);
		this.setBlock(world, i + 5, j + 0, k + 16, Blocks.mossy_cobblestone, 0);
		this.setBlock(world, i + 5, j + 0, k + 17, Blocks.mycelium, 0);
		this.setBlock(world, i + 5, j + 0, k + 18, Blocks.mycelium, 0);
		this.setBlock(world, i + 5, j + 0, k + 19, Blocks.mycelium, 0);
		this.setBlock(world, i + 5, j + 0, k + 20, Blocks.mycelium, 0);
		this.setBlock(world, i + 5, j + 0, k + 21, Blocks.mycelium, 0);
		this.setBlock(world, i + 5, j + 0, k + 22, Blocks.mycelium, 0);
		this.setBlock(world, i + 5, j + 0, k + 23, Blocks.cobblestone, 0);
		this.setBlock(world, i + 5, j + 0, k + 24, Blocks.cobblestone, 0);
		this.setBlock(world, i + 5, j + 0, k + 25, Blocks.mycelium, 0);
		this.setBlock(world, i + 5, j + 0, k + 26, Blocks.mycelium, 0);
		this.setBlock(world, i + 5, j + 0, k + 27, Blocks.mycelium, 0);
		this.setBlock(world, i + 5, j + 0, k + 28, Blocks.stonebrick, 3);
		this.setBlock(world, i + 5, j + 0, k + 29, Blocks.stonebrick, 3);
		this.setBlock(world, i + 5, j + 0, k + 30, Blocks.stonebrick, 3);
		this.setBlock(world, i + 5, j + 1, k + 0, Blocks.cobblestone, 0);
		this.setBlock(world, i + 5, j + 1, k + 1, ModBlocks.gravewoodStairs, 7);
		this.setBlock(world, i + 5, j + 1, k + 2, Blocks.air, 0);
		this.setBlock(world, i + 5, j + 1, k + 3, Blocks.air, 0);
		this.setBlock(world, i + 5, j + 1, k + 4, Blocks.air, 0);
		this.setBlock(world, i + 5, j + 1, k + 5, Blocks.air, 0);
		this.setBlock(world, i + 5, j + 1, k + 6, Blocks.air, 0);
		this.setBlock(world, i + 5, j + 1, k + 7, Blocks.air, 0);
		this.setBlock(world, i + 5, j + 1, k + 8, Blocks.air, 0);
		this.setBlock(world, i + 5, j + 1, k + 9, Blocks.air, 0);
		this.setBlock(world, i + 5, j + 1, k + 10, Blocks.air, 0);
		this.setBlock(world, i + 5, j + 1, k + 11, Blocks.air, 0);
		this.setBlock(world, i + 5, j + 1, k + 12, Blocks.air, 0);
		this.setBlock(world, i + 5, j + 1, k + 13, Blocks.air, 0);
		this.setBlock(world, i + 5, j + 1, k + 14, Blocks.air, 0);
		this.setBlock(world, i + 5, j + 1, k + 15, Blocks.air, 0);
		this.setBlock(world, i + 5, j + 1, k + 16, Blocks.air, 0);
		this.setBlock(world, i + 5, j + 1, k + 17, Blocks.air, 0);
		this.setBlock(world, i + 5, j + 1, k + 18, Blocks.air, 0);
		this.setBlock(world, i + 5, j + 1, k + 19, Blocks.air, 0);
		this.setBlock(world, i + 5, j + 1, k + 20, Blocks.air, 0);
		this.setBlock(world, i + 5, j + 1, k + 21, Blocks.air, 0);
		this.setBlock(world, i + 5, j + 1, k + 22, Blocks.air, 0);
		this.setBlock(world, i + 5, j + 1, k + 23, Blocks.air, 0);
		this.setBlock(world, i + 5, j + 1, k + 24, Blocks.air, 0);
		this.setBlock(world, i + 5, j + 1, k + 25, Blocks.air, 0);
		this.setBlock(world, i + 5, j + 1, k + 26, Blocks.air, 0);
		this.setBlock(world, i + 5, j + 1, k + 27, Blocks.air, 0);
		this.setBlock(world, i + 5, j + 1, k + 28, Blocks.air, 0);
		this.setBlock(world, i + 5, j + 1, k + 29, ModBlocks.gravewoodStairs, 6);
		this.setBlock(world, i + 5, j + 1, k + 30, Blocks.cobblestone, 0);
		this.setBlock(world, i + 5, j + 2, k + 0, Blocks.mossy_cobblestone, 0);
		this.setBlock(world, i + 5, j + 2, k + 1, Blocks.chest, 3);
		tileentitychest = (TileEntityChest) world.getTileEntity(new BlockPos(i + 5, j + 2, k + 1));
		if (tileentitychest != null)
		{
			WeightedRandomChestContent.generateChestContents(new Random(), GraveyardChestLoot.getItems(new Random()), tileentitychest, 1);
		}
		this.setBlock(world, i + 5, j + 2, k + 2, Blocks.air, 0);
		this.setBlock(world, i + 5, j + 2, k + 3, Blocks.air, 0);
		this.setBlock(world, i + 5, j + 2, k + 4, Blocks.air, 0);
		this.setBlock(world, i + 5, j + 2, k + 5, Blocks.air, 0);
		this.setBlock(world, i + 5, j + 2, k + 6, Blocks.air, 0);
		this.setBlock(world, i + 5, j + 2, k + 7, Blocks.air, 0);
		this.setBlock(world, i + 5, j + 2, k + 8, Blocks.air, 0);
		this.setBlock(world, i + 5, j + 2, k + 9, Blocks.air, 0);
		this.setBlock(world, i + 5, j + 2, k + 10, Blocks.air, 0);
		this.setBlock(world, i + 5, j + 2, k + 11, Blocks.air, 0);
		this.setBlock(world, i + 5, j + 2, k + 12, Blocks.air, 0);
		this.setBlock(world, i + 5, j + 2, k + 13, Blocks.air, 0);
		this.setBlock(world, i + 5, j + 2, k + 14, Blocks.air, 0);
		this.setBlock(world, i + 5, j + 2, k + 15, Blocks.air, 0);
		this.setBlock(world, i + 5, j + 2, k + 16, Blocks.air, 0);
		this.setBlock(world, i + 5, j + 2, k + 17, Blocks.air, 0);
		this.setBlock(world, i + 5, j + 2, k + 18, Blocks.air, 0);
		this.setBlock(world, i + 5, j + 2, k + 19, Blocks.air, 0);
		this.setBlock(world, i + 5, j + 2, k + 20, Blocks.air, 0);
		this.setBlock(world, i + 5, j + 2, k + 21, Blocks.air, 0);
		this.setBlock(world, i + 5, j + 2, k + 22, Blocks.air, 0);
		this.setBlock(world, i + 5, j + 2, k + 23, Blocks.air, 0);
		this.setBlock(world, i + 5, j + 2, k + 24, Blocks.air, 0);
		this.setBlock(world, i + 5, j + 2, k + 25, Blocks.air, 0);
		this.setBlock(world, i + 5, j + 2, k + 26, Blocks.air, 0);
		this.setBlock(world, i + 5, j + 2, k + 27, Blocks.air, 0);
		this.setBlock(world, i + 5, j + 2, k + 28, Blocks.air, 0);
		this.setBlock(world, i + 5, j + 2, k + 29, Blocks.chest, 2);
		tileentitychest = (TileEntityChest) world.getTileEntity(new BlockPos(i + 5, j + 2, k + 29));
		if (tileentitychest != null)
		{
			WeightedRandomChestContent.generateChestContents(new Random(), GraveyardChestLoot.getItems(new Random()), tileentitychest, 1);
		}
		this.setBlock(world, i + 5, j + 2, k + 30, Blocks.mossy_cobblestone, 0);
		this.setBlock(world, i + 5, j + 3, k + 0, Blocks.cobblestone, 0);
		this.setBlock(world, i + 5, j + 3, k + 1, Blocks.air, 0);
		this.setBlock(world, i + 5, j + 3, k + 2, Blocks.air, 0);
		this.setBlock(world, i + 5, j + 3, k + 3, Blocks.air, 0);
		this.setBlock(world, i + 5, j + 3, k + 4, Blocks.air, 0);
		this.setBlock(world, i + 5, j + 3, k + 5, Blocks.air, 0);
		this.setBlock(world, i + 5, j + 3, k + 6, Blocks.air, 0);
		this.setBlock(world, i + 5, j + 3, k + 7, Blocks.air, 0);
		this.setBlock(world, i + 5, j + 3, k + 8, Blocks.air, 0);
		this.setBlock(world, i + 5, j + 3, k + 9, Blocks.air, 0);
		this.setBlock(world, i + 5, j + 3, k + 10, Blocks.air, 0);
		this.setBlock(world, i + 5, j + 3, k + 11, Blocks.air, 0);
		this.setBlock(world, i + 5, j + 3, k + 12, Blocks.air, 0);
		this.setBlock(world, i + 5, j + 3, k + 13, Blocks.air, 0);
		this.setBlock(world, i + 5, j + 3, k + 14, Blocks.air, 0);
		this.setBlock(world, i + 5, j + 3, k + 15, Blocks.air, 0);
		this.setBlock(world, i + 5, j + 3, k + 16, Blocks.air, 0);
		this.setBlock(world, i + 5, j + 3, k + 17, Blocks.air, 0);
		this.setBlock(world, i + 5, j + 3, k + 18, Blocks.air, 0);
		this.setBlock(world, i + 5, j + 3, k + 19, Blocks.air, 0);
		this.setBlock(world, i + 5, j + 3, k + 20, Blocks.air, 0);
		this.setBlock(world, i + 5, j + 3, k + 21, Blocks.air, 0);
		this.setBlock(world, i + 5, j + 3, k + 22, Blocks.air, 0);
		this.setBlock(world, i + 5, j + 3, k + 23, Blocks.air, 0);
		this.setBlock(world, i + 5, j + 3, k + 24, Blocks.air, 0);
		this.setBlock(world, i + 5, j + 3, k + 25, Blocks.air, 0);
		this.setBlock(world, i + 5, j + 3, k + 26, Blocks.air, 0);
		this.setBlock(world, i + 5, j + 3, k + 27, Blocks.air, 0);
		this.setBlock(world, i + 5, j + 3, k + 28, Blocks.air, 0);
		this.setBlock(world, i + 5, j + 3, k + 29, Blocks.air, 0);
		this.setBlock(world, i + 5, j + 3, k + 30, Blocks.cobblestone, 0);
		this.setBlock(world, i + 5, j + 4, k + 0, Blocks.cobblestone, 0);
		this.setBlock(world, i + 5, j + 4, k + 1, Blocks.stone_stairs, 5);
		this.setBlock(world, i + 5, j + 4, k + 2, Blocks.air, 0);
		this.setBlock(world, i + 5, j + 4, k + 3, Blocks.air, 0);
		this.setBlock(world, i + 5, j + 4, k + 4, Blocks.air, 0);
		this.setBlock(world, i + 5, j + 4, k + 5, Blocks.air, 0);
		this.setBlock(world, i + 5, j + 4, k + 6, Blocks.air, 0);
		this.setBlock(world, i + 5, j + 4, k + 7, Blocks.air, 0);
		this.setBlock(world, i + 5, j + 4, k + 8, Blocks.air, 0);
		this.setBlock(world, i + 5, j + 4, k + 9, Blocks.air, 0);
		this.setBlock(world, i + 5, j + 4, k + 10, Blocks.air, 0);
		this.setBlock(world, i + 5, j + 4, k + 11, Blocks.air, 0);
		this.setBlock(world, i + 5, j + 4, k + 12, Blocks.air, 0);
		this.setBlock(world, i + 5, j + 4, k + 13, Blocks.air, 0);
		this.setBlock(world, i + 5, j + 4, k + 14, Blocks.air, 0);
		this.setBlock(world, i + 5, j + 4, k + 15, Blocks.air, 0);
		this.setBlock(world, i + 5, j + 4, k + 16, Blocks.air, 0);
		this.setBlock(world, i + 5, j + 4, k + 17, Blocks.air, 0);
		this.setBlock(world, i + 5, j + 4, k + 18, Blocks.air, 0);
		this.setBlock(world, i + 5, j + 4, k + 19, Blocks.air, 0);
		this.setBlock(world, i + 5, j + 4, k + 20, Blocks.air, 0);
		this.setBlock(world, i + 5, j + 4, k + 21, Blocks.air, 0);
		this.setBlock(world, i + 5, j + 4, k + 22, Blocks.air, 0);
		this.setBlock(world, i + 5, j + 4, k + 23, Blocks.air, 0);
		this.setBlock(world, i + 5, j + 4, k + 24, Blocks.air, 0);
		this.setBlock(world, i + 5, j + 4, k + 25, Blocks.air, 0);
		this.setBlock(world, i + 5, j + 4, k + 26, Blocks.air, 0);
		this.setBlock(world, i + 5, j + 4, k + 27, Blocks.air, 0);
		this.setBlock(world, i + 5, j + 4, k + 28, Blocks.air, 0);
		this.setBlock(world, i + 5, j + 4, k + 29, Blocks.stone_stairs, 5);
		this.setBlock(world, i + 5, j + 4, k + 30, Blocks.mossy_cobblestone, 0);
		this.setBlock(world, i + 5, j + 5, k + 1, Blocks.cobblestone, 0);
		this.setBlock(world, i + 5, j + 5, k + 2, Blocks.stone_stairs, 5);
		this.setBlock(world, i + 5, j + 5, k + 3, Blocks.air, 0);
		this.setBlock(world, i + 5, j + 5, k + 4, Blocks.air, 0);
		this.setBlock(world, i + 5, j + 5, k + 5, Blocks.air, 0);
		this.setBlock(world, i + 5, j + 5, k + 6, Blocks.air, 0);
		this.setBlock(world, i + 5, j + 5, k + 7, Blocks.air, 0);
		this.setBlock(world, i + 5, j + 5, k + 8, Blocks.air, 0);
		this.setBlock(world, i + 5, j + 5, k + 9, Blocks.air, 0);
		this.setBlock(world, i + 5, j + 5, k + 10, Blocks.air, 0);
		this.setBlock(world, i + 5, j + 5, k + 11, Blocks.air, 0);
		this.setBlock(world, i + 5, j + 5, k + 12, Blocks.air, 0);
		this.setBlock(world, i + 5, j + 5, k + 13, Blocks.air, 0);
		this.setBlock(world, i + 5, j + 5, k + 14, Blocks.air, 0);
		this.setBlock(world, i + 5, j + 5, k + 15, Blocks.air, 0);
		this.setBlock(world, i + 5, j + 5, k + 16, Blocks.air, 0);
		this.setBlock(world, i + 5, j + 5, k + 17, Blocks.air, 0);
		this.setBlock(world, i + 5, j + 5, k + 18, Blocks.air, 0);
		this.setBlock(world, i + 5, j + 5, k + 19, Blocks.air, 0);
		this.setBlock(world, i + 5, j + 5, k + 20, Blocks.air, 0);
		this.setBlock(world, i + 5, j + 5, k + 21, Blocks.air, 0);
		this.setBlock(world, i + 5, j + 5, k + 22, Blocks.air, 0);
		this.setBlock(world, i + 5, j + 5, k + 23, Blocks.air, 0);
		this.setBlock(world, i + 5, j + 5, k + 24, Blocks.air, 0);
		this.setBlock(world, i + 5, j + 5, k + 25, Blocks.air, 0);
		this.setBlock(world, i + 5, j + 5, k + 26, Blocks.air, 0);
		this.setBlock(world, i + 5, j + 5, k + 27, Blocks.air, 0);
		this.setBlock(world, i + 5, j + 5, k + 28, Blocks.stone_stairs, 5);
		this.setBlock(world, i + 5, j + 5, k + 29, Blocks.mossy_cobblestone, 0);
		this.setBlock(world, i + 5, j + 6, k + 2, Blocks.cobblestone, 0);
		this.setBlock(world, i + 5, j + 6, k + 3, Blocks.stone_brick_stairs, 5);
		this.setBlock(world, i + 5, j + 6, k + 4, Blocks.air, 0);
		this.setBlock(world, i + 5, j + 6, k + 5, Blocks.air, 0);
		this.setBlock(world, i + 5, j + 6, k + 6, Blocks.air, 0);
		this.setBlock(world, i + 5, j + 6, k + 7, Blocks.air, 0);
		this.setBlock(world, i + 5, j + 6, k + 8, Blocks.air, 0);
		this.setBlock(world, i + 5, j + 6, k + 9, Blocks.air, 0);
		this.setBlock(world, i + 5, j + 6, k + 10, Blocks.air, 0);
		this.setBlock(world, i + 5, j + 6, k + 11, Blocks.stone_brick_stairs, 5);
		this.setBlock(world, i + 5, j + 6, k + 12, Blocks.air, 0);
		this.setBlock(world, i + 5, j + 6, k + 13, Blocks.air, 0);
		this.setBlock(world, i + 5, j + 6, k + 14, Blocks.air, 0);
		this.setBlock(world, i + 5, j + 6, k + 15, Blocks.air, 0);
		this.setBlock(world, i + 5, j + 6, k + 16, Blocks.air, 0);
		this.setBlock(world, i + 5, j + 6, k + 17, Blocks.air, 0);
		this.setBlock(world, i + 5, j + 6, k + 18, Blocks.air, 0);
		this.setBlock(world, i + 5, j + 6, k + 19, Blocks.stone_brick_stairs, 5);
		this.setBlock(world, i + 5, j + 6, k + 20, Blocks.air, 0);
		this.setBlock(world, i + 5, j + 6, k + 21, Blocks.air, 0);
		this.setBlock(world, i + 5, j + 6, k + 22, Blocks.air, 0);
		this.setBlock(world, i + 5, j + 6, k + 23, Blocks.air, 0);
		this.setBlock(world, i + 5, j + 6, k + 24, Blocks.air, 0);
		this.setBlock(world, i + 5, j + 6, k + 25, Blocks.air, 0);
		this.setBlock(world, i + 5, j + 6, k + 26, Blocks.air, 0);
		this.setBlock(world, i + 5, j + 6, k + 27, Blocks.stone_brick_stairs, 5);
		this.setBlock(world, i + 5, j + 6, k + 28, Blocks.cobblestone, 0);
		this.setBlock(world, i + 5, j + 7, k + 3, Blocks.stonebrick, 0);
		this.setBlock(world, i + 5, j + 7, k + 4, Blocks.stone_brick_stairs, 5);
		this.setBlock(world, i + 5, j + 7, k + 5, Blocks.air, 0);
		this.setBlock(world, i + 5, j + 7, k + 6, Blocks.air, 0);
		this.setBlock(world, i + 5, j + 7, k + 7, Blocks.air, 0);
		this.setBlock(world, i + 5, j + 7, k + 8, Blocks.air, 0);
		this.setBlock(world, i + 5, j + 7, k + 9, Blocks.air, 0);
		this.setBlock(world, i + 5, j + 7, k + 10, Blocks.stone_brick_stairs, 5);
		this.setBlock(world, i + 5, j + 7, k + 11, Blocks.stonebrick, 0);
		this.setBlock(world, i + 5, j + 7, k + 12, Blocks.stone_brick_stairs, 5);
		this.setBlock(world, i + 5, j + 7, k + 13, Blocks.air, 0);
		this.setBlock(world, i + 5, j + 7, k + 14, Blocks.air, 0);
		this.setBlock(world, i + 5, j + 7, k + 15, Blocks.air, 0);
		this.setBlock(world, i + 5, j + 7, k + 16, Blocks.air, 0);
		this.setBlock(world, i + 5, j + 7, k + 17, Blocks.air, 0);
		this.setBlock(world, i + 5, j + 7, k + 18, Blocks.stone_brick_stairs, 5);
		this.setBlock(world, i + 5, j + 7, k + 19, Blocks.stonebrick, 0);
		this.setBlock(world, i + 5, j + 7, k + 20, Blocks.stone_brick_stairs, 5);
		this.setBlock(world, i + 5, j + 7, k + 21, Blocks.air, 0);
		this.setBlock(world, i + 5, j + 7, k + 22, Blocks.air, 0);
		this.setBlock(world, i + 5, j + 7, k + 23, Blocks.air, 0);
		this.setBlock(world, i + 5, j + 7, k + 24, Blocks.air, 0);
		this.setBlock(world, i + 5, j + 7, k + 25, Blocks.air, 0);
		this.setBlock(world, i + 5, j + 7, k + 26, Blocks.stone_brick_stairs, 5);
		this.setBlock(world, i + 5, j + 7, k + 27, Blocks.stonebrick, 0);
		this.setBlock(world, i + 5, j + 8, k + 4, Blocks.stonebrick, 0);
		this.setBlock(world, i + 5, j + 8, k + 5, Blocks.stonebrick, 0);
		this.setBlock(world, i + 5, j + 8, k + 6, Blocks.air, 0);
		this.setBlock(world, i + 5, j + 8, k + 7, Blocks.air, 0);
		this.setBlock(world, i + 5, j + 8, k + 8, Blocks.air, 0);
		this.setBlock(world, i + 5, j + 8, k + 9, Blocks.stonebrick, 0);
		this.setBlock(world, i + 5, j + 8, k + 10, Blocks.stonebrick, 0);
		this.setBlock(world, i + 5, j + 8, k + 12, Blocks.stonebrick, 0);
		this.setBlock(world, i + 5, j + 8, k + 13, Blocks.stonebrick, 0);
		this.setBlock(world, i + 5, j + 8, k + 14, Blocks.air, 0);
		this.setBlock(world, i + 5, j + 8, k + 15, Blocks.air, 0);
		this.setBlock(world, i + 5, j + 8, k + 16, Blocks.air, 0);
		this.setBlock(world, i + 5, j + 8, k + 17, Blocks.stonebrick, 0);
		this.setBlock(world, i + 5, j + 8, k + 18, Blocks.stonebrick, 0);
		this.setBlock(world, i + 5, j + 8, k + 20, Blocks.stonebrick, 0);
		this.setBlock(world, i + 5, j + 8, k + 21, Blocks.stonebrick, 0);
		this.setBlock(world, i + 5, j + 8, k + 22, Blocks.air, 0);
		this.setBlock(world, i + 5, j + 8, k + 23, Blocks.air, 0);
		this.setBlock(world, i + 5, j + 8, k + 24, Blocks.air, 0);
		this.setBlock(world, i + 5, j + 8, k + 25, Blocks.stonebrick, 0);
		this.setBlock(world, i + 5, j + 8, k + 26, Blocks.stonebrick, 0);
		this.setBlock(world, i + 5, j + 9, k + 5, Blocks.stonebrick, 0);
		this.setBlock(world, i + 5, j + 9, k + 6, Blocks.stone_brick_stairs, 7);
		this.setBlock(world, i + 5, j + 9, k + 7, Blocks.air, 0);
		this.setBlock(world, i + 5, j + 9, k + 8, Blocks.stone_brick_stairs, 6);
		this.setBlock(world, i + 5, j + 9, k + 9, Blocks.stonebrick, 0);
		this.setBlock(world, i + 5, j + 9, k + 13, Blocks.stonebrick, 0);
		this.setBlock(world, i + 5, j + 9, k + 14, Blocks.stone_brick_stairs, 7);
		this.setBlock(world, i + 5, j + 9, k + 15, Blocks.air, 0);
		this.setBlock(world, i + 5, j + 9, k + 16, Blocks.stone_brick_stairs, 6);
		this.setBlock(world, i + 5, j + 9, k + 17, Blocks.stonebrick, 0);
		this.setBlock(world, i + 5, j + 9, k + 21, Blocks.stonebrick, 0);
		this.setBlock(world, i + 5, j + 9, k + 22, Blocks.stone_brick_stairs, 7);
		this.setBlock(world, i + 5, j + 9, k + 23, Blocks.air, 0);
		this.setBlock(world, i + 5, j + 9, k + 24, Blocks.stone_brick_stairs, 6);
		this.setBlock(world, i + 5, j + 9, k + 25, Blocks.stonebrick, 0);
		this.setBlock(world, i + 5, j + 10, k + 6, Blocks.stonebrick, 0);
		this.setBlock(world, i + 5, j + 10, k + 7, Blocks.stonebrick, 0);
		this.setBlock(world, i + 5, j + 10, k + 8, Blocks.stonebrick, 0);
		this.setBlock(world, i + 5, j + 10, k + 14, Blocks.stonebrick, 0);
		this.setBlock(world, i + 5, j + 10, k + 15, Blocks.stonebrick, 0);
		this.setBlock(world, i + 5, j + 10, k + 16, Blocks.stonebrick, 0);
		this.setBlock(world, i + 5, j + 10, k + 22, Blocks.stonebrick, 0);
		this.setBlock(world, i + 5, j + 10, k + 23, Blocks.stonebrick, 0);
		this.setBlock(world, i + 5, j + 10, k + 24, Blocks.stonebrick, 0);
		this.setBlock(world, i + 6, j + 0, k + 0, Blocks.stonebrick, 3);
		this.setBlock(world, i + 6, j + 0, k + 1, Blocks.stonebrick, 3);
		this.setBlock(world, i + 6, j + 0, k + 2, Blocks.stonebrick, 3);
		this.setBlock(world, i + 6, j + 0, k + 3, Blocks.mycelium, 0);
		this.setBlock(world, i + 6, j + 0, k + 4, Blocks.mycelium, 0);
		this.setBlock(world, i + 6, j + 0, k + 5, Blocks.mycelium, 0);
		this.setBlock(world, i + 6, j + 0, k + 6, Blocks.mycelium, 0);
		this.setBlock(world, i + 6, j + 0, k + 7, Blocks.mossy_cobblestone, 0);
		this.setBlock(world, i + 6, j + 0, k + 8, Blocks.mycelium, 0);
		this.setBlock(world, i + 6, j + 0, k + 9, Blocks.mycelium, 0);
		this.setBlock(world, i + 6, j + 0, k + 10, Blocks.mycelium, 0);
		this.setBlock(world, i + 6, j + 0, k + 11, Blocks.cobblestone, 0);
		this.setBlock(world, i + 6, j + 0, k + 12, Blocks.mycelium, 0);
		this.setBlock(world, i + 6, j + 0, k + 13, Blocks.mycelium, 0);
		this.setBlock(world, i + 6, j + 0, k + 14, Blocks.mycelium, 0);
		this.setBlock(world, i + 6, j + 0, k + 15, Blocks.mycelium, 0);
		this.setBlock(world, i + 6, j + 0, k + 16, Blocks.mossy_cobblestone, 0);
		this.setBlock(world, i + 6, j + 0, k + 17, Blocks.mycelium, 0);
		this.setBlock(world, i + 6, j + 0, k + 18, Blocks.mycelium, 0);
		this.setBlock(world, i + 6, j + 0, k + 19, Blocks.mycelium, 0);
		this.setBlock(world, i + 6, j + 0, k + 20, Blocks.mycelium, 0);
		this.setBlock(world, i + 6, j + 0, k + 21, Blocks.stonebrick, 3);
		this.setBlock(world, i + 6, j + 0, k + 22, Blocks.mycelium, 0);
		this.setBlock(world, i + 6, j + 0, k + 23, Blocks.mycelium, 0);
		this.setBlock(world, i + 6, j + 0, k + 24, Blocks.mycelium, 0);
		this.setBlock(world, i + 6, j + 0, k + 25, Blocks.mycelium, 0);
		this.setBlock(world, i + 6, j + 0, k + 26, Blocks.mycelium, 0);
		this.setBlock(world, i + 6, j + 0, k + 27, Blocks.stonebrick, 2);
		this.setBlock(world, i + 6, j + 0, k + 28, Blocks.stonebrick, 3);
		this.setBlock(world, i + 6, j + 0, k + 29, Blocks.stonebrick, 3);
		this.setBlock(world, i + 6, j + 0, k + 30, Blocks.stonebrick, 3);
		this.setBlock(world, i + 6, j + 1, k + 0, Blocks.mossy_cobblestone, 0);
		this.setBlock(world, i + 6, j + 1, k + 1, ModBlocks.gravewoodStairs, 7);
		this.setBlock(world, i + 6, j + 1, k + 2, Blocks.air, 0);
		this.setBlock(world, i + 6, j + 1, k + 3, Blocks.air, 0);
		this.setBlock(world, i + 6, j + 1, k + 4, Blocks.air, 0);
		this.setBlock(world, i + 6, j + 1, k + 5, Blocks.air, 0);
		this.setBlock(world, i + 6, j + 1, k + 6, Blocks.stone_stairs, 2);
		this.setBlock(world, i + 6, j + 1, k + 7, Blocks.stone_stairs, 0);
		this.setBlock(world, i + 6, j + 1, k + 8, Blocks.stone_stairs, 0);
		this.setBlock(world, i + 6, j + 1, k + 9, Blocks.air, 0);
		this.setBlock(world, i + 6, j + 1, k + 10, Blocks.air, 0);
		this.setBlock(world, i + 6, j + 1, k + 11, Blocks.air, 0);
		this.setBlock(world, i + 6, j + 1, k + 12, Blocks.air, 0);
		this.setBlock(world, i + 6, j + 1, k + 13, Blocks.air, 0);
		this.setBlock(world, i + 6, j + 1, k + 14, Blocks.air, 0);
		this.setBlock(world, i + 6, j + 1, k + 15, Blocks.air, 0);
		this.setBlock(world, i + 6, j + 1, k + 16, Blocks.air, 0);
		this.setBlock(world, i + 6, j + 1, k + 17, Blocks.air, 0);
		this.setBlock(world, i + 6, j + 1, k + 18, Blocks.air, 0);
		this.setBlock(world, i + 6, j + 1, k + 19, Blocks.air, 0);
		this.setBlock(world, i + 6, j + 1, k + 20, Blocks.air, 0);
		this.setBlock(world, i + 6, j + 1, k + 21, Blocks.air, 0);
		this.setBlock(world, i + 6, j + 1, k + 22, Blocks.stone_stairs, 0);
		this.setBlock(world, i + 6, j + 1, k + 23, Blocks.stone_stairs, 0);
		this.setBlock(world, i + 6, j + 1, k + 24, Blocks.stone_stairs, 0);
		this.setBlock(world, i + 6, j + 1, k + 25, Blocks.air, 0);
		this.setBlock(world, i + 6, j + 1, k + 26, Blocks.air, 0);
		this.setBlock(world, i + 6, j + 1, k + 27, Blocks.air, 0);
		this.setBlock(world, i + 6, j + 1, k + 28, Blocks.air, 0);
		this.setBlock(world, i + 6, j + 1, k + 29, ModBlocks.gravewoodStairs, 6);
		this.setBlock(world, i + 6, j + 1, k + 30, Blocks.mossy_cobblestone, 0);
		this.setBlock(world, i + 6, j + 2, k + 0, Blocks.cobblestone, 0);
		this.setBlock(world, i + 6, j + 2, k + 1, Blocks.chest, 3);
		tileentitychest = (TileEntityChest) world.getTileEntity(new BlockPos(i + 6, j + 2, k + 1));
		if (tileentitychest != null)
		{
			WeightedRandomChestContent.generateChestContents(new Random(), GraveyardChestLoot.getItems(new Random()), tileentitychest, 1);
		}
		this.setBlock(world, i + 6, j + 2, k + 2, Blocks.air, 0);
		this.setBlock(world, i + 6, j + 2, k + 3, Blocks.air, 0);
		this.setBlock(world, i + 6, j + 2, k + 4, Blocks.air, 0);
		this.setBlock(world, i + 6, j + 2, k + 5, Blocks.air, 0);
		this.setBlock(world, i + 6, j + 2, k + 6, Blocks.air, 0);
		this.setBlock(world, i + 6, j + 2, k + 7, Blocks.air, 0);
		this.setBlock(world, i + 6, j + 2, k + 8, Blocks.air, 0);
		this.setBlock(world, i + 6, j + 2, k + 9, Blocks.air, 0);
		this.setBlock(world, i + 6, j + 2, k + 10, Blocks.air, 0);
		this.setBlock(world, i + 6, j + 2, k + 11, Blocks.air, 0);
		this.setBlock(world, i + 6, j + 2, k + 12, Blocks.air, 0);
		this.setBlock(world, i + 6, j + 2, k + 13, Blocks.air, 0);
		this.setBlock(world, i + 6, j + 2, k + 14, Blocks.air, 0);
		this.setBlock(world, i + 6, j + 2, k + 15, Blocks.air, 0);
		this.setBlock(world, i + 6, j + 2, k + 16, Blocks.air, 0);
		this.setBlock(world, i + 6, j + 2, k + 17, Blocks.air, 0);
		this.setBlock(world, i + 6, j + 2, k + 18, Blocks.air, 0);
		this.setBlock(world, i + 6, j + 2, k + 19, Blocks.air, 0);
		this.setBlock(world, i + 6, j + 2, k + 20, Blocks.air, 0);
		this.setBlock(world, i + 6, j + 2, k + 21, Blocks.air, 0);
		this.setBlock(world, i + 6, j + 2, k + 22, Blocks.air, 0);
		this.setBlock(world, i + 6, j + 2, k + 23, Blocks.air, 0);
		this.setBlock(world, i + 6, j + 2, k + 24, Blocks.air, 0);
		this.setBlock(world, i + 6, j + 2, k + 25, Blocks.air, 0);
		this.setBlock(world, i + 6, j + 2, k + 26, Blocks.air, 0);
		this.setBlock(world, i + 6, j + 2, k + 27, Blocks.air, 0);
		this.setBlock(world, i + 6, j + 2, k + 28, Blocks.air, 0);
		this.setBlock(world, i + 6, j + 2, k + 29, Blocks.chest, 2);
		tileentitychest = (TileEntityChest) world.getTileEntity(new BlockPos(i + 6, j + 2, k + 29));
		if (tileentitychest != null)
		{
			WeightedRandomChestContent.generateChestContents(new Random(), GraveyardChestLoot.getItems(new Random()), tileentitychest, 1);
		}
		this.setBlock(world, i + 6, j + 2, k + 30, Blocks.mossy_cobblestone, 0);
		this.setBlock(world, i + 6, j + 3, k + 0, Blocks.mossy_cobblestone, 0);
		this.setBlock(world, i + 6, j + 3, k + 1, Blocks.air, 0);
		this.setBlock(world, i + 6, j + 3, k + 2, Blocks.air, 0);
		this.setBlock(world, i + 6, j + 3, k + 3, Blocks.air, 0);
		this.setBlock(world, i + 6, j + 3, k + 4, Blocks.air, 0);
		this.setBlock(world, i + 6, j + 3, k + 5, Blocks.air, 0);
		this.setBlock(world, i + 6, j + 3, k + 6, Blocks.air, 0);
		this.setBlock(world, i + 6, j + 3, k + 7, Blocks.air, 0);
		this.setBlock(world, i + 6, j + 3, k + 8, Blocks.air, 0);
		this.setBlock(world, i + 6, j + 3, k + 9, Blocks.air, 0);
		this.setBlock(world, i + 6, j + 3, k + 10, Blocks.air, 0);
		this.setBlock(world, i + 6, j + 3, k + 11, Blocks.air, 0);
		this.setBlock(world, i + 6, j + 3, k + 12, Blocks.air, 0);
		this.setBlock(world, i + 6, j + 3, k + 13, Blocks.air, 0);
		this.setBlock(world, i + 6, j + 3, k + 14, Blocks.air, 0);
		this.setBlock(world, i + 6, j + 3, k + 15, Blocks.air, 0);
		this.setBlock(world, i + 6, j + 3, k + 16, Blocks.air, 0);
		this.setBlock(world, i + 6, j + 3, k + 17, Blocks.air, 0);
		this.setBlock(world, i + 6, j + 3, k + 18, Blocks.air, 0);
		this.setBlock(world, i + 6, j + 3, k + 19, Blocks.air, 0);
		this.setBlock(world, i + 6, j + 3, k + 20, Blocks.air, 0);
		this.setBlock(world, i + 6, j + 3, k + 21, Blocks.air, 0);
		this.setBlock(world, i + 6, j + 3, k + 22, Blocks.air, 0);
		this.setBlock(world, i + 6, j + 3, k + 23, Blocks.air, 0);
		this.setBlock(world, i + 6, j + 3, k + 24, Blocks.air, 0);
		this.setBlock(world, i + 6, j + 3, k + 25, Blocks.air, 0);
		this.setBlock(world, i + 6, j + 3, k + 26, Blocks.air, 0);
		this.setBlock(world, i + 6, j + 3, k + 27, Blocks.air, 0);
		this.setBlock(world, i + 6, j + 3, k + 28, Blocks.air, 0);
		this.setBlock(world, i + 6, j + 3, k + 29, Blocks.air, 0);
		this.setBlock(world, i + 6, j + 3, k + 30, Blocks.cobblestone, 0);
		this.setBlock(world, i + 6, j + 4, k + 0, Blocks.mossy_cobblestone, 0);
		this.setBlock(world, i + 6, j + 4, k + 1, Blocks.air, 0);
		this.setBlock(world, i + 6, j + 4, k + 2, Blocks.air, 0);
		this.setBlock(world, i + 6, j + 4, k + 3, Blocks.air, 0);
		this.setBlock(world, i + 6, j + 4, k + 4, Blocks.air, 0);
		this.setBlock(world, i + 6, j + 4, k + 5, Blocks.air, 0);
		this.setBlock(world, i + 6, j + 4, k + 6, Blocks.air, 0);
		this.setBlock(world, i + 6, j + 4, k + 7, Blocks.air, 0);
		this.setBlock(world, i + 6, j + 4, k + 8, Blocks.air, 0);
		this.setBlock(world, i + 6, j + 4, k + 9, Blocks.air, 0);
		this.setBlock(world, i + 6, j + 4, k + 10, Blocks.air, 0);
		this.setBlock(world, i + 6, j + 4, k + 11, Blocks.air, 0);
		this.setBlock(world, i + 6, j + 4, k + 12, Blocks.air, 0);
		this.setBlock(world, i + 6, j + 4, k + 13, Blocks.air, 0);
		this.setBlock(world, i + 6, j + 4, k + 14, Blocks.air, 0);
		this.setBlock(world, i + 6, j + 4, k + 15, Blocks.air, 0);
		this.setBlock(world, i + 6, j + 4, k + 16, Blocks.air, 0);
		this.setBlock(world, i + 6, j + 4, k + 17, Blocks.air, 0);
		this.setBlock(world, i + 6, j + 4, k + 18, Blocks.air, 0);
		this.setBlock(world, i + 6, j + 4, k + 19, Blocks.air, 0);
		this.setBlock(world, i + 6, j + 4, k + 20, Blocks.air, 0);
		this.setBlock(world, i + 6, j + 4, k + 21, Blocks.air, 0);
		this.setBlock(world, i + 6, j + 4, k + 22, Blocks.air, 0);
		this.setBlock(world, i + 6, j + 4, k + 23, Blocks.air, 0);
		this.setBlock(world, i + 6, j + 4, k + 24, Blocks.air, 0);
		this.setBlock(world, i + 6, j + 4, k + 25, Blocks.air, 0);
		this.setBlock(world, i + 6, j + 4, k + 26, Blocks.air, 0);
		this.setBlock(world, i + 6, j + 4, k + 27, Blocks.air, 0);
		this.setBlock(world, i + 6, j + 4, k + 28, Blocks.air, 0);
		this.setBlock(world, i + 6, j + 4, k + 29, Blocks.air, 0);
		this.setBlock(world, i + 6, j + 4, k + 30, Blocks.cobblestone, 0);
		this.setBlock(world, i + 6, j + 5, k + 0, Blocks.mossy_cobblestone, 0);
		this.setBlock(world, i + 6, j + 5, k + 1, Blocks.stone_stairs, 5);
		this.setBlock(world, i + 6, j + 5, k + 2, Blocks.air, 0);
		this.setBlock(world, i + 6, j + 5, k + 3, Blocks.air, 0);
		this.setBlock(world, i + 6, j + 5, k + 4, Blocks.air, 0);
		this.setBlock(world, i + 6, j + 5, k + 5, Blocks.air, 0);
		this.setBlock(world, i + 6, j + 5, k + 6, Blocks.air, 0);
		this.setBlock(world, i + 6, j + 5, k + 7, Blocks.air, 0);
		this.setBlock(world, i + 6, j + 5, k + 8, Blocks.air, 0);
		this.setBlock(world, i + 6, j + 5, k + 9, Blocks.air, 0);
		this.setBlock(world, i + 6, j + 5, k + 10, Blocks.air, 0);
		this.setBlock(world, i + 6, j + 5, k + 11, Blocks.air, 0);
		this.setBlock(world, i + 6, j + 5, k + 12, Blocks.air, 0);
		this.setBlock(world, i + 6, j + 5, k + 13, Blocks.air, 0);
		this.setBlock(world, i + 6, j + 5, k + 14, Blocks.air, 0);
		this.setBlock(world, i + 6, j + 5, k + 15, Blocks.air, 0);
		this.setBlock(world, i + 6, j + 5, k + 16, Blocks.air, 0);
		this.setBlock(world, i + 6, j + 5, k + 17, Blocks.air, 0);
		this.setBlock(world, i + 6, j + 5, k + 18, Blocks.air, 0);
		this.setBlock(world, i + 6, j + 5, k + 19, Blocks.air, 0);
		this.setBlock(world, i + 6, j + 5, k + 20, Blocks.air, 0);
		this.setBlock(world, i + 6, j + 5, k + 21, Blocks.air, 0);
		this.setBlock(world, i + 6, j + 5, k + 22, Blocks.air, 0);
		this.setBlock(world, i + 6, j + 5, k + 23, Blocks.air, 0);
		this.setBlock(world, i + 6, j + 5, k + 24, Blocks.air, 0);
		this.setBlock(world, i + 6, j + 5, k + 25, Blocks.air, 0);
		this.setBlock(world, i + 6, j + 5, k + 26, Blocks.air, 0);
		this.setBlock(world, i + 6, j + 5, k + 27, Blocks.air, 0);
		this.setBlock(world, i + 6, j + 5, k + 28, Blocks.air, 0);
		this.setBlock(world, i + 6, j + 5, k + 29, Blocks.stone_stairs, 5);
		this.setBlock(world, i + 6, j + 5, k + 30, Blocks.cobblestone, 0);
		this.setBlock(world, i + 6, j + 6, k + 1, Blocks.mossy_cobblestone, 0);
		this.setBlock(world, i + 6, j + 6, k + 2, Blocks.stone_stairs, 5);
		this.setBlock(world, i + 6, j + 6, k + 3, Blocks.air, 0);
		this.setBlock(world, i + 6, j + 6, k + 4, Blocks.air, 0);
		this.setBlock(world, i + 6, j + 6, k + 5, Blocks.air, 0);
		this.setBlock(world, i + 6, j + 6, k + 6, Blocks.air, 0);
		this.setBlock(world, i + 6, j + 6, k + 7, Blocks.air, 0);
		this.setBlock(world, i + 6, j + 6, k + 8, Blocks.air, 0);
		this.setBlock(world, i + 6, j + 6, k + 9, Blocks.air, 0);
		this.setBlock(world, i + 6, j + 6, k + 10, Blocks.air, 0);
		this.setBlock(world, i + 6, j + 6, k + 11, Blocks.air, 0);
		this.setBlock(world, i + 6, j + 6, k + 12, Blocks.air, 0);
		this.setBlock(world, i + 6, j + 6, k + 13, Blocks.air, 0);
		this.setBlock(world, i + 6, j + 6, k + 14, Blocks.air, 0);
		this.setBlock(world, i + 6, j + 6, k + 15, Blocks.air, 0);
		this.setBlock(world, i + 6, j + 6, k + 16, Blocks.air, 0);
		this.setBlock(world, i + 6, j + 6, k + 17, Blocks.air, 0);
		this.setBlock(world, i + 6, j + 6, k + 18, Blocks.air, 0);
		this.setBlock(world, i + 6, j + 6, k + 19, Blocks.air, 0);
		this.setBlock(world, i + 6, j + 6, k + 20, Blocks.air, 0);
		this.setBlock(world, i + 6, j + 6, k + 21, Blocks.air, 0);
		this.setBlock(world, i + 6, j + 6, k + 22, Blocks.air, 0);
		this.setBlock(world, i + 6, j + 6, k + 23, Blocks.air, 0);
		this.setBlock(world, i + 6, j + 6, k + 24, Blocks.air, 0);
		this.setBlock(world, i + 6, j + 6, k + 25, Blocks.air, 0);
		this.setBlock(world, i + 6, j + 6, k + 26, Blocks.air, 0);
		this.setBlock(world, i + 6, j + 6, k + 27, Blocks.air, 0);
		this.setBlock(world, i + 6, j + 6, k + 28, Blocks.stone_stairs, 5);
		this.setBlock(world, i + 6, j + 6, k + 29, Blocks.mossy_cobblestone, 0);
		this.setBlock(world, i + 6, j + 7, k + 2, Blocks.cobblestone, 0);
		this.setBlock(world, i + 6, j + 7, k + 3, Blocks.stone_brick_stairs, 5);
		this.setBlock(world, i + 6, j + 7, k + 4, Blocks.air, 0);
		this.setBlock(world, i + 6, j + 7, k + 5, Blocks.air, 0);
		this.setBlock(world, i + 6, j + 7, k + 6, Blocks.air, 0);
		this.setBlock(world, i + 6, j + 7, k + 7, Blocks.air, 0);
		this.setBlock(world, i + 6, j + 7, k + 8, Blocks.air, 0);
		this.setBlock(world, i + 6, j + 7, k + 9, Blocks.air, 0);
		this.setBlock(world, i + 6, j + 7, k + 10, Blocks.air, 0);
		this.setBlock(world, i + 6, j + 7, k + 11, Blocks.stone_brick_stairs, 5);
		this.setBlock(world, i + 6, j + 7, k + 12, Blocks.air, 0);
		this.setBlock(world, i + 6, j + 7, k + 13, Blocks.air, 0);
		this.setBlock(world, i + 6, j + 7, k + 14, Blocks.air, 0);
		this.setBlock(world, i + 6, j + 7, k + 15, Blocks.air, 0);
		this.setBlock(world, i + 6, j + 7, k + 16, Blocks.air, 0);
		this.setBlock(world, i + 6, j + 7, k + 17, Blocks.air, 0);
		this.setBlock(world, i + 6, j + 7, k + 18, Blocks.air, 0);
		this.setBlock(world, i + 6, j + 7, k + 19, Blocks.stone_brick_stairs, 5);
		this.setBlock(world, i + 6, j + 7, k + 20, Blocks.air, 0);
		this.setBlock(world, i + 6, j + 7, k + 21, Blocks.air, 0);
		this.setBlock(world, i + 6, j + 7, k + 22, Blocks.air, 0);
		this.setBlock(world, i + 6, j + 7, k + 23, Blocks.air, 0);
		this.setBlock(world, i + 6, j + 7, k + 24, Blocks.air, 0);
		this.setBlock(world, i + 6, j + 7, k + 25, Blocks.air, 0);
		this.setBlock(world, i + 6, j + 7, k + 26, Blocks.air, 0);
		this.setBlock(world, i + 6, j + 7, k + 27, Blocks.stone_brick_stairs, 5);
		this.setBlock(world, i + 6, j + 7, k + 28, Blocks.mossy_cobblestone, 0);
		this.setBlock(world, i + 6, j + 8, k + 3, Blocks.stonebrick, 0);
		this.setBlock(world, i + 6, j + 8, k + 4, Blocks.stone_brick_stairs, 5);
		this.setBlock(world, i + 6, j + 8, k + 5, Blocks.air, 0);
		this.setBlock(world, i + 6, j + 8, k + 6, Blocks.air, 0);
		this.setBlock(world, i + 6, j + 8, k + 7, Blocks.air, 0);
		this.setBlock(world, i + 6, j + 8, k + 8, Blocks.air, 0);
		this.setBlock(world, i + 6, j + 8, k + 9, Blocks.air, 0);
		this.setBlock(world, i + 6, j + 8, k + 10, Blocks.stone_brick_stairs, 5);
		this.setBlock(world, i + 6, j + 8, k + 11, Blocks.stonebrick, 0);
		this.setBlock(world, i + 6, j + 8, k + 12, Blocks.stone_brick_stairs, 5);
		this.setBlock(world, i + 6, j + 8, k + 13, Blocks.air, 0);
		this.setBlock(world, i + 6, j + 8, k + 14, Blocks.air, 0);
		this.setBlock(world, i + 6, j + 8, k + 15, Blocks.air, 0);
		this.setBlock(world, i + 6, j + 8, k + 16, Blocks.air, 0);
		this.setBlock(world, i + 6, j + 8, k + 17, Blocks.air, 0);
		this.setBlock(world, i + 6, j + 8, k + 18, Blocks.stone_brick_stairs, 5);
		this.setBlock(world, i + 6, j + 8, k + 19, Blocks.stonebrick, 0);
		this.setBlock(world, i + 6, j + 8, k + 20, Blocks.stone_brick_stairs, 5);
		this.setBlock(world, i + 6, j + 8, k + 21, Blocks.air, 0);
		this.setBlock(world, i + 6, j + 8, k + 22, Blocks.air, 0);
		this.setBlock(world, i + 6, j + 8, k + 23, Blocks.air, 0);
		this.setBlock(world, i + 6, j + 8, k + 24, Blocks.air, 0);
		this.setBlock(world, i + 6, j + 8, k + 25, Blocks.air, 0);
		this.setBlock(world, i + 6, j + 8, k + 26, Blocks.stone_brick_stairs, 5);
		this.setBlock(world, i + 6, j + 8, k + 27, Blocks.stonebrick, 0);
		this.setBlock(world, i + 6, j + 9, k + 4, Blocks.stonebrick, 0);
		this.setBlock(world, i + 6, j + 9, k + 5, Blocks.stone_brick_stairs, 5);
		this.setBlock(world, i + 6, j + 9, k + 6, Blocks.stone_slab, 13);
		this.setBlock(world, i + 6, j + 9, k + 7, Blocks.air, 0);
		this.setBlock(world, i + 6, j + 9, k + 8, Blocks.stone_slab, 13);
		this.setBlock(world, i + 6, j + 9, k + 9, Blocks.stone_brick_stairs, 5);
		this.setBlock(world, i + 6, j + 9, k + 10, Blocks.stonebrick, 0);
		this.setBlock(world, i + 6, j + 9, k + 12, Blocks.stonebrick, 0);
		this.setBlock(world, i + 6, j + 9, k + 13, Blocks.stone_brick_stairs, 5);
		this.setBlock(world, i + 6, j + 9, k + 14, Blocks.stone_slab, 13);
		this.setBlock(world, i + 6, j + 9, k + 15, Blocks.air, 0);
		this.setBlock(world, i + 6, j + 9, k + 16, Blocks.stone_slab, 13);
		this.setBlock(world, i + 6, j + 9, k + 17, Blocks.stone_brick_stairs, 5);
		this.setBlock(world, i + 6, j + 9, k + 18, Blocks.stonebrick, 0);
		this.setBlock(world, i + 6, j + 9, k + 20, Blocks.stonebrick, 0);
		this.setBlock(world, i + 6, j + 9, k + 21, Blocks.stone_brick_stairs, 5);
		this.setBlock(world, i + 6, j + 9, k + 22, Blocks.stone_slab, 13);
		this.setBlock(world, i + 6, j + 9, k + 23, Blocks.air, 0);
		this.setBlock(world, i + 6, j + 9, k + 24, Blocks.stone_slab, 13);
		this.setBlock(world, i + 6, j + 9, k + 25, Blocks.stone_brick_stairs, 5);
		this.setBlock(world, i + 6, j + 9, k + 26, Blocks.stonebrick, 0);
		this.setBlock(world, i + 6, j + 10, k + 5, Blocks.stonebrick, 0);
		this.setBlock(world, i + 6, j + 10, k + 6, Blocks.stonebrick, 0);
		this.setBlock(world, i + 6, j + 10, k + 7, Blocks.stonebrick, 0);
		this.setBlock(world, i + 6, j + 10, k + 8, Blocks.stonebrick, 0);
		this.setBlock(world, i + 6, j + 10, k + 9, Blocks.stonebrick, 0);
		this.setBlock(world, i + 6, j + 10, k + 13, Blocks.stonebrick, 0);
		this.setBlock(world, i + 6, j + 10, k + 14, Blocks.stonebrick, 0);
		this.setBlock(world, i + 6, j + 10, k + 15, Blocks.stonebrick, 0);
		this.setBlock(world, i + 6, j + 10, k + 16, Blocks.stonebrick, 0);
		this.setBlock(world, i + 6, j + 10, k + 17, Blocks.stonebrick, 0);
		this.setBlock(world, i + 6, j + 10, k + 21, Blocks.stonebrick, 0);
		this.setBlock(world, i + 6, j + 10, k + 22, Blocks.stonebrick, 0);
		this.setBlock(world, i + 6, j + 10, k + 23, Blocks.stonebrick, 0);
		this.setBlock(world, i + 6, j + 10, k + 24, Blocks.stonebrick, 0);
		this.setBlock(world, i + 6, j + 10, k + 25, Blocks.stonebrick, 0);
		this.setBlock(world, i + 7, j + 0, k + 0, Blocks.stonebrick, 3);
		this.setBlock(world, i + 7, j + 0, k + 1, Blocks.stonebrick, 3);
		this.setBlock(world, i + 7, j + 0, k + 2, Blocks.stonebrick, 3);
		this.setBlock(world, i + 7, j + 0, k + 3, Blocks.cobblestone, 0);
		this.setBlock(world, i + 7, j + 0, k + 4, Blocks.mycelium, 0);
		this.setBlock(world, i + 7, j + 0, k + 5, Blocks.mycelium, 0);
		this.setBlock(world, i + 7, j + 0, k + 6, Blocks.mycelium, 0);
		this.setBlock(world, i + 7, j + 0, k + 7, Blocks.mossy_cobblestone, 0);
		this.setBlock(world, i + 7, j + 0, k + 8, Blocks.mossy_cobblestone, 0);
		this.setBlock(world, i + 7, j + 0, k + 9, Blocks.mycelium, 0);
		this.setBlock(world, i + 7, j + 0, k + 10, Blocks.mycelium, 0);
		this.setBlock(world, i + 7, j + 0, k + 11, Blocks.mycelium, 0);
		this.setBlock(world, i + 7, j + 0, k + 12, Blocks.mycelium, 0);
		this.setBlock(world, i + 7, j + 0, k + 13, Blocks.mycelium, 0);
		this.setBlock(world, i + 7, j + 0, k + 14, Blocks.mossy_cobblestone, 0);
		this.setBlock(world, i + 7, j + 0, k + 15, Blocks.mycelium, 0);
		this.setBlock(world, i + 7, j + 0, k + 16, Blocks.stonebrick, 2);
		this.setBlock(world, i + 7, j + 0, k + 17, Blocks.mycelium, 0);
		this.setBlock(world, i + 7, j + 0, k + 18, Blocks.mycelium, 0);
		this.setBlock(world, i + 7, j + 0, k + 19, Blocks.cobblestone, 0);
		this.setBlock(world, i + 7, j + 0, k + 20, Blocks.mycelium, 0);
		this.setBlock(world, i + 7, j + 0, k + 21, Blocks.mycelium, 0);
		this.setBlock(world, i + 7, j + 0, k + 22, Blocks.mycelium, 0);
		this.setBlock(world, i + 7, j + 0, k + 23, Blocks.mycelium, 0);
		this.setBlock(world, i + 7, j + 0, k + 24, Blocks.stonebrick, 2);
		this.setBlock(world, i + 7, j + 0, k + 25, Blocks.mycelium, 0);
		this.setBlock(world, i + 7, j + 0, k + 26, Blocks.stonebrick, 2);
		this.setBlock(world, i + 7, j + 0, k + 27, Blocks.stonebrick, 2);
		this.setBlock(world, i + 7, j + 0, k + 28, Blocks.stonebrick, 3);
		this.setBlock(world, i + 7, j + 0, k + 29, Blocks.stonebrick, 3);
		this.setBlock(world, i + 7, j + 0, k + 30, Blocks.stonebrick, 3);
		this.setBlock(world, i + 7, j + 1, k + 0, Blocks.cobblestone, 0);
		this.setBlock(world, i + 7, j + 1, k + 1, ModBlocks.gravewoodStairs, 7);
		this.setBlock(world, i + 7, j + 1, k + 2, Blocks.air, 0);
		this.setBlock(world, i + 7, j + 1, k + 3, Blocks.air, 0);
		this.setBlock(world, i + 7, j + 1, k + 4, Blocks.air, 0);
		this.setBlock(world, i + 7, j + 1, k + 5, Blocks.air, 0);
		this.setBlock(world, i + 7, j + 1, k + 6, Blocks.stone_stairs, 2);
		this.setBlockSpawner(world, i + 7, j + 1, k + 7, Blocks.mob_spawner, "Zombie");
		this.setBlock(world, i + 7, j + 1, k + 8, Blocks.stone_stairs, 3);
		this.setBlock(world, i + 7, j + 1, k + 9, Blocks.air, 0);
