/*
 *** MADE BY MRPONYCAPTAIN'S .SCHEMATIC TO .JAVA CONVERTING TOOL v2.0 ***
 */
package com.DavidM1A2.AfraidOfTheDark.worldGeneration;

import java.util.Random;

import net.minecraft.block.Block;
import net.minecraft.init.Blocks;
import net.minecraft.tileentity.TileEntityChest;
import net.minecraft.util.BlockPos;
import net.minecraft.util.WeightedRandomChestContent;
import net.minecraft.world.World;

import com.DavidM1A2.AfraidOfTheDark.initializeMod.ModBlocks;

public class Graveyard
{
	public static void setBlock(World world, int x, int y, int z, Block block, int metadata)
	{
		BlockPos current = new BlockPos(x, y, z);
		world.setBlockState(current, block.getDefaultState(), 2);
	}

	public static void generate(World world, Random rand, int i, int j, int k)
	{
		setBlock(world, i + 0, j + 5, k + 2, Blocks.dirt, 2);
		setBlock(world, i + 0, j + 5, k + 3, Blocks.dirt, 2);
		setBlock(world, i + 0, j + 6, k + 2, Blocks.nether_brick_fence, 0);
		setBlock(world, i + 0, j + 6, k + 3, Blocks.nether_brick_fence, 0);
		setBlock(world, i + 0, j + 7, k + 2, Blocks.air, 0);
		setBlock(world, i + 0, j + 7, k + 3, Blocks.air, 0);
		setBlock(world, i + 1, j + 1, k + 5, Blocks.stone, 0);
		setBlock(world, i + 1, j + 1, k + 6, Blocks.stone, 0);
		setBlock(world, i + 1, j + 2, k + 5, Blocks.stone, 0);
		setBlock(world, i + 1, j + 2, k + 6, Blocks.stone, 0);
		setBlock(world, i + 1, j + 3, k + 5, Blocks.stonebrick, 3);
		setBlock(world, i + 1, j + 3, k + 6, Blocks.stonebrick, 3);
		setBlock(world, i + 1, j + 4, k + 5, Blocks.stone, 0);
		setBlock(world, i + 1, j + 4, k + 6, Blocks.stone, 0);
		setBlock(world, i + 1, j + 5, k + 2, Blocks.dirt, 2);
		setBlock(world, i + 1, j + 5, k + 3, Blocks.dirt, 2);
		setBlock(world, i + 1, j + 5, k + 4, Blocks.dirt, 2);
		setBlock(world, i + 1, j + 5, k + 5, Blocks.dirt, 2);
		setBlock(world, i + 1, j + 5, k + 6, Blocks.dirt, 2);
		setBlock(world, i + 1, j + 6, k + 2, Blocks.air, 0);
		setBlock(world, i + 1, j + 6, k + 3, Blocks.air, 0);
		setBlock(world, i + 1, j + 6, k + 4, Blocks.nether_brick_fence, 0);
		setBlock(world, i + 1, j + 6, k + 5, Blocks.air, 0);
		setBlock(world, i + 1, j + 6, k + 6, Blocks.air, 0);
		setBlock(world, i + 1, j + 7, k + 2, Blocks.air, 0);
		setBlock(world, i + 1, j + 7, k + 3, Blocks.air, 0);
		setBlock(world, i + 1, j + 7, k + 4, Blocks.air, 0);
		setBlock(world, i + 1, j + 7, k + 5, Blocks.air, 0);
		setBlock(world, i + 1, j + 7, k + 6, Blocks.air, 0);
		setBlock(world, i + 1, j + 8, k + 3, Blocks.air, 0);
		setBlock(world, i + 2, j + 1, k + 3, Blocks.stone, 0);
		setBlock(world, i + 2, j + 1, k + 4, Blocks.stone, 0);
		setBlock(world, i + 2, j + 1, k + 5, Blocks.stone, 0);
		setBlock(world, i + 2, j + 1, k + 6, Blocks.stone, 0);
		setBlock(world, i + 2, j + 1, k + 7, Blocks.stone, 0);
		setBlock(world, i + 2, j + 2, k + 3, Blocks.dirt, 2);
		setBlock(world, i + 2, j + 2, k + 4, Blocks.dirt, 2);
		setBlock(world, i + 2, j + 2, k + 5, Blocks.air, 0);
		setBlock(world, i + 2, j + 2, k + 6, Blocks.stone_slab, 6);
		setBlock(world, i + 2, j + 2, k + 7, Blocks.stone, 0);
		setBlock(world, i + 2, j + 3, k + 3, Blocks.dirt, 2);
		setBlock(world, i + 2, j + 3, k + 4, Blocks.dirt, 2);
		setBlock(world, i + 2, j + 3, k + 5, Blocks.air, 0);
		setBlock(world, i + 2, j + 3, k + 6, Blocks.air, 0);
		setBlock(world, i + 2, j + 3, k + 7, Blocks.stonebrick, 3);
		setBlock(world, i + 2, j + 4, k + 3, Blocks.dirt, 2);
		setBlock(world, i + 2, j + 4, k + 4, Blocks.dirt, 2);
		setBlock(world, i + 2, j + 4, k + 5, Blocks.air, 0);
		setBlock(world, i + 2, j + 4, k + 6, Blocks.air, 0);
		setBlock(world, i + 2, j + 4, k + 7, Blocks.stone, 0);
		setBlock(world, i + 2, j + 5, k + 1, Blocks.dirt, 2);
		setBlock(world, i + 2, j + 5, k + 2, Blocks.dirt, 2);
		setBlock(world, i + 2, j + 5, k + 3, Blocks.dirt, 2);
		setBlock(world, i + 2, j + 5, k + 4, Blocks.grass, 0);
		setBlock(world, i + 2, j + 5, k + 5, Blocks.dirt, 2);
		setBlock(world, i + 2, j + 5, k + 6, Blocks.dirt, 2);
		setBlock(world, i + 2, j + 5, k + 7, Blocks.dirt, 2);
		setBlock(world, i + 2, j + 6, k + 1, Blocks.air, 0);
		setBlock(world, i + 2, j + 6, k + 2, Blocks.air, 0);
		setBlock(world, i + 2, j + 6, k + 3, Blocks.stone_slab, 6);
		setBlock(world, i + 2, j + 6, k + 4, Blocks.stone_slab, 6);
		setBlock(world, i + 2, j + 6, k + 5, Blocks.nether_brick_fence, 0);
		setBlock(world, i + 2, j + 6, k + 6, Blocks.air, 0);
		setBlock(world, i + 2, j + 6, k + 7, Blocks.air, 0);
		setBlock(world, i + 2, j + 7, k + 1, Blocks.air, 0);
		setBlock(world, i + 2, j + 7, k + 2, Blocks.air, 0);
		setBlock(world, i + 2, j + 7, k + 3, Blocks.air, 0);
		setBlock(world, i + 2, j + 7, k + 4, Blocks.air, 0);
		setBlock(world, i + 2, j + 7, k + 5, Blocks.air, 0);
		setBlock(world, i + 2, j + 7, k + 6, Blocks.air, 0);
		setBlock(world, i + 2, j + 7, k + 7, Blocks.air, 0);
		setBlock(world, i + 2, j + 8, k + 2, Blocks.air, 0);
		setBlock(world, i + 2, j + 8, k + 4, Blocks.air, 0);
		setBlock(world, i + 2, j + 8, k + 5, Blocks.air, 0);
		setBlock(world, i + 2, j + 8, k + 6, Blocks.air, 0);
		setBlock(world, i + 2, j + 10, k + 7, ModBlocks.gravewood, 0);
		setBlock(world, i + 3, j + 1, k + 3, Blocks.stone, 0);
		setBlock(world, i + 3, j + 1, k + 4, Blocks.stone, 0);
		setBlock(world, i + 3, j + 1, k + 5, Blocks.stone, 0);
		setBlock(world, i + 3, j + 1, k + 6, Blocks.stone, 0);
		setBlock(world, i + 3, j + 1, k + 7, Blocks.stone, 0);
		setBlock(world, i + 3, j + 1, k + 8, Blocks.stone, 0);
		setBlock(world, i + 3, j + 2, k + 3, Blocks.dirt, 2);
		setBlock(world, i + 3, j + 2, k + 4, Blocks.air, 0);
		setBlock(world, i + 3, j + 2, k + 5, Blocks.air, 0);
		setBlock(world, i + 3, j + 2, k + 6, Blocks.air, 0);
		setBlock(world, i + 3, j + 2, k + 7, Blocks.stone_slab, 6);
		setBlock(world, i + 3, j + 2, k + 8, Blocks.stone, 0);
		setBlock(world, i + 3, j + 2, k + 10, Blocks.stone, 0);
		setBlock(world, i + 3, j + 2, k + 11, Blocks.stone, 0);
		setBlock(world, i + 3, j + 3, k + 3, Blocks.dirt, 2);
		setBlock(world, i + 3, j + 3, k + 4, Blocks.air, 0);
		setBlock(world, i + 3, j + 3, k + 5, Blocks.air, 0);
		setBlock(world, i + 3, j + 3, k + 6, Blocks.air, 0);
		setBlock(world, i + 3, j + 3, k + 7, Blocks.air, 0);
		setBlock(world, i + 3, j + 3, k + 8, Blocks.stonebrick, 3);
		setBlock(world, i + 3, j + 3, k + 9, Blocks.dirt, 0);
		setBlock(world, i + 3, j + 3, k + 10, Blocks.dirt, 0);
		setBlock(world, i + 3, j + 3, k + 11, Blocks.dirt, 0);
		setBlock(world, i + 3, j + 4, k + 3, Blocks.dirt, 2);
		setBlock(world, i + 3, j + 4, k + 4, Blocks.air, 0);
		setBlock(world, i + 3, j + 4, k + 5, Blocks.double_stone_slab, 6);
		setBlock(world, i + 3, j + 4, k + 6, Blocks.air, 8);
		setBlock(world, i + 3, j + 4, k + 7, ModBlocks.gravewood, 0);
		setBlock(world, i + 3, j + 4, k + 8, Blocks.stone, 0);
		setBlock(world, i + 3, j + 4, k + 9, Blocks.dirt, 0);
		setBlock(world, i + 3, j + 4, k + 10, Blocks.dirt, 0);
		setBlock(world, i + 3, j + 5, k + 0, Blocks.dirt, 2);
		setBlock(world, i + 3, j + 5, k + 1, Blocks.dirt, 2);
		setBlock(world, i + 3, j + 5, k + 2, Blocks.dirt, 2);
		setBlock(world, i + 3, j + 5, k + 3, Blocks.air, 0);
		setBlock(world, i + 3, j + 5, k + 4, Blocks.air, 0);
		setBlock(world, i + 3, j + 5, k + 5, Blocks.grass, 0);
		setBlock(world, i + 3, j + 5, k + 6, Blocks.dirt, 2);
		setBlock(world, i + 3, j + 5, k + 7, Blocks.dirt, 2);
		setBlock(world, i + 3, j + 5, k + 8, Blocks.dirt, 2);
		setBlock(world, i + 3, j + 5, k + 9, Blocks.dirt, 0);
		setBlock(world, i + 3, j + 6, k + 0, Blocks.nether_brick_fence, 0);
		setBlock(world, i + 3, j + 6, k + 1, Blocks.nether_brick_fence, 0);
		setBlock(world, i + 3, j + 6, k + 2, Blocks.double_stone_slab, 6);
		setBlock(world, i + 3, j + 6, k + 3, Blocks.stone_slab, 14);
		setBlock(world, i + 3, j + 6, k + 4, Blocks.stone_slab, 14);
		setBlock(world, i + 3, j + 6, k + 5, Blocks.stone_slab, 6);
		setBlock(world, i + 3, j + 6, k + 6, Blocks.air, 0);
		setBlock(world, i + 3, j + 6, k + 7, Blocks.nether_brick_fence, 0);
		setBlock(world, i + 3, j + 6, k + 8, Blocks.nether_brick_fence, 0);
		setBlock(world, i + 3, j + 7, k + 0, Blocks.air, 0);
		setBlock(world, i + 3, j + 7, k + 1, Blocks.air, 0);
		setBlock(world, i + 3, j + 7, k + 2, Blocks.air, 0);
		setBlock(world, i + 3, j + 7, k + 3, Blocks.air, 0);
		setBlock(world, i + 3, j + 7, k + 4, Blocks.stone_slab, 6);
		setBlock(world, i + 3, j + 7, k + 5, Blocks.air, 0);
		setBlock(world, i + 3, j + 7, k + 6, Blocks.air, 0);
		setBlock(world, i + 3, j + 7, k + 7, Blocks.air, 0);
		setBlock(world, i + 3, j + 7, k + 8, Blocks.air, 0);
		setBlock(world, i + 3, j + 8, k + 1, Blocks.air, 0);
		setBlock(world, i + 3, j + 8, k + 2, Blocks.air, 0);
		setBlock(world, i + 3, j + 8, k + 3, Blocks.air, 0);
		setBlock(world, i + 3, j + 8, k + 4, Blocks.air, 0);
		setBlock(world, i + 3, j + 8, k + 5, Blocks.air, 0);
		setBlock(world, i + 3, j + 8, k + 6, Blocks.air, 0);
		setBlock(world, i + 3, j + 8, k + 7, Blocks.air, 0);
		setBlock(world, i + 3, j + 9, k + 3, Blocks.air, 0);
		setBlock(world, i + 3, j + 9, k + 4, Blocks.air, 0);
		setBlock(world, i + 3, j + 9, k + 5, Blocks.air, 0);
		setBlock(world, i + 3, j + 9, k + 7, ModBlocks.gravewood, 0);
		setBlock(world, i + 3, j + 9, k + 8, ModBlocks.gravewood, 0);
		setBlock(world, i + 4, j + 0, k + 7, Blocks.stone, 0);
		setBlock(world, i + 4, j + 1, k + 2, Blocks.stone, 0);
		setBlock(world, i + 4, j + 1, k + 3, Blocks.stone, 0);
		setBlock(world, i + 4, j + 1, k + 4, Blocks.stone, 0);
		setBlock(world, i + 4, j + 1, k + 5, Blocks.clay, 0);
		setBlock(world, i + 4, j + 1, k + 6, Blocks.stone_slab, 6);
		setBlock(world, i + 4, j + 1, k + 7, Blocks.air, 0);
		setBlock(world, i + 4, j + 1, k + 8, Blocks.stone, 0);
		setBlock(world, i + 4, j + 1, k + 9, Blocks.stone, 0);
		setBlock(world, i + 4, j + 1, k + 10, Blocks.stone, 0);
		setBlock(world, i + 4, j + 1, k + 11, Blocks.stone, 0);
		setBlock(world, i + 4, j + 2, k + 2, Blocks.stone, 0);
		setBlock(world, i + 4, j + 2, k + 3, Blocks.air, 0);
		setBlock(world, i + 4, j + 2, k + 4, Blocks.air, 0);
		setBlock(world, i + 4, j + 2, k + 5, Blocks.air, 0);
		setBlock(world, i + 4, j + 2, k + 6, Blocks.air, 0);
		setBlock(world, i + 4, j + 2, k + 7, Blocks.air, 0);
		setBlock(world, i + 4, j + 2, k + 8, Blocks.stone_slab, 6);
		setBlock(world, i + 4, j + 2, k + 9, Blocks.stone, 0);
		setBlock(world, i + 4, j + 2, k + 10, Blocks.stone_slab, 14);
		setBlock(world, i + 4, j + 2, k + 11, Blocks.lit_pumpkin, 1);
		setBlock(world, i + 4, j + 2, k + 12, Blocks.stone, 0);
		setBlock(world, i + 4, j + 2, k + 13, Blocks.stone, 0);
		setBlock(world, i + 4, j + 2, k + 14, Blocks.stone, 0);
		setBlock(world, i + 4, j + 2, k + 15, Blocks.stone, 0);
		setBlock(world, i + 4, j + 2, k + 16, Blocks.stone, 0);
		setBlock(world, i + 4, j + 3, k + 2, Blocks.stone, 0);
		setBlock(world, i + 4, j + 3, k + 3, Blocks.air, 0);
		setBlock(world, i + 4, j + 3, k + 4, Blocks.air, 0);
		setBlock(world, i + 4, j + 3, k + 5, Blocks.air, 0);
		setBlock(world, i + 4, j + 3, k + 6, Blocks.air, 0);
		setBlock(world, i + 4, j + 3, k + 7, Blocks.air, 0);
		setBlock(world, i + 4, j + 3, k + 8, Blocks.air, 0);
		setBlock(world, i + 4, j + 3, k + 9, Blocks.stonebrick, 3);
		setBlock(world, i + 4, j + 3, k + 10, Blocks.stonebrick, 3);
		setBlock(world, i + 4, j + 3, k + 11, Blocks.dirt, 0);
		setBlock(world, i + 4, j + 3, k + 12, Blocks.dirt, 0);
		setBlock(world, i + 4, j + 3, k + 13, Blocks.dirt, 0);
		setBlock(world, i + 4, j + 3, k + 14, Blocks.dirt, 0);
		setBlock(world, i + 4, j + 3, k + 15, Blocks.dirt, 0);
		setBlock(world, i + 4, j + 3, k + 16, Blocks.dirt, 0);
		setBlock(world, i + 4, j + 4, k + 2, Blocks.stone, 0);
		setBlock(world, i + 4, j + 4, k + 3, Blocks.dirt, 2);
		setBlock(world, i + 4, j + 4, k + 4, Blocks.stone_slab, 6);
		setBlock(world, i + 4, j + 4, k + 5, Blocks.dirt, 2);
		setBlock(world, i + 4, j + 4, k + 6, Blocks.air, 4);
		setBlock(world, i + 4, j + 4, k + 7, ModBlocks.gravewoodLeaves, 0);
		setBlock(world, i + 4, j + 4, k + 8, Blocks.air, 0);
		setBlock(world, i + 4, j + 4, k + 9, Blocks.stone, 0);
		setBlock(world, i + 4, j + 4, k + 10, Blocks.dirt, 0);
		setBlock(world, i + 4, j + 4, k + 11, Blocks.dirt, 0);
		setBlock(world, i + 4, j + 4, k + 12, Blocks.dirt, 0);
		setBlock(world, i + 4, j + 4, k + 13, Blocks.dirt, 0);
		setBlock(world, i + 4, j + 4, k + 14, Blocks.dirt, 0);
		setBlock(world, i + 4, j + 4, k + 15, Blocks.dirt, 0);
		setBlock(world, i + 4, j + 4, k + 16, Blocks.dirt, 0);
		setBlock(world, i + 4, j + 5, k + 0, Blocks.dirt, 2);
		setBlock(world, i + 4, j + 5, k + 1, Blocks.dirt, 2);
		setBlock(world, i + 4, j + 5, k + 2, Blocks.dirt, 2);
		setBlock(world, i + 4, j + 5, k + 3, Blocks.air, 0);
		setBlock(world, i + 4, j + 5, k + 4, Blocks.air, 0);
		setBlock(world, i + 4, j + 5, k + 5, Blocks.dirt, 2);
		setBlock(world, i + 4, j + 5, k + 6, Blocks.dirt, 2);
		setBlock(world, i + 4, j + 5, k + 7, Blocks.dirt, 0);
		setBlock(world, i + 4, j + 5, k + 8, Blocks.dirt, 2);
		setBlock(world, i + 4, j + 5, k + 9, Blocks.dirt, 2);
		setBlock(world, i + 4, j + 5, k + 10, Blocks.dirt, 0);
		setBlock(world, i + 4, j + 6, k + 0, Blocks.nether_brick_fence, 0);
		setBlock(world, i + 4, j + 6, k + 1, Blocks.stone_slab, 6);
		setBlock(world, i + 4, j + 6, k + 2, Blocks.stone_slab, 14);
		setBlock(world, i + 4, j + 6, k + 3, Blocks.air, 0);
		setBlock(world, i + 4, j + 6, k + 4, Blocks.air, 0);
		setBlock(world, i + 4, j + 6, k + 5, Blocks.double_stone_slab, 6);
		setBlock(world, i + 4, j + 6, k + 6, Blocks.air, 0);
		setBlock(world, i + 4, j + 6, k + 7, Blocks.nether_brick_fence, 0);
		setBlock(world, i + 4, j + 6, k + 8, Blocks.air, 0);
		setBlock(world, i + 4, j + 6, k + 9, Blocks.nether_brick_fence, 0);
		setBlock(world, i + 4, j + 7, k + 0, Blocks.air, 0);
		setBlock(world, i + 4, j + 7, k + 1, Blocks.air, 0);
		setBlock(world, i + 4, j + 7, k + 2, Blocks.air, 0);
		setBlock(world, i + 4, j + 7, k + 3, Blocks.stone_slab, 6);
		setBlock(world, i + 4, j + 7, k + 4, Blocks.stone_slab, 14);
		setBlock(world, i + 4, j + 7, k + 5, Blocks.double_stone_slab, 6);
		setBlock(world, i + 4, j + 7, k + 6, Blocks.air, 0);
		setBlock(world, i + 4, j + 7, k + 7, ModBlocks.gravewood, 0);
		setBlock(world, i + 4, j + 7, k + 8, Blocks.air, 0);
		setBlock(world, i + 4, j + 7, k + 9, Blocks.air, 0);
		setBlock(world, i + 4, j + 8, k + 1, Blocks.air, 0);
		setBlock(world, i + 4, j + 8, k + 2, Blocks.air, 0);
		setBlock(world, i + 4, j + 8, k + 3, Blocks.air, 0);
		setBlock(world, i + 4, j + 8, k + 4, Blocks.air, 0);
		setBlock(world, i + 4, j + 8, k + 5, ModBlocks.gravewood, 0);
		setBlock(world, i + 4, j + 8, k + 6, ModBlocks.gravewood, 0);
		setBlock(world, i + 4, j + 8, k + 7, ModBlocks.gravewood, 0);
		setBlock(world, i + 4, j + 8, k + 8, Blocks.air, 0);
		setBlock(world, i + 4, j + 9, k + 3, Blocks.air, 0);
		setBlock(world, i + 4, j + 9, k + 4, ModBlocks.gravewood, 0);
		setBlock(world, i + 4, j + 9, k + 5, Blocks.air, 0);
		setBlock(world, i + 4, j + 9, k + 6, Blocks.air, 0);
		setBlock(world, i + 4, j + 9, k + 7, Blocks.air, 0);
		setBlock(world, i + 5, j + 0, k + 7, Blocks.clay, 0);
		setBlock(world, i + 5, j + 0, k + 8, Blocks.stone, 0);
		setBlock(world, i + 5, j + 0, k + 9, Blocks.clay, 0);
		setBlock(world, i + 5, j + 1, k + 2, Blocks.stone, 0);
		setBlock(world, i + 5, j + 1, k + 3, Blocks.stone, 0);
		setBlock(world, i + 5, j + 1, k + 4, Blocks.stone, 0);
		setBlock(world, i + 5, j + 1, k + 5, Blocks.stone_slab, 6);
		setBlock(world, i + 5, j + 1, k + 6, Blocks.stone_slab, 6);
		setBlock(world, i + 5, j + 1, k + 7, Blocks.air, 0);
		setBlock(world, i + 5, j + 1, k + 8, Blocks.air, 0);
		setBlock(world, i + 5, j + 1, k + 9, Blocks.stone, 0);
		setBlock(world, i + 5, j + 1, k + 10, Blocks.stone, 0);
		setBlock(world, i + 5, j + 1, k + 11, Blocks.stone, 0);
		setBlock(world, i + 5, j + 2, k + 2, Blocks.stone, 0);
		setBlock(world, i + 5, j + 2, k + 3, Blocks.stone_slab, 6);
		setBlock(world, i + 5, j + 2, k + 4, Blocks.air, 0);
		setBlock(world, i + 5, j + 2, k + 5, Blocks.air, 0);
		setBlock(world, i + 5, j + 2, k + 6, Blocks.air, 0);
		setBlock(world, i + 5, j + 2, k + 7, Blocks.air, 0);
		setBlock(world, i + 5, j + 2, k + 8, Blocks.air, 0);
		setBlock(world, i + 5, j + 2, k + 9, Blocks.stone_slab, 6);
		setBlock(world, i + 5, j + 2, k + 10, Blocks.air, 0);
		setBlock(world, i + 5, j + 2, k + 11, Blocks.air, 0);
		setBlock(world, i + 5, j + 2, k + 12, Blocks.stone, 0);
		setBlock(world, i + 5, j + 2, k + 13, Blocks.stone, 0);
		setBlock(world, i + 5, j + 2, k + 14, Blocks.stone, 0);
		setBlock(world, i + 5, j + 2, k + 15, Blocks.stone, 0);
		setBlock(world, i + 5, j + 2, k + 16, Blocks.stone, 0);
		setBlock(world, i + 5, j + 3, k + 2, Blocks.stonebrick, 3);
		setBlock(world, i + 5, j + 3, k + 3, Blocks.air, 0);
		setBlock(world, i + 5, j + 3, k + 4, Blocks.air, 0);
		setBlock(world, i + 5, j + 3, k + 5, Blocks.air, 0);
		setBlock(world, i + 5, j + 3, k + 6, Blocks.air, 0);
		setBlock(world, i + 5, j + 3, k + 7, Blocks.air, 0);
		setBlock(world, i + 5, j + 3, k + 8, ModBlocks.gravewoodLeaves, 0);
		setBlock(world, i + 5, j + 3, k + 9, Blocks.air, 4);
		setBlock(world, i + 5, j + 3, k + 10, Blocks.stonebrick, 3);
		setBlock(world, i + 5, j + 3, k + 11, Blocks.stonebrick, 3);
		setBlock(world, i + 5, j + 3, k + 12, Blocks.dirt, 0);
		setBlock(world, i + 5, j + 3, k + 13, Blocks.dirt, 0);
		setBlock(world, i + 5, j + 3, k + 14, Blocks.dirt, 0);
		setBlock(world, i + 5, j + 3, k + 15, Blocks.dirt, 0);
		setBlock(world, i + 5, j + 3, k + 16, Blocks.dirt, 0);
		setBlock(world, i + 5, j + 4, k + 2, Blocks.stone, 0);
		setBlock(world, i + 5, j + 4, k + 3, Blocks.dirt, 2);
		setBlock(world, i + 5, j + 4, k + 4, Blocks.stone_slab, 14);
		setBlock(world, i + 5, j + 4, k + 5, Blocks.dirt, 2);
		setBlock(world, i + 5, j + 4, k + 6, Blocks.air, 4);
		setBlock(world, i + 5, j + 4, k + 7, ModBlocks.gravewoodLeaves, 0);
		setBlock(world, i + 5, j + 4, k + 8, ModBlocks.gravewoodLeaves, 0);
		setBlock(world, i + 5, j + 4, k + 10, Blocks.stone, 0);
		setBlock(world, i + 5, j + 4, k + 11, Blocks.dirt, 0);
		setBlock(world, i + 5, j + 4, k + 12, Blocks.dirt, 0);
		setBlock(world, i + 5, j + 4, k + 13, Blocks.dirt, 0);
		setBlock(world, i + 5, j + 4, k + 14, Blocks.dirt, 0);
		setBlock(world, i + 5, j + 4, k + 15, Blocks.dirt, 0);
		setBlock(world, i + 5, j + 4, k + 16, Blocks.dirt, 0);
		setBlock(world, i + 5, j + 5, k + 0, Blocks.dirt, 2);
		setBlock(world, i + 5, j + 5, k + 1, Blocks.dirt, 2);
		setBlock(world, i + 5, j + 5, k + 2, Blocks.grass, 0);
		setBlock(world, i + 5, j + 5, k + 3, Blocks.dirt, 2);
		setBlock(world, i + 5, j + 5, k + 4, Blocks.air, 0);
		setBlock(world, i + 5, j + 5, k + 5, Blocks.dirt, 2);
		setBlock(world, i + 5, j + 5, k + 6, Blocks.dirt, 2);
		setBlock(world, i + 5, j + 5, k + 7, Blocks.dirt, 0);
		setBlock(world, i + 5, j + 5, k + 8, Blocks.dirt, 2);
		setBlock(world, i + 5, j + 5, k + 9, Blocks.dirt, 2);
		setBlock(world, i + 5, j + 5, k + 10, Blocks.dirt, 2);
		setBlock(world, i + 5, j + 5, k + 11, Blocks.dirt, 0);
		setBlock(world, i + 5, j + 6, k + 0, Blocks.air, 0);
		setBlock(world, i + 5, j + 6, k + 1, Blocks.air, 0);
		setBlock(world, i + 5, j + 6, k + 2, Blocks.double_stone_slab, 6);
		setBlock(world, i + 5, j + 6, k + 3, Blocks.stone_slab, 14);
		setBlock(world, i + 5, j + 6, k + 4, Blocks.air, 0);
		setBlock(world, i + 5, j + 6, k + 5, Blocks.air, 0);
		setBlock(world, i + 5, j + 6, k + 6, Blocks.air, 0);
		setBlock(world, i + 5, j + 6, k + 7, ModBlocks.gravewood, 0);
		setBlock(world, i + 5, j + 6, k + 8, Blocks.air, 0);
		setBlock(world, i + 5, j + 6, k + 9, Blocks.air, 0);
		setBlock(world, i + 5, j + 6, k + 10, Blocks.air, 0);
		setBlock(world, i + 5, j + 7, k + 0, Blocks.air, 0);
		setBlock(world, i + 5, j + 7, k + 1, Blocks.air, 0);
		setBlock(world, i + 5, j + 7, k + 2, Blocks.air, 0);
		setBlock(world, i + 5, j + 7, k + 3, Blocks.air, 0);
		setBlock(world, i + 5, j + 7, k + 4, Blocks.air, 0);
		setBlock(world, i + 5, j + 7, k + 5, Blocks.air, 0);
		setBlock(world, i + 5, j + 7, k + 6, Blocks.air, 0);
		setBlock(world, i + 5, j + 7, k + 7, Blocks.air, 0);
		setBlock(world, i + 5, j + 7, k + 8, Blocks.air, 0);
		setBlock(world, i + 5, j + 7, k + 9, Blocks.air, 0);
		setBlock(world, i + 5, j + 7, k + 10, Blocks.air, 0);
		setBlock(world, i + 5, j + 8, k + 1, Blocks.air, 0);
		setBlock(world, i + 5, j + 8, k + 2, Blocks.air, 0);
		setBlock(world, i + 5, j + 8, k + 3, Blocks.air, 0);
		setBlock(world, i + 5, j + 8, k + 4, Blocks.air, 0);
		setBlock(world, i + 5, j + 8, k + 5, Blocks.air, 0);
		setBlock(world, i + 5, j + 8, k + 6, Blocks.air, 0);
		setBlock(world, i + 5, j + 8, k + 7, Blocks.air, 0);
		setBlock(world, i + 5, j + 8, k + 8, ModBlocks.gravewood, 0);
		setBlock(world, i + 5, j + 8, k + 9, Blocks.air, 0);
		setBlock(world, i + 5, j + 9, k + 3, Blocks.air, 0);
		setBlock(world, i + 5, j + 9, k + 4, Blocks.air, 0);
		setBlock(world, i + 5, j + 9, k + 5, Blocks.air, 0);
		setBlock(world, i + 5, j + 9, k + 6, Blocks.air, 0);
		setBlock(world, i + 5, j + 9, k + 7, Blocks.air, 0);
		setBlock(world, i + 5, j + 9, k + 8, ModBlocks.gravewood, 0);
		setBlock(world, i + 5, j + 10, k + 4, ModBlocks.gravewood, 0);
		setBlock(world, i + 5, j + 10, k + 5, Blocks.air, 0);
		setBlock(world, i + 5, j + 10, k + 6, Blocks.air, 0);
		setBlock(world, i + 6, j + 0, k + 5, Blocks.stone, 0);
		setBlock(world, i + 6, j + 0, k + 6, Blocks.stone, 0);
		setBlock(world, i + 6, j + 0, k + 7, Blocks.cobblestone, 0);
		setBlock(world, i + 6, j + 0, k + 8, Blocks.cobblestone, 0);
		setBlock(world, i + 6, j + 0, k + 9, Blocks.clay, 0);
		setBlock(world, i + 6, j + 1, k + 4, Blocks.stone, 0);
		setBlock(world, i + 6, j + 1, k + 5, Blocks.air, 0);
		setBlock(world, i + 6, j + 1, k + 6, Blocks.air, 0);
		setBlock(world, i + 6, j + 1, k + 7, Blocks.air, 0);
		setBlock(world, i + 6, j + 1, k + 8, Blocks.air, 0);
		setBlock(world, i + 6, j + 1, k + 9, Blocks.air, 0);
		setBlock(world, i + 6, j + 1, k + 10, Blocks.stone, 0);
		setBlock(world, i + 6, j + 1, k + 11, Blocks.stone, 0);
		setBlock(world, i + 6, j + 2, k + 3, Blocks.stone, 0);
		setBlock(world, i + 6, j + 2, k + 4, Blocks.stone_slab, 6);
		setBlock(world, i + 6, j + 2, k + 5, Blocks.air, 0);
		setBlock(world, i + 6, j + 2, k + 6, Blocks.air, 0);
		setBlock(world, i + 6, j + 2, k + 7, Blocks.air, 0);
		setBlock(world, i + 6, j + 2, k + 8, Blocks.air, 0);
		setBlock(world, i + 6, j + 2, k + 9, Blocks.air, 0);
		setBlock(world, i + 6, j + 2, k + 10, Blocks.stone_slab, 6);
		setBlock(world, i + 6, j + 2, k + 11, Blocks.stone, 0);
		setBlock(world, i + 6, j + 2, k + 12, Blocks.stone, 0);
		setBlock(world, i + 6, j + 2, k + 13, Blocks.stone, 0);
		setBlock(world, i + 6, j + 2, k + 14, Blocks.stone, 0);
		setBlock(world, i + 6, j + 2, k + 15, Blocks.stone, 0);
		setBlock(world, i + 6, j + 2, k + 16, Blocks.stone, 0);
		setBlock(world, i + 6, j + 3, k + 2, Blocks.dirt, 0);
		setBlock(world, i + 6, j + 3, k + 3, Blocks.stonebrick, 3);
		setBlock(world, i + 6, j + 3, k + 4, Blocks.air, 0);
		setBlock(world, i + 6, j + 3, k + 5, Blocks.air, 0);
		setBlock(world, i + 6, j + 3, k + 6, Blocks.air, 0);
		setBlock(world, i + 6, j + 3, k + 7, Blocks.air, 0);
		setBlock(world, i + 6, j + 3, k + 8, Blocks.air, 0);
		setBlock(world, i + 6, j + 3, k + 9, Blocks.air, 0);
		setBlock(world, i + 6, j + 3, k + 10, ModBlocks.gravewood, 0);
		setBlock(world, i + 6, j + 3, k + 11, Blocks.stonebrick, 3);
		setBlock(world, i + 6, j + 3, k + 12, Blocks.dirt, 0);
		setBlock(world, i + 6, j + 3, k + 13, Blocks.stone, 0);
		setBlock(world, i + 6, j + 3, k + 14, Blocks.stone, 0);
		setBlock(world, i + 6, j + 3, k + 15, Blocks.stone, 0);
		setBlock(world, i + 6, j + 3, k + 16, Blocks.stone, 0);
		setBlock(world, i + 6, j + 4, k + 2, Blocks.dirt, 0);
		setBlock(world, i + 6, j + 4, k + 3, Blocks.stone, 0);
		setBlock(world, i + 6, j + 4, k + 4, Blocks.air, 4);
		setBlock(world, i + 6, j + 4, k + 5, Blocks.air, 0);
		setBlock(world, i + 6, j + 4, k + 6, Blocks.air, 4);
		setBlock(world, i + 6, j + 4, k + 7, Blocks.air, 0);
		setBlock(world, i + 6, j + 4, k + 8, ModBlocks.gravewoodLeaves, 0);
		setBlock(world, i + 6, j + 4, k + 10, Blocks.air, 8);
		setBlock(world, i + 6, j + 4, k + 11, Blocks.stone, 0);
		setBlock(world, i + 6, j + 4, k + 12, Blocks.dirt, 0);
		setBlock(world, i + 6, j + 4, k + 13, Blocks.dirt, 0);
		setBlock(world, i + 6, j + 4, k + 14, Blocks.dirt, 0);
		setBlock(world, i + 6, j + 4, k + 15, Blocks.dirt, 0);
		setBlock(world, i + 6, j + 4, k + 16, Blocks.dirt, 0);
		setBlock(world, i + 6, j + 5, k + 0, Blocks.dirt, 2);
		setBlock(world, i + 6, j + 5, k + 1, Blocks.dirt, 2);
		setBlock(world, i + 6, j + 5, k + 2, Blocks.grass, 0);
		setBlock(world, i + 6, j + 5, k + 3, Blocks.dirt, 2);
		setBlock(world, i + 6, j + 5, k + 4, Blocks.stone_slab, 6);
		setBlock(world, i + 6, j + 5, k + 5, Blocks.dirt, 2);
		setBlock(world, i + 6, j + 5, k + 6, Blocks.dirt, 2);
		setBlock(world, i + 6, j + 5, k + 7, ModBlocks.gravewood, 0);
		setBlock(world, i + 6, j + 5, k + 8, Blocks.mycelium, 0);
		setBlock(world, i + 6, j + 5, k + 9, Blocks.mycelium, 0);
		setBlock(world, i + 6, j + 5, k + 10, Blocks.mycelium, 0);
		setBlock(world, i + 6, j + 5, k + 11, Blocks.mycelium, 0);
		setBlock(world, i + 6, j + 5, k + 12, Blocks.mycelium, 0);
		setBlock(world, i + 6, j + 5, k + 13, Blocks.mycelium, 0);
		setBlock(world, i + 6, j + 5, k + 14, Blocks.mycelium, 0);
		setBlock(world, i + 6, j + 5, k + 15, Blocks.mycelium, 0);
		setBlock(world, i + 6, j + 5, k + 16, Blocks.mycelium, 0);
		setBlock(world, i + 6, j + 5, k + 17, Blocks.mycelium, 0);
		setBlock(world, i + 6, j + 5, k + 18, Blocks.mycelium, 0);
		setBlock(world, i + 6, j + 6, k + 0, Blocks.nether_brick_fence, 0);
		setBlock(world, i + 6, j + 6, k + 1, Blocks.nether_brick_fence, 0);
		setBlock(world, i + 6, j + 6, k + 2, Blocks.stone_slab, 6);
		setBlock(world, i + 6, j + 6, k + 3, Blocks.stone_slab, 14);
		setBlock(world, i + 6, j + 6, k + 4, Blocks.air, 0);
		setBlock(world, i + 6, j + 6, k + 5, Blocks.air, 0);
		setBlock(world, i + 6, j + 6, k + 6, Blocks.air, 0);
		setBlock(world, i + 6, j + 6, k + 7, Blocks.air, 0);
		setBlock(world, i + 6, j + 6, k + 8, Blocks.nether_brick_fence, 0);
		setBlock(world, i + 6, j + 6, k + 9, Blocks.nether_brick_fence, 0);
		setBlock(world, i + 6, j + 6, k + 10, Blocks.nether_brick_fence, 0);
		setBlock(world, i + 6, j + 6, k + 11, Blocks.nether_brick_fence, 0);
		setBlock(world, i + 6, j + 6, k + 12, Blocks.air, 0);
		setBlock(world, i + 6, j + 6, k + 13, Blocks.nether_brick_fence, 0);
		setBlock(world, i + 6, j + 6, k + 14, Blocks.nether_brick_fence, 0);
		setBlock(world, i + 6, j + 6, k + 15, Blocks.nether_brick_fence, 0);
		setBlock(world, i + 6, j + 6, k + 16, Blocks.nether_brick_fence, 0);
		setBlock(world, i + 6, j + 6, k + 17, Blocks.nether_brick_fence, 0);
		setBlock(world, i + 6, j + 6, k + 18, Blocks.nether_brick_fence, 0);
		setBlock(world, i + 6, j + 7, k + 0, Blocks.air, 0);
		setBlock(world, i + 6, j + 7, k + 1, Blocks.air, 0);
		setBlock(world, i + 6, j + 7, k + 2, Blocks.air, 0);
		setBlock(world, i + 6, j + 7, k + 3, Blocks.air, 0);
		setBlock(world, i + 6, j + 7, k + 4, Blocks.air, 0);
		setBlock(world, i + 6, j + 7, k + 5, Blocks.air, 0);
		setBlock(world, i + 6, j + 7, k + 6, Blocks.air, 0);
		setBlock(world, i + 6, j + 7, k + 7, Blocks.air, 0);
		setBlock(world, i + 6, j + 7, k + 8, Blocks.air, 0);
		setBlock(world, i + 6, j + 7, k + 9, Blocks.air, 0);
		setBlock(world, i + 6, j + 7, k + 10, Blocks.air, 0);
		setBlock(world, i + 6, j + 7, k + 11, Blocks.air, 0);
		setBlock(world, i + 6, j + 7, k + 12, Blocks.air, 0);
		setBlock(world, i + 6, j + 7, k + 13, Blocks.air, 0);
		setBlock(world, i + 6, j + 7, k + 14, Blocks.air, 0);
		setBlock(world, i + 6, j + 7, k + 15, Blocks.air, 0);
		setBlock(world, i + 6, j + 7, k + 16, Blocks.air, 0);
		setBlock(world, i + 6, j + 7, k + 17, Blocks.air, 0);
		setBlock(world, i + 6, j + 7, k + 18, Blocks.air, 0);
		setBlock(world, i + 6, j + 8, k + 2, Blocks.air, 0);
		setBlock(world, i + 6, j + 8, k + 3, Blocks.air, 0);
		setBlock(world, i + 6, j + 8, k + 4, Blocks.air, 0);
		setBlock(world, i + 6, j + 8, k + 5, Blocks.air, 0);
		setBlock(world, i + 6, j + 8, k + 6, Blocks.air, 0);
		setBlock(world, i + 6, j + 8, k + 7, Blocks.air, 0);
		setBlock(world, i + 6, j + 8, k + 8, Blocks.air, 0);
		setBlock(world, i + 6, j + 8, k + 9, Blocks.air, 0);
		setBlock(world, i + 6, j + 8, k + 10, Blocks.air, 0);
		setBlock(world, i + 6, j + 9, k + 4, Blocks.air, 0);
		setBlock(world, i + 6, j + 9, k + 5, Blocks.air, 0);
		setBlock(world, i + 6, j + 9, k + 6, Blocks.air, 0);
		setBlock(world, i + 6, j + 9, k + 7, Blocks.air, 0);
		setBlock(world, i + 6, j + 9, k + 8, Blocks.air, 0);
		setBlock(world, i + 6, j + 10, k + 5, Blocks.air, 0);
		setBlock(world, i + 6, j + 10, k + 6, Blocks.air, 0);
		setBlock(world, i + 7, j + 0, k + 5, Blocks.stone, 0);
		setBlock(world, i + 7, j + 0, k + 6, Blocks.cobblestone, 0);
		setBlock(world, i + 7, j + 0, k + 7, Blocks.cobblestone, 0);
		setBlock(world, i + 7, j + 0, k + 8, Blocks.cobblestone, 0);
		setBlock(world, i + 7, j + 0, k + 9, Blocks.clay, 0);
		setBlock(world, i + 7, j + 0, k + 10, Blocks.stone, 0);
		setBlock(world, i + 7, j + 1, k + 5, ModBlocks.gravewood, 0);
		setBlock(world, i + 7, j + 1, k + 6, Blocks.air, 0);
		setBlock(world, i + 7, j + 1, k + 7, Blocks.air, 0);
		setBlock(world, i + 7, j + 1, k + 8, Blocks.air, 0);
		setBlock(world, i + 7, j + 1, k + 9, Blocks.air, 0);
		setBlock(world, i + 7, j + 1, k + 10, Blocks.air, 0);
		setBlock(world, i + 7, j + 1, k + 11, Blocks.stone, 0);
		setBlock(world, i + 7, j + 2, k + 3, Blocks.stone, 0);
		setBlock(world, i + 7, j + 2, k + 4, Blocks.stone, 0);
		setBlock(world, i + 7, j + 2, k + 5, Blocks.air, 0);
		setBlock(world, i + 7, j + 2, k + 6, ModBlocks.gravewood, 0);
		setBlock(world, i + 7, j + 2, k + 7, Blocks.air, 0);
		setBlock(world, i + 7, j + 2, k + 8, Blocks.air, 0);
		setBlock(world, i + 7, j + 2, k + 9, Blocks.air, 0);
		setBlock(world, i + 7, j + 2, k + 10, Blocks.air, 0);
		setBlock(world, i + 7, j + 2, k + 11, Blocks.stone_slab, 6);
		setBlock(world, i + 7, j + 2, k + 12, Blocks.stone, 0);
		setBlock(world, i + 7, j + 2, k + 13, Blocks.stone_slab, 6);
		setBlock(world, i + 7, j + 2, k + 14, Blocks.stone_slab, 6);
		setBlock(world, i + 7, j + 2, k + 15, Blocks.stone_slab, 6);
		setBlock(world, i + 7, j + 2, k + 16, Blocks.stone_slab, 6);
		setBlock(world, i + 7, j + 2, k + 17, Blocks.stone_slab, 6);
		setBlock(world, i + 7, j + 2, k + 18, Blocks.stone_slab, 6);
		setBlock(world, i + 7, j + 3, k + 2, Blocks.dirt, 0);
		setBlock(world, i + 7, j + 3, k + 3, Blocks.stone, 0);
		setBlock(world, i + 7, j + 3, k + 4, Blocks.stonebrick, 3);
		setBlock(world, i + 7, j + 3, k + 5, Blocks.air, 0);
		setBlock(world, i + 7, j + 3, k + 6, ModBlocks.gravewood, 0);
		setBlock(world, i + 7, j + 3, k + 7, Blocks.air, 0);
		setBlock(world, i + 7, j + 3, k + 8, Blocks.air, 0);
		setBlock(world, i + 7, j + 3, k + 9, Blocks.air, 0);
		setBlock(world, i + 7, j + 3, k + 10, Blocks.air, 0);
		setBlock(world, i + 7, j + 3, k + 11, ModBlocks.gravewood, 0);
		setBlock(world, i + 7, j + 3, k + 12, Blocks.stonebrick, 3);
		setBlock(world, i + 7, j + 3, k + 13, Blocks.stone, 0);
		setBlock(world, i + 7, j + 3, k + 14, Blocks.stone, 0);
		setBlock(world, i + 7, j + 3, k + 15, Blocks.stone, 0);
		setBlock(world, i + 7, j + 3, k + 16, Blocks.stone, 0);
		setBlock(world, i + 7, j + 3, k + 17, Blocks.stone, 0);
		setBlock(world, i + 7, j + 3, k + 18, Blocks.stone, 0);
		setBlock(world, i + 7, j + 4, k + 2, Blocks.dirt, 0);
		setBlock(world, i + 7, j + 4, k + 3, Blocks.dirt, 0);
		setBlock(world, i + 7, j + 4, k + 4, Blocks.stone, 0);
		setBlock(world, i + 7, j + 4, k + 5, Blocks.air, 4);
		setBlock(world, i + 7, j + 4, k + 6, ModBlocks.gravewood, 0);
		setBlock(world, i + 7, j + 4, k + 7, ModBlocks.gravewood, 0);
		setBlock(world, i + 7, j + 4, k + 8, ModBlocks.gravewood, 0);
		setBlock(world, i + 7, j + 4, k + 9, ModBlocks.gravewoodLeaves, 0);
		setBlock(world, i + 7, j + 4, k + 10, Blocks.air, 4);
		setBlock(world, i + 7, j + 4, k + 11, ModBlocks.gravewood, 0);
		setBlock(world, i + 7, j + 4, k + 12, Blocks.stone, 0);
		setBlock(world, i + 7, j + 4, k + 13, Blocks.dirt, 0);
		setBlock(world, i + 7, j + 4, k + 14, Blocks.dirt, 0);
		setBlock(world, i + 7, j + 4, k + 15, Blocks.dirt, 0);
		setBlock(world, i + 7, j + 4, k + 16, Blocks.dirt, 0);
		setBlock(world, i + 7, j + 4, k + 17, Blocks.dirt, 0);
		setBlock(world, i + 7, j + 5, k + 1, Blocks.dirt, 2);
		setBlock(world, i + 7, j + 5, k + 2, Blocks.dirt, 2);
		setBlock(world, i + 7, j + 5, k + 3, Blocks.dirt, 2);
		setBlock(world, i + 7, j + 5, k + 4, Blocks.mycelium, 0);
		setBlock(world, i + 7, j + 5, k + 5, Blocks.mycelium, 0);
		setBlock(world, i + 7, j + 5, k + 6, Blocks.mycelium, 0);
		setBlock(world, i + 7, j + 5, k + 7, Blocks.mycelium, 0);
		setBlock(world, i + 7, j + 5, k + 8, Blocks.mycelium, 0);
		setBlock(world, i + 7, j + 5, k + 9, Blocks.mycelium, 0);
		setBlock(world, i + 7, j + 5, k + 10, Blocks.mycelium, 0);
		setBlock(world, i + 7, j + 5, k + 11, Blocks.mycelium, 0);
		setBlock(world, i + 7, j + 5, k + 12, Blocks.mycelium, 0);
		setBlock(world, i + 7, j + 5, k + 13, Blocks.mycelium, 0);
		setBlock(world, i + 7, j + 5, k + 14, Blocks.mycelium, 0);
		setBlock(world, i + 7, j + 5, k + 15, Blocks.mycelium, 0);
		setBlock(world, i + 7, j + 5, k + 16, Blocks.mycelium, 0);
		setBlock(world, i + 7, j + 5, k + 17, Blocks.mycelium, 0);
		setBlock(world, i + 7, j + 5, k + 18, Blocks.mycelium, 0);
		setBlock(world, i + 7, j + 6, k + 1, Blocks.nether_brick_fence, 0);
		setBlock(world, i + 7, j + 6, k + 2, Blocks.air, 0);
		setBlock(world, i + 7, j + 6, k + 3, Blocks.air, 0);
		setBlock(world, i + 7, j + 6, k + 4, Blocks.air, 0);
		setBlock(world, i + 7, j + 6, k + 5, Blocks.air, 0);
		setBlock(world, i + 7, j + 6, k + 6, Blocks.air, 0);
		setBlock(world, i + 7, j + 6, k + 7, Blocks.air, 0);
		setBlock(world, i + 7, j + 6, k + 8, Blocks.air, 0);
		setBlock(world, i + 7, j + 6, k + 9, Blocks.air, 0);
		setBlock(world, i + 7, j + 6, k + 10, Blocks.air, 0);
		setBlock(world, i + 7, j + 6, k + 11, Blocks.air, 0);
		setBlock(world, i + 7, j + 6, k + 12, Blocks.air, 0);
		setBlock(world, i + 7, j + 6, k + 13, Blocks.air, 0);
		setBlock(world, i + 7, j + 6, k + 14, Blocks.air, 0);
		setBlock(world, i + 7, j + 6, k + 15, Blocks.air, 0);
		setBlock(world, i + 7, j + 6, k + 16, Blocks.air, 0);
		setBlock(world, i + 7, j + 6, k + 17, Blocks.air, 0);
		setBlock(world, i + 7, j + 6, k + 18, Blocks.nether_brick_fence, 0);
		setBlock(world, i + 7, j + 7, k + 1, Blocks.air, 0);
		setBlock(world, i + 7, j + 7, k + 2, Blocks.air, 0);
		setBlock(world, i + 7, j + 7, k + 3, Blocks.air, 0);
		setBlock(world, i + 7, j + 7, k + 4, Blocks.air, 0);
		setBlock(world, i + 7, j + 7, k + 5, Blocks.air, 0);
		setBlock(world, i + 7, j + 7, k + 6, Blocks.air, 0);
		setBlock(world, i + 7, j + 7, k + 7, Blocks.air, 0);
		setBlock(world, i + 7, j + 7, k + 8, Blocks.air, 0);
		setBlock(world, i + 7, j + 7, k + 9, Blocks.air, 0);
		setBlock(world, i + 7, j + 7, k + 10, Blocks.air, 0);
		setBlock(world, i + 7, j + 7, k + 11, Blocks.air, 0);
		setBlock(world, i + 7, j + 7, k + 12, Blocks.air, 0);
		setBlock(world, i + 7, j + 7, k + 13, Blocks.air, 0);
		setBlock(world, i + 7, j + 7, k + 14, Blocks.air, 0);
		setBlock(world, i + 7, j + 7, k + 15, Blocks.air, 0);
		setBlock(world, i + 7, j + 7, k + 16, Blocks.air, 0);
		setBlock(world, i + 7, j + 7, k + 17, Blocks.air, 0);
		setBlock(world, i + 7, j + 7, k + 18, Blocks.air, 0);
		setBlock(world, i + 7, j + 8, k + 3, Blocks.air, 0);
		setBlock(world, i + 7, j + 8, k + 4, Blocks.air, 0);
		setBlock(world, i + 7, j + 8, k + 5, Blocks.air, 0);
		setBlock(world, i + 7, j + 8, k + 6, Blocks.air, 0);
		setBlock(world, i + 7, j + 8, k + 7, Blocks.air, 0);
		setBlock(world, i + 7, j + 8, k + 8, Blocks.air, 0);
		setBlock(world, i + 7, j + 8, k + 9, Blocks.air, 0);
		setBlock(world, i + 7, j + 8, k + 10, Blocks.air, 0);
		setBlock(world, i + 7, j + 8, k + 11, Blocks.air, 0);
		setBlock(world, i + 7, j + 9, k + 5, Blocks.air, 0);
		setBlock(world, i + 7, j + 9, k + 6, Blocks.air, 0);
		setBlock(world, i + 7, j + 9, k + 7, Blocks.air, 0);
		setBlock(world, i + 7, j + 9, k + 8, Blocks.air, 0);
		setBlock(world, i + 7, j + 9, k + 9, Blocks.air, 0);
		setBlock(world, i + 7, j + 10, k + 5, Blocks.air, 0);
		setBlock(world, i + 7, j + 10, k + 6, Blocks.air, 0);
		setBlock(world, i + 7, j + 10, k + 7, Blocks.air, 0);
		setBlock(world, i + 7, j + 10, k + 8, Blocks.air, 0);
		setBlock(world, i + 8, j + 0, k + 7, Blocks.stone, 0);
		setBlock(world, i + 8, j + 0, k + 8, Blocks.stone, 0);
		setBlock(world, i + 8, j + 0, k + 9, Blocks.stone, 0);
		setBlock(world, i + 8, j + 0, k + 10, Blocks.stone, 0);
		setBlock(world, i + 8, j + 0, k + 11, Blocks.stone, 0);
		setBlock(world, i + 8, j + 0, k + 12, Blocks.stone, 0);
		setBlock(world, i + 8, j + 1, k + 5, Blocks.stone, 0);
		setBlock(world, i + 8, j + 1, k + 6, Blocks.stone, 0);
		setBlock(world, i + 8, j + 1, k + 7, Blocks.air, 0);
		setBlock(world, i + 8, j + 1, k + 8, Blocks.air, 0);
		setBlock(world, i + 8, j + 1, k + 9, Blocks.air, 0);
		setBlock(world, i + 8, j + 1, k + 10, Blocks.air, 0);
		setBlock(world, i + 8, j + 1, k + 11, Blocks.air, 0);
		setBlock(world, i + 8, j + 1, k + 12, Blocks.air, 1);
		setBlock(world, i + 8, j + 1, k + 13, Blocks.air, 1);
		setBlock(world, i + 8, j + 1, k + 14, Blocks.air, 1);
		setBlock(world, i + 8, j + 1, k + 15, Blocks.air, 1);
		setBlock(world, i + 8, j + 1, k + 16, Blocks.air, 1);
		setBlock(world, i + 8, j + 2, k + 3, Blocks.stone, 0);
		setBlock(world, i + 8, j + 2, k + 4, Blocks.stone, 0);
		setBlock(world, i + 8, j + 2, k + 5, Blocks.stone, 0);
		setBlock(world, i + 8, j + 2, k + 6, Blocks.stone_slab, 6);
		setBlock(world, i + 8, j + 2, k + 7, Blocks.air, 0);
		setBlock(world, i + 8, j + 2, k + 8, Blocks.air, 0);
		setBlock(world, i + 8, j + 2, k + 9, Blocks.air, 0);
		setBlock(world, i + 8, j + 2, k + 10, Blocks.air, 0);
		setBlock(world, i + 8, j + 2, k + 11, Blocks.air, 0);
		setBlock(world, i + 8, j + 2, k + 12, Blocks.double_stone_slab, 6);
		setBlock(world, i + 8, j + 2, k + 13, Blocks.stone_slab, 14);
		setBlock(world, i + 8, j + 2, k + 14, Blocks.stone_slab, 14);
		setBlock(world, i + 8, j + 2, k + 15, Blocks.stone_slab, 14);
		setBlock(world, i + 8, j + 2, k + 16, Blocks.stone_slab, 14);
		setBlock(world, i + 8, j + 2, k + 17, Blocks.stone_slab, 14);
		setBlock(world, i + 8, j + 2, k + 18, Blocks.stone_slab, 6);
		setBlock(world, i + 8, j + 3, k + 3, Blocks.dirt, 0);
		setBlock(world, i + 8, j + 3, k + 4, Blocks.stone, 0);
		setBlock(world, i + 8, j + 3, k + 5, Blocks.stonebrick, 3);
		setBlock(world, i + 8, j + 3, k + 6, Blocks.air, 0);
		setBlock(world, i + 8, j + 3, k + 7, Blocks.air, 0);
		setBlock(world, i + 8, j + 3, k + 8, Blocks.air, 0);
		setBlock(world, i + 8, j + 3, k + 9, Blocks.air, 0);
		setBlock(world, i + 8, j + 3, k + 10, Blocks.air, 0);
		setBlock(world, i + 8, j + 3, k + 11, Blocks.air, 4);
		setBlock(world, i + 8, j + 3, k + 12, Blocks.air, 0);
		setBlock(world, i + 8, j + 3, k + 13, Blocks.stonebrick, 3);
		setBlock(world, i + 8, j + 3, k + 14, Blocks.stonebrick, 3);
		setBlock(world, i + 8, j + 3, k + 15, Blocks.stonebrick, 3);
		setBlock(world, i + 8, j + 3, k + 16, Blocks.stonebrick, 3);
		setBlock(world, i + 8, j + 3, k + 17, Blocks.stonebrick, 3);
		setBlock(world, i + 8, j + 3, k + 18, Blocks.stone, 0);
		setBlock(world, i + 8, j + 4, k + 2, Blocks.dirt, 0);
		setBlock(world, i + 8, j + 4, k + 3, Blocks.dirt, 0);
		setBlock(world, i + 8, j + 4, k + 4, Blocks.dirt, 0);
		setBlock(world, i + 8, j + 4, k + 5, Blocks.stone, 0);
		setBlock(world, i + 8, j + 4, k + 6, Blocks.air, 0);
		setBlock(world, i + 8, j + 4, k + 7, ModBlocks.gravewood, 0);
		setBlock(world, i + 8, j + 4, k + 8, ModBlocks.gravewoodLeaves, 0);
		setBlock(world, i + 8, j + 4, k + 9, Blocks.air, 0);
		setBlock(world, i + 8, j + 4, k + 10, Blocks.air, 0);
		setBlock(world, i + 8, j + 4, k + 11, ModBlocks.gravewoodLeaves, 0);
		setBlock(world, i + 8, j + 4, k + 12, ModBlocks.gravewood, 0);
		setBlock(world, i + 8, j + 4, k + 13, Blocks.nether_brick_stairs, 5);
		setBlock(world, i + 8, j + 4, k + 14, Blocks.nether_brick_stairs, 5);
		setBlock(world, i + 8, j + 4, k + 15, Blocks.nether_brick_stairs, 5);
		setBlock(world, i + 8, j + 4, k + 16, Blocks.nether_brick_stairs, 5);
		setBlock(world, i + 8, j + 4, k + 17, Blocks.nether_brick_stairs, 6);
		setBlock(world, i + 8, j + 4, k + 18, Blocks.dirt, 0);
		setBlock(world, i + 8, j + 5, k + 2, Blocks.mycelium, 0);
		setBlock(world, i + 8, j + 5, k + 3, Blocks.mycelium, 0);
		setBlock(world, i + 8, j + 5, k + 4, Blocks.mycelium, 0);
		setBlock(world, i + 8, j + 5, k + 5, Blocks.mycelium, 0);
		setBlock(world, i + 8, j + 5, k + 6, Blocks.mycelium, 0);
		setBlock(world, i + 8, j + 5, k + 7, Blocks.mycelium, 0);
		setBlock(world, i + 8, j + 5, k + 8, Blocks.mycelium, 0);
		setBlock(world, i + 8, j + 5, k + 9, Blocks.dirt, 2);
		setBlock(world, i + 8, j + 5, k + 10, Blocks.dirt, 2);
		setBlock(world, i + 8, j + 5, k + 11, Blocks.mycelium, 0);
		setBlock(world, i + 8, j + 5, k + 12, Blocks.dirt, 2);
		setBlock(world, i + 8, j + 5, k + 13, Blocks.dirt, 2);
		setBlock(world, i + 8, j + 5, k + 14, Blocks.mycelium, 0);
		setBlock(world, i + 8, j + 5, k + 15, Blocks.dirt, 2);
		setBlock(world, i + 8, j + 5, k + 16, Blocks.dirt, 2);
		setBlock(world, i + 8, j + 5, k + 17, Blocks.mycelium, 0);
		setBlock(world, i + 8, j + 5, k + 18, Blocks.mycelium, 0);
		setBlock(world, i + 8, j + 6, k + 2, Blocks.nether_brick_fence, 0);
		setBlock(world, i + 8, j + 6, k + 3, Blocks.air, 0);
		setBlock(world, i + 8, j + 6, k + 4, Blocks.air, 0);
		setBlock(world, i + 8, j + 6, k + 5, Blocks.air, 0);
		setBlock(world, i + 8, j + 6, k + 6, Blocks.air, 0);
		setBlock(world, i + 8, j + 6, k + 7, Blocks.air, 0);
		setBlock(world, i + 8, j + 6, k + 8, Blocks.air, 0);
		setBlock(world, i + 8, j + 6, k + 9, Blocks.air, 0);
		setBlock(world, i + 8, j + 6, k + 10, Blocks.air, 0);
		setBlock(world, i + 8, j + 6, k + 11, Blocks.air, 0);
		setBlock(world, i + 8, j + 6, k + 12, Blocks.air, 0);
		setBlock(world, i + 8, j + 6, k + 14, Blocks.air, 0);
		setBlock(world, i + 8, j + 6, k + 16, Blocks.air, 0);
		setBlock(world, i + 8, j + 6, k + 17, Blocks.air, 0);
		setBlock(world, i + 8, j + 6, k + 18, Blocks.air, 0);
		setBlock(world, i + 8, j + 7, k + 2, Blocks.air, 0);
		setBlock(world, i + 8, j + 7, k + 3, Blocks.air, 0);
		setBlock(world, i + 8, j + 7, k + 4, Blocks.air, 0);
		setBlock(world, i + 8, j + 7, k + 5, Blocks.air, 0);
		setBlock(world, i + 8, j + 7, k + 6, Blocks.air, 0);
		setBlock(world, i + 8, j + 7, k + 7, Blocks.air, 0);
		setBlock(world, i + 8, j + 7, k + 8, Blocks.air, 0);
		setBlock(world, i + 8, j + 7, k + 9, Blocks.air, 0);
		setBlock(world, i + 8, j + 7, k + 10, Blocks.air, 0);
		setBlock(world, i + 8, j + 7, k + 11, Blocks.air, 0);
		setBlock(world, i + 8, j + 7, k + 12, Blocks.air, 0);
		setBlock(world, i + 8, j + 7, k + 13, Blocks.air, 0);
		setBlock(world, i + 8, j + 7, k + 14, Blocks.air, 0);
		setBlock(world, i + 8, j + 7, k + 15, Blocks.air, 0);
		setBlock(world, i + 8, j + 7, k + 16, Blocks.air, 0);
		setBlock(world, i + 8, j + 7, k + 17, Blocks.air, 0);
		setBlock(world, i + 8, j + 7, k + 18, Blocks.air, 0);
		setBlock(world, i + 8, j + 8, k + 3, Blocks.air, 0);
		setBlock(world, i + 8, j + 8, k + 4, Blocks.air, 0);
		setBlock(world, i + 8, j + 8, k + 5, Blocks.air, 0);
		setBlock(world, i + 8, j + 8, k + 6, Blocks.air, 0);
		setBlock(world, i + 8, j + 8, k + 7, Blocks.air, 0);
		setBlock(world, i + 8, j + 8, k + 8, Blocks.air, 0);
		setBlock(world, i + 8, j + 8, k + 9, Blocks.air, 0);
		setBlock(world, i + 8, j + 8, k + 10, Blocks.air, 0);
		setBlock(world, i + 8, j + 8, k + 11, Blocks.air, 0);
		setBlock(world, i + 8, j + 8, k + 12, Blocks.air, 0);
		setBlock(world, i + 8, j + 8, k + 13, Blocks.air, 0);
		setBlock(world, i + 8, j + 8, k + 14, Blocks.air, 0);
		setBlock(world, i + 8, j + 8, k + 15, Blocks.air, 0);
		setBlock(world, i + 8, j + 8, k + 16, Blocks.air, 0);
		setBlock(world, i + 8, j + 8, k + 17, Blocks.air, 0);
		setBlock(world, i + 8, j + 9, k + 5, Blocks.air, 0);
		setBlock(world, i + 8, j + 9, k + 6, Blocks.air, 0);
		setBlock(world, i + 8, j + 9, k + 7, Blocks.air, 0);
		setBlock(world, i + 8, j + 9, k + 8, Blocks.air, 0);
		setBlock(world, i + 8, j + 9, k + 9, Blocks.air, 0);
		setBlock(world, i + 8, j + 9, k + 10, Blocks.air, 0);
		setBlock(world, i + 8, j + 10, k + 6, Blocks.air, 0);
		setBlock(world, i + 8, j + 10, k + 7, Blocks.air, 0);
		setBlock(world, i + 8, j + 10, k + 8, Blocks.air, 0);
		setBlock(world, i + 8, j + 10, k + 9, Blocks.air, 0);
		setBlock(world, i + 9, j + 0, k + 8, Blocks.stone, 0);
		setBlock(world, i + 9, j + 0, k + 9, Blocks.stone, 0);
		setBlock(world, i + 9, j + 0, k + 10, Blocks.stone, 0);
		setBlock(world, i + 9, j + 0, k + 11, Blocks.stone, 0);
		setBlock(world, i + 9, j + 0, k + 12, Blocks.stone, 0);
		setBlock(world, i + 9, j + 0, k + 13, Blocks.clay, 0);
		setBlock(world, i + 9, j + 0, k + 14, Blocks.clay, 0);
		setBlock(world, i + 9, j + 0, k + 15, Blocks.stone, 0);
		setBlock(world, i + 9, j + 0, k + 16, Blocks.stone, 0);
		setBlock(world, i + 9, j + 1, k + 5, Blocks.stone, 0);
		setBlock(world, i + 9, j + 1, k + 6, Blocks.stone, 0);
		setBlock(world, i + 9, j + 1, k + 7, Blocks.stone, 0);
		setBlock(world, i + 9, j + 1, k + 8, Blocks.air, 0);
		setBlock(world, i + 9, j + 1, k + 9, Blocks.air, 0);
		setBlock(world, i + 9, j + 1, k + 10, Blocks.air, 0);
		setBlock(world, i + 9, j + 1, k + 11, Blocks.air, 0);
		setBlock(world, i + 9, j + 1, k + 12, Blocks.air, 0);
		setBlock(world, i + 9, j + 1, k + 13, Blocks.air, 0);
		setBlock(world, i + 9, j + 1, k + 14, Blocks.air, 0);
		setBlock(world, i + 9, j + 1, k + 15, Blocks.air, 0);
		setBlock(world, i + 9, j + 1, k + 16, Blocks.air, 0);
		setBlock(world, i + 9, j + 1, k + 17, Blocks.air, 2);
		setBlock(world, i + 9, j + 2, k + 3, Blocks.stone, 0);
		setBlock(world, i + 9, j + 2, k + 4, Blocks.stone, 0);
		setBlock(world, i + 9, j + 2, k + 5, Blocks.stone_slab, 14);
		setBlock(world, i + 9, j + 2, k + 6, Blocks.air, 0);
		setBlock(world, i + 9, j + 2, k + 7, Blocks.stone_slab, 6);
		setBlock(world, i + 9, j + 2, k + 8, Blocks.air, 0);
		setBlock(world, i + 9, j + 2, k + 9, Blocks.air, 0);
		setBlock(world, i + 9, j + 2, k + 10, Blocks.air, 0);
		setBlock(world, i + 9, j + 2, k + 11, Blocks.air, 0);
		setBlock(world, i + 9, j + 2, k + 12, Blocks.air, 0);
		setBlock(world, i + 9, j + 2, k + 13, Blocks.air, 0);
		setBlock(world, i + 9, j + 2, k + 14, Blocks.air, 0);
		setBlock(world, i + 9, j + 2, k + 15, Blocks.air, 0);
		setBlock(world, i + 9, j + 2, k + 16, Blocks.air, 0);
		setBlock(world, i + 9, j + 2, k + 17, Blocks.stone_slab, 14);
		setBlock(world, i + 9, j + 2, k + 18, Blocks.stone_slab, 6);
		setBlock(world, i + 9, j + 3, k + 4, Blocks.dirt, 0);
		setBlock(world, i + 9, j + 3, k + 5, Blocks.stonebrick, 3);
		setBlock(world, i + 9, j + 3, k + 6, Blocks.stonebrick, 3);
		setBlock(world, i + 9, j + 3, k + 7, Blocks.air, 0);
		setBlock(world, i + 9, j + 3, k + 8, Blocks.air, 0);
		setBlock(world, i + 9, j + 3, k + 9, Blocks.air, 0);
		setBlock(world, i + 9, j + 3, k + 10, Blocks.air, 0);
		setBlock(world, i + 9, j + 3, k + 11, Blocks.air, 0);
		setBlock(world, i + 9, j + 3, k + 12, Blocks.air, 0);
		setBlock(world, i + 9, j + 3, k + 13, Blocks.air, 0);
		setBlock(world, i + 9, j + 3, k + 14, Blocks.air, 0);
		setBlock(world, i + 9, j + 3, k + 15, Blocks.air, 0);
		setBlock(world, i + 9, j + 3, k + 16, Blocks.air, 0);
		setBlock(world, i + 9, j + 3, k + 17, Blocks.stonebrick, 3);
		setBlock(world, i + 9, j + 3, k + 18, Blocks.stone, 0);
		setBlock(world, i + 9, j + 4, k + 3, Blocks.dirt, 0);
		setBlock(world, i + 9, j + 4, k + 4, Blocks.dirt, 0);
		setBlock(world, i + 9, j + 4, k + 5, Blocks.dirt, 0);
		setBlock(world, i + 9, j + 4, k + 6, Blocks.stone, 0);
		setBlock(world, i + 9, j + 4, k + 7, Blocks.air, 4);
		setBlock(world, i + 9, j + 4, k + 8, Blocks.air, 0);
		setBlock(world, i + 9, j + 4, k + 9, Blocks.air, 0);
		setBlock(world, i + 9, j + 4, k + 10, ModBlocks.gravewoodLeaves, 0);
		setBlock(world, i + 9, j + 4, k + 11, ModBlocks.gravewoodLeaves, 0);
		setBlock(world, i + 9, j + 4, k + 12, ModBlocks.gravewood, 0);
		setBlock(world, i + 9, j + 4, k + 13, ModBlocks.gravewood, 0);
		setBlock(world, i + 9, j + 4, k + 14, ModBlocks.gravewood, 0);
		setBlock(world, i + 9, j + 4, k + 15, ModBlocks.gravewoodLeaves, 0);
		setBlock(world, i + 9, j + 4, k + 16, Blocks.air, 0);
		setBlock(world, i + 9, j + 4, k + 17, Blocks.nether_brick_stairs, 6);
		setBlock(world, i + 9, j + 4, k + 18, Blocks.dirt, 0);
		setBlock(world, i + 9, j + 5, k + 2, Blocks.mycelium, 0);
		setBlock(world, i + 9, j + 5, k + 3, Blocks.mycelium, 0);
		setBlock(world, i + 9, j + 5, k + 4, Blocks.mycelium, 0);
		setBlock(world, i + 9, j + 5, k + 5, Blocks.mycelium, 0);
		setBlock(world, i + 9, j + 5, k + 6, Blocks.mycelium, 0);
		setBlock(world, i + 9, j + 5, k + 7, Blocks.mycelium, 0);
		setBlock(world, i + 9, j + 5, k + 8, Blocks.mycelium, 0);
		setBlock(world, i + 9, j + 5, k + 9, Blocks.mycelium, 0);
		setBlock(world, i + 9, j + 5, k + 10, Blocks.mycelium, 0);
		setBlock(world, i + 9, j + 5, k + 11, Blocks.mycelium, 0);
		setBlock(world, i + 9, j + 5, k + 12, Blocks.mycelium, 0);
		setBlock(world, i + 9, j + 5, k + 13, Blocks.mycelium, 0);
		setBlock(world, i + 9, j + 5, k + 14, Blocks.stone, 0);
		setBlock(world, i + 9, j + 5, k + 15, Blocks.mycelium, 0);
		setBlock(world, i + 9, j + 5, k + 16, Blocks.mycelium, 0);
		setBlock(world, i + 9, j + 5, k + 17, Blocks.mycelium, 0);
		setBlock(world, i + 9, j + 5, k + 18, Blocks.mycelium, 0);
		setBlock(world, i + 9, j + 6, k + 2, Blocks.nether_brick_fence, 0);
		setBlock(world, i + 9, j + 6, k + 3, Blocks.air, 0);
		setBlock(world, i + 9, j + 6, k + 4, Blocks.air, 0);
		setBlock(world, i + 9, j + 6, k + 5, Blocks.air, 0);
		setBlock(world, i + 9, j + 6, k + 6, Blocks.air, 0);
		setBlock(world, i + 9, j + 6, k + 7, Blocks.air, 0);
		setBlock(world, i + 9, j + 6, k + 8, Blocks.air, 0);
		setBlock(world, i + 9, j + 6, k + 9, Blocks.air, 0);
		setBlock(world, i + 9, j + 6, k + 10, Blocks.air, 0);
		setBlock(world, i + 9, j + 6, k + 11, Blocks.air, 0);
		setBlock(world, i + 9, j + 6, k + 12, Blocks.air, 0);
		setBlock(world, i + 9, j + 6, k + 13, Blocks.air, 0);
		setBlock(world, i + 9, j + 6, k + 14, Blocks.air, 0);
		setBlock(world, i + 9, j + 6, k + 15, Blocks.air, 0);
		setBlock(world, i + 9, j + 6, k + 16, Blocks.air, 0);
		setBlock(world, i + 9, j + 6, k + 17, Blocks.air, 0);
		setBlock(world, i + 9, j + 6, k + 18, Blocks.air, 0);
		setBlock(world, i + 9, j + 7, k + 2, Blocks.air, 0);
		setBlock(world, i + 9, j + 7, k + 3, Blocks.air, 0);
		setBlock(world, i + 9, j + 7, k + 4, Blocks.air, 0);
		setBlock(world, i + 9, j + 7, k + 5, Blocks.air, 0);
		setBlock(world, i + 9, j + 7, k + 6, Blocks.air, 0);
		setBlock(world, i + 9, j + 7, k + 7, Blocks.air, 0);
		setBlock(world, i + 9, j + 7, k + 8, Blocks.air, 0);
		setBlock(world, i + 9, j + 7, k + 9, Blocks.air, 0);
		setBlock(world, i + 9, j + 7, k + 10, Blocks.air, 0);
		setBlock(world, i + 9, j + 7, k + 11, Blocks.air, 0);
		setBlock(world, i + 9, j + 7, k + 12, Blocks.air, 0);
		setBlock(world, i + 9, j + 7, k + 13, Blocks.air, 0);
		setBlock(world, i + 9, j + 7, k + 14, Blocks.air, 0);
		setBlock(world, i + 9, j + 7, k + 15, Blocks.air, 0);
		setBlock(world, i + 9, j + 7, k + 16, Blocks.air, 0);
		setBlock(world, i + 9, j + 7, k + 17, Blocks.air, 0);
		setBlock(world, i + 9, j + 7, k + 18, Blocks.air, 0);
		setBlock(world, i + 9, j + 8, k + 3, Blocks.air, 0);
		setBlock(world, i + 9, j + 8, k + 4, Blocks.air, 0);
		setBlock(world, i + 9, j + 8, k + 5, Blocks.air, 0);
		setBlock(world, i + 9, j + 8, k + 6, Blocks.air, 0);
		setBlock(world, i + 9, j + 8, k + 7, Blocks.air, 0);
		setBlock(world, i + 9, j + 8, k + 8, Blocks.air, 0);
		setBlock(world, i + 9, j + 8, k + 9, Blocks.air, 0);
		setBlock(world, i + 9, j + 8, k + 10, Blocks.air, 0);
		setBlock(world, i + 9, j + 8, k + 11, Blocks.air, 0);
		setBlock(world, i + 9, j + 8, k + 12, Blocks.air, 0);
		setBlock(world, i + 9, j + 8, k + 13, Blocks.air, 0);
		setBlock(world, i + 9, j + 8, k + 14, Blocks.air, 0);
		setBlock(world, i + 9, j + 8, k + 15, Blocks.air, 0);
		setBlock(world, i + 9, j + 8, k + 16, Blocks.air, 0);
		setBlock(world, i + 9, j + 8, k + 17, Blocks.air, 0);
		setBlock(world, i + 9, j + 9, k + 6, Blocks.air, 0);
		setBlock(world, i + 9, j + 9, k + 7, Blocks.air, 0);
		setBlock(world, i + 9, j + 9, k + 8, Blocks.air, 0);
		setBlock(world, i + 9, j + 9, k + 9, Blocks.air, 0);
		setBlock(world, i + 9, j + 9, k + 10, Blocks.air, 0);
		setBlock(world, i + 9, j + 9, k + 11, Blocks.air, 0);
		setBlock(world, i + 9, j + 9, k + 12, Blocks.air, 0);
		setBlock(world, i + 9, j + 9, k + 13, Blocks.air, 0);
		setBlock(world, i + 9, j + 9, k + 14, Blocks.air, 0);
		setBlock(world, i + 9, j + 9, k + 15, Blocks.air, 0);
		setBlock(world, i + 9, j + 9, k + 16, Blocks.air, 0);
		setBlock(world, i + 9, j + 10, k + 7, Blocks.air, 0);
		setBlock(world, i + 9, j + 10, k + 8, Blocks.air, 0);
		setBlock(world, i + 9, j + 10, k + 9, Blocks.air, 0);
		setBlock(world, i + 9, j + 10, k + 10, Blocks.air, 0);
		setBlock(world, i + 9, j + 10, k + 11, Blocks.air, 0);
		setBlock(world, i + 10, j + 0, k + 9, Blocks.stone, 0);
		setBlock(world, i + 10, j + 0, k + 10, Blocks.clay, 0);
		setBlock(world, i + 10, j + 0, k + 11, Blocks.stone, 0);
		setBlock(world, i + 10, j + 0, k + 12, Blocks.stone, 0);
		setBlock(world, i + 10, j + 0, k + 13, Blocks.stone, 0);
		setBlock(world, i + 10, j + 0, k + 14, Blocks.cobblestone, 0);
		setBlock(world, i + 10, j + 0, k + 15, Blocks.stone, 0);
		setBlock(world, i + 10, j + 0, k + 16, Blocks.stone, 0);
		setBlock(world, i + 10, j + 1, k + 5, Blocks.stone, 0);
		setBlock(world, i + 10, j + 1, k + 6, Blocks.stone, 0);
		setBlock(world, i + 10, j + 1, k + 8, Blocks.stone, 0);
		setBlock(world, i + 10, j + 1, k + 9, Blocks.air, 0);
		setBlock(world, i + 10, j + 1, k + 10, Blocks.air, 0);
		setBlock(world, i + 10, j + 1, k + 11, Blocks.air, 0);
		setBlock(world, i + 10, j + 1, k + 12, Blocks.air, 0);
		setBlock(world, i + 10, j + 1, k + 13, Blocks.air, 0);
		setBlock(world, i + 10, j + 1, k + 14, Blocks.air, 0);
		setBlock(world, i + 10, j + 1, k + 15, Blocks.air, 0);
		setBlock(world, i + 10, j + 1, k + 16, Blocks.air, 0);
		setBlock(world, i + 10, j + 1, k + 17, Blocks.air, 2);
		setBlock(world, i + 10, j + 2, k + 3, Blocks.stone, 0);
		setBlock(world, i + 10, j + 2, k + 4, Blocks.stone, 0);
		setBlock(world, i + 10, j + 2, k + 5, Blocks.lit_pumpkin, 3);
		setBlock(world, i + 10, j + 2, k + 6, Blocks.air, 0);
		setBlock(world, i + 10, j + 2, k + 7, Blocks.stone, 0);
		setBlock(world, i + 10, j + 2, k + 8, Blocks.stone_slab, 6);
		setBlock(world, i + 10, j + 2, k + 9, Blocks.air, 0);
		setBlock(world, i + 10, j + 2, k + 10, Blocks.air, 0);
		setBlock(world, i + 10, j + 2, k + 11, Blocks.air, 0);
		setBlock(world, i + 10, j + 2, k + 12, Blocks.air, 0);
		setBlock(world, i + 10, j + 2, k + 13, Blocks.air, 0);
		setBlock(world, i + 10, j + 2, k + 14, Blocks.air, 0);
		setBlock(world, i + 10, j + 2, k + 15, Blocks.air, 0);
		setBlock(world, i + 10, j + 2, k + 16, Blocks.air, 0);
		setBlock(world, i + 10, j + 2, k + 17, Blocks.stone_slab, 14);
		setBlock(world, i + 10, j + 2, k + 18, Blocks.stone_slab, 6);
		setBlock(world, i + 10, j + 3, k + 4, Blocks.stone, 0);
		setBlock(world, i + 10, j + 3, k + 5, Blocks.stone, 0);
		setBlock(world, i + 10, j + 3, k + 6, Blocks.stonebrick, 3);
		setBlock(world, i + 10, j + 3, k + 7, Blocks.stonebrick, 3);
		setBlock(world, i + 10, j + 3, k + 8, Blocks.air, 0);
		setBlock(world, i + 10, j + 3, k + 9, Blocks.air, 0);
		setBlock(world, i + 10, j + 3, k + 10, Blocks.air, 0);
		setBlock(world, i + 10, j + 3, k + 11, Blocks.air, 0);
		setBlock(world, i + 10, j + 3, k + 12, Blocks.air, 0);
		setBlock(world, i + 10, j + 3, k + 13, Blocks.air, 0);
		setBlock(world, i + 10, j + 3, k + 14, ModBlocks.gravewoodLeaves, 0);
		setBlock(world, i + 10, j + 3, k + 15, Blocks.air, 0);
		setBlock(world, i + 10, j + 3, k + 16, Blocks.air, 0);
		setBlock(world, i + 10, j + 3, k + 17, Blocks.stonebrick, 3);
		setBlock(world, i + 10, j + 3, k + 18, Blocks.stone, 0);
		setBlock(world, i + 10, j + 4, k + 4, Blocks.dirt, 0);
		setBlock(world, i + 10, j + 4, k + 5, Blocks.dirt, 0);
		setBlock(world, i + 10, j + 4, k + 6, Blocks.stone, 0);
		setBlock(world, i + 10, j + 4, k + 7, Blocks.stone, 0);
		setBlock(world, i + 10, j + 4, k + 8, Blocks.air, 0);
		setBlock(world, i + 10, j + 4, k + 9, Blocks.air, 0);
		setBlock(world, i + 10, j + 4, k + 10, Blocks.air, 4);
		setBlock(world, i + 10, j + 4, k + 11, ModBlocks.gravewoodLeaves, 0);
		setBlock(world, i + 10, j + 4, k + 12, ModBlocks.gravewoodLeaves, 0);
		setBlock(world, i + 10, j + 4, k + 13, Blocks.air, 0);
		setBlock(world, i + 10, j + 4, k + 14, ModBlocks.gravewood, 0);
		setBlock(world, i + 10, j + 4, k + 15, ModBlocks.gravewoodLeaves, 0);
		setBlock(world, i + 10, j + 4, k + 16, Blocks.air, 0);
		setBlock(world, i + 10, j + 4, k + 17, Blocks.nether_brick_stairs, 6);
		setBlock(world, i + 10, j + 4, k + 18, Blocks.dirt, 0);
		setBlock(world, i + 10, j + 5, k + 2, Blocks.mycelium, 0);
		setBlock(world, i + 10, j + 5, k + 3, Blocks.mycelium, 0);
		setBlock(world, i + 10, j + 5, k + 4, Blocks.mycelium, 0);
		setBlock(world, i + 10, j + 5, k + 5, Blocks.mycelium, 0);
		setBlock(world, i + 10, j + 5, k + 6, Blocks.mycelium, 0);
		setBlock(world, i + 10, j + 5, k + 7, Blocks.mycelium, 0);
		setBlock(world, i + 10, j + 5, k + 8, Blocks.mycelium, 0);
		setBlock(world, i + 10, j + 5, k + 9, Blocks.dirt, 2);
		setBlock(world, i + 10, j + 5, k + 10, Blocks.dirt, 2);
		setBlock(world, i + 10, j + 5, k + 11, Blocks.mycelium, 0);
		setBlock(world, i + 10, j + 5, k + 12, Blocks.dirt, 2);
		setBlock(world, i + 10, j + 5, k + 13, Blocks.dirt, 2);
		setBlock(world, i + 10, j + 5, k + 14, Blocks.stone, 0);
		setBlock(world, i + 10, j + 5, k + 15, Blocks.dirt, 2);
		setBlock(world, i + 10, j + 5, k + 16, Blocks.dirt, 2);
		setBlock(world, i + 10, j + 5, k + 17, Blocks.mycelium, 0);
		setBlock(world, i + 10, j + 5, k + 18, Blocks.mycelium, 0);
		setBlock(world, i + 10, j + 6, k + 2, Blocks.nether_brick_fence, 0);
		setBlock(world, i + 10, j + 6, k + 3, Blocks.air, 0);
		setBlock(world, i + 10, j + 6, k + 4, Blocks.nether_brick_fence, 0);
		setBlock(world, i + 10, j + 6, k + 5, Blocks.nether_brick_fence, 0);
		setBlock(world, i + 10, j + 6, k + 6, ModBlocks.gravewoodLeaves, 0);
		setBlock(world, i + 10, j + 6, k + 7, Blocks.air, 0);
		setBlock(world, i + 10, j + 6, k + 8, Blocks.air, 0);
		setBlock(world, i + 10, j + 6, k + 10, Blocks.air, 0);
		setBlock(world, i + 10, j + 6, k + 11, Blocks.air, 0);
		setBlock(world, i + 10, j + 6, k + 12, Blocks.air, 0);
		setBlock(world, i + 10, j + 6, k + 14, Blocks.stone, 0);
		setBlock(world, i + 10, j + 6, k + 16, Blocks.air, 0);
		setBlock(world, i + 10, j + 6, k + 17, Blocks.air, 0);
		setBlock(world, i + 10, j + 6, k + 18, Blocks.nether_brick_fence, 0);
		setBlock(world, i + 10, j + 7, k + 2, Blocks.air, 0);
		setBlock(world, i + 10, j + 7, k + 3, Blocks.air, 0);
		setBlock(world, i + 10, j + 7, k + 4, Blocks.air, 0);
		setBlock(world, i + 10, j + 7, k + 5, Blocks.air, 0);
		setBlock(world, i + 10, j + 7, k + 6, Blocks.air, 0);
		setBlock(world, i + 10, j + 7, k + 7, Blocks.air, 0);
		setBlock(world, i + 10, j + 7, k + 8, Blocks.air, 0);
		setBlock(world, i + 10, j + 7, k + 9, Blocks.air, 0);
		setBlock(world, i + 10, j + 7, k + 10, Blocks.air, 0);
		setBlock(world, i + 10, j + 7, k + 11, Blocks.air, 0);
		setBlock(world, i + 10, j + 7, k + 12, Blocks.air, 0);
		setBlock(world, i + 10, j + 7, k + 13, Blocks.air, 0);
		setBlock(world, i + 10, j + 7, k + 14, Blocks.air, 0);
		setBlock(world, i + 10, j + 7, k + 15, Blocks.air, 0);
		setBlock(world, i + 10, j + 7, k + 16, Blocks.air, 0);
		setBlock(world, i + 10, j + 7, k + 17, Blocks.air, 0);
		setBlock(world, i + 10, j + 7, k + 18, Blocks.air, 0);
		setBlock(world, i + 10, j + 8, k + 6, Blocks.air, 0);
		setBlock(world, i + 10, j + 8, k + 7, Blocks.air, 0);
		setBlock(world, i + 10, j + 8, k + 8, Blocks.air, 0);
		setBlock(world, i + 10, j + 8, k + 9, Blocks.air, 0);
		setBlock(world, i + 10, j + 8, k + 10, Blocks.air, 0);
		setBlock(world, i + 10, j + 8, k + 11, Blocks.air, 0);
		setBlock(world, i + 10, j + 8, k + 12, Blocks.air, 0);
		setBlock(world, i + 10, j + 8, k + 13, Blocks.air, 0);
		setBlock(world, i + 10, j + 8, k + 14, Blocks.air, 0);
		setBlock(world, i + 10, j + 8, k + 15, Blocks.air, 0);
		setBlock(world, i + 10, j + 8, k + 16, Blocks.air, 0);
		setBlock(world, i + 10, j + 8, k + 17, Blocks.air, 0);
		setBlock(world, i + 10, j + 9, k + 7, Blocks.air, 0);
		setBlock(world, i + 10, j + 9, k + 8, Blocks.air, 0);
		setBlock(world, i + 10, j + 9, k + 9, Blocks.air, 0);
		setBlock(world, i + 10, j + 9, k + 10, Blocks.air, 0);
		setBlock(world, i + 10, j + 9, k + 11, Blocks.air, 0);
		setBlock(world, i + 10, j + 9, k + 12, Blocks.air, 0);
		setBlock(world, i + 10, j + 9, k + 13, Blocks.air, 0);
		setBlock(world, i + 10, j + 9, k + 14, Blocks.air, 0);
		setBlock(world, i + 10, j + 9, k + 15, Blocks.air, 0);
		setBlock(world, i + 10, j + 9, k + 16, Blocks.air, 0);
		setBlock(world, i + 10, j + 10, k + 8, Blocks.air, 0);
		setBlock(world, i + 10, j + 10, k + 9, Blocks.air, 0);
		setBlock(world, i + 10, j + 10, k + 10, Blocks.air, 0);
		setBlock(world, i + 10, j + 10, k + 11, Blocks.air, 0);
		setBlock(world, i + 10, j + 10, k + 12, Blocks.air, 0);
		setBlock(world, i + 10, j + 10, k + 13, Blocks.air, 0);
		setBlock(world, i + 10, j + 10, k + 14, Blocks.air, 0);
		setBlock(world, i + 10, j + 10, k + 15, Blocks.air, 0);
		setBlock(world, i + 11, j + 0, k + 9, Blocks.stone, 0);
		setBlock(world, i + 11, j + 0, k + 10, Blocks.stone, 0);
		setBlock(world, i + 11, j + 0, k + 11, Blocks.clay, 0);
		setBlock(world, i + 11, j + 0, k + 12, Blocks.stone, 0);
		setBlock(world, i + 11, j + 0, k + 13, Blocks.stone, 0);
		setBlock(world, i + 11, j + 0, k + 14, Blocks.stone, 0);
		setBlock(world, i + 11, j + 0, k + 15, Blocks.cobblestone, 0);
		setBlock(world, i + 11, j + 0, k + 16, Blocks.stone, 0);
		setBlock(world, i + 11, j + 1, k + 6, Blocks.stone, 0);
		setBlock(world, i + 11, j + 1, k + 9, Blocks.air, 3);
		setBlock(world, i + 11, j + 1, k + 10, Blocks.air, 0);
		setBlock(world, i + 11, j + 1, k + 11, Blocks.air, 0);
		setBlock(world, i + 11, j + 1, k + 12, Blocks.air, 0);
		setBlock(world, i + 11, j + 1, k + 13, Blocks.stone_slab, 6);
		setBlock(world, i + 11, j + 1, k + 14, Blocks.air, 0);
		setBlock(world, i + 11, j + 1, k + 15, Blocks.air, 0);
		setBlock(world, i + 11, j + 1, k + 16, Blocks.air, 0);
		setBlock(world, i + 11, j + 1, k + 17, Blocks.air, 2);
		setBlock(world, i + 11, j + 2, k + 3, Blocks.stone, 0);
		setBlock(world, i + 11, j + 2, k + 4, Blocks.stone, 0);
		setBlock(world, i + 11, j + 2, k + 5, Blocks.stone, 0);
		setBlock(world, i + 11, j + 2, k + 6, Blocks.stone, 0);
		setBlock(world, i + 11, j + 2, k + 7, Blocks.stone, 0);
		setBlock(world, i + 11, j + 2, k + 8, Blocks.stone, 0);
		setBlock(world, i + 11, j + 2, k + 9, Blocks.double_stone_slab, 6);
		setBlock(world, i + 11, j + 2, k + 10, Blocks.air, 0);
		setBlock(world, i + 11, j + 2, k + 11, Blocks.air, 0);
		setBlock(world, i + 11, j + 2, k + 12, Blocks.air, 0);
		setBlock(world, i + 11, j + 2, k + 13, Blocks.air, 0);
		setBlock(world, i + 11, j + 2, k + 14, Blocks.air, 0);
		setBlock(world, i + 11, j + 2, k + 15, Blocks.air, 0);
		setBlock(world, i + 11, j + 2, k + 16, Blocks.air, 0);
		setBlock(world, i + 11, j + 2, k + 17, Blocks.stone_slab, 14);
		setBlock(world, i + 11, j + 2, k + 18, Blocks.stone_slab, 6);
		setBlock(world, i + 11, j + 3, k + 4, Blocks.stone, 0);
		setBlock(world, i + 11, j + 3, k + 5, Blocks.dirt, 0);
		setBlock(world, i + 11, j + 3, k + 6, Blocks.stone, 0);
		setBlock(world, i + 11, j + 3, k + 7, Blocks.stone, 0);
		setBlock(world, i + 11, j + 3, k + 8, Blocks.stonebrick, 3);
		setBlock(world, i + 11, j + 3, k + 9, Blocks.stonebrick, 3);
		setBlock(world, i + 11, j + 3, k + 10, Blocks.air, 0);
		setBlock(world, i + 11, j + 3, k + 11, Blocks.air, 0);
		setBlock(world, i + 11, j + 3, k + 12, Blocks.air, 0);
		setBlock(world, i + 11, j + 3, k + 13, Blocks.air, 0);
		setBlock(world, i + 11, j + 3, k + 14, Blocks.air, 0);
		setBlock(world, i + 11, j + 3, k + 15, Blocks.air, 0);
		setBlock(world, i + 11, j + 3, k + 16, Blocks.air, 0);
		setBlock(world, i + 11, j + 3, k + 17, Blocks.stonebrick, 3);
		setBlock(world, i + 11, j + 3, k + 18, Blocks.stone, 0);
		setBlock(world, i + 11, j + 4, k + 4, Blocks.dirt, 0);
		setBlock(world, i + 11, j + 4, k + 5, Blocks.dirt, 0);
		setBlock(world, i + 11, j + 4, k + 6, Blocks.dirt, 0);
		setBlock(world, i + 11, j + 4, k + 7, Blocks.stone, 0);
		setBlock(world, i + 11, j + 4, k + 8, Blocks.stone, 0);
		setBlock(world, i + 11, j + 4, k + 9, Blocks.nether_brick_stairs, 7);
		setBlock(world, i + 11, j + 4, k + 10, ModBlocks.gravewood, 0);
		setBlock(world, i + 11, j + 4, k + 11, Blocks.air, 8);
		setBlock(world, i + 11, j + 4, k + 12, ModBlocks.gravewoodLeaves, 0);
		setBlock(world, i + 11, j + 4, k + 13, ModBlocks.gravewood, 0);
		setBlock(world, i + 11, j + 4, k + 14, ModBlocks.gravewood, 0);
		setBlock(world, i + 11, j + 4, k + 15, ModBlocks.gravewoodLeaves, 0);
		setBlock(world, i + 11, j + 4, k + 16, Blocks.air, 0);
		setBlock(world, i + 11, j + 4, k + 17, Blocks.nether_brick_stairs, 6);
		setBlock(world, i + 11, j + 4, k + 18, Blocks.dirt, 0);
		setBlock(world, i + 11, j + 5, k + 5, Blocks.mycelium, 0);
		setBlock(world, i + 11, j + 5, k + 6, Blocks.dirt, 0);
		setBlock(world, i + 11, j + 5, k + 7, Blocks.mycelium, 0);
		setBlock(world, i + 11, j + 5, k + 8, Blocks.mycelium, 0);
		setBlock(world, i + 11, j + 5, k + 9, Blocks.mycelium, 0);
		setBlock(world, i + 11, j + 5, k + 10, Blocks.mycelium, 0);
		setBlock(world, i + 11, j + 5, k + 11, Blocks.mycelium, 0);
		setBlock(world, i + 11, j + 5, k + 12, Blocks.mycelium, 0);
		setBlock(world, i + 11, j + 5, k + 13, Blocks.mycelium, 0);
		setBlock(world, i + 11, j + 5, k + 14, Blocks.dirt, 0);
		setBlock(world, i + 11, j + 5, k + 15, Blocks.mycelium, 0);
		setBlock(world, i + 11, j + 5, k + 16, Blocks.mycelium, 0);
		setBlock(world, i + 11, j + 5, k + 17, Blocks.mycelium, 0);
		setBlock(world, i + 11, j + 5, k + 18, Blocks.mycelium, 0);
		setBlock(world, i + 11, j + 6, k + 5, Blocks.nether_brick_fence, 0);
		setBlock(world, i + 11, j + 6, k + 6, ModBlocks.gravewood, 0);
		setBlock(world, i + 11, j + 6, k + 7, ModBlocks.gravewoodLeaves, 0);
		setBlock(world, i + 11, j + 6, k + 8, Blocks.air, 0);
		setBlock(world, i + 11, j + 6, k + 9, Blocks.air, 0);
		setBlock(world, i + 11, j + 6, k + 10, Blocks.air, 0);
		setBlock(world, i + 11, j + 6, k + 11, Blocks.air, 0);
		setBlock(world, i + 11, j + 6, k + 12, Blocks.air, 0);
		setBlock(world, i + 11, j + 6, k + 13, Blocks.air, 0);
		setBlock(world, i + 11, j + 6, k + 14, Blocks.stone, 0);
		setBlock(world, i + 11, j + 6, k + 15, Blocks.air, 0);
		setBlock(world, i + 11, j + 6, k + 16, Blocks.air, 0);
		setBlock(world, i + 11, j + 6, k + 17, Blocks.air, 0);
		setBlock(world, i + 11, j + 6, k + 18, Blocks.nether_brick_fence, 0);
		setBlock(world, i + 11, j + 7, k + 5, Blocks.air, 0);
		setBlock(world, i + 11, j + 7, k + 6, ModBlocks.gravewoodLeaves, 0);
		setBlock(world, i + 11, j + 7, k + 7, Blocks.air, 0);
		setBlock(world, i + 11, j + 7, k + 8, Blocks.air, 0);
		setBlock(world, i + 11, j + 7, k + 9, Blocks.air, 0);
		setBlock(world, i + 11, j + 7, k + 10, Blocks.air, 0);
		setBlock(world, i + 11, j + 7, k + 11, Blocks.air, 0);
		setBlock(world, i + 11, j + 7, k + 12, Blocks.air, 0);
		setBlock(world, i + 11, j + 7, k + 13, Blocks.air, 0);
		setBlock(world, i + 11, j + 7, k + 14, Blocks.air, 0);
		setBlock(world, i + 11, j + 7, k + 15, Blocks.air, 0);
		setBlock(world, i + 11, j + 7, k + 16, Blocks.air, 0);
		setBlock(world, i + 11, j + 7, k + 17, Blocks.air, 0);
		setBlock(world, i + 11, j + 7, k + 18, Blocks.air, 0);
		setBlock(world, i + 11, j + 8, k + 7, Blocks.air, 0);
		setBlock(world, i + 11, j + 8, k + 8, Blocks.air, 0);
		setBlock(world, i + 11, j + 8, k + 9, Blocks.air, 0);
		setBlock(world, i + 11, j + 8, k + 10, Blocks.air, 0);
		setBlock(world, i + 11, j + 8, k + 11, Blocks.air, 0);
		setBlock(world, i + 11, j + 8, k + 12, Blocks.air, 0);
		setBlock(world, i + 11, j + 8, k + 13, Blocks.air, 0);
		setBlock(world, i + 11, j + 8, k + 14, Blocks.air, 0);
		setBlock(world, i + 11, j + 8, k + 15, Blocks.air, 0);
		setBlock(world, i + 11, j + 8, k + 16, Blocks.air, 0);
		setBlock(world, i + 11, j + 8, k + 17, Blocks.air, 0);
		setBlock(world, i + 11, j + 9, k + 8, Blocks.air, 0);
		setBlock(world, i + 11, j + 9, k + 9, Blocks.air, 0);
		setBlock(world, i + 11, j + 9, k + 10, Blocks.air, 0);
		setBlock(world, i + 11, j + 9, k + 11, Blocks.air, 0);
		setBlock(world, i + 11, j + 9, k + 12, Blocks.air, 0);
		setBlock(world, i + 11, j + 9, k + 13, Blocks.air, 0);
		setBlock(world, i + 11, j + 9, k + 14, Blocks.air, 0);
		setBlock(world, i + 11, j + 9, k + 15, Blocks.air, 0);
		setBlock(world, i + 11, j + 9, k + 16, Blocks.air, 0);
		setBlock(world, i + 11, j + 10, k + 9, Blocks.air, 0);
		setBlock(world, i + 11, j + 10, k + 10, Blocks.air, 0);
		setBlock(world, i + 11, j + 10, k + 11, Blocks.air, 0);
		setBlock(world, i + 11, j + 10, k + 12, Blocks.air, 0);
		setBlock(world, i + 11, j + 10, k + 13, Blocks.air, 0);
		setBlock(world, i + 11, j + 10, k + 14, Blocks.air, 0);
		setBlock(world, i + 11, j + 10, k + 15, Blocks.air, 0);
		setBlock(world, i + 11, j + 11, k + 11, Blocks.air, 0);
		setBlock(world, i + 11, j + 11, k + 12, Blocks.air, 0);
		setBlock(world, i + 11, j + 11, k + 13, Blocks.air, 0);
		setBlock(world, i + 11, j + 11, k + 14, Blocks.air, 0);
		setBlock(world, i + 12, j + 0, k + 10, Blocks.stone, 0);
		setBlock(world, i + 12, j + 0, k + 11, Blocks.clay, 0);
		setBlock(world, i + 12, j + 0, k + 12, Blocks.stone, 0);
		setBlock(world, i + 12, j + 0, k + 13, Blocks.glowstone, 0);

		setBlock(world, i + 12, j + 2, k + 13, Blocks.chest, 0);
		TileEntityChest tileentitychest = (TileEntityChest) world.getTileEntity(new BlockPos(i + 12, j + 2, k + 13));
		if (tileentitychest != null)
		{
			WeightedRandomChestContent.generateChestContents(new Random(), GraveyardChestLoot.getItems(new Random()), tileentitychest, 1);
		}

		setBlock(world, i + 12, j + 0, k + 14, Blocks.stone, 0);
		setBlock(world, i + 12, j + 0, k + 15, Blocks.cobblestone, 0);
		setBlock(world, i + 12, j + 0, k + 16, Blocks.cobblestone, 0);
		setBlock(world, i + 12, j + 1, k + 9, Blocks.air, 3);
		setBlock(world, i + 12, j + 1, k + 10, Blocks.air, 0);
		setBlock(world, i + 12, j + 1, k + 11, Blocks.air, 0);
		setBlock(world, i + 12, j + 1, k + 12, Blocks.stone_slab, 6);
		setBlock(world, i + 12, j + 1, k + 13, Blocks.air, 0);
		setBlock(world, i + 12, j + 1, k + 14, Blocks.stone_slab, 6);
		setBlock(world, i + 12, j + 1, k + 15, Blocks.air, 0);
		setBlock(world, i + 12, j + 1, k + 16, Blocks.air, 0);
		setBlock(world, i + 12, j + 1, k + 17, Blocks.air, 2);
		setBlock(world, i + 12, j + 2, k + 3, Blocks.stone, 0);
		setBlock(world, i + 12, j + 2, k + 4, Blocks.stone, 0);
		setBlock(world, i + 12, j + 2, k + 5, Blocks.stone, 0);
		setBlock(world, i + 12, j + 2, k + 6, Blocks.stone, 0);
		setBlock(world, i + 12, j + 2, k + 7, Blocks.stone, 0);
		setBlock(world, i + 12, j + 2, k + 8, Blocks.stone_slab, 6);
		setBlock(world, i + 12, j + 2, k + 9, Blocks.stone_slab, 14);
		setBlock(world, i + 12, j + 2, k + 10, Blocks.air, 0);
		setBlock(world, i + 12, j + 2, k + 11, Blocks.air, 0);
		setBlock(world, i + 12, j + 2, k + 12, Blocks.air, 0);
		setBlock(world, i + 12, j + 2, k + 14, Blocks.air, 0);
		setBlock(world, i + 12, j + 2, k + 15, Blocks.air, 0);
		setBlock(world, i + 12, j + 2, k + 16, Blocks.air, 0);
		setBlock(world, i + 12, j + 2, k + 17, Blocks.stone_slab, 14);
		setBlock(world, i + 12, j + 2, k + 18, Blocks.stone_slab, 6);
		setBlock(world, i + 12, j + 3, k + 4, Blocks.stone, 0);
		setBlock(world, i + 12, j + 3, k + 5, Blocks.stone, 0);
		setBlock(world, i + 12, j + 3, k + 6, Blocks.dirt, 0);
		setBlock(world, i + 12, j + 3, k + 7, Blocks.dirt, 0);
		setBlock(world, i + 12, j + 3, k + 8, Blocks.stone, 0);
		setBlock(world, i + 12, j + 3, k + 9, Blocks.stonebrick, 3);
		setBlock(world, i + 12, j + 3, k + 10, Blocks.air, 0);
		setBlock(world, i + 12, j + 3, k + 11, Blocks.air, 0);
		setBlock(world, i + 12, j + 3, k + 12, Blocks.air, 0);
		setBlock(world, i + 12, j + 3, k + 13, Blocks.air, 0);
		setBlock(world, i + 12, j + 3, k + 14, Blocks.air, 0);
		setBlock(world, i + 12, j + 3, k + 15, Blocks.air, 0);
		setBlock(world, i + 12, j + 3, k + 16, Blocks.air, 0);
		setBlock(world, i + 12, j + 3, k + 17, Blocks.stonebrick, 3);
		setBlock(world, i + 12, j + 3, k + 18, Blocks.stone, 0);
		setBlock(world, i + 12, j + 4, k + 4, Blocks.dirt, 0);
		setBlock(world, i + 12, j + 4, k + 5, Blocks.dirt, 0);
		setBlock(world, i + 12, j + 4, k + 6, Blocks.dirt, 0);
		setBlock(world, i + 12, j + 4, k + 7, Blocks.dirt, 0);
		setBlock(world, i + 12, j + 4, k + 8, Blocks.dirt, 0);
		setBlock(world, i + 12, j + 4, k + 9, Blocks.nether_brick_stairs, 7);
		setBlock(world, i + 12, j + 4, k + 10, ModBlocks.gravewoodLeaves, 0);
		setBlock(world, i + 12, j + 4, k + 11, Blocks.air, 0);
		setBlock(world, i + 12, j + 4, k + 12, Blocks.air, 0);
		setBlock(world, i + 12, j + 4, k + 13, ModBlocks.gravewoodLeaves, 0);
		setBlock(world, i + 12, j + 4, k + 14, ModBlocks.gravewoodLeaves, 0);
		setBlock(world, i + 12, j + 4, k + 15, Blocks.air, 0);
		setBlock(world, i + 12, j + 4, k + 16, Blocks.air, 0);
		setBlock(world, i + 12, j + 4, k + 17, Blocks.nether_brick_stairs, 6);
		setBlock(world, i + 12, j + 4, k + 18, Blocks.dirt, 0);
		setBlock(world, i + 12, j + 5, k + 6, Blocks.mycelium, 0);
		setBlock(world, i + 12, j + 5, k + 7, Blocks.mycelium, 0);
		setBlock(world, i + 12, j + 5, k + 8, Blocks.mycelium, 0);
		setBlock(world, i + 12, j + 5, k + 9, Blocks.dirt, 2);
		setBlock(world, i + 12, j + 5, k + 10, Blocks.dirt, 2);
		setBlock(world, i + 12, j + 5, k + 11, Blocks.mycelium, 0);
		setBlock(world, i + 12, j + 5, k + 12, Blocks.dirt, 2);
		setBlock(world, i + 12, j + 5, k + 13, Blocks.dirt, 2);
		setBlock(world, i + 12, j + 5, k + 14, Blocks.dirt, 0);
		setBlock(world, i + 12, j + 5, k + 15, Blocks.dirt, 2);
		setBlock(world, i + 12, j + 5, k + 16, Blocks.dirt, 2);
		setBlock(world, i + 12, j + 5, k + 17, Blocks.mycelium, 0);
		setBlock(world, i + 12, j + 5, k + 18, Blocks.mycelium, 0);
		setBlock(world, i + 12, j + 6, k + 6, ModBlocks.gravewoodLeaves, 0);
		setBlock(world, i + 12, j + 6, k + 7, Blocks.nether_brick_fence, 0);
		setBlock(world, i + 12, j + 6, k + 8, Blocks.air, 0);
		setBlock(world, i + 12, j + 6, k + 10, Blocks.air, 0);
		setBlock(world, i + 12, j + 6, k + 11, Blocks.air, 0);
		setBlock(world, i + 12, j + 6, k + 12, Blocks.air, 0);
		setBlock(world, i + 12, j + 6, k + 14, Blocks.stone, 0);
		setBlock(world, i + 12, j + 6, k + 16, Blocks.air, 0);
		setBlock(world, i + 12, j + 6, k + 17, Blocks.air, 0);
		setBlock(world, i + 12, j + 6, k + 18, Blocks.air, 0);
		setBlock(world, i + 12, j + 7, k + 6, Blocks.air, 0);
		setBlock(world, i + 12, j + 7, k + 7, Blocks.air, 0);
		setBlock(world, i + 12, j + 7, k + 8, Blocks.air, 0);
		setBlock(world, i + 12, j + 7, k + 9, Blocks.air, 0);
		setBlock(world, i + 12, j + 7, k + 10, Blocks.air, 0);
		setBlock(world, i + 12, j + 7, k + 11, Blocks.air, 0);
		setBlock(world, i + 12, j + 7, k + 12, Blocks.air, 0);
		setBlock(world, i + 12, j + 7, k + 13, Blocks.air, 0);
		setBlock(world, i + 12, j + 7, k + 14, Blocks.air, 0);
		setBlock(world, i + 12, j + 7, k + 15, Blocks.air, 0);
		setBlock(world, i + 12, j + 7, k + 16, Blocks.air, 0);
		setBlock(world, i + 12, j + 7, k + 17, Blocks.air, 0);
		setBlock(world, i + 12, j + 7, k + 18, Blocks.air, 0);
		setBlock(world, i + 12, j + 8, k + 8, Blocks.air, 0);
		setBlock(world, i + 12, j + 8, k + 9, Blocks.air, 0);
		setBlock(world, i + 12, j + 8, k + 10, Blocks.air, 0);
		setBlock(world, i + 12, j + 8, k + 11, Blocks.air, 0);
		setBlock(world, i + 12, j + 8, k + 12, Blocks.air, 0);
		setBlock(world, i + 12, j + 8, k + 13, Blocks.air, 0);
		setBlock(world, i + 12, j + 8, k + 14, ModBlocks.gravewoodLeaves, 0);
		setBlock(world, i + 12, j + 8, k + 15, Blocks.air, 0);
		setBlock(world, i + 12, j + 8, k + 16, Blocks.air, 0);
		setBlock(world, i + 12, j + 8, k + 17, Blocks.air, 0);
		setBlock(world, i + 12, j + 9, k + 9, Blocks.air, 0);
		setBlock(world, i + 12, j + 9, k + 10, Blocks.air, 0);
		setBlock(world, i + 12, j + 9, k + 11, Blocks.air, 0);
		setBlock(world, i + 12, j + 9, k + 12, Blocks.air, 0);
		setBlock(world, i + 12, j + 9, k + 13, ModBlocks.gravewoodLeaves, 0);
		setBlock(world, i + 12, j + 9, k + 14, ModBlocks.gravewood, 0);
		setBlock(world, i + 12, j + 9, k + 15, Blocks.air, 0);
		setBlock(world, i + 12, j + 9, k + 16, Blocks.air, 0);
		setBlock(world, i + 12, j + 10, k + 10, Blocks.air, 0);
		setBlock(world, i + 12, j + 10, k + 11, Blocks.air, 0);
		setBlock(world, i + 12, j + 10, k + 12, Blocks.air, 0);
		setBlock(world, i + 12, j + 10, k + 13, Blocks.air, 0);
		setBlock(world, i + 12, j + 10, k + 14, Blocks.air, 0);
		setBlock(world, i + 12, j + 10, k + 15, Blocks.air, 0);
		setBlock(world, i + 12, j + 11, k + 12, Blocks.air, 0);
		setBlock(world, i + 12, j + 11, k + 13, Blocks.air, 0);
		setBlock(world, i + 12, j + 11, k + 14, Blocks.air, 0);
		setBlock(world, i + 13, j + 0, k + 10, Blocks.stone, 0);
		setBlock(world, i + 13, j + 0, k + 11, Blocks.stone, 0);
		setBlock(world, i + 13, j + 0, k + 12, Blocks.stone, 0);
		setBlock(world, i + 13, j + 0, k + 13, Blocks.stone, 0);
		setBlock(world, i + 13, j + 0, k + 14, Blocks.stone, 0);
		setBlock(world, i + 13, j + 0, k + 15, Blocks.cobblestone, 0);
		setBlock(world, i + 13, j + 0, k + 16, Blocks.stone, 0);
		setBlock(world, i + 13, j + 1, k + 9, Blocks.air, 3);
		setBlock(world, i + 13, j + 1, k + 10, Blocks.air, 0);
		setBlock(world, i + 13, j + 1, k + 11, Blocks.air, 0);
		setBlock(world, i + 13, j + 1, k + 12, Blocks.air, 0);
		setBlock(world, i + 13, j + 1, k + 13, Blocks.stone_slab, 6);
		setBlock(world, i + 13, j + 1, k + 14, Blocks.air, 0);
		setBlock(world, i + 13, j + 1, k + 15, Blocks.air, 0);
		setBlock(world, i + 13, j + 1, k + 16, Blocks.air, 0);
		setBlock(world, i + 13, j + 1, k + 17, Blocks.air, 2);
		setBlock(world, i + 13, j + 2, k + 3, Blocks.stone, 0);
		setBlock(world, i + 13, j + 2, k + 4, Blocks.stone, 0);
		setBlock(world, i + 13, j + 2, k + 5, Blocks.stone, 0);
		setBlock(world, i + 13, j + 2, k + 6, Blocks.stone, 0);
		setBlock(world, i + 13, j + 2, k + 7, Blocks.stone, 0);
		setBlock(world, i + 13, j + 2, k + 8, Blocks.stone_slab, 6);
		setBlock(world, i + 13, j + 2, k + 9, Blocks.stone_slab, 14);
		setBlock(world, i + 13, j + 2, k + 10, Blocks.air, 0);
		setBlock(world, i + 13, j + 2, k + 11, Blocks.air, 0);
		setBlock(world, i + 13, j + 2, k + 12, Blocks.air, 0);
		setBlock(world, i + 13, j + 2, k + 13, Blocks.air, 0);
		setBlock(world, i + 13, j + 2, k + 14, Blocks.air, 0);
		setBlock(world, i + 13, j + 2, k + 15, Blocks.air, 0);
		setBlock(world, i + 13, j + 2, k + 16, Blocks.air, 0);
		setBlock(world, i + 13, j + 2, k + 17, Blocks.stone_slab, 14);
		setBlock(world, i + 13, j + 2, k + 18, Blocks.stone_slab, 6);
		setBlock(world, i + 13, j + 3, k + 4, Blocks.stone, 0);
		setBlock(world, i + 13, j + 3, k + 5, Blocks.stone, 0);
		setBlock(world, i + 13, j + 3, k + 6, Blocks.dirt, 0);
		setBlock(world, i + 13, j + 3, k + 7, Blocks.dirt, 0);
		setBlock(world, i + 13, j + 3, k + 8, Blocks.stone, 0);
		setBlock(world, i + 13, j + 3, k + 9, Blocks.stonebrick, 3);
		setBlock(world, i + 13, j + 3, k + 10, ModBlocks.gravewoodLeaves, 0);
		setBlock(world, i + 13, j + 3, k + 11, Blocks.air, 0);
		setBlock(world, i + 13, j + 3, k + 12, Blocks.air, 0);
		setBlock(world, i + 13, j + 3, k + 13, Blocks.air, 0);
		setBlock(world, i + 13, j + 3, k + 14, Blocks.air, 0);
		setBlock(world, i + 13, j + 3, k + 15, Blocks.air, 0);
		setBlock(world, i + 13, j + 3, k + 16, Blocks.air, 0);
		setBlock(world, i + 13, j + 3, k + 17, Blocks.stonebrick, 3);
		setBlock(world, i + 13, j + 3, k + 18, Blocks.stone, 0);
		setBlock(world, i + 13, j + 4, k + 4, Blocks.dirt, 0);
		setBlock(world, i + 13, j + 4, k + 5, Blocks.dirt, 0);
		setBlock(world, i + 13, j + 4, k + 6, Blocks.dirt, 0);
		setBlock(world, i + 13, j + 4, k + 7, Blocks.dirt, 0);
		setBlock(world, i + 13, j + 4, k + 8, Blocks.dirt, 0);
		setBlock(world, i + 13, j + 4, k + 9, Blocks.nether_brick_stairs, 7);
		setBlock(world, i + 13, j + 4, k + 10, ModBlocks.gravewoodLeaves, 0);
		setBlock(world, i + 13, j + 4, k + 11, Blocks.air, 4);
		setBlock(world, i + 13, j + 4, k + 12, ModBlocks.gravewoodLeaves, 0);
		setBlock(world, i + 13, j + 4, k + 13, ModBlocks.gravewoodLeaves, 0);
		setBlock(world, i + 13, j + 4, k + 14, Blocks.air, 0);
		setBlock(world, i + 13, j + 4, k + 15, Blocks.air, 0);
		setBlock(world, i + 13, j + 4, k + 16, Blocks.air, 0);
		setBlock(world, i + 13, j + 4, k + 17, Blocks.nether_brick_stairs, 6);
		setBlock(world, i + 13, j + 4, k + 18, Blocks.dirt, 0);
		setBlock(world, i + 13, j + 5, k + 7, Blocks.mycelium, 0);
		setBlock(world, i + 13, j + 5, k + 8, Blocks.mycelium, 0);
		setBlock(world, i + 13, j + 5, k + 9, Blocks.mycelium, 0);
		setBlock(world, i + 13, j + 5, k + 10, Blocks.mycelium, 0);
		setBlock(world, i + 13, j + 5, k + 11, Blocks.mycelium, 0);
		setBlock(world, i + 13, j + 5, k + 12, Blocks.mycelium, 0);
		setBlock(world, i + 13, j + 5, k + 13, Blocks.mycelium, 0);
		setBlock(world, i + 13, j + 5, k + 14, Blocks.mycelium, 0);
		setBlock(world, i + 13, j + 5, k + 15, Blocks.mycelium, 0);
		setBlock(world, i + 13, j + 5, k + 16, Blocks.mycelium, 0);
		setBlock(world, i + 13, j + 5, k + 17, Blocks.mycelium, 0);
		setBlock(world, i + 13, j + 5, k + 18, Blocks.mycelium, 0);
		setBlock(world, i + 13, j + 6, k + 7, Blocks.nether_brick_fence, 0);
		setBlock(world, i + 13, j + 6, k + 8, Blocks.air, 0);
		setBlock(world, i + 13, j + 6, k + 9, Blocks.air, 0);
		setBlock(world, i + 13, j + 6, k + 10, Blocks.air, 0);
		setBlock(world, i + 13, j + 6, k + 11, Blocks.air, 0);
		setBlock(world, i + 13, j + 6, k + 12, Blocks.air, 0);
		setBlock(world, i + 13, j + 6, k + 13, Blocks.air, 0);
		setBlock(world, i + 13, j + 6, k + 14, Blocks.air, 0);
		setBlock(world, i + 13, j + 6, k + 15, Blocks.air, 0);
		setBlock(world, i + 13, j + 6, k + 16, Blocks.air, 0);
		setBlock(world, i + 13, j + 6, k + 17, Blocks.air, 0);
		setBlock(world, i + 13, j + 6, k + 18, Blocks.air, 0);
		setBlock(world, i + 13, j + 7, k + 7, Blocks.air, 0);
		setBlock(world, i + 13, j + 7, k + 8, Blocks.air, 0);
		setBlock(world, i + 13, j + 7, k + 9, Blocks.air, 0);
		setBlock(world, i + 13, j + 7, k + 10, Blocks.air, 0);
		setBlock(world, i + 13, j + 7, k + 11, Blocks.air, 0);
		setBlock(world, i + 13, j + 7, k + 12, Blocks.air, 0);
		setBlock(world, i + 13, j + 7, k + 13, Blocks.air, 0);
		setBlock(world, i + 13, j + 7, k + 14, Blocks.air, 0);
		setBlock(world, i + 13, j + 7, k + 15, Blocks.air, 0);
		setBlock(world, i + 13, j + 7, k + 16, Blocks.air, 0);
		setBlock(world, i + 13, j + 7, k + 17, Blocks.air, 0);
		setBlock(world, i + 13, j + 7, k + 18, Blocks.air, 0);
		setBlock(world, i + 13, j + 8, k + 8, Blocks.air, 0);
		setBlock(world, i + 13, j + 8, k + 9, Blocks.air, 0);
		setBlock(world, i + 13, j + 8, k + 10, Blocks.air, 0);
		setBlock(world, i + 13, j + 8, k + 11, Blocks.air, 0);
		setBlock(world, i + 13, j + 8, k + 12, Blocks.air, 0);
		setBlock(world, i + 13, j + 8, k + 13, Blocks.air, 0);
		setBlock(world, i + 13, j + 8, k + 14, ModBlocks.gravewoodLeaves, 0);
		setBlock(world, i + 13, j + 8, k + 15, Blocks.air, 0);
		setBlock(world, i + 13, j + 8, k + 16, Blocks.air, 0);
		setBlock(world, i + 13, j + 8, k + 17, Blocks.air, 0);
		setBlock(world, i + 13, j + 9, k + 9, Blocks.air, 0);
		setBlock(world, i + 13, j + 9, k + 10, Blocks.air, 0);
		setBlock(world, i + 13, j + 9, k + 11, Blocks.air, 0);
		setBlock(world, i + 13, j + 9, k + 12, Blocks.air, 0);
		setBlock(world, i + 13, j + 9, k + 13, Blocks.air, 0);
		setBlock(world, i + 13, j + 9, k + 14, ModBlocks.gravewood, 0);
		setBlock(world, i + 13, j + 9, k + 15, ModBlocks.gravewoodLeaves, 0);
		setBlock(world, i + 13, j + 9, k + 16, Blocks.air, 0);
		setBlock(world, i + 13, j + 10, k + 11, Blocks.air, 0);
		setBlock(world, i + 13, j + 10, k + 12, Blocks.air, 0);
		setBlock(world, i + 13, j + 10, k + 13, Blocks.air, 0);
		setBlock(world, i + 13, j + 10, k + 14, ModBlocks.gravewoodLeaves, 0);
		setBlock(world, i + 13, j + 10, k + 15, Blocks.air, 0);
		setBlock(world, i + 13, j + 11, k + 12, Blocks.air, 0);
		setBlock(world, i + 13, j + 11, k + 13, Blocks.air, 0);
		setBlock(world, i + 13, j + 11, k + 14, Blocks.air, 0);
		setBlock(world, i + 14, j + 0, k + 10, Blocks.stone, 0);
		setBlock(world, i + 14, j + 0, k + 11, Blocks.cobblestone, 0);
		setBlock(world, i + 14, j + 0, k + 12, Blocks.cobblestone, 0);
		setBlock(world, i + 14, j + 0, k + 13, Blocks.stone, 0);
		setBlock(world, i + 14, j + 0, k + 14, Blocks.stone, 0);
		setBlock(world, i + 14, j + 0, k + 15, Blocks.cobblestone, 0);
		setBlock(world, i + 14, j + 0, k + 16, Blocks.cobblestone, 0);
		setBlock(world, i + 14, j + 1, k + 9, Blocks.air, 3);
		setBlock(world, i + 14, j + 1, k + 10, Blocks.air, 0);
		setBlock(world, i + 14, j + 1, k + 11, Blocks.air, 0);
		setBlock(world, i + 14, j + 1, k + 12, Blocks.air, 0);
		setBlock(world, i + 14, j + 1, k + 13, Blocks.air, 0);
		setBlock(world, i + 14, j + 1, k + 14, Blocks.air, 0);
		setBlock(world, i + 14, j + 1, k + 15, ModBlocks.gravewoodLeaves, 0);
		setBlock(world, i + 14, j + 1, k + 16, ModBlocks.gravewoodLeaves, 0);
		setBlock(world, i + 14, j + 1, k + 17, Blocks.air, 2);
		setBlock(world, i + 14, j + 2, k + 3, Blocks.stone, 0);
		setBlock(world, i + 14, j + 2, k + 4, Blocks.stone, 0);
		setBlock(world, i + 14, j + 2, k + 5, Blocks.stone, 0);
		setBlock(world, i + 14, j + 2, k + 6, Blocks.stone, 0);
		setBlock(world, i + 14, j + 2, k + 7, Blocks.stone, 0);
		setBlock(world, i + 14, j + 2, k + 8, Blocks.stone_slab, 6);
		setBlock(world, i + 14, j + 2, k + 9, Blocks.stone_slab, 14);
		setBlock(world, i + 14, j + 2, k + 10, Blocks.air, 0);
		setBlock(world, i + 14, j + 2, k + 11, Blocks.air, 0);
		setBlock(world, i + 14, j + 2, k + 12, Blocks.air, 0);
		setBlock(world, i + 14, j + 2, k + 13, Blocks.air, 0);
		setBlock(world, i + 14, j + 2, k + 14, Blocks.air, 0);
		setBlock(world, i + 14, j + 2, k + 15, Blocks.air, 0);
		setBlock(world, i + 14, j + 2, k + 16, Blocks.air, 0);
		setBlock(world, i + 14, j + 2, k + 17, Blocks.stone_slab, 14);
		setBlock(world, i + 14, j + 2, k + 18, Blocks.stone_slab, 6);
		setBlock(world, i + 14, j + 3, k + 4, Blocks.stone, 0);
		setBlock(world, i + 14, j + 3, k + 5, Blocks.stone, 0);
		setBlock(world, i + 14, j + 3, k + 6, Blocks.dirt, 0);
		setBlock(world, i + 14, j + 3, k + 7, Blocks.dirt, 0);
		setBlock(world, i + 14, j + 3, k + 8, Blocks.stone, 0);
		setBlock(world, i + 14, j + 3, k + 9, Blocks.stonebrick, 3);
		setBlock(world, i + 14, j + 3, k + 10, Blocks.air, 0);
		setBlock(world, i + 14, j + 3, k + 11, Blocks.air, 0);
		setBlock(world, i + 14, j + 3, k + 12, Blocks.air, 0);
		setBlock(world, i + 14, j + 3, k + 13, Blocks.air, 0);
		setBlock(world, i + 14, j + 3, k + 14, Blocks.air, 0);
		setBlock(world, i + 14, j + 3, k + 15, Blocks.air, 0);
		setBlock(world, i + 14, j + 3, k + 16, Blocks.air, 0);
		setBlock(world, i + 14, j + 3, k + 17, Blocks.stonebrick, 3);
		setBlock(world, i + 14, j + 3, k + 18, Blocks.stone, 0);
		setBlock(world, i + 14, j + 4, k + 4, Blocks.dirt, 0);
		setBlock(world, i + 14, j + 4, k + 5, Blocks.dirt, 0);
		setBlock(world, i + 14, j + 4, k + 6, Blocks.dirt, 0);
		setBlock(world, i + 14, j + 4, k + 7, Blocks.dirt, 0);
		setBlock(world, i + 14, j + 4, k + 8, Blocks.dirt, 0);
		setBlock(world, i + 14, j + 4, k + 9, Blocks.nether_brick_stairs, 7);
		setBlock(world, i + 14, j + 4, k + 10, ModBlocks.gravewood, 0);
		setBlock(world, i + 14, j + 4, k + 11, ModBlocks.gravewoodLeaves, 0);
		setBlock(world, i + 14, j + 4, k + 12, ModBlocks.gravewood, 0);
		setBlock(world, i + 14, j + 4, k + 13, ModBlocks.gravewoodLeaves, 0);
		setBlock(world, i + 14, j + 4, k + 14, ModBlocks.gravewoodLeaves, 0);
		setBlock(world, i + 14, j + 4, k + 14, ModBlocks.gravewoodLeaves, 0);

		generate2(world, rand, i, j, k);

	}

	public static void generate2(World world, Random rand, int i, int j, int k)
	{
		setBlock(world, i + 14, j + 4, k + 15, Blocks.air, 0);
		setBlock(world, i + 14, j + 4, k + 16, Blocks.air, 0);
		setBlock(world, i + 14, j + 4, k + 17, Blocks.nether_brick_stairs, 6);
		setBlock(world, i + 14, j + 4, k + 18, Blocks.dirt, 0);
		setBlock(world, i + 14, j + 5, k + 7, Blocks.dirt, 0);
		setBlock(world, i + 14, j + 5, k + 8, Blocks.dirt, 0);
		setBlock(world, i + 14, j + 5, k + 9, Blocks.dirt, 2);
		setBlock(world, i + 14, j + 5, k + 10, Blocks.dirt, 2);
		setBlock(world, i + 14, j + 5, k + 11, Blocks.mycelium, 0);
		setBlock(world, i + 14, j + 5, k + 12, Blocks.dirt, 2);
		setBlock(world, i + 14, j + 5, k + 13, Blocks.dirt, 2);
		setBlock(world, i + 14, j + 5, k + 14, Blocks.dirt, 0);
		setBlock(world, i + 14, j + 5, k + 15, Blocks.dirt, 2);
		setBlock(world, i + 14, j + 5, k + 16, Blocks.dirt, 2);
		setBlock(world, i + 14, j + 5, k + 17, Blocks.mycelium, 0);
		setBlock(world, i + 14, j + 5, k + 18, Blocks.mycelium, 0);
		setBlock(world, i + 14, j + 6, k + 7, Blocks.stone, 0);
		setBlock(world, i + 14, j + 6, k + 8, Blocks.stone, 0);
		setBlock(world, i + 14, j + 6, k + 10, Blocks.air, 0);
		setBlock(world, i + 14, j + 6, k + 11, Blocks.air, 0);
		setBlock(world, i + 14, j + 6, k + 12, Blocks.air, 0);
		setBlock(world, i + 14, j + 6, k + 13, Blocks.air, 0);
		setBlock(world, i + 14, j + 6, k + 14, ModBlocks.gravewood, 0);
		setBlock(world, i + 14, j + 6, k + 15, Blocks.air, 0);
		setBlock(world, i + 14, j + 6, k + 16, Blocks.air, 0);
		setBlock(world, i + 14, j + 6, k + 17, Blocks.air, 0);
		setBlock(world, i + 14, j + 6, k + 18, Blocks.nether_brick_fence, 0);
		setBlock(world, i + 14, j + 7, k + 7, Blocks.air, 0);
		setBlock(world, i + 14, j + 7, k + 8, Blocks.air, 0);
		setBlock(world, i + 14, j + 7, k + 9, Blocks.air, 0);
		setBlock(world, i + 14, j + 7, k + 10, Blocks.air, 0);
		setBlock(world, i + 14, j + 7, k + 11, Blocks.air, 0);
		setBlock(world, i + 14, j + 7, k + 12, Blocks.air, 0);
		setBlock(world, i + 14, j + 7, k + 13, Blocks.air, 0);
		setBlock(world, i + 14, j + 7, k + 14, ModBlocks.gravewood, 0);
		setBlock(world, i + 14, j + 7, k + 15, ModBlocks.gravewoodLeaves, 0);
		setBlock(world, i + 14, j + 7, k + 16, Blocks.air, 0);
		setBlock(world, i + 14, j + 7, k + 17, Blocks.air, 0);
		setBlock(world, i + 14, j + 7, k + 18, Blocks.air, 0);
		setBlock(world, i + 14, j + 8, k + 8, Blocks.air, 0);
		setBlock(world, i + 14, j + 8, k + 9, Blocks.air, 0);
		setBlock(world, i + 14, j + 8, k + 10, Blocks.air, 0);
		setBlock(world, i + 14, j + 8, k + 11, Blocks.air, 0);
		setBlock(world, i + 14, j + 8, k + 12, Blocks.air, 0);
		setBlock(world, i + 14, j + 8, k + 13, Blocks.air, 0);
		setBlock(world, i + 14, j + 8, k + 14, ModBlocks.gravewood, 0);
		setBlock(world, i + 14, j + 8, k + 15, ModBlocks.gravewoodLeaves, 0);
		setBlock(world, i + 14, j + 8, k + 16, Blocks.air, 0);
		setBlock(world, i + 14, j + 8, k + 17, Blocks.air, 0);
		setBlock(world, i + 14, j + 9, k + 9, Blocks.air, 0);
		setBlock(world, i + 14, j + 9, k + 10, Blocks.air, 0);
		setBlock(world, i + 14, j + 9, k + 11, Blocks.air, 0);
		setBlock(world, i + 14, j + 9, k + 12, Blocks.air, 0);
		setBlock(world, i + 14, j + 9, k + 13, ModBlocks.gravewoodLeaves, 0);
		setBlock(world, i + 14, j + 9, k + 14, ModBlocks.gravewood, 0);
		setBlock(world, i + 14, j + 9, k + 15, ModBlocks.gravewoodLeaves, 0);
		setBlock(world, i + 14, j + 9, k + 16, Blocks.air, 0);
		setBlock(world, i + 14, j + 10, k + 12, Blocks.air, 0);
		setBlock(world, i + 14, j + 10, k + 13, ModBlocks.gravewoodLeaves, 0);
		setBlock(world, i + 14, j + 10, k + 14, ModBlocks.gravewood, 0);
		setBlock(world, i + 14, j + 10, k + 15, Blocks.air, 0);
		setBlock(world, i + 14, j + 11, k + 14, ModBlocks.gravewoodLeaves, 0);
		setBlock(world, i + 15, j + 0, k + 10, Blocks.stone, 0);
		setBlock(world, i + 15, j + 0, k + 11, Blocks.cobblestone, 0);
		setBlock(world, i + 15, j + 0, k + 12, Blocks.stone, 0);
		setBlock(world, i + 15, j + 0, k + 13, Blocks.stone, 0);
		setBlock(world, i + 15, j + 0, k + 14, Blocks.air, 8);
		setBlock(world, i + 15, j + 0, k + 15, Blocks.air, 8);
		setBlock(world, i + 15, j + 0, k + 16, Blocks.air, 4);
		setBlock(world, i + 15, j + 1, k + 9, Blocks.air, 3);
		setBlock(world, i + 15, j + 1, k + 10, Blocks.air, 0);
		setBlock(world, i + 15, j + 1, k + 11, Blocks.air, 0);
		setBlock(world, i + 15, j + 1, k + 12, Blocks.air, 0);
		setBlock(world, i + 15, j + 1, k + 13, Blocks.air, 0);
		setBlock(world, i + 15, j + 1, k + 14, Blocks.air, 0);
		setBlock(world, i + 15, j + 1, k + 15, ModBlocks.gravewoodLeaves, 0);
		setBlock(world, i + 15, j + 1, k + 17, Blocks.air, 2);
		setBlock(world, i + 15, j + 2, k + 4, Blocks.stone, 0);
		setBlock(world, i + 15, j + 2, k + 5, Blocks.stone, 0);
		setBlock(world, i + 15, j + 2, k + 6, Blocks.stone, 0);
		setBlock(world, i + 15, j + 2, k + 7, Blocks.stone, 0);
		setBlock(world, i + 15, j + 2, k + 8, Blocks.stone_slab, 6);
		setBlock(world, i + 15, j + 2, k + 9, Blocks.stone_slab, 14);
		setBlock(world, i + 15, j + 2, k + 10, Blocks.air, 0);
		setBlock(world, i + 15, j + 2, k + 11, Blocks.air, 0);
		setBlock(world, i + 15, j + 2, k + 12, Blocks.air, 0);
		setBlock(world, i + 15, j + 2, k + 13, Blocks.air, 0);
		setBlock(world, i + 15, j + 2, k + 14, Blocks.air, 0);
		setBlock(world, i + 15, j + 2, k + 15, Blocks.air, 0);
		setBlock(world, i + 15, j + 2, k + 16, Blocks.air, 0);
		setBlock(world, i + 15, j + 2, k + 17, Blocks.stone_slab, 14);
		setBlock(world, i + 15, j + 2, k + 18, Blocks.stone_slab, 6);
		setBlock(world, i + 15, j + 3, k + 6, Blocks.dirt, 0);
		setBlock(world, i + 15, j + 3, k + 7, Blocks.dirt, 0);
		setBlock(world, i + 15, j + 3, k + 8, Blocks.stone, 0);
		setBlock(world, i + 15, j + 3, k + 9, Blocks.stonebrick, 3);
		setBlock(world, i + 15, j + 3, k + 10, Blocks.air, 0);
		setBlock(world, i + 15, j + 3, k + 11, ModBlocks.gravewoodLeaves, 0);
		setBlock(world, i + 15, j + 3, k + 12, Blocks.air, 0);
		setBlock(world, i + 15, j + 3, k + 13, Blocks.air, 0);
		setBlock(world, i + 15, j + 3, k + 14, Blocks.air, 0);
		setBlock(world, i + 15, j + 3, k + 15, Blocks.air, 0);
		setBlock(world, i + 15, j + 3, k + 16, ModBlocks.gravewoodLeaves, 0);
		setBlock(world, i + 15, j + 3, k + 17, Blocks.stonebrick, 3);
		setBlock(world, i + 15, j + 3, k + 18, Blocks.stone, 0);
		setBlock(world, i + 15, j + 4, k + 6, Blocks.mycelium, 0);
		setBlock(world, i + 15, j + 4, k + 7, Blocks.dirt, 0);
		setBlock(world, i + 15, j + 4, k + 8, Blocks.dirt, 0);
		setBlock(world, i + 15, j + 4, k + 9, Blocks.nether_brick_stairs, 7);
		setBlock(world, i + 15, j + 4, k + 10, ModBlocks.gravewoodLeaves, 0);
		setBlock(world, i + 15, j + 4, k + 11, ModBlocks.gravewood, 0);
		setBlock(world, i + 15, j + 4, k + 12, ModBlocks.gravewoodLeaves, 0);
		setBlock(world, i + 15, j + 4, k + 13, Blocks.air, 0);
		setBlock(world, i + 15, j + 4, k + 14, Blocks.air, 0);
		setBlock(world, i + 15, j + 4, k + 15, Blocks.air, 0);
		setBlock(world, i + 15, j + 4, k + 16, Blocks.air, 0);
		setBlock(world, i + 15, j + 4, k + 17, Blocks.nether_brick_stairs, 6);
		setBlock(world, i + 15, j + 4, k + 18, Blocks.dirt, 0);
		setBlock(world, i + 15, j + 5, k + 7, Blocks.mycelium, 0);
		setBlock(world, i + 15, j + 5, k + 8, Blocks.dirt, 0);
		setBlock(world, i + 15, j + 5, k + 9, Blocks.dirt, 2);
		setBlock(world, i + 15, j + 5, k + 10, Blocks.dirt, 2);
		setBlock(world, i + 15, j + 5, k + 11, Blocks.mycelium, 0);
		setBlock(world, i + 15, j + 5, k + 12, Blocks.mycelium, 0);
		setBlock(world, i + 15, j + 5, k + 13, Blocks.mycelium, 0);
		setBlock(world, i + 15, j + 5, k + 14, Blocks.mycelium, 0);
		setBlock(world, i + 15, j + 5, k + 15, Blocks.mycelium, 0);
		setBlock(world, i + 15, j + 5, k + 16, Blocks.mycelium, 0);
		setBlock(world, i + 15, j + 5, k + 17, Blocks.mycelium, 0);
		setBlock(world, i + 15, j + 5, k + 18, Blocks.mycelium, 0);
		setBlock(world, i + 15, j + 6, k + 7, Blocks.air, 0);
		setBlock(world, i + 15, j + 6, k + 8, Blocks.stone, 0);
		setBlock(world, i + 15, j + 6, k + 10, Blocks.air, 0);
		setBlock(world, i + 15, j + 6, k + 11, Blocks.air, 0);
		setBlock(world, i + 15, j + 6, k + 12, Blocks.air, 0);
		setBlock(world, i + 15, j + 6, k + 13, Blocks.air, 0);
		setBlock(world, i + 15, j + 6, k + 14, Blocks.air, 0);
		setBlock(world, i + 15, j + 6, k + 15, Blocks.air, 0);
		setBlock(world, i + 15, j + 6, k + 16, Blocks.air, 0);
		setBlock(world, i + 15, j + 6, k + 17, Blocks.air, 0);
		setBlock(world, i + 15, j + 6, k + 18, Blocks.air, 0);
		setBlock(world, i + 15, j + 7, k + 7, Blocks.air, 0);
		setBlock(world, i + 15, j + 7, k + 8, Blocks.air, 0);
		setBlock(world, i + 15, j + 7, k + 9, Blocks.air, 0);
		setBlock(world, i + 15, j + 7, k + 10, Blocks.air, 0);
		setBlock(world, i + 15, j + 7, k + 11, Blocks.air, 0);
		setBlock(world, i + 15, j + 7, k + 12, Blocks.air, 0);
		setBlock(world, i + 15, j + 7, k + 13, Blocks.air, 0);
		setBlock(world, i + 15, j + 7, k + 14, Blocks.air, 0);
		setBlock(world, i + 15, j + 7, k + 15, Blocks.air, 0);
		setBlock(world, i + 15, j + 7, k + 16, Blocks.air, 0);
		setBlock(world, i + 15, j + 7, k + 17, Blocks.air, 0);
		setBlock(world, i + 15, j + 7, k + 18, Blocks.air, 0);
		setBlock(world, i + 15, j + 8, k + 8, Blocks.air, 0);
		setBlock(world, i + 15, j + 8, k + 9, Blocks.air, 0);
		setBlock(world, i + 15, j + 8, k + 10, Blocks.air, 0);
		setBlock(world, i + 15, j + 8, k + 11, Blocks.air, 0);
		setBlock(world, i + 15, j + 8, k + 12, Blocks.air, 0);
		setBlock(world, i + 15, j + 8, k + 13, Blocks.air, 0);
		setBlock(world, i + 15, j + 8, k + 14, Blocks.air, 0);
		setBlock(world, i + 15, j + 8, k + 15, Blocks.air, 0);
		setBlock(world, i + 15, j + 8, k + 16, Blocks.air, 0);
		setBlock(world, i + 15, j + 8, k + 17, Blocks.air, 0);
		setBlock(world, i + 15, j + 9, k + 9, Blocks.air, 0);
		setBlock(world, i + 15, j + 9, k + 10, Blocks.air, 0);
		setBlock(world, i + 15, j + 9, k + 11, Blocks.air, 0);
		setBlock(world, i + 15, j + 9, k + 12, Blocks.air, 0);
		setBlock(world, i + 15, j + 9, k + 13, Blocks.air, 0);
		setBlock(world, i + 15, j + 9, k + 14, ModBlocks.gravewoodLeaves, 0);
		setBlock(world, i + 15, j + 9, k + 15, Blocks.air, 0);
		setBlock(world, i + 15, j + 9, k + 16, Blocks.air, 0);
		setBlock(world, i + 15, j + 10, k + 14, ModBlocks.gravewoodLeaves, 0);
		setBlock(world, i + 16, j + 0, k + 16, Blocks.cobblestone, 0);
		setBlock(world, i + 16, j + 1, k + 14, Blocks.air, 8);
		setBlock(world, i + 16, j + 1, k + 15, Blocks.air, 8);
		setBlock(world, i + 16, j + 1, k + 17, Blocks.air, 4);
		setBlock(world, i + 16, j + 2, k + 6, Blocks.stone, 0);
		setBlock(world, i + 16, j + 2, k + 7, Blocks.stone, 0);
		setBlock(world, i + 16, j + 2, k + 8, Blocks.stone_slab, 6);
		setBlock(world, i + 16, j + 2, k + 9, Blocks.stone_slab, 14);
		setBlock(world, i + 16, j + 2, k + 10, Blocks.stone_slab, 14);
		setBlock(world, i + 16, j + 2, k + 11, Blocks.stone_slab, 14);
		setBlock(world, i + 16, j + 2, k + 12, Blocks.stone_slab, 14);
		setBlock(world, i + 16, j + 2, k + 13, Blocks.air, 0);
		setBlock(world, i + 16, j + 2, k + 14, Blocks.air, 0);
		setBlock(world, i + 16, j + 2, k + 15, Blocks.air, 0);
		setBlock(world, i + 16, j + 2, k + 16, Blocks.air, 0);
		setBlock(world, i + 16, j + 2, k + 17, Blocks.stone_slab, 14);
		setBlock(world, i + 16, j + 2, k + 18, Blocks.stone_slab, 6);
